2022-05-12 15:46:45.209 | ERROR    | monitor.searchSpiders.people:get_request_from_keyword:45 - E 人民网错误HTTPConnectionPool(host='search.people.cn', port=80): Max retries exceeded with url: /search-platform/front/search (Caused by NewConnectionError('<urllib3.connection.HTTPConnection object at 0x7f910427d970>: Failed to establish a new connection: [Errno 111] Connection refused'))
Traceback (most recent call last):

  File "/home/chase/.local/lib/python3.8/site-packages/urllib3/connection.py", line 174, in _new_conn
    conn = connection.create_connection(
           │          └ <function create_connection at 0x7f92585fd1f0>
           └ <module 'urllib3.util.connection' from '/home/chase/.local/lib/python3.8/site-packages/urllib3/util/connection.py'>
  File "/home/chase/.local/lib/python3.8/site-packages/urllib3/util/connection.py", line 96, in create_connection
    raise err
          └ ConnectionRefusedError(111, 'Connection refused')
  File "/home/chase/.local/lib/python3.8/site-packages/urllib3/util/connection.py", line 86, in create_connection
    sock.connect(sa)
    │            └ ('118.212.233.249', 80)
    └ None

ConnectionRefusedError: [Errno 111] Connection refused


During handling of the above exception, another exception occurred:


Traceback (most recent call last):

  File "/home/chase/.local/lib/python3.8/site-packages/urllib3/connectionpool.py", line 699, in urlopen
    httplib_response = self._make_request(
                       │    └ <function HTTPConnectionPool._make_request at 0x7f92585c05e0>
                       └ <urllib3.connectionpool.HTTPConnectionPool object at 0x7f91601f6a00>
  File "/home/chase/.local/lib/python3.8/site-packages/urllib3/connectionpool.py", line 394, in _make_request
    conn.request(method, url, **httplib_request_kw)
    │    │       │       │      └ {'body': b'{"key": "\\u5916\\u4ea4\\u90e8\\uff1a\\u7f8e\\u65b9\\u4fee\\u6539\\u201c\\u7f8e\\u53f0\\u5173\\u7cfb\\u4e8b\\u5b9e...
    │    │       │       └ '/search-platform/front/search'
    │    │       └ 'POST'
    │    └ <function HTTPConnection.request at 0x7f92585b0f70>
    └ <urllib3.connection.HTTPConnection object at 0x7f910427d970>
  File "/home/chase/.local/lib/python3.8/site-packages/urllib3/connection.py", line 239, in request
    super(HTTPConnection, self).request(method, url, body=body, headers=headers)
          │               │             │       │         │             └ {'User-Agent': 'Mozilla/5.0 (Windows NT 10.0; Win64; x64) AppleWebKit/537.36 (KHTML, like Gecko) Chrome/101.0.4951.54 Safari/...
          │               │             │       │         └ b'{"key": "\\u5916\\u4ea4\\u90e8\\uff1a\\u7f8e\\u65b9\\u4fee\\u6539\\u201c\\u7f8e\\u53f0\\u5173\\u7cfb\\u4e8b\\u5b9e\\u6e05\\...
          │               │             │       └ '/search-platform/front/search'
          │               │             └ 'POST'
          │               └ <urllib3.connection.HTTPConnection object at 0x7f910427d970>
          └ <class 'urllib3.connection.HTTPConnection'>
  File "/usr/lib/python3.8/http/client.py", line 1256, in request
    self._send_request(method, url, body, headers, encode_chunked)
    │    │             │       │    │     │        └ False
    │    │             │       │    │     └ {'User-Agent': 'Mozilla/5.0 (Windows NT 10.0; Win64; x64) AppleWebKit/537.36 (KHTML, like Gecko) Chrome/101.0.4951.54 Safari/...
    │    │             │       │    └ b'{"key": "\\u5916\\u4ea4\\u90e8\\uff1a\\u7f8e\\u65b9\\u4fee\\u6539\\u201c\\u7f8e\\u53f0\\u5173\\u7cfb\\u4e8b\\u5b9e\\u6e05\\...
    │    │             │       └ '/search-platform/front/search'
    │    │             └ 'POST'
    │    └ <function HTTPConnection._send_request at 0x7f926be50280>
    └ <urllib3.connection.HTTPConnection object at 0x7f910427d970>
  File "/usr/lib/python3.8/http/client.py", line 1302, in _send_request
    self.endheaders(body, encode_chunked=encode_chunked)
    │    │          │                    └ False
    │    │          └ b'{"key": "\\u5916\\u4ea4\\u90e8\\uff1a\\u7f8e\\u65b9\\u4fee\\u6539\\u201c\\u7f8e\\u53f0\\u5173\\u7cfb\\u4e8b\\u5b9e\\u6e05\\...
    │    └ <function HTTPConnection.endheaders at 0x7f926be50160>
    └ <urllib3.connection.HTTPConnection object at 0x7f910427d970>
  File "/usr/lib/python3.8/http/client.py", line 1251, in endheaders
    self._send_output(message_body, encode_chunked=encode_chunked)
    │    │            │                            └ False
    │    │            └ b'{"key": "\\u5916\\u4ea4\\u90e8\\uff1a\\u7f8e\\u65b9\\u4fee\\u6539\\u201c\\u7f8e\\u53f0\\u5173\\u7cfb\\u4e8b\\u5b9e\\u6e05\\...
    │    └ <function HTTPConnection._send_output at 0x7f926beb7d30>
    └ <urllib3.connection.HTTPConnection object at 0x7f910427d970>
  File "/usr/lib/python3.8/http/client.py", line 1011, in _send_output
    self.send(msg)
    │    │    └ b'POST /search-platform/front/search HTTP/1.1\r\nHost: search.people.cn\r\nUser-Agent: Mozilla/5.0 (Windows NT 10.0; Win64; x...
    │    └ <function HTTPConnection.send at 0x7f926beb7b80>
    └ <urllib3.connection.HTTPConnection object at 0x7f910427d970>
  File "/usr/lib/python3.8/http/client.py", line 951, in send
    self.connect()
    │    └ <function HTTPConnection.connect at 0x7f92585b0dc0>
    └ <urllib3.connection.HTTPConnection object at 0x7f910427d970>
  File "/home/chase/.local/lib/python3.8/site-packages/urllib3/connection.py", line 205, in connect
    conn = self._new_conn()
           │    └ <function HTTPConnection._new_conn at 0x7f92585b0c10>
           └ <urllib3.connection.HTTPConnection object at 0x7f910427d970>
  File "/home/chase/.local/lib/python3.8/site-packages/urllib3/connection.py", line 186, in _new_conn
    raise NewConnectionError(
          └ <class 'urllib3.exceptions.NewConnectionError'>

urllib3.exceptions.NewConnectionError: <urllib3.connection.HTTPConnection object at 0x7f910427d970>: Failed to establish a new connection: [Errno 111] Connection refused


During handling of the above exception, another exception occurred:


Traceback (most recent call last):

  File "/home/chase/.local/lib/python3.8/site-packages/requests/adapters.py", line 439, in send
    resp = conn.urlopen(
           │    └ <function HTTPConnectionPool.urlopen at 0x7f92585c0820>
           └ <urllib3.connectionpool.HTTPConnectionPool object at 0x7f91601f6a00>
  File "/home/chase/.local/lib/python3.8/site-packages/urllib3/connectionpool.py", line 755, in urlopen
    retries = retries.increment(
              │       └ <function Retry.increment at 0x7f9258608b80>
              └ Retry(total=0, connect=None, read=False, redirect=None, status=None)
  File "/home/chase/.local/lib/python3.8/site-packages/urllib3/util/retry.py", line 574, in increment
    raise MaxRetryError(_pool, url, error or ResponseError(cause))
          │             │      │    │        │             └ 'unknown'
          │             │      │    │        └ <class 'urllib3.exceptions.ResponseError'>
          │             │      │    └ NewConnectionError('<urllib3.connection.HTTPConnection object at 0x7f910427d970>: Failed to establish a new connection: [Errn...
          │             │      └ '/search-platform/front/search'
          │             └ <urllib3.connectionpool.HTTPConnectionPool object at 0x7f91601f6a00>
          └ <class 'urllib3.exceptions.MaxRetryError'>

urllib3.exceptions.MaxRetryError: HTTPConnectionPool(host='search.people.cn', port=80): Max retries exceeded with url: /search-platform/front/search (Caused by NewConnectionError('<urllib3.connection.HTTPConnection object at 0x7f910427d970>: Failed to establish a new connection: [Errno 111] Connection refused'))


During handling of the above exception, another exception occurred:


Traceback (most recent call last):

  File "/usr/lib/python3.8/threading.py", line 890, in _bootstrap
    self._bootstrap_inner()
    │    └ <function Thread._bootstrap_inner at 0x7f927a614a60>
    └ <Thread(Thread-116, started daemon 140260344329984)>
  File "/usr/lib/python3.8/threading.py", line 932, in _bootstrap_inner
    self.run()
    │    └ <function Thread.run at 0x7f927a614790>
    └ <Thread(Thread-116, started daemon 140260344329984)>
  File "/usr/lib/python3.8/threading.py", line 870, in run
    self._target(*self._args, **self._kwargs)
    │    │        │    │        │    └ {}
    │    │        │    │        └ <Thread(Thread-116, started daemon 140260344329984)>
    │    │        │    └ ('ProjectManager.run_func_by_thread',)
    │    │        └ <Thread(Thread-116, started daemon 140260344329984)>
    │    └ <bound method ProjectManager.get_request_from_keywords_hot of <monitor.projectManager.ProjectManager object at 0x7f9162af4700>>
    └ <Thread(Thread-116, started daemon 140260344329984)>

  File "/home/users/Scy/yuqing/spider/monitor/projectManager.py", line 795, in get_request_from_keywords_hot
    self.search_spider_manager.crawl_by_keyword(
    │    │                     └ <function SearchSpidersManager.crawl_by_keyword at 0x7f9162b00040>
    │    └ <monitor.spiderManager.SearchSpidersManager object at 0x7f916270f0d0>
    └ <monitor.projectManager.ProjectManager object at 0x7f9162af4700>

  File "/home/users/Scy/yuqing/spider/monitor/spiderManager.py", line 118, in crawl_by_keyword
    self.crawl_by_keyword_signal_platform(project_names, platform, keyword, crawl_time, project_times)
    │    │                                │              │         │        │           └ {'default': <monitor.TimeSection object at 0x7f91628317f0>}
    │    │                                │              │         │        └ <monitor.TimeSection object at 0x7f916271da30>
    │    │                                │              │         └ '外交部：美方修改“美台关系事实清单”必将引火烧身'
    │    │                                │              └ '人民网'
    │    │                                └ ['default']
    │    └ <function SearchSpidersManager.crawl_by_keyword_signal_platform at 0x7f9162b000d0>
    └ <monitor.spiderManager.SearchSpidersManager object at 0x7f916270f0d0>

  File "/home/users/Scy/yuqing/spider/monitor/spiderManager.py", line 134, in crawl_by_keyword_signal_platform
    requests = self.get_request_from_keyword(platform, keyword, **crawl_time.to_dict())
               │    │                        │         │          │          └ <function TimeSection.to_dict at 0x7f925aaa8550>
               │    │                        │         │          └ <monitor.TimeSection object at 0x7f916271da30>
               │    │                        │         └ '外交部：美方修改“美台关系事实清单”必将引火烧身'
               │    │                        └ '人民网'
               │    └ <function SearchSpidersManager.get_request_from_keyword at 0x7f9162b001f0>
               └ <monitor.spiderManager.SearchSpidersManager object at 0x7f916270f0d0>

  File "/home/users/Scy/yuqing/spider/monitor/spiderManager.py", line 191, in get_request_from_keyword
    for request in self.spiders[platform].get_request_from_keyword(headers, search_url, keyword, content_url,
                   │    │       │                                  │        │           │        └ <string.Template object at 0x7f9253d8dd00>
                   │    │       │                                  │        │           └ '外交部：美方修改“美台关系事实清单”必将引火烧身'
                   │    │       │                                  │        └ <string.Template object at 0x7f9148777160>
                   │    │       │                                  └ {'Accept': 'application/json, text/plain, */*', 'Accept-Language': 'zh-CN,zh;q=0.9', 'Connection': 'keep-alive', 'Origin': 'h...
                   │    │       └ '人民网'
                   │    └ {'凤凰网': <monitor.searchSpiders.ifeng.Ifeng object at 0x7f916270f220>, '头条': <monitor.searchSpiders.toutiao.Toutiao object at ...
                   └ <monitor.spiderManager.SearchSpidersManager object at 0x7f916270f0d0>

> File "/home/users/Scy/yuqing/spider/monitor/searchSpiders/people.py", line 28, in get_request_from_keyword
    response = requests.post(search_url.substitute(), json=data, headers=headers)
               │        │    │          │                  │             └ {'Accept': 'application/json, text/plain, */*', 'Accept-Language': 'zh-CN,zh;q=0.9', 'Connection': 'keep-alive', 'Origin': 'h...
               │        │    │          │                  └ {'key': '外交部：美方修改“美台关系事实清单”必将引火烧身', 'page': 1, 'limit': 10, 'hasTitle': True, 'hasContent': True, 'isFuzzy': True, 'type': 0,...
               │        │    │          └ <function Template.substitute at 0x7f927a5fd0d0>
               │        │    └ <string.Template object at 0x7f9148777160>
               │        └ <function post at 0x7f92583e73a0>
               └ <module 'requests' from '/home/chase/.local/lib/python3.8/site-packages/requests/__init__.py'>

  File "/home/chase/.local/lib/python3.8/site-packages/requests/api.py", line 117, in post
    return request('post', url, data=data, json=json, **kwargs)
           │               │         │          │       └ {'headers': {'Accept': 'application/json, text/plain, */*', 'Accept-Language': 'zh-CN,zh;q=0.9', 'Connection': 'keep-alive', ...
           │               │         │          └ {'key': '外交部：美方修改“美台关系事实清单”必将引火烧身', 'page': 1, 'limit': 10, 'hasTitle': True, 'hasContent': True, 'isFuzzy': True, 'type': 0,...
           │               │         └ None
           │               └ 'http://search.people.cn/search-platform/front/search'
           └ <function request at 0x7f9258455040>
  File "/home/chase/.local/lib/python3.8/site-packages/requests/api.py", line 61, in request
    return session.request(method=method, url=url, **kwargs)
           │       │              │           │      └ {'data': None, 'json': {'key': '外交部：美方修改“美台关系事实清单”必将引火烧身', 'page': 1, 'limit': 10, 'hasTitle': True, 'hasContent': True, 'isF...
           │       │              │           └ 'http://search.people.cn/search-platform/front/search'
           │       │              └ 'post'
           │       └ <function Session.request at 0x7f92583e6940>
           └ <requests.sessions.Session object at 0x7f91480e8d30>
  File "/home/chase/.local/lib/python3.8/site-packages/requests/sessions.py", line 542, in request
    resp = self.send(prep, **send_kwargs)
           │    │    │       └ {'timeout': None, 'allow_redirects': True, 'verify': True, 'proxies': OrderedDict(), 'stream': False, 'cert': None}
           │    │    └ <PreparedRequest [POST]>
           │    └ <function Session.send at 0x7f92583e6dc0>
           └ <requests.sessions.Session object at 0x7f91480e8d30>
  File "/home/chase/.local/lib/python3.8/site-packages/requests/sessions.py", line 655, in send
    r = adapter.send(request, **kwargs)
        │       │    │          └ {'timeout': None, 'verify': True, 'proxies': OrderedDict(), 'stream': False, 'cert': None}
        │       │    └ <PreparedRequest [POST]>
        │       └ <function HTTPAdapter.send at 0x7f92583e6280>
        └ <requests.adapters.HTTPAdapter object at 0x7f91244a1880>
  File "/home/chase/.local/lib/python3.8/site-packages/requests/adapters.py", line 516, in send
    raise ConnectionError(e, request=request)
          │                          └ <PreparedRequest [POST]>
          └ <class 'requests.exceptions.ConnectionError'>

requests.exceptions.ConnectionError: HTTPConnectionPool(host='search.people.cn', port=80): Max retries exceeded with url: /search-platform/front/search (Caused by NewConnectionError('<urllib3.connection.HTTPConnection object at 0x7f910427d970>: Failed to establish a new connection: [Errno 111] Connection refused'))
2022-05-12 15:46:45.323 | ERROR    | monitor.searchSpiders.people:get_request_from_keyword:45 - E 人民网错误HTTPConnectionPool(host='search.people.cn', port=80): Max retries exceeded with url: /search-platform/front/search (Caused by NewConnectionError('<urllib3.connection.HTTPConnection object at 0x7f9124392f70>: Failed to establish a new connection: [Errno 111] Connection refused'))
Traceback (most recent call last):

  File "/home/chase/.local/lib/python3.8/site-packages/urllib3/connection.py", line 174, in _new_conn
    conn = connection.create_connection(
           │          └ <function create_connection at 0x7f92585fd1f0>
           └ <module 'urllib3.util.connection' from '/home/chase/.local/lib/python3.8/site-packages/urllib3/util/connection.py'>
  File "/home/chase/.local/lib/python3.8/site-packages/urllib3/util/connection.py", line 96, in create_connection
    raise err
          └ ConnectionRefusedError(111, 'Connection refused')
  File "/home/chase/.local/lib/python3.8/site-packages/urllib3/util/connection.py", line 86, in create_connection
    sock.connect(sa)
    │            └ ('118.212.233.249', 80)
    └ None

ConnectionRefusedError: [Errno 111] Connection refused


During handling of the above exception, another exception occurred:


Traceback (most recent call last):

  File "/home/chase/.local/lib/python3.8/site-packages/urllib3/connectionpool.py", line 699, in urlopen
    httplib_response = self._make_request(
                       │    └ <function HTTPConnectionPool._make_request at 0x7f92585c05e0>
                       └ <urllib3.connectionpool.HTTPConnectionPool object at 0x7f91485dc040>
  File "/home/chase/.local/lib/python3.8/site-packages/urllib3/connectionpool.py", line 394, in _make_request
    conn.request(method, url, **httplib_request_kw)
    │    │       │       │      └ {'body': b'{"key": "\\u7b2c78\\u96c6\\u56e2\\u519b\\u67d0\\u65c5\\uff1a\\u201c\\u4f34\\u968f\\u4fdd\\u969c\\u201d\\u5f3a\\u53...
    │    │       │       └ '/search-platform/front/search'
    │    │       └ 'POST'
    │    └ <function HTTPConnection.request at 0x7f92585b0f70>
    └ <urllib3.connection.HTTPConnection object at 0x7f9124392f70>
  File "/home/chase/.local/lib/python3.8/site-packages/urllib3/connection.py", line 239, in request
    super(HTTPConnection, self).request(method, url, body=body, headers=headers)
          │               │             │       │         │             └ {'User-Agent': 'Mozilla/5.0 (Windows NT 10.0; Win64; x64) AppleWebKit/537.36 (KHTML, like Gecko) Chrome/101.0.4951.54 Safari/...
          │               │             │       │         └ b'{"key": "\\u7b2c78\\u96c6\\u56e2\\u519b\\u67d0\\u65c5\\uff1a\\u201c\\u4f34\\u968f\\u4fdd\\u969c\\u201d\\u5f3a\\u5316\\u6218...
          │               │             │       └ '/search-platform/front/search'
          │               │             └ 'POST'
          │               └ <urllib3.connection.HTTPConnection object at 0x7f9124392f70>
          └ <class 'urllib3.connection.HTTPConnection'>
  File "/usr/lib/python3.8/http/client.py", line 1256, in request
    self._send_request(method, url, body, headers, encode_chunked)
    │    │             │       │    │     │        └ False
    │    │             │       │    │     └ {'User-Agent': 'Mozilla/5.0 (Windows NT 10.0; Win64; x64) AppleWebKit/537.36 (KHTML, like Gecko) Chrome/101.0.4951.54 Safari/...
    │    │             │       │    └ b'{"key": "\\u7b2c78\\u96c6\\u56e2\\u519b\\u67d0\\u65c5\\uff1a\\u201c\\u4f34\\u968f\\u4fdd\\u969c\\u201d\\u5f3a\\u5316\\u6218...
    │    │             │       └ '/search-platform/front/search'
    │    │             └ 'POST'
    │    └ <function HTTPConnection._send_request at 0x7f926be50280>
    └ <urllib3.connection.HTTPConnection object at 0x7f9124392f70>
  File "/usr/lib/python3.8/http/client.py", line 1302, in _send_request
    self.endheaders(body, encode_chunked=encode_chunked)
    │    │          │                    └ False
    │    │          └ b'{"key": "\\u7b2c78\\u96c6\\u56e2\\u519b\\u67d0\\u65c5\\uff1a\\u201c\\u4f34\\u968f\\u4fdd\\u969c\\u201d\\u5f3a\\u5316\\u6218...
    │    └ <function HTTPConnection.endheaders at 0x7f926be50160>
    └ <urllib3.connection.HTTPConnection object at 0x7f9124392f70>
  File "/usr/lib/python3.8/http/client.py", line 1251, in endheaders
    self._send_output(message_body, encode_chunked=encode_chunked)
    │    │            │                            └ False
    │    │            └ b'{"key": "\\u7b2c78\\u96c6\\u56e2\\u519b\\u67d0\\u65c5\\uff1a\\u201c\\u4f34\\u968f\\u4fdd\\u969c\\u201d\\u5f3a\\u5316\\u6218...
    │    └ <function HTTPConnection._send_output at 0x7f926beb7d30>
    └ <urllib3.connection.HTTPConnection object at 0x7f9124392f70>
  File "/usr/lib/python3.8/http/client.py", line 1011, in _send_output
    self.send(msg)
    │    │    └ b'POST /search-platform/front/search HTTP/1.1\r\nHost: search.people.cn\r\nUser-Agent: Mozilla/5.0 (Windows NT 10.0; Win64; x...
    │    └ <function HTTPConnection.send at 0x7f926beb7b80>
    └ <urllib3.connection.HTTPConnection object at 0x7f9124392f70>
  File "/usr/lib/python3.8/http/client.py", line 951, in send
    self.connect()
    │    └ <function HTTPConnection.connect at 0x7f92585b0dc0>
    └ <urllib3.connection.HTTPConnection object at 0x7f9124392f70>
  File "/home/chase/.local/lib/python3.8/site-packages/urllib3/connection.py", line 205, in connect
    conn = self._new_conn()
           │    └ <function HTTPConnection._new_conn at 0x7f92585b0c10>
           └ <urllib3.connection.HTTPConnection object at 0x7f9124392f70>
  File "/home/chase/.local/lib/python3.8/site-packages/urllib3/connection.py", line 186, in _new_conn
    raise NewConnectionError(
          └ <class 'urllib3.exceptions.NewConnectionError'>

urllib3.exceptions.NewConnectionError: <urllib3.connection.HTTPConnection object at 0x7f9124392f70>: Failed to establish a new connection: [Errno 111] Connection refused


During handling of the above exception, another exception occurred:


Traceback (most recent call last):

  File "/home/chase/.local/lib/python3.8/site-packages/requests/adapters.py", line 439, in send
    resp = conn.urlopen(
           │    └ <function HTTPConnectionPool.urlopen at 0x7f92585c0820>
           └ <urllib3.connectionpool.HTTPConnectionPool object at 0x7f91485dc040>
  File "/home/chase/.local/lib/python3.8/site-packages/urllib3/connectionpool.py", line 755, in urlopen
    retries = retries.increment(
              │       └ <function Retry.increment at 0x7f9258608b80>
              └ Retry(total=0, connect=None, read=False, redirect=None, status=None)
  File "/home/chase/.local/lib/python3.8/site-packages/urllib3/util/retry.py", line 574, in increment
    raise MaxRetryError(_pool, url, error or ResponseError(cause))
          │             │      │    │        │             └ 'unknown'
          │             │      │    │        └ <class 'urllib3.exceptions.ResponseError'>
          │             │      │    └ NewConnectionError('<urllib3.connection.HTTPConnection object at 0x7f9124392f70>: Failed to establish a new connection: [Errn...
          │             │      └ '/search-platform/front/search'
          │             └ <urllib3.connectionpool.HTTPConnectionPool object at 0x7f91485dc040>
          └ <class 'urllib3.exceptions.MaxRetryError'>

urllib3.exceptions.MaxRetryError: HTTPConnectionPool(host='search.people.cn', port=80): Max retries exceeded with url: /search-platform/front/search (Caused by NewConnectionError('<urllib3.connection.HTTPConnection object at 0x7f9124392f70>: Failed to establish a new connection: [Errno 111] Connection refused'))


During handling of the above exception, another exception occurred:


Traceback (most recent call last):

  File "/usr/lib/python3.8/threading.py", line 890, in _bootstrap
    self._bootstrap_inner()
    │    └ <function Thread._bootstrap_inner at 0x7f927a614a60>
    └ <Thread(Thread-244, started daemon 140258196846336)>
  File "/usr/lib/python3.8/threading.py", line 932, in _bootstrap_inner
    self.run()
    │    └ <function Thread.run at 0x7f927a614790>
    └ <Thread(Thread-244, started daemon 140258196846336)>
  File "/usr/lib/python3.8/threading.py", line 870, in run
    self._target(*self._args, **self._kwargs)
    │    │        │    │        │    └ {}
    │    │        │    │        └ <Thread(Thread-244, started daemon 140258196846336)>
    │    │        │    └ ('ProjectManager.run_func_by_thread',)
    │    │        └ <Thread(Thread-244, started daemon 140258196846336)>
    │    └ <bound method ProjectManager.get_request_from_keywords_hot of <monitor.projectManager.ProjectManager object at 0x7f9162af4700>>
    └ <Thread(Thread-244, started daemon 140258196846336)>

  File "/home/users/Scy/yuqing/spider/monitor/projectManager.py", line 795, in get_request_from_keywords_hot
    self.search_spider_manager.crawl_by_keyword(
    │    │                     └ <function SearchSpidersManager.crawl_by_keyword at 0x7f9162b00040>
    │    └ <monitor.spiderManager.SearchSpidersManager object at 0x7f916270f0d0>
    └ <monitor.projectManager.ProjectManager object at 0x7f9162af4700>

  File "/home/users/Scy/yuqing/spider/monitor/spiderManager.py", line 118, in crawl_by_keyword
    self.crawl_by_keyword_signal_platform(project_names, platform, keyword, crawl_time, project_times)
    │    │                                │              │         │        │           └ {'default': <monitor.TimeSection object at 0x7f91628317f0>}
    │    │                                │              │         │        └ <monitor.TimeSection object at 0x7f91247aeb50>
    │    │                                │              │         └ '第78集团军某旅：“伴随保障”强化战场意识'
    │    │                                │              └ '人民网'
    │    │                                └ ['default']
    │    └ <function SearchSpidersManager.crawl_by_keyword_signal_platform at 0x7f9162b000d0>
    └ <monitor.spiderManager.SearchSpidersManager object at 0x7f916270f0d0>

  File "/home/users/Scy/yuqing/spider/monitor/spiderManager.py", line 134, in crawl_by_keyword_signal_platform
    requests = self.get_request_from_keyword(platform, keyword, **crawl_time.to_dict())
               │    │                        │         │          │          └ <function TimeSection.to_dict at 0x7f925aaa8550>
               │    │                        │         │          └ <monitor.TimeSection object at 0x7f91247aeb50>
               │    │                        │         └ '第78集团军某旅：“伴随保障”强化战场意识'
               │    │                        └ '人民网'
               │    └ <function SearchSpidersManager.get_request_from_keyword at 0x7f9162b001f0>
               └ <monitor.spiderManager.SearchSpidersManager object at 0x7f916270f0d0>

  File "/home/users/Scy/yuqing/spider/monitor/spiderManager.py", line 191, in get_request_from_keyword
    for request in self.spiders[platform].get_request_from_keyword(headers, search_url, keyword, content_url,
                   │    │       │                                  │        │           │        └ <string.Template object at 0x7f91480e8a60>
                   │    │       │                                  │        │           └ '第78集团军某旅：“伴随保障”强化战场意识'
                   │    │       │                                  │        └ <string.Template object at 0x7f916053c760>
                   │    │       │                                  └ {'Accept': 'application/json, text/plain, */*', 'Accept-Language': 'zh-CN,zh;q=0.9', 'Connection': 'keep-alive', 'Origin': 'h...
                   │    │       └ '人民网'
                   │    └ {'凤凰网': <monitor.searchSpiders.ifeng.Ifeng object at 0x7f916270f220>, '头条': <monitor.searchSpiders.toutiao.Toutiao object at ...
                   └ <monitor.spiderManager.SearchSpidersManager object at 0x7f916270f0d0>

> File "/home/users/Scy/yuqing/spider/monitor/searchSpiders/people.py", line 28, in get_request_from_keyword
    response = requests.post(search_url.substitute(), json=data, headers=headers)
               │        │    │          │                  │             └ {'Accept': 'application/json, text/plain, */*', 'Accept-Language': 'zh-CN,zh;q=0.9', 'Connection': 'keep-alive', 'Origin': 'h...
               │        │    │          │                  └ {'key': '第78集团军某旅：“伴随保障”强化战场意识', 'page': 1, 'limit': 10, 'hasTitle': True, 'hasContent': True, 'isFuzzy': True, 'type': 0, 's...
               │        │    │          └ <function Template.substitute at 0x7f927a5fd0d0>
               │        │    └ <string.Template object at 0x7f916053c760>
               │        └ <function post at 0x7f92583e73a0>
               └ <module 'requests' from '/home/chase/.local/lib/python3.8/site-packages/requests/__init__.py'>

  File "/home/chase/.local/lib/python3.8/site-packages/requests/api.py", line 117, in post
    return request('post', url, data=data, json=json, **kwargs)
           │               │         │          │       └ {'headers': {'Accept': 'application/json, text/plain, */*', 'Accept-Language': 'zh-CN,zh;q=0.9', 'Connection': 'keep-alive', ...
           │               │         │          └ {'key': '第78集团军某旅：“伴随保障”强化战场意识', 'page': 1, 'limit': 10, 'hasTitle': True, 'hasContent': True, 'isFuzzy': True, 'type': 0, 's...
           │               │         └ None
           │               └ 'http://search.people.cn/search-platform/front/search'
           └ <function request at 0x7f9258455040>
  File "/home/chase/.local/lib/python3.8/site-packages/requests/api.py", line 61, in request
    return session.request(method=method, url=url, **kwargs)
           │       │              │           │      └ {'data': None, 'json': {'key': '第78集团军某旅：“伴随保障”强化战场意识', 'page': 1, 'limit': 10, 'hasTitle': True, 'hasContent': True, 'isFuzz...
           │       │              │           └ 'http://search.people.cn/search-platform/front/search'
           │       │              └ 'post'
           │       └ <function Session.request at 0x7f92583e6940>
           └ <requests.sessions.Session object at 0x7f91480fca30>
  File "/home/chase/.local/lib/python3.8/site-packages/requests/sessions.py", line 542, in request
    resp = self.send(prep, **send_kwargs)
           │    │    │       └ {'timeout': None, 'allow_redirects': True, 'verify': True, 'proxies': OrderedDict(), 'stream': False, 'cert': None}
           │    │    └ <PreparedRequest [POST]>
           │    └ <function Session.send at 0x7f92583e6dc0>
           └ <requests.sessions.Session object at 0x7f91480fca30>
  File "/home/chase/.local/lib/python3.8/site-packages/requests/sessions.py", line 655, in send
    r = adapter.send(request, **kwargs)
        │       │    │          └ {'timeout': None, 'verify': True, 'proxies': OrderedDict(), 'stream': False, 'cert': None}
        │       │    └ <PreparedRequest [POST]>
        │       └ <function HTTPAdapter.send at 0x7f92583e6280>
        └ <requests.adapters.HTTPAdapter object at 0x7f9124363490>
  File "/home/chase/.local/lib/python3.8/site-packages/requests/adapters.py", line 516, in send
    raise ConnectionError(e, request=request)
          │                          └ <PreparedRequest [POST]>
          └ <class 'requests.exceptions.ConnectionError'>

requests.exceptions.ConnectionError: HTTPConnectionPool(host='search.people.cn', port=80): Max retries exceeded with url: /search-platform/front/search (Caused by NewConnectionError('<urllib3.connection.HTTPConnection object at 0x7f9124392f70>: Failed to establish a new connection: [Errno 111] Connection refused'))
2022-05-12 15:46:45.569 | ERROR    | monitor.searchSpiders.people:get_request_from_keyword:45 - E 人民网错误HTTPConnectionPool(host='search.people.cn', port=80): Max retries exceeded with url: /search-platform/front/search (Caused by NewConnectionError('<urllib3.connection.HTTPConnection object at 0x7f91240cae80>: Failed to establish a new connection: [Errno 111] Connection refused'))
Traceback (most recent call last):

  File "/home/chase/.local/lib/python3.8/site-packages/urllib3/connection.py", line 174, in _new_conn
    conn = connection.create_connection(
           │          └ <function create_connection at 0x7f92585fd1f0>
           └ <module 'urllib3.util.connection' from '/home/chase/.local/lib/python3.8/site-packages/urllib3/util/connection.py'>
  File "/home/chase/.local/lib/python3.8/site-packages/urllib3/util/connection.py", line 96, in create_connection
    raise err
          └ ConnectionRefusedError(111, 'Connection refused')
  File "/home/chase/.local/lib/python3.8/site-packages/urllib3/util/connection.py", line 86, in create_connection
    sock.connect(sa)
    │            └ ('118.212.233.249', 80)
    └ None

ConnectionRefusedError: [Errno 111] Connection refused


During handling of the above exception, another exception occurred:


Traceback (most recent call last):

  File "/home/chase/.local/lib/python3.8/site-packages/urllib3/connectionpool.py", line 699, in urlopen
    httplib_response = self._make_request(
                       │    └ <function HTTPConnectionPool._make_request at 0x7f92585c05e0>
                       └ <urllib3.connectionpool.HTTPConnectionPool object at 0x7f914862aa90>
  File "/home/chase/.local/lib/python3.8/site-packages/urllib3/connectionpool.py", line 394, in _make_request
    conn.request(method, url, **httplib_request_kw)
    │    │       │       │      └ {'body': b'{"key": "\\u5e94\\u5bf9\\u6c14\\u5019\\u53d8\\u5316\\uff0c\\u4e2d\\u56fd\\u91cd\\u4fe1\\u5b88\\u8bfa\\uff08\\u56fd...
    │    │       │       └ '/search-platform/front/search'
    │    │       └ 'POST'
    │    └ <function HTTPConnection.request at 0x7f92585b0f70>
    └ <urllib3.connection.HTTPConnection object at 0x7f91240cae80>
  File "/home/chase/.local/lib/python3.8/site-packages/urllib3/connection.py", line 239, in request
    super(HTTPConnection, self).request(method, url, body=body, headers=headers)
          │               │             │       │         │             └ {'User-Agent': 'Mozilla/5.0 (Windows NT 10.0; Win64; x64) AppleWebKit/537.36 (KHTML, like Gecko) Chrome/101.0.4951.54 Safari/...
          │               │             │       │         └ b'{"key": "\\u5e94\\u5bf9\\u6c14\\u5019\\u53d8\\u5316\\uff0c\\u4e2d\\u56fd\\u91cd\\u4fe1\\u5b88\\u8bfa\\uff08\\u56fd\\u9645\\...
          │               │             │       └ '/search-platform/front/search'
          │               │             └ 'POST'
          │               └ <urllib3.connection.HTTPConnection object at 0x7f91240cae80>
          └ <class 'urllib3.connection.HTTPConnection'>
  File "/usr/lib/python3.8/http/client.py", line 1256, in request
    self._send_request(method, url, body, headers, encode_chunked)
    │    │             │       │    │     │        └ False
    │    │             │       │    │     └ {'User-Agent': 'Mozilla/5.0 (Windows NT 10.0; Win64; x64) AppleWebKit/537.36 (KHTML, like Gecko) Chrome/101.0.4951.54 Safari/...
    │    │             │       │    └ b'{"key": "\\u5e94\\u5bf9\\u6c14\\u5019\\u53d8\\u5316\\uff0c\\u4e2d\\u56fd\\u91cd\\u4fe1\\u5b88\\u8bfa\\uff08\\u56fd\\u9645\\...
    │    │             │       └ '/search-platform/front/search'
    │    │             └ 'POST'
    │    └ <function HTTPConnection._send_request at 0x7f926be50280>
    └ <urllib3.connection.HTTPConnection object at 0x7f91240cae80>
  File "/usr/lib/python3.8/http/client.py", line 1302, in _send_request
    self.endheaders(body, encode_chunked=encode_chunked)
    │    │          │                    └ False
    │    │          └ b'{"key": "\\u5e94\\u5bf9\\u6c14\\u5019\\u53d8\\u5316\\uff0c\\u4e2d\\u56fd\\u91cd\\u4fe1\\u5b88\\u8bfa\\uff08\\u56fd\\u9645\\...
    │    └ <function HTTPConnection.endheaders at 0x7f926be50160>
    └ <urllib3.connection.HTTPConnection object at 0x7f91240cae80>
  File "/usr/lib/python3.8/http/client.py", line 1251, in endheaders
    self._send_output(message_body, encode_chunked=encode_chunked)
    │    │            │                            └ False
    │    │            └ b'{"key": "\\u5e94\\u5bf9\\u6c14\\u5019\\u53d8\\u5316\\uff0c\\u4e2d\\u56fd\\u91cd\\u4fe1\\u5b88\\u8bfa\\uff08\\u56fd\\u9645\\...
    │    └ <function HTTPConnection._send_output at 0x7f926beb7d30>
    └ <urllib3.connection.HTTPConnection object at 0x7f91240cae80>
  File "/usr/lib/python3.8/http/client.py", line 1011, in _send_output
    self.send(msg)
    │    │    └ b'POST /search-platform/front/search HTTP/1.1\r\nHost: search.people.cn\r\nUser-Agent: Mozilla/5.0 (Windows NT 10.0; Win64; x...
    │    └ <function HTTPConnection.send at 0x7f926beb7b80>
    └ <urllib3.connection.HTTPConnection object at 0x7f91240cae80>
  File "/usr/lib/python3.8/http/client.py", line 951, in send
    self.connect()
    │    └ <function HTTPConnection.connect at 0x7f92585b0dc0>
    └ <urllib3.connection.HTTPConnection object at 0x7f91240cae80>
  File "/home/chase/.local/lib/python3.8/site-packages/urllib3/connection.py", line 205, in connect
    conn = self._new_conn()
           │    └ <function HTTPConnection._new_conn at 0x7f92585b0c10>
           └ <urllib3.connection.HTTPConnection object at 0x7f91240cae80>
  File "/home/chase/.local/lib/python3.8/site-packages/urllib3/connection.py", line 186, in _new_conn
    raise NewConnectionError(
          └ <class 'urllib3.exceptions.NewConnectionError'>

urllib3.exceptions.NewConnectionError: <urllib3.connection.HTTPConnection object at 0x7f91240cae80>: Failed to establish a new connection: [Errno 111] Connection refused


During handling of the above exception, another exception occurred:


Traceback (most recent call last):

  File "/home/chase/.local/lib/python3.8/site-packages/requests/adapters.py", line 439, in send
    resp = conn.urlopen(
           │    └ <function HTTPConnectionPool.urlopen at 0x7f92585c0820>
           └ <urllib3.connectionpool.HTTPConnectionPool object at 0x7f914862aa90>
  File "/home/chase/.local/lib/python3.8/site-packages/urllib3/connectionpool.py", line 755, in urlopen
    retries = retries.increment(
              │       └ <function Retry.increment at 0x7f9258608b80>
              └ Retry(total=0, connect=None, read=False, redirect=None, status=None)
  File "/home/chase/.local/lib/python3.8/site-packages/urllib3/util/retry.py", line 574, in increment
    raise MaxRetryError(_pool, url, error or ResponseError(cause))
          │             │      │    │        │             └ 'unknown'
          │             │      │    │        └ <class 'urllib3.exceptions.ResponseError'>
          │             │      │    └ NewConnectionError('<urllib3.connection.HTTPConnection object at 0x7f91240cae80>: Failed to establish a new connection: [Errn...
          │             │      └ '/search-platform/front/search'
          │             └ <urllib3.connectionpool.HTTPConnectionPool object at 0x7f914862aa90>
          └ <class 'urllib3.exceptions.MaxRetryError'>

urllib3.exceptions.MaxRetryError: HTTPConnectionPool(host='search.people.cn', port=80): Max retries exceeded with url: /search-platform/front/search (Caused by NewConnectionError('<urllib3.connection.HTTPConnection object at 0x7f91240cae80>: Failed to establish a new connection: [Errno 111] Connection refused'))


During handling of the above exception, another exception occurred:


Traceback (most recent call last):

  File "/usr/lib/python3.8/threading.py", line 890, in _bootstrap
    self._bootstrap_inner()
    │    └ <function Thread._bootstrap_inner at 0x7f927a614a60>
    └ <Thread(Thread-101, started daemon 140260856022784)>
  File "/usr/lib/python3.8/threading.py", line 932, in _bootstrap_inner
    self.run()
    │    └ <function Thread.run at 0x7f927a614790>
    └ <Thread(Thread-101, started daemon 140260856022784)>
  File "/usr/lib/python3.8/threading.py", line 870, in run
    self._target(*self._args, **self._kwargs)
    │    │        │    │        │    └ {}
    │    │        │    │        └ <Thread(Thread-101, started daemon 140260856022784)>
    │    │        │    └ ('ProjectManager.run_func_by_thread',)
    │    │        └ <Thread(Thread-101, started daemon 140260856022784)>
    │    └ <bound method ProjectManager.get_request_from_keywords_hot of <monitor.projectManager.ProjectManager object at 0x7f9162af4700>>
    └ <Thread(Thread-101, started daemon 140260856022784)>

  File "/home/users/Scy/yuqing/spider/monitor/projectManager.py", line 795, in get_request_from_keywords_hot
    self.search_spider_manager.crawl_by_keyword(
    │    │                     └ <function SearchSpidersManager.crawl_by_keyword at 0x7f9162b00040>
    │    └ <monitor.spiderManager.SearchSpidersManager object at 0x7f916270f0d0>
    └ <monitor.projectManager.ProjectManager object at 0x7f9162af4700>

  File "/home/users/Scy/yuqing/spider/monitor/spiderManager.py", line 118, in crawl_by_keyword
    self.crawl_by_keyword_signal_platform(project_names, platform, keyword, crawl_time, project_times)
    │    │                                │              │         │        │           └ {'default': <monitor.TimeSection object at 0x7f91628317f0>}
    │    │                                │              │         │        └ <monitor.TimeSection object at 0x7f91600dc550>
    │    │                                │              │         └ '应对气候变化，中国重信守诺（国际论坛）'
    │    │                                │              └ '人民网'
    │    │                                └ ['default']
    │    └ <function SearchSpidersManager.crawl_by_keyword_signal_platform at 0x7f9162b000d0>
    └ <monitor.spiderManager.SearchSpidersManager object at 0x7f916270f0d0>

  File "/home/users/Scy/yuqing/spider/monitor/spiderManager.py", line 134, in crawl_by_keyword_signal_platform
    requests = self.get_request_from_keyword(platform, keyword, **crawl_time.to_dict())
               │    │                        │         │          │          └ <function TimeSection.to_dict at 0x7f925aaa8550>
               │    │                        │         │          └ <monitor.TimeSection object at 0x7f91600dc550>
               │    │                        │         └ '应对气候变化，中国重信守诺（国际论坛）'
               │    │                        └ '人民网'
               │    └ <function SearchSpidersManager.get_request_from_keyword at 0x7f9162b001f0>
               └ <monitor.spiderManager.SearchSpidersManager object at 0x7f916270f0d0>

  File "/home/users/Scy/yuqing/spider/monitor/spiderManager.py", line 191, in get_request_from_keyword
    for request in self.spiders[platform].get_request_from_keyword(headers, search_url, keyword, content_url,
                   │    │       │                                  │        │           │        └ <string.Template object at 0x7f9124674fd0>
                   │    │       │                                  │        │           └ '应对气候变化，中国重信守诺（国际论坛）'
                   │    │       │                                  │        └ <string.Template object at 0x7f914821e490>
                   │    │       │                                  └ {'Accept': 'application/json, text/plain, */*', 'Accept-Language': 'zh-CN,zh;q=0.9', 'Connection': 'keep-alive', 'Origin': 'h...
                   │    │       └ '人民网'
                   │    └ {'凤凰网': <monitor.searchSpiders.ifeng.Ifeng object at 0x7f916270f220>, '头条': <monitor.searchSpiders.toutiao.Toutiao object at ...
                   └ <monitor.spiderManager.SearchSpidersManager object at 0x7f916270f0d0>

> File "/home/users/Scy/yuqing/spider/monitor/searchSpiders/people.py", line 28, in get_request_from_keyword
    response = requests.post(search_url.substitute(), json=data, headers=headers)
               │        │    │          │                  │             └ {'Accept': 'application/json, text/plain, */*', 'Accept-Language': 'zh-CN,zh;q=0.9', 'Connection': 'keep-alive', 'Origin': 'h...
               │        │    │          │                  └ {'key': '应对气候变化，中国重信守诺（国际论坛）', 'page': 1, 'limit': 10, 'hasTitle': True, 'hasContent': True, 'isFuzzy': True, 'type': 0, 'sor...
               │        │    │          └ <function Template.substitute at 0x7f927a5fd0d0>
               │        │    └ <string.Template object at 0x7f914821e490>
               │        └ <function post at 0x7f92583e73a0>
               └ <module 'requests' from '/home/chase/.local/lib/python3.8/site-packages/requests/__init__.py'>

  File "/home/chase/.local/lib/python3.8/site-packages/requests/api.py", line 117, in post
    return request('post', url, data=data, json=json, **kwargs)
           │               │         │          │       └ {'headers': {'Accept': 'application/json, text/plain, */*', 'Accept-Language': 'zh-CN,zh;q=0.9', 'Connection': 'keep-alive', ...
           │               │         │          └ {'key': '应对气候变化，中国重信守诺（国际论坛）', 'page': 1, 'limit': 10, 'hasTitle': True, 'hasContent': True, 'isFuzzy': True, 'type': 0, 'sor...
           │               │         └ None
           │               └ 'http://search.people.cn/search-platform/front/search'
           └ <function request at 0x7f9258455040>
  File "/home/chase/.local/lib/python3.8/site-packages/requests/api.py", line 61, in request
    return session.request(method=method, url=url, **kwargs)
           │       │              │           │      └ {'data': None, 'json': {'key': '应对气候变化，中国重信守诺（国际论坛）', 'page': 1, 'limit': 10, 'hasTitle': True, 'hasContent': True, 'isFuzzy'...
           │       │              │           └ 'http://search.people.cn/search-platform/front/search'
           │       │              └ 'post'
           │       └ <function Session.request at 0x7f92583e6940>
           └ <requests.sessions.Session object at 0x7f91603752b0>
  File "/home/chase/.local/lib/python3.8/site-packages/requests/sessions.py", line 542, in request
    resp = self.send(prep, **send_kwargs)
           │    │    │       └ {'timeout': None, 'allow_redirects': True, 'verify': True, 'proxies': OrderedDict(), 'stream': False, 'cert': None}
           │    │    └ <PreparedRequest [POST]>
           │    └ <function Session.send at 0x7f92583e6dc0>
           └ <requests.sessions.Session object at 0x7f91603752b0>
  File "/home/chase/.local/lib/python3.8/site-packages/requests/sessions.py", line 655, in send
    r = adapter.send(request, **kwargs)
        │       │    │          └ {'timeout': None, 'verify': True, 'proxies': OrderedDict(), 'stream': False, 'cert': None}
        │       │    └ <PreparedRequest [POST]>
        │       └ <function HTTPAdapter.send at 0x7f92583e6280>
        └ <requests.adapters.HTTPAdapter object at 0x7f91242d5730>
  File "/home/chase/.local/lib/python3.8/site-packages/requests/adapters.py", line 516, in send
    raise ConnectionError(e, request=request)
          │                          └ <PreparedRequest [POST]>
          └ <class 'requests.exceptions.ConnectionError'>

requests.exceptions.ConnectionError: HTTPConnectionPool(host='search.people.cn', port=80): Max retries exceeded with url: /search-platform/front/search (Caused by NewConnectionError('<urllib3.connection.HTTPConnection object at 0x7f91240cae80>: Failed to establish a new connection: [Errno 111] Connection refused'))
2022-05-12 15:46:45.857 | ERROR    | monitor.searchSpiders.people:get_request_from_keyword:45 - E 人民网错误HTTPConnectionPool(host='search.people.cn', port=80): Max retries exceeded with url: /search-platform/front/search (Caused by NewConnectionError('<urllib3.connection.HTTPConnection object at 0x7f9124507280>: Failed to establish a new connection: [Errno 111] Connection refused'))
Traceback (most recent call last):

  File "/home/chase/.local/lib/python3.8/site-packages/urllib3/connection.py", line 174, in _new_conn
    conn = connection.create_connection(
           │          └ <function create_connection at 0x7f92585fd1f0>
           └ <module 'urllib3.util.connection' from '/home/chase/.local/lib/python3.8/site-packages/urllib3/util/connection.py'>
  File "/home/chase/.local/lib/python3.8/site-packages/urllib3/util/connection.py", line 96, in create_connection
    raise err
          └ ConnectionRefusedError(111, 'Connection refused')
  File "/home/chase/.local/lib/python3.8/site-packages/urllib3/util/connection.py", line 86, in create_connection
    sock.connect(sa)
    │            └ ('118.212.233.249', 80)
    └ None

ConnectionRefusedError: [Errno 111] Connection refused


During handling of the above exception, another exception occurred:


Traceback (most recent call last):

  File "/home/chase/.local/lib/python3.8/site-packages/urllib3/connectionpool.py", line 699, in urlopen
    httplib_response = self._make_request(
                       │    └ <function HTTPConnectionPool._make_request at 0x7f92585c05e0>
                       └ <urllib3.connectionpool.HTTPConnectionPool object at 0x7f9124537640>
  File "/home/chase/.local/lib/python3.8/site-packages/urllib3/connectionpool.py", line 394, in _make_request
    conn.request(method, url, **httplib_request_kw)
    │    │       │       │      └ {'body': b'{"key": "\\u5916\\u4ea4\\u90e8\\uff1a\\u7f8e\\u65b9\\u4fee\\u6539\\u201c\\u7f8e\\u53f0\\u5173\\u7cfb\\u4e8b\\u5b9e...
    │    │       │       └ '/search-platform/front/search'
    │    │       └ 'POST'
    │    └ <function HTTPConnection.request at 0x7f92585b0f70>
    └ <urllib3.connection.HTTPConnection object at 0x7f9124507280>
  File "/home/chase/.local/lib/python3.8/site-packages/urllib3/connection.py", line 239, in request
    super(HTTPConnection, self).request(method, url, body=body, headers=headers)
          │               │             │       │         │             └ {'User-Agent': 'Mozilla/5.0 (Windows NT 10.0; Win64; x64) AppleWebKit/537.36 (KHTML, like Gecko) Chrome/101.0.4951.54 Safari/...
          │               │             │       │         └ b'{"key": "\\u5916\\u4ea4\\u90e8\\uff1a\\u7f8e\\u65b9\\u4fee\\u6539\\u201c\\u7f8e\\u53f0\\u5173\\u7cfb\\u4e8b\\u5b9e\\u6e05\\...
          │               │             │       └ '/search-platform/front/search'
          │               │             └ 'POST'
          │               └ <urllib3.connection.HTTPConnection object at 0x7f9124507280>
          └ <class 'urllib3.connection.HTTPConnection'>
  File "/usr/lib/python3.8/http/client.py", line 1256, in request
    self._send_request(method, url, body, headers, encode_chunked)
    │    │             │       │    │     │        └ False
    │    │             │       │    │     └ {'User-Agent': 'Mozilla/5.0 (Windows NT 10.0; Win64; x64) AppleWebKit/537.36 (KHTML, like Gecko) Chrome/101.0.4951.54 Safari/...
    │    │             │       │    └ b'{"key": "\\u5916\\u4ea4\\u90e8\\uff1a\\u7f8e\\u65b9\\u4fee\\u6539\\u201c\\u7f8e\\u53f0\\u5173\\u7cfb\\u4e8b\\u5b9e\\u6e05\\...
    │    │             │       └ '/search-platform/front/search'
    │    │             └ 'POST'
    │    └ <function HTTPConnection._send_request at 0x7f926be50280>
    └ <urllib3.connection.HTTPConnection object at 0x7f9124507280>
  File "/usr/lib/python3.8/http/client.py", line 1302, in _send_request
    self.endheaders(body, encode_chunked=encode_chunked)
    │    │          │                    └ False
    │    │          └ b'{"key": "\\u5916\\u4ea4\\u90e8\\uff1a\\u7f8e\\u65b9\\u4fee\\u6539\\u201c\\u7f8e\\u53f0\\u5173\\u7cfb\\u4e8b\\u5b9e\\u6e05\\...
    │    └ <function HTTPConnection.endheaders at 0x7f926be50160>
    └ <urllib3.connection.HTTPConnection object at 0x7f9124507280>
  File "/usr/lib/python3.8/http/client.py", line 1251, in endheaders
    self._send_output(message_body, encode_chunked=encode_chunked)
    │    │            │                            └ False
    │    │            └ b'{"key": "\\u5916\\u4ea4\\u90e8\\uff1a\\u7f8e\\u65b9\\u4fee\\u6539\\u201c\\u7f8e\\u53f0\\u5173\\u7cfb\\u4e8b\\u5b9e\\u6e05\\...
    │    └ <function HTTPConnection._send_output at 0x7f926beb7d30>
    └ <urllib3.connection.HTTPConnection object at 0x7f9124507280>
  File "/usr/lib/python3.8/http/client.py", line 1011, in _send_output
    self.send(msg)
    │    │    └ b'POST /search-platform/front/search HTTP/1.1\r\nHost: search.people.cn\r\nUser-Agent: Mozilla/5.0 (Windows NT 10.0; Win64; x...
    │    └ <function HTTPConnection.send at 0x7f926beb7b80>
    └ <urllib3.connection.HTTPConnection object at 0x7f9124507280>
  File "/usr/lib/python3.8/http/client.py", line 951, in send
    self.connect()
    │    └ <function HTTPConnection.connect at 0x7f92585b0dc0>
    └ <urllib3.connection.HTTPConnection object at 0x7f9124507280>
  File "/home/chase/.local/lib/python3.8/site-packages/urllib3/connection.py", line 205, in connect
    conn = self._new_conn()
           │    └ <function HTTPConnection._new_conn at 0x7f92585b0c10>
           └ <urllib3.connection.HTTPConnection object at 0x7f9124507280>
  File "/home/chase/.local/lib/python3.8/site-packages/urllib3/connection.py", line 186, in _new_conn
    raise NewConnectionError(
          └ <class 'urllib3.exceptions.NewConnectionError'>

urllib3.exceptions.NewConnectionError: <urllib3.connection.HTTPConnection object at 0x7f9124507280>: Failed to establish a new connection: [Errno 111] Connection refused


During handling of the above exception, another exception occurred:


Traceback (most recent call last):

  File "/home/chase/.local/lib/python3.8/site-packages/requests/adapters.py", line 439, in send
    resp = conn.urlopen(
           │    └ <function HTTPConnectionPool.urlopen at 0x7f92585c0820>
           └ <urllib3.connectionpool.HTTPConnectionPool object at 0x7f9124537640>
  File "/home/chase/.local/lib/python3.8/site-packages/urllib3/connectionpool.py", line 755, in urlopen
    retries = retries.increment(
              │       └ <function Retry.increment at 0x7f9258608b80>
              └ Retry(total=0, connect=None, read=False, redirect=None, status=None)
  File "/home/chase/.local/lib/python3.8/site-packages/urllib3/util/retry.py", line 574, in increment
    raise MaxRetryError(_pool, url, error or ResponseError(cause))
          │             │      │    │        │             └ 'unknown'
          │             │      │    │        └ <class 'urllib3.exceptions.ResponseError'>
          │             │      │    └ NewConnectionError('<urllib3.connection.HTTPConnection object at 0x7f9124507280>: Failed to establish a new connection: [Errn...
          │             │      └ '/search-platform/front/search'
          │             └ <urllib3.connectionpool.HTTPConnectionPool object at 0x7f9124537640>
          └ <class 'urllib3.exceptions.MaxRetryError'>

urllib3.exceptions.MaxRetryError: HTTPConnectionPool(host='search.people.cn', port=80): Max retries exceeded with url: /search-platform/front/search (Caused by NewConnectionError('<urllib3.connection.HTTPConnection object at 0x7f9124507280>: Failed to establish a new connection: [Errno 111] Connection refused'))


During handling of the above exception, another exception occurred:


Traceback (most recent call last):

  File "/usr/lib/python3.8/threading.py", line 890, in _bootstrap
    self._bootstrap_inner()
    │    └ <function Thread._bootstrap_inner at 0x7f927a614a60>
    └ <Thread(Thread-106, started daemon 140260839237376)>
  File "/usr/lib/python3.8/threading.py", line 932, in _bootstrap_inner
    self.run()
    │    └ <function Thread.run at 0x7f927a614790>
    └ <Thread(Thread-106, started daemon 140260839237376)>
  File "/usr/lib/python3.8/threading.py", line 870, in run
    self._target(*self._args, **self._kwargs)
    │    │        │    │        │    └ {}
    │    │        │    │        └ <Thread(Thread-106, started daemon 140260839237376)>
    │    │        │    └ ('ProjectManager.run_func_by_thread',)
    │    │        └ <Thread(Thread-106, started daemon 140260839237376)>
    │    └ <bound method ProjectManager.get_request_from_keywords_hot of <monitor.projectManager.ProjectManager object at 0x7f9162af4700>>
    └ <Thread(Thread-106, started daemon 140260839237376)>

  File "/home/users/Scy/yuqing/spider/monitor/projectManager.py", line 795, in get_request_from_keywords_hot
    self.search_spider_manager.crawl_by_keyword(
    │    │                     └ <function SearchSpidersManager.crawl_by_keyword at 0x7f9162b00040>
    │    └ <monitor.spiderManager.SearchSpidersManager object at 0x7f916270f0d0>
    └ <monitor.projectManager.ProjectManager object at 0x7f9162af4700>

  File "/home/users/Scy/yuqing/spider/monitor/spiderManager.py", line 118, in crawl_by_keyword
    self.crawl_by_keyword_signal_platform(project_names, platform, keyword, crawl_time, project_times)
    │    │                                │              │         │        │           └ {'default': <monitor.TimeSection object at 0x7f91628317f0>}
    │    │                                │              │         │        └ <monitor.TimeSection object at 0x7f91604d7fd0>
    │    │                                │              │         └ '外交部：美方修改“美台关系事实清单”必将引火烧身'
    │    │                                │              └ '人民网'
    │    │                                └ ['default']
    │    └ <function SearchSpidersManager.crawl_by_keyword_signal_platform at 0x7f9162b000d0>
    └ <monitor.spiderManager.SearchSpidersManager object at 0x7f916270f0d0>

  File "/home/users/Scy/yuqing/spider/monitor/spiderManager.py", line 134, in crawl_by_keyword_signal_platform
    requests = self.get_request_from_keyword(platform, keyword, **crawl_time.to_dict())
               │    │                        │         │          │          └ <function TimeSection.to_dict at 0x7f925aaa8550>
               │    │                        │         │          └ <monitor.TimeSection object at 0x7f91604d7fd0>
               │    │                        │         └ '外交部：美方修改“美台关系事实清单”必将引火烧身'
               │    │                        └ '人民网'
               │    └ <function SearchSpidersManager.get_request_from_keyword at 0x7f9162b001f0>
               └ <monitor.spiderManager.SearchSpidersManager object at 0x7f916270f0d0>

  File "/home/users/Scy/yuqing/spider/monitor/spiderManager.py", line 191, in get_request_from_keyword
    for request in self.spiders[platform].get_request_from_keyword(headers, search_url, keyword, content_url,
                   │    │       │                                  │        │           │        └ <string.Template object at 0x7f914809d700>
                   │    │       │                                  │        │           └ '外交部：美方修改“美台关系事实清单”必将引火烧身'
                   │    │       │                                  │        └ <string.Template object at 0x7f9124085430>
                   │    │       │                                  └ {'Accept': 'application/json, text/plain, */*', 'Accept-Language': 'zh-CN,zh;q=0.9', 'Connection': 'keep-alive', 'Origin': 'h...
                   │    │       └ '人民网'
                   │    └ {'凤凰网': <monitor.searchSpiders.ifeng.Ifeng object at 0x7f916270f220>, '头条': <monitor.searchSpiders.toutiao.Toutiao object at ...
                   └ <monitor.spiderManager.SearchSpidersManager object at 0x7f916270f0d0>

> File "/home/users/Scy/yuqing/spider/monitor/searchSpiders/people.py", line 28, in get_request_from_keyword
    response = requests.post(search_url.substitute(), json=data, headers=headers)
               │        │    │          │                  │             └ {'Accept': 'application/json, text/plain, */*', 'Accept-Language': 'zh-CN,zh;q=0.9', 'Connection': 'keep-alive', 'Origin': 'h...
               │        │    │          │                  └ {'key': '外交部：美方修改“美台关系事实清单”必将引火烧身', 'page': 1, 'limit': 10, 'hasTitle': True, 'hasContent': True, 'isFuzzy': True, 'type': 0,...
               │        │    │          └ <function Template.substitute at 0x7f927a5fd0d0>
               │        │    └ <string.Template object at 0x7f9124085430>
               │        └ <function post at 0x7f92583e73a0>
               └ <module 'requests' from '/home/chase/.local/lib/python3.8/site-packages/requests/__init__.py'>

  File "/home/chase/.local/lib/python3.8/site-packages/requests/api.py", line 117, in post
    return request('post', url, data=data, json=json, **kwargs)
           │               │         │          │       └ {'headers': {'Accept': 'application/json, text/plain, */*', 'Accept-Language': 'zh-CN,zh;q=0.9', 'Connection': 'keep-alive', ...
           │               │         │          └ {'key': '外交部：美方修改“美台关系事实清单”必将引火烧身', 'page': 1, 'limit': 10, 'hasTitle': True, 'hasContent': True, 'isFuzzy': True, 'type': 0,...
           │               │         └ None
           │               └ 'http://search.people.cn/search-platform/front/search'
           └ <function request at 0x7f9258455040>
  File "/home/chase/.local/lib/python3.8/site-packages/requests/api.py", line 61, in request
    return session.request(method=method, url=url, **kwargs)
           │       │              │           │      └ {'data': None, 'json': {'key': '外交部：美方修改“美台关系事实清单”必将引火烧身', 'page': 1, 'limit': 10, 'hasTitle': True, 'hasContent': True, 'isF...
           │       │              │           └ 'http://search.people.cn/search-platform/front/search'
           │       │              └ 'post'
           │       └ <function Session.request at 0x7f92583e6940>
           └ <requests.sessions.Session object at 0x7f9124605c40>
  File "/home/chase/.local/lib/python3.8/site-packages/requests/sessions.py", line 542, in request
    resp = self.send(prep, **send_kwargs)
           │    │    │       └ {'timeout': None, 'allow_redirects': True, 'verify': True, 'proxies': OrderedDict(), 'stream': False, 'cert': None}
           │    │    └ <PreparedRequest [POST]>
           │    └ <function Session.send at 0x7f92583e6dc0>
           └ <requests.sessions.Session object at 0x7f9124605c40>
  File "/home/chase/.local/lib/python3.8/site-packages/requests/sessions.py", line 655, in send
    r = adapter.send(request, **kwargs)
        │       │    │          └ {'timeout': None, 'verify': True, 'proxies': OrderedDict(), 'stream': False, 'cert': None}
        │       │    └ <PreparedRequest [POST]>
        │       └ <function HTTPAdapter.send at 0x7f92583e6280>
        └ <requests.adapters.HTTPAdapter object at 0x7f91603dae20>
  File "/home/chase/.local/lib/python3.8/site-packages/requests/adapters.py", line 516, in send
    raise ConnectionError(e, request=request)
          │                          └ <PreparedRequest [POST]>
          └ <class 'requests.exceptions.ConnectionError'>

requests.exceptions.ConnectionError: HTTPConnectionPool(host='search.people.cn', port=80): Max retries exceeded with url: /search-platform/front/search (Caused by NewConnectionError('<urllib3.connection.HTTPConnection object at 0x7f9124507280>: Failed to establish a new connection: [Errno 111] Connection refused'))
2022-05-12 15:46:46.450 | ERROR    | monitor.searchSpiders.people:get_request_from_keyword:45 - E 人民网错误HTTPConnectionPool(host='search.people.cn', port=80): Max retries exceeded with url: /search-platform/front/search (Caused by NewConnectionError('<urllib3.connection.HTTPConnection object at 0x7f91243cbb80>: Failed to establish a new connection: [Errno 111] Connection refused'))
Traceback (most recent call last):

  File "/home/chase/.local/lib/python3.8/site-packages/urllib3/connection.py", line 174, in _new_conn
    conn = connection.create_connection(
           │          └ <function create_connection at 0x7f92585fd1f0>
           └ <module 'urllib3.util.connection' from '/home/chase/.local/lib/python3.8/site-packages/urllib3/util/connection.py'>
  File "/home/chase/.local/lib/python3.8/site-packages/urllib3/util/connection.py", line 96, in create_connection
    raise err
          └ ConnectionRefusedError(111, 'Connection refused')
  File "/home/chase/.local/lib/python3.8/site-packages/urllib3/util/connection.py", line 86, in create_connection
    sock.connect(sa)
    │            └ ('118.212.233.249', 80)
    └ None

ConnectionRefusedError: [Errno 111] Connection refused


During handling of the above exception, another exception occurred:


Traceback (most recent call last):

  File "/home/chase/.local/lib/python3.8/site-packages/urllib3/connectionpool.py", line 699, in urlopen
    httplib_response = self._make_request(
                       │    └ <function HTTPConnectionPool._make_request at 0x7f92585c05e0>
                       └ <urllib3.connectionpool.HTTPConnectionPool object at 0x7f9253e09a90>
  File "/home/chase/.local/lib/python3.8/site-packages/urllib3/connectionpool.py", line 394, in _make_request
    conn.request(method, url, **httplib_request_kw)
    │    │       │       │      └ {'body': b'{"key": "\\u4fc4\\u7f57\\u65af\\u4e3e\\u884c\\u80dc\\u5229\\u65e5\\u9605\\u5175", "page": 1, "limit": 10, "hasTitl...
    │    │       │       └ '/search-platform/front/search'
    │    │       └ 'POST'
    │    └ <function HTTPConnection.request at 0x7f92585b0f70>
    └ <urllib3.connection.HTTPConnection object at 0x7f91243cbb80>
  File "/home/chase/.local/lib/python3.8/site-packages/urllib3/connection.py", line 239, in request
    super(HTTPConnection, self).request(method, url, body=body, headers=headers)
          │               │             │       │         │             └ {'User-Agent': 'Mozilla/5.0 (Windows NT 10.0; Win64; x64) AppleWebKit/537.36 (KHTML, like Gecko) Chrome/101.0.4951.54 Safari/...
          │               │             │       │         └ b'{"key": "\\u4fc4\\u7f57\\u65af\\u4e3e\\u884c\\u80dc\\u5229\\u65e5\\u9605\\u5175", "page": 1, "limit": 10, "hasTitle": true,...
          │               │             │       └ '/search-platform/front/search'
          │               │             └ 'POST'
          │               └ <urllib3.connection.HTTPConnection object at 0x7f91243cbb80>
          └ <class 'urllib3.connection.HTTPConnection'>
  File "/usr/lib/python3.8/http/client.py", line 1256, in request
    self._send_request(method, url, body, headers, encode_chunked)
    │    │             │       │    │     │        └ False
    │    │             │       │    │     └ {'User-Agent': 'Mozilla/5.0 (Windows NT 10.0; Win64; x64) AppleWebKit/537.36 (KHTML, like Gecko) Chrome/101.0.4951.54 Safari/...
    │    │             │       │    └ b'{"key": "\\u4fc4\\u7f57\\u65af\\u4e3e\\u884c\\u80dc\\u5229\\u65e5\\u9605\\u5175", "page": 1, "limit": 10, "hasTitle": true,...
    │    │             │       └ '/search-platform/front/search'
    │    │             └ 'POST'
    │    └ <function HTTPConnection._send_request at 0x7f926be50280>
    └ <urllib3.connection.HTTPConnection object at 0x7f91243cbb80>
  File "/usr/lib/python3.8/http/client.py", line 1302, in _send_request
    self.endheaders(body, encode_chunked=encode_chunked)
    │    │          │                    └ False
    │    │          └ b'{"key": "\\u4fc4\\u7f57\\u65af\\u4e3e\\u884c\\u80dc\\u5229\\u65e5\\u9605\\u5175", "page": 1, "limit": 10, "hasTitle": true,...
    │    └ <function HTTPConnection.endheaders at 0x7f926be50160>
    └ <urllib3.connection.HTTPConnection object at 0x7f91243cbb80>
  File "/usr/lib/python3.8/http/client.py", line 1251, in endheaders
    self._send_output(message_body, encode_chunked=encode_chunked)
    │    │            │                            └ False
    │    │            └ b'{"key": "\\u4fc4\\u7f57\\u65af\\u4e3e\\u884c\\u80dc\\u5229\\u65e5\\u9605\\u5175", "page": 1, "limit": 10, "hasTitle": true,...
    │    └ <function HTTPConnection._send_output at 0x7f926beb7d30>
    └ <urllib3.connection.HTTPConnection object at 0x7f91243cbb80>
  File "/usr/lib/python3.8/http/client.py", line 1011, in _send_output
    self.send(msg)
    │    │    └ b'POST /search-platform/front/search HTTP/1.1\r\nHost: search.people.cn\r\nUser-Agent: Mozilla/5.0 (Windows NT 10.0; Win64; x...
    │    └ <function HTTPConnection.send at 0x7f926beb7b80>
    └ <urllib3.connection.HTTPConnection object at 0x7f91243cbb80>
  File "/usr/lib/python3.8/http/client.py", line 951, in send
    self.connect()
    │    └ <function HTTPConnection.connect at 0x7f92585b0dc0>
    └ <urllib3.connection.HTTPConnection object at 0x7f91243cbb80>
  File "/home/chase/.local/lib/python3.8/site-packages/urllib3/connection.py", line 205, in connect
    conn = self._new_conn()
           │    └ <function HTTPConnection._new_conn at 0x7f92585b0c10>
           └ <urllib3.connection.HTTPConnection object at 0x7f91243cbb80>
  File "/home/chase/.local/lib/python3.8/site-packages/urllib3/connection.py", line 186, in _new_conn
    raise NewConnectionError(
          └ <class 'urllib3.exceptions.NewConnectionError'>

urllib3.exceptions.NewConnectionError: <urllib3.connection.HTTPConnection object at 0x7f91243cbb80>: Failed to establish a new connection: [Errno 111] Connection refused


During handling of the above exception, another exception occurred:


Traceback (most recent call last):

  File "/home/chase/.local/lib/python3.8/site-packages/requests/adapters.py", line 439, in send
    resp = conn.urlopen(
           │    └ <function HTTPConnectionPool.urlopen at 0x7f92585c0820>
           └ <urllib3.connectionpool.HTTPConnectionPool object at 0x7f9253e09a90>
  File "/home/chase/.local/lib/python3.8/site-packages/urllib3/connectionpool.py", line 755, in urlopen
    retries = retries.increment(
              │       └ <function Retry.increment at 0x7f9258608b80>
              └ Retry(total=0, connect=None, read=False, redirect=None, status=None)
  File "/home/chase/.local/lib/python3.8/site-packages/urllib3/util/retry.py", line 574, in increment
    raise MaxRetryError(_pool, url, error or ResponseError(cause))
          │             │      │    │        │             └ 'unknown'
          │             │      │    │        └ <class 'urllib3.exceptions.ResponseError'>
          │             │      │    └ NewConnectionError('<urllib3.connection.HTTPConnection object at 0x7f91243cbb80>: Failed to establish a new connection: [Errn...
          │             │      └ '/search-platform/front/search'
          │             └ <urllib3.connectionpool.HTTPConnectionPool object at 0x7f9253e09a90>
          └ <class 'urllib3.exceptions.MaxRetryError'>

urllib3.exceptions.MaxRetryError: HTTPConnectionPool(host='search.people.cn', port=80): Max retries exceeded with url: /search-platform/front/search (Caused by NewConnectionError('<urllib3.connection.HTTPConnection object at 0x7f91243cbb80>: Failed to establish a new connection: [Errno 111] Connection refused'))


During handling of the above exception, another exception occurred:


Traceback (most recent call last):

  File "/usr/lib/python3.8/threading.py", line 890, in _bootstrap
    self._bootstrap_inner()
    │    └ <function Thread._bootstrap_inner at 0x7f927a614a60>
    └ <Thread(Thread-262, started daemon 140258171668224)>
  File "/usr/lib/python3.8/threading.py", line 932, in _bootstrap_inner
    self.run()
    │    └ <function Thread.run at 0x7f927a614790>
    └ <Thread(Thread-262, started daemon 140258171668224)>
  File "/usr/lib/python3.8/threading.py", line 870, in run
    self._target(*self._args, **self._kwargs)
    │    │        │    │        │    └ {}
    │    │        │    │        └ <Thread(Thread-262, started daemon 140258171668224)>
    │    │        │    └ ('ProjectManager.run_func_by_thread',)
    │    │        └ <Thread(Thread-262, started daemon 140258171668224)>
    │    └ <bound method ProjectManager.get_request_from_keywords_hot of <monitor.projectManager.ProjectManager object at 0x7f9162af4700>>
    └ <Thread(Thread-262, started daemon 140258171668224)>

  File "/home/users/Scy/yuqing/spider/monitor/projectManager.py", line 795, in get_request_from_keywords_hot
    self.search_spider_manager.crawl_by_keyword(
    │    │                     └ <function SearchSpidersManager.crawl_by_keyword at 0x7f9162b00040>
    │    └ <monitor.spiderManager.SearchSpidersManager object at 0x7f916270f0d0>
    └ <monitor.projectManager.ProjectManager object at 0x7f9162af4700>

  File "/home/users/Scy/yuqing/spider/monitor/spiderManager.py", line 118, in crawl_by_keyword
    self.crawl_by_keyword_signal_platform(project_names, platform, keyword, crawl_time, project_times)
    │    │                                │              │         │        │           └ {'default': <monitor.TimeSection object at 0x7f91628317f0>}
    │    │                                │              │         │        └ <monitor.TimeSection object at 0x7f9160384d90>
    │    │                                │              │         └ '俄罗斯举行胜利日阅兵'
    │    │                                │              └ '人民网'
    │    │                                └ ['default']
    │    └ <function SearchSpidersManager.crawl_by_keyword_signal_platform at 0x7f9162b000d0>
    └ <monitor.spiderManager.SearchSpidersManager object at 0x7f916270f0d0>

  File "/home/users/Scy/yuqing/spider/monitor/spiderManager.py", line 134, in crawl_by_keyword_signal_platform
    requests = self.get_request_from_keyword(platform, keyword, **crawl_time.to_dict())
               │    │                        │         │          │          └ <function TimeSection.to_dict at 0x7f925aaa8550>
               │    │                        │         │          └ <monitor.TimeSection object at 0x7f9160384d90>
               │    │                        │         └ '俄罗斯举行胜利日阅兵'
               │    │                        └ '人民网'
               │    └ <function SearchSpidersManager.get_request_from_keyword at 0x7f9162b001f0>
               └ <monitor.spiderManager.SearchSpidersManager object at 0x7f916270f0d0>

  File "/home/users/Scy/yuqing/spider/monitor/spiderManager.py", line 191, in get_request_from_keyword
    for request in self.spiders[platform].get_request_from_keyword(headers, search_url, keyword, content_url,
                   │    │       │                                  │        │           │        └ <string.Template object at 0x7f91042a67c0>
                   │    │       │                                  │        │           └ '俄罗斯举行胜利日阅兵'
                   │    │       │                                  │        └ <string.Template object at 0x7f9124507700>
                   │    │       │                                  └ {'Accept': 'application/json, text/plain, */*', 'Accept-Language': 'zh-CN,zh;q=0.9', 'Connection': 'keep-alive', 'Origin': 'h...
                   │    │       └ '人民网'
                   │    └ {'凤凰网': <monitor.searchSpiders.ifeng.Ifeng object at 0x7f916270f220>, '头条': <monitor.searchSpiders.toutiao.Toutiao object at ...
                   └ <monitor.spiderManager.SearchSpidersManager object at 0x7f916270f0d0>

> File "/home/users/Scy/yuqing/spider/monitor/searchSpiders/people.py", line 28, in get_request_from_keyword
    response = requests.post(search_url.substitute(), json=data, headers=headers)
               │        │    │          │                  │             └ {'Accept': 'application/json, text/plain, */*', 'Accept-Language': 'zh-CN,zh;q=0.9', 'Connection': 'keep-alive', 'Origin': 'h...
               │        │    │          │                  └ {'key': '俄罗斯举行胜利日阅兵', 'page': 1, 'limit': 10, 'hasTitle': True, 'hasContent': True, 'isFuzzy': True, 'type': 0, 'sortType': 2...
               │        │    │          └ <function Template.substitute at 0x7f927a5fd0d0>
               │        │    └ <string.Template object at 0x7f9124507700>
               │        └ <function post at 0x7f92583e73a0>
               └ <module 'requests' from '/home/chase/.local/lib/python3.8/site-packages/requests/__init__.py'>

  File "/home/chase/.local/lib/python3.8/site-packages/requests/api.py", line 117, in post
    return request('post', url, data=data, json=json, **kwargs)
           │               │         │          │       └ {'headers': {'Accept': 'application/json, text/plain, */*', 'Accept-Language': 'zh-CN,zh;q=0.9', 'Connection': 'keep-alive', ...
           │               │         │          └ {'key': '俄罗斯举行胜利日阅兵', 'page': 1, 'limit': 10, 'hasTitle': True, 'hasContent': True, 'isFuzzy': True, 'type': 0, 'sortType': 2...
           │               │         └ None
           │               └ 'http://search.people.cn/search-platform/front/search'
           └ <function request at 0x7f9258455040>
  File "/home/chase/.local/lib/python3.8/site-packages/requests/api.py", line 61, in request
    return session.request(method=method, url=url, **kwargs)
           │       │              │           │      └ {'data': None, 'json': {'key': '俄罗斯举行胜利日阅兵', 'page': 1, 'limit': 10, 'hasTitle': True, 'hasContent': True, 'isFuzzy': True, '...
           │       │              │           └ 'http://search.people.cn/search-platform/front/search'
           │       │              └ 'post'
           │       └ <function Session.request at 0x7f92583e6940>
           └ <requests.sessions.Session object at 0x7f9253d8dd60>
  File "/home/chase/.local/lib/python3.8/site-packages/requests/sessions.py", line 542, in request
    resp = self.send(prep, **send_kwargs)
           │    │    │       └ {'timeout': None, 'allow_redirects': True, 'verify': True, 'proxies': OrderedDict(), 'stream': False, 'cert': None}
           │    │    └ <PreparedRequest [POST]>
           │    └ <function Session.send at 0x7f92583e6dc0>
           └ <requests.sessions.Session object at 0x7f9253d8dd60>
  File "/home/chase/.local/lib/python3.8/site-packages/requests/sessions.py", line 655, in send
    r = adapter.send(request, **kwargs)
        │       │    │          └ {'timeout': None, 'verify': True, 'proxies': OrderedDict(), 'stream': False, 'cert': None}
        │       │    └ <PreparedRequest [POST]>
        │       └ <function HTTPAdapter.send at 0x7f92583e6280>
        └ <requests.adapters.HTTPAdapter object at 0x7f91480717f0>
  File "/home/chase/.local/lib/python3.8/site-packages/requests/adapters.py", line 516, in send
    raise ConnectionError(e, request=request)
          │                          └ <PreparedRequest [POST]>
          └ <class 'requests.exceptions.ConnectionError'>

requests.exceptions.ConnectionError: HTTPConnectionPool(host='search.people.cn', port=80): Max retries exceeded with url: /search-platform/front/search (Caused by NewConnectionError('<urllib3.connection.HTTPConnection object at 0x7f91243cbb80>: Failed to establish a new connection: [Errno 111] Connection refused'))
2022-05-12 15:46:46.847 | ERROR    | monitor.searchSpiders.people:get_request_from_keyword:45 - E 人民网错误HTTPConnectionPool(host='search.people.cn', port=80): Max retries exceeded with url: /search-platform/front/search (Caused by NewConnectionError('<urllib3.connection.HTTPConnection object at 0x7f9253e5d520>: Failed to establish a new connection: [Errno 111] Connection refused'))
Traceback (most recent call last):

  File "/home/chase/.local/lib/python3.8/site-packages/urllib3/connection.py", line 174, in _new_conn
    conn = connection.create_connection(
           │          └ <function create_connection at 0x7f92585fd1f0>
           └ <module 'urllib3.util.connection' from '/home/chase/.local/lib/python3.8/site-packages/urllib3/util/connection.py'>
  File "/home/chase/.local/lib/python3.8/site-packages/urllib3/util/connection.py", line 96, in create_connection
    raise err
          └ ConnectionRefusedError(111, 'Connection refused')
  File "/home/chase/.local/lib/python3.8/site-packages/urllib3/util/connection.py", line 86, in create_connection
    sock.connect(sa)
    │            └ ('118.212.233.249', 80)
    └ None

ConnectionRefusedError: [Errno 111] Connection refused


During handling of the above exception, another exception occurred:


Traceback (most recent call last):

  File "/home/chase/.local/lib/python3.8/site-packages/urllib3/connectionpool.py", line 699, in urlopen
    httplib_response = self._make_request(
                       │    └ <function HTTPConnectionPool._make_request at 0x7f92585c05e0>
                       └ <urllib3.connectionpool.HTTPConnectionPool object at 0x7f9124155820>
  File "/home/chase/.local/lib/python3.8/site-packages/urllib3/connectionpool.py", line 394, in _make_request
    conn.request(method, url, **httplib_request_kw)
    │    │       │       │      └ {'body': b'{"key": "\\u4e1c\\u90e8\\u6218\\u533a\\u7ec4\\u7ec7\\u5175\\u529b\\u5728\\u53f0\\u5c9b\\u4ee5\\u4e1c\\u548c\\u897f...
    │    │       │       └ '/search-platform/front/search'
    │    │       └ 'POST'
    │    └ <function HTTPConnection.request at 0x7f92585b0f70>
    └ <urllib3.connection.HTTPConnection object at 0x7f9253e5d520>
  File "/home/chase/.local/lib/python3.8/site-packages/urllib3/connection.py", line 239, in request
    super(HTTPConnection, self).request(method, url, body=body, headers=headers)
          │               │             │       │         │             └ {'User-Agent': 'Mozilla/5.0 (Windows NT 10.0; Win64; x64) AppleWebKit/537.36 (KHTML, like Gecko) Chrome/101.0.4951.54 Safari/...
          │               │             │       │         └ b'{"key": "\\u4e1c\\u90e8\\u6218\\u533a\\u7ec4\\u7ec7\\u5175\\u529b\\u5728\\u53f0\\u5c9b\\u4ee5\\u4e1c\\u548c\\u897f\\u5357\\...
          │               │             │       └ '/search-platform/front/search'
          │               │             └ 'POST'
          │               └ <urllib3.connection.HTTPConnection object at 0x7f9253e5d520>
          └ <class 'urllib3.connection.HTTPConnection'>
  File "/usr/lib/python3.8/http/client.py", line 1256, in request
    self._send_request(method, url, body, headers, encode_chunked)
    │    │             │       │    │     │        └ False
    │    │             │       │    │     └ {'User-Agent': 'Mozilla/5.0 (Windows NT 10.0; Win64; x64) AppleWebKit/537.36 (KHTML, like Gecko) Chrome/101.0.4951.54 Safari/...
    │    │             │       │    └ b'{"key": "\\u4e1c\\u90e8\\u6218\\u533a\\u7ec4\\u7ec7\\u5175\\u529b\\u5728\\u53f0\\u5c9b\\u4ee5\\u4e1c\\u548c\\u897f\\u5357\\...
    │    │             │       └ '/search-platform/front/search'
    │    │             └ 'POST'
    │    └ <function HTTPConnection._send_request at 0x7f926be50280>
    └ <urllib3.connection.HTTPConnection object at 0x7f9253e5d520>
  File "/usr/lib/python3.8/http/client.py", line 1302, in _send_request
    self.endheaders(body, encode_chunked=encode_chunked)
    │    │          │                    └ False
    │    │          └ b'{"key": "\\u4e1c\\u90e8\\u6218\\u533a\\u7ec4\\u7ec7\\u5175\\u529b\\u5728\\u53f0\\u5c9b\\u4ee5\\u4e1c\\u548c\\u897f\\u5357\\...
    │    └ <function HTTPConnection.endheaders at 0x7f926be50160>
    └ <urllib3.connection.HTTPConnection object at 0x7f9253e5d520>
  File "/usr/lib/python3.8/http/client.py", line 1251, in endheaders
    self._send_output(message_body, encode_chunked=encode_chunked)
    │    │            │                            └ False
    │    │            └ b'{"key": "\\u4e1c\\u90e8\\u6218\\u533a\\u7ec4\\u7ec7\\u5175\\u529b\\u5728\\u53f0\\u5c9b\\u4ee5\\u4e1c\\u548c\\u897f\\u5357\\...
    │    └ <function HTTPConnection._send_output at 0x7f926beb7d30>
    └ <urllib3.connection.HTTPConnection object at 0x7f9253e5d520>
  File "/usr/lib/python3.8/http/client.py", line 1011, in _send_output
    self.send(msg)
    │    │    └ b'POST /search-platform/front/search HTTP/1.1\r\nHost: search.people.cn\r\nUser-Agent: Mozilla/5.0 (Windows NT 10.0; Win64; x...
    │    └ <function HTTPConnection.send at 0x7f926beb7b80>
    └ <urllib3.connection.HTTPConnection object at 0x7f9253e5d520>
  File "/usr/lib/python3.8/http/client.py", line 951, in send
    self.connect()
    │    └ <function HTTPConnection.connect at 0x7f92585b0dc0>
    └ <urllib3.connection.HTTPConnection object at 0x7f9253e5d520>
  File "/home/chase/.local/lib/python3.8/site-packages/urllib3/connection.py", line 205, in connect
    conn = self._new_conn()
           │    └ <function HTTPConnection._new_conn at 0x7f92585b0c10>
           └ <urllib3.connection.HTTPConnection object at 0x7f9253e5d520>
  File "/home/chase/.local/lib/python3.8/site-packages/urllib3/connection.py", line 186, in _new_conn
    raise NewConnectionError(
          └ <class 'urllib3.exceptions.NewConnectionError'>

urllib3.exceptions.NewConnectionError: <urllib3.connection.HTTPConnection object at 0x7f9253e5d520>: Failed to establish a new connection: [Errno 111] Connection refused


During handling of the above exception, another exception occurred:


Traceback (most recent call last):

  File "/home/chase/.local/lib/python3.8/site-packages/requests/adapters.py", line 439, in send
    resp = conn.urlopen(
           │    └ <function HTTPConnectionPool.urlopen at 0x7f92585c0820>
           └ <urllib3.connectionpool.HTTPConnectionPool object at 0x7f9124155820>
  File "/home/chase/.local/lib/python3.8/site-packages/urllib3/connectionpool.py", line 755, in urlopen
    retries = retries.increment(
              │       └ <function Retry.increment at 0x7f9258608b80>
              └ Retry(total=0, connect=None, read=False, redirect=None, status=None)
  File "/home/chase/.local/lib/python3.8/site-packages/urllib3/util/retry.py", line 574, in increment
    raise MaxRetryError(_pool, url, error or ResponseError(cause))
          │             │      │    │        │             └ 'unknown'
          │             │      │    │        └ <class 'urllib3.exceptions.ResponseError'>
          │             │      │    └ NewConnectionError('<urllib3.connection.HTTPConnection object at 0x7f9253e5d520>: Failed to establish a new connection: [Errn...
          │             │      └ '/search-platform/front/search'
          │             └ <urllib3.connectionpool.HTTPConnectionPool object at 0x7f9124155820>
          └ <class 'urllib3.exceptions.MaxRetryError'>

urllib3.exceptions.MaxRetryError: HTTPConnectionPool(host='search.people.cn', port=80): Max retries exceeded with url: /search-platform/front/search (Caused by NewConnectionError('<urllib3.connection.HTTPConnection object at 0x7f9253e5d520>: Failed to establish a new connection: [Errno 111] Connection refused'))


During handling of the above exception, another exception occurred:


Traceback (most recent call last):

  File "/usr/lib/python3.8/threading.py", line 890, in _bootstrap
    self._bootstrap_inner()
    │    └ <function Thread._bootstrap_inner at 0x7f927a614a60>
    └ <Thread(Thread-51, started daemon 140261409679104)>
  File "/usr/lib/python3.8/threading.py", line 932, in _bootstrap_inner
    self.run()
    │    └ <function Thread.run at 0x7f927a614790>
    └ <Thread(Thread-51, started daemon 140261409679104)>
  File "/usr/lib/python3.8/threading.py", line 870, in run
    self._target(*self._args, **self._kwargs)
    │    │        │    │        │    └ {}
    │    │        │    │        └ <Thread(Thread-51, started daemon 140261409679104)>
    │    │        │    └ ('ProjectManager.run_func_by_thread',)
    │    │        └ <Thread(Thread-51, started daemon 140261409679104)>
    │    └ <bound method ProjectManager.get_request_from_keywords_hot of <monitor.projectManager.ProjectManager object at 0x7f9162af4700>>
    └ <Thread(Thread-51, started daemon 140261409679104)>

  File "/home/users/Scy/yuqing/spider/monitor/projectManager.py", line 795, in get_request_from_keywords_hot
    self.search_spider_manager.crawl_by_keyword(
    │    │                     └ <function SearchSpidersManager.crawl_by_keyword at 0x7f9162b00040>
    │    └ <monitor.spiderManager.SearchSpidersManager object at 0x7f916270f0d0>
    └ <monitor.projectManager.ProjectManager object at 0x7f9162af4700>

  File "/home/users/Scy/yuqing/spider/monitor/spiderManager.py", line 118, in crawl_by_keyword
    self.crawl_by_keyword_signal_platform(project_names, platform, keyword, crawl_time, project_times)
    │    │                                │              │         │        │           └ {'default': <monitor.TimeSection object at 0x7f91628317f0>}
    │    │                                │              │         │        └ <monitor.TimeSection object at 0x7f9160260070>
    │    │                                │              │         └ '东部战区组织兵力在台岛以东和西南海空域进行实兵演练'
    │    │                                │              └ '人民网'
    │    │                                └ ['default']
    │    └ <function SearchSpidersManager.crawl_by_keyword_signal_platform at 0x7f9162b000d0>
    └ <monitor.spiderManager.SearchSpidersManager object at 0x7f916270f0d0>

  File "/home/users/Scy/yuqing/spider/monitor/spiderManager.py", line 134, in crawl_by_keyword_signal_platform
    requests = self.get_request_from_keyword(platform, keyword, **crawl_time.to_dict())
               │    │                        │         │          │          └ <function TimeSection.to_dict at 0x7f925aaa8550>
               │    │                        │         │          └ <monitor.TimeSection object at 0x7f9160260070>
               │    │                        │         └ '东部战区组织兵力在台岛以东和西南海空域进行实兵演练'
               │    │                        └ '人民网'
               │    └ <function SearchSpidersManager.get_request_from_keyword at 0x7f9162b001f0>
               └ <monitor.spiderManager.SearchSpidersManager object at 0x7f916270f0d0>

  File "/home/users/Scy/yuqing/spider/monitor/spiderManager.py", line 191, in get_request_from_keyword
    for request in self.spiders[platform].get_request_from_keyword(headers, search_url, keyword, content_url,
                   │    │       │                                  │        │           │        └ <string.Template object at 0x7f914821eac0>
                   │    │       │                                  │        │           └ '东部战区组织兵力在台岛以东和西南海空域进行实兵演练'
                   │    │       │                                  │        └ <string.Template object at 0x7f91041b60d0>
                   │    │       │                                  └ {'Accept': 'application/json, text/plain, */*', 'Accept-Language': 'zh-CN,zh;q=0.9', 'Connection': 'keep-alive', 'Origin': 'h...
                   │    │       └ '人民网'
                   │    └ {'凤凰网': <monitor.searchSpiders.ifeng.Ifeng object at 0x7f916270f220>, '头条': <monitor.searchSpiders.toutiao.Toutiao object at ...
                   └ <monitor.spiderManager.SearchSpidersManager object at 0x7f916270f0d0>

> File "/home/users/Scy/yuqing/spider/monitor/searchSpiders/people.py", line 28, in get_request_from_keyword
    response = requests.post(search_url.substitute(), json=data, headers=headers)
               │        │    │          │                  │             └ {'Accept': 'application/json, text/plain, */*', 'Accept-Language': 'zh-CN,zh;q=0.9', 'Connection': 'keep-alive', 'Origin': 'h...
               │        │    │          │                  └ {'key': '东部战区组织兵力在台岛以东和西南海空域进行实兵演练', 'page': 1, 'limit': 10, 'hasTitle': True, 'hasContent': True, 'isFuzzy': True, 'type': 0...
               │        │    │          └ <function Template.substitute at 0x7f927a5fd0d0>
               │        │    └ <string.Template object at 0x7f91041b60d0>
               │        └ <function post at 0x7f92583e73a0>
               └ <module 'requests' from '/home/chase/.local/lib/python3.8/site-packages/requests/__init__.py'>

  File "/home/chase/.local/lib/python3.8/site-packages/requests/api.py", line 117, in post
    return request('post', url, data=data, json=json, **kwargs)
           │               │         │          │       └ {'headers': {'Accept': 'application/json, text/plain, */*', 'Accept-Language': 'zh-CN,zh;q=0.9', 'Connection': 'keep-alive', ...
           │               │         │          └ {'key': '东部战区组织兵力在台岛以东和西南海空域进行实兵演练', 'page': 1, 'limit': 10, 'hasTitle': True, 'hasContent': True, 'isFuzzy': True, 'type': 0...
           │               │         └ None
           │               └ 'http://search.people.cn/search-platform/front/search'
           └ <function request at 0x7f9258455040>
  File "/home/chase/.local/lib/python3.8/site-packages/requests/api.py", line 61, in request
    return session.request(method=method, url=url, **kwargs)
           │       │              │           │      └ {'data': None, 'json': {'key': '东部战区组织兵力在台岛以东和西南海空域进行实兵演练', 'page': 1, 'limit': 10, 'hasTitle': True, 'hasContent': True, 'is...
           │       │              │           └ 'http://search.people.cn/search-platform/front/search'
           │       │              └ 'post'
           │       └ <function Session.request at 0x7f92583e6940>
           └ <requests.sessions.Session object at 0x7f9124537250>
  File "/home/chase/.local/lib/python3.8/site-packages/requests/sessions.py", line 542, in request
    resp = self.send(prep, **send_kwargs)
           │    │    │       └ {'timeout': None, 'allow_redirects': True, 'verify': True, 'proxies': OrderedDict(), 'stream': False, 'cert': None}
           │    │    └ <PreparedRequest [POST]>
           │    └ <function Session.send at 0x7f92583e6dc0>
           └ <requests.sessions.Session object at 0x7f9124537250>
  File "/home/chase/.local/lib/python3.8/site-packages/requests/sessions.py", line 655, in send
    r = adapter.send(request, **kwargs)
        │       │    │          └ {'timeout': None, 'verify': True, 'proxies': OrderedDict(), 'stream': False, 'cert': None}
        │       │    └ <PreparedRequest [POST]>
        │       └ <function HTTPAdapter.send at 0x7f92583e6280>
        └ <requests.adapters.HTTPAdapter object at 0x7f91243e8e20>
  File "/home/chase/.local/lib/python3.8/site-packages/requests/adapters.py", line 516, in send
    raise ConnectionError(e, request=request)
          │                          └ <PreparedRequest [POST]>
          └ <class 'requests.exceptions.ConnectionError'>

requests.exceptions.ConnectionError: HTTPConnectionPool(host='search.people.cn', port=80): Max retries exceeded with url: /search-platform/front/search (Caused by NewConnectionError('<urllib3.connection.HTTPConnection object at 0x7f9253e5d520>: Failed to establish a new connection: [Errno 111] Connection refused'))
2022-05-12 15:46:46.922 | ERROR    | monitor.searchSpiders.people:get_request_from_keyword:45 - E 人民网错误HTTPConnectionPool(host='search.people.cn', port=80): Max retries exceeded with url: /search-platform/front/search (Caused by NewConnectionError('<urllib3.connection.HTTPConnection object at 0x7f91603a45b0>: Failed to establish a new connection: [Errno 111] Connection refused'))
Traceback (most recent call last):

  File "/home/chase/.local/lib/python3.8/site-packages/urllib3/connection.py", line 174, in _new_conn
    conn = connection.create_connection(
           │          └ <function create_connection at 0x7f92585fd1f0>
           └ <module 'urllib3.util.connection' from '/home/chase/.local/lib/python3.8/site-packages/urllib3/util/connection.py'>
  File "/home/chase/.local/lib/python3.8/site-packages/urllib3/util/connection.py", line 96, in create_connection
    raise err
          └ ConnectionRefusedError(111, 'Connection refused')
  File "/home/chase/.local/lib/python3.8/site-packages/urllib3/util/connection.py", line 86, in create_connection
    sock.connect(sa)
    │            └ ('118.212.233.249', 80)
    └ None

ConnectionRefusedError: [Errno 111] Connection refused


During handling of the above exception, another exception occurred:


Traceback (most recent call last):

  File "/home/chase/.local/lib/python3.8/site-packages/urllib3/connectionpool.py", line 699, in urlopen
    httplib_response = self._make_request(
                       │    └ <function HTTPConnectionPool._make_request at 0x7f92585c05e0>
                       └ <urllib3.connectionpool.HTTPConnectionPool object at 0x7f91483814f0>
  File "/home/chase/.local/lib/python3.8/site-packages/urllib3/connectionpool.py", line 394, in _make_request
    conn.request(method, url, **httplib_request_kw)
    │    │       │       │      └ {'body': b'{"key": "\\u5e94\\u5bf9\\u6c14\\u5019\\u53d8\\u5316\\uff0c\\u4e2d\\u56fd\\u91cd\\u4fe1\\u5b88\\u8bfa\\uff08\\u56fd...
    │    │       │       └ '/search-platform/front/search'
    │    │       └ 'POST'
    │    └ <function HTTPConnection.request at 0x7f92585b0f70>
    └ <urllib3.connection.HTTPConnection object at 0x7f91603a45b0>
  File "/home/chase/.local/lib/python3.8/site-packages/urllib3/connection.py", line 239, in request
    super(HTTPConnection, self).request(method, url, body=body, headers=headers)
          │               │             │       │         │             └ {'User-Agent': 'Mozilla/5.0 (Windows NT 10.0; Win64; x64) AppleWebKit/537.36 (KHTML, like Gecko) Chrome/101.0.4951.54 Safari/...
          │               │             │       │         └ b'{"key": "\\u5e94\\u5bf9\\u6c14\\u5019\\u53d8\\u5316\\uff0c\\u4e2d\\u56fd\\u91cd\\u4fe1\\u5b88\\u8bfa\\uff08\\u56fd\\u9645\\...
          │               │             │       └ '/search-platform/front/search'
          │               │             └ 'POST'
          │               └ <urllib3.connection.HTTPConnection object at 0x7f91603a45b0>
          └ <class 'urllib3.connection.HTTPConnection'>
  File "/usr/lib/python3.8/http/client.py", line 1256, in request
    self._send_request(method, url, body, headers, encode_chunked)
    │    │             │       │    │     │        └ False
    │    │             │       │    │     └ {'User-Agent': 'Mozilla/5.0 (Windows NT 10.0; Win64; x64) AppleWebKit/537.36 (KHTML, like Gecko) Chrome/101.0.4951.54 Safari/...
    │    │             │       │    └ b'{"key": "\\u5e94\\u5bf9\\u6c14\\u5019\\u53d8\\u5316\\uff0c\\u4e2d\\u56fd\\u91cd\\u4fe1\\u5b88\\u8bfa\\uff08\\u56fd\\u9645\\...
    │    │             │       └ '/search-platform/front/search'
    │    │             └ 'POST'
    │    └ <function HTTPConnection._send_request at 0x7f926be50280>
    └ <urllib3.connection.HTTPConnection object at 0x7f91603a45b0>
  File "/usr/lib/python3.8/http/client.py", line 1302, in _send_request
    self.endheaders(body, encode_chunked=encode_chunked)
    │    │          │                    └ False
    │    │          └ b'{"key": "\\u5e94\\u5bf9\\u6c14\\u5019\\u53d8\\u5316\\uff0c\\u4e2d\\u56fd\\u91cd\\u4fe1\\u5b88\\u8bfa\\uff08\\u56fd\\u9645\\...
    │    └ <function HTTPConnection.endheaders at 0x7f926be50160>
    └ <urllib3.connection.HTTPConnection object at 0x7f91603a45b0>
  File "/usr/lib/python3.8/http/client.py", line 1251, in endheaders
    self._send_output(message_body, encode_chunked=encode_chunked)
    │    │            │                            └ False
    │    │            └ b'{"key": "\\u5e94\\u5bf9\\u6c14\\u5019\\u53d8\\u5316\\uff0c\\u4e2d\\u56fd\\u91cd\\u4fe1\\u5b88\\u8bfa\\uff08\\u56fd\\u9645\\...
    │    └ <function HTTPConnection._send_output at 0x7f926beb7d30>
    └ <urllib3.connection.HTTPConnection object at 0x7f91603a45b0>
  File "/usr/lib/python3.8/http/client.py", line 1011, in _send_output
    self.send(msg)
    │    │    └ b'POST /search-platform/front/search HTTP/1.1\r\nHost: search.people.cn\r\nUser-Agent: Mozilla/5.0 (Windows NT 10.0; Win64; x...
    │    └ <function HTTPConnection.send at 0x7f926beb7b80>
    └ <urllib3.connection.HTTPConnection object at 0x7f91603a45b0>
  File "/usr/lib/python3.8/http/client.py", line 951, in send
    self.connect()
    │    └ <function HTTPConnection.connect at 0x7f92585b0dc0>
    └ <urllib3.connection.HTTPConnection object at 0x7f91603a45b0>
  File "/home/chase/.local/lib/python3.8/site-packages/urllib3/connection.py", line 205, in connect
    conn = self._new_conn()
           │    └ <function HTTPConnection._new_conn at 0x7f92585b0c10>
           └ <urllib3.connection.HTTPConnection object at 0x7f91603a45b0>
  File "/home/chase/.local/lib/python3.8/site-packages/urllib3/connection.py", line 186, in _new_conn
    raise NewConnectionError(
          └ <class 'urllib3.exceptions.NewConnectionError'>

urllib3.exceptions.NewConnectionError: <urllib3.connection.HTTPConnection object at 0x7f91603a45b0>: Failed to establish a new connection: [Errno 111] Connection refused


During handling of the above exception, another exception occurred:


Traceback (most recent call last):

  File "/home/chase/.local/lib/python3.8/site-packages/requests/adapters.py", line 439, in send
    resp = conn.urlopen(
           │    └ <function HTTPConnectionPool.urlopen at 0x7f92585c0820>
           └ <urllib3.connectionpool.HTTPConnectionPool object at 0x7f91483814f0>
  File "/home/chase/.local/lib/python3.8/site-packages/urllib3/connectionpool.py", line 755, in urlopen
    retries = retries.increment(
              │       └ <function Retry.increment at 0x7f9258608b80>
              └ Retry(total=0, connect=None, read=False, redirect=None, status=None)
  File "/home/chase/.local/lib/python3.8/site-packages/urllib3/util/retry.py", line 574, in increment
    raise MaxRetryError(_pool, url, error or ResponseError(cause))
          │             │      │    │        │             └ 'unknown'
          │             │      │    │        └ <class 'urllib3.exceptions.ResponseError'>
          │             │      │    └ NewConnectionError('<urllib3.connection.HTTPConnection object at 0x7f91603a45b0>: Failed to establish a new connection: [Errn...
          │             │      └ '/search-platform/front/search'
          │             └ <urllib3.connectionpool.HTTPConnectionPool object at 0x7f91483814f0>
          └ <class 'urllib3.exceptions.MaxRetryError'>

urllib3.exceptions.MaxRetryError: HTTPConnectionPool(host='search.people.cn', port=80): Max retries exceeded with url: /search-platform/front/search (Caused by NewConnectionError('<urllib3.connection.HTTPConnection object at 0x7f91603a45b0>: Failed to establish a new connection: [Errno 111] Connection refused'))


During handling of the above exception, another exception occurred:


Traceback (most recent call last):

  File "/usr/lib/python3.8/threading.py", line 890, in _bootstrap
    self._bootstrap_inner()
    │    └ <function Thread._bootstrap_inner at 0x7f927a614a60>
    └ <Thread(Thread-175, started daemon 140259757102848)>
  File "/usr/lib/python3.8/threading.py", line 932, in _bootstrap_inner
    self.run()
    │    └ <function Thread.run at 0x7f927a614790>
    └ <Thread(Thread-175, started daemon 140259757102848)>
  File "/usr/lib/python3.8/threading.py", line 870, in run
    self._target(*self._args, **self._kwargs)
    │    │        │    │        │    └ {}
    │    │        │    │        └ <Thread(Thread-175, started daemon 140259757102848)>
    │    │        │    └ ('ProjectManager.run_func_by_thread',)
    │    │        └ <Thread(Thread-175, started daemon 140259757102848)>
    │    └ <bound method ProjectManager.get_request_from_keywords_hot of <monitor.projectManager.ProjectManager object at 0x7f9162af4700>>
    └ <Thread(Thread-175, started daemon 140259757102848)>

  File "/home/users/Scy/yuqing/spider/monitor/projectManager.py", line 795, in get_request_from_keywords_hot
    self.search_spider_manager.crawl_by_keyword(
    │    │                     └ <function SearchSpidersManager.crawl_by_keyword at 0x7f9162b00040>
    │    └ <monitor.spiderManager.SearchSpidersManager object at 0x7f916270f0d0>
    └ <monitor.projectManager.ProjectManager object at 0x7f9162af4700>

  File "/home/users/Scy/yuqing/spider/monitor/spiderManager.py", line 118, in crawl_by_keyword
    self.crawl_by_keyword_signal_platform(project_names, platform, keyword, crawl_time, project_times)
    │    │                                │              │         │        │           └ {'default': <monitor.TimeSection object at 0x7f91628317f0>}
    │    │                                │              │         │        └ <monitor.TimeSection object at 0x7f91480a4040>
    │    │                                │              │         └ '应对气候变化，中国重信守诺（国际论坛）'
    │    │                                │              └ '人民网'
    │    │                                └ ['default']
    │    └ <function SearchSpidersManager.crawl_by_keyword_signal_platform at 0x7f9162b000d0>
    └ <monitor.spiderManager.SearchSpidersManager object at 0x7f916270f0d0>

  File "/home/users/Scy/yuqing/spider/monitor/spiderManager.py", line 134, in crawl_by_keyword_signal_platform
    requests = self.get_request_from_keyword(platform, keyword, **crawl_time.to_dict())
               │    │                        │         │          │          └ <function TimeSection.to_dict at 0x7f925aaa8550>
               │    │                        │         │          └ <monitor.TimeSection object at 0x7f91480a4040>
               │    │                        │         └ '应对气候变化，中国重信守诺（国际论坛）'
               │    │                        └ '人民网'
               │    └ <function SearchSpidersManager.get_request_from_keyword at 0x7f9162b001f0>
               └ <monitor.spiderManager.SearchSpidersManager object at 0x7f916270f0d0>

  File "/home/users/Scy/yuqing/spider/monitor/spiderManager.py", line 191, in get_request_from_keyword
    for request in self.spiders[platform].get_request_from_keyword(headers, search_url, keyword, content_url,
                   │    │       │                                  │        │           │        └ <string.Template object at 0x7f9148534580>
                   │    │       │                                  │        │           └ '应对气候变化，中国重信守诺（国际论坛）'
                   │    │       │                                  │        └ <string.Template object at 0x7f914815c160>
                   │    │       │                                  └ {'Accept': 'application/json, text/plain, */*', 'Accept-Language': 'zh-CN,zh;q=0.9', 'Connection': 'keep-alive', 'Origin': 'h...
                   │    │       └ '人民网'
                   │    └ {'凤凰网': <monitor.searchSpiders.ifeng.Ifeng object at 0x7f916270f220>, '头条': <monitor.searchSpiders.toutiao.Toutiao object at ...
                   └ <monitor.spiderManager.SearchSpidersManager object at 0x7f916270f0d0>

> File "/home/users/Scy/yuqing/spider/monitor/searchSpiders/people.py", line 28, in get_request_from_keyword
    response = requests.post(search_url.substitute(), json=data, headers=headers)
               │        │    │          │                  │             └ {'Accept': 'application/json, text/plain, */*', 'Accept-Language': 'zh-CN,zh;q=0.9', 'Connection': 'keep-alive', 'Origin': 'h...
               │        │    │          │                  └ {'key': '应对气候变化，中国重信守诺（国际论坛）', 'page': 1, 'limit': 10, 'hasTitle': True, 'hasContent': True, 'isFuzzy': True, 'type': 0, 'sor...
               │        │    │          └ <function Template.substitute at 0x7f927a5fd0d0>
               │        │    └ <string.Template object at 0x7f914815c160>
               │        └ <function post at 0x7f92583e73a0>
               └ <module 'requests' from '/home/chase/.local/lib/python3.8/site-packages/requests/__init__.py'>

  File "/home/chase/.local/lib/python3.8/site-packages/requests/api.py", line 117, in post
    return request('post', url, data=data, json=json, **kwargs)
           │               │         │          │       └ {'headers': {'Accept': 'application/json, text/plain, */*', 'Accept-Language': 'zh-CN,zh;q=0.9', 'Connection': 'keep-alive', ...
           │               │         │          └ {'key': '应对气候变化，中国重信守诺（国际论坛）', 'page': 1, 'limit': 10, 'hasTitle': True, 'hasContent': True, 'isFuzzy': True, 'type': 0, 'sor...
           │               │         └ None
           │               └ 'http://search.people.cn/search-platform/front/search'
           └ <function request at 0x7f9258455040>
  File "/home/chase/.local/lib/python3.8/site-packages/requests/api.py", line 61, in request
    return session.request(method=method, url=url, **kwargs)
           │       │              │           │      └ {'data': None, 'json': {'key': '应对气候变化，中国重信守诺（国际论坛）', 'page': 1, 'limit': 10, 'hasTitle': True, 'hasContent': True, 'isFuzzy'...
           │       │              │           └ 'http://search.people.cn/search-platform/front/search'
           │       │              └ 'post'
           │       └ <function Session.request at 0x7f92583e6940>
           └ <requests.sessions.Session object at 0x7f91600c3d60>
  File "/home/chase/.local/lib/python3.8/site-packages/requests/sessions.py", line 542, in request
    resp = self.send(prep, **send_kwargs)
           │    │    │       └ {'timeout': None, 'allow_redirects': True, 'verify': True, 'proxies': OrderedDict(), 'stream': False, 'cert': None}
           │    │    └ <PreparedRequest [POST]>
           │    └ <function Session.send at 0x7f92583e6dc0>
           └ <requests.sessions.Session object at 0x7f91600c3d60>
  File "/home/chase/.local/lib/python3.8/site-packages/requests/sessions.py", line 655, in send
    r = adapter.send(request, **kwargs)
        │       │    │          └ {'timeout': None, 'verify': True, 'proxies': OrderedDict(), 'stream': False, 'cert': None}
        │       │    └ <PreparedRequest [POST]>
        │       └ <function HTTPAdapter.send at 0x7f92583e6280>
        └ <requests.adapters.HTTPAdapter object at 0x7f91600c39a0>
  File "/home/chase/.local/lib/python3.8/site-packages/requests/adapters.py", line 516, in send
    raise ConnectionError(e, request=request)
          │                          └ <PreparedRequest [POST]>
          └ <class 'requests.exceptions.ConnectionError'>

requests.exceptions.ConnectionError: HTTPConnectionPool(host='search.people.cn', port=80): Max retries exceeded with url: /search-platform/front/search (Caused by NewConnectionError('<urllib3.connection.HTTPConnection object at 0x7f91603a45b0>: Failed to establish a new connection: [Errno 111] Connection refused'))
2022-05-12 15:46:47.386 | ERROR    | monitor.searchSpiders.people:get_request_from_keyword:45 - E 人民网错误HTTPConnectionPool(host='search.people.cn', port=80): Max retries exceeded with url: /search-platform/front/search (Caused by NewConnectionError('<urllib3.connection.HTTPConnection object at 0x7f9253dfc130>: Failed to establish a new connection: [Errno 111] Connection refused'))
Traceback (most recent call last):

  File "/home/chase/.local/lib/python3.8/site-packages/urllib3/connection.py", line 174, in _new_conn
    conn = connection.create_connection(
           │          └ <function create_connection at 0x7f92585fd1f0>
           └ <module 'urllib3.util.connection' from '/home/chase/.local/lib/python3.8/site-packages/urllib3/util/connection.py'>
  File "/home/chase/.local/lib/python3.8/site-packages/urllib3/util/connection.py", line 96, in create_connection
    raise err
          └ ConnectionRefusedError(111, 'Connection refused')
  File "/home/chase/.local/lib/python3.8/site-packages/urllib3/util/connection.py", line 86, in create_connection
    sock.connect(sa)
    │            └ ('118.212.233.249', 80)
    └ None

ConnectionRefusedError: [Errno 111] Connection refused


During handling of the above exception, another exception occurred:


Traceback (most recent call last):

  File "/home/chase/.local/lib/python3.8/site-packages/urllib3/connectionpool.py", line 699, in urlopen
    httplib_response = self._make_request(
                       │    └ <function HTTPConnectionPool._make_request at 0x7f92585c05e0>
                       └ <urllib3.connectionpool.HTTPConnectionPool object at 0x7f91602518e0>
  File "/home/chase/.local/lib/python3.8/site-packages/urllib3/connectionpool.py", line 394, in _make_request
    conn.request(method, url, **httplib_request_kw)
    │    │       │       │      └ {'body': b'{"key": "\\u672a\\u6765\\u4e94\\u5e74\\u5168\\u7403\\u8f83\\u5de5\\u4e1a\\u5316\\u524d\\u5347\\u6e29\\u4e00\\u70b9...
    │    │       │       └ '/search-platform/front/search'
    │    │       └ 'POST'
    │    └ <function HTTPConnection.request at 0x7f92585b0f70>
    └ <urllib3.connection.HTTPConnection object at 0x7f9253dfc130>
  File "/home/chase/.local/lib/python3.8/site-packages/urllib3/connection.py", line 239, in request
    super(HTTPConnection, self).request(method, url, body=body, headers=headers)
          │               │             │       │         │             └ {'User-Agent': 'Mozilla/5.0 (Windows NT 10.0; Win64; x64) AppleWebKit/537.36 (KHTML, like Gecko) Chrome/101.0.4951.54 Safari/...
          │               │             │       │         └ b'{"key": "\\u672a\\u6765\\u4e94\\u5e74\\u5168\\u7403\\u8f83\\u5de5\\u4e1a\\u5316\\u524d\\u5347\\u6e29\\u4e00\\u70b9\\u4e94\\...
          │               │             │       └ '/search-platform/front/search'
          │               │             └ 'POST'
          │               └ <urllib3.connection.HTTPConnection object at 0x7f9253dfc130>
          └ <class 'urllib3.connection.HTTPConnection'>
  File "/usr/lib/python3.8/http/client.py", line 1256, in request
    self._send_request(method, url, body, headers, encode_chunked)
    │    │             │       │    │     │        └ False
    │    │             │       │    │     └ {'User-Agent': 'Mozilla/5.0 (Windows NT 10.0; Win64; x64) AppleWebKit/537.36 (KHTML, like Gecko) Chrome/101.0.4951.54 Safari/...
    │    │             │       │    └ b'{"key": "\\u672a\\u6765\\u4e94\\u5e74\\u5168\\u7403\\u8f83\\u5de5\\u4e1a\\u5316\\u524d\\u5347\\u6e29\\u4e00\\u70b9\\u4e94\\...
    │    │             │       └ '/search-platform/front/search'
    │    │             └ 'POST'
    │    └ <function HTTPConnection._send_request at 0x7f926be50280>
    └ <urllib3.connection.HTTPConnection object at 0x7f9253dfc130>
  File "/usr/lib/python3.8/http/client.py", line 1302, in _send_request
    self.endheaders(body, encode_chunked=encode_chunked)
    │    │          │                    └ False
    │    │          └ b'{"key": "\\u672a\\u6765\\u4e94\\u5e74\\u5168\\u7403\\u8f83\\u5de5\\u4e1a\\u5316\\u524d\\u5347\\u6e29\\u4e00\\u70b9\\u4e94\\...
    │    └ <function HTTPConnection.endheaders at 0x7f926be50160>
    └ <urllib3.connection.HTTPConnection object at 0x7f9253dfc130>
  File "/usr/lib/python3.8/http/client.py", line 1251, in endheaders
    self._send_output(message_body, encode_chunked=encode_chunked)
    │    │            │                            └ False
    │    │            └ b'{"key": "\\u672a\\u6765\\u4e94\\u5e74\\u5168\\u7403\\u8f83\\u5de5\\u4e1a\\u5316\\u524d\\u5347\\u6e29\\u4e00\\u70b9\\u4e94\\...
    │    └ <function HTTPConnection._send_output at 0x7f926beb7d30>
    └ <urllib3.connection.HTTPConnection object at 0x7f9253dfc130>
  File "/usr/lib/python3.8/http/client.py", line 1011, in _send_output
    self.send(msg)
    │    │    └ b'POST /search-platform/front/search HTTP/1.1\r\nHost: search.people.cn\r\nUser-Agent: Mozilla/5.0 (Windows NT 10.0; Win64; x...
    │    └ <function HTTPConnection.send at 0x7f926beb7b80>
    └ <urllib3.connection.HTTPConnection object at 0x7f9253dfc130>
  File "/usr/lib/python3.8/http/client.py", line 951, in send
    self.connect()
    │    └ <function HTTPConnection.connect at 0x7f92585b0dc0>
    └ <urllib3.connection.HTTPConnection object at 0x7f9253dfc130>
  File "/home/chase/.local/lib/python3.8/site-packages/urllib3/connection.py", line 205, in connect
    conn = self._new_conn()
           │    └ <function HTTPConnection._new_conn at 0x7f92585b0c10>
           └ <urllib3.connection.HTTPConnection object at 0x7f9253dfc130>
  File "/home/chase/.local/lib/python3.8/site-packages/urllib3/connection.py", line 186, in _new_conn
    raise NewConnectionError(
          └ <class 'urllib3.exceptions.NewConnectionError'>

urllib3.exceptions.NewConnectionError: <urllib3.connection.HTTPConnection object at 0x7f9253dfc130>: Failed to establish a new connection: [Errno 111] Connection refused


During handling of the above exception, another exception occurred:


Traceback (most recent call last):

  File "/home/chase/.local/lib/python3.8/site-packages/requests/adapters.py", line 439, in send
    resp = conn.urlopen(
           │    └ <function HTTPConnectionPool.urlopen at 0x7f92585c0820>
           └ <urllib3.connectionpool.HTTPConnectionPool object at 0x7f91602518e0>
  File "/home/chase/.local/lib/python3.8/site-packages/urllib3/connectionpool.py", line 755, in urlopen
    retries = retries.increment(
              │       └ <function Retry.increment at 0x7f9258608b80>
              └ Retry(total=0, connect=None, read=False, redirect=None, status=None)
  File "/home/chase/.local/lib/python3.8/site-packages/urllib3/util/retry.py", line 574, in increment
    raise MaxRetryError(_pool, url, error or ResponseError(cause))
          │             │      │    │        │             └ 'unknown'
          │             │      │    │        └ <class 'urllib3.exceptions.ResponseError'>
          │             │      │    └ NewConnectionError('<urllib3.connection.HTTPConnection object at 0x7f9253dfc130>: Failed to establish a new connection: [Errn...
          │             │      └ '/search-platform/front/search'
          │             └ <urllib3.connectionpool.HTTPConnectionPool object at 0x7f91602518e0>
          └ <class 'urllib3.exceptions.MaxRetryError'>

urllib3.exceptions.MaxRetryError: HTTPConnectionPool(host='search.people.cn', port=80): Max retries exceeded with url: /search-platform/front/search (Caused by NewConnectionError('<urllib3.connection.HTTPConnection object at 0x7f9253dfc130>: Failed to establish a new connection: [Errno 111] Connection refused'))


During handling of the above exception, another exception occurred:


Traceback (most recent call last):

  File "/usr/lib/python3.8/threading.py", line 890, in _bootstrap
    self._bootstrap_inner()
    │    └ <function Thread._bootstrap_inner at 0x7f927a614a60>
    └ <Thread(Thread-152, started daemon 140259799066368)>
  File "/usr/lib/python3.8/threading.py", line 932, in _bootstrap_inner
    self.run()
    │    └ <function Thread.run at 0x7f927a614790>
    └ <Thread(Thread-152, started daemon 140259799066368)>
  File "/usr/lib/python3.8/threading.py", line 870, in run
    self._target(*self._args, **self._kwargs)
    │    │        │    │        │    └ {}
    │    │        │    │        └ <Thread(Thread-152, started daemon 140259799066368)>
    │    │        │    └ ('ProjectManager.run_func_by_thread',)
    │    │        └ <Thread(Thread-152, started daemon 140259799066368)>
    │    └ <bound method ProjectManager.get_request_from_keywords_hot of <monitor.projectManager.ProjectManager object at 0x7f9162af4700>>
    └ <Thread(Thread-152, started daemon 140259799066368)>

  File "/home/users/Scy/yuqing/spider/monitor/projectManager.py", line 795, in get_request_from_keywords_hot
    self.search_spider_manager.crawl_by_keyword(
    │    │                     └ <function SearchSpidersManager.crawl_by_keyword at 0x7f9162b00040>
    │    └ <monitor.spiderManager.SearchSpidersManager object at 0x7f916270f0d0>
    └ <monitor.projectManager.ProjectManager object at 0x7f9162af4700>

  File "/home/users/Scy/yuqing/spider/monitor/spiderManager.py", line 118, in crawl_by_keyword
    self.crawl_by_keyword_signal_platform(project_names, platform, keyword, crawl_time, project_times)
    │    │                                │              │         │        │           └ {'default': <monitor.TimeSection object at 0x7f91628317f0>}
    │    │                                │              │         │        └ <monitor.TimeSection object at 0x7f916012db50>
    │    │                                │              │         └ '未来五年全球较工业化前升温一点五度概率近半'
    │    │                                │              └ '人民网'
    │    │                                └ ['default']
    │    └ <function SearchSpidersManager.crawl_by_keyword_signal_platform at 0x7f9162b000d0>
    └ <monitor.spiderManager.SearchSpidersManager object at 0x7f916270f0d0>

  File "/home/users/Scy/yuqing/spider/monitor/spiderManager.py", line 134, in crawl_by_keyword_signal_platform
    requests = self.get_request_from_keyword(platform, keyword, **crawl_time.to_dict())
               │    │                        │         │          │          └ <function TimeSection.to_dict at 0x7f925aaa8550>
               │    │                        │         │          └ <monitor.TimeSection object at 0x7f916012db50>
               │    │                        │         └ '未来五年全球较工业化前升温一点五度概率近半'
               │    │                        └ '人民网'
               │    └ <function SearchSpidersManager.get_request_from_keyword at 0x7f9162b001f0>
               └ <monitor.spiderManager.SearchSpidersManager object at 0x7f916270f0d0>

  File "/home/users/Scy/yuqing/spider/monitor/spiderManager.py", line 191, in get_request_from_keyword
    for request in self.spiders[platform].get_request_from_keyword(headers, search_url, keyword, content_url,
                   │    │       │                                  │        │           │        └ <string.Template object at 0x7f91600c3970>
                   │    │       │                                  │        │           └ '未来五年全球较工业化前升温一点五度概率近半'
                   │    │       │                                  │        └ <string.Template object at 0x7f91601394c0>
                   │    │       │                                  └ {'Accept': 'application/json, text/plain, */*', 'Accept-Language': 'zh-CN,zh;q=0.9', 'Connection': 'keep-alive', 'Origin': 'h...
                   │    │       └ '人民网'
                   │    └ {'凤凰网': <monitor.searchSpiders.ifeng.Ifeng object at 0x7f916270f220>, '头条': <monitor.searchSpiders.toutiao.Toutiao object at ...
                   └ <monitor.spiderManager.SearchSpidersManager object at 0x7f916270f0d0>

> File "/home/users/Scy/yuqing/spider/monitor/searchSpiders/people.py", line 28, in get_request_from_keyword
    response = requests.post(search_url.substitute(), json=data, headers=headers)
               │        │    │          │                  │             └ {'Accept': 'application/json, text/plain, */*', 'Accept-Language': 'zh-CN,zh;q=0.9', 'Connection': 'keep-alive', 'Origin': 'h...
               │        │    │          │                  └ {'key': '未来五年全球较工业化前升温一点五度概率近半', 'page': 1, 'limit': 10, 'hasTitle': True, 'hasContent': True, 'isFuzzy': True, 'type': 0, 's...
               │        │    │          └ <function Template.substitute at 0x7f927a5fd0d0>
               │        │    └ <string.Template object at 0x7f91601394c0>
               │        └ <function post at 0x7f92583e73a0>
               └ <module 'requests' from '/home/chase/.local/lib/python3.8/site-packages/requests/__init__.py'>

  File "/home/chase/.local/lib/python3.8/site-packages/requests/api.py", line 117, in post
    return request('post', url, data=data, json=json, **kwargs)
           │               │         │          │       └ {'headers': {'Accept': 'application/json, text/plain, */*', 'Accept-Language': 'zh-CN,zh;q=0.9', 'Connection': 'keep-alive', ...
           │               │         │          └ {'key': '未来五年全球较工业化前升温一点五度概率近半', 'page': 1, 'limit': 10, 'hasTitle': True, 'hasContent': True, 'isFuzzy': True, 'type': 0, 's...
           │               │         └ None
           │               └ 'http://search.people.cn/search-platform/front/search'
           └ <function request at 0x7f9258455040>
  File "/home/chase/.local/lib/python3.8/site-packages/requests/api.py", line 61, in request
    return session.request(method=method, url=url, **kwargs)
           │       │              │           │      └ {'data': None, 'json': {'key': '未来五年全球较工业化前升温一点五度概率近半', 'page': 1, 'limit': 10, 'hasTitle': True, 'hasContent': True, 'isFuzz...
           │       │              │           └ 'http://search.people.cn/search-platform/front/search'
           │       │              └ 'post'
           │       └ <function Session.request at 0x7f92583e6940>
           └ <requests.sessions.Session object at 0x7f91485ef250>
  File "/home/chase/.local/lib/python3.8/site-packages/requests/sessions.py", line 542, in request
    resp = self.send(prep, **send_kwargs)
           │    │    │       └ {'timeout': None, 'allow_redirects': True, 'verify': True, 'proxies': OrderedDict(), 'stream': False, 'cert': None}
           │    │    └ <PreparedRequest [POST]>
           │    └ <function Session.send at 0x7f92583e6dc0>
           └ <requests.sessions.Session object at 0x7f91485ef250>
  File "/home/chase/.local/lib/python3.8/site-packages/requests/sessions.py", line 655, in send
    r = adapter.send(request, **kwargs)
        │       │    │          └ {'timeout': None, 'verify': True, 'proxies': OrderedDict(), 'stream': False, 'cert': None}
        │       │    └ <PreparedRequest [POST]>
        │       └ <function HTTPAdapter.send at 0x7f92583e6280>
        └ <requests.adapters.HTTPAdapter object at 0x7f9160250070>
  File "/home/chase/.local/lib/python3.8/site-packages/requests/adapters.py", line 516, in send
    raise ConnectionError(e, request=request)
          │                          └ <PreparedRequest [POST]>
          └ <class 'requests.exceptions.ConnectionError'>

requests.exceptions.ConnectionError: HTTPConnectionPool(host='search.people.cn', port=80): Max retries exceeded with url: /search-platform/front/search (Caused by NewConnectionError('<urllib3.connection.HTTPConnection object at 0x7f9253dfc130>: Failed to establish a new connection: [Errno 111] Connection refused'))
2022-05-12 15:46:47.916 | ERROR    | monitor.searchSpiders.people:get_request_from_keyword:45 - E 人民网错误HTTPConnectionPool(host='search.people.cn', port=80): Max retries exceeded with url: /search-platform/front/search (Caused by NewConnectionError('<urllib3.connection.HTTPConnection object at 0x7f91042568e0>: Failed to establish a new connection: [Errno 111] Connection refused'))
Traceback (most recent call last):

  File "/home/chase/.local/lib/python3.8/site-packages/urllib3/connection.py", line 174, in _new_conn
    conn = connection.create_connection(
           │          └ <function create_connection at 0x7f92585fd1f0>
           └ <module 'urllib3.util.connection' from '/home/chase/.local/lib/python3.8/site-packages/urllib3/util/connection.py'>
  File "/home/chase/.local/lib/python3.8/site-packages/urllib3/util/connection.py", line 96, in create_connection
    raise err
          └ ConnectionRefusedError(111, 'Connection refused')
  File "/home/chase/.local/lib/python3.8/site-packages/urllib3/util/connection.py", line 86, in create_connection
    sock.connect(sa)
    │            └ ('118.212.233.249', 80)
    └ None

ConnectionRefusedError: [Errno 111] Connection refused


During handling of the above exception, another exception occurred:


Traceback (most recent call last):

  File "/home/chase/.local/lib/python3.8/site-packages/urllib3/connectionpool.py", line 699, in urlopen
    httplib_response = self._make_request(
                       │    └ <function HTTPConnectionPool._make_request at 0x7f92585c05e0>
                       └ <urllib3.connectionpool.HTTPConnectionPool object at 0x7f91240a80a0>
  File "/home/chase/.local/lib/python3.8/site-packages/urllib3/connectionpool.py", line 394, in _make_request
    conn.request(method, url, **httplib_request_kw)
    │    │       │       │      └ {'body': b'{"key": "\\u57c3\\u53ca\\u5357\\u90e8\\u53d1\\u6398\\u51fa85\\u5ea7\\u53e4\\u4ee3\\u5893\\u846c", "page": 1, "limi...
    │    │       │       └ '/search-platform/front/search'
    │    │       └ 'POST'
    │    └ <function HTTPConnection.request at 0x7f92585b0f70>
    └ <urllib3.connection.HTTPConnection object at 0x7f91042568e0>
  File "/home/chase/.local/lib/python3.8/site-packages/urllib3/connection.py", line 239, in request
    super(HTTPConnection, self).request(method, url, body=body, headers=headers)
          │               │             │       │         │             └ {'User-Agent': 'Mozilla/5.0 (Windows NT 10.0; Win64; x64) AppleWebKit/537.36 (KHTML, like Gecko) Chrome/101.0.4951.54 Safari/...
          │               │             │       │         └ b'{"key": "\\u57c3\\u53ca\\u5357\\u90e8\\u53d1\\u6398\\u51fa85\\u5ea7\\u53e4\\u4ee3\\u5893\\u846c", "page": 1, "limit": 10, "...
          │               │             │       └ '/search-platform/front/search'
          │               │             └ 'POST'
          │               └ <urllib3.connection.HTTPConnection object at 0x7f91042568e0>
          └ <class 'urllib3.connection.HTTPConnection'>
  File "/usr/lib/python3.8/http/client.py", line 1256, in request
    self._send_request(method, url, body, headers, encode_chunked)
    │    │             │       │    │     │        └ False
    │    │             │       │    │     └ {'User-Agent': 'Mozilla/5.0 (Windows NT 10.0; Win64; x64) AppleWebKit/537.36 (KHTML, like Gecko) Chrome/101.0.4951.54 Safari/...
    │    │             │       │    └ b'{"key": "\\u57c3\\u53ca\\u5357\\u90e8\\u53d1\\u6398\\u51fa85\\u5ea7\\u53e4\\u4ee3\\u5893\\u846c", "page": 1, "limit": 10, "...
    │    │             │       └ '/search-platform/front/search'
    │    │             └ 'POST'
    │    └ <function HTTPConnection._send_request at 0x7f926be50280>
    └ <urllib3.connection.HTTPConnection object at 0x7f91042568e0>
  File "/usr/lib/python3.8/http/client.py", line 1302, in _send_request
    self.endheaders(body, encode_chunked=encode_chunked)
    │    │          │                    └ False
    │    │          └ b'{"key": "\\u57c3\\u53ca\\u5357\\u90e8\\u53d1\\u6398\\u51fa85\\u5ea7\\u53e4\\u4ee3\\u5893\\u846c", "page": 1, "limit": 10, "...
    │    └ <function HTTPConnection.endheaders at 0x7f926be50160>
    └ <urllib3.connection.HTTPConnection object at 0x7f91042568e0>
  File "/usr/lib/python3.8/http/client.py", line 1251, in endheaders
    self._send_output(message_body, encode_chunked=encode_chunked)
    │    │            │                            └ False
    │    │            └ b'{"key": "\\u57c3\\u53ca\\u5357\\u90e8\\u53d1\\u6398\\u51fa85\\u5ea7\\u53e4\\u4ee3\\u5893\\u846c", "page": 1, "limit": 10, "...
    │    └ <function HTTPConnection._send_output at 0x7f926beb7d30>
    └ <urllib3.connection.HTTPConnection object at 0x7f91042568e0>
  File "/usr/lib/python3.8/http/client.py", line 1011, in _send_output
    self.send(msg)
    │    │    └ b'POST /search-platform/front/search HTTP/1.1\r\nHost: search.people.cn\r\nUser-Agent: Mozilla/5.0 (Windows NT 10.0; Win64; x...
    │    └ <function HTTPConnection.send at 0x7f926beb7b80>
    └ <urllib3.connection.HTTPConnection object at 0x7f91042568e0>
  File "/usr/lib/python3.8/http/client.py", line 951, in send
    self.connect()
    │    └ <function HTTPConnection.connect at 0x7f92585b0dc0>
    └ <urllib3.connection.HTTPConnection object at 0x7f91042568e0>
  File "/home/chase/.local/lib/python3.8/site-packages/urllib3/connection.py", line 205, in connect
    conn = self._new_conn()
           │    └ <function HTTPConnection._new_conn at 0x7f92585b0c10>
           └ <urllib3.connection.HTTPConnection object at 0x7f91042568e0>
  File "/home/chase/.local/lib/python3.8/site-packages/urllib3/connection.py", line 186, in _new_conn
    raise NewConnectionError(
          └ <class 'urllib3.exceptions.NewConnectionError'>

urllib3.exceptions.NewConnectionError: <urllib3.connection.HTTPConnection object at 0x7f91042568e0>: Failed to establish a new connection: [Errno 111] Connection refused


During handling of the above exception, another exception occurred:


Traceback (most recent call last):

  File "/home/chase/.local/lib/python3.8/site-packages/requests/adapters.py", line 439, in send
    resp = conn.urlopen(
           │    └ <function HTTPConnectionPool.urlopen at 0x7f92585c0820>
           └ <urllib3.connectionpool.HTTPConnectionPool object at 0x7f91240a80a0>
  File "/home/chase/.local/lib/python3.8/site-packages/urllib3/connectionpool.py", line 755, in urlopen
    retries = retries.increment(
              │       └ <function Retry.increment at 0x7f9258608b80>
              └ Retry(total=0, connect=None, read=False, redirect=None, status=None)
  File "/home/chase/.local/lib/python3.8/site-packages/urllib3/util/retry.py", line 574, in increment
    raise MaxRetryError(_pool, url, error or ResponseError(cause))
          │             │      │    │        │             └ 'unknown'
          │             │      │    │        └ <class 'urllib3.exceptions.ResponseError'>
          │             │      │    └ NewConnectionError('<urllib3.connection.HTTPConnection object at 0x7f91042568e0>: Failed to establish a new connection: [Errn...
          │             │      └ '/search-platform/front/search'
          │             └ <urllib3.connectionpool.HTTPConnectionPool object at 0x7f91240a80a0>
          └ <class 'urllib3.exceptions.MaxRetryError'>

urllib3.exceptions.MaxRetryError: HTTPConnectionPool(host='search.people.cn', port=80): Max retries exceeded with url: /search-platform/front/search (Caused by NewConnectionError('<urllib3.connection.HTTPConnection object at 0x7f91042568e0>: Failed to establish a new connection: [Errno 111] Connection refused'))


During handling of the above exception, another exception occurred:


Traceback (most recent call last):

  File "/usr/lib/python3.8/threading.py", line 890, in _bootstrap
    self._bootstrap_inner()
    │    └ <function Thread._bootstrap_inner at 0x7f927a614a60>
    └ <Thread(Thread-166, started daemon 140259765495552)>
  File "/usr/lib/python3.8/threading.py", line 932, in _bootstrap_inner
    self.run()
    │    └ <function Thread.run at 0x7f927a614790>
    └ <Thread(Thread-166, started daemon 140259765495552)>
  File "/usr/lib/python3.8/threading.py", line 870, in run
    self._target(*self._args, **self._kwargs)
    │    │        │    │        │    └ {}
    │    │        │    │        └ <Thread(Thread-166, started daemon 140259765495552)>
    │    │        │    └ ('ProjectManager.run_func_by_thread',)
    │    │        └ <Thread(Thread-166, started daemon 140259765495552)>
    │    └ <bound method ProjectManager.get_request_from_keywords_hot of <monitor.projectManager.ProjectManager object at 0x7f9162af4700>>
    └ <Thread(Thread-166, started daemon 140259765495552)>

  File "/home/users/Scy/yuqing/spider/monitor/projectManager.py", line 795, in get_request_from_keywords_hot
    self.search_spider_manager.crawl_by_keyword(
    │    │                     └ <function SearchSpidersManager.crawl_by_keyword at 0x7f9162b00040>
    │    └ <monitor.spiderManager.SearchSpidersManager object at 0x7f916270f0d0>
    └ <monitor.projectManager.ProjectManager object at 0x7f9162af4700>

  File "/home/users/Scy/yuqing/spider/monitor/spiderManager.py", line 118, in crawl_by_keyword
    self.crawl_by_keyword_signal_platform(project_names, platform, keyword, crawl_time, project_times)
    │    │                                │              │         │        │           └ {'default': <monitor.TimeSection object at 0x7f91628317f0>}
    │    │                                │              │         │        └ <monitor.TimeSection object at 0x7f9148503e20>
    │    │                                │              │         └ '埃及南部发掘出85座古代墓葬'
    │    │                                │              └ '人民网'
    │    │                                └ ['default']
    │    └ <function SearchSpidersManager.crawl_by_keyword_signal_platform at 0x7f9162b000d0>
    └ <monitor.spiderManager.SearchSpidersManager object at 0x7f916270f0d0>

  File "/home/users/Scy/yuqing/spider/monitor/spiderManager.py", line 134, in crawl_by_keyword_signal_platform
    requests = self.get_request_from_keyword(platform, keyword, **crawl_time.to_dict())
               │    │                        │         │          │          └ <function TimeSection.to_dict at 0x7f925aaa8550>
               │    │                        │         │          └ <monitor.TimeSection object at 0x7f9148503e20>
               │    │                        │         └ '埃及南部发掘出85座古代墓葬'
               │    │                        └ '人民网'
               │    └ <function SearchSpidersManager.get_request_from_keyword at 0x7f9162b001f0>
               └ <monitor.spiderManager.SearchSpidersManager object at 0x7f916270f0d0>

  File "/home/users/Scy/yuqing/spider/monitor/spiderManager.py", line 191, in get_request_from_keyword
    for request in self.spiders[platform].get_request_from_keyword(headers, search_url, keyword, content_url,
                   │    │       │                                  │        │           │        └ <string.Template object at 0x7f91247e75b0>
                   │    │       │                                  │        │           └ '埃及南部发掘出85座古代墓葬'
                   │    │       │                                  │        └ <string.Template object at 0x7f9148209220>
                   │    │       │                                  └ {'Accept': 'application/json, text/plain, */*', 'Accept-Language': 'zh-CN,zh;q=0.9', 'Connection': 'keep-alive', 'Origin': 'h...
                   │    │       └ '人民网'
                   │    └ {'凤凰网': <monitor.searchSpiders.ifeng.Ifeng object at 0x7f916270f220>, '头条': <monitor.searchSpiders.toutiao.Toutiao object at ...
                   └ <monitor.spiderManager.SearchSpidersManager object at 0x7f916270f0d0>

> File "/home/users/Scy/yuqing/spider/monitor/searchSpiders/people.py", line 28, in get_request_from_keyword
    response = requests.post(search_url.substitute(), json=data, headers=headers)
               │        │    │          │                  │             └ {'Accept': 'application/json, text/plain, */*', 'Accept-Language': 'zh-CN,zh;q=0.9', 'Connection': 'keep-alive', 'Origin': 'h...
               │        │    │          │                  └ {'key': '埃及南部发掘出85座古代墓葬', 'page': 1, 'limit': 10, 'hasTitle': True, 'hasContent': True, 'isFuzzy': True, 'type': 0, 'sortType...
               │        │    │          └ <function Template.substitute at 0x7f927a5fd0d0>
               │        │    └ <string.Template object at 0x7f9148209220>
               │        └ <function post at 0x7f92583e73a0>
               └ <module 'requests' from '/home/chase/.local/lib/python3.8/site-packages/requests/__init__.py'>

  File "/home/chase/.local/lib/python3.8/site-packages/requests/api.py", line 117, in post
    return request('post', url, data=data, json=json, **kwargs)
           │               │         │          │       └ {'headers': {'Accept': 'application/json, text/plain, */*', 'Accept-Language': 'zh-CN,zh;q=0.9', 'Connection': 'keep-alive', ...
           │               │         │          └ {'key': '埃及南部发掘出85座古代墓葬', 'page': 1, 'limit': 10, 'hasTitle': True, 'hasContent': True, 'isFuzzy': True, 'type': 0, 'sortType...
           │               │         └ None
           │               └ 'http://search.people.cn/search-platform/front/search'
           └ <function request at 0x7f9258455040>
  File "/home/chase/.local/lib/python3.8/site-packages/requests/api.py", line 61, in request
    return session.request(method=method, url=url, **kwargs)
           │       │              │           │      └ {'data': None, 'json': {'key': '埃及南部发掘出85座古代墓葬', 'page': 1, 'limit': 10, 'hasTitle': True, 'hasContent': True, 'isFuzzy': Tru...
           │       │              │           └ 'http://search.people.cn/search-platform/front/search'
           │       │              └ 'post'
           │       └ <function Session.request at 0x7f92583e6940>
           └ <requests.sessions.Session object at 0x7f9148232310>
  File "/home/chase/.local/lib/python3.8/site-packages/requests/sessions.py", line 542, in request
    resp = self.send(prep, **send_kwargs)
           │    │    │       └ {'timeout': None, 'allow_redirects': True, 'verify': True, 'proxies': OrderedDict(), 'stream': False, 'cert': None}
           │    │    └ <PreparedRequest [POST]>
           │    └ <function Session.send at 0x7f92583e6dc0>
           └ <requests.sessions.Session object at 0x7f9148232310>
  File "/home/chase/.local/lib/python3.8/site-packages/requests/sessions.py", line 655, in send
    r = adapter.send(request, **kwargs)
        │       │    │          └ {'timeout': None, 'verify': True, 'proxies': OrderedDict(), 'stream': False, 'cert': None}
        │       │    └ <PreparedRequest [POST]>
        │       └ <function HTTPAdapter.send at 0x7f92583e6280>
        └ <requests.adapters.HTTPAdapter object at 0x7f91482329d0>
  File "/home/chase/.local/lib/python3.8/site-packages/requests/adapters.py", line 516, in send
    raise ConnectionError(e, request=request)
          │                          └ <PreparedRequest [POST]>
          └ <class 'requests.exceptions.ConnectionError'>

requests.exceptions.ConnectionError: HTTPConnectionPool(host='search.people.cn', port=80): Max retries exceeded with url: /search-platform/front/search (Caused by NewConnectionError('<urllib3.connection.HTTPConnection object at 0x7f91042568e0>: Failed to establish a new connection: [Errno 111] Connection refused'))
2022-05-12 15:46:49.089 | ERROR    | monitor.searchSpiders.people:get_request_from_keyword:45 - E 人民网错误HTTPConnectionPool(host='search.people.cn', port=80): Max retries exceeded with url: /search-platform/front/search (Caused by NewConnectionError('<urllib3.connection.HTTPConnection object at 0x7f9124506e20>: Failed to establish a new connection: [Errno 111] Connection refused'))
Traceback (most recent call last):

  File "/home/chase/.local/lib/python3.8/site-packages/urllib3/connection.py", line 174, in _new_conn
    conn = connection.create_connection(
           │          └ <function create_connection at 0x7f92585fd1f0>
           └ <module 'urllib3.util.connection' from '/home/chase/.local/lib/python3.8/site-packages/urllib3/util/connection.py'>
  File "/home/chase/.local/lib/python3.8/site-packages/urllib3/util/connection.py", line 96, in create_connection
    raise err
          └ ConnectionRefusedError(111, 'Connection refused')
  File "/home/chase/.local/lib/python3.8/site-packages/urllib3/util/connection.py", line 86, in create_connection
    sock.connect(sa)
    │            └ ('118.212.233.249', 80)
    └ None

ConnectionRefusedError: [Errno 111] Connection refused


During handling of the above exception, another exception occurred:


Traceback (most recent call last):

  File "/home/chase/.local/lib/python3.8/site-packages/urllib3/connectionpool.py", line 699, in urlopen
    httplib_response = self._make_request(
                       │    └ <function HTTPConnectionPool._make_request at 0x7f92585c05e0>
                       └ <urllib3.connectionpool.HTTPConnectionPool object at 0x7f9253ebd280>
  File "/home/chase/.local/lib/python3.8/site-packages/urllib3/connectionpool.py", line 394, in _make_request
    conn.request(method, url, **httplib_request_kw)
    │    │       │       │      └ {'body': b'{"key": "\\u4e1c\\u90e8\\u6218\\u533a\\u7ec4\\u7ec7\\u5175\\u529b\\u5728\\u53f0\\u5c9b\\u4ee5\\u4e1c\\u548c\\u897f...
    │    │       │       └ '/search-platform/front/search'
    │    │       └ 'POST'
    │    └ <function HTTPConnection.request at 0x7f92585b0f70>
    └ <urllib3.connection.HTTPConnection object at 0x7f9124506e20>
  File "/home/chase/.local/lib/python3.8/site-packages/urllib3/connection.py", line 239, in request
    super(HTTPConnection, self).request(method, url, body=body, headers=headers)
          │               │             │       │         │             └ {'User-Agent': 'Mozilla/5.0 (Windows NT 10.0; Win64; x64) AppleWebKit/537.36 (KHTML, like Gecko) Chrome/101.0.4951.54 Safari/...
          │               │             │       │         └ b'{"key": "\\u4e1c\\u90e8\\u6218\\u533a\\u7ec4\\u7ec7\\u5175\\u529b\\u5728\\u53f0\\u5c9b\\u4ee5\\u4e1c\\u548c\\u897f\\u5357\\...
          │               │             │       └ '/search-platform/front/search'
          │               │             └ 'POST'
          │               └ <urllib3.connection.HTTPConnection object at 0x7f9124506e20>
          └ <class 'urllib3.connection.HTTPConnection'>
  File "/usr/lib/python3.8/http/client.py", line 1256, in request
    self._send_request(method, url, body, headers, encode_chunked)
    │    │             │       │    │     │        └ False
    │    │             │       │    │     └ {'User-Agent': 'Mozilla/5.0 (Windows NT 10.0; Win64; x64) AppleWebKit/537.36 (KHTML, like Gecko) Chrome/101.0.4951.54 Safari/...
    │    │             │       │    └ b'{"key": "\\u4e1c\\u90e8\\u6218\\u533a\\u7ec4\\u7ec7\\u5175\\u529b\\u5728\\u53f0\\u5c9b\\u4ee5\\u4e1c\\u548c\\u897f\\u5357\\...
    │    │             │       └ '/search-platform/front/search'
    │    │             └ 'POST'
    │    └ <function HTTPConnection._send_request at 0x7f926be50280>
    └ <urllib3.connection.HTTPConnection object at 0x7f9124506e20>
  File "/usr/lib/python3.8/http/client.py", line 1302, in _send_request
    self.endheaders(body, encode_chunked=encode_chunked)
    │    │          │                    └ False
    │    │          └ b'{"key": "\\u4e1c\\u90e8\\u6218\\u533a\\u7ec4\\u7ec7\\u5175\\u529b\\u5728\\u53f0\\u5c9b\\u4ee5\\u4e1c\\u548c\\u897f\\u5357\\...
    │    └ <function HTTPConnection.endheaders at 0x7f926be50160>
    └ <urllib3.connection.HTTPConnection object at 0x7f9124506e20>
  File "/usr/lib/python3.8/http/client.py", line 1251, in endheaders
    self._send_output(message_body, encode_chunked=encode_chunked)
    │    │            │                            └ False
    │    │            └ b'{"key": "\\u4e1c\\u90e8\\u6218\\u533a\\u7ec4\\u7ec7\\u5175\\u529b\\u5728\\u53f0\\u5c9b\\u4ee5\\u4e1c\\u548c\\u897f\\u5357\\...
    │    └ <function HTTPConnection._send_output at 0x7f926beb7d30>
    └ <urllib3.connection.HTTPConnection object at 0x7f9124506e20>
  File "/usr/lib/python3.8/http/client.py", line 1011, in _send_output
    self.send(msg)
    │    │    └ b'POST /search-platform/front/search HTTP/1.1\r\nHost: search.people.cn\r\nUser-Agent: Mozilla/5.0 (Windows NT 10.0; Win64; x...
    │    └ <function HTTPConnection.send at 0x7f926beb7b80>
    └ <urllib3.connection.HTTPConnection object at 0x7f9124506e20>
  File "/usr/lib/python3.8/http/client.py", line 951, in send
    self.connect()
    │    └ <function HTTPConnection.connect at 0x7f92585b0dc0>
    └ <urllib3.connection.HTTPConnection object at 0x7f9124506e20>
  File "/home/chase/.local/lib/python3.8/site-packages/urllib3/connection.py", line 205, in connect
    conn = self._new_conn()
           │    └ <function HTTPConnection._new_conn at 0x7f92585b0c10>
           └ <urllib3.connection.HTTPConnection object at 0x7f9124506e20>
  File "/home/chase/.local/lib/python3.8/site-packages/urllib3/connection.py", line 186, in _new_conn
    raise NewConnectionError(
          └ <class 'urllib3.exceptions.NewConnectionError'>

urllib3.exceptions.NewConnectionError: <urllib3.connection.HTTPConnection object at 0x7f9124506e20>: Failed to establish a new connection: [Errno 111] Connection refused


During handling of the above exception, another exception occurred:


Traceback (most recent call last):

  File "/home/chase/.local/lib/python3.8/site-packages/requests/adapters.py", line 439, in send
    resp = conn.urlopen(
           │    └ <function HTTPConnectionPool.urlopen at 0x7f92585c0820>
           └ <urllib3.connectionpool.HTTPConnectionPool object at 0x7f9253ebd280>
  File "/home/chase/.local/lib/python3.8/site-packages/urllib3/connectionpool.py", line 755, in urlopen
    retries = retries.increment(
              │       └ <function Retry.increment at 0x7f9258608b80>
              └ Retry(total=0, connect=None, read=False, redirect=None, status=None)
  File "/home/chase/.local/lib/python3.8/site-packages/urllib3/util/retry.py", line 574, in increment
    raise MaxRetryError(_pool, url, error or ResponseError(cause))
          │             │      │    │        │             └ 'unknown'
          │             │      │    │        └ <class 'urllib3.exceptions.ResponseError'>
          │             │      │    └ NewConnectionError('<urllib3.connection.HTTPConnection object at 0x7f9124506e20>: Failed to establish a new connection: [Errn...
          │             │      └ '/search-platform/front/search'
          │             └ <urllib3.connectionpool.HTTPConnectionPool object at 0x7f9253ebd280>
          └ <class 'urllib3.exceptions.MaxRetryError'>

urllib3.exceptions.MaxRetryError: HTTPConnectionPool(host='search.people.cn', port=80): Max retries exceeded with url: /search-platform/front/search (Caused by NewConnectionError('<urllib3.connection.HTTPConnection object at 0x7f9124506e20>: Failed to establish a new connection: [Errno 111] Connection refused'))


During handling of the above exception, another exception occurred:


Traceback (most recent call last):

  File "/usr/lib/python3.8/threading.py", line 890, in _bootstrap
    self._bootstrap_inner()
    │    └ <function Thread._bootstrap_inner at 0x7f927a614a60>
    └ <Thread(Thread-55, started daemon 140261418071808)>
  File "/usr/lib/python3.8/threading.py", line 932, in _bootstrap_inner
    self.run()
    │    └ <function Thread.run at 0x7f927a614790>
    └ <Thread(Thread-55, started daemon 140261418071808)>
  File "/usr/lib/python3.8/threading.py", line 870, in run
    self._target(*self._args, **self._kwargs)
    │    │        │    │        │    └ {}
    │    │        │    │        └ <Thread(Thread-55, started daemon 140261418071808)>
    │    │        │    └ ('ProjectManager.run_func_by_thread',)
    │    │        └ <Thread(Thread-55, started daemon 140261418071808)>
    │    └ <bound method ProjectManager.get_request_from_keywords_hot of <monitor.projectManager.ProjectManager object at 0x7f9162af4700>>
    └ <Thread(Thread-55, started daemon 140261418071808)>

  File "/home/users/Scy/yuqing/spider/monitor/projectManager.py", line 795, in get_request_from_keywords_hot
    self.search_spider_manager.crawl_by_keyword(
    │    │                     └ <function SearchSpidersManager.crawl_by_keyword at 0x7f9162b00040>
    │    └ <monitor.spiderManager.SearchSpidersManager object at 0x7f916270f0d0>
    └ <monitor.projectManager.ProjectManager object at 0x7f9162af4700>

  File "/home/users/Scy/yuqing/spider/monitor/spiderManager.py", line 118, in crawl_by_keyword
    self.crawl_by_keyword_signal_platform(project_names, platform, keyword, crawl_time, project_times)
    │    │                                │              │         │        │           └ {'default': <monitor.TimeSection object at 0x7f91628317f0>}
    │    │                                │              │         │        └ <monitor.TimeSection object at 0x7f91604259d0>
    │    │                                │              │         └ '东部战区组织兵力在台岛以东和西南海空域进行实兵演练'
    │    │                                │              └ '人民网'
    │    │                                └ ['default']
    │    └ <function SearchSpidersManager.crawl_by_keyword_signal_platform at 0x7f9162b000d0>
    └ <monitor.spiderManager.SearchSpidersManager object at 0x7f916270f0d0>

  File "/home/users/Scy/yuqing/spider/monitor/spiderManager.py", line 134, in crawl_by_keyword_signal_platform
    requests = self.get_request_from_keyword(platform, keyword, **crawl_time.to_dict())
               │    │                        │         │          │          └ <function TimeSection.to_dict at 0x7f925aaa8550>
               │    │                        │         │          └ <monitor.TimeSection object at 0x7f91604259d0>
               │    │                        │         └ '东部战区组织兵力在台岛以东和西南海空域进行实兵演练'
               │    │                        └ '人民网'
               │    └ <function SearchSpidersManager.get_request_from_keyword at 0x7f9162b001f0>
               └ <monitor.spiderManager.SearchSpidersManager object at 0x7f916270f0d0>

  File "/home/users/Scy/yuqing/spider/monitor/spiderManager.py", line 191, in get_request_from_keyword
    for request in self.spiders[platform].get_request_from_keyword(headers, search_url, keyword, content_url,
                   │    │       │                                  │        │           │        └ <string.Template object at 0x7f91241f9430>
                   │    │       │                                  │        │           └ '东部战区组织兵力在台岛以东和西南海空域进行实兵演练'
                   │    │       │                                  │        └ <string.Template object at 0x7f910420bb20>
                   │    │       │                                  └ {'Accept': 'application/json, text/plain, */*', 'Accept-Language': 'zh-CN,zh;q=0.9', 'Connection': 'keep-alive', 'Origin': 'h...
                   │    │       └ '人民网'
                   │    └ {'凤凰网': <monitor.searchSpiders.ifeng.Ifeng object at 0x7f916270f220>, '头条': <monitor.searchSpiders.toutiao.Toutiao object at ...
                   └ <monitor.spiderManager.SearchSpidersManager object at 0x7f916270f0d0>

> File "/home/users/Scy/yuqing/spider/monitor/searchSpiders/people.py", line 28, in get_request_from_keyword
    response = requests.post(search_url.substitute(), json=data, headers=headers)
               │        │    │          │                  │             └ {'Accept': 'application/json, text/plain, */*', 'Accept-Language': 'zh-CN,zh;q=0.9', 'Connection': 'keep-alive', 'Origin': 'h...
               │        │    │          │                  └ {'key': '东部战区组织兵力在台岛以东和西南海空域进行实兵演练', 'page': 1, 'limit': 10, 'hasTitle': True, 'hasContent': True, 'isFuzzy': True, 'type': 0...
               │        │    │          └ <function Template.substitute at 0x7f927a5fd0d0>
               │        │    └ <string.Template object at 0x7f910420bb20>
               │        └ <function post at 0x7f92583e73a0>
               └ <module 'requests' from '/home/chase/.local/lib/python3.8/site-packages/requests/__init__.py'>

  File "/home/chase/.local/lib/python3.8/site-packages/requests/api.py", line 117, in post
    return request('post', url, data=data, json=json, **kwargs)
           │               │         │          │       └ {'headers': {'Accept': 'application/json, text/plain, */*', 'Accept-Language': 'zh-CN,zh;q=0.9', 'Connection': 'keep-alive', ...
           │               │         │          └ {'key': '东部战区组织兵力在台岛以东和西南海空域进行实兵演练', 'page': 1, 'limit': 10, 'hasTitle': True, 'hasContent': True, 'isFuzzy': True, 'type': 0...
           │               │         └ None
           │               └ 'http://search.people.cn/search-platform/front/search'
           └ <function request at 0x7f9258455040>
  File "/home/chase/.local/lib/python3.8/site-packages/requests/api.py", line 61, in request
    return session.request(method=method, url=url, **kwargs)
           │       │              │           │      └ {'data': None, 'json': {'key': '东部战区组织兵力在台岛以东和西南海空域进行实兵演练', 'page': 1, 'limit': 10, 'hasTitle': True, 'hasContent': True, 'is...
           │       │              │           └ 'http://search.people.cn/search-platform/front/search'
           │       │              └ 'post'
           │       └ <function Session.request at 0x7f92583e6940>
           └ <requests.sessions.Session object at 0x7f9253f534c0>
  File "/home/chase/.local/lib/python3.8/site-packages/requests/sessions.py", line 542, in request
    resp = self.send(prep, **send_kwargs)
           │    │    │       └ {'timeout': None, 'allow_redirects': True, 'verify': True, 'proxies': OrderedDict(), 'stream': False, 'cert': None}
           │    │    └ <PreparedRequest [POST]>
           │    └ <function Session.send at 0x7f92583e6dc0>
           └ <requests.sessions.Session object at 0x7f9253f534c0>
  File "/home/chase/.local/lib/python3.8/site-packages/requests/sessions.py", line 655, in send
    r = adapter.send(request, **kwargs)
        │       │    │          └ {'timeout': None, 'verify': True, 'proxies': OrderedDict(), 'stream': False, 'cert': None}
        │       │    └ <PreparedRequest [POST]>
        │       └ <function HTTPAdapter.send at 0x7f92583e6280>
        └ <requests.adapters.HTTPAdapter object at 0x7f9160375a90>
  File "/home/chase/.local/lib/python3.8/site-packages/requests/adapters.py", line 516, in send
    raise ConnectionError(e, request=request)
          │                          └ <PreparedRequest [POST]>
          └ <class 'requests.exceptions.ConnectionError'>

requests.exceptions.ConnectionError: HTTPConnectionPool(host='search.people.cn', port=80): Max retries exceeded with url: /search-platform/front/search (Caused by NewConnectionError('<urllib3.connection.HTTPConnection object at 0x7f9124506e20>: Failed to establish a new connection: [Errno 111] Connection refused'))
2022-05-12 15:46:49.402 | ERROR    | monitor.searchSpiders.people:get_request_from_keyword:45 - E 人民网错误HTTPConnectionPool(host='search.people.cn', port=80): Max retries exceeded with url: /search-platform/front/search (Caused by NewConnectionError('<urllib3.connection.HTTPConnection object at 0x7f9124155cd0>: Failed to establish a new connection: [Errno 111] Connection refused'))
Traceback (most recent call last):

  File "/home/chase/.local/lib/python3.8/site-packages/urllib3/connection.py", line 174, in _new_conn
    conn = connection.create_connection(
           │          └ <function create_connection at 0x7f92585fd1f0>
           └ <module 'urllib3.util.connection' from '/home/chase/.local/lib/python3.8/site-packages/urllib3/util/connection.py'>
  File "/home/chase/.local/lib/python3.8/site-packages/urllib3/util/connection.py", line 96, in create_connection
    raise err
          └ ConnectionRefusedError(111, 'Connection refused')
  File "/home/chase/.local/lib/python3.8/site-packages/urllib3/util/connection.py", line 86, in create_connection
    sock.connect(sa)
    │            └ ('118.212.233.249', 80)
    └ None

ConnectionRefusedError: [Errno 111] Connection refused


During handling of the above exception, another exception occurred:


Traceback (most recent call last):

  File "/home/chase/.local/lib/python3.8/site-packages/urllib3/connectionpool.py", line 699, in urlopen
    httplib_response = self._make_request(
                       │    └ <function HTTPConnectionPool._make_request at 0x7f92585c05e0>
                       └ <urllib3.connectionpool.HTTPConnectionPool object at 0x7f91243e8370>
  File "/home/chase/.local/lib/python3.8/site-packages/urllib3/connectionpool.py", line 394, in _make_request
    conn.request(method, url, **httplib_request_kw)
    │    │       │       │      └ {'body': b'{"key": "\\u5916\\u4ea4\\u90e8\\uff1a\\u7f8e\\u65b9\\u4fee\\u6539\\u201c\\u7f8e\\u53f0\\u5173\\u7cfb\\u4e8b\\u5b9e...
    │    │       │       └ '/search-platform/front/search'
    │    │       └ 'POST'
    │    └ <function HTTPConnection.request at 0x7f92585b0f70>
    └ <urllib3.connection.HTTPConnection object at 0x7f9124155cd0>
  File "/home/chase/.local/lib/python3.8/site-packages/urllib3/connection.py", line 239, in request
    super(HTTPConnection, self).request(method, url, body=body, headers=headers)
          │               │             │       │         │             └ {'User-Agent': 'Mozilla/5.0 (Windows NT 10.0; Win64; x64) AppleWebKit/537.36 (KHTML, like Gecko) Chrome/101.0.4951.54 Safari/...
          │               │             │       │         └ b'{"key": "\\u5916\\u4ea4\\u90e8\\uff1a\\u7f8e\\u65b9\\u4fee\\u6539\\u201c\\u7f8e\\u53f0\\u5173\\u7cfb\\u4e8b\\u5b9e\\u6e05\\...
          │               │             │       └ '/search-platform/front/search'
          │               │             └ 'POST'
          │               └ <urllib3.connection.HTTPConnection object at 0x7f9124155cd0>
          └ <class 'urllib3.connection.HTTPConnection'>
  File "/usr/lib/python3.8/http/client.py", line 1256, in request
    self._send_request(method, url, body, headers, encode_chunked)
    │    │             │       │    │     │        └ False
    │    │             │       │    │     └ {'User-Agent': 'Mozilla/5.0 (Windows NT 10.0; Win64; x64) AppleWebKit/537.36 (KHTML, like Gecko) Chrome/101.0.4951.54 Safari/...
    │    │             │       │    └ b'{"key": "\\u5916\\u4ea4\\u90e8\\uff1a\\u7f8e\\u65b9\\u4fee\\u6539\\u201c\\u7f8e\\u53f0\\u5173\\u7cfb\\u4e8b\\u5b9e\\u6e05\\...
    │    │             │       └ '/search-platform/front/search'
    │    │             └ 'POST'
    │    └ <function HTTPConnection._send_request at 0x7f926be50280>
    └ <urllib3.connection.HTTPConnection object at 0x7f9124155cd0>
  File "/usr/lib/python3.8/http/client.py", line 1302, in _send_request
    self.endheaders(body, encode_chunked=encode_chunked)
    │    │          │                    └ False
    │    │          └ b'{"key": "\\u5916\\u4ea4\\u90e8\\uff1a\\u7f8e\\u65b9\\u4fee\\u6539\\u201c\\u7f8e\\u53f0\\u5173\\u7cfb\\u4e8b\\u5b9e\\u6e05\\...
    │    └ <function HTTPConnection.endheaders at 0x7f926be50160>
    └ <urllib3.connection.HTTPConnection object at 0x7f9124155cd0>
  File "/usr/lib/python3.8/http/client.py", line 1251, in endheaders
    self._send_output(message_body, encode_chunked=encode_chunked)
    │    │            │                            └ False
    │    │            └ b'{"key": "\\u5916\\u4ea4\\u90e8\\uff1a\\u7f8e\\u65b9\\u4fee\\u6539\\u201c\\u7f8e\\u53f0\\u5173\\u7cfb\\u4e8b\\u5b9e\\u6e05\\...
    │    └ <function HTTPConnection._send_output at 0x7f926beb7d30>
    └ <urllib3.connection.HTTPConnection object at 0x7f9124155cd0>
  File "/usr/lib/python3.8/http/client.py", line 1011, in _send_output
    self.send(msg)
    │    │    └ b'POST /search-platform/front/search HTTP/1.1\r\nHost: search.people.cn\r\nUser-Agent: Mozilla/5.0 (Windows NT 10.0; Win64; x...
    │    └ <function HTTPConnection.send at 0x7f926beb7b80>
    └ <urllib3.connection.HTTPConnection object at 0x7f9124155cd0>
  File "/usr/lib/python3.8/http/client.py", line 951, in send
    self.connect()
    │    └ <function HTTPConnection.connect at 0x7f92585b0dc0>
    └ <urllib3.connection.HTTPConnection object at 0x7f9124155cd0>
  File "/home/chase/.local/lib/python3.8/site-packages/urllib3/connection.py", line 205, in connect
    conn = self._new_conn()
           │    └ <function HTTPConnection._new_conn at 0x7f92585b0c10>
           └ <urllib3.connection.HTTPConnection object at 0x7f9124155cd0>
  File "/home/chase/.local/lib/python3.8/site-packages/urllib3/connection.py", line 186, in _new_conn
    raise NewConnectionError(
          └ <class 'urllib3.exceptions.NewConnectionError'>

urllib3.exceptions.NewConnectionError: <urllib3.connection.HTTPConnection object at 0x7f9124155cd0>: Failed to establish a new connection: [Errno 111] Connection refused


During handling of the above exception, another exception occurred:


Traceback (most recent call last):

  File "/home/chase/.local/lib/python3.8/site-packages/requests/adapters.py", line 439, in send
    resp = conn.urlopen(
           │    └ <function HTTPConnectionPool.urlopen at 0x7f92585c0820>
           └ <urllib3.connectionpool.HTTPConnectionPool object at 0x7f91243e8370>
  File "/home/chase/.local/lib/python3.8/site-packages/urllib3/connectionpool.py", line 755, in urlopen
    retries = retries.increment(
              │       └ <function Retry.increment at 0x7f9258608b80>
              └ Retry(total=0, connect=None, read=False, redirect=None, status=None)
  File "/home/chase/.local/lib/python3.8/site-packages/urllib3/util/retry.py", line 574, in increment
    raise MaxRetryError(_pool, url, error or ResponseError(cause))
          │             │      │    │        │             └ 'unknown'
          │             │      │    │        └ <class 'urllib3.exceptions.ResponseError'>
          │             │      │    └ NewConnectionError('<urllib3.connection.HTTPConnection object at 0x7f9124155cd0>: Failed to establish a new connection: [Errn...
          │             │      └ '/search-platform/front/search'
          │             └ <urllib3.connectionpool.HTTPConnectionPool object at 0x7f91243e8370>
          └ <class 'urllib3.exceptions.MaxRetryError'>

urllib3.exceptions.MaxRetryError: HTTPConnectionPool(host='search.people.cn', port=80): Max retries exceeded with url: /search-platform/front/search (Caused by NewConnectionError('<urllib3.connection.HTTPConnection object at 0x7f9124155cd0>: Failed to establish a new connection: [Errno 111] Connection refused'))


During handling of the above exception, another exception occurred:


Traceback (most recent call last):

  File "/usr/lib/python3.8/threading.py", line 890, in _bootstrap
    self._bootstrap_inner()
    │    └ <function Thread._bootstrap_inner at 0x7f927a614a60>
    └ <Thread(Thread-93, started daemon 140260864415488)>
  File "/usr/lib/python3.8/threading.py", line 932, in _bootstrap_inner
    self.run()
    │    └ <function Thread.run at 0x7f927a614790>
    └ <Thread(Thread-93, started daemon 140260864415488)>
  File "/usr/lib/python3.8/threading.py", line 870, in run
    self._target(*self._args, **self._kwargs)
    │    │        │    │        │    └ {}
    │    │        │    │        └ <Thread(Thread-93, started daemon 140260864415488)>
    │    │        │    └ ('ProjectManager.run_func_by_thread',)
    │    │        └ <Thread(Thread-93, started daemon 140260864415488)>
    │    └ <bound method ProjectManager.get_request_from_keywords_hot of <monitor.projectManager.ProjectManager object at 0x7f9162af4700>>
    └ <Thread(Thread-93, started daemon 140260864415488)>

  File "/home/users/Scy/yuqing/spider/monitor/projectManager.py", line 795, in get_request_from_keywords_hot
    self.search_spider_manager.crawl_by_keyword(
    │    │                     └ <function SearchSpidersManager.crawl_by_keyword at 0x7f9162b00040>
    │    └ <monitor.spiderManager.SearchSpidersManager object at 0x7f916270f0d0>
    └ <monitor.projectManager.ProjectManager object at 0x7f9162af4700>

  File "/home/users/Scy/yuqing/spider/monitor/spiderManager.py", line 118, in crawl_by_keyword
    self.crawl_by_keyword_signal_platform(project_names, platform, keyword, crawl_time, project_times)
    │    │                                │              │         │        │           └ {'default': <monitor.TimeSection object at 0x7f91628317f0>}
    │    │                                │              │         │        └ <monitor.TimeSection object at 0x7f916040a370>
    │    │                                │              │         └ '外交部：美方修改“美台关系事实清单”必将引火烧身'
    │    │                                │              └ '人民网'
    │    │                                └ ['default']
    │    └ <function SearchSpidersManager.crawl_by_keyword_signal_platform at 0x7f9162b000d0>
    └ <monitor.spiderManager.SearchSpidersManager object at 0x7f916270f0d0>

  File "/home/users/Scy/yuqing/spider/monitor/spiderManager.py", line 134, in crawl_by_keyword_signal_platform
    requests = self.get_request_from_keyword(platform, keyword, **crawl_time.to_dict())
               │    │                        │         │          │          └ <function TimeSection.to_dict at 0x7f925aaa8550>
               │    │                        │         │          └ <monitor.TimeSection object at 0x7f916040a370>
               │    │                        │         └ '外交部：美方修改“美台关系事实清单”必将引火烧身'
               │    │                        └ '人民网'
               │    └ <function SearchSpidersManager.get_request_from_keyword at 0x7f9162b001f0>
               └ <monitor.spiderManager.SearchSpidersManager object at 0x7f916270f0d0>

  File "/home/users/Scy/yuqing/spider/monitor/spiderManager.py", line 191, in get_request_from_keyword
    for request in self.spiders[platform].get_request_from_keyword(headers, search_url, keyword, content_url,
                   │    │       │                                  │        │           │        └ <string.Template object at 0x7f912422f130>
                   │    │       │                                  │        │           └ '外交部：美方修改“美台关系事实清单”必将引火烧身'
                   │    │       │                                  │        └ <string.Template object at 0x7f9124537ac0>
                   │    │       │                                  └ {'Accept': 'application/json, text/plain, */*', 'Accept-Language': 'zh-CN,zh;q=0.9', 'Connection': 'keep-alive', 'Origin': 'h...
                   │    │       └ '人民网'
                   │    └ {'凤凰网': <monitor.searchSpiders.ifeng.Ifeng object at 0x7f916270f220>, '头条': <monitor.searchSpiders.toutiao.Toutiao object at ...
                   └ <monitor.spiderManager.SearchSpidersManager object at 0x7f916270f0d0>

> File "/home/users/Scy/yuqing/spider/monitor/searchSpiders/people.py", line 28, in get_request_from_keyword
    response = requests.post(search_url.substitute(), json=data, headers=headers)
               │        │    │          │                  │             └ {'Accept': 'application/json, text/plain, */*', 'Accept-Language': 'zh-CN,zh;q=0.9', 'Connection': 'keep-alive', 'Origin': 'h...
               │        │    │          │                  └ {'key': '外交部：美方修改“美台关系事实清单”必将引火烧身', 'page': 1, 'limit': 10, 'hasTitle': True, 'hasContent': True, 'isFuzzy': True, 'type': 0,...
               │        │    │          └ <function Template.substitute at 0x7f927a5fd0d0>
               │        │    └ <string.Template object at 0x7f9124537ac0>
               │        └ <function post at 0x7f92583e73a0>
               └ <module 'requests' from '/home/chase/.local/lib/python3.8/site-packages/requests/__init__.py'>

  File "/home/chase/.local/lib/python3.8/site-packages/requests/api.py", line 117, in post
    return request('post', url, data=data, json=json, **kwargs)
           │               │         │          │       └ {'headers': {'Accept': 'application/json, text/plain, */*', 'Accept-Language': 'zh-CN,zh;q=0.9', 'Connection': 'keep-alive', ...
           │               │         │          └ {'key': '外交部：美方修改“美台关系事实清单”必将引火烧身', 'page': 1, 'limit': 10, 'hasTitle': True, 'hasContent': True, 'isFuzzy': True, 'type': 0,...
           │               │         └ None
           │               └ 'http://search.people.cn/search-platform/front/search'
           └ <function request at 0x7f9258455040>
  File "/home/chase/.local/lib/python3.8/site-packages/requests/api.py", line 61, in request
    return session.request(method=method, url=url, **kwargs)
           │       │              │           │      └ {'data': None, 'json': {'key': '外交部：美方修改“美台关系事实清单”必将引火烧身', 'page': 1, 'limit': 10, 'hasTitle': True, 'hasContent': True, 'isF...
           │       │              │           └ 'http://search.people.cn/search-platform/front/search'
           │       │              └ 'post'
           │       └ <function Session.request at 0x7f92583e6940>
           └ <requests.sessions.Session object at 0x7f91241f0070>
  File "/home/chase/.local/lib/python3.8/site-packages/requests/sessions.py", line 542, in request
    resp = self.send(prep, **send_kwargs)
           │    │    │       └ {'timeout': None, 'allow_redirects': True, 'verify': True, 'proxies': OrderedDict(), 'stream': False, 'cert': None}
           │    │    └ <PreparedRequest [POST]>
           │    └ <function Session.send at 0x7f92583e6dc0>
           └ <requests.sessions.Session object at 0x7f91241f0070>
  File "/home/chase/.local/lib/python3.8/site-packages/requests/sessions.py", line 655, in send
    r = adapter.send(request, **kwargs)
        │       │    │          └ {'timeout': None, 'verify': True, 'proxies': OrderedDict(), 'stream': False, 'cert': None}
        │       │    └ <PreparedRequest [POST]>
        │       └ <function HTTPAdapter.send at 0x7f92583e6280>
        └ <requests.adapters.HTTPAdapter object at 0x7f91247dcdc0>
  File "/home/chase/.local/lib/python3.8/site-packages/requests/adapters.py", line 516, in send
    raise ConnectionError(e, request=request)
          │                          └ <PreparedRequest [POST]>
          └ <class 'requests.exceptions.ConnectionError'>

requests.exceptions.ConnectionError: HTTPConnectionPool(host='search.people.cn', port=80): Max retries exceeded with url: /search-platform/front/search (Caused by NewConnectionError('<urllib3.connection.HTTPConnection object at 0x7f9124155cd0>: Failed to establish a new connection: [Errno 111] Connection refused'))
2022-05-12 15:46:49.690 | ERROR    | monitor.searchSpiders.people:get_request_from_keyword:45 - E 人民网错误HTTPConnectionPool(host='search.people.cn', port=80): Max retries exceeded with url: /search-platform/front/search (Caused by NewConnectionError('<urllib3.connection.HTTPConnection object at 0x7f91485de460>: Failed to establish a new connection: [Errno 111] Connection refused'))
Traceback (most recent call last):

  File "/home/chase/.local/lib/python3.8/site-packages/urllib3/connection.py", line 174, in _new_conn
    conn = connection.create_connection(
           │          └ <function create_connection at 0x7f92585fd1f0>
           └ <module 'urllib3.util.connection' from '/home/chase/.local/lib/python3.8/site-packages/urllib3/util/connection.py'>
  File "/home/chase/.local/lib/python3.8/site-packages/urllib3/util/connection.py", line 96, in create_connection
    raise err
          └ ConnectionRefusedError(111, 'Connection refused')
  File "/home/chase/.local/lib/python3.8/site-packages/urllib3/util/connection.py", line 86, in create_connection
    sock.connect(sa)
    │            └ ('118.212.233.249', 80)
    └ None

ConnectionRefusedError: [Errno 111] Connection refused


During handling of the above exception, another exception occurred:


Traceback (most recent call last):

  File "/home/chase/.local/lib/python3.8/site-packages/urllib3/connectionpool.py", line 699, in urlopen
    httplib_response = self._make_request(
                       │    └ <function HTTPConnectionPool._make_request at 0x7f92585c05e0>
                       └ <urllib3.connectionpool.HTTPConnectionPool object at 0x7f9160e44520>
  File "/home/chase/.local/lib/python3.8/site-packages/urllib3/connectionpool.py", line 394, in _make_request
    conn.request(method, url, **httplib_request_kw)
    │    │       │       │      └ {'body': b'{"key": "\\u57c3\\u53ca\\u5357\\u90e8\\u53d1\\u6398\\u51fa85\\u5ea7\\u53e4\\u4ee3\\u5893\\u846c", "page": 1, "limi...
    │    │       │       └ '/search-platform/front/search'
    │    │       └ 'POST'
    │    └ <function HTTPConnection.request at 0x7f92585b0f70>
    └ <urllib3.connection.HTTPConnection object at 0x7f91485de460>
  File "/home/chase/.local/lib/python3.8/site-packages/urllib3/connection.py", line 239, in request
    super(HTTPConnection, self).request(method, url, body=body, headers=headers)
          │               │             │       │         │             └ {'User-Agent': 'Mozilla/5.0 (Windows NT 10.0; Win64; x64) AppleWebKit/537.36 (KHTML, like Gecko) Chrome/101.0.4951.54 Safari/...
          │               │             │       │         └ b'{"key": "\\u57c3\\u53ca\\u5357\\u90e8\\u53d1\\u6398\\u51fa85\\u5ea7\\u53e4\\u4ee3\\u5893\\u846c", "page": 1, "limit": 10, "...
          │               │             │       └ '/search-platform/front/search'
          │               │             └ 'POST'
          │               └ <urllib3.connection.HTTPConnection object at 0x7f91485de460>
          └ <class 'urllib3.connection.HTTPConnection'>
  File "/usr/lib/python3.8/http/client.py", line 1256, in request
    self._send_request(method, url, body, headers, encode_chunked)
    │    │             │       │    │     │        └ False
    │    │             │       │    │     └ {'User-Agent': 'Mozilla/5.0 (Windows NT 10.0; Win64; x64) AppleWebKit/537.36 (KHTML, like Gecko) Chrome/101.0.4951.54 Safari/...
    │    │             │       │    └ b'{"key": "\\u57c3\\u53ca\\u5357\\u90e8\\u53d1\\u6398\\u51fa85\\u5ea7\\u53e4\\u4ee3\\u5893\\u846c", "page": 1, "limit": 10, "...
    │    │             │       └ '/search-platform/front/search'
    │    │             └ 'POST'
    │    └ <function HTTPConnection._send_request at 0x7f926be50280>
    └ <urllib3.connection.HTTPConnection object at 0x7f91485de460>
  File "/usr/lib/python3.8/http/client.py", line 1302, in _send_request
    self.endheaders(body, encode_chunked=encode_chunked)
    │    │          │                    └ False
    │    │          └ b'{"key": "\\u57c3\\u53ca\\u5357\\u90e8\\u53d1\\u6398\\u51fa85\\u5ea7\\u53e4\\u4ee3\\u5893\\u846c", "page": 1, "limit": 10, "...
    │    └ <function HTTPConnection.endheaders at 0x7f926be50160>
    └ <urllib3.connection.HTTPConnection object at 0x7f91485de460>
  File "/usr/lib/python3.8/http/client.py", line 1251, in endheaders
    self._send_output(message_body, encode_chunked=encode_chunked)
    │    │            │                            └ False
    │    │            └ b'{"key": "\\u57c3\\u53ca\\u5357\\u90e8\\u53d1\\u6398\\u51fa85\\u5ea7\\u53e4\\u4ee3\\u5893\\u846c", "page": 1, "limit": 10, "...
    │    └ <function HTTPConnection._send_output at 0x7f926beb7d30>
    └ <urllib3.connection.HTTPConnection object at 0x7f91485de460>
  File "/usr/lib/python3.8/http/client.py", line 1011, in _send_output
    self.send(msg)
    │    │    └ b'POST /search-platform/front/search HTTP/1.1\r\nHost: search.people.cn\r\nUser-Agent: Mozilla/5.0 (Windows NT 10.0; Win64; x...
    │    └ <function HTTPConnection.send at 0x7f926beb7b80>
    └ <urllib3.connection.HTTPConnection object at 0x7f91485de460>
  File "/usr/lib/python3.8/http/client.py", line 951, in send
    self.connect()
    │    └ <function HTTPConnection.connect at 0x7f92585b0dc0>
    └ <urllib3.connection.HTTPConnection object at 0x7f91485de460>
  File "/home/chase/.local/lib/python3.8/site-packages/urllib3/connection.py", line 205, in connect
    conn = self._new_conn()
           │    └ <function HTTPConnection._new_conn at 0x7f92585b0c10>
           └ <urllib3.connection.HTTPConnection object at 0x7f91485de460>
  File "/home/chase/.local/lib/python3.8/site-packages/urllib3/connection.py", line 186, in _new_conn
    raise NewConnectionError(
          └ <class 'urllib3.exceptions.NewConnectionError'>

urllib3.exceptions.NewConnectionError: <urllib3.connection.HTTPConnection object at 0x7f91485de460>: Failed to establish a new connection: [Errno 111] Connection refused


During handling of the above exception, another exception occurred:


Traceback (most recent call last):

  File "/home/chase/.local/lib/python3.8/site-packages/requests/adapters.py", line 439, in send
    resp = conn.urlopen(
           │    └ <function HTTPConnectionPool.urlopen at 0x7f92585c0820>
           └ <urllib3.connectionpool.HTTPConnectionPool object at 0x7f9160e44520>
  File "/home/chase/.local/lib/python3.8/site-packages/urllib3/connectionpool.py", line 755, in urlopen
    retries = retries.increment(
              │       └ <function Retry.increment at 0x7f9258608b80>
              └ Retry(total=0, connect=None, read=False, redirect=None, status=None)
  File "/home/chase/.local/lib/python3.8/site-packages/urllib3/util/retry.py", line 574, in increment
    raise MaxRetryError(_pool, url, error or ResponseError(cause))
          │             │      │    │        │             └ 'unknown'
          │             │      │    │        └ <class 'urllib3.exceptions.ResponseError'>
          │             │      │    └ NewConnectionError('<urllib3.connection.HTTPConnection object at 0x7f91485de460>: Failed to establish a new connection: [Errn...
          │             │      └ '/search-platform/front/search'
          │             └ <urllib3.connectionpool.HTTPConnectionPool object at 0x7f9160e44520>
          └ <class 'urllib3.exceptions.MaxRetryError'>

urllib3.exceptions.MaxRetryError: HTTPConnectionPool(host='search.people.cn', port=80): Max retries exceeded with url: /search-platform/front/search (Caused by NewConnectionError('<urllib3.connection.HTTPConnection object at 0x7f91485de460>: Failed to establish a new connection: [Errno 111] Connection refused'))


During handling of the above exception, another exception occurred:


Traceback (most recent call last):

  File "/usr/lib/python3.8/threading.py", line 890, in _bootstrap
    self._bootstrap_inner()
    │    └ <function Thread._bootstrap_inner at 0x7f927a614a60>
    └ <Thread(Thread-170, started daemon 140259773888256)>
  File "/usr/lib/python3.8/threading.py", line 932, in _bootstrap_inner
    self.run()
    │    └ <function Thread.run at 0x7f927a614790>
    └ <Thread(Thread-170, started daemon 140259773888256)>
  File "/usr/lib/python3.8/threading.py", line 870, in run
    self._target(*self._args, **self._kwargs)
    │    │        │    │        │    └ {}
    │    │        │    │        └ <Thread(Thread-170, started daemon 140259773888256)>
    │    │        │    └ ('ProjectManager.run_func_by_thread',)
    │    │        └ <Thread(Thread-170, started daemon 140259773888256)>
    │    └ <bound method ProjectManager.get_request_from_keywords_hot of <monitor.projectManager.ProjectManager object at 0x7f9162af4700>>
    └ <Thread(Thread-170, started daemon 140259773888256)>

  File "/home/users/Scy/yuqing/spider/monitor/projectManager.py", line 795, in get_request_from_keywords_hot
    self.search_spider_manager.crawl_by_keyword(
    │    │                     └ <function SearchSpidersManager.crawl_by_keyword at 0x7f9162b00040>
    │    └ <monitor.spiderManager.SearchSpidersManager object at 0x7f916270f0d0>
    └ <monitor.projectManager.ProjectManager object at 0x7f9162af4700>

  File "/home/users/Scy/yuqing/spider/monitor/spiderManager.py", line 118, in crawl_by_keyword
    self.crawl_by_keyword_signal_platform(project_names, platform, keyword, crawl_time, project_times)
    │    │                                │              │         │        │           └ {'default': <monitor.TimeSection object at 0x7f91628317f0>}
    │    │                                │              │         │        └ <monitor.TimeSection object at 0x7f9148581f40>
    │    │                                │              │         └ '埃及南部发掘出85座古代墓葬'
    │    │                                │              └ '人民网'
    │    │                                └ ['default']
    │    └ <function SearchSpidersManager.crawl_by_keyword_signal_platform at 0x7f9162b000d0>
    └ <monitor.spiderManager.SearchSpidersManager object at 0x7f916270f0d0>

  File "/home/users/Scy/yuqing/spider/monitor/spiderManager.py", line 134, in crawl_by_keyword_signal_platform
    requests = self.get_request_from_keyword(platform, keyword, **crawl_time.to_dict())
               │    │                        │         │          │          └ <function TimeSection.to_dict at 0x7f925aaa8550>
               │    │                        │         │          └ <monitor.TimeSection object at 0x7f9148581f40>
               │    │                        │         └ '埃及南部发掘出85座古代墓葬'
               │    │                        └ '人民网'
               │    └ <function SearchSpidersManager.get_request_from_keyword at 0x7f9162b001f0>
               └ <monitor.spiderManager.SearchSpidersManager object at 0x7f916270f0d0>

  File "/home/users/Scy/yuqing/spider/monitor/spiderManager.py", line 191, in get_request_from_keyword
    for request in self.spiders[platform].get_request_from_keyword(headers, search_url, keyword, content_url,
                   │    │       │                                  │        │           │        └ <string.Template object at 0x7f91242c72b0>
                   │    │       │                                  │        │           └ '埃及南部发掘出85座古代墓葬'
                   │    │       │                                  │        └ <string.Template object at 0x7f9253f53760>
                   │    │       │                                  └ {'Accept': 'application/json, text/plain, */*', 'Accept-Language': 'zh-CN,zh;q=0.9', 'Connection': 'keep-alive', 'Origin': 'h...
                   │    │       └ '人民网'
                   │    └ {'凤凰网': <monitor.searchSpiders.ifeng.Ifeng object at 0x7f916270f220>, '头条': <monitor.searchSpiders.toutiao.Toutiao object at ...
                   └ <monitor.spiderManager.SearchSpidersManager object at 0x7f916270f0d0>

> File "/home/users/Scy/yuqing/spider/monitor/searchSpiders/people.py", line 28, in get_request_from_keyword
    response = requests.post(search_url.substitute(), json=data, headers=headers)
               │        │    │          │                  │             └ {'Accept': 'application/json, text/plain, */*', 'Accept-Language': 'zh-CN,zh;q=0.9', 'Connection': 'keep-alive', 'Origin': 'h...
               │        │    │          │                  └ {'key': '埃及南部发掘出85座古代墓葬', 'page': 1, 'limit': 10, 'hasTitle': True, 'hasContent': True, 'isFuzzy': True, 'type': 0, 'sortType...
               │        │    │          └ <function Template.substitute at 0x7f927a5fd0d0>
               │        │    └ <string.Template object at 0x7f9253f53760>
               │        └ <function post at 0x7f92583e73a0>
               └ <module 'requests' from '/home/chase/.local/lib/python3.8/site-packages/requests/__init__.py'>

  File "/home/chase/.local/lib/python3.8/site-packages/requests/api.py", line 117, in post
    return request('post', url, data=data, json=json, **kwargs)
           │               │         │          │       └ {'headers': {'Accept': 'application/json, text/plain, */*', 'Accept-Language': 'zh-CN,zh;q=0.9', 'Connection': 'keep-alive', ...
           │               │         │          └ {'key': '埃及南部发掘出85座古代墓葬', 'page': 1, 'limit': 10, 'hasTitle': True, 'hasContent': True, 'isFuzzy': True, 'type': 0, 'sortType...
           │               │         └ None
           │               └ 'http://search.people.cn/search-platform/front/search'
           └ <function request at 0x7f9258455040>
  File "/home/chase/.local/lib/python3.8/site-packages/requests/api.py", line 61, in request
    return session.request(method=method, url=url, **kwargs)
           │       │              │           │      └ {'data': None, 'json': {'key': '埃及南部发掘出85座古代墓葬', 'page': 1, 'limit': 10, 'hasTitle': True, 'hasContent': True, 'isFuzzy': Tru...
           │       │              │           └ 'http://search.people.cn/search-platform/front/search'
           │       │              └ 'post'
           │       └ <function Session.request at 0x7f92583e6940>
           └ <requests.sessions.Session object at 0x7f91480fc760>
  File "/home/chase/.local/lib/python3.8/site-packages/requests/sessions.py", line 542, in request
    resp = self.send(prep, **send_kwargs)
           │    │    │       └ {'timeout': None, 'allow_redirects': True, 'verify': True, 'proxies': OrderedDict(), 'stream': False, 'cert': None}
           │    │    └ <PreparedRequest [POST]>
           │    └ <function Session.send at 0x7f92583e6dc0>
           └ <requests.sessions.Session object at 0x7f91480fc760>
  File "/home/chase/.local/lib/python3.8/site-packages/requests/sessions.py", line 655, in send
    r = adapter.send(request, **kwargs)
        │       │    │          └ {'timeout': None, 'verify': True, 'proxies': OrderedDict(), 'stream': False, 'cert': None}
        │       │    └ <PreparedRequest [POST]>
        │       └ <function HTTPAdapter.send at 0x7f92583e6280>
        └ <requests.adapters.HTTPAdapter object at 0x7f916063ddf0>
  File "/home/chase/.local/lib/python3.8/site-packages/requests/adapters.py", line 516, in send
    raise ConnectionError(e, request=request)
          │                          └ <PreparedRequest [POST]>
          └ <class 'requests.exceptions.ConnectionError'>

requests.exceptions.ConnectionError: HTTPConnectionPool(host='search.people.cn', port=80): Max retries exceeded with url: /search-platform/front/search (Caused by NewConnectionError('<urllib3.connection.HTTPConnection object at 0x7f91485de460>: Failed to establish a new connection: [Errno 111] Connection refused'))
