2022-05-14 02:55:23.164 | ERROR    | base.db.mysql:update:390 - 【mysql更新数据出错】
Traceback (most recent call last):

  File "/home/chase/.local/lib/python3.8/site-packages/sqlalchemy/engine/base.py", line 1771, in _execute_context
    self.dialect.do_execute(
    │    │       └ <function DefaultDialect.do_execute at 0x7f31f38f75e0>
    │    └ <sqlalchemy.dialects.mysql.pymysql.MySQLDialect_pymysql object at 0x7f3103ffde20>
    └ <sqlalchemy.engine.base.Connection object at 0x7f310029f2e0>
  File "/home/chase/.local/lib/python3.8/site-packages/sqlalchemy/engine/default.py", line 717, in do_execute
    cursor.execute(statement, parameters)
    │      │       │          └ {'server_id': '180.201.163.246:6800', 'ip': '180.201.163.246', 'username': 'chase', 'password': '9573484877125589465390262585...
    │      │       └ 'UPDATE device SET server_id=%(server_id)s, ip=%(ip)s, username=%(username)s, password=%(password)s, address=%(address)s, por...
    │      └ <function Cursor.execute at 0x7f31f354cdc0>
    └ <pymysql.cursors.Cursor object at 0x7f2ff863a760>
  File "/home/chase/.local/lib/python3.8/site-packages/pymysql/cursors.py", line 148, in execute
    result = self._query(query)
             │    │      └ "UPDATE device SET server_id='180.201.163.246:6800', ip='180.201.163.246', username='chase', password='9573484877125589465390...
             │    └ <function Cursor._query at 0x7f31f34d7280>
             └ <pymysql.cursors.Cursor object at 0x7f2ff863a760>
  File "/home/chase/.local/lib/python3.8/site-packages/pymysql/cursors.py", line 310, in _query
    conn.query(q)
    │    │     └ "UPDATE device SET server_id='180.201.163.246:6800', ip='180.201.163.246', username='chase', password='9573484877125589465390...
    │    └ <function Connection.query at 0x7f31f34e5670>
    └ <pymysql.connections.Connection object at 0x7f3098200dc0>
  File "/home/chase/.local/lib/python3.8/site-packages/pymysql/connections.py", line 548, in query
    self._affected_rows = self._read_query_result(unbuffered=unbuffered)
    │    │                │    │                             └ False
    │    │                │    └ <function Connection._read_query_result at 0x7f31f34e5ca0>
    │    │                └ <pymysql.connections.Connection object at 0x7f3098200dc0>
    │    └ 1
    └ <pymysql.connections.Connection object at 0x7f3098200dc0>
  File "/home/chase/.local/lib/python3.8/site-packages/pymysql/connections.py", line 775, in _read_query_result
    result.read()
    │      └ <function MySQLResult.read at 0x7f31f34e64c0>
    └ <pymysql.connections.MySQLResult object at 0x7f30d809feb0>
  File "/home/chase/.local/lib/python3.8/site-packages/pymysql/connections.py", line 1156, in read
    first_packet = self.connection._read_packet()
                   │    └ None
                   └ <pymysql.connections.MySQLResult object at 0x7f30d809feb0>
  File "/home/chase/.local/lib/python3.8/site-packages/pymysql/connections.py", line 725, in _read_packet
    packet.raise_for_error()
    │      └ <function MysqlPacket.raise_for_error at 0x7f31f34ddee0>
    └ <pymysql.protocol.MysqlPacket object at 0x7f309878bc40>
  File "/home/chase/.local/lib/python3.8/site-packages/pymysql/protocol.py", line 221, in raise_for_error
    err.raise_mysql_exception(self._data)
    │   │                     │    └ <member '_data' of 'MysqlPacket' objects>
    │   │                     └ <pymysql.protocol.MysqlPacket object at 0x7f309878bc40>
    │   └ <function raise_mysql_exception at 0x7f31f358c670>
    └ <module 'pymysql.err' from '/home/chase/.local/lib/python3.8/site-packages/pymysql/err.py'>
  File "/home/chase/.local/lib/python3.8/site-packages/pymysql/err.py", line 143, in raise_mysql_exception
    raise errorclass(errno, errval)
          │          │      └ "Duplicate entry '180.201.163.246:6800' for key 'device.PRIMARY'"
          │          └ 1062
          └ <class 'pymysql.err.IntegrityError'>

pymysql.err.IntegrityError: (1062, "Duplicate entry '180.201.163.246:6800' for key 'device.PRIMARY'")


The above exception was the direct cause of the following exception:


Traceback (most recent call last):

  File "/usr/lib/python3.8/threading.py", line 890, in _bootstrap
    self._bootstrap_inner()
    │    └ <function Thread._bootstrap_inner at 0x7f321bf29a60>
    └ <Thread(Thread-9088, started daemon 139839084091136)>
  File "/usr/lib/python3.8/threading.py", line 932, in _bootstrap_inner
    self.run()
    │    └ <function Thread.run at 0x7f321bf29790>
    └ <Thread(Thread-9088, started daemon 139839084091136)>
  File "/usr/lib/python3.8/threading.py", line 870, in run
    self._target(*self._args, **self._kwargs)
    │    │        │    │        │    └ {}
    │    │        │    │        └ <Thread(Thread-9088, started daemon 139839084091136)>
    │    │        │    └ ('ProjectManager.run_func_by_thread',)
    │    │        └ <Thread(Thread-9088, started daemon 139839084091136)>
    │    └ <bound method ProjectManager.get_request_from_keywords_hot of <monitor.projectManager.ProjectManager object at 0x7f31042e52e0>>
    └ <Thread(Thread-9088, started daemon 139839084091136)>

  File "/home/users/Scy/yuqing/spider/monitor/projectManager.py", line 799, in get_request_from_keywords_hot
    self.start_finished_spider_every_interval(project_names)
    │    │                                    └ ['default', 'test']
    │    └ <function ProjectManager.start_finished_spider_every_interval at 0x7f3104005280>
    └ <monitor.projectManager.ProjectManager object at 0x7f31042e52e0>

  File "/home/users/Scy/yuqing/spider/monitor/projectManager.py", line 784, in start_finished_spider_every_interval
    self[name].start_spider()
    │    └ 'default'
    └ <monitor.projectManager.ProjectManager object at 0x7f31042e52e0>

  File "/home/users/Scy/yuqing/spider/monitor/projectManager.py", line 366, in start_spider
    self.update_device_valid(device)
    │    │                   └ <monitor.deviceManager.DeviceC object at 0x7f3104029220>
    │    └ <function Project.update_device_valid at 0x7f3104003280>
    └ <monitor.projectManager.Project object at 0x7f3104029460>

  File "/home/users/Scy/yuqing/spider/monitor/projectManager.py", line 421, in update_device_valid
    self.database_manager.mysql.update(Device(**device.to_item()))
    │    │                │     │      │        │      └ <function DeviceC.to_item at 0x7f31f34ed310>
    │    │                │     │      │        └ <monitor.deviceManager.DeviceC object at 0x7f3104029220>
    │    │                │     │      └ <class 'base.db.mysql.Device'>
    │    │                │     └ <function Mysql.update at 0x7f31f35f4790>
    │    │                └ <base.db.mysql.Mysql object at 0x7f3103ffdfd0>
    │    └ <base.db.dbSlot.Slot object at 0x7f3103ffdf10>
    └ <monitor.projectManager.Project object at 0x7f3104029460>

> File "/home/users/Scy/yuqing/spider/base/db/mysql.py", line 375, in update
    row.update(new)
    │   │      └ {'server_id': '180.201.163.246:6800', 'ip': '180.201.163.246', 'username': 'chase', 'password': '9573484877125589465390262585...
    │   └ <function Query.update at 0x7f31f37333a0>
    └ <sqlalchemy.orm.query.Query object at 0x7f3098204640>

  File "/home/chase/.local/lib/python3.8/site-packages/sqlalchemy/orm/query.py", line 3221, in update
    result = self.session.execute(
             │    │       └ <function Session.execute at 0x7f31f370faf0>
             │    └ <sqlalchemy.orm.session.Session object at 0x7f309855cbb0>
             └ <sqlalchemy.orm.query.Query object at 0x7f3098204640>
  File "/home/chase/.local/lib/python3.8/site-packages/sqlalchemy/orm/session.py", line 1689, in execute
    result = conn._execute_20(statement, params or {}, execution_options)
             │    │           │          │             └ immutabledict({'synchronize_session': 'evaluate', '_sa_orm_update_options': default_update_options(_matched_objects=[], _reso...
             │    │           │          └ immutabledict({})
             │    │           └ <sqlalchemy.sql.annotation.AnnotatedUpdate object at 0x7f30d8553cd0>
             │    └ <function Connection._execute_20 at 0x7f31f39bc790>
             └ <sqlalchemy.engine.base.Connection object at 0x7f310029f2e0>
  File "/home/chase/.local/lib/python3.8/site-packages/sqlalchemy/engine/base.py", line 1583, in _execute_20
    return meth(self, args_10style, kwargs_10style, execution_options)
           │    │     │             │               └ immutabledict({'synchronize_session': 'evaluate', '_sa_orm_update_options': default_update_options(_matched_objects=[], _reso...
           │    │     │             └ immutabledict({})
           │    │     └ ({},)
           │    └ <sqlalchemy.engine.base.Connection object at 0x7f310029f2e0>
           └ <bound method ClauseElement._execute_on_connection of <sqlalchemy.sql.annotation.AnnotatedUpdate object at 0x7f30d8553cd0>>
  File "/home/chase/.local/lib/python3.8/site-packages/sqlalchemy/sql/elements.py", line 323, in _execute_on_connection
    return connection._execute_clauseelement(
           │          └ <function Connection._execute_clauseelement at 0x7f31f39bc5e0>
           └ <sqlalchemy.engine.base.Connection object at 0x7f310029f2e0>
  File "/home/chase/.local/lib/python3.8/site-packages/sqlalchemy/engine/base.py", line 1452, in _execute_clauseelement
    ret = self._execute_context(
          │    └ <function Connection._execute_context at 0x7f31f39bc8b0>
          └ <sqlalchemy.engine.base.Connection object at 0x7f310029f2e0>
  File "/home/chase/.local/lib/python3.8/site-packages/sqlalchemy/engine/base.py", line 1814, in _execute_context
    self._handle_dbapi_exception(
    │    └ <function Connection._handle_dbapi_exception at 0x7f31f39bca60>
    └ <sqlalchemy.engine.base.Connection object at 0x7f310029f2e0>
  File "/home/chase/.local/lib/python3.8/site-packages/sqlalchemy/engine/base.py", line 1995, in _handle_dbapi_exception
    util.raise_(
    │    └ <function raise_ at 0x7f31f3d7ea60>
    └ <module 'sqlalchemy.util' from '/home/chase/.local/lib/python3.8/site-packages/sqlalchemy/util/__init__.py'>
  File "/home/chase/.local/lib/python3.8/site-packages/sqlalchemy/util/compat.py", line 207, in raise_
    raise exception
  File "/home/chase/.local/lib/python3.8/site-packages/sqlalchemy/engine/base.py", line 1771, in _execute_context
    self.dialect.do_execute(
    │    │       └ <function DefaultDialect.do_execute at 0x7f31f38f75e0>
    │    └ <sqlalchemy.dialects.mysql.pymysql.MySQLDialect_pymysql object at 0x7f3103ffde20>
    └ <sqlalchemy.engine.base.Connection object at 0x7f310029f2e0>
  File "/home/chase/.local/lib/python3.8/site-packages/sqlalchemy/engine/default.py", line 717, in do_execute
    cursor.execute(statement, parameters)
    │      │       │          └ {'server_id': '180.201.163.246:6800', 'ip': '180.201.163.246', 'username': 'chase', 'password': '9573484877125589465390262585...
    │      │       └ 'UPDATE device SET server_id=%(server_id)s, ip=%(ip)s, username=%(username)s, password=%(password)s, address=%(address)s, por...
    │      └ <function Cursor.execute at 0x7f31f354cdc0>
    └ <pymysql.cursors.Cursor object at 0x7f2ff863a760>
  File "/home/chase/.local/lib/python3.8/site-packages/pymysql/cursors.py", line 148, in execute
    result = self._query(query)
             │    │      └ "UPDATE device SET server_id='180.201.163.246:6800', ip='180.201.163.246', username='chase', password='9573484877125589465390...
             │    └ <function Cursor._query at 0x7f31f34d7280>
             └ <pymysql.cursors.Cursor object at 0x7f2ff863a760>
  File "/home/chase/.local/lib/python3.8/site-packages/pymysql/cursors.py", line 310, in _query
    conn.query(q)
    │    │     └ "UPDATE device SET server_id='180.201.163.246:6800', ip='180.201.163.246', username='chase', password='9573484877125589465390...
    │    └ <function Connection.query at 0x7f31f34e5670>
    └ <pymysql.connections.Connection object at 0x7f3098200dc0>
  File "/home/chase/.local/lib/python3.8/site-packages/pymysql/connections.py", line 548, in query
    self._affected_rows = self._read_query_result(unbuffered=unbuffered)
    │    │                │    │                             └ False
    │    │                │    └ <function Connection._read_query_result at 0x7f31f34e5ca0>
    │    │                └ <pymysql.connections.Connection object at 0x7f3098200dc0>
    │    └ 1
    └ <pymysql.connections.Connection object at 0x7f3098200dc0>
  File "/home/chase/.local/lib/python3.8/site-packages/pymysql/connections.py", line 775, in _read_query_result
    result.read()
    │      └ <function MySQLResult.read at 0x7f31f34e64c0>
    └ <pymysql.connections.MySQLResult object at 0x7f30d809feb0>
  File "/home/chase/.local/lib/python3.8/site-packages/pymysql/connections.py", line 1156, in read
    first_packet = self.connection._read_packet()
                   │    └ None
                   └ <pymysql.connections.MySQLResult object at 0x7f30d809feb0>
  File "/home/chase/.local/lib/python3.8/site-packages/pymysql/connections.py", line 725, in _read_packet
    packet.raise_for_error()
    │      └ <function MysqlPacket.raise_for_error at 0x7f31f34ddee0>
    └ <pymysql.protocol.MysqlPacket object at 0x7f309878bc40>
  File "/home/chase/.local/lib/python3.8/site-packages/pymysql/protocol.py", line 221, in raise_for_error
    err.raise_mysql_exception(self._data)
    │   │                     │    └ <member '_data' of 'MysqlPacket' objects>
    │   │                     └ <pymysql.protocol.MysqlPacket object at 0x7f309878bc40>
    │   └ <function raise_mysql_exception at 0x7f31f358c670>
    └ <module 'pymysql.err' from '/home/chase/.local/lib/python3.8/site-packages/pymysql/err.py'>
  File "/home/chase/.local/lib/python3.8/site-packages/pymysql/err.py", line 143, in raise_mysql_exception
    raise errorclass(errno, errval)
          │          │      └ "Duplicate entry '180.201.163.246:6800' for key 'device.PRIMARY'"
          │          └ 1062
          └ <class 'pymysql.err.IntegrityError'>

sqlalchemy.exc.IntegrityError: (pymysql.err.IntegrityError) (1062, "Duplicate entry '180.201.163.246:6800' for key 'device.PRIMARY'")
[SQL: UPDATE device SET server_id=%(server_id)s, ip=%(ip)s, username=%(username)s, password=%(password)s, address=%(address)s, port=%(port)s, valid=%(valid)s WHERE device.ip = %(ip_1)s]
[parameters: {'server_id': '180.201.163.246:6800', 'ip': '180.201.163.246', 'username': 'chase', 'password': '95734848771255894653902625856418710254583496639551284370233287980532589166066509485406626822282502159997082933256024413320630839609793976610046705004 ... (10 characters truncated) ... 07163448370492402598737972572108929095558914099610404921137111824062458665529894184979971984741186214035123613326535472376166953106629652290287681270', 'address': '/home/users/CT/pycharmproject/spiders/', 'port': 6800, 'valid': 1, 'ip_1': '180.201.163.246'}]
(Background on this error at: https://sqlalche.me/e/14/gkpj)
2022-05-14 02:55:40.343 | ERROR    | base.db.mysql:update:390 - 【mysql更新数据出错】
Traceback (most recent call last):

  File "/home/chase/.local/lib/python3.8/site-packages/sqlalchemy/engine/base.py", line 1771, in _execute_context
    self.dialect.do_execute(
    │    │       └ <function DefaultDialect.do_execute at 0x7f31f38f75e0>
    │    └ <sqlalchemy.dialects.mysql.pymysql.MySQLDialect_pymysql object at 0x7f3103ffde20>
    └ <sqlalchemy.engine.base.Connection object at 0x7f303851c640>
  File "/home/chase/.local/lib/python3.8/site-packages/sqlalchemy/engine/default.py", line 717, in do_execute
    cursor.execute(statement, parameters)
    │      │       │          └ {'server_id': '180.201.163.246:6800', 'ip': '180.201.163.246', 'username': 'chase', 'password': '5919960971819907291210157900...
    │      │       └ 'UPDATE device SET server_id=%(server_id)s, ip=%(ip)s, username=%(username)s, password=%(password)s, address=%(address)s, por...
    │      └ <function Cursor.execute at 0x7f31f354cdc0>
    └ <pymysql.cursors.Cursor object at 0x7f30d825b5e0>
  File "/home/chase/.local/lib/python3.8/site-packages/pymysql/cursors.py", line 148, in execute
    result = self._query(query)
             │    │      └ "UPDATE device SET server_id='180.201.163.246:6800', ip='180.201.163.246', username='chase', password='5919960971819907291210...
             │    └ <function Cursor._query at 0x7f31f34d7280>
             └ <pymysql.cursors.Cursor object at 0x7f30d825b5e0>
  File "/home/chase/.local/lib/python3.8/site-packages/pymysql/cursors.py", line 310, in _query
    conn.query(q)
    │    │     └ "UPDATE device SET server_id='180.201.163.246:6800', ip='180.201.163.246', username='chase', password='5919960971819907291210...
    │    └ <function Connection.query at 0x7f31f34e5670>
    └ <pymysql.connections.Connection object at 0x7f31020c9e80>
  File "/home/chase/.local/lib/python3.8/site-packages/pymysql/connections.py", line 548, in query
    self._affected_rows = self._read_query_result(unbuffered=unbuffered)
    │    │                │    │                             └ False
    │    │                │    └ <function Connection._read_query_result at 0x7f31f34e5ca0>
    │    │                └ <pymysql.connections.Connection object at 0x7f31020c9e80>
    │    └ 1
    └ <pymysql.connections.Connection object at 0x7f31020c9e80>
  File "/home/chase/.local/lib/python3.8/site-packages/pymysql/connections.py", line 775, in _read_query_result
    result.read()
    │      └ <function MySQLResult.read at 0x7f31f34e64c0>
    └ <pymysql.connections.MySQLResult object at 0x7f3102299d00>
  File "/home/chase/.local/lib/python3.8/site-packages/pymysql/connections.py", line 1156, in read
    first_packet = self.connection._read_packet()
                   │    └ None
                   └ <pymysql.connections.MySQLResult object at 0x7f3102299d00>
  File "/home/chase/.local/lib/python3.8/site-packages/pymysql/connections.py", line 725, in _read_packet
    packet.raise_for_error()
    │      └ <function MysqlPacket.raise_for_error at 0x7f31f34ddee0>
    └ <pymysql.protocol.MysqlPacket object at 0x7f30d80b30a0>
  File "/home/chase/.local/lib/python3.8/site-packages/pymysql/protocol.py", line 221, in raise_for_error
    err.raise_mysql_exception(self._data)
    │   │                     │    └ <member '_data' of 'MysqlPacket' objects>
    │   │                     └ <pymysql.protocol.MysqlPacket object at 0x7f30d80b30a0>
    │   └ <function raise_mysql_exception at 0x7f31f358c670>
    └ <module 'pymysql.err' from '/home/chase/.local/lib/python3.8/site-packages/pymysql/err.py'>
  File "/home/chase/.local/lib/python3.8/site-packages/pymysql/err.py", line 143, in raise_mysql_exception
    raise errorclass(errno, errval)
          │          │      └ "Duplicate entry '180.201.163.246:6800' for key 'device.PRIMARY'"
          │          └ 1062
          └ <class 'pymysql.err.IntegrityError'>

pymysql.err.IntegrityError: (1062, "Duplicate entry '180.201.163.246:6800' for key 'device.PRIMARY'")


The above exception was the direct cause of the following exception:


Traceback (most recent call last):

  File "/usr/lib/python3.8/threading.py", line 890, in _bootstrap
    self._bootstrap_inner()
    │    └ <function Thread._bootstrap_inner at 0x7f321bf29a60>
    └ <Thread(Thread-9093, started daemon 139839058913024)>
  File "/usr/lib/python3.8/threading.py", line 932, in _bootstrap_inner
    self.run()
    │    └ <function Thread.run at 0x7f321bf29790>
    └ <Thread(Thread-9093, started daemon 139839058913024)>
  File "/usr/lib/python3.8/threading.py", line 870, in run
    self._target(*self._args, **self._kwargs)
    │    │        │    │        │    └ {}
    │    │        │    │        └ <Thread(Thread-9093, started daemon 139839058913024)>
    │    │        │    └ ('ProjectManager.run_func_by_thread',)
    │    │        └ <Thread(Thread-9093, started daemon 139839058913024)>
    │    └ <bound method ProjectManager.get_request_from_keywords_hot of <monitor.projectManager.ProjectManager object at 0x7f31042e52e0>>
    └ <Thread(Thread-9093, started daemon 139839058913024)>

  File "/home/users/Scy/yuqing/spider/monitor/projectManager.py", line 799, in get_request_from_keywords_hot
    self.start_finished_spider_every_interval(project_names)
    │    │                                    └ ['default', 'test']
    │    └ <function ProjectManager.start_finished_spider_every_interval at 0x7f3104005280>
    └ <monitor.projectManager.ProjectManager object at 0x7f31042e52e0>

  File "/home/users/Scy/yuqing/spider/monitor/projectManager.py", line 784, in start_finished_spider_every_interval
    self[name].start_spider()
    │    └ 'default'
    └ <monitor.projectManager.ProjectManager object at 0x7f31042e52e0>

  File "/home/users/Scy/yuqing/spider/monitor/projectManager.py", line 366, in start_spider
    self.update_device_valid(device)
    │    │                   └ <monitor.deviceManager.DeviceC object at 0x7f3104029220>
    │    └ <function Project.update_device_valid at 0x7f3104003280>
    └ <monitor.projectManager.Project object at 0x7f3104029460>

  File "/home/users/Scy/yuqing/spider/monitor/projectManager.py", line 421, in update_device_valid
    self.database_manager.mysql.update(Device(**device.to_item()))
    │    │                │     │      │        │      └ <function DeviceC.to_item at 0x7f31f34ed310>
    │    │                │     │      │        └ <monitor.deviceManager.DeviceC object at 0x7f3104029220>
    │    │                │     │      └ <class 'base.db.mysql.Device'>
    │    │                │     └ <function Mysql.update at 0x7f31f35f4790>
    │    │                └ <base.db.mysql.Mysql object at 0x7f3103ffdfd0>
    │    └ <base.db.dbSlot.Slot object at 0x7f3103ffdf10>
    └ <monitor.projectManager.Project object at 0x7f3104029460>

> File "/home/users/Scy/yuqing/spider/base/db/mysql.py", line 375, in update
    row.update(new)
    │   │      └ {'server_id': '180.201.163.246:6800', 'ip': '180.201.163.246', 'username': 'chase', 'password': '5919960971819907291210157900...
    │   └ <function Query.update at 0x7f31f37333a0>
    └ <sqlalchemy.orm.query.Query object at 0x7f30985b2940>

  File "/home/chase/.local/lib/python3.8/site-packages/sqlalchemy/orm/query.py", line 3221, in update
    result = self.session.execute(
             │    │       └ <function Session.execute at 0x7f31f370faf0>
             │    └ <sqlalchemy.orm.session.Session object at 0x7f3102203ac0>
             └ <sqlalchemy.orm.query.Query object at 0x7f30985b2940>
  File "/home/chase/.local/lib/python3.8/site-packages/sqlalchemy/orm/session.py", line 1689, in execute
    result = conn._execute_20(statement, params or {}, execution_options)
             │    │           │          │             └ immutabledict({'synchronize_session': 'evaluate', '_sa_orm_update_options': default_update_options(_matched_objects=[], _reso...
             │    │           │          └ immutabledict({})
             │    │           └ <sqlalchemy.sql.annotation.AnnotatedUpdate object at 0x7f30986459a0>
             │    └ <function Connection._execute_20 at 0x7f31f39bc790>
             └ <sqlalchemy.engine.base.Connection object at 0x7f303851c640>
  File "/home/chase/.local/lib/python3.8/site-packages/sqlalchemy/engine/base.py", line 1583, in _execute_20
    return meth(self, args_10style, kwargs_10style, execution_options)
           │    │     │             │               └ immutabledict({'synchronize_session': 'evaluate', '_sa_orm_update_options': default_update_options(_matched_objects=[], _reso...
           │    │     │             └ immutabledict({})
           │    │     └ ({},)
           │    └ <sqlalchemy.engine.base.Connection object at 0x7f303851c640>
           └ <bound method ClauseElement._execute_on_connection of <sqlalchemy.sql.annotation.AnnotatedUpdate object at 0x7f30986459a0>>
  File "/home/chase/.local/lib/python3.8/site-packages/sqlalchemy/sql/elements.py", line 323, in _execute_on_connection
    return connection._execute_clauseelement(
           │          └ <function Connection._execute_clauseelement at 0x7f31f39bc5e0>
           └ <sqlalchemy.engine.base.Connection object at 0x7f303851c640>
  File "/home/chase/.local/lib/python3.8/site-packages/sqlalchemy/engine/base.py", line 1452, in _execute_clauseelement
    ret = self._execute_context(
          │    └ <function Connection._execute_context at 0x7f31f39bc8b0>
          └ <sqlalchemy.engine.base.Connection object at 0x7f303851c640>
  File "/home/chase/.local/lib/python3.8/site-packages/sqlalchemy/engine/base.py", line 1814, in _execute_context
    self._handle_dbapi_exception(
    │    └ <function Connection._handle_dbapi_exception at 0x7f31f39bca60>
    └ <sqlalchemy.engine.base.Connection object at 0x7f303851c640>
  File "/home/chase/.local/lib/python3.8/site-packages/sqlalchemy/engine/base.py", line 1995, in _handle_dbapi_exception
    util.raise_(
    │    └ <function raise_ at 0x7f31f3d7ea60>
    └ <module 'sqlalchemy.util' from '/home/chase/.local/lib/python3.8/site-packages/sqlalchemy/util/__init__.py'>
  File "/home/chase/.local/lib/python3.8/site-packages/sqlalchemy/util/compat.py", line 207, in raise_
    raise exception
  File "/home/chase/.local/lib/python3.8/site-packages/sqlalchemy/engine/base.py", line 1771, in _execute_context
    self.dialect.do_execute(
    │    │       └ <function DefaultDialect.do_execute at 0x7f31f38f75e0>
    │    └ <sqlalchemy.dialects.mysql.pymysql.MySQLDialect_pymysql object at 0x7f3103ffde20>
    └ <sqlalchemy.engine.base.Connection object at 0x7f303851c640>
  File "/home/chase/.local/lib/python3.8/site-packages/sqlalchemy/engine/default.py", line 717, in do_execute
    cursor.execute(statement, parameters)
    │      │       │          └ {'server_id': '180.201.163.246:6800', 'ip': '180.201.163.246', 'username': 'chase', 'password': '5919960971819907291210157900...
    │      │       └ 'UPDATE device SET server_id=%(server_id)s, ip=%(ip)s, username=%(username)s, password=%(password)s, address=%(address)s, por...
    │      └ <function Cursor.execute at 0x7f31f354cdc0>
    └ <pymysql.cursors.Cursor object at 0x7f30d825b5e0>
  File "/home/chase/.local/lib/python3.8/site-packages/pymysql/cursors.py", line 148, in execute
    result = self._query(query)
             │    │      └ "UPDATE device SET server_id='180.201.163.246:6800', ip='180.201.163.246', username='chase', password='5919960971819907291210...
             │    └ <function Cursor._query at 0x7f31f34d7280>
             └ <pymysql.cursors.Cursor object at 0x7f30d825b5e0>
  File "/home/chase/.local/lib/python3.8/site-packages/pymysql/cursors.py", line 310, in _query
    conn.query(q)
    │    │     └ "UPDATE device SET server_id='180.201.163.246:6800', ip='180.201.163.246', username='chase', password='5919960971819907291210...
    │    └ <function Connection.query at 0x7f31f34e5670>
    └ <pymysql.connections.Connection object at 0x7f31020c9e80>
  File "/home/chase/.local/lib/python3.8/site-packages/pymysql/connections.py", line 548, in query
    self._affected_rows = self._read_query_result(unbuffered=unbuffered)
    │    │                │    │                             └ False
    │    │                │    └ <function Connection._read_query_result at 0x7f31f34e5ca0>
    │    │                └ <pymysql.connections.Connection object at 0x7f31020c9e80>
    │    └ 1
    └ <pymysql.connections.Connection object at 0x7f31020c9e80>
  File "/home/chase/.local/lib/python3.8/site-packages/pymysql/connections.py", line 775, in _read_query_result
    result.read()
    │      └ <function MySQLResult.read at 0x7f31f34e64c0>
    └ <pymysql.connections.MySQLResult object at 0x7f3102299d00>
  File "/home/chase/.local/lib/python3.8/site-packages/pymysql/connections.py", line 1156, in read
    first_packet = self.connection._read_packet()
                   │    └ None
                   └ <pymysql.connections.MySQLResult object at 0x7f3102299d00>
  File "/home/chase/.local/lib/python3.8/site-packages/pymysql/connections.py", line 725, in _read_packet
    packet.raise_for_error()
    │      └ <function MysqlPacket.raise_for_error at 0x7f31f34ddee0>
    └ <pymysql.protocol.MysqlPacket object at 0x7f30d80b30a0>
  File "/home/chase/.local/lib/python3.8/site-packages/pymysql/protocol.py", line 221, in raise_for_error
    err.raise_mysql_exception(self._data)
    │   │                     │    └ <member '_data' of 'MysqlPacket' objects>
    │   │                     └ <pymysql.protocol.MysqlPacket object at 0x7f30d80b30a0>
    │   └ <function raise_mysql_exception at 0x7f31f358c670>
    └ <module 'pymysql.err' from '/home/chase/.local/lib/python3.8/site-packages/pymysql/err.py'>
  File "/home/chase/.local/lib/python3.8/site-packages/pymysql/err.py", line 143, in raise_mysql_exception
    raise errorclass(errno, errval)
          │          │      └ "Duplicate entry '180.201.163.246:6800' for key 'device.PRIMARY'"
          │          └ 1062
          └ <class 'pymysql.err.IntegrityError'>

sqlalchemy.exc.IntegrityError: (pymysql.err.IntegrityError) (1062, "Duplicate entry '180.201.163.246:6800' for key 'device.PRIMARY'")
[SQL: UPDATE device SET server_id=%(server_id)s, ip=%(ip)s, username=%(username)s, password=%(password)s, address=%(address)s, port=%(port)s, valid=%(valid)s WHERE device.ip = %(ip_1)s]
[parameters: {'server_id': '180.201.163.246:6800', 'ip': '180.201.163.246', 'username': 'chase', 'password': '59199609718199072912101579002747496032699156200813645687491245265705055419976799299320941775283585185117234478779625773555171813340857636680797969476 ... (10 characters truncated) ... 63251260501617576147066081304139635402139116560702205929183429838944551392225480623734830852813224670127567860583183289845874226343617054561453697319', 'address': '/home/users/CT/pycharmproject/spiders/', 'port': 6800, 'valid': 1, 'ip_1': '180.201.163.246'}]
(Background on this error at: https://sqlalche.me/e/14/gkpj)
2022-05-14 02:55:58.173 | ERROR    | base.db.mysql:update:390 - 【mysql更新数据出错】
Traceback (most recent call last):

  File "/home/chase/.local/lib/python3.8/site-packages/sqlalchemy/engine/base.py", line 1771, in _execute_context
    self.dialect.do_execute(
    │    │       └ <function DefaultDialect.do_execute at 0x7f31f38f75e0>
    │    └ <sqlalchemy.dialects.mysql.pymysql.MySQLDialect_pymysql object at 0x7f3103ffde20>
    └ <sqlalchemy.engine.base.Connection object at 0x7f3102024ee0>
  File "/home/chase/.local/lib/python3.8/site-packages/sqlalchemy/engine/default.py", line 717, in do_execute
    cursor.execute(statement, parameters)
    │      │       │          └ {'server_id': '180.201.163.246:6800', 'ip': '180.201.163.246', 'username': 'chase', 'password': '4027043599937349359725464389...
    │      │       └ 'UPDATE device SET server_id=%(server_id)s, ip=%(ip)s, username=%(username)s, password=%(password)s, address=%(address)s, por...
    │      └ <function Cursor.execute at 0x7f31f354cdc0>
    └ <pymysql.cursors.Cursor object at 0x7f30782e6520>
  File "/home/chase/.local/lib/python3.8/site-packages/pymysql/cursors.py", line 148, in execute
    result = self._query(query)
             │    │      └ "UPDATE device SET server_id='180.201.163.246:6800', ip='180.201.163.246', username='chase', password='4027043599937349359725...
             │    └ <function Cursor._query at 0x7f31f34d7280>
             └ <pymysql.cursors.Cursor object at 0x7f30782e6520>
  File "/home/chase/.local/lib/python3.8/site-packages/pymysql/cursors.py", line 310, in _query
    conn.query(q)
    │    │     └ "UPDATE device SET server_id='180.201.163.246:6800', ip='180.201.163.246', username='chase', password='4027043599937349359725...
    │    └ <function Connection.query at 0x7f31f34e5670>
    └ <pymysql.connections.Connection object at 0x7f3098687b50>
  File "/home/chase/.local/lib/python3.8/site-packages/pymysql/connections.py", line 548, in query
    self._affected_rows = self._read_query_result(unbuffered=unbuffered)
    │    │                │    │                             └ False
    │    │                │    └ <function Connection._read_query_result at 0x7f31f34e5ca0>
    │    │                └ <pymysql.connections.Connection object at 0x7f3098687b50>
    │    └ 1
    └ <pymysql.connections.Connection object at 0x7f3098687b50>
  File "/home/chase/.local/lib/python3.8/site-packages/pymysql/connections.py", line 775, in _read_query_result
    result.read()
    │      └ <function MySQLResult.read at 0x7f31f34e64c0>
    └ <pymysql.connections.MySQLResult object at 0x7f30d82fc070>
  File "/home/chase/.local/lib/python3.8/site-packages/pymysql/connections.py", line 1156, in read
    first_packet = self.connection._read_packet()
                   │    └ None
                   └ <pymysql.connections.MySQLResult object at 0x7f30d82fc070>
  File "/home/chase/.local/lib/python3.8/site-packages/pymysql/connections.py", line 725, in _read_packet
    packet.raise_for_error()
    │      └ <function MysqlPacket.raise_for_error at 0x7f31f34ddee0>
    └ <pymysql.protocol.MysqlPacket object at 0x7f3100347670>
  File "/home/chase/.local/lib/python3.8/site-packages/pymysql/protocol.py", line 221, in raise_for_error
    err.raise_mysql_exception(self._data)
    │   │                     │    └ <member '_data' of 'MysqlPacket' objects>
    │   │                     └ <pymysql.protocol.MysqlPacket object at 0x7f3100347670>
    │   └ <function raise_mysql_exception at 0x7f31f358c670>
    └ <module 'pymysql.err' from '/home/chase/.local/lib/python3.8/site-packages/pymysql/err.py'>
  File "/home/chase/.local/lib/python3.8/site-packages/pymysql/err.py", line 143, in raise_mysql_exception
    raise errorclass(errno, errval)
          │          │      └ "Duplicate entry '180.201.163.246:6800' for key 'device.PRIMARY'"
          │          └ 1062
          └ <class 'pymysql.err.IntegrityError'>

pymysql.err.IntegrityError: (1062, "Duplicate entry '180.201.163.246:6800' for key 'device.PRIMARY'")


The above exception was the direct cause of the following exception:


Traceback (most recent call last):

  File "/usr/lib/python3.8/threading.py", line 890, in _bootstrap
    self._bootstrap_inner()
    │    └ <function Thread._bootstrap_inner at 0x7f321bf29a60>
    └ <Thread(Thread-9098, started daemon 139838983378688)>
  File "/usr/lib/python3.8/threading.py", line 932, in _bootstrap_inner
    self.run()
    │    └ <function Thread.run at 0x7f321bf29790>
    └ <Thread(Thread-9098, started daemon 139838983378688)>
  File "/usr/lib/python3.8/threading.py", line 870, in run
    self._target(*self._args, **self._kwargs)
    │    │        │    │        │    └ {}
    │    │        │    │        └ <Thread(Thread-9098, started daemon 139838983378688)>
    │    │        │    └ ('ProjectManager.run_func_by_thread',)
    │    │        └ <Thread(Thread-9098, started daemon 139838983378688)>
    │    └ <bound method ProjectManager.get_request_from_keywords_hot of <monitor.projectManager.ProjectManager object at 0x7f31042e52e0>>
    └ <Thread(Thread-9098, started daemon 139838983378688)>

  File "/home/users/Scy/yuqing/spider/monitor/projectManager.py", line 799, in get_request_from_keywords_hot
    self.start_finished_spider_every_interval(project_names)
    │    │                                    └ ['default', 'test']
    │    └ <function ProjectManager.start_finished_spider_every_interval at 0x7f3104005280>
    └ <monitor.projectManager.ProjectManager object at 0x7f31042e52e0>

  File "/home/users/Scy/yuqing/spider/monitor/projectManager.py", line 784, in start_finished_spider_every_interval
    self[name].start_spider()
    │    └ 'default'
    └ <monitor.projectManager.ProjectManager object at 0x7f31042e52e0>

  File "/home/users/Scy/yuqing/spider/monitor/projectManager.py", line 366, in start_spider
    self.update_device_valid(device)
    │    │                   └ <monitor.deviceManager.DeviceC object at 0x7f3104029220>
    │    └ <function Project.update_device_valid at 0x7f3104003280>
    └ <monitor.projectManager.Project object at 0x7f3104029460>

  File "/home/users/Scy/yuqing/spider/monitor/projectManager.py", line 421, in update_device_valid
    self.database_manager.mysql.update(Device(**device.to_item()))
    │    │                │     │      │        │      └ <function DeviceC.to_item at 0x7f31f34ed310>
    │    │                │     │      │        └ <monitor.deviceManager.DeviceC object at 0x7f3104029220>
    │    │                │     │      └ <class 'base.db.mysql.Device'>
    │    │                │     └ <function Mysql.update at 0x7f31f35f4790>
    │    │                └ <base.db.mysql.Mysql object at 0x7f3103ffdfd0>
    │    └ <base.db.dbSlot.Slot object at 0x7f3103ffdf10>
    └ <monitor.projectManager.Project object at 0x7f3104029460>

> File "/home/users/Scy/yuqing/spider/base/db/mysql.py", line 375, in update
    row.update(new)
    │   │      └ {'server_id': '180.201.163.246:6800', 'ip': '180.201.163.246', 'username': 'chase', 'password': '4027043599937349359725464389...
    │   └ <function Query.update at 0x7f31f37333a0>
    └ <sqlalchemy.orm.query.Query object at 0x7f3102205cd0>

  File "/home/chase/.local/lib/python3.8/site-packages/sqlalchemy/orm/query.py", line 3221, in update
    result = self.session.execute(
             │    │       └ <function Session.execute at 0x7f31f370faf0>
             │    └ <sqlalchemy.orm.session.Session object at 0x7f3100092040>
             └ <sqlalchemy.orm.query.Query object at 0x7f3102205cd0>
  File "/home/chase/.local/lib/python3.8/site-packages/sqlalchemy/orm/session.py", line 1689, in execute
    result = conn._execute_20(statement, params or {}, execution_options)
             │    │           │          │             └ immutabledict({'synchronize_session': 'evaluate', '_sa_orm_update_options': default_update_options(_matched_objects=[], _reso...
             │    │           │          └ immutabledict({})
             │    │           └ <sqlalchemy.sql.annotation.AnnotatedUpdate object at 0x7f31001823a0>
             │    └ <function Connection._execute_20 at 0x7f31f39bc790>
             └ <sqlalchemy.engine.base.Connection object at 0x7f3102024ee0>
  File "/home/chase/.local/lib/python3.8/site-packages/sqlalchemy/engine/base.py", line 1583, in _execute_20
    return meth(self, args_10style, kwargs_10style, execution_options)
           │    │     │             │               └ immutabledict({'synchronize_session': 'evaluate', '_sa_orm_update_options': default_update_options(_matched_objects=[], _reso...
           │    │     │             └ immutabledict({})
           │    │     └ ({},)
           │    └ <sqlalchemy.engine.base.Connection object at 0x7f3102024ee0>
           └ <bound method ClauseElement._execute_on_connection of <sqlalchemy.sql.annotation.AnnotatedUpdate object at 0x7f31001823a0>>
  File "/home/chase/.local/lib/python3.8/site-packages/sqlalchemy/sql/elements.py", line 323, in _execute_on_connection
    return connection._execute_clauseelement(
           │          └ <function Connection._execute_clauseelement at 0x7f31f39bc5e0>
           └ <sqlalchemy.engine.base.Connection object at 0x7f3102024ee0>
  File "/home/chase/.local/lib/python3.8/site-packages/sqlalchemy/engine/base.py", line 1452, in _execute_clauseelement
    ret = self._execute_context(
          │    └ <function Connection._execute_context at 0x7f31f39bc8b0>
          └ <sqlalchemy.engine.base.Connection object at 0x7f3102024ee0>
  File "/home/chase/.local/lib/python3.8/site-packages/sqlalchemy/engine/base.py", line 1814, in _execute_context
    self._handle_dbapi_exception(
    │    └ <function Connection._handle_dbapi_exception at 0x7f31f39bca60>
    └ <sqlalchemy.engine.base.Connection object at 0x7f3102024ee0>
  File "/home/chase/.local/lib/python3.8/site-packages/sqlalchemy/engine/base.py", line 1995, in _handle_dbapi_exception
    util.raise_(
    │    └ <function raise_ at 0x7f31f3d7ea60>
    └ <module 'sqlalchemy.util' from '/home/chase/.local/lib/python3.8/site-packages/sqlalchemy/util/__init__.py'>
  File "/home/chase/.local/lib/python3.8/site-packages/sqlalchemy/util/compat.py", line 207, in raise_
    raise exception
  File "/home/chase/.local/lib/python3.8/site-packages/sqlalchemy/engine/base.py", line 1771, in _execute_context
    self.dialect.do_execute(
    │    │       └ <function DefaultDialect.do_execute at 0x7f31f38f75e0>
    │    └ <sqlalchemy.dialects.mysql.pymysql.MySQLDialect_pymysql object at 0x7f3103ffde20>
    └ <sqlalchemy.engine.base.Connection object at 0x7f3102024ee0>
  File "/home/chase/.local/lib/python3.8/site-packages/sqlalchemy/engine/default.py", line 717, in do_execute
    cursor.execute(statement, parameters)
    │      │       │          └ {'server_id': '180.201.163.246:6800', 'ip': '180.201.163.246', 'username': 'chase', 'password': '4027043599937349359725464389...
    │      │       └ 'UPDATE device SET server_id=%(server_id)s, ip=%(ip)s, username=%(username)s, password=%(password)s, address=%(address)s, por...
    │      └ <function Cursor.execute at 0x7f31f354cdc0>
    └ <pymysql.cursors.Cursor object at 0x7f30782e6520>
  File "/home/chase/.local/lib/python3.8/site-packages/pymysql/cursors.py", line 148, in execute
    result = self._query(query)
             │    │      └ "UPDATE device SET server_id='180.201.163.246:6800', ip='180.201.163.246', username='chase', password='4027043599937349359725...
             │    └ <function Cursor._query at 0x7f31f34d7280>
             └ <pymysql.cursors.Cursor object at 0x7f30782e6520>
  File "/home/chase/.local/lib/python3.8/site-packages/pymysql/cursors.py", line 310, in _query
    conn.query(q)
    │    │     └ "UPDATE device SET server_id='180.201.163.246:6800', ip='180.201.163.246', username='chase', password='4027043599937349359725...
    │    └ <function Connection.query at 0x7f31f34e5670>
    └ <pymysql.connections.Connection object at 0x7f3098687b50>
  File "/home/chase/.local/lib/python3.8/site-packages/pymysql/connections.py", line 548, in query
    self._affected_rows = self._read_query_result(unbuffered=unbuffered)
    │    │                │    │                             └ False
    │    │                │    └ <function Connection._read_query_result at 0x7f31f34e5ca0>
    │    │                └ <pymysql.connections.Connection object at 0x7f3098687b50>
    │    └ 1
    └ <pymysql.connections.Connection object at 0x7f3098687b50>
  File "/home/chase/.local/lib/python3.8/site-packages/pymysql/connections.py", line 775, in _read_query_result
    result.read()
    │      └ <function MySQLResult.read at 0x7f31f34e64c0>
    └ <pymysql.connections.MySQLResult object at 0x7f30d82fc070>
  File "/home/chase/.local/lib/python3.8/site-packages/pymysql/connections.py", line 1156, in read
    first_packet = self.connection._read_packet()
                   │    └ None
                   └ <pymysql.connections.MySQLResult object at 0x7f30d82fc070>
  File "/home/chase/.local/lib/python3.8/site-packages/pymysql/connections.py", line 725, in _read_packet
    packet.raise_for_error()
    │      └ <function MysqlPacket.raise_for_error at 0x7f31f34ddee0>
    └ <pymysql.protocol.MysqlPacket object at 0x7f3100347670>
  File "/home/chase/.local/lib/python3.8/site-packages/pymysql/protocol.py", line 221, in raise_for_error
    err.raise_mysql_exception(self._data)
    │   │                     │    └ <member '_data' of 'MysqlPacket' objects>
    │   │                     └ <pymysql.protocol.MysqlPacket object at 0x7f3100347670>
    │   └ <function raise_mysql_exception at 0x7f31f358c670>
    └ <module 'pymysql.err' from '/home/chase/.local/lib/python3.8/site-packages/pymysql/err.py'>
  File "/home/chase/.local/lib/python3.8/site-packages/pymysql/err.py", line 143, in raise_mysql_exception
    raise errorclass(errno, errval)
          │          │      └ "Duplicate entry '180.201.163.246:6800' for key 'device.PRIMARY'"
          │          └ 1062
          └ <class 'pymysql.err.IntegrityError'>

sqlalchemy.exc.IntegrityError: (pymysql.err.IntegrityError) (1062, "Duplicate entry '180.201.163.246:6800' for key 'device.PRIMARY'")
[SQL: UPDATE device SET server_id=%(server_id)s, ip=%(ip)s, username=%(username)s, password=%(password)s, address=%(address)s, port=%(port)s, valid=%(valid)s WHERE device.ip = %(ip_1)s]
[parameters: {'server_id': '180.201.163.246:6800', 'ip': '180.201.163.246', 'username': 'chase', 'password': '40270435999373493597254643898253925706072011756673153746679664565005853287810736726167100645987767250169782469539252316358936911102452751717886285383 ... (10 characters truncated) ... 91885651847666803052809262055029275848214331689228276558985500889251856545724556686765038478530879246792739951243877655936354848609856790536027495510', 'address': '/home/users/CT/pycharmproject/spiders/', 'port': 6800, 'valid': 1, 'ip_1': '180.201.163.246'}]
(Background on this error at: https://sqlalche.me/e/14/gkpj)
2022-05-14 02:56:16.545 | ERROR    | base.db.mysql:update:390 - 【mysql更新数据出错】
Traceback (most recent call last):

  File "/home/chase/.local/lib/python3.8/site-packages/sqlalchemy/engine/base.py", line 1771, in _execute_context
    self.dialect.do_execute(
    │    │       └ <function DefaultDialect.do_execute at 0x7f31f38f75e0>
    │    └ <sqlalchemy.dialects.mysql.pymysql.MySQLDialect_pymysql object at 0x7f3103ffde20>
    └ <sqlalchemy.engine.base.Connection object at 0x7f30b83b90a0>
  File "/home/chase/.local/lib/python3.8/site-packages/sqlalchemy/engine/default.py", line 717, in do_execute
    cursor.execute(statement, parameters)
    │      │       │          └ {'server_id': '180.201.163.246:6800', 'ip': '180.201.163.246', 'username': 'chase', 'password': '3007574850514612810947151664...
    │      │       └ 'UPDATE device SET server_id=%(server_id)s, ip=%(ip)s, username=%(username)s, password=%(password)s, address=%(address)s, por...
    │      └ <function Cursor.execute at 0x7f31f354cdc0>
    └ <pymysql.cursors.Cursor object at 0x7f3038160a00>
  File "/home/chase/.local/lib/python3.8/site-packages/pymysql/cursors.py", line 148, in execute
    result = self._query(query)
             │    │      └ "UPDATE device SET server_id='180.201.163.246:6800', ip='180.201.163.246', username='chase', password='3007574850514612810947...
             │    └ <function Cursor._query at 0x7f31f34d7280>
             └ <pymysql.cursors.Cursor object at 0x7f3038160a00>
  File "/home/chase/.local/lib/python3.8/site-packages/pymysql/cursors.py", line 310, in _query
    conn.query(q)
    │    │     └ "UPDATE device SET server_id='180.201.163.246:6800', ip='180.201.163.246', username='chase', password='3007574850514612810947...
    │    └ <function Connection.query at 0x7f31f34e5670>
    └ <pymysql.connections.Connection object at 0x7f3018153d00>
  File "/home/chase/.local/lib/python3.8/site-packages/pymysql/connections.py", line 548, in query
    self._affected_rows = self._read_query_result(unbuffered=unbuffered)
    │    │                │    │                             └ False
    │    │                │    └ <function Connection._read_query_result at 0x7f31f34e5ca0>
    │    │                └ <pymysql.connections.Connection object at 0x7f3018153d00>
    │    └ 1
    └ <pymysql.connections.Connection object at 0x7f3018153d00>
  File "/home/chase/.local/lib/python3.8/site-packages/pymysql/connections.py", line 775, in _read_query_result
    result.read()
    │      └ <function MySQLResult.read at 0x7f31f34e64c0>
    └ <pymysql.connections.MySQLResult object at 0x7f30d82fc130>
  File "/home/chase/.local/lib/python3.8/site-packages/pymysql/connections.py", line 1156, in read
    first_packet = self.connection._read_packet()
                   │    └ None
                   └ <pymysql.connections.MySQLResult object at 0x7f30d82fc130>
  File "/home/chase/.local/lib/python3.8/site-packages/pymysql/connections.py", line 725, in _read_packet
    packet.raise_for_error()
    │      └ <function MysqlPacket.raise_for_error at 0x7f31f34ddee0>
    └ <pymysql.protocol.MysqlPacket object at 0x7f2fb81c1520>
  File "/home/chase/.local/lib/python3.8/site-packages/pymysql/protocol.py", line 221, in raise_for_error
    err.raise_mysql_exception(self._data)
    │   │                     │    └ <member '_data' of 'MysqlPacket' objects>
    │   │                     └ <pymysql.protocol.MysqlPacket object at 0x7f2fb81c1520>
    │   └ <function raise_mysql_exception at 0x7f31f358c670>
    └ <module 'pymysql.err' from '/home/chase/.local/lib/python3.8/site-packages/pymysql/err.py'>
  File "/home/chase/.local/lib/python3.8/site-packages/pymysql/err.py", line 143, in raise_mysql_exception
    raise errorclass(errno, errval)
          │          │      └ "Duplicate entry '180.201.163.246:6800' for key 'device.PRIMARY'"
          │          └ 1062
          └ <class 'pymysql.err.IntegrityError'>

pymysql.err.IntegrityError: (1062, "Duplicate entry '180.201.163.246:6800' for key 'device.PRIMARY'")


The above exception was the direct cause of the following exception:


Traceback (most recent call last):

  File "/usr/lib/python3.8/threading.py", line 890, in _bootstrap
    self._bootstrap_inner()
    │    └ <function Thread._bootstrap_inner at 0x7f321bf29a60>
    └ <Thread(Thread-9103, started daemon 139839000164096)>
  File "/usr/lib/python3.8/threading.py", line 932, in _bootstrap_inner
    self.run()
    │    └ <function Thread.run at 0x7f321bf29790>
    └ <Thread(Thread-9103, started daemon 139839000164096)>
  File "/usr/lib/python3.8/threading.py", line 870, in run
    self._target(*self._args, **self._kwargs)
    │    │        │    │        │    └ {}
    │    │        │    │        └ <Thread(Thread-9103, started daemon 139839000164096)>
    │    │        │    └ ('ProjectManager.run_func_by_thread',)
    │    │        └ <Thread(Thread-9103, started daemon 139839000164096)>
    │    └ <bound method ProjectManager.get_request_from_keywords_hot of <monitor.projectManager.ProjectManager object at 0x7f31042e52e0>>
    └ <Thread(Thread-9103, started daemon 139839000164096)>

  File "/home/users/Scy/yuqing/spider/monitor/projectManager.py", line 799, in get_request_from_keywords_hot
    self.start_finished_spider_every_interval(project_names)
    │    │                                    └ ['default', 'test']
    │    └ <function ProjectManager.start_finished_spider_every_interval at 0x7f3104005280>
    └ <monitor.projectManager.ProjectManager object at 0x7f31042e52e0>

  File "/home/users/Scy/yuqing/spider/monitor/projectManager.py", line 784, in start_finished_spider_every_interval
    self[name].start_spider()
    │    └ 'default'
    └ <monitor.projectManager.ProjectManager object at 0x7f31042e52e0>

  File "/home/users/Scy/yuqing/spider/monitor/projectManager.py", line 366, in start_spider
    self.update_device_valid(device)
    │    │                   └ <monitor.deviceManager.DeviceC object at 0x7f3104029220>
    │    └ <function Project.update_device_valid at 0x7f3104003280>
    └ <monitor.projectManager.Project object at 0x7f3104029460>

  File "/home/users/Scy/yuqing/spider/monitor/projectManager.py", line 421, in update_device_valid
    self.database_manager.mysql.update(Device(**device.to_item()))
    │    │                │     │      │        │      └ <function DeviceC.to_item at 0x7f31f34ed310>
    │    │                │     │      │        └ <monitor.deviceManager.DeviceC object at 0x7f3104029220>
    │    │                │     │      └ <class 'base.db.mysql.Device'>
    │    │                │     └ <function Mysql.update at 0x7f31f35f4790>
    │    │                └ <base.db.mysql.Mysql object at 0x7f3103ffdfd0>
    │    └ <base.db.dbSlot.Slot object at 0x7f3103ffdf10>
    └ <monitor.projectManager.Project object at 0x7f3104029460>

> File "/home/users/Scy/yuqing/spider/base/db/mysql.py", line 375, in update
    row.update(new)
    │   │      └ {'server_id': '180.201.163.246:6800', 'ip': '180.201.163.246', 'username': 'chase', 'password': '3007574850514612810947151664...
    │   └ <function Query.update at 0x7f31f37333a0>
    └ <sqlalchemy.orm.query.Query object at 0x7f30b815d520>

  File "/home/chase/.local/lib/python3.8/site-packages/sqlalchemy/orm/query.py", line 3221, in update
    result = self.session.execute(
             │    │       └ <function Session.execute at 0x7f31f370faf0>
             │    └ <sqlalchemy.orm.session.Session object at 0x7f3100156d90>
             └ <sqlalchemy.orm.query.Query object at 0x7f30b815d520>
  File "/home/chase/.local/lib/python3.8/site-packages/sqlalchemy/orm/session.py", line 1689, in execute
    result = conn._execute_20(statement, params or {}, execution_options)
             │    │           │          │             └ immutabledict({'synchronize_session': 'evaluate', '_sa_orm_update_options': default_update_options(_matched_objects=[], _reso...
             │    │           │          └ immutabledict({})
             │    │           └ <sqlalchemy.sql.annotation.AnnotatedUpdate object at 0x7f30786ea6d0>
             │    └ <function Connection._execute_20 at 0x7f31f39bc790>
             └ <sqlalchemy.engine.base.Connection object at 0x7f30b83b90a0>
  File "/home/chase/.local/lib/python3.8/site-packages/sqlalchemy/engine/base.py", line 1583, in _execute_20
    return meth(self, args_10style, kwargs_10style, execution_options)
           │    │     │             │               └ immutabledict({'synchronize_session': 'evaluate', '_sa_orm_update_options': default_update_options(_matched_objects=[], _reso...
           │    │     │             └ immutabledict({})
           │    │     └ ({},)
           │    └ <sqlalchemy.engine.base.Connection object at 0x7f30b83b90a0>
           └ <bound method ClauseElement._execute_on_connection of <sqlalchemy.sql.annotation.AnnotatedUpdate object at 0x7f30786ea6d0>>
  File "/home/chase/.local/lib/python3.8/site-packages/sqlalchemy/sql/elements.py", line 323, in _execute_on_connection
    return connection._execute_clauseelement(
           │          └ <function Connection._execute_clauseelement at 0x7f31f39bc5e0>
           └ <sqlalchemy.engine.base.Connection object at 0x7f30b83b90a0>
  File "/home/chase/.local/lib/python3.8/site-packages/sqlalchemy/engine/base.py", line 1452, in _execute_clauseelement
    ret = self._execute_context(
          │    └ <function Connection._execute_context at 0x7f31f39bc8b0>
          └ <sqlalchemy.engine.base.Connection object at 0x7f30b83b90a0>
  File "/home/chase/.local/lib/python3.8/site-packages/sqlalchemy/engine/base.py", line 1814, in _execute_context
    self._handle_dbapi_exception(
    │    └ <function Connection._handle_dbapi_exception at 0x7f31f39bca60>
    └ <sqlalchemy.engine.base.Connection object at 0x7f30b83b90a0>
  File "/home/chase/.local/lib/python3.8/site-packages/sqlalchemy/engine/base.py", line 1995, in _handle_dbapi_exception
    util.raise_(
    │    └ <function raise_ at 0x7f31f3d7ea60>
    └ <module 'sqlalchemy.util' from '/home/chase/.local/lib/python3.8/site-packages/sqlalchemy/util/__init__.py'>
  File "/home/chase/.local/lib/python3.8/site-packages/sqlalchemy/util/compat.py", line 207, in raise_
    raise exception
  File "/home/chase/.local/lib/python3.8/site-packages/sqlalchemy/engine/base.py", line 1771, in _execute_context
    self.dialect.do_execute(
    │    │       └ <function DefaultDialect.do_execute at 0x7f31f38f75e0>
    │    └ <sqlalchemy.dialects.mysql.pymysql.MySQLDialect_pymysql object at 0x7f3103ffde20>
    └ <sqlalchemy.engine.base.Connection object at 0x7f30b83b90a0>
  File "/home/chase/.local/lib/python3.8/site-packages/sqlalchemy/engine/default.py", line 717, in do_execute
    cursor.execute(statement, parameters)
    │      │       │          └ {'server_id': '180.201.163.246:6800', 'ip': '180.201.163.246', 'username': 'chase', 'password': '3007574850514612810947151664...
    │      │       └ 'UPDATE device SET server_id=%(server_id)s, ip=%(ip)s, username=%(username)s, password=%(password)s, address=%(address)s, por...
    │      └ <function Cursor.execute at 0x7f31f354cdc0>
    └ <pymysql.cursors.Cursor object at 0x7f3038160a00>
  File "/home/chase/.local/lib/python3.8/site-packages/pymysql/cursors.py", line 148, in execute
    result = self._query(query)
             │    │      └ "UPDATE device SET server_id='180.201.163.246:6800', ip='180.201.163.246', username='chase', password='3007574850514612810947...
             │    └ <function Cursor._query at 0x7f31f34d7280>
             └ <pymysql.cursors.Cursor object at 0x7f3038160a00>
  File "/home/chase/.local/lib/python3.8/site-packages/pymysql/cursors.py", line 310, in _query
    conn.query(q)
    │    │     └ "UPDATE device SET server_id='180.201.163.246:6800', ip='180.201.163.246', username='chase', password='3007574850514612810947...
    │    └ <function Connection.query at 0x7f31f34e5670>
    └ <pymysql.connections.Connection object at 0x7f3018153d00>
  File "/home/chase/.local/lib/python3.8/site-packages/pymysql/connections.py", line 548, in query
    self._affected_rows = self._read_query_result(unbuffered=unbuffered)
    │    │                │    │                             └ False
    │    │                │    └ <function Connection._read_query_result at 0x7f31f34e5ca0>
    │    │                └ <pymysql.connections.Connection object at 0x7f3018153d00>
    │    └ 1
    └ <pymysql.connections.Connection object at 0x7f3018153d00>
  File "/home/chase/.local/lib/python3.8/site-packages/pymysql/connections.py", line 775, in _read_query_result
    result.read()
    │      └ <function MySQLResult.read at 0x7f31f34e64c0>
    └ <pymysql.connections.MySQLResult object at 0x7f30d82fc130>
  File "/home/chase/.local/lib/python3.8/site-packages/pymysql/connections.py", line 1156, in read
    first_packet = self.connection._read_packet()
                   │    └ None
                   └ <pymysql.connections.MySQLResult object at 0x7f30d82fc130>
  File "/home/chase/.local/lib/python3.8/site-packages/pymysql/connections.py", line 725, in _read_packet
    packet.raise_for_error()
    │      └ <function MysqlPacket.raise_for_error at 0x7f31f34ddee0>
    └ <pymysql.protocol.MysqlPacket object at 0x7f2fb81c1520>
  File "/home/chase/.local/lib/python3.8/site-packages/pymysql/protocol.py", line 221, in raise_for_error
    err.raise_mysql_exception(self._data)
    │   │                     │    └ <member '_data' of 'MysqlPacket' objects>
    │   │                     └ <pymysql.protocol.MysqlPacket object at 0x7f2fb81c1520>
    │   └ <function raise_mysql_exception at 0x7f31f358c670>
    └ <module 'pymysql.err' from '/home/chase/.local/lib/python3.8/site-packages/pymysql/err.py'>
  File "/home/chase/.local/lib/python3.8/site-packages/pymysql/err.py", line 143, in raise_mysql_exception
    raise errorclass(errno, errval)
          │          │      └ "Duplicate entry '180.201.163.246:6800' for key 'device.PRIMARY'"
          │          └ 1062
          └ <class 'pymysql.err.IntegrityError'>

sqlalchemy.exc.IntegrityError: (pymysql.err.IntegrityError) (1062, "Duplicate entry '180.201.163.246:6800' for key 'device.PRIMARY'")
[SQL: UPDATE device SET server_id=%(server_id)s, ip=%(ip)s, username=%(username)s, password=%(password)s, address=%(address)s, port=%(port)s, valid=%(valid)s WHERE device.ip = %(ip_1)s]
[parameters: {'server_id': '180.201.163.246:6800', 'ip': '180.201.163.246', 'username': 'chase', 'password': '30075748505146128109471516640866023669986826530315557613617641371654300362338330353395005382706469120085708380233291964241674441788739743340221633994 ... (10 characters truncated) ... 20746716513252823868334964574378017779415038131039700606034148805751691336025111416779087294254808182424959341281853432428958624913106522202218530542', 'address': '/home/users/CT/pycharmproject/spiders/', 'port': 6800, 'valid': 1, 'ip_1': '180.201.163.246'}]
(Background on this error at: https://sqlalche.me/e/14/gkpj)
2022-05-14 02:56:34.877 | ERROR    | base.db.mysql:update:390 - 【mysql更新数据出错】
Traceback (most recent call last):

  File "/home/chase/.local/lib/python3.8/site-packages/sqlalchemy/engine/base.py", line 1771, in _execute_context
    self.dialect.do_execute(
    │    │       └ <function DefaultDialect.do_execute at 0x7f31f38f75e0>
    │    └ <sqlalchemy.dialects.mysql.pymysql.MySQLDialect_pymysql object at 0x7f3103ffde20>
    └ <sqlalchemy.engine.base.Connection object at 0x7f30d85ab580>
  File "/home/chase/.local/lib/python3.8/site-packages/sqlalchemy/engine/default.py", line 717, in do_execute
    cursor.execute(statement, parameters)
    │      │       │          └ {'server_id': '180.201.163.246:6800', 'ip': '180.201.163.246', 'username': 'chase', 'password': '3543534745564213405957785021...
    │      │       └ 'UPDATE device SET server_id=%(server_id)s, ip=%(ip)s, username=%(username)s, password=%(password)s, address=%(address)s, por...
    │      └ <function Cursor.execute at 0x7f31f354cdc0>
    └ <pymysql.cursors.Cursor object at 0x7f310230d820>
  File "/home/chase/.local/lib/python3.8/site-packages/pymysql/cursors.py", line 148, in execute
    result = self._query(query)
             │    │      └ "UPDATE device SET server_id='180.201.163.246:6800', ip='180.201.163.246', username='chase', password='3543534745564213405957...
             │    └ <function Cursor._query at 0x7f31f34d7280>
             └ <pymysql.cursors.Cursor object at 0x7f310230d820>
  File "/home/chase/.local/lib/python3.8/site-packages/pymysql/cursors.py", line 310, in _query
    conn.query(q)
    │    │     └ "UPDATE device SET server_id='180.201.163.246:6800', ip='180.201.163.246', username='chase', password='3543534745564213405957...
    │    └ <function Connection.query at 0x7f31f34e5670>
    └ <pymysql.connections.Connection object at 0x7f30784fc790>
  File "/home/chase/.local/lib/python3.8/site-packages/pymysql/connections.py", line 548, in query
    self._affected_rows = self._read_query_result(unbuffered=unbuffered)
    │    │                │    │                             └ False
    │    │                │    └ <function Connection._read_query_result at 0x7f31f34e5ca0>
    │    │                └ <pymysql.connections.Connection object at 0x7f30784fc790>
    │    └ 1
    └ <pymysql.connections.Connection object at 0x7f30784fc790>
  File "/home/chase/.local/lib/python3.8/site-packages/pymysql/connections.py", line 775, in _read_query_result
    result.read()
    │      └ <function MySQLResult.read at 0x7f31f34e64c0>
    └ <pymysql.connections.MySQLResult object at 0x7f30b815e880>
  File "/home/chase/.local/lib/python3.8/site-packages/pymysql/connections.py", line 1156, in read
    first_packet = self.connection._read_packet()
                   │    └ None
                   └ <pymysql.connections.MySQLResult object at 0x7f30b815e880>
  File "/home/chase/.local/lib/python3.8/site-packages/pymysql/connections.py", line 725, in _read_packet
    packet.raise_for_error()
    │      └ <function MysqlPacket.raise_for_error at 0x7f31f34ddee0>
    └ <pymysql.protocol.MysqlPacket object at 0x7f2ff84a5cd0>
  File "/home/chase/.local/lib/python3.8/site-packages/pymysql/protocol.py", line 221, in raise_for_error
    err.raise_mysql_exception(self._data)
    │   │                     │    └ <member '_data' of 'MysqlPacket' objects>
    │   │                     └ <pymysql.protocol.MysqlPacket object at 0x7f2ff84a5cd0>
    │   └ <function raise_mysql_exception at 0x7f31f358c670>
    └ <module 'pymysql.err' from '/home/chase/.local/lib/python3.8/site-packages/pymysql/err.py'>
  File "/home/chase/.local/lib/python3.8/site-packages/pymysql/err.py", line 143, in raise_mysql_exception
    raise errorclass(errno, errval)
          │          │      └ "Duplicate entry '180.201.163.246:6800' for key 'device.PRIMARY'"
          │          └ 1062
          └ <class 'pymysql.err.IntegrityError'>

pymysql.err.IntegrityError: (1062, "Duplicate entry '180.201.163.246:6800' for key 'device.PRIMARY'")


The above exception was the direct cause of the following exception:


Traceback (most recent call last):

  File "/usr/lib/python3.8/threading.py", line 890, in _bootstrap
    self._bootstrap_inner()
    │    └ <function Thread._bootstrap_inner at 0x7f321bf29a60>
    └ <Thread(Thread-9107, started daemon 139838933022464)>
  File "/usr/lib/python3.8/threading.py", line 932, in _bootstrap_inner
    self.run()
    │    └ <function Thread.run at 0x7f321bf29790>
    └ <Thread(Thread-9107, started daemon 139838933022464)>
  File "/usr/lib/python3.8/threading.py", line 870, in run
    self._target(*self._args, **self._kwargs)
    │    │        │    │        │    └ {}
    │    │        │    │        └ <Thread(Thread-9107, started daemon 139838933022464)>
    │    │        │    └ ('ProjectManager.run_func_by_thread',)
    │    │        └ <Thread(Thread-9107, started daemon 139838933022464)>
    │    └ <bound method ProjectManager.get_request_from_keywords_hot of <monitor.projectManager.ProjectManager object at 0x7f31042e52e0>>
    └ <Thread(Thread-9107, started daemon 139838933022464)>

  File "/home/users/Scy/yuqing/spider/monitor/projectManager.py", line 799, in get_request_from_keywords_hot
    self.start_finished_spider_every_interval(project_names)
    │    │                                    └ ['default', 'test']
    │    └ <function ProjectManager.start_finished_spider_every_interval at 0x7f3104005280>
    └ <monitor.projectManager.ProjectManager object at 0x7f31042e52e0>

  File "/home/users/Scy/yuqing/spider/monitor/projectManager.py", line 784, in start_finished_spider_every_interval
    self[name].start_spider()
    │    └ 'default'
    └ <monitor.projectManager.ProjectManager object at 0x7f31042e52e0>

  File "/home/users/Scy/yuqing/spider/monitor/projectManager.py", line 366, in start_spider
    self.update_device_valid(device)
    │    │                   └ <monitor.deviceManager.DeviceC object at 0x7f3104029220>
    │    └ <function Project.update_device_valid at 0x7f3104003280>
    └ <monitor.projectManager.Project object at 0x7f3104029460>

  File "/home/users/Scy/yuqing/spider/monitor/projectManager.py", line 421, in update_device_valid
    self.database_manager.mysql.update(Device(**device.to_item()))
    │    │                │     │      │        │      └ <function DeviceC.to_item at 0x7f31f34ed310>
    │    │                │     │      │        └ <monitor.deviceManager.DeviceC object at 0x7f3104029220>
    │    │                │     │      └ <class 'base.db.mysql.Device'>
    │    │                │     └ <function Mysql.update at 0x7f31f35f4790>
    │    │                └ <base.db.mysql.Mysql object at 0x7f3103ffdfd0>
    │    └ <base.db.dbSlot.Slot object at 0x7f3103ffdf10>
    └ <monitor.projectManager.Project object at 0x7f3104029460>

> File "/home/users/Scy/yuqing/spider/base/db/mysql.py", line 375, in update
    row.update(new)
    │   │      └ {'server_id': '180.201.163.246:6800', 'ip': '180.201.163.246', 'username': 'chase', 'password': '3543534745564213405957785021...
    │   └ <function Query.update at 0x7f31f37333a0>
    └ <sqlalchemy.orm.query.Query object at 0x7f3038156520>

  File "/home/chase/.local/lib/python3.8/site-packages/sqlalchemy/orm/query.py", line 3221, in update
    result = self.session.execute(
             │    │       └ <function Session.execute at 0x7f31f370faf0>
             │    └ <sqlalchemy.orm.session.Session object at 0x7f3101f5f8b0>
             └ <sqlalchemy.orm.query.Query object at 0x7f3038156520>
  File "/home/chase/.local/lib/python3.8/site-packages/sqlalchemy/orm/session.py", line 1689, in execute
    result = conn._execute_20(statement, params or {}, execution_options)
             │    │           │          │             └ immutabledict({'synchronize_session': 'evaluate', '_sa_orm_update_options': default_update_options(_matched_objects=[], _reso...
             │    │           │          └ immutabledict({})
             │    │           └ <sqlalchemy.sql.annotation.AnnotatedUpdate object at 0x7f2fb860a970>
             │    └ <function Connection._execute_20 at 0x7f31f39bc790>
             └ <sqlalchemy.engine.base.Connection object at 0x7f30d85ab580>
  File "/home/chase/.local/lib/python3.8/site-packages/sqlalchemy/engine/base.py", line 1583, in _execute_20
    return meth(self, args_10style, kwargs_10style, execution_options)
           │    │     │             │               └ immutabledict({'synchronize_session': 'evaluate', '_sa_orm_update_options': default_update_options(_matched_objects=[], _reso...
           │    │     │             └ immutabledict({})
           │    │     └ ({},)
           │    └ <sqlalchemy.engine.base.Connection object at 0x7f30d85ab580>
           └ <bound method ClauseElement._execute_on_connection of <sqlalchemy.sql.annotation.AnnotatedUpdate object at 0x7f2fb860a970>>
  File "/home/chase/.local/lib/python3.8/site-packages/sqlalchemy/sql/elements.py", line 323, in _execute_on_connection
    return connection._execute_clauseelement(
           │          └ <function Connection._execute_clauseelement at 0x7f31f39bc5e0>
           └ <sqlalchemy.engine.base.Connection object at 0x7f30d85ab580>
  File "/home/chase/.local/lib/python3.8/site-packages/sqlalchemy/engine/base.py", line 1452, in _execute_clauseelement
    ret = self._execute_context(
          │    └ <function Connection._execute_context at 0x7f31f39bc8b0>
          └ <sqlalchemy.engine.base.Connection object at 0x7f30d85ab580>
  File "/home/chase/.local/lib/python3.8/site-packages/sqlalchemy/engine/base.py", line 1814, in _execute_context
    self._handle_dbapi_exception(
    │    └ <function Connection._handle_dbapi_exception at 0x7f31f39bca60>
    └ <sqlalchemy.engine.base.Connection object at 0x7f30d85ab580>
  File "/home/chase/.local/lib/python3.8/site-packages/sqlalchemy/engine/base.py", line 1995, in _handle_dbapi_exception
    util.raise_(
    │    └ <function raise_ at 0x7f31f3d7ea60>
    └ <module 'sqlalchemy.util' from '/home/chase/.local/lib/python3.8/site-packages/sqlalchemy/util/__init__.py'>
  File "/home/chase/.local/lib/python3.8/site-packages/sqlalchemy/util/compat.py", line 207, in raise_
    raise exception
  File "/home/chase/.local/lib/python3.8/site-packages/sqlalchemy/engine/base.py", line 1771, in _execute_context
    self.dialect.do_execute(
    │    │       └ <function DefaultDialect.do_execute at 0x7f31f38f75e0>
    │    └ <sqlalchemy.dialects.mysql.pymysql.MySQLDialect_pymysql object at 0x7f3103ffde20>
    └ <sqlalchemy.engine.base.Connection object at 0x7f30d85ab580>
  File "/home/chase/.local/lib/python3.8/site-packages/sqlalchemy/engine/default.py", line 717, in do_execute
    cursor.execute(statement, parameters)
    │      │       │          └ {'server_id': '180.201.163.246:6800', 'ip': '180.201.163.246', 'username': 'chase', 'password': '3543534745564213405957785021...
    │      │       └ 'UPDATE device SET server_id=%(server_id)s, ip=%(ip)s, username=%(username)s, password=%(password)s, address=%(address)s, por...
    │      └ <function Cursor.execute at 0x7f31f354cdc0>
    └ <pymysql.cursors.Cursor object at 0x7f310230d820>
  File "/home/chase/.local/lib/python3.8/site-packages/pymysql/cursors.py", line 148, in execute
    result = self._query(query)
             │    │      └ "UPDATE device SET server_id='180.201.163.246:6800', ip='180.201.163.246', username='chase', password='3543534745564213405957...
             │    └ <function Cursor._query at 0x7f31f34d7280>
             └ <pymysql.cursors.Cursor object at 0x7f310230d820>
  File "/home/chase/.local/lib/python3.8/site-packages/pymysql/cursors.py", line 310, in _query
    conn.query(q)
    │    │     └ "UPDATE device SET server_id='180.201.163.246:6800', ip='180.201.163.246', username='chase', password='3543534745564213405957...
    │    └ <function Connection.query at 0x7f31f34e5670>
    └ <pymysql.connections.Connection object at 0x7f30784fc790>
  File "/home/chase/.local/lib/python3.8/site-packages/pymysql/connections.py", line 548, in query
    self._affected_rows = self._read_query_result(unbuffered=unbuffered)
    │    │                │    │                             └ False
    │    │                │    └ <function Connection._read_query_result at 0x7f31f34e5ca0>
    │    │                └ <pymysql.connections.Connection object at 0x7f30784fc790>
    │    └ 1
    └ <pymysql.connections.Connection object at 0x7f30784fc790>
  File "/home/chase/.local/lib/python3.8/site-packages/pymysql/connections.py", line 775, in _read_query_result
    result.read()
    │      └ <function MySQLResult.read at 0x7f31f34e64c0>
    └ <pymysql.connections.MySQLResult object at 0x7f30b815e880>
  File "/home/chase/.local/lib/python3.8/site-packages/pymysql/connections.py", line 1156, in read
    first_packet = self.connection._read_packet()
                   │    └ None
                   └ <pymysql.connections.MySQLResult object at 0x7f30b815e880>
  File "/home/chase/.local/lib/python3.8/site-packages/pymysql/connections.py", line 725, in _read_packet
    packet.raise_for_error()
    │      └ <function MysqlPacket.raise_for_error at 0x7f31f34ddee0>
    └ <pymysql.protocol.MysqlPacket object at 0x7f2ff84a5cd0>
  File "/home/chase/.local/lib/python3.8/site-packages/pymysql/protocol.py", line 221, in raise_for_error
    err.raise_mysql_exception(self._data)
    │   │                     │    └ <member '_data' of 'MysqlPacket' objects>
    │   │                     └ <pymysql.protocol.MysqlPacket object at 0x7f2ff84a5cd0>
    │   └ <function raise_mysql_exception at 0x7f31f358c670>
    └ <module 'pymysql.err' from '/home/chase/.local/lib/python3.8/site-packages/pymysql/err.py'>
  File "/home/chase/.local/lib/python3.8/site-packages/pymysql/err.py", line 143, in raise_mysql_exception
    raise errorclass(errno, errval)
          │          │      └ "Duplicate entry '180.201.163.246:6800' for key 'device.PRIMARY'"
          │          └ 1062
          └ <class 'pymysql.err.IntegrityError'>

sqlalchemy.exc.IntegrityError: (pymysql.err.IntegrityError) (1062, "Duplicate entry '180.201.163.246:6800' for key 'device.PRIMARY'")
[SQL: UPDATE device SET server_id=%(server_id)s, ip=%(ip)s, username=%(username)s, password=%(password)s, address=%(address)s, port=%(port)s, valid=%(valid)s WHERE device.ip = %(ip_1)s]
[parameters: {'server_id': '180.201.163.246:6800', 'ip': '180.201.163.246', 'username': 'chase', 'password': '35435347455642134059577850214489868419300589522652680513752744202454070405807938578728973965434399796603910882632507122955347375606981029479001765146 ... (10 characters truncated) ... 99140829647169225286037898309907333998862068128148691952077843442077768168586406243339863351612176563021789313501939223837218361115788555060626011317', 'address': '/home/users/CT/pycharmproject/spiders/', 'port': 6800, 'valid': 1, 'ip_1': '180.201.163.246'}]
(Background on this error at: https://sqlalche.me/e/14/gkpj)
2022-05-14 02:56:53.557 | ERROR    | base.db.mysql:update:390 - 【mysql更新数据出错】
Traceback (most recent call last):

  File "/home/chase/.local/lib/python3.8/site-packages/sqlalchemy/engine/base.py", line 1771, in _execute_context
    self.dialect.do_execute(
    │    │       └ <function DefaultDialect.do_execute at 0x7f31f38f75e0>
    │    └ <sqlalchemy.dialects.mysql.pymysql.MySQLDialect_pymysql object at 0x7f3103ffde20>
    └ <sqlalchemy.engine.base.Connection object at 0x7f2fb8376bb0>
  File "/home/chase/.local/lib/python3.8/site-packages/sqlalchemy/engine/default.py", line 717, in do_execute
    cursor.execute(statement, parameters)
    │      │       │          └ {'server_id': '180.201.163.246:6800', 'ip': '180.201.163.246', 'username': 'chase', 'password': '7308331282958015650821971552...
    │      │       └ 'UPDATE device SET server_id=%(server_id)s, ip=%(ip)s, username=%(username)s, password=%(password)s, address=%(address)s, por...
    │      └ <function Cursor.execute at 0x7f31f354cdc0>
    └ <pymysql.cursors.Cursor object at 0x7f3100037310>
  File "/home/chase/.local/lib/python3.8/site-packages/pymysql/cursors.py", line 148, in execute
    result = self._query(query)
             │    │      └ "UPDATE device SET server_id='180.201.163.246:6800', ip='180.201.163.246', username='chase', password='7308331282958015650821...
             │    └ <function Cursor._query at 0x7f31f34d7280>
             └ <pymysql.cursors.Cursor object at 0x7f3100037310>
  File "/home/chase/.local/lib/python3.8/site-packages/pymysql/cursors.py", line 310, in _query
    conn.query(q)
    │    │     └ "UPDATE device SET server_id='180.201.163.246:6800', ip='180.201.163.246', username='chase', password='7308331282958015650821...
    │    └ <function Connection.query at 0x7f31f34e5670>
    └ <pymysql.connections.Connection object at 0x7f2f9842c910>
  File "/home/chase/.local/lib/python3.8/site-packages/pymysql/connections.py", line 548, in query
    self._affected_rows = self._read_query_result(unbuffered=unbuffered)
    │    │                │    │                             └ False
    │    │                │    └ <function Connection._read_query_result at 0x7f31f34e5ca0>
    │    │                └ <pymysql.connections.Connection object at 0x7f2f9842c910>
    │    └ 1
    └ <pymysql.connections.Connection object at 0x7f2f9842c910>
  File "/home/chase/.local/lib/python3.8/site-packages/pymysql/connections.py", line 775, in _read_query_result
    result.read()
    │      └ <function MySQLResult.read at 0x7f31f34e64c0>
    └ <pymysql.connections.MySQLResult object at 0x7f30782d2700>
  File "/home/chase/.local/lib/python3.8/site-packages/pymysql/connections.py", line 1156, in read
    first_packet = self.connection._read_packet()
                   │    └ None
                   └ <pymysql.connections.MySQLResult object at 0x7f30782d2700>
  File "/home/chase/.local/lib/python3.8/site-packages/pymysql/connections.py", line 725, in _read_packet
    packet.raise_for_error()
    │      └ <function MysqlPacket.raise_for_error at 0x7f31f34ddee0>
    └ <pymysql.protocol.MysqlPacket object at 0x7f30b814a730>
  File "/home/chase/.local/lib/python3.8/site-packages/pymysql/protocol.py", line 221, in raise_for_error
    err.raise_mysql_exception(self._data)
    │   │                     │    └ <member '_data' of 'MysqlPacket' objects>
    │   │                     └ <pymysql.protocol.MysqlPacket object at 0x7f30b814a730>
    │   └ <function raise_mysql_exception at 0x7f31f358c670>
    └ <module 'pymysql.err' from '/home/chase/.local/lib/python3.8/site-packages/pymysql/err.py'>
  File "/home/chase/.local/lib/python3.8/site-packages/pymysql/err.py", line 143, in raise_mysql_exception
    raise errorclass(errno, errval)
          │          │      └ "Duplicate entry '180.201.163.246:6800' for key 'device.PRIMARY'"
          │          └ 1062
          └ <class 'pymysql.err.IntegrityError'>

pymysql.err.IntegrityError: (1062, "Duplicate entry '180.201.163.246:6800' for key 'device.PRIMARY'")


The above exception was the direct cause of the following exception:


Traceback (most recent call last):

  File "/usr/lib/python3.8/threading.py", line 890, in _bootstrap
    self._bootstrap_inner()
    │    └ <function Thread._bootstrap_inner at 0x7f321bf29a60>
    └ <Thread(Thread-9111, started daemon 139838958200576)>
  File "/usr/lib/python3.8/threading.py", line 932, in _bootstrap_inner
    self.run()
    │    └ <function Thread.run at 0x7f321bf29790>
    └ <Thread(Thread-9111, started daemon 139838958200576)>
  File "/usr/lib/python3.8/threading.py", line 870, in run
    self._target(*self._args, **self._kwargs)
    │    │        │    │        │    └ {}
    │    │        │    │        └ <Thread(Thread-9111, started daemon 139838958200576)>
    │    │        │    └ ('ProjectManager.run_func_by_thread',)
    │    │        └ <Thread(Thread-9111, started daemon 139838958200576)>
    │    └ <bound method ProjectManager.get_request_from_keywords_hot of <monitor.projectManager.ProjectManager object at 0x7f31042e52e0>>
    └ <Thread(Thread-9111, started daemon 139838958200576)>

  File "/home/users/Scy/yuqing/spider/monitor/projectManager.py", line 799, in get_request_from_keywords_hot
    self.start_finished_spider_every_interval(project_names)
    │    │                                    └ ['default', 'test']
    │    └ <function ProjectManager.start_finished_spider_every_interval at 0x7f3104005280>
    └ <monitor.projectManager.ProjectManager object at 0x7f31042e52e0>

  File "/home/users/Scy/yuqing/spider/monitor/projectManager.py", line 784, in start_finished_spider_every_interval
    self[name].start_spider()
    │    └ 'default'
    └ <monitor.projectManager.ProjectManager object at 0x7f31042e52e0>

  File "/home/users/Scy/yuqing/spider/monitor/projectManager.py", line 366, in start_spider
    self.update_device_valid(device)
    │    │                   └ <monitor.deviceManager.DeviceC object at 0x7f3104029220>
    │    └ <function Project.update_device_valid at 0x7f3104003280>
    └ <monitor.projectManager.Project object at 0x7f3104029460>

  File "/home/users/Scy/yuqing/spider/monitor/projectManager.py", line 421, in update_device_valid
    self.database_manager.mysql.update(Device(**device.to_item()))
    │    │                │     │      │        │      └ <function DeviceC.to_item at 0x7f31f34ed310>
    │    │                │     │      │        └ <monitor.deviceManager.DeviceC object at 0x7f3104029220>
    │    │                │     │      └ <class 'base.db.mysql.Device'>
    │    │                │     └ <function Mysql.update at 0x7f31f35f4790>
    │    │                └ <base.db.mysql.Mysql object at 0x7f3103ffdfd0>
    │    └ <base.db.dbSlot.Slot object at 0x7f3103ffdf10>
    └ <monitor.projectManager.Project object at 0x7f3104029460>

> File "/home/users/Scy/yuqing/spider/base/db/mysql.py", line 375, in update
    row.update(new)
    │   │      └ {'server_id': '180.201.163.246:6800', 'ip': '180.201.163.246', 'username': 'chase', 'password': '7308331282958015650821971552...
    │   └ <function Query.update at 0x7f31f37333a0>
    └ <sqlalchemy.orm.query.Query object at 0x7f2f984007f0>

  File "/home/chase/.local/lib/python3.8/site-packages/sqlalchemy/orm/query.py", line 3221, in update
    result = self.session.execute(
             │    │       └ <function Session.execute at 0x7f31f370faf0>
             │    └ <sqlalchemy.orm.session.Session object at 0x7f30786d7fd0>
             └ <sqlalchemy.orm.query.Query object at 0x7f2f984007f0>
  File "/home/chase/.local/lib/python3.8/site-packages/sqlalchemy/orm/session.py", line 1689, in execute
    result = conn._execute_20(statement, params or {}, execution_options)
             │    │           │          │             └ immutabledict({'synchronize_session': 'evaluate', '_sa_orm_update_options': default_update_options(_matched_objects=[], _reso...
             │    │           │          └ immutabledict({})
             │    │           └ <sqlalchemy.sql.annotation.AnnotatedUpdate object at 0x7f30b815dd30>
             │    └ <function Connection._execute_20 at 0x7f31f39bc790>
             └ <sqlalchemy.engine.base.Connection object at 0x7f2fb8376bb0>
  File "/home/chase/.local/lib/python3.8/site-packages/sqlalchemy/engine/base.py", line 1583, in _execute_20
    return meth(self, args_10style, kwargs_10style, execution_options)
           │    │     │             │               └ immutabledict({'synchronize_session': 'evaluate', '_sa_orm_update_options': default_update_options(_matched_objects=[], _reso...
           │    │     │             └ immutabledict({})
           │    │     └ ({},)
           │    └ <sqlalchemy.engine.base.Connection object at 0x7f2fb8376bb0>
           └ <bound method ClauseElement._execute_on_connection of <sqlalchemy.sql.annotation.AnnotatedUpdate object at 0x7f30b815dd30>>
  File "/home/chase/.local/lib/python3.8/site-packages/sqlalchemy/sql/elements.py", line 323, in _execute_on_connection
    return connection._execute_clauseelement(
           │          └ <function Connection._execute_clauseelement at 0x7f31f39bc5e0>
           └ <sqlalchemy.engine.base.Connection object at 0x7f2fb8376bb0>
  File "/home/chase/.local/lib/python3.8/site-packages/sqlalchemy/engine/base.py", line 1452, in _execute_clauseelement
    ret = self._execute_context(
          │    └ <function Connection._execute_context at 0x7f31f39bc8b0>
          └ <sqlalchemy.engine.base.Connection object at 0x7f2fb8376bb0>
  File "/home/chase/.local/lib/python3.8/site-packages/sqlalchemy/engine/base.py", line 1814, in _execute_context
    self._handle_dbapi_exception(
    │    └ <function Connection._handle_dbapi_exception at 0x7f31f39bca60>
    └ <sqlalchemy.engine.base.Connection object at 0x7f2fb8376bb0>
  File "/home/chase/.local/lib/python3.8/site-packages/sqlalchemy/engine/base.py", line 1995, in _handle_dbapi_exception
    util.raise_(
    │    └ <function raise_ at 0x7f31f3d7ea60>
    └ <module 'sqlalchemy.util' from '/home/chase/.local/lib/python3.8/site-packages/sqlalchemy/util/__init__.py'>
  File "/home/chase/.local/lib/python3.8/site-packages/sqlalchemy/util/compat.py", line 207, in raise_
    raise exception
  File "/home/chase/.local/lib/python3.8/site-packages/sqlalchemy/engine/base.py", line 1771, in _execute_context
    self.dialect.do_execute(
    │    │       └ <function DefaultDialect.do_execute at 0x7f31f38f75e0>
    │    └ <sqlalchemy.dialects.mysql.pymysql.MySQLDialect_pymysql object at 0x7f3103ffde20>
    └ <sqlalchemy.engine.base.Connection object at 0x7f2fb8376bb0>
  File "/home/chase/.local/lib/python3.8/site-packages/sqlalchemy/engine/default.py", line 717, in do_execute
    cursor.execute(statement, parameters)
    │      │       │          └ {'server_id': '180.201.163.246:6800', 'ip': '180.201.163.246', 'username': 'chase', 'password': '7308331282958015650821971552...
    │      │       └ 'UPDATE device SET server_id=%(server_id)s, ip=%(ip)s, username=%(username)s, password=%(password)s, address=%(address)s, por...
    │      └ <function Cursor.execute at 0x7f31f354cdc0>
    └ <pymysql.cursors.Cursor object at 0x7f3100037310>
  File "/home/chase/.local/lib/python3.8/site-packages/pymysql/cursors.py", line 148, in execute
    result = self._query(query)
             │    │      └ "UPDATE device SET server_id='180.201.163.246:6800', ip='180.201.163.246', username='chase', password='7308331282958015650821...
             │    └ <function Cursor._query at 0x7f31f34d7280>
             └ <pymysql.cursors.Cursor object at 0x7f3100037310>
  File "/home/chase/.local/lib/python3.8/site-packages/pymysql/cursors.py", line 310, in _query
    conn.query(q)
    │    │     └ "UPDATE device SET server_id='180.201.163.246:6800', ip='180.201.163.246', username='chase', password='7308331282958015650821...
    │    └ <function Connection.query at 0x7f31f34e5670>
    └ <pymysql.connections.Connection object at 0x7f2f9842c910>
  File "/home/chase/.local/lib/python3.8/site-packages/pymysql/connections.py", line 548, in query
    self._affected_rows = self._read_query_result(unbuffered=unbuffered)
    │    │                │    │                             └ False
    │    │                │    └ <function Connection._read_query_result at 0x7f31f34e5ca0>
    │    │                └ <pymysql.connections.Connection object at 0x7f2f9842c910>
    │    └ 1
    └ <pymysql.connections.Connection object at 0x7f2f9842c910>
  File "/home/chase/.local/lib/python3.8/site-packages/pymysql/connections.py", line 775, in _read_query_result
    result.read()
    │      └ <function MySQLResult.read at 0x7f31f34e64c0>
    └ <pymysql.connections.MySQLResult object at 0x7f30782d2700>
  File "/home/chase/.local/lib/python3.8/site-packages/pymysql/connections.py", line 1156, in read
    first_packet = self.connection._read_packet()
                   │    └ None
                   └ <pymysql.connections.MySQLResult object at 0x7f30782d2700>
  File "/home/chase/.local/lib/python3.8/site-packages/pymysql/connections.py", line 725, in _read_packet
    packet.raise_for_error()
    │      └ <function MysqlPacket.raise_for_error at 0x7f31f34ddee0>
    └ <pymysql.protocol.MysqlPacket object at 0x7f30b814a730>
  File "/home/chase/.local/lib/python3.8/site-packages/pymysql/protocol.py", line 221, in raise_for_error
    err.raise_mysql_exception(self._data)
    │   │                     │    └ <member '_data' of 'MysqlPacket' objects>
    │   │                     └ <pymysql.protocol.MysqlPacket object at 0x7f30b814a730>
    │   └ <function raise_mysql_exception at 0x7f31f358c670>
    └ <module 'pymysql.err' from '/home/chase/.local/lib/python3.8/site-packages/pymysql/err.py'>
  File "/home/chase/.local/lib/python3.8/site-packages/pymysql/err.py", line 143, in raise_mysql_exception
    raise errorclass(errno, errval)
          │          │      └ "Duplicate entry '180.201.163.246:6800' for key 'device.PRIMARY'"
          │          └ 1062
          └ <class 'pymysql.err.IntegrityError'>

sqlalchemy.exc.IntegrityError: (pymysql.err.IntegrityError) (1062, "Duplicate entry '180.201.163.246:6800' for key 'device.PRIMARY'")
[SQL: UPDATE device SET server_id=%(server_id)s, ip=%(ip)s, username=%(username)s, password=%(password)s, address=%(address)s, port=%(port)s, valid=%(valid)s WHERE device.ip = %(ip_1)s]
[parameters: {'server_id': '180.201.163.246:6800', 'ip': '180.201.163.246', 'username': 'chase', 'password': '73083312829580156508219715527770530795849094205679828699331691345481538486564604828371062003239158804046494326402104187820112258903819156284071789239 ... (10 characters truncated) ... 28932487184040308332575122006890007226625618618229302586161332066928005416126100135150376363750209534434355210762724664795086527563383534739202629163', 'address': '/home/users/CT/pycharmproject/spiders/', 'port': 6800, 'valid': 1, 'ip_1': '180.201.163.246'}]
(Background on this error at: https://sqlalche.me/e/14/gkpj)
2022-05-14 02:57:11.183 | ERROR    | base.db.mysql:update:390 - 【mysql更新数据出错】
Traceback (most recent call last):

  File "/home/chase/.local/lib/python3.8/site-packages/sqlalchemy/engine/base.py", line 1771, in _execute_context
    self.dialect.do_execute(
    │    │       └ <function DefaultDialect.do_execute at 0x7f31f38f75e0>
    │    └ <sqlalchemy.dialects.mysql.pymysql.MySQLDialect_pymysql object at 0x7f3103ffde20>
    └ <sqlalchemy.engine.base.Connection object at 0x7f30d87813d0>
  File "/home/chase/.local/lib/python3.8/site-packages/sqlalchemy/engine/default.py", line 717, in do_execute
    cursor.execute(statement, parameters)
    │      │       │          └ {'server_id': '180.201.163.246:6800', 'ip': '180.201.163.246', 'username': 'chase', 'password': '5760795302573054943953015964...
    │      │       └ 'UPDATE device SET server_id=%(server_id)s, ip=%(ip)s, username=%(username)s, password=%(password)s, address=%(address)s, por...
    │      └ <function Cursor.execute at 0x7f31f354cdc0>
    └ <pymysql.cursors.Cursor object at 0x7f30180cb2b0>
  File "/home/chase/.local/lib/python3.8/site-packages/pymysql/cursors.py", line 148, in execute
    result = self._query(query)
             │    │      └ "UPDATE device SET server_id='180.201.163.246:6800', ip='180.201.163.246', username='chase', password='5760795302573054943953...
             │    └ <function Cursor._query at 0x7f31f34d7280>
             └ <pymysql.cursors.Cursor object at 0x7f30180cb2b0>
  File "/home/chase/.local/lib/python3.8/site-packages/pymysql/cursors.py", line 310, in _query
    conn.query(q)
    │    │     └ "UPDATE device SET server_id='180.201.163.246:6800', ip='180.201.163.246', username='chase', password='5760795302573054943953...
    │    └ <function Connection.query at 0x7f31f34e5670>
    └ <pymysql.connections.Connection object at 0x7f3100060be0>
  File "/home/chase/.local/lib/python3.8/site-packages/pymysql/connections.py", line 548, in query
    self._affected_rows = self._read_query_result(unbuffered=unbuffered)
    │    │                │    │                             └ False
    │    │                │    └ <function Connection._read_query_result at 0x7f31f34e5ca0>
    │    │                └ <pymysql.connections.Connection object at 0x7f3100060be0>
    │    └ 1
    └ <pymysql.connections.Connection object at 0x7f3100060be0>
  File "/home/chase/.local/lib/python3.8/site-packages/pymysql/connections.py", line 775, in _read_query_result
    result.read()
    │      └ <function MySQLResult.read at 0x7f31f34e64c0>
    └ <pymysql.connections.MySQLResult object at 0x7f30582e3a00>
  File "/home/chase/.local/lib/python3.8/site-packages/pymysql/connections.py", line 1156, in read
    first_packet = self.connection._read_packet()
                   │    └ None
                   └ <pymysql.connections.MySQLResult object at 0x7f30582e3a00>
  File "/home/chase/.local/lib/python3.8/site-packages/pymysql/connections.py", line 725, in _read_packet
    packet.raise_for_error()
    │      └ <function MysqlPacket.raise_for_error at 0x7f31f34ddee0>
    └ <pymysql.protocol.MysqlPacket object at 0x7f2fd843ea30>
  File "/home/chase/.local/lib/python3.8/site-packages/pymysql/protocol.py", line 221, in raise_for_error
    err.raise_mysql_exception(self._data)
    │   │                     │    └ <member '_data' of 'MysqlPacket' objects>
    │   │                     └ <pymysql.protocol.MysqlPacket object at 0x7f2fd843ea30>
    │   └ <function raise_mysql_exception at 0x7f31f358c670>
    └ <module 'pymysql.err' from '/home/chase/.local/lib/python3.8/site-packages/pymysql/err.py'>
  File "/home/chase/.local/lib/python3.8/site-packages/pymysql/err.py", line 143, in raise_mysql_exception
    raise errorclass(errno, errval)
          │          │      └ "Duplicate entry '180.201.163.246:6800' for key 'device.PRIMARY'"
          │          └ 1062
          └ <class 'pymysql.err.IntegrityError'>

pymysql.err.IntegrityError: (1062, "Duplicate entry '180.201.163.246:6800' for key 'device.PRIMARY'")


The above exception was the direct cause of the following exception:


Traceback (most recent call last):

  File "/usr/lib/python3.8/threading.py", line 890, in _bootstrap
    self._bootstrap_inner()
    │    └ <function Thread._bootstrap_inner at 0x7f321bf29a60>
    └ <Thread(Thread-9116, started daemon 139838924629760)>
  File "/usr/lib/python3.8/threading.py", line 932, in _bootstrap_inner
    self.run()
    │    └ <function Thread.run at 0x7f321bf29790>
    └ <Thread(Thread-9116, started daemon 139838924629760)>
  File "/usr/lib/python3.8/threading.py", line 870, in run
    self._target(*self._args, **self._kwargs)
    │    │        │    │        │    └ {}
    │    │        │    │        └ <Thread(Thread-9116, started daemon 139838924629760)>
    │    │        │    └ ('ProjectManager.run_func_by_thread',)
    │    │        └ <Thread(Thread-9116, started daemon 139838924629760)>
    │    └ <bound method ProjectManager.get_request_from_keywords_hot of <monitor.projectManager.ProjectManager object at 0x7f31042e52e0>>
    └ <Thread(Thread-9116, started daemon 139838924629760)>

  File "/home/users/Scy/yuqing/spider/monitor/projectManager.py", line 799, in get_request_from_keywords_hot
    self.start_finished_spider_every_interval(project_names)
    │    │                                    └ ['default', 'test']
    │    └ <function ProjectManager.start_finished_spider_every_interval at 0x7f3104005280>
    └ <monitor.projectManager.ProjectManager object at 0x7f31042e52e0>

  File "/home/users/Scy/yuqing/spider/monitor/projectManager.py", line 784, in start_finished_spider_every_interval
    self[name].start_spider()
    │    └ 'default'
    └ <monitor.projectManager.ProjectManager object at 0x7f31042e52e0>

  File "/home/users/Scy/yuqing/spider/monitor/projectManager.py", line 366, in start_spider
    self.update_device_valid(device)
    │    │                   └ <monitor.deviceManager.DeviceC object at 0x7f3104029220>
    │    └ <function Project.update_device_valid at 0x7f3104003280>
    └ <monitor.projectManager.Project object at 0x7f3104029460>

  File "/home/users/Scy/yuqing/spider/monitor/projectManager.py", line 421, in update_device_valid
    self.database_manager.mysql.update(Device(**device.to_item()))
    │    │                │     │      │        │      └ <function DeviceC.to_item at 0x7f31f34ed310>
    │    │                │     │      │        └ <monitor.deviceManager.DeviceC object at 0x7f3104029220>
    │    │                │     │      └ <class 'base.db.mysql.Device'>
    │    │                │     └ <function Mysql.update at 0x7f31f35f4790>
    │    │                └ <base.db.mysql.Mysql object at 0x7f3103ffdfd0>
    │    └ <base.db.dbSlot.Slot object at 0x7f3103ffdf10>
    └ <monitor.projectManager.Project object at 0x7f3104029460>

> File "/home/users/Scy/yuqing/spider/base/db/mysql.py", line 375, in update
    row.update(new)
    │   │      └ {'server_id': '180.201.163.246:6800', 'ip': '180.201.163.246', 'username': 'chase', 'password': '5760795302573054943953015964...
    │   └ <function Query.update at 0x7f31f37333a0>
    └ <sqlalchemy.orm.query.Query object at 0x7f30b8621e20>

  File "/home/chase/.local/lib/python3.8/site-packages/sqlalchemy/orm/query.py", line 3221, in update
    result = self.session.execute(
             │    │       └ <function Session.execute at 0x7f31f370faf0>
             │    └ <sqlalchemy.orm.session.Session object at 0x7f30781fd130>
             └ <sqlalchemy.orm.query.Query object at 0x7f30b8621e20>
  File "/home/chase/.local/lib/python3.8/site-packages/sqlalchemy/orm/session.py", line 1689, in execute
    result = conn._execute_20(statement, params or {}, execution_options)
             │    │           │          │             └ immutabledict({'synchronize_session': 'evaluate', '_sa_orm_update_options': default_update_options(_matched_objects=[], _reso...
             │    │           │          └ immutabledict({})
             │    │           └ <sqlalchemy.sql.annotation.AnnotatedUpdate object at 0x7f31f933ee20>
             │    └ <function Connection._execute_20 at 0x7f31f39bc790>
             └ <sqlalchemy.engine.base.Connection object at 0x7f30d87813d0>
  File "/home/chase/.local/lib/python3.8/site-packages/sqlalchemy/engine/base.py", line 1583, in _execute_20
    return meth(self, args_10style, kwargs_10style, execution_options)
           │    │     │             │               └ immutabledict({'synchronize_session': 'evaluate', '_sa_orm_update_options': default_update_options(_matched_objects=[], _reso...
           │    │     │             └ immutabledict({})
           │    │     └ ({},)
           │    └ <sqlalchemy.engine.base.Connection object at 0x7f30d87813d0>
           └ <bound method ClauseElement._execute_on_connection of <sqlalchemy.sql.annotation.AnnotatedUpdate object at 0x7f31f933ee20>>
  File "/home/chase/.local/lib/python3.8/site-packages/sqlalchemy/sql/elements.py", line 323, in _execute_on_connection
    return connection._execute_clauseelement(
           │          └ <function Connection._execute_clauseelement at 0x7f31f39bc5e0>
           └ <sqlalchemy.engine.base.Connection object at 0x7f30d87813d0>
  File "/home/chase/.local/lib/python3.8/site-packages/sqlalchemy/engine/base.py", line 1452, in _execute_clauseelement
    ret = self._execute_context(
          │    └ <function Connection._execute_context at 0x7f31f39bc8b0>
          └ <sqlalchemy.engine.base.Connection object at 0x7f30d87813d0>
  File "/home/chase/.local/lib/python3.8/site-packages/sqlalchemy/engine/base.py", line 1814, in _execute_context
    self._handle_dbapi_exception(
    │    └ <function Connection._handle_dbapi_exception at 0x7f31f39bca60>
    └ <sqlalchemy.engine.base.Connection object at 0x7f30d87813d0>
  File "/home/chase/.local/lib/python3.8/site-packages/sqlalchemy/engine/base.py", line 1995, in _handle_dbapi_exception
    util.raise_(
    │    └ <function raise_ at 0x7f31f3d7ea60>
    └ <module 'sqlalchemy.util' from '/home/chase/.local/lib/python3.8/site-packages/sqlalchemy/util/__init__.py'>
  File "/home/chase/.local/lib/python3.8/site-packages/sqlalchemy/util/compat.py", line 207, in raise_
    raise exception
  File "/home/chase/.local/lib/python3.8/site-packages/sqlalchemy/engine/base.py", line 1771, in _execute_context
    self.dialect.do_execute(
    │    │       └ <function DefaultDialect.do_execute at 0x7f31f38f75e0>
    │    └ <sqlalchemy.dialects.mysql.pymysql.MySQLDialect_pymysql object at 0x7f3103ffde20>
    └ <sqlalchemy.engine.base.Connection object at 0x7f30d87813d0>
  File "/home/chase/.local/lib/python3.8/site-packages/sqlalchemy/engine/default.py", line 717, in do_execute
    cursor.execute(statement, parameters)
    │      │       │          └ {'server_id': '180.201.163.246:6800', 'ip': '180.201.163.246', 'username': 'chase', 'password': '5760795302573054943953015964...
    │      │       └ 'UPDATE device SET server_id=%(server_id)s, ip=%(ip)s, username=%(username)s, password=%(password)s, address=%(address)s, por...
    │      └ <function Cursor.execute at 0x7f31f354cdc0>
    └ <pymysql.cursors.Cursor object at 0x7f30180cb2b0>
  File "/home/chase/.local/lib/python3.8/site-packages/pymysql/cursors.py", line 148, in execute
    result = self._query(query)
             │    │      └ "UPDATE device SET server_id='180.201.163.246:6800', ip='180.201.163.246', username='chase', password='5760795302573054943953...
             │    └ <function Cursor._query at 0x7f31f34d7280>
             └ <pymysql.cursors.Cursor object at 0x7f30180cb2b0>
  File "/home/chase/.local/lib/python3.8/site-packages/pymysql/cursors.py", line 310, in _query
    conn.query(q)
    │    │     └ "UPDATE device SET server_id='180.201.163.246:6800', ip='180.201.163.246', username='chase', password='5760795302573054943953...
    │    └ <function Connection.query at 0x7f31f34e5670>
    └ <pymysql.connections.Connection object at 0x7f3100060be0>
  File "/home/chase/.local/lib/python3.8/site-packages/pymysql/connections.py", line 548, in query
    self._affected_rows = self._read_query_result(unbuffered=unbuffered)
    │    │                │    │                             └ False
    │    │                │    └ <function Connection._read_query_result at 0x7f31f34e5ca0>
    │    │                └ <pymysql.connections.Connection object at 0x7f3100060be0>
    │    └ 1
    └ <pymysql.connections.Connection object at 0x7f3100060be0>
  File "/home/chase/.local/lib/python3.8/site-packages/pymysql/connections.py", line 775, in _read_query_result
    result.read()
    │      └ <function MySQLResult.read at 0x7f31f34e64c0>
    └ <pymysql.connections.MySQLResult object at 0x7f30582e3a00>
  File "/home/chase/.local/lib/python3.8/site-packages/pymysql/connections.py", line 1156, in read
    first_packet = self.connection._read_packet()
                   │    └ None
                   └ <pymysql.connections.MySQLResult object at 0x7f30582e3a00>
  File "/home/chase/.local/lib/python3.8/site-packages/pymysql/connections.py", line 725, in _read_packet
    packet.raise_for_error()
    │      └ <function MysqlPacket.raise_for_error at 0x7f31f34ddee0>
    └ <pymysql.protocol.MysqlPacket object at 0x7f2fd843ea30>
  File "/home/chase/.local/lib/python3.8/site-packages/pymysql/protocol.py", line 221, in raise_for_error
    err.raise_mysql_exception(self._data)
    │   │                     │    └ <member '_data' of 'MysqlPacket' objects>
    │   │                     └ <pymysql.protocol.MysqlPacket object at 0x7f2fd843ea30>
    │   └ <function raise_mysql_exception at 0x7f31f358c670>
    └ <module 'pymysql.err' from '/home/chase/.local/lib/python3.8/site-packages/pymysql/err.py'>
  File "/home/chase/.local/lib/python3.8/site-packages/pymysql/err.py", line 143, in raise_mysql_exception
    raise errorclass(errno, errval)
          │          │      └ "Duplicate entry '180.201.163.246:6800' for key 'device.PRIMARY'"
          │          └ 1062
          └ <class 'pymysql.err.IntegrityError'>

sqlalchemy.exc.IntegrityError: (pymysql.err.IntegrityError) (1062, "Duplicate entry '180.201.163.246:6800' for key 'device.PRIMARY'")
[SQL: UPDATE device SET server_id=%(server_id)s, ip=%(ip)s, username=%(username)s, password=%(password)s, address=%(address)s, port=%(port)s, valid=%(valid)s WHERE device.ip = %(ip_1)s]
[parameters: {'server_id': '180.201.163.246:6800', 'ip': '180.201.163.246', 'username': 'chase', 'password': '57607953025730549439530159643988934270528155163503482910356218867019464133363912838878832103893597525011988375653605774262355585559090115845009973606 ... (10 characters truncated) ... 39444981893661705060112453610929935535902898771649495036958980401998027396999338969637252129340705785700028765259583434351043295862231692502673223157', 'address': '/home/users/CT/pycharmproject/spiders/', 'port': 6800, 'valid': 1, 'ip_1': '180.201.163.246'}]
(Background on this error at: https://sqlalche.me/e/14/gkpj)
2022-05-14 02:57:29.144 | ERROR    | base.db.mysql:update:390 - 【mysql更新数据出错】
Traceback (most recent call last):

  File "/home/chase/.local/lib/python3.8/site-packages/sqlalchemy/engine/base.py", line 1771, in _execute_context
    self.dialect.do_execute(
    │    │       └ <function DefaultDialect.do_execute at 0x7f31f38f75e0>
    │    └ <sqlalchemy.dialects.mysql.pymysql.MySQLDialect_pymysql object at 0x7f3103ffde20>
    └ <sqlalchemy.engine.base.Connection object at 0x7f2ff86cd460>
  File "/home/chase/.local/lib/python3.8/site-packages/sqlalchemy/engine/default.py", line 717, in do_execute
    cursor.execute(statement, parameters)
    │      │       │          └ {'server_id': '180.201.163.246:6800', 'ip': '180.201.163.246', 'username': 'chase', 'password': '3770651397383422101775182657...
    │      │       └ 'UPDATE device SET server_id=%(server_id)s, ip=%(ip)s, username=%(username)s, password=%(password)s, address=%(address)s, por...
    │      └ <function Cursor.execute at 0x7f31f354cdc0>
    └ <pymysql.cursors.Cursor object at 0x7f30384dd340>
  File "/home/chase/.local/lib/python3.8/site-packages/pymysql/cursors.py", line 148, in execute
    result = self._query(query)
             │    │      └ "UPDATE device SET server_id='180.201.163.246:6800', ip='180.201.163.246', username='chase', password='3770651397383422101775...
             │    └ <function Cursor._query at 0x7f31f34d7280>
             └ <pymysql.cursors.Cursor object at 0x7f30384dd340>
  File "/home/chase/.local/lib/python3.8/site-packages/pymysql/cursors.py", line 310, in _query
    conn.query(q)
    │    │     └ "UPDATE device SET server_id='180.201.163.246:6800', ip='180.201.163.246', username='chase', password='3770651397383422101775...
    │    └ <function Connection.query at 0x7f31f34e5670>
    └ <pymysql.connections.Connection object at 0x7f30986ac640>
  File "/home/chase/.local/lib/python3.8/site-packages/pymysql/connections.py", line 548, in query
    self._affected_rows = self._read_query_result(unbuffered=unbuffered)
    │    │                │    │                             └ False
    │    │                │    └ <function Connection._read_query_result at 0x7f31f34e5ca0>
    │    │                └ <pymysql.connections.Connection object at 0x7f30986ac640>
    │    └ 1
    └ <pymysql.connections.Connection object at 0x7f30986ac640>
  File "/home/chase/.local/lib/python3.8/site-packages/pymysql/connections.py", line 775, in _read_query_result
    result.read()
    │      └ <function MySQLResult.read at 0x7f31f34e64c0>
    └ <pymysql.connections.MySQLResult object at 0x7f2fb86a1550>
  File "/home/chase/.local/lib/python3.8/site-packages/pymysql/connections.py", line 1156, in read
    first_packet = self.connection._read_packet()
                   │    └ None
                   └ <pymysql.connections.MySQLResult object at 0x7f2fb86a1550>
  File "/home/chase/.local/lib/python3.8/site-packages/pymysql/connections.py", line 725, in _read_packet
    packet.raise_for_error()
    │      └ <function MysqlPacket.raise_for_error at 0x7f31f34ddee0>
    └ <pymysql.protocol.MysqlPacket object at 0x7f30383dd430>
  File "/home/chase/.local/lib/python3.8/site-packages/pymysql/protocol.py", line 221, in raise_for_error
    err.raise_mysql_exception(self._data)
    │   │                     │    └ <member '_data' of 'MysqlPacket' objects>
    │   │                     └ <pymysql.protocol.MysqlPacket object at 0x7f30383dd430>
    │   └ <function raise_mysql_exception at 0x7f31f358c670>
    └ <module 'pymysql.err' from '/home/chase/.local/lib/python3.8/site-packages/pymysql/err.py'>
  File "/home/chase/.local/lib/python3.8/site-packages/pymysql/err.py", line 143, in raise_mysql_exception
    raise errorclass(errno, errval)
          │          │      └ "Duplicate entry '180.201.163.246:6800' for key 'device.PRIMARY'"
          │          └ 1062
          └ <class 'pymysql.err.IntegrityError'>

pymysql.err.IntegrityError: (1062, "Duplicate entry '180.201.163.246:6800' for key 'device.PRIMARY'")


The above exception was the direct cause of the following exception:


Traceback (most recent call last):

  File "/usr/lib/python3.8/threading.py", line 890, in _bootstrap
    self._bootstrap_inner()
    │    └ <function Thread._bootstrap_inner at 0x7f321bf29a60>
    └ <Thread(Thread-9121, started daemon 139838874273536)>
  File "/usr/lib/python3.8/threading.py", line 932, in _bootstrap_inner
    self.run()
    │    └ <function Thread.run at 0x7f321bf29790>
    └ <Thread(Thread-9121, started daemon 139838874273536)>
  File "/usr/lib/python3.8/threading.py", line 870, in run
    self._target(*self._args, **self._kwargs)
    │    │        │    │        │    └ {}
    │    │        │    │        └ <Thread(Thread-9121, started daemon 139838874273536)>
    │    │        │    └ ('ProjectManager.run_func_by_thread',)
    │    │        └ <Thread(Thread-9121, started daemon 139838874273536)>
    │    └ <bound method ProjectManager.get_request_from_keywords_hot of <monitor.projectManager.ProjectManager object at 0x7f31042e52e0>>
    └ <Thread(Thread-9121, started daemon 139838874273536)>

  File "/home/users/Scy/yuqing/spider/monitor/projectManager.py", line 799, in get_request_from_keywords_hot
    self.start_finished_spider_every_interval(project_names)
    │    │                                    └ ['default', 'test']
    │    └ <function ProjectManager.start_finished_spider_every_interval at 0x7f3104005280>
    └ <monitor.projectManager.ProjectManager object at 0x7f31042e52e0>

  File "/home/users/Scy/yuqing/spider/monitor/projectManager.py", line 784, in start_finished_spider_every_interval
    self[name].start_spider()
    │    └ 'default'
    └ <monitor.projectManager.ProjectManager object at 0x7f31042e52e0>

  File "/home/users/Scy/yuqing/spider/monitor/projectManager.py", line 366, in start_spider
    self.update_device_valid(device)
    │    │                   └ <monitor.deviceManager.DeviceC object at 0x7f3104029220>
    │    └ <function Project.update_device_valid at 0x7f3104003280>
    └ <monitor.projectManager.Project object at 0x7f3104029460>

  File "/home/users/Scy/yuqing/spider/monitor/projectManager.py", line 421, in update_device_valid
    self.database_manager.mysql.update(Device(**device.to_item()))
    │    │                │     │      │        │      └ <function DeviceC.to_item at 0x7f31f34ed310>
    │    │                │     │      │        └ <monitor.deviceManager.DeviceC object at 0x7f3104029220>
    │    │                │     │      └ <class 'base.db.mysql.Device'>
    │    │                │     └ <function Mysql.update at 0x7f31f35f4790>
    │    │                └ <base.db.mysql.Mysql object at 0x7f3103ffdfd0>
    │    └ <base.db.dbSlot.Slot object at 0x7f3103ffdf10>
    └ <monitor.projectManager.Project object at 0x7f3104029460>

> File "/home/users/Scy/yuqing/spider/base/db/mysql.py", line 375, in update
    row.update(new)
    │   │      └ {'server_id': '180.201.163.246:6800', 'ip': '180.201.163.246', 'username': 'chase', 'password': '3770651397383422101775182657...
    │   └ <function Query.update at 0x7f31f37333a0>
    └ <sqlalchemy.orm.query.Query object at 0x7f30782d21f0>

  File "/home/chase/.local/lib/python3.8/site-packages/sqlalchemy/orm/query.py", line 3221, in update
    result = self.session.execute(
             │    │       └ <function Session.execute at 0x7f31f370faf0>
             │    └ <sqlalchemy.orm.session.Session object at 0x7f30b816c250>
             └ <sqlalchemy.orm.query.Query object at 0x7f30782d21f0>
  File "/home/chase/.local/lib/python3.8/site-packages/sqlalchemy/orm/session.py", line 1689, in execute
    result = conn._execute_20(statement, params or {}, execution_options)
             │    │           │          │             └ immutabledict({'synchronize_session': 'evaluate', '_sa_orm_update_options': default_update_options(_matched_objects=[], _reso...
             │    │           │          └ immutabledict({})
             │    │           └ <sqlalchemy.sql.annotation.AnnotatedUpdate object at 0x7f30785eb7f0>
             │    └ <function Connection._execute_20 at 0x7f31f39bc790>
             └ <sqlalchemy.engine.base.Connection object at 0x7f2ff86cd460>
  File "/home/chase/.local/lib/python3.8/site-packages/sqlalchemy/engine/base.py", line 1583, in _execute_20
    return meth(self, args_10style, kwargs_10style, execution_options)
           │    │     │             │               └ immutabledict({'synchronize_session': 'evaluate', '_sa_orm_update_options': default_update_options(_matched_objects=[], _reso...
           │    │     │             └ immutabledict({})
           │    │     └ ({},)
           │    └ <sqlalchemy.engine.base.Connection object at 0x7f2ff86cd460>
           └ <bound method ClauseElement._execute_on_connection of <sqlalchemy.sql.annotation.AnnotatedUpdate object at 0x7f30785eb7f0>>
  File "/home/chase/.local/lib/python3.8/site-packages/sqlalchemy/sql/elements.py", line 323, in _execute_on_connection
    return connection._execute_clauseelement(
           │          └ <function Connection._execute_clauseelement at 0x7f31f39bc5e0>
           └ <sqlalchemy.engine.base.Connection object at 0x7f2ff86cd460>
  File "/home/chase/.local/lib/python3.8/site-packages/sqlalchemy/engine/base.py", line 1452, in _execute_clauseelement
    ret = self._execute_context(
          │    └ <function Connection._execute_context at 0x7f31f39bc8b0>
          └ <sqlalchemy.engine.base.Connection object at 0x7f2ff86cd460>
  File "/home/chase/.local/lib/python3.8/site-packages/sqlalchemy/engine/base.py", line 1814, in _execute_context
    self._handle_dbapi_exception(
    │    └ <function Connection._handle_dbapi_exception at 0x7f31f39bca60>
    └ <sqlalchemy.engine.base.Connection object at 0x7f2ff86cd460>
  File "/home/chase/.local/lib/python3.8/site-packages/sqlalchemy/engine/base.py", line 1995, in _handle_dbapi_exception
    util.raise_(
    │    └ <function raise_ at 0x7f31f3d7ea60>
    └ <module 'sqlalchemy.util' from '/home/chase/.local/lib/python3.8/site-packages/sqlalchemy/util/__init__.py'>
  File "/home/chase/.local/lib/python3.8/site-packages/sqlalchemy/util/compat.py", line 207, in raise_
    raise exception
  File "/home/chase/.local/lib/python3.8/site-packages/sqlalchemy/engine/base.py", line 1771, in _execute_context
    self.dialect.do_execute(
    │    │       └ <function DefaultDialect.do_execute at 0x7f31f38f75e0>
    │    └ <sqlalchemy.dialects.mysql.pymysql.MySQLDialect_pymysql object at 0x7f3103ffde20>
    └ <sqlalchemy.engine.base.Connection object at 0x7f2ff86cd460>
  File "/home/chase/.local/lib/python3.8/site-packages/sqlalchemy/engine/default.py", line 717, in do_execute
    cursor.execute(statement, parameters)
    │      │       │          └ {'server_id': '180.201.163.246:6800', 'ip': '180.201.163.246', 'username': 'chase', 'password': '3770651397383422101775182657...
    │      │       └ 'UPDATE device SET server_id=%(server_id)s, ip=%(ip)s, username=%(username)s, password=%(password)s, address=%(address)s, por...
    │      └ <function Cursor.execute at 0x7f31f354cdc0>
    └ <pymysql.cursors.Cursor object at 0x7f30384dd340>
  File "/home/chase/.local/lib/python3.8/site-packages/pymysql/cursors.py", line 148, in execute
    result = self._query(query)
             │    │      └ "UPDATE device SET server_id='180.201.163.246:6800', ip='180.201.163.246', username='chase', password='3770651397383422101775...
             │    └ <function Cursor._query at 0x7f31f34d7280>
             └ <pymysql.cursors.Cursor object at 0x7f30384dd340>
  File "/home/chase/.local/lib/python3.8/site-packages/pymysql/cursors.py", line 310, in _query
    conn.query(q)
    │    │     └ "UPDATE device SET server_id='180.201.163.246:6800', ip='180.201.163.246', username='chase', password='3770651397383422101775...
    │    └ <function Connection.query at 0x7f31f34e5670>
    └ <pymysql.connections.Connection object at 0x7f30986ac640>
  File "/home/chase/.local/lib/python3.8/site-packages/pymysql/connections.py", line 548, in query
    self._affected_rows = self._read_query_result(unbuffered=unbuffered)
    │    │                │    │                             └ False
    │    │                │    └ <function Connection._read_query_result at 0x7f31f34e5ca0>
    │    │                └ <pymysql.connections.Connection object at 0x7f30986ac640>
    │    └ 1
    └ <pymysql.connections.Connection object at 0x7f30986ac640>
  File "/home/chase/.local/lib/python3.8/site-packages/pymysql/connections.py", line 775, in _read_query_result
    result.read()
    │      └ <function MySQLResult.read at 0x7f31f34e64c0>
    └ <pymysql.connections.MySQLResult object at 0x7f2fb86a1550>
  File "/home/chase/.local/lib/python3.8/site-packages/pymysql/connections.py", line 1156, in read
    first_packet = self.connection._read_packet()
                   │    └ None
                   └ <pymysql.connections.MySQLResult object at 0x7f2fb86a1550>
  File "/home/chase/.local/lib/python3.8/site-packages/pymysql/connections.py", line 725, in _read_packet
    packet.raise_for_error()
    │      └ <function MysqlPacket.raise_for_error at 0x7f31f34ddee0>
    └ <pymysql.protocol.MysqlPacket object at 0x7f30383dd430>
  File "/home/chase/.local/lib/python3.8/site-packages/pymysql/protocol.py", line 221, in raise_for_error
    err.raise_mysql_exception(self._data)
    │   │                     │    └ <member '_data' of 'MysqlPacket' objects>
    │   │                     └ <pymysql.protocol.MysqlPacket object at 0x7f30383dd430>
    │   └ <function raise_mysql_exception at 0x7f31f358c670>
    └ <module 'pymysql.err' from '/home/chase/.local/lib/python3.8/site-packages/pymysql/err.py'>
  File "/home/chase/.local/lib/python3.8/site-packages/pymysql/err.py", line 143, in raise_mysql_exception
    raise errorclass(errno, errval)
          │          │      └ "Duplicate entry '180.201.163.246:6800' for key 'device.PRIMARY'"
          │          └ 1062
          └ <class 'pymysql.err.IntegrityError'>

sqlalchemy.exc.IntegrityError: (pymysql.err.IntegrityError) (1062, "Duplicate entry '180.201.163.246:6800' for key 'device.PRIMARY'")
[SQL: UPDATE device SET server_id=%(server_id)s, ip=%(ip)s, username=%(username)s, password=%(password)s, address=%(address)s, port=%(port)s, valid=%(valid)s WHERE device.ip = %(ip_1)s]
[parameters: {'server_id': '180.201.163.246:6800', 'ip': '180.201.163.246', 'username': 'chase', 'password': '37706513973834221017751826571278261592074927805021894290273636833164554370117070371699466519000182608502770724362519125110832157675122978251034012115 ... (10 characters truncated) ... 20469114205497249852402678029904404637782491721261973529481657734184278800313594773584329845856841320365951569924431864012417419879981942839692677930', 'address': '/home/users/CT/pycharmproject/spiders/', 'port': 6800, 'valid': 1, 'ip_1': '180.201.163.246'}]
(Background on this error at: https://sqlalche.me/e/14/gkpj)
2022-05-14 02:57:48.259 | ERROR    | base.db.mysql:update:390 - 【mysql更新数据出错】
Traceback (most recent call last):

  File "/home/chase/.local/lib/python3.8/site-packages/sqlalchemy/engine/base.py", line 1771, in _execute_context
    self.dialect.do_execute(
    │    │       └ <function DefaultDialect.do_execute at 0x7f31f38f75e0>
    │    └ <sqlalchemy.dialects.mysql.pymysql.MySQLDialect_pymysql object at 0x7f3103ffde20>
    └ <sqlalchemy.engine.base.Connection object at 0x7f2ff87d8c40>
  File "/home/chase/.local/lib/python3.8/site-packages/sqlalchemy/engine/default.py", line 717, in do_execute
    cursor.execute(statement, parameters)
    │      │       │          └ {'server_id': '180.201.163.246:6800', 'ip': '180.201.163.246', 'username': 'chase', 'password': '8535952576800001285928227382...
    │      │       └ 'UPDATE device SET server_id=%(server_id)s, ip=%(ip)s, username=%(username)s, password=%(password)s, address=%(address)s, por...
    │      └ <function Cursor.execute at 0x7f31f354cdc0>
    └ <pymysql.cursors.Cursor object at 0x7f3101c8b7c0>
  File "/home/chase/.local/lib/python3.8/site-packages/pymysql/cursors.py", line 148, in execute
    result = self._query(query)
             │    │      └ "UPDATE device SET server_id='180.201.163.246:6800', ip='180.201.163.246', username='chase', password='8535952576800001285928...
             │    └ <function Cursor._query at 0x7f31f34d7280>
             └ <pymysql.cursors.Cursor object at 0x7f3101c8b7c0>
  File "/home/chase/.local/lib/python3.8/site-packages/pymysql/cursors.py", line 310, in _query
    conn.query(q)
    │    │     └ "UPDATE device SET server_id='180.201.163.246:6800', ip='180.201.163.246', username='chase', password='8535952576800001285928...
    │    └ <function Connection.query at 0x7f31f34e5670>
    └ <pymysql.connections.Connection object at 0x7f3098759a30>
  File "/home/chase/.local/lib/python3.8/site-packages/pymysql/connections.py", line 548, in query
    self._affected_rows = self._read_query_result(unbuffered=unbuffered)
    │    │                │    │                             └ False
    │    │                │    └ <function Connection._read_query_result at 0x7f31f34e5ca0>
    │    │                └ <pymysql.connections.Connection object at 0x7f3098759a30>
    │    └ 1
    └ <pymysql.connections.Connection object at 0x7f3098759a30>
  File "/home/chase/.local/lib/python3.8/site-packages/pymysql/connections.py", line 775, in _read_query_result
    result.read()
    │      └ <function MySQLResult.read at 0x7f31f34e64c0>
    └ <pymysql.connections.MySQLResult object at 0x7f30980a1f70>
  File "/home/chase/.local/lib/python3.8/site-packages/pymysql/connections.py", line 1156, in read
    first_packet = self.connection._read_packet()
                   │    └ None
                   └ <pymysql.connections.MySQLResult object at 0x7f30980a1f70>
  File "/home/chase/.local/lib/python3.8/site-packages/pymysql/connections.py", line 725, in _read_packet
    packet.raise_for_error()
    │      └ <function MysqlPacket.raise_for_error at 0x7f31f34ddee0>
    └ <pymysql.protocol.MysqlPacket object at 0x7f30d82d8370>
  File "/home/chase/.local/lib/python3.8/site-packages/pymysql/protocol.py", line 221, in raise_for_error
    err.raise_mysql_exception(self._data)
    │   │                     │    └ <member '_data' of 'MysqlPacket' objects>
    │   │                     └ <pymysql.protocol.MysqlPacket object at 0x7f30d82d8370>
    │   └ <function raise_mysql_exception at 0x7f31f358c670>
    └ <module 'pymysql.err' from '/home/chase/.local/lib/python3.8/site-packages/pymysql/err.py'>
  File "/home/chase/.local/lib/python3.8/site-packages/pymysql/err.py", line 143, in raise_mysql_exception
    raise errorclass(errno, errval)
          │          │      └ "Duplicate entry '180.201.163.246:6800' for key 'device.PRIMARY'"
          │          └ 1062
          └ <class 'pymysql.err.IntegrityError'>

pymysql.err.IntegrityError: (1062, "Duplicate entry '180.201.163.246:6800' for key 'device.PRIMARY'")


The above exception was the direct cause of the following exception:


Traceback (most recent call last):

  File "/usr/lib/python3.8/threading.py", line 890, in _bootstrap
    self._bootstrap_inner()
    │    └ <function Thread._bootstrap_inner at 0x7f321bf29a60>
    └ <Thread(Thread-9126, started daemon 139838865880832)>
  File "/usr/lib/python3.8/threading.py", line 932, in _bootstrap_inner
    self.run()
    │    └ <function Thread.run at 0x7f321bf29790>
    └ <Thread(Thread-9126, started daemon 139838865880832)>
  File "/usr/lib/python3.8/threading.py", line 870, in run
    self._target(*self._args, **self._kwargs)
    │    │        │    │        │    └ {}
    │    │        │    │        └ <Thread(Thread-9126, started daemon 139838865880832)>
    │    │        │    └ ('ProjectManager.run_func_by_thread',)
    │    │        └ <Thread(Thread-9126, started daemon 139838865880832)>
    │    └ <bound method ProjectManager.get_request_from_keywords_hot of <monitor.projectManager.ProjectManager object at 0x7f31042e52e0>>
    └ <Thread(Thread-9126, started daemon 139838865880832)>

  File "/home/users/Scy/yuqing/spider/monitor/projectManager.py", line 799, in get_request_from_keywords_hot
    self.start_finished_spider_every_interval(project_names)
    │    │                                    └ ['default', 'test']
    │    └ <function ProjectManager.start_finished_spider_every_interval at 0x7f3104005280>
    └ <monitor.projectManager.ProjectManager object at 0x7f31042e52e0>

  File "/home/users/Scy/yuqing/spider/monitor/projectManager.py", line 784, in start_finished_spider_every_interval
    self[name].start_spider()
    │    └ 'default'
    └ <monitor.projectManager.ProjectManager object at 0x7f31042e52e0>

  File "/home/users/Scy/yuqing/spider/monitor/projectManager.py", line 366, in start_spider
    self.update_device_valid(device)
    │    │                   └ <monitor.deviceManager.DeviceC object at 0x7f3104029220>
    │    └ <function Project.update_device_valid at 0x7f3104003280>
    └ <monitor.projectManager.Project object at 0x7f3104029460>

  File "/home/users/Scy/yuqing/spider/monitor/projectManager.py", line 421, in update_device_valid
    self.database_manager.mysql.update(Device(**device.to_item()))
    │    │                │     │      │        │      └ <function DeviceC.to_item at 0x7f31f34ed310>
    │    │                │     │      │        └ <monitor.deviceManager.DeviceC object at 0x7f3104029220>
    │    │                │     │      └ <class 'base.db.mysql.Device'>
    │    │                │     └ <function Mysql.update at 0x7f31f35f4790>
    │    │                └ <base.db.mysql.Mysql object at 0x7f3103ffdfd0>
    │    └ <base.db.dbSlot.Slot object at 0x7f3103ffdf10>
    └ <monitor.projectManager.Project object at 0x7f3104029460>

> File "/home/users/Scy/yuqing/spider/base/db/mysql.py", line 375, in update
    row.update(new)
    │   │      └ {'server_id': '180.201.163.246:6800', 'ip': '180.201.163.246', 'username': 'chase', 'password': '8535952576800001285928227382...
    │   └ <function Query.update at 0x7f31f37333a0>
    └ <sqlalchemy.orm.query.Query object at 0x7f3101be0eb0>

  File "/home/chase/.local/lib/python3.8/site-packages/sqlalchemy/orm/query.py", line 3221, in update
    result = self.session.execute(
             │    │       └ <function Session.execute at 0x7f31f370faf0>
             │    └ <sqlalchemy.orm.session.Session object at 0x7f30581c6d60>
             └ <sqlalchemy.orm.query.Query object at 0x7f3101be0eb0>
  File "/home/chase/.local/lib/python3.8/site-packages/sqlalchemy/orm/session.py", line 1689, in execute
    result = conn._execute_20(statement, params or {}, execution_options)
             │    │           │          │             └ immutabledict({'synchronize_session': 'evaluate', '_sa_orm_update_options': default_update_options(_matched_objects=[], _reso...
             │    │           │          └ immutabledict({})
             │    │           └ <sqlalchemy.sql.annotation.AnnotatedUpdate object at 0x7f30985b2cd0>
             │    └ <function Connection._execute_20 at 0x7f31f39bc790>
             └ <sqlalchemy.engine.base.Connection object at 0x7f2ff87d8c40>
  File "/home/chase/.local/lib/python3.8/site-packages/sqlalchemy/engine/base.py", line 1583, in _execute_20
    return meth(self, args_10style, kwargs_10style, execution_options)
           │    │     │             │               └ immutabledict({'synchronize_session': 'evaluate', '_sa_orm_update_options': default_update_options(_matched_objects=[], _reso...
           │    │     │             └ immutabledict({})
           │    │     └ ({},)
           │    └ <sqlalchemy.engine.base.Connection object at 0x7f2ff87d8c40>
           └ <bound method ClauseElement._execute_on_connection of <sqlalchemy.sql.annotation.AnnotatedUpdate object at 0x7f30985b2cd0>>
  File "/home/chase/.local/lib/python3.8/site-packages/sqlalchemy/sql/elements.py", line 323, in _execute_on_connection
    return connection._execute_clauseelement(
           │          └ <function Connection._execute_clauseelement at 0x7f31f39bc5e0>
           └ <sqlalchemy.engine.base.Connection object at 0x7f2ff87d8c40>
  File "/home/chase/.local/lib/python3.8/site-packages/sqlalchemy/engine/base.py", line 1452, in _execute_clauseelement
    ret = self._execute_context(
          │    └ <function Connection._execute_context at 0x7f31f39bc8b0>
          └ <sqlalchemy.engine.base.Connection object at 0x7f2ff87d8c40>
  File "/home/chase/.local/lib/python3.8/site-packages/sqlalchemy/engine/base.py", line 1814, in _execute_context
    self._handle_dbapi_exception(
    │    └ <function Connection._handle_dbapi_exception at 0x7f31f39bca60>
    └ <sqlalchemy.engine.base.Connection object at 0x7f2ff87d8c40>
  File "/home/chase/.local/lib/python3.8/site-packages/sqlalchemy/engine/base.py", line 1995, in _handle_dbapi_exception
    util.raise_(
    │    └ <function raise_ at 0x7f31f3d7ea60>
    └ <module 'sqlalchemy.util' from '/home/chase/.local/lib/python3.8/site-packages/sqlalchemy/util/__init__.py'>
  File "/home/chase/.local/lib/python3.8/site-packages/sqlalchemy/util/compat.py", line 207, in raise_
    raise exception
  File "/home/chase/.local/lib/python3.8/site-packages/sqlalchemy/engine/base.py", line 1771, in _execute_context
    self.dialect.do_execute(
    │    │       └ <function DefaultDialect.do_execute at 0x7f31f38f75e0>
    │    └ <sqlalchemy.dialects.mysql.pymysql.MySQLDialect_pymysql object at 0x7f3103ffde20>
    └ <sqlalchemy.engine.base.Connection object at 0x7f2ff87d8c40>
  File "/home/chase/.local/lib/python3.8/site-packages/sqlalchemy/engine/default.py", line 717, in do_execute
    cursor.execute(statement, parameters)
    │      │       │          └ {'server_id': '180.201.163.246:6800', 'ip': '180.201.163.246', 'username': 'chase', 'password': '8535952576800001285928227382...
    │      │       └ 'UPDATE device SET server_id=%(server_id)s, ip=%(ip)s, username=%(username)s, password=%(password)s, address=%(address)s, por...
    │      └ <function Cursor.execute at 0x7f31f354cdc0>
    └ <pymysql.cursors.Cursor object at 0x7f3101c8b7c0>
  File "/home/chase/.local/lib/python3.8/site-packages/pymysql/cursors.py", line 148, in execute
    result = self._query(query)
             │    │      └ "UPDATE device SET server_id='180.201.163.246:6800', ip='180.201.163.246', username='chase', password='8535952576800001285928...
             │    └ <function Cursor._query at 0x7f31f34d7280>
             └ <pymysql.cursors.Cursor object at 0x7f3101c8b7c0>
  File "/home/chase/.local/lib/python3.8/site-packages/pymysql/cursors.py", line 310, in _query
    conn.query(q)
    │    │     └ "UPDATE device SET server_id='180.201.163.246:6800', ip='180.201.163.246', username='chase', password='8535952576800001285928...
    │    └ <function Connection.query at 0x7f31f34e5670>
    └ <pymysql.connections.Connection object at 0x7f3098759a30>
  File "/home/chase/.local/lib/python3.8/site-packages/pymysql/connections.py", line 548, in query
    self._affected_rows = self._read_query_result(unbuffered=unbuffered)
    │    │                │    │                             └ False
    │    │                │    └ <function Connection._read_query_result at 0x7f31f34e5ca0>
    │    │                └ <pymysql.connections.Connection object at 0x7f3098759a30>
    │    └ 1
    └ <pymysql.connections.Connection object at 0x7f3098759a30>
  File "/home/chase/.local/lib/python3.8/site-packages/pymysql/connections.py", line 775, in _read_query_result
    result.read()
    │      └ <function MySQLResult.read at 0x7f31f34e64c0>
    └ <pymysql.connections.MySQLResult object at 0x7f30980a1f70>
  File "/home/chase/.local/lib/python3.8/site-packages/pymysql/connections.py", line 1156, in read
    first_packet = self.connection._read_packet()
                   │    └ None
                   └ <pymysql.connections.MySQLResult object at 0x7f30980a1f70>
  File "/home/chase/.local/lib/python3.8/site-packages/pymysql/connections.py", line 725, in _read_packet
    packet.raise_for_error()
    │      └ <function MysqlPacket.raise_for_error at 0x7f31f34ddee0>
    └ <pymysql.protocol.MysqlPacket object at 0x7f30d82d8370>
  File "/home/chase/.local/lib/python3.8/site-packages/pymysql/protocol.py", line 221, in raise_for_error
    err.raise_mysql_exception(self._data)
    │   │                     │    └ <member '_data' of 'MysqlPacket' objects>
    │   │                     └ <pymysql.protocol.MysqlPacket object at 0x7f30d82d8370>
    │   └ <function raise_mysql_exception at 0x7f31f358c670>
    └ <module 'pymysql.err' from '/home/chase/.local/lib/python3.8/site-packages/pymysql/err.py'>
  File "/home/chase/.local/lib/python3.8/site-packages/pymysql/err.py", line 143, in raise_mysql_exception
    raise errorclass(errno, errval)
          │          │      └ "Duplicate entry '180.201.163.246:6800' for key 'device.PRIMARY'"
          │          └ 1062
          └ <class 'pymysql.err.IntegrityError'>

sqlalchemy.exc.IntegrityError: (pymysql.err.IntegrityError) (1062, "Duplicate entry '180.201.163.246:6800' for key 'device.PRIMARY'")
[SQL: UPDATE device SET server_id=%(server_id)s, ip=%(ip)s, username=%(username)s, password=%(password)s, address=%(address)s, port=%(port)s, valid=%(valid)s WHERE device.ip = %(ip_1)s]
[parameters: {'server_id': '180.201.163.246:6800', 'ip': '180.201.163.246', 'username': 'chase', 'password': '85359525768000012859282273821792859847440155684947865287869948583938043170583053659313531212254208669134496219376638565518939097119203793860875172658 ... (10 characters truncated) ... 03269357216809440630910830259310661913848991037868798049885197040173510983683873639627450502668384509603818932796045222137641615334348933608045355543', 'address': '/home/users/CT/pycharmproject/spiders/', 'port': 6800, 'valid': 1, 'ip_1': '180.201.163.246'}]
(Background on this error at: https://sqlalche.me/e/14/gkpj)
2022-05-14 02:58:06.124 | ERROR    | base.db.mysql:update:390 - 【mysql更新数据出错】
Traceback (most recent call last):

  File "/home/chase/.local/lib/python3.8/site-packages/sqlalchemy/engine/base.py", line 1771, in _execute_context
    self.dialect.do_execute(
    │    │       └ <function DefaultDialect.do_execute at 0x7f31f38f75e0>
    │    └ <sqlalchemy.dialects.mysql.pymysql.MySQLDialect_pymysql object at 0x7f3103ffde20>
    └ <sqlalchemy.engine.base.Connection object at 0x7f2fb833f820>
  File "/home/chase/.local/lib/python3.8/site-packages/sqlalchemy/engine/default.py", line 717, in do_execute
    cursor.execute(statement, parameters)
    │      │       │          └ {'server_id': '180.201.163.246:6800', 'ip': '180.201.163.246', 'username': 'chase', 'password': '2054387722598125417142331652...
    │      │       └ 'UPDATE device SET server_id=%(server_id)s, ip=%(ip)s, username=%(username)s, password=%(password)s, address=%(address)s, por...
    │      └ <function Cursor.execute at 0x7f31f354cdc0>
    └ <pymysql.cursors.Cursor object at 0x7f30185fd070>
  File "/home/chase/.local/lib/python3.8/site-packages/pymysql/cursors.py", line 148, in execute
    result = self._query(query)
             │    │      └ "UPDATE device SET server_id='180.201.163.246:6800', ip='180.201.163.246', username='chase', password='2054387722598125417142...
             │    └ <function Cursor._query at 0x7f31f34d7280>
             └ <pymysql.cursors.Cursor object at 0x7f30185fd070>
  File "/home/chase/.local/lib/python3.8/site-packages/pymysql/cursors.py", line 310, in _query
    conn.query(q)
    │    │     └ "UPDATE device SET server_id='180.201.163.246:6800', ip='180.201.163.246', username='chase', password='2054387722598125417142...
    │    └ <function Connection.query at 0x7f31f34e5670>
    └ <pymysql.connections.Connection object at 0x7f30786eabe0>
  File "/home/chase/.local/lib/python3.8/site-packages/pymysql/connections.py", line 548, in query
    self._affected_rows = self._read_query_result(unbuffered=unbuffered)
    │    │                │    │                             └ False
    │    │                │    └ <function Connection._read_query_result at 0x7f31f34e5ca0>
    │    │                └ <pymysql.connections.Connection object at 0x7f30786eabe0>
    │    └ 1
    └ <pymysql.connections.Connection object at 0x7f30786eabe0>
  File "/home/chase/.local/lib/python3.8/site-packages/pymysql/connections.py", line 775, in _read_query_result
    result.read()
    │      └ <function MySQLResult.read at 0x7f31f34e64c0>
    └ <pymysql.connections.MySQLResult object at 0x7f3102008730>
  File "/home/chase/.local/lib/python3.8/site-packages/pymysql/connections.py", line 1156, in read
    first_packet = self.connection._read_packet()
                   │    └ None
                   └ <pymysql.connections.MySQLResult object at 0x7f3102008730>
  File "/home/chase/.local/lib/python3.8/site-packages/pymysql/connections.py", line 725, in _read_packet
    packet.raise_for_error()
    │      └ <function MysqlPacket.raise_for_error at 0x7f31f34ddee0>
    └ <pymysql.protocol.MysqlPacket object at 0x7f2f987afa30>
  File "/home/chase/.local/lib/python3.8/site-packages/pymysql/protocol.py", line 221, in raise_for_error
    err.raise_mysql_exception(self._data)
    │   │                     │    └ <member '_data' of 'MysqlPacket' objects>
    │   │                     └ <pymysql.protocol.MysqlPacket object at 0x7f2f987afa30>
    │   └ <function raise_mysql_exception at 0x7f31f358c670>
    └ <module 'pymysql.err' from '/home/chase/.local/lib/python3.8/site-packages/pymysql/err.py'>
  File "/home/chase/.local/lib/python3.8/site-packages/pymysql/err.py", line 143, in raise_mysql_exception
    raise errorclass(errno, errval)
          │          │      └ "Duplicate entry '180.201.163.246:6800' for key 'device.PRIMARY'"
          │          └ 1062
          └ <class 'pymysql.err.IntegrityError'>

pymysql.err.IntegrityError: (1062, "Duplicate entry '180.201.163.246:6800' for key 'device.PRIMARY'")


The above exception was the direct cause of the following exception:


Traceback (most recent call last):

  File "/usr/lib/python3.8/threading.py", line 890, in _bootstrap
    self._bootstrap_inner()
    │    └ <function Thread._bootstrap_inner at 0x7f321bf29a60>
    └ <Thread(Thread-9130, started daemon 139838857488128)>
  File "/usr/lib/python3.8/threading.py", line 932, in _bootstrap_inner
    self.run()
    │    └ <function Thread.run at 0x7f321bf29790>
    └ <Thread(Thread-9130, started daemon 139838857488128)>
  File "/usr/lib/python3.8/threading.py", line 870, in run
    self._target(*self._args, **self._kwargs)
    │    │        │    │        │    └ {}
    │    │        │    │        └ <Thread(Thread-9130, started daemon 139838857488128)>
    │    │        │    └ ('ProjectManager.run_func_by_thread',)
    │    │        └ <Thread(Thread-9130, started daemon 139838857488128)>
    │    └ <bound method ProjectManager.get_request_from_keywords_hot of <monitor.projectManager.ProjectManager object at 0x7f31042e52e0>>
    └ <Thread(Thread-9130, started daemon 139838857488128)>

  File "/home/users/Scy/yuqing/spider/monitor/projectManager.py", line 799, in get_request_from_keywords_hot
    self.start_finished_spider_every_interval(project_names)
    │    │                                    └ ['default', 'test']
    │    └ <function ProjectManager.start_finished_spider_every_interval at 0x7f3104005280>
    └ <monitor.projectManager.ProjectManager object at 0x7f31042e52e0>

  File "/home/users/Scy/yuqing/spider/monitor/projectManager.py", line 784, in start_finished_spider_every_interval
    self[name].start_spider()
    │    └ 'default'
    └ <monitor.projectManager.ProjectManager object at 0x7f31042e52e0>

  File "/home/users/Scy/yuqing/spider/monitor/projectManager.py", line 366, in start_spider
    self.update_device_valid(device)
    │    │                   └ <monitor.deviceManager.DeviceC object at 0x7f3104029220>
    │    └ <function Project.update_device_valid at 0x7f3104003280>
    └ <monitor.projectManager.Project object at 0x7f3104029460>

  File "/home/users/Scy/yuqing/spider/monitor/projectManager.py", line 421, in update_device_valid
    self.database_manager.mysql.update(Device(**device.to_item()))
    │    │                │     │      │        │      └ <function DeviceC.to_item at 0x7f31f34ed310>
    │    │                │     │      │        └ <monitor.deviceManager.DeviceC object at 0x7f3104029220>
    │    │                │     │      └ <class 'base.db.mysql.Device'>
    │    │                │     └ <function Mysql.update at 0x7f31f35f4790>
    │    │                └ <base.db.mysql.Mysql object at 0x7f3103ffdfd0>
    │    └ <base.db.dbSlot.Slot object at 0x7f3103ffdf10>
    └ <monitor.projectManager.Project object at 0x7f3104029460>

> File "/home/users/Scy/yuqing/spider/base/db/mysql.py", line 375, in update
    row.update(new)
    │   │      └ {'server_id': '180.201.163.246:6800', 'ip': '180.201.163.246', 'username': 'chase', 'password': '2054387722598125417142331652...
    │   └ <function Query.update at 0x7f31f37333a0>
    └ <sqlalchemy.orm.query.Query object at 0x7f30b8288370>

  File "/home/chase/.local/lib/python3.8/site-packages/sqlalchemy/orm/query.py", line 3221, in update
    result = self.session.execute(
             │    │       └ <function Session.execute at 0x7f31f370faf0>
             │    └ <sqlalchemy.orm.session.Session object at 0x7f31022b5c10>
             └ <sqlalchemy.orm.query.Query object at 0x7f30b8288370>
  File "/home/chase/.local/lib/python3.8/site-packages/sqlalchemy/orm/session.py", line 1689, in execute
    result = conn._execute_20(statement, params or {}, execution_options)
             │    │           │          │             └ immutabledict({'synchronize_session': 'evaluate', '_sa_orm_update_options': default_update_options(_matched_objects=[], _reso...
             │    │           │          └ immutabledict({})
             │    │           └ <sqlalchemy.sql.annotation.AnnotatedUpdate object at 0x7f30185fdeb0>
             │    └ <function Connection._execute_20 at 0x7f31f39bc790>
             └ <sqlalchemy.engine.base.Connection object at 0x7f2fb833f820>
  File "/home/chase/.local/lib/python3.8/site-packages/sqlalchemy/engine/base.py", line 1583, in _execute_20
    return meth(self, args_10style, kwargs_10style, execution_options)
           │    │     │             │               └ immutabledict({'synchronize_session': 'evaluate', '_sa_orm_update_options': default_update_options(_matched_objects=[], _reso...
           │    │     │             └ immutabledict({})
           │    │     └ ({},)
           │    └ <sqlalchemy.engine.base.Connection object at 0x7f2fb833f820>
           └ <bound method ClauseElement._execute_on_connection of <sqlalchemy.sql.annotation.AnnotatedUpdate object at 0x7f30185fdeb0>>
  File "/home/chase/.local/lib/python3.8/site-packages/sqlalchemy/sql/elements.py", line 323, in _execute_on_connection
    return connection._execute_clauseelement(
           │          └ <function Connection._execute_clauseelement at 0x7f31f39bc5e0>
           └ <sqlalchemy.engine.base.Connection object at 0x7f2fb833f820>
  File "/home/chase/.local/lib/python3.8/site-packages/sqlalchemy/engine/base.py", line 1452, in _execute_clauseelement
    ret = self._execute_context(
          │    └ <function Connection._execute_context at 0x7f31f39bc8b0>
          └ <sqlalchemy.engine.base.Connection object at 0x7f2fb833f820>
  File "/home/chase/.local/lib/python3.8/site-packages/sqlalchemy/engine/base.py", line 1814, in _execute_context
    self._handle_dbapi_exception(
    │    └ <function Connection._handle_dbapi_exception at 0x7f31f39bca60>
    └ <sqlalchemy.engine.base.Connection object at 0x7f2fb833f820>
  File "/home/chase/.local/lib/python3.8/site-packages/sqlalchemy/engine/base.py", line 1995, in _handle_dbapi_exception
    util.raise_(
    │    └ <function raise_ at 0x7f31f3d7ea60>
    └ <module 'sqlalchemy.util' from '/home/chase/.local/lib/python3.8/site-packages/sqlalchemy/util/__init__.py'>
  File "/home/chase/.local/lib/python3.8/site-packages/sqlalchemy/util/compat.py", line 207, in raise_
    raise exception
  File "/home/chase/.local/lib/python3.8/site-packages/sqlalchemy/engine/base.py", line 1771, in _execute_context
    self.dialect.do_execute(
    │    │       └ <function DefaultDialect.do_execute at 0x7f31f38f75e0>
    │    └ <sqlalchemy.dialects.mysql.pymysql.MySQLDialect_pymysql object at 0x7f3103ffde20>
    └ <sqlalchemy.engine.base.Connection object at 0x7f2fb833f820>
  File "/home/chase/.local/lib/python3.8/site-packages/sqlalchemy/engine/default.py", line 717, in do_execute
    cursor.execute(statement, parameters)
    │      │       │          └ {'server_id': '180.201.163.246:6800', 'ip': '180.201.163.246', 'username': 'chase', 'password': '2054387722598125417142331652...
    │      │       └ 'UPDATE device SET server_id=%(server_id)s, ip=%(ip)s, username=%(username)s, password=%(password)s, address=%(address)s, por...
    │      └ <function Cursor.execute at 0x7f31f354cdc0>
    └ <pymysql.cursors.Cursor object at 0x7f30185fd070>
  File "/home/chase/.local/lib/python3.8/site-packages/pymysql/cursors.py", line 148, in execute
    result = self._query(query)
             │    │      └ "UPDATE device SET server_id='180.201.163.246:6800', ip='180.201.163.246', username='chase', password='2054387722598125417142...
             │    └ <function Cursor._query at 0x7f31f34d7280>
             └ <pymysql.cursors.Cursor object at 0x7f30185fd070>
  File "/home/chase/.local/lib/python3.8/site-packages/pymysql/cursors.py", line 310, in _query
    conn.query(q)
    │    │     └ "UPDATE device SET server_id='180.201.163.246:6800', ip='180.201.163.246', username='chase', password='2054387722598125417142...
    │    └ <function Connection.query at 0x7f31f34e5670>
    └ <pymysql.connections.Connection object at 0x7f30786eabe0>
  File "/home/chase/.local/lib/python3.8/site-packages/pymysql/connections.py", line 548, in query
    self._affected_rows = self._read_query_result(unbuffered=unbuffered)
    │    │                │    │                             └ False
    │    │                │    └ <function Connection._read_query_result at 0x7f31f34e5ca0>
    │    │                └ <pymysql.connections.Connection object at 0x7f30786eabe0>
    │    └ 1
    └ <pymysql.connections.Connection object at 0x7f30786eabe0>
  File "/home/chase/.local/lib/python3.8/site-packages/pymysql/connections.py", line 775, in _read_query_result
    result.read()
    │      └ <function MySQLResult.read at 0x7f31f34e64c0>
    └ <pymysql.connections.MySQLResult object at 0x7f3102008730>
  File "/home/chase/.local/lib/python3.8/site-packages/pymysql/connections.py", line 1156, in read
    first_packet = self.connection._read_packet()
                   │    └ None
                   └ <pymysql.connections.MySQLResult object at 0x7f3102008730>
  File "/home/chase/.local/lib/python3.8/site-packages/pymysql/connections.py", line 725, in _read_packet
    packet.raise_for_error()
    │      └ <function MysqlPacket.raise_for_error at 0x7f31f34ddee0>
    └ <pymysql.protocol.MysqlPacket object at 0x7f2f987afa30>
  File "/home/chase/.local/lib/python3.8/site-packages/pymysql/protocol.py", line 221, in raise_for_error
    err.raise_mysql_exception(self._data)
    │   │                     │    └ <member '_data' of 'MysqlPacket' objects>
    │   │                     └ <pymysql.protocol.MysqlPacket object at 0x7f2f987afa30>
    │   └ <function raise_mysql_exception at 0x7f31f358c670>
    └ <module 'pymysql.err' from '/home/chase/.local/lib/python3.8/site-packages/pymysql/err.py'>
  File "/home/chase/.local/lib/python3.8/site-packages/pymysql/err.py", line 143, in raise_mysql_exception
    raise errorclass(errno, errval)
          │          │      └ "Duplicate entry '180.201.163.246:6800' for key 'device.PRIMARY'"
          │          └ 1062
          └ <class 'pymysql.err.IntegrityError'>

sqlalchemy.exc.IntegrityError: (pymysql.err.IntegrityError) (1062, "Duplicate entry '180.201.163.246:6800' for key 'device.PRIMARY'")
[SQL: UPDATE device SET server_id=%(server_id)s, ip=%(ip)s, username=%(username)s, password=%(password)s, address=%(address)s, port=%(port)s, valid=%(valid)s WHERE device.ip = %(ip_1)s]
[parameters: {'server_id': '180.201.163.246:6800', 'ip': '180.201.163.246', 'username': 'chase', 'password': '20543877225981254171423316526276474282864818123958240362740560536784990527811914460541191066343414114051590365662314459341951073952350314436545675314 ... (10 characters truncated) ... 37424621739142263242761346381504286587038230235758495979838468424073068352675526945522183250343348651104819615804843055808133004438732220378856335494', 'address': '/home/users/CT/pycharmproject/spiders/', 'port': 6800, 'valid': 1, 'ip_1': '180.201.163.246'}]
(Background on this error at: https://sqlalche.me/e/14/gkpj)
2022-05-14 02:58:41.189 | ERROR    | base.db.mysql:update:390 - 【mysql更新数据出错】
Traceback (most recent call last):

  File "/home/chase/.local/lib/python3.8/site-packages/sqlalchemy/engine/base.py", line 1771, in _execute_context
    self.dialect.do_execute(
    │    │       └ <function DefaultDialect.do_execute at 0x7f31f38f75e0>
    │    └ <sqlalchemy.dialects.mysql.pymysql.MySQLDialect_pymysql object at 0x7f3103ffde20>
    └ <sqlalchemy.engine.base.Connection object at 0x7f2fb83235b0>
  File "/home/chase/.local/lib/python3.8/site-packages/sqlalchemy/engine/default.py", line 717, in do_execute
    cursor.execute(statement, parameters)
    │      │       │          └ {'server_id': '180.201.163.246:6800', 'ip': '180.201.163.246', 'username': 'chase', 'password': '3303313517262501374972423115...
    │      │       └ 'UPDATE device SET server_id=%(server_id)s, ip=%(ip)s, username=%(username)s, password=%(password)s, address=%(address)s, por...
    │      └ <function Cursor.execute at 0x7f31f354cdc0>
    └ <pymysql.cursors.Cursor object at 0x7f30d84fab50>
  File "/home/chase/.local/lib/python3.8/site-packages/pymysql/cursors.py", line 148, in execute
    result = self._query(query)
             │    │      └ "UPDATE device SET server_id='180.201.163.246:6800', ip='180.201.163.246', username='chase', password='3303313517262501374972...
             │    └ <function Cursor._query at 0x7f31f34d7280>
             └ <pymysql.cursors.Cursor object at 0x7f30d84fab50>
  File "/home/chase/.local/lib/python3.8/site-packages/pymysql/cursors.py", line 310, in _query
    conn.query(q)
    │    │     └ "UPDATE device SET server_id='180.201.163.246:6800', ip='180.201.163.246', username='chase', password='3303313517262501374972...
    │    └ <function Connection.query at 0x7f31f34e5670>
    └ <pymysql.connections.Connection object at 0x7f30583005b0>
  File "/home/chase/.local/lib/python3.8/site-packages/pymysql/connections.py", line 548, in query
    self._affected_rows = self._read_query_result(unbuffered=unbuffered)
    │    │                │    │                             └ False
    │    │                │    └ <function Connection._read_query_result at 0x7f31f34e5ca0>
    │    │                └ <pymysql.connections.Connection object at 0x7f30583005b0>
    │    └ 1
    └ <pymysql.connections.Connection object at 0x7f30583005b0>
  File "/home/chase/.local/lib/python3.8/site-packages/pymysql/connections.py", line 775, in _read_query_result
    result.read()
    │      └ <function MySQLResult.read at 0x7f31f34e64c0>
    └ <pymysql.connections.MySQLResult object at 0x7f3018250e50>
  File "/home/chase/.local/lib/python3.8/site-packages/pymysql/connections.py", line 1156, in read
    first_packet = self.connection._read_packet()
                   │    └ None
                   └ <pymysql.connections.MySQLResult object at 0x7f3018250e50>
  File "/home/chase/.local/lib/python3.8/site-packages/pymysql/connections.py", line 725, in _read_packet
    packet.raise_for_error()
    │      └ <function MysqlPacket.raise_for_error at 0x7f31f34ddee0>
    └ <pymysql.protocol.MysqlPacket object at 0x7f30b84ee850>
  File "/home/chase/.local/lib/python3.8/site-packages/pymysql/protocol.py", line 221, in raise_for_error
    err.raise_mysql_exception(self._data)
    │   │                     │    └ <member '_data' of 'MysqlPacket' objects>
    │   │                     └ <pymysql.protocol.MysqlPacket object at 0x7f30b84ee850>
    │   └ <function raise_mysql_exception at 0x7f31f358c670>
    └ <module 'pymysql.err' from '/home/chase/.local/lib/python3.8/site-packages/pymysql/err.py'>
  File "/home/chase/.local/lib/python3.8/site-packages/pymysql/err.py", line 143, in raise_mysql_exception
    raise errorclass(errno, errval)
          │          │      └ "Duplicate entry '180.201.163.246:6800' for key 'device.PRIMARY'"
          │          └ 1062
          └ <class 'pymysql.err.IntegrityError'>

pymysql.err.IntegrityError: (1062, "Duplicate entry '180.201.163.246:6800' for key 'device.PRIMARY'")


The above exception was the direct cause of the following exception:


Traceback (most recent call last):

  File "/usr/lib/python3.8/threading.py", line 890, in _bootstrap
    self._bootstrap_inner()
    │    └ <function Thread._bootstrap_inner at 0x7f321bf29a60>
    └ <Thread(Thread-9139, started daemon 139838798739200)>
  File "/usr/lib/python3.8/threading.py", line 932, in _bootstrap_inner
    self.run()
    │    └ <function Thread.run at 0x7f321bf29790>
    └ <Thread(Thread-9139, started daemon 139838798739200)>
  File "/usr/lib/python3.8/threading.py", line 870, in run
    self._target(*self._args, **self._kwargs)
    │    │        │    │        │    └ {}
    │    │        │    │        └ <Thread(Thread-9139, started daemon 139838798739200)>
    │    │        │    └ ('ProjectManager.run_func_by_thread',)
    │    │        └ <Thread(Thread-9139, started daemon 139838798739200)>
    │    └ <bound method ProjectManager.get_request_from_keywords_hot of <monitor.projectManager.ProjectManager object at 0x7f31042e52e0>>
    └ <Thread(Thread-9139, started daemon 139838798739200)>

  File "/home/users/Scy/yuqing/spider/monitor/projectManager.py", line 799, in get_request_from_keywords_hot
    self.start_finished_spider_every_interval(project_names)
    │    │                                    └ ['default', 'test']
    │    └ <function ProjectManager.start_finished_spider_every_interval at 0x7f3104005280>
    └ <monitor.projectManager.ProjectManager object at 0x7f31042e52e0>

  File "/home/users/Scy/yuqing/spider/monitor/projectManager.py", line 784, in start_finished_spider_every_interval
    self[name].start_spider()
    │    └ 'default'
    └ <monitor.projectManager.ProjectManager object at 0x7f31042e52e0>

  File "/home/users/Scy/yuqing/spider/monitor/projectManager.py", line 366, in start_spider
    self.update_device_valid(device)
    │    │                   └ <monitor.deviceManager.DeviceC object at 0x7f3104029220>
    │    └ <function Project.update_device_valid at 0x7f3104003280>
    └ <monitor.projectManager.Project object at 0x7f3104029460>

  File "/home/users/Scy/yuqing/spider/monitor/projectManager.py", line 421, in update_device_valid
    self.database_manager.mysql.update(Device(**device.to_item()))
    │    │                │     │      │        │      └ <function DeviceC.to_item at 0x7f31f34ed310>
    │    │                │     │      │        └ <monitor.deviceManager.DeviceC object at 0x7f3104029220>
    │    │                │     │      └ <class 'base.db.mysql.Device'>
    │    │                │     └ <function Mysql.update at 0x7f31f35f4790>
    │    │                └ <base.db.mysql.Mysql object at 0x7f3103ffdfd0>
    │    └ <base.db.dbSlot.Slot object at 0x7f3103ffdf10>
    └ <monitor.projectManager.Project object at 0x7f3104029460>

> File "/home/users/Scy/yuqing/spider/base/db/mysql.py", line 375, in update
    row.update(new)
    │   │      └ {'server_id': '180.201.163.246:6800', 'ip': '180.201.163.246', 'username': 'chase', 'password': '3303313517262501374972423115...
    │   └ <function Query.update at 0x7f31f37333a0>
    └ <sqlalchemy.orm.query.Query object at 0x7f303838e970>

  File "/home/chase/.local/lib/python3.8/site-packages/sqlalchemy/orm/query.py", line 3221, in update
    result = self.session.execute(
             │    │       └ <function Session.execute at 0x7f31f370faf0>
             │    └ <sqlalchemy.orm.session.Session object at 0x7f30581339a0>
             └ <sqlalchemy.orm.query.Query object at 0x7f303838e970>
  File "/home/chase/.local/lib/python3.8/site-packages/sqlalchemy/orm/session.py", line 1689, in execute
    result = conn._execute_20(statement, params or {}, execution_options)
             │    │           │          │             └ immutabledict({'synchronize_session': 'evaluate', '_sa_orm_update_options': default_update_options(_matched_objects=[], _reso...
             │    │           │          └ immutabledict({})
             │    │           └ <sqlalchemy.sql.annotation.AnnotatedUpdate object at 0x7f30d84fae80>
             │    └ <function Connection._execute_20 at 0x7f31f39bc790>
             └ <sqlalchemy.engine.base.Connection object at 0x7f2fb83235b0>
  File "/home/chase/.local/lib/python3.8/site-packages/sqlalchemy/engine/base.py", line 1583, in _execute_20
    return meth(self, args_10style, kwargs_10style, execution_options)
           │    │     │             │               └ immutabledict({'synchronize_session': 'evaluate', '_sa_orm_update_options': default_update_options(_matched_objects=[], _reso...
           │    │     │             └ immutabledict({})
           │    │     └ ({},)
           │    └ <sqlalchemy.engine.base.Connection object at 0x7f2fb83235b0>
           └ <bound method ClauseElement._execute_on_connection of <sqlalchemy.sql.annotation.AnnotatedUpdate object at 0x7f30d84fae80>>
  File "/home/chase/.local/lib/python3.8/site-packages/sqlalchemy/sql/elements.py", line 323, in _execute_on_connection
    return connection._execute_clauseelement(
           │          └ <function Connection._execute_clauseelement at 0x7f31f39bc5e0>
           └ <sqlalchemy.engine.base.Connection object at 0x7f2fb83235b0>
  File "/home/chase/.local/lib/python3.8/site-packages/sqlalchemy/engine/base.py", line 1452, in _execute_clauseelement
    ret = self._execute_context(
          │    └ <function Connection._execute_context at 0x7f31f39bc8b0>
          └ <sqlalchemy.engine.base.Connection object at 0x7f2fb83235b0>
  File "/home/chase/.local/lib/python3.8/site-packages/sqlalchemy/engine/base.py", line 1814, in _execute_context
    self._handle_dbapi_exception(
    │    └ <function Connection._handle_dbapi_exception at 0x7f31f39bca60>
    └ <sqlalchemy.engine.base.Connection object at 0x7f2fb83235b0>
  File "/home/chase/.local/lib/python3.8/site-packages/sqlalchemy/engine/base.py", line 1995, in _handle_dbapi_exception
    util.raise_(
    │    └ <function raise_ at 0x7f31f3d7ea60>
    └ <module 'sqlalchemy.util' from '/home/chase/.local/lib/python3.8/site-packages/sqlalchemy/util/__init__.py'>
  File "/home/chase/.local/lib/python3.8/site-packages/sqlalchemy/util/compat.py", line 207, in raise_
    raise exception
  File "/home/chase/.local/lib/python3.8/site-packages/sqlalchemy/engine/base.py", line 1771, in _execute_context
    self.dialect.do_execute(
    │    │       └ <function DefaultDialect.do_execute at 0x7f31f38f75e0>
    │    └ <sqlalchemy.dialects.mysql.pymysql.MySQLDialect_pymysql object at 0x7f3103ffde20>
    └ <sqlalchemy.engine.base.Connection object at 0x7f2fb83235b0>
  File "/home/chase/.local/lib/python3.8/site-packages/sqlalchemy/engine/default.py", line 717, in do_execute
    cursor.execute(statement, parameters)
    │      │       │          └ {'server_id': '180.201.163.246:6800', 'ip': '180.201.163.246', 'username': 'chase', 'password': '3303313517262501374972423115...
    │      │       └ 'UPDATE device SET server_id=%(server_id)s, ip=%(ip)s, username=%(username)s, password=%(password)s, address=%(address)s, por...
    │      └ <function Cursor.execute at 0x7f31f354cdc0>
    └ <pymysql.cursors.Cursor object at 0x7f30d84fab50>
  File "/home/chase/.local/lib/python3.8/site-packages/pymysql/cursors.py", line 148, in execute
    result = self._query(query)
             │    │      └ "UPDATE device SET server_id='180.201.163.246:6800', ip='180.201.163.246', username='chase', password='3303313517262501374972...
             │    └ <function Cursor._query at 0x7f31f34d7280>
             └ <pymysql.cursors.Cursor object at 0x7f30d84fab50>
  File "/home/chase/.local/lib/python3.8/site-packages/pymysql/cursors.py", line 310, in _query
    conn.query(q)
    │    │     └ "UPDATE device SET server_id='180.201.163.246:6800', ip='180.201.163.246', username='chase', password='3303313517262501374972...
    │    └ <function Connection.query at 0x7f31f34e5670>
    └ <pymysql.connections.Connection object at 0x7f30583005b0>
  File "/home/chase/.local/lib/python3.8/site-packages/pymysql/connections.py", line 548, in query
    self._affected_rows = self._read_query_result(unbuffered=unbuffered)
    │    │                │    │                             └ False
    │    │                │    └ <function Connection._read_query_result at 0x7f31f34e5ca0>
    │    │                └ <pymysql.connections.Connection object at 0x7f30583005b0>
    │    └ 1
    └ <pymysql.connections.Connection object at 0x7f30583005b0>
  File "/home/chase/.local/lib/python3.8/site-packages/pymysql/connections.py", line 775, in _read_query_result
    result.read()
    │      └ <function MySQLResult.read at 0x7f31f34e64c0>
    └ <pymysql.connections.MySQLResult object at 0x7f3018250e50>
  File "/home/chase/.local/lib/python3.8/site-packages/pymysql/connections.py", line 1156, in read
    first_packet = self.connection._read_packet()
                   │    └ None
                   └ <pymysql.connections.MySQLResult object at 0x7f3018250e50>
  File "/home/chase/.local/lib/python3.8/site-packages/pymysql/connections.py", line 725, in _read_packet
    packet.raise_for_error()
    │      └ <function MysqlPacket.raise_for_error at 0x7f31f34ddee0>
    └ <pymysql.protocol.MysqlPacket object at 0x7f30b84ee850>
  File "/home/chase/.local/lib/python3.8/site-packages/pymysql/protocol.py", line 221, in raise_for_error
    err.raise_mysql_exception(self._data)
    │   │                     │    └ <member '_data' of 'MysqlPacket' objects>
    │   │                     └ <pymysql.protocol.MysqlPacket object at 0x7f30b84ee850>
    │   └ <function raise_mysql_exception at 0x7f31f358c670>
    └ <module 'pymysql.err' from '/home/chase/.local/lib/python3.8/site-packages/pymysql/err.py'>
  File "/home/chase/.local/lib/python3.8/site-packages/pymysql/err.py", line 143, in raise_mysql_exception
    raise errorclass(errno, errval)
          │          │      └ "Duplicate entry '180.201.163.246:6800' for key 'device.PRIMARY'"
          │          └ 1062
          └ <class 'pymysql.err.IntegrityError'>

sqlalchemy.exc.IntegrityError: (pymysql.err.IntegrityError) (1062, "Duplicate entry '180.201.163.246:6800' for key 'device.PRIMARY'")
[SQL: UPDATE device SET server_id=%(server_id)s, ip=%(ip)s, username=%(username)s, password=%(password)s, address=%(address)s, port=%(port)s, valid=%(valid)s WHERE device.ip = %(ip_1)s]
[parameters: {'server_id': '180.201.163.246:6800', 'ip': '180.201.163.246', 'username': 'chase', 'password': '33033135172625013749724231152283788448495054089384488365714795796698524189261300505092933151516093362244316096325235560579563687035189979850149050168 ... (10 characters truncated) ... 62963517184732051731141088162947556532153481407097306469823116937486825427346416259632647866818059830366324643460801293993925491482829810044426804252', 'address': '/home/users/CT/pycharmproject/spiders/', 'port': 6800, 'valid': 1, 'ip_1': '180.201.163.246'}]
(Background on this error at: https://sqlalche.me/e/14/gkpj)
2022-05-14 02:58:53.353 | ERROR    | base.db.mysql:update:390 - 【mysql更新数据出错】
Traceback (most recent call last):

  File "/usr/lib/python3.8/threading.py", line 890, in _bootstrap
    self._bootstrap_inner()
    │    └ <function Thread._bootstrap_inner at 0x7f321bf29a60>
    └ <Thread(Thread-9134, started daemon 139838899451648)>
  File "/usr/lib/python3.8/threading.py", line 932, in _bootstrap_inner
    self.run()
    │    └ <function Thread.run at 0x7f321bf29790>
    └ <Thread(Thread-9134, started daemon 139838899451648)>
  File "/usr/lib/python3.8/threading.py", line 870, in run
    self._target(*self._args, **self._kwargs)
    │    │        │    │        │    └ {}
    │    │        │    │        └ <Thread(Thread-9134, started daemon 139838899451648)>
    │    │        │    └ ('ProjectManager.run_func_by_thread',)
    │    │        └ <Thread(Thread-9134, started daemon 139838899451648)>
    │    └ <bound method ProjectManager.get_request_from_keywords_hot of <monitor.projectManager.ProjectManager object at 0x7f31042e52e0>>
    └ <Thread(Thread-9134, started daemon 139838899451648)>

  File "/home/users/Scy/yuqing/spider/monitor/projectManager.py", line 799, in get_request_from_keywords_hot
    self.start_finished_spider_every_interval(project_names)
    │    │                                    └ ['default', 'test']
    │    └ <function ProjectManager.start_finished_spider_every_interval at 0x7f3104005280>
    └ <monitor.projectManager.ProjectManager object at 0x7f31042e52e0>

  File "/home/users/Scy/yuqing/spider/monitor/projectManager.py", line 784, in start_finished_spider_every_interval
    self[name].start_spider()
    │    └ 'default'
    └ <monitor.projectManager.ProjectManager object at 0x7f31042e52e0>

  File "/home/users/Scy/yuqing/spider/monitor/projectManager.py", line 366, in start_spider
    self.update_device_valid(device)
    │    │                   └ <monitor.deviceManager.DeviceC object at 0x7f3104029220>
    │    └ <function Project.update_device_valid at 0x7f3104003280>
    └ <monitor.projectManager.Project object at 0x7f3104029460>

  File "/home/users/Scy/yuqing/spider/monitor/projectManager.py", line 421, in update_device_valid
    self.database_manager.mysql.update(Device(**device.to_item()))
    │    │                │     │      │        │      └ <function DeviceC.to_item at 0x7f31f34ed310>
    │    │                │     │      │        └ <monitor.deviceManager.DeviceC object at 0x7f3104029220>
    │    │                │     │      └ <class 'base.db.mysql.Device'>
    │    │                │     └ <function Mysql.update at 0x7f31f35f4790>
    │    │                └ <base.db.mysql.Mysql object at 0x7f3103ffdfd0>
    │    └ <base.db.dbSlot.Slot object at 0x7f3103ffdf10>
    └ <monitor.projectManager.Project object at 0x7f3104029460>

> File "/home/users/Scy/yuqing/spider/base/db/mysql.py", line 373, in update
    if row.all():
       │   └ <function Query.all at 0x7f31f3730700>
       └ <sqlalchemy.orm.query.Query object at 0x7f3018278700>

  File "/home/chase/.local/lib/python3.8/site-packages/sqlalchemy/orm/query.py", line 2711, in all
    return self._iter().all()
           │    └ <function Query._iter at 0x7f31f3730e50>
           └ <sqlalchemy.orm.query.Query object at 0x7f3018278700>
  File "/home/chase/.local/lib/python3.8/site-packages/sqlalchemy/orm/query.py", line 2846, in _iter
    result = self.session.execute(
             │    │       └ <function Session.execute at 0x7f31f370faf0>
             │    └ <sqlalchemy.orm.session.Session object at 0x7f2fd8040250>
             └ <sqlalchemy.orm.query.Query object at 0x7f3018278700>
  File "/home/chase/.local/lib/python3.8/site-packages/sqlalchemy/orm/session.py", line 1688, in execute
    conn = self._connection_for_bind(bind)
           │    │                    └ Engine(mysql+pymysql://root:***@180.201.163.246:33061/spider?autocommit=true&charset=utf8)
           │    └ <function Session._connection_for_bind at 0x7f31f370fa60>
           └ <sqlalchemy.orm.session.Session object at 0x7f2fd8040250>
  File "/home/chase/.local/lib/python3.8/site-packages/sqlalchemy/orm/session.py", line 1529, in _connection_for_bind
    return self._transaction._connection_for_bind(
           │    │            └ <function SessionTransaction._connection_for_bind at 0x7f31f370c670>
           │    └ <sqlalchemy.orm.session.SessionTransaction object at 0x7f3018278f10>
           └ <sqlalchemy.orm.session.Session object at 0x7f2fd8040250>
  File "/home/chase/.local/lib/python3.8/site-packages/sqlalchemy/orm/session.py", line 747, in _connection_for_bind
    conn = bind.connect()
           │    └ <function Engine.connect at 0x7f31f39c6040>
           └ Engine(mysql+pymysql://root:***@180.201.163.246:33061/spider?autocommit=true&charset=utf8)
  File "/home/chase/.local/lib/python3.8/site-packages/sqlalchemy/engine/base.py", line 3166, in connect
    return self._connection_cls(self, close_with_result=close_with_result)
           │    │               │                       └ False
           │    │               └ Engine(mysql+pymysql://root:***@180.201.163.246:33061/spider?autocommit=true&charset=utf8)
           │    └ <class 'sqlalchemy.engine.base.Connection'>
           └ Engine(mysql+pymysql://root:***@180.201.163.246:33061/spider?autocommit=true&charset=utf8)
  File "/home/chase/.local/lib/python3.8/site-packages/sqlalchemy/engine/base.py", line 96, in __init__
    else engine.raw_connection()
         │      └ <function Engine.raw_connection at 0x7f31f39c64c0>
         └ Engine(mysql+pymysql://root:***@180.201.163.246:33061/spider?autocommit=true&charset=utf8)
  File "/home/chase/.local/lib/python3.8/site-packages/sqlalchemy/engine/base.py", line 3245, in raw_connection
    return self._wrap_pool_connect(self.pool.connect, _connection)
           │    │                  │    │    │        └ None
           │    │                  │    │    └ <function Pool.connect at 0x7f31f396f550>
           │    │                  │    └ <sqlalchemy.pool.impl.QueuePool object at 0x7f3103ffdb20>
           │    │                  └ Engine(mysql+pymysql://root:***@180.201.163.246:33061/spider?autocommit=true&charset=utf8)
           │    └ <function Engine._wrap_pool_connect at 0x7f31f39c60d0>
           └ Engine(mysql+pymysql://root:***@180.201.163.246:33061/spider?autocommit=true&charset=utf8)
  File "/home/chase/.local/lib/python3.8/site-packages/sqlalchemy/engine/base.py", line 3212, in _wrap_pool_connect
    return fn()
           └ <bound method Pool.connect of <sqlalchemy.pool.impl.QueuePool object at 0x7f3103ffdb20>>
  File "/home/chase/.local/lib/python3.8/site-packages/sqlalchemy/pool/base.py", line 307, in connect
    return _ConnectionFairy._checkout(self)
           │                │         └ <sqlalchemy.pool.impl.QueuePool object at 0x7f3103ffdb20>
           │                └ <classmethod object at 0x7f31f3969a00>
           └ <class 'sqlalchemy.pool.base._ConnectionFairy'>
  File "/home/chase/.local/lib/python3.8/site-packages/sqlalchemy/pool/base.py", line 767, in _checkout
    fairy = _ConnectionRecord.checkout(pool)
            │                 │        └ <sqlalchemy.pool.impl.QueuePool object at 0x7f3103ffdb20>
            │                 └ <classmethod object at 0x7f31f39699a0>
            └ <class 'sqlalchemy.pool.base._ConnectionRecord'>
  File "/home/chase/.local/lib/python3.8/site-packages/sqlalchemy/pool/base.py", line 425, in checkout
    rec = pool._do_get()
          │    └ <function QueuePool._do_get at 0x7f31f39819d0>
          └ <sqlalchemy.pool.impl.QueuePool object at 0x7f3103ffdb20>
  File "/home/chase/.local/lib/python3.8/site-packages/sqlalchemy/pool/impl.py", line 134, in _do_get
    raise exc.TimeoutError(
          │   └ <class 'sqlalchemy.exc.TimeoutError'>
          └ <module 'sqlalchemy.exc' from '/home/chase/.local/lib/python3.8/site-packages/sqlalchemy/exc.py'>

sqlalchemy.exc.TimeoutError: QueuePool limit of size 5 overflow 10 reached, connection timed out, timeout 30.00 (Background on this error at: https://sqlalche.me/e/14/3o7r)
2022-05-14 02:58:59.446 | ERROR    | base.db.mysql:update:390 - 【mysql更新数据出错】
Traceback (most recent call last):

  File "/home/chase/.local/lib/python3.8/site-packages/sqlalchemy/engine/base.py", line 1771, in _execute_context
    self.dialect.do_execute(
    │    │       └ <function DefaultDialect.do_execute at 0x7f31f38f75e0>
    │    └ <sqlalchemy.dialects.mysql.pymysql.MySQLDialect_pymysql object at 0x7f3103ffde20>
    └ <sqlalchemy.engine.base.Connection object at 0x7f309855cf40>
  File "/home/chase/.local/lib/python3.8/site-packages/sqlalchemy/engine/default.py", line 717, in do_execute
    cursor.execute(statement, parameters)
    │      │       │          └ {'server_id': '180.201.163.246:6800', 'ip': '180.201.163.246', 'username': 'chase', 'password': '8790219917433061930899241978...
    │      │       └ 'UPDATE device SET server_id=%(server_id)s, ip=%(ip)s, username=%(username)s, password=%(password)s, address=%(address)s, por...
    │      └ <function Cursor.execute at 0x7f31f354cdc0>
    └ <pymysql.cursors.Cursor object at 0x7f30b8315310>
  File "/home/chase/.local/lib/python3.8/site-packages/pymysql/cursors.py", line 148, in execute
    result = self._query(query)
             │    │      └ "UPDATE device SET server_id='180.201.163.246:6800', ip='180.201.163.246', username='chase', password='8790219917433061930899...
             │    └ <function Cursor._query at 0x7f31f34d7280>
             └ <pymysql.cursors.Cursor object at 0x7f30b8315310>
  File "/home/chase/.local/lib/python3.8/site-packages/pymysql/cursors.py", line 310, in _query
    conn.query(q)
    │    │     └ "UPDATE device SET server_id='180.201.163.246:6800', ip='180.201.163.246', username='chase', password='8790219917433061930899...
    │    └ <function Connection.query at 0x7f31f34e5670>
    └ <pymysql.connections.Connection object at 0x7f2f98568490>
  File "/home/chase/.local/lib/python3.8/site-packages/pymysql/connections.py", line 548, in query
    self._affected_rows = self._read_query_result(unbuffered=unbuffered)
    │    │                │    │                             └ False
    │    │                │    └ <function Connection._read_query_result at 0x7f31f34e5ca0>
    │    │                └ <pymysql.connections.Connection object at 0x7f2f98568490>
    │    └ 1
    └ <pymysql.connections.Connection object at 0x7f2f98568490>
  File "/home/chase/.local/lib/python3.8/site-packages/pymysql/connections.py", line 775, in _read_query_result
    result.read()
    │      └ <function MySQLResult.read at 0x7f31f34e64c0>
    └ <pymysql.connections.MySQLResult object at 0x7f3102172070>
  File "/home/chase/.local/lib/python3.8/site-packages/pymysql/connections.py", line 1156, in read
    first_packet = self.connection._read_packet()
                   │    └ None
                   └ <pymysql.connections.MySQLResult object at 0x7f3102172070>
  File "/home/chase/.local/lib/python3.8/site-packages/pymysql/connections.py", line 725, in _read_packet
    packet.raise_for_error()
    │      └ <function MysqlPacket.raise_for_error at 0x7f31f34ddee0>
    └ <pymysql.protocol.MysqlPacket object at 0x7f307838f940>
  File "/home/chase/.local/lib/python3.8/site-packages/pymysql/protocol.py", line 221, in raise_for_error
    err.raise_mysql_exception(self._data)
    │   │                     │    └ <member '_data' of 'MysqlPacket' objects>
    │   │                     └ <pymysql.protocol.MysqlPacket object at 0x7f307838f940>
    │   └ <function raise_mysql_exception at 0x7f31f358c670>
    └ <module 'pymysql.err' from '/home/chase/.local/lib/python3.8/site-packages/pymysql/err.py'>
  File "/home/chase/.local/lib/python3.8/site-packages/pymysql/err.py", line 143, in raise_mysql_exception
    raise errorclass(errno, errval)
          │          │      └ "Duplicate entry '180.201.163.246:6800' for key 'device.PRIMARY'"
          │          └ 1062
          └ <class 'pymysql.err.IntegrityError'>

pymysql.err.IntegrityError: (1062, "Duplicate entry '180.201.163.246:6800' for key 'device.PRIMARY'")


The above exception was the direct cause of the following exception:


Traceback (most recent call last):

  File "/usr/lib/python3.8/threading.py", line 890, in _bootstrap
    self._bootstrap_inner()
    │    └ <function Thread._bootstrap_inner at 0x7f321bf29a60>
    └ <Thread(Thread-9144, started daemon 139838832310016)>
  File "/usr/lib/python3.8/threading.py", line 932, in _bootstrap_inner
    self.run()
    │    └ <function Thread.run at 0x7f321bf29790>
    └ <Thread(Thread-9144, started daemon 139838832310016)>
  File "/usr/lib/python3.8/threading.py", line 870, in run
    self._target(*self._args, **self._kwargs)
    │    │        │    │        │    └ {}
    │    │        │    │        └ <Thread(Thread-9144, started daemon 139838832310016)>
    │    │        │    └ ('ProjectManager.run_func_by_thread',)
    │    │        └ <Thread(Thread-9144, started daemon 139838832310016)>
    │    └ <bound method ProjectManager.get_request_from_keywords_hot of <monitor.projectManager.ProjectManager object at 0x7f31042e52e0>>
    └ <Thread(Thread-9144, started daemon 139838832310016)>

  File "/home/users/Scy/yuqing/spider/monitor/projectManager.py", line 799, in get_request_from_keywords_hot
    self.start_finished_spider_every_interval(project_names)
    │    │                                    └ ['default', 'test']
    │    └ <function ProjectManager.start_finished_spider_every_interval at 0x7f3104005280>
    └ <monitor.projectManager.ProjectManager object at 0x7f31042e52e0>

  File "/home/users/Scy/yuqing/spider/monitor/projectManager.py", line 784, in start_finished_spider_every_interval
    self[name].start_spider()
    │    └ 'default'
    └ <monitor.projectManager.ProjectManager object at 0x7f31042e52e0>

  File "/home/users/Scy/yuqing/spider/monitor/projectManager.py", line 366, in start_spider
    self.update_device_valid(device)
    │    │                   └ <monitor.deviceManager.DeviceC object at 0x7f3104029220>
    │    └ <function Project.update_device_valid at 0x7f3104003280>
    └ <monitor.projectManager.Project object at 0x7f3104029460>

  File "/home/users/Scy/yuqing/spider/monitor/projectManager.py", line 421, in update_device_valid
    self.database_manager.mysql.update(Device(**device.to_item()))
    │    │                │     │      │        │      └ <function DeviceC.to_item at 0x7f31f34ed310>
    │    │                │     │      │        └ <monitor.deviceManager.DeviceC object at 0x7f3104029220>
    │    │                │     │      └ <class 'base.db.mysql.Device'>
    │    │                │     └ <function Mysql.update at 0x7f31f35f4790>
    │    │                └ <base.db.mysql.Mysql object at 0x7f3103ffdfd0>
    │    └ <base.db.dbSlot.Slot object at 0x7f3103ffdf10>
    └ <monitor.projectManager.Project object at 0x7f3104029460>

> File "/home/users/Scy/yuqing/spider/base/db/mysql.py", line 375, in update
    row.update(new)
    │   │      └ {'server_id': '180.201.163.246:6800', 'ip': '180.201.163.246', 'username': 'chase', 'password': '8790219917433061930899241978...
    │   └ <function Query.update at 0x7f31f37333a0>
    └ <sqlalchemy.orm.query.Query object at 0x7f2fb87d2ac0>

  File "/home/chase/.local/lib/python3.8/site-packages/sqlalchemy/orm/query.py", line 3221, in update
    result = self.session.execute(
             │    │       └ <function Session.execute at 0x7f31f370faf0>
             │    └ <sqlalchemy.orm.session.Session object at 0x7f2f982d13d0>
             └ <sqlalchemy.orm.query.Query object at 0x7f2fb87d2ac0>
  File "/home/chase/.local/lib/python3.8/site-packages/sqlalchemy/orm/session.py", line 1689, in execute
    result = conn._execute_20(statement, params or {}, execution_options)
             │    │           │          │             └ immutabledict({'synchronize_session': 'evaluate', '_sa_orm_update_options': default_update_options(_matched_objects=[], _reso...
             │    │           │          └ immutabledict({})
             │    │           └ <sqlalchemy.sql.annotation.AnnotatedUpdate object at 0x7f3100057cd0>
             │    └ <function Connection._execute_20 at 0x7f31f39bc790>
             └ <sqlalchemy.engine.base.Connection object at 0x7f309855cf40>
  File "/home/chase/.local/lib/python3.8/site-packages/sqlalchemy/engine/base.py", line 1583, in _execute_20
    return meth(self, args_10style, kwargs_10style, execution_options)
           │    │     │             │               └ immutabledict({'synchronize_session': 'evaluate', '_sa_orm_update_options': default_update_options(_matched_objects=[], _reso...
           │    │     │             └ immutabledict({})
           │    │     └ ({},)
           │    └ <sqlalchemy.engine.base.Connection object at 0x7f309855cf40>
           └ <bound method ClauseElement._execute_on_connection of <sqlalchemy.sql.annotation.AnnotatedUpdate object at 0x7f3100057cd0>>
  File "/home/chase/.local/lib/python3.8/site-packages/sqlalchemy/sql/elements.py", line 323, in _execute_on_connection
    return connection._execute_clauseelement(
           │          └ <function Connection._execute_clauseelement at 0x7f31f39bc5e0>
           └ <sqlalchemy.engine.base.Connection object at 0x7f309855cf40>
  File "/home/chase/.local/lib/python3.8/site-packages/sqlalchemy/engine/base.py", line 1452, in _execute_clauseelement
    ret = self._execute_context(
          │    └ <function Connection._execute_context at 0x7f31f39bc8b0>
          └ <sqlalchemy.engine.base.Connection object at 0x7f309855cf40>
  File "/home/chase/.local/lib/python3.8/site-packages/sqlalchemy/engine/base.py", line 1814, in _execute_context
    self._handle_dbapi_exception(
    │    └ <function Connection._handle_dbapi_exception at 0x7f31f39bca60>
    └ <sqlalchemy.engine.base.Connection object at 0x7f309855cf40>
  File "/home/chase/.local/lib/python3.8/site-packages/sqlalchemy/engine/base.py", line 1995, in _handle_dbapi_exception
    util.raise_(
    │    └ <function raise_ at 0x7f31f3d7ea60>
    └ <module 'sqlalchemy.util' from '/home/chase/.local/lib/python3.8/site-packages/sqlalchemy/util/__init__.py'>
  File "/home/chase/.local/lib/python3.8/site-packages/sqlalchemy/util/compat.py", line 207, in raise_
    raise exception
  File "/home/chase/.local/lib/python3.8/site-packages/sqlalchemy/engine/base.py", line 1771, in _execute_context
    self.dialect.do_execute(
    │    │       └ <function DefaultDialect.do_execute at 0x7f31f38f75e0>
    │    └ <sqlalchemy.dialects.mysql.pymysql.MySQLDialect_pymysql object at 0x7f3103ffde20>
    └ <sqlalchemy.engine.base.Connection object at 0x7f309855cf40>
  File "/home/chase/.local/lib/python3.8/site-packages/sqlalchemy/engine/default.py", line 717, in do_execute
    cursor.execute(statement, parameters)
    │      │       │          └ {'server_id': '180.201.163.246:6800', 'ip': '180.201.163.246', 'username': 'chase', 'password': '8790219917433061930899241978...
    │      │       └ 'UPDATE device SET server_id=%(server_id)s, ip=%(ip)s, username=%(username)s, password=%(password)s, address=%(address)s, por...
    │      └ <function Cursor.execute at 0x7f31f354cdc0>
    └ <pymysql.cursors.Cursor object at 0x7f30b8315310>
  File "/home/chase/.local/lib/python3.8/site-packages/pymysql/cursors.py", line 148, in execute
    result = self._query(query)
             │    │      └ "UPDATE device SET server_id='180.201.163.246:6800', ip='180.201.163.246', username='chase', password='8790219917433061930899...
             │    └ <function Cursor._query at 0x7f31f34d7280>
             └ <pymysql.cursors.Cursor object at 0x7f30b8315310>
  File "/home/chase/.local/lib/python3.8/site-packages/pymysql/cursors.py", line 310, in _query
    conn.query(q)
    │    │     └ "UPDATE device SET server_id='180.201.163.246:6800', ip='180.201.163.246', username='chase', password='8790219917433061930899...
    │    └ <function Connection.query at 0x7f31f34e5670>
    └ <pymysql.connections.Connection object at 0x7f2f98568490>
  File "/home/chase/.local/lib/python3.8/site-packages/pymysql/connections.py", line 548, in query
    self._affected_rows = self._read_query_result(unbuffered=unbuffered)
    │    │                │    │                             └ False
    │    │                │    └ <function Connection._read_query_result at 0x7f31f34e5ca0>
    │    │                └ <pymysql.connections.Connection object at 0x7f2f98568490>
    │    └ 1
    └ <pymysql.connections.Connection object at 0x7f2f98568490>
  File "/home/chase/.local/lib/python3.8/site-packages/pymysql/connections.py", line 775, in _read_query_result
    result.read()
    │      └ <function MySQLResult.read at 0x7f31f34e64c0>
    └ <pymysql.connections.MySQLResult object at 0x7f3102172070>
  File "/home/chase/.local/lib/python3.8/site-packages/pymysql/connections.py", line 1156, in read
    first_packet = self.connection._read_packet()
                   │    └ None
                   └ <pymysql.connections.MySQLResult object at 0x7f3102172070>
  File "/home/chase/.local/lib/python3.8/site-packages/pymysql/connections.py", line 725, in _read_packet
    packet.raise_for_error()
    │      └ <function MysqlPacket.raise_for_error at 0x7f31f34ddee0>
    └ <pymysql.protocol.MysqlPacket object at 0x7f307838f940>
  File "/home/chase/.local/lib/python3.8/site-packages/pymysql/protocol.py", line 221, in raise_for_error
    err.raise_mysql_exception(self._data)
    │   │                     │    └ <member '_data' of 'MysqlPacket' objects>
    │   │                     └ <pymysql.protocol.MysqlPacket object at 0x7f307838f940>
    │   └ <function raise_mysql_exception at 0x7f31f358c670>
    └ <module 'pymysql.err' from '/home/chase/.local/lib/python3.8/site-packages/pymysql/err.py'>
  File "/home/chase/.local/lib/python3.8/site-packages/pymysql/err.py", line 143, in raise_mysql_exception
    raise errorclass(errno, errval)
          │          │      └ "Duplicate entry '180.201.163.246:6800' for key 'device.PRIMARY'"
          │          └ 1062
          └ <class 'pymysql.err.IntegrityError'>

sqlalchemy.exc.IntegrityError: (pymysql.err.IntegrityError) (1062, "Duplicate entry '180.201.163.246:6800' for key 'device.PRIMARY'")
[SQL: UPDATE device SET server_id=%(server_id)s, ip=%(ip)s, username=%(username)s, password=%(password)s, address=%(address)s, port=%(port)s, valid=%(valid)s WHERE device.ip = %(ip_1)s]
[parameters: {'server_id': '180.201.163.246:6800', 'ip': '180.201.163.246', 'username': 'chase', 'password': '87902199174330619308992419789513126601582822798433966033192614866668505322628737156664024512989221840981336433964722881491924952601871302940590277940 ... (10 characters truncated) ... 79400777436004908205451536722187336401268722700524680667185146678923601028637705405941568228573321250973895360139698400486892477867513633103827840271', 'address': '/home/users/CT/pycharmproject/spiders/', 'port': 6800, 'valid': 1, 'ip_1': '180.201.163.246'}]
(Background on this error at: https://sqlalche.me/e/14/gkpj)
