2022-05-12 15:51:34.957 | ERROR    | monitor.searchSpiders.people:get_request_from_keyword:45 - E 人民网错误HTTPConnectionPool(host='search.people.cn', port=80): Max retries exceeded with url: /search-platform/front/search (Caused by NewConnectionError('<urllib3.connection.HTTPConnection object at 0x7f910408cdc0>: Failed to establish a new connection: [Errno 111] Connection refused'))
Traceback (most recent call last):

  File "/home/chase/.local/lib/python3.8/site-packages/urllib3/connection.py", line 174, in _new_conn
    conn = connection.create_connection(
           │          └ <function create_connection at 0x7f92585fd1f0>
           └ <module 'urllib3.util.connection' from '/home/chase/.local/lib/python3.8/site-packages/urllib3/util/connection.py'>
  File "/home/chase/.local/lib/python3.8/site-packages/urllib3/util/connection.py", line 96, in create_connection
    raise err
          └ ConnectionRefusedError(111, 'Connection refused')
  File "/home/chase/.local/lib/python3.8/site-packages/urllib3/util/connection.py", line 86, in create_connection
    sock.connect(sa)
    │            └ ('1.31.128.250', 80)
    └ None

ConnectionRefusedError: [Errno 111] Connection refused


During handling of the above exception, another exception occurred:


Traceback (most recent call last):

  File "/home/chase/.local/lib/python3.8/site-packages/urllib3/connectionpool.py", line 699, in urlopen
    httplib_response = self._make_request(
                       │    └ <function HTTPConnectionPool._make_request at 0x7f92585c05e0>
                       └ <urllib3.connectionpool.HTTPConnectionPool object at 0x7f91601f9a60>
  File "/home/chase/.local/lib/python3.8/site-packages/urllib3/connectionpool.py", line 394, in _make_request
    conn.request(method, url, **httplib_request_kw)
    │    │       │       │      └ {'body': b'{"key": "\\u534e\\u5357\\u6709\\u6301\\u7eed\\u6027\\u5f3a\\u964d\\u96e8 \\u591a\\u5730\\u6c14\\u8c61\\u90e8\\u95e...
    │    │       │       └ '/search-platform/front/search'
    │    │       └ 'POST'
    │    └ <function HTTPConnection.request at 0x7f92585b0f70>
    └ <urllib3.connection.HTTPConnection object at 0x7f910408cdc0>
  File "/home/chase/.local/lib/python3.8/site-packages/urllib3/connection.py", line 239, in request
    super(HTTPConnection, self).request(method, url, body=body, headers=headers)
          │               │             │       │         │             └ {'User-Agent': 'Mozilla/5.0 (Windows NT 10.0; Win64; x64) AppleWebKit/537.36 (KHTML, like Gecko) Chrome/101.0.4951.54 Safari/...
          │               │             │       │         └ b'{"key": "\\u534e\\u5357\\u6709\\u6301\\u7eed\\u6027\\u5f3a\\u964d\\u96e8 \\u591a\\u5730\\u6c14\\u8c61\\u90e8\\u95e8\\u5f3a\...
          │               │             │       └ '/search-platform/front/search'
          │               │             └ 'POST'
          │               └ <urllib3.connection.HTTPConnection object at 0x7f910408cdc0>
          └ <class 'urllib3.connection.HTTPConnection'>
  File "/usr/lib/python3.8/http/client.py", line 1256, in request
    self._send_request(method, url, body, headers, encode_chunked)
    │    │             │       │    │     │        └ False
    │    │             │       │    │     └ {'User-Agent': 'Mozilla/5.0 (Windows NT 10.0; Win64; x64) AppleWebKit/537.36 (KHTML, like Gecko) Chrome/101.0.4951.54 Safari/...
    │    │             │       │    └ b'{"key": "\\u534e\\u5357\\u6709\\u6301\\u7eed\\u6027\\u5f3a\\u964d\\u96e8 \\u591a\\u5730\\u6c14\\u8c61\\u90e8\\u95e8\\u5f3a\...
    │    │             │       └ '/search-platform/front/search'
    │    │             └ 'POST'
    │    └ <function HTTPConnection._send_request at 0x7f926be50280>
    └ <urllib3.connection.HTTPConnection object at 0x7f910408cdc0>
  File "/usr/lib/python3.8/http/client.py", line 1302, in _send_request
    self.endheaders(body, encode_chunked=encode_chunked)
    │    │          │                    └ False
    │    │          └ b'{"key": "\\u534e\\u5357\\u6709\\u6301\\u7eed\\u6027\\u5f3a\\u964d\\u96e8 \\u591a\\u5730\\u6c14\\u8c61\\u90e8\\u95e8\\u5f3a\...
    │    └ <function HTTPConnection.endheaders at 0x7f926be50160>
    └ <urllib3.connection.HTTPConnection object at 0x7f910408cdc0>
  File "/usr/lib/python3.8/http/client.py", line 1251, in endheaders
    self._send_output(message_body, encode_chunked=encode_chunked)
    │    │            │                            └ False
    │    │            └ b'{"key": "\\u534e\\u5357\\u6709\\u6301\\u7eed\\u6027\\u5f3a\\u964d\\u96e8 \\u591a\\u5730\\u6c14\\u8c61\\u90e8\\u95e8\\u5f3a\...
    │    └ <function HTTPConnection._send_output at 0x7f926beb7d30>
    └ <urllib3.connection.HTTPConnection object at 0x7f910408cdc0>
  File "/usr/lib/python3.8/http/client.py", line 1011, in _send_output
    self.send(msg)
    │    │    └ b'POST /search-platform/front/search HTTP/1.1\r\nHost: search.people.cn\r\nUser-Agent: Mozilla/5.0 (Windows NT 10.0; Win64; x...
    │    └ <function HTTPConnection.send at 0x7f926beb7b80>
    └ <urllib3.connection.HTTPConnection object at 0x7f910408cdc0>
  File "/usr/lib/python3.8/http/client.py", line 951, in send
    self.connect()
    │    └ <function HTTPConnection.connect at 0x7f92585b0dc0>
    └ <urllib3.connection.HTTPConnection object at 0x7f910408cdc0>
  File "/home/chase/.local/lib/python3.8/site-packages/urllib3/connection.py", line 205, in connect
    conn = self._new_conn()
           │    └ <function HTTPConnection._new_conn at 0x7f92585b0c10>
           └ <urllib3.connection.HTTPConnection object at 0x7f910408cdc0>
  File "/home/chase/.local/lib/python3.8/site-packages/urllib3/connection.py", line 186, in _new_conn
    raise NewConnectionError(
          └ <class 'urllib3.exceptions.NewConnectionError'>

urllib3.exceptions.NewConnectionError: <urllib3.connection.HTTPConnection object at 0x7f910408cdc0>: Failed to establish a new connection: [Errno 111] Connection refused


During handling of the above exception, another exception occurred:


Traceback (most recent call last):

  File "/home/chase/.local/lib/python3.8/site-packages/requests/adapters.py", line 439, in send
    resp = conn.urlopen(
           │    └ <function HTTPConnectionPool.urlopen at 0x7f92585c0820>
           └ <urllib3.connectionpool.HTTPConnectionPool object at 0x7f91601f9a60>
  File "/home/chase/.local/lib/python3.8/site-packages/urllib3/connectionpool.py", line 755, in urlopen
    retries = retries.increment(
              │       └ <function Retry.increment at 0x7f9258608b80>
              └ Retry(total=0, connect=None, read=False, redirect=None, status=None)
  File "/home/chase/.local/lib/python3.8/site-packages/urllib3/util/retry.py", line 574, in increment
    raise MaxRetryError(_pool, url, error or ResponseError(cause))
          │             │      │    │        │             └ 'unknown'
          │             │      │    │        └ <class 'urllib3.exceptions.ResponseError'>
          │             │      │    └ NewConnectionError('<urllib3.connection.HTTPConnection object at 0x7f910408cdc0>: Failed to establish a new connection: [Errn...
          │             │      └ '/search-platform/front/search'
          │             └ <urllib3.connectionpool.HTTPConnectionPool object at 0x7f91601f9a60>
          └ <class 'urllib3.exceptions.MaxRetryError'>

urllib3.exceptions.MaxRetryError: HTTPConnectionPool(host='search.people.cn', port=80): Max retries exceeded with url: /search-platform/front/search (Caused by NewConnectionError('<urllib3.connection.HTTPConnection object at 0x7f910408cdc0>: Failed to establish a new connection: [Errno 111] Connection refused'))


During handling of the above exception, another exception occurred:


Traceback (most recent call last):

  File "/usr/lib/python3.8/threading.py", line 890, in _bootstrap
    self._bootstrap_inner()
    │    └ <function Thread._bootstrap_inner at 0x7f927a614a60>
    └ <Thread(Thread-65, started daemon 140261392893696)>
  File "/usr/lib/python3.8/threading.py", line 932, in _bootstrap_inner
    self.run()
    │    └ <function Thread.run at 0x7f927a614790>
    └ <Thread(Thread-65, started daemon 140261392893696)>
  File "/usr/lib/python3.8/threading.py", line 870, in run
    self._target(*self._args, **self._kwargs)
    │    │        │    │        │    └ {}
    │    │        │    │        └ <Thread(Thread-65, started daemon 140261392893696)>
    │    │        │    └ ('ProjectManager.run_func_by_thread',)
    │    │        └ <Thread(Thread-65, started daemon 140261392893696)>
    │    └ <bound method ProjectManager.get_request_from_keywords_hot of <monitor.projectManager.ProjectManager object at 0x7f9162af4700>>
    └ <Thread(Thread-65, started daemon 140261392893696)>

  File "/home/users/Scy/yuqing/spider/monitor/projectManager.py", line 795, in get_request_from_keywords_hot
    self.search_spider_manager.crawl_by_keyword(
    │    │                     └ <function SearchSpidersManager.crawl_by_keyword at 0x7f9162b00040>
    │    └ <monitor.spiderManager.SearchSpidersManager object at 0x7f916270f0d0>
    └ <monitor.projectManager.ProjectManager object at 0x7f9162af4700>

  File "/home/users/Scy/yuqing/spider/monitor/spiderManager.py", line 118, in crawl_by_keyword
    self.crawl_by_keyword_signal_platform(project_names, platform, keyword, crawl_time, project_times)
    │    │                                │              │         │        │           └ {'default': <monitor.TimeSection object at 0x7f91628317f0>}
    │    │                                │              │         │        └ <monitor.TimeSection object at 0x7f91601075e0>
    │    │                                │              │         └ '华南有持续性强降雨 多地气象部门强化应急联动全力防范应对强降雨'
    │    │                                │              └ '人民网'
    │    │                                └ ['default']
    │    └ <function SearchSpidersManager.crawl_by_keyword_signal_platform at 0x7f9162b000d0>
    └ <monitor.spiderManager.SearchSpidersManager object at 0x7f916270f0d0>

  File "/home/users/Scy/yuqing/spider/monitor/spiderManager.py", line 134, in crawl_by_keyword_signal_platform
    requests = self.get_request_from_keyword(platform, keyword, **crawl_time.to_dict())
               │    │                        │         │          │          └ <function TimeSection.to_dict at 0x7f925aaa8550>
               │    │                        │         │          └ <monitor.TimeSection object at 0x7f91601075e0>
               │    │                        │         └ '华南有持续性强降雨 多地气象部门强化应急联动全力防范应对强降雨'
               │    │                        └ '人民网'
               │    └ <function SearchSpidersManager.get_request_from_keyword at 0x7f9162b001f0>
               └ <monitor.spiderManager.SearchSpidersManager object at 0x7f916270f0d0>

  File "/home/users/Scy/yuqing/spider/monitor/spiderManager.py", line 191, in get_request_from_keyword
    for request in self.spiders[platform].get_request_from_keyword(headers, search_url, keyword, content_url,
                   │    │       │                                  │        │           │        └ <string.Template object at 0x7f91241eb9a0>
                   │    │       │                                  │        │           └ '华南有持续性强降雨 多地气象部门强化应急联动全力防范应对强降雨'
                   │    │       │                                  │        └ <string.Template object at 0x7f9160355f10>
                   │    │       │                                  └ {'Accept': 'application/json, text/plain, */*', 'Accept-Language': 'zh-CN,zh;q=0.9', 'Connection': 'keep-alive', 'Origin': 'h...
                   │    │       └ '人民网'
                   │    └ {'凤凰网': <monitor.searchSpiders.ifeng.Ifeng object at 0x7f916270f220>, '头条': <monitor.searchSpiders.toutiao.Toutiao object at ...
                   └ <monitor.spiderManager.SearchSpidersManager object at 0x7f916270f0d0>

> File "/home/users/Scy/yuqing/spider/monitor/searchSpiders/people.py", line 28, in get_request_from_keyword
    response = requests.post(search_url.substitute(), json=data, headers=headers)
               │        │    │          │                  │             └ {'Accept': 'application/json, text/plain, */*', 'Accept-Language': 'zh-CN,zh;q=0.9', 'Connection': 'keep-alive', 'Origin': 'h...
               │        │    │          │                  └ {'key': '华南有持续性强降雨 多地气象部门强化应急联动全力防范应对强降雨', 'page': 1, 'limit': 10, 'hasTitle': True, 'hasContent': True, 'isFuzzy': True, 'ty...
               │        │    │          └ <function Template.substitute at 0x7f927a5fd0d0>
               │        │    └ <string.Template object at 0x7f9160355f10>
               │        └ <function post at 0x7f92583e73a0>
               └ <module 'requests' from '/home/chase/.local/lib/python3.8/site-packages/requests/__init__.py'>

  File "/home/chase/.local/lib/python3.8/site-packages/requests/api.py", line 117, in post
    return request('post', url, data=data, json=json, **kwargs)
           │               │         │          │       └ {'headers': {'Accept': 'application/json, text/plain, */*', 'Accept-Language': 'zh-CN,zh;q=0.9', 'Connection': 'keep-alive', ...
           │               │         │          └ {'key': '华南有持续性强降雨 多地气象部门强化应急联动全力防范应对强降雨', 'page': 1, 'limit': 10, 'hasTitle': True, 'hasContent': True, 'isFuzzy': True, 'ty...
           │               │         └ None
           │               └ 'http://search.people.cn/search-platform/front/search'
           └ <function request at 0x7f9258455040>
  File "/home/chase/.local/lib/python3.8/site-packages/requests/api.py", line 61, in request
    return session.request(method=method, url=url, **kwargs)
           │       │              │           │      └ {'data': None, 'json': {'key': '华南有持续性强降雨 多地气象部门强化应急联动全力防范应对强降雨', 'page': 1, 'limit': 10, 'hasTitle': True, 'hasContent': Tru...
           │       │              │           └ 'http://search.people.cn/search-platform/front/search'
           │       │              └ 'post'
           │       └ <function Session.request at 0x7f92583e6940>
           └ <requests.sessions.Session object at 0x7f912436a220>
  File "/home/chase/.local/lib/python3.8/site-packages/requests/sessions.py", line 542, in request
    resp = self.send(prep, **send_kwargs)
           │    │    │       └ {'timeout': None, 'allow_redirects': True, 'verify': True, 'proxies': OrderedDict(), 'stream': False, 'cert': None}
           │    │    └ <PreparedRequest [POST]>
           │    └ <function Session.send at 0x7f92583e6dc0>
           └ <requests.sessions.Session object at 0x7f912436a220>
  File "/home/chase/.local/lib/python3.8/site-packages/requests/sessions.py", line 655, in send
    r = adapter.send(request, **kwargs)
        │       │    │          └ {'timeout': None, 'verify': True, 'proxies': OrderedDict(), 'stream': False, 'cert': None}
        │       │    └ <PreparedRequest [POST]>
        │       └ <function HTTPAdapter.send at 0x7f92583e6280>
        └ <requests.adapters.HTTPAdapter object at 0x7f9104156df0>
  File "/home/chase/.local/lib/python3.8/site-packages/requests/adapters.py", line 516, in send
    raise ConnectionError(e, request=request)
          │                          └ <PreparedRequest [POST]>
          └ <class 'requests.exceptions.ConnectionError'>

requests.exceptions.ConnectionError: HTTPConnectionPool(host='search.people.cn', port=80): Max retries exceeded with url: /search-platform/front/search (Caused by NewConnectionError('<urllib3.connection.HTTPConnection object at 0x7f910408cdc0>: Failed to establish a new connection: [Errno 111] Connection refused'))
2022-05-12 15:51:35.652 | ERROR    | monitor.searchSpiders.qinagguoLT:get_request_from_keyword:27 - E 强国论坛错误HTTPConnectionPool(host='bbs1.people.com.cn', port=80): Max retries exceeded with url: /board/1.html (Caused by NewConnectionError('<urllib3.connection.HTTPConnection object at 0x7f9253e2b1f0>: Failed to establish a new connection: [Errno 111] Connection refused'))
Traceback (most recent call last):

  File "/home/chase/.local/lib/python3.8/site-packages/urllib3/connection.py", line 174, in _new_conn
    conn = connection.create_connection(
           │          └ <function create_connection at 0x7f92585fd1f0>
           └ <module 'urllib3.util.connection' from '/home/chase/.local/lib/python3.8/site-packages/urllib3/util/connection.py'>
  File "/home/chase/.local/lib/python3.8/site-packages/urllib3/util/connection.py", line 96, in create_connection
    raise err
          └ ConnectionRefusedError(111, 'Connection refused')
  File "/home/chase/.local/lib/python3.8/site-packages/urllib3/util/connection.py", line 86, in create_connection
    sock.connect(sa)
    │            └ ('118.212.233.223', 80)
    └ None

ConnectionRefusedError: [Errno 111] Connection refused


During handling of the above exception, another exception occurred:


Traceback (most recent call last):

  File "/home/chase/.local/lib/python3.8/site-packages/urllib3/connectionpool.py", line 699, in urlopen
    httplib_response = self._make_request(
                       │    └ <function HTTPConnectionPool._make_request at 0x7f92585c05e0>
                       └ <urllib3.connectionpool.HTTPConnectionPool object at 0x7f90e4737700>
  File "/home/chase/.local/lib/python3.8/site-packages/urllib3/connectionpool.py", line 394, in _make_request
    conn.request(method, url, **httplib_request_kw)
    │    │       │       │      └ {'body': None, 'headers': {'User-Agent': 'Mozilla/5.0 (X11; Linux x86_64) AppleWebKit/537.36 (KHTML, like Gecko) Chrome/93.0....
    │    │       │       └ '/board/1.html'
    │    │       └ 'GET'
    │    └ <function HTTPConnection.request at 0x7f92585b0f70>
    └ <urllib3.connection.HTTPConnection object at 0x7f9253e2b1f0>
  File "/home/chase/.local/lib/python3.8/site-packages/urllib3/connection.py", line 239, in request
    super(HTTPConnection, self).request(method, url, body=body, headers=headers)
          │               │             │       │         │             └ {'User-Agent': 'Mozilla/5.0 (X11; Linux x86_64) AppleWebKit/537.36 (KHTML, like Gecko) Chrome/93.0.4577.63 Safari/537.36', 'A...
          │               │             │       │         └ None
          │               │             │       └ '/board/1.html'
          │               │             └ 'GET'
          │               └ <urllib3.connection.HTTPConnection object at 0x7f9253e2b1f0>
          └ <class 'urllib3.connection.HTTPConnection'>
  File "/usr/lib/python3.8/http/client.py", line 1256, in request
    self._send_request(method, url, body, headers, encode_chunked)
    │    │             │       │    │     │        └ False
    │    │             │       │    │     └ {'User-Agent': 'Mozilla/5.0 (X11; Linux x86_64) AppleWebKit/537.36 (KHTML, like Gecko) Chrome/93.0.4577.63 Safari/537.36', 'A...
    │    │             │       │    └ None
    │    │             │       └ '/board/1.html'
    │    │             └ 'GET'
    │    └ <function HTTPConnection._send_request at 0x7f926be50280>
    └ <urllib3.connection.HTTPConnection object at 0x7f9253e2b1f0>
  File "/usr/lib/python3.8/http/client.py", line 1302, in _send_request
    self.endheaders(body, encode_chunked=encode_chunked)
    │    │          │                    └ False
    │    │          └ None
    │    └ <function HTTPConnection.endheaders at 0x7f926be50160>
    └ <urllib3.connection.HTTPConnection object at 0x7f9253e2b1f0>
  File "/usr/lib/python3.8/http/client.py", line 1251, in endheaders
    self._send_output(message_body, encode_chunked=encode_chunked)
    │    │            │                            └ False
    │    │            └ None
    │    └ <function HTTPConnection._send_output at 0x7f926beb7d30>
    └ <urllib3.connection.HTTPConnection object at 0x7f9253e2b1f0>
  File "/usr/lib/python3.8/http/client.py", line 1011, in _send_output
    self.send(msg)
    │    │    └ b'GET /board/1.html HTTP/1.1\r\nHost: bbs1.people.com.cn\r\nUser-Agent: Mozilla/5.0 (X11; Linux x86_64) AppleWebKit/537.36 (K...
    │    └ <function HTTPConnection.send at 0x7f926beb7b80>
    └ <urllib3.connection.HTTPConnection object at 0x7f9253e2b1f0>
  File "/usr/lib/python3.8/http/client.py", line 951, in send
    self.connect()
    │    └ <function HTTPConnection.connect at 0x7f92585b0dc0>
    └ <urllib3.connection.HTTPConnection object at 0x7f9253e2b1f0>
  File "/home/chase/.local/lib/python3.8/site-packages/urllib3/connection.py", line 205, in connect
    conn = self._new_conn()
           │    └ <function HTTPConnection._new_conn at 0x7f92585b0c10>
           └ <urllib3.connection.HTTPConnection object at 0x7f9253e2b1f0>
  File "/home/chase/.local/lib/python3.8/site-packages/urllib3/connection.py", line 186, in _new_conn
    raise NewConnectionError(
          └ <class 'urllib3.exceptions.NewConnectionError'>

urllib3.exceptions.NewConnectionError: <urllib3.connection.HTTPConnection object at 0x7f9253e2b1f0>: Failed to establish a new connection: [Errno 111] Connection refused


During handling of the above exception, another exception occurred:


Traceback (most recent call last):

  File "/home/chase/.local/lib/python3.8/site-packages/requests/adapters.py", line 439, in send
    resp = conn.urlopen(
           │    └ <function HTTPConnectionPool.urlopen at 0x7f92585c0820>
           └ <urllib3.connectionpool.HTTPConnectionPool object at 0x7f90e4737700>
  File "/home/chase/.local/lib/python3.8/site-packages/urllib3/connectionpool.py", line 755, in urlopen
    retries = retries.increment(
              │       └ <function Retry.increment at 0x7f9258608b80>
              └ Retry(total=0, connect=None, read=False, redirect=None, status=None)
  File "/home/chase/.local/lib/python3.8/site-packages/urllib3/util/retry.py", line 574, in increment
    raise MaxRetryError(_pool, url, error or ResponseError(cause))
          │             │      │    │        │             └ 'unknown'
          │             │      │    │        └ <class 'urllib3.exceptions.ResponseError'>
          │             │      │    └ NewConnectionError('<urllib3.connection.HTTPConnection object at 0x7f9253e2b1f0>: Failed to establish a new connection: [Errn...
          │             │      └ '/board/1.html'
          │             └ <urllib3.connectionpool.HTTPConnectionPool object at 0x7f90e4737700>
          └ <class 'urllib3.exceptions.MaxRetryError'>

urllib3.exceptions.MaxRetryError: HTTPConnectionPool(host='bbs1.people.com.cn', port=80): Max retries exceeded with url: /board/1.html (Caused by NewConnectionError('<urllib3.connection.HTTPConnection object at 0x7f9253e2b1f0>: Failed to establish a new connection: [Errno 111] Connection refused'))


During handling of the above exception, another exception occurred:


Traceback (most recent call last):

  File "/usr/lib/python3.8/threading.py", line 890, in _bootstrap
    self._bootstrap_inner()
    │    └ <function Thread._bootstrap_inner at 0x7f927a614a60>
    └ <Thread(Thread-97, started daemon 140260847630080)>
  File "/usr/lib/python3.8/threading.py", line 932, in _bootstrap_inner
    self.run()
    │    └ <function Thread.run at 0x7f927a614790>
    └ <Thread(Thread-97, started daemon 140260847630080)>
  File "/usr/lib/python3.8/threading.py", line 870, in run
    self._target(*self._args, **self._kwargs)
    │    │        │    │        │    └ {}
    │    │        │    │        └ <Thread(Thread-97, started daemon 140260847630080)>
    │    │        │    └ ('ProjectManager.run_func_by_thread',)
    │    │        └ <Thread(Thread-97, started daemon 140260847630080)>
    │    └ <bound method ProjectManager.get_request_from_keywords_hot of <monitor.projectManager.ProjectManager object at 0x7f9162af4700>>
    └ <Thread(Thread-97, started daemon 140260847630080)>

  File "/home/users/Scy/yuqing/spider/monitor/projectManager.py", line 795, in get_request_from_keywords_hot
    self.search_spider_manager.crawl_by_keyword(
    │    │                     └ <function SearchSpidersManager.crawl_by_keyword at 0x7f9162b00040>
    │    └ <monitor.spiderManager.SearchSpidersManager object at 0x7f916270f0d0>
    └ <monitor.projectManager.ProjectManager object at 0x7f9162af4700>

  File "/home/users/Scy/yuqing/spider/monitor/spiderManager.py", line 118, in crawl_by_keyword
    self.crawl_by_keyword_signal_platform(project_names, platform, keyword, crawl_time, project_times)
    │    │                                │              │         │        │           └ {'default': <monitor.TimeSection object at 0x7f91628317f0>}
    │    │                                │              │         │        └ <monitor.TimeSection object at 0x7f91486c84f0>
    │    │                                │              │         └ '非洲极端组织武器来源引关注'
    │    │                                │              └ '强国论坛'
    │    │                                └ ['default']
    │    └ <function SearchSpidersManager.crawl_by_keyword_signal_platform at 0x7f9162b000d0>
    └ <monitor.spiderManager.SearchSpidersManager object at 0x7f916270f0d0>

  File "/home/users/Scy/yuqing/spider/monitor/spiderManager.py", line 134, in crawl_by_keyword_signal_platform
    requests = self.get_request_from_keyword(platform, keyword, **crawl_time.to_dict())
               │    │                        │         │          │          └ <function TimeSection.to_dict at 0x7f925aaa8550>
               │    │                        │         │          └ <monitor.TimeSection object at 0x7f91486c84f0>
               │    │                        │         └ '非洲极端组织武器来源引关注'
               │    │                        └ '强国论坛'
               │    └ <function SearchSpidersManager.get_request_from_keyword at 0x7f9162b001f0>
               └ <monitor.spiderManager.SearchSpidersManager object at 0x7f916270f0d0>

  File "/home/users/Scy/yuqing/spider/monitor/spiderManager.py", line 191, in get_request_from_keyword
    for request in self.spiders[platform].get_request_from_keyword(headers, search_url, keyword, content_url,
                   │    │       │                                  │        │           │        └ <string.Template object at 0x7f91600c05b0>
                   │    │       │                                  │        │           └ '非洲极端组织武器来源引关注'
                   │    │       │                                  │        └ <string.Template object at 0x7f91600c0d00>
                   │    │       │                                  └ {'Connection': 'keep-alive', 'Cache-Control': 'max-age=0', 'Upgrade-Insecure-Requests': '1', 'User-Agent': 'Mozilla/5.0 (X11;...
                   │    │       └ '强国论坛'
                   │    └ {'凤凰网': <monitor.searchSpiders.ifeng.Ifeng object at 0x7f916270f220>, '头条': <monitor.searchSpiders.toutiao.Toutiao object at ...
                   └ <monitor.spiderManager.SearchSpidersManager object at 0x7f916270f0d0>

> File "/home/users/Scy/yuqing/spider/monitor/searchSpiders/qinagguoLT.py", line 18, in get_request_from_keyword
    response = requests.get(search_url.substitute(), headers=headers)
               │        │   │          │                     └ {'Connection': 'keep-alive', 'Cache-Control': 'max-age=0', 'Upgrade-Insecure-Requests': '1', 'User-Agent': 'Mozilla/5.0 (X11;...
               │        │   │          └ <function Template.substitute at 0x7f927a5fd0d0>
               │        │   └ <string.Template object at 0x7f91600c0d00>
               │        └ <function get at 0x7f92583e71f0>
               └ <module 'requests' from '/home/chase/.local/lib/python3.8/site-packages/requests/__init__.py'>

  File "/home/chase/.local/lib/python3.8/site-packages/requests/api.py", line 75, in get
    return request('get', url, params=params, **kwargs)
           │              │           │         └ {'headers': {'Connection': 'keep-alive', 'Cache-Control': 'max-age=0', 'Upgrade-Insecure-Requests': '1', 'User-Agent': 'Mozil...
           │              │           └ None
           │              └ 'http://bbs1.people.com.cn/board/1.html'
           └ <function request at 0x7f9258455040>
  File "/home/chase/.local/lib/python3.8/site-packages/requests/api.py", line 61, in request
    return session.request(method=method, url=url, **kwargs)
           │       │              │           │      └ {'params': None, 'headers': {'Connection': 'keep-alive', 'Cache-Control': 'max-age=0', 'Upgrade-Insecure-Requests': '1', 'Use...
           │       │              │           └ 'http://bbs1.people.com.cn/board/1.html'
           │       │              └ 'get'
           │       └ <function Session.request at 0x7f92583e6940>
           └ <requests.sessions.Session object at 0x7f912433be80>
  File "/home/chase/.local/lib/python3.8/site-packages/requests/sessions.py", line 542, in request
    resp = self.send(prep, **send_kwargs)
           │    │    │       └ {'timeout': None, 'allow_redirects': True, 'verify': True, 'proxies': OrderedDict(), 'stream': False, 'cert': None}
           │    │    └ <PreparedRequest [GET]>
           │    └ <function Session.send at 0x7f92583e6dc0>
           └ <requests.sessions.Session object at 0x7f912433be80>
  File "/home/chase/.local/lib/python3.8/site-packages/requests/sessions.py", line 655, in send
    r = adapter.send(request, **kwargs)
        │       │    │          └ {'timeout': None, 'verify': True, 'proxies': OrderedDict(), 'stream': False, 'cert': None}
        │       │    └ <PreparedRequest [GET]>
        │       └ <function HTTPAdapter.send at 0x7f92583e6280>
        └ <requests.adapters.HTTPAdapter object at 0x7f91481e2dc0>
  File "/home/chase/.local/lib/python3.8/site-packages/requests/adapters.py", line 516, in send
    raise ConnectionError(e, request=request)
          │                          └ <PreparedRequest [GET]>
          └ <class 'requests.exceptions.ConnectionError'>

requests.exceptions.ConnectionError: HTTPConnectionPool(host='bbs1.people.com.cn', port=80): Max retries exceeded with url: /board/1.html (Caused by NewConnectionError('<urllib3.connection.HTTPConnection object at 0x7f9253e2b1f0>: Failed to establish a new connection: [Errno 111] Connection refused'))
2022-05-12 15:51:35.987 | ERROR    | monitor.searchSpiders.people:get_request_from_keyword:45 - E 人民网错误HTTPConnectionPool(host='search.people.cn', port=80): Max retries exceeded with url: /search-platform/front/search (Caused by NewConnectionError('<urllib3.connection.HTTPConnection object at 0x7f91603cf2e0>: Failed to establish a new connection: [Errno 111] Connection refused'))
Traceback (most recent call last):

  File "/home/chase/.local/lib/python3.8/site-packages/urllib3/connection.py", line 174, in _new_conn
    conn = connection.create_connection(
           │          └ <function create_connection at 0x7f92585fd1f0>
           └ <module 'urllib3.util.connection' from '/home/chase/.local/lib/python3.8/site-packages/urllib3/util/connection.py'>
  File "/home/chase/.local/lib/python3.8/site-packages/urllib3/util/connection.py", line 96, in create_connection
    raise err
          └ ConnectionRefusedError(111, 'Connection refused')
  File "/home/chase/.local/lib/python3.8/site-packages/urllib3/util/connection.py", line 86, in create_connection
    sock.connect(sa)
    │            └ ('1.31.128.250', 80)
    └ None

ConnectionRefusedError: [Errno 111] Connection refused


During handling of the above exception, another exception occurred:


Traceback (most recent call last):

  File "/home/chase/.local/lib/python3.8/site-packages/urllib3/connectionpool.py", line 699, in urlopen
    httplib_response = self._make_request(
                       │    └ <function HTTPConnectionPool._make_request at 0x7f92585c05e0>
                       └ <urllib3.connectionpool.HTTPConnectionPool object at 0x7f9253d91940>
  File "/home/chase/.local/lib/python3.8/site-packages/urllib3/connectionpool.py", line 394, in _make_request
    conn.request(method, url, **httplib_request_kw)
    │    │       │       │      └ {'body': b'{"key": "\\u975e\\u6d32\\u6781\\u7aef\\u7ec4\\u7ec7\\u6b66\\u5668\\u6765\\u6e90\\u5f15\\u5173\\u6ce8", "page": 1, ...
    │    │       │       └ '/search-platform/front/search'
    │    │       └ 'POST'
    │    └ <function HTTPConnection.request at 0x7f92585b0f70>
    └ <urllib3.connection.HTTPConnection object at 0x7f91603cf2e0>
  File "/home/chase/.local/lib/python3.8/site-packages/urllib3/connection.py", line 239, in request
    super(HTTPConnection, self).request(method, url, body=body, headers=headers)
          │               │             │       │         │             └ {'User-Agent': 'Mozilla/5.0 (Windows NT 10.0; Win64; x64) AppleWebKit/537.36 (KHTML, like Gecko) Chrome/101.0.4951.54 Safari/...
          │               │             │       │         └ b'{"key": "\\u975e\\u6d32\\u6781\\u7aef\\u7ec4\\u7ec7\\u6b66\\u5668\\u6765\\u6e90\\u5f15\\u5173\\u6ce8", "page": 1, "limit": ...
          │               │             │       └ '/search-platform/front/search'
          │               │             └ 'POST'
          │               └ <urllib3.connection.HTTPConnection object at 0x7f91603cf2e0>
          └ <class 'urllib3.connection.HTTPConnection'>
  File "/usr/lib/python3.8/http/client.py", line 1256, in request
    self._send_request(method, url, body, headers, encode_chunked)
    │    │             │       │    │     │        └ False
    │    │             │       │    │     └ {'User-Agent': 'Mozilla/5.0 (Windows NT 10.0; Win64; x64) AppleWebKit/537.36 (KHTML, like Gecko) Chrome/101.0.4951.54 Safari/...
    │    │             │       │    └ b'{"key": "\\u975e\\u6d32\\u6781\\u7aef\\u7ec4\\u7ec7\\u6b66\\u5668\\u6765\\u6e90\\u5f15\\u5173\\u6ce8", "page": 1, "limit": ...
    │    │             │       └ '/search-platform/front/search'
    │    │             └ 'POST'
    │    └ <function HTTPConnection._send_request at 0x7f926be50280>
    └ <urllib3.connection.HTTPConnection object at 0x7f91603cf2e0>
  File "/usr/lib/python3.8/http/client.py", line 1302, in _send_request
    self.endheaders(body, encode_chunked=encode_chunked)
    │    │          │                    └ False
    │    │          └ b'{"key": "\\u975e\\u6d32\\u6781\\u7aef\\u7ec4\\u7ec7\\u6b66\\u5668\\u6765\\u6e90\\u5f15\\u5173\\u6ce8", "page": 1, "limit": ...
    │    └ <function HTTPConnection.endheaders at 0x7f926be50160>
    └ <urllib3.connection.HTTPConnection object at 0x7f91603cf2e0>
  File "/usr/lib/python3.8/http/client.py", line 1251, in endheaders
    self._send_output(message_body, encode_chunked=encode_chunked)
    │    │            │                            └ False
    │    │            └ b'{"key": "\\u975e\\u6d32\\u6781\\u7aef\\u7ec4\\u7ec7\\u6b66\\u5668\\u6765\\u6e90\\u5f15\\u5173\\u6ce8", "page": 1, "limit": ...
    │    └ <function HTTPConnection._send_output at 0x7f926beb7d30>
    └ <urllib3.connection.HTTPConnection object at 0x7f91603cf2e0>
  File "/usr/lib/python3.8/http/client.py", line 1011, in _send_output
    self.send(msg)
    │    │    └ b'POST /search-platform/front/search HTTP/1.1\r\nHost: search.people.cn\r\nUser-Agent: Mozilla/5.0 (Windows NT 10.0; Win64; x...
    │    └ <function HTTPConnection.send at 0x7f926beb7b80>
    └ <urllib3.connection.HTTPConnection object at 0x7f91603cf2e0>
  File "/usr/lib/python3.8/http/client.py", line 951, in send
    self.connect()
    │    └ <function HTTPConnection.connect at 0x7f92585b0dc0>
    └ <urllib3.connection.HTTPConnection object at 0x7f91603cf2e0>
  File "/home/chase/.local/lib/python3.8/site-packages/urllib3/connection.py", line 205, in connect
    conn = self._new_conn()
           │    └ <function HTTPConnection._new_conn at 0x7f92585b0c10>
           └ <urllib3.connection.HTTPConnection object at 0x7f91603cf2e0>
  File "/home/chase/.local/lib/python3.8/site-packages/urllib3/connection.py", line 186, in _new_conn
    raise NewConnectionError(
          └ <class 'urllib3.exceptions.NewConnectionError'>

urllib3.exceptions.NewConnectionError: <urllib3.connection.HTTPConnection object at 0x7f91603cf2e0>: Failed to establish a new connection: [Errno 111] Connection refused


During handling of the above exception, another exception occurred:


Traceback (most recent call last):

  File "/home/chase/.local/lib/python3.8/site-packages/requests/adapters.py", line 439, in send
    resp = conn.urlopen(
           │    └ <function HTTPConnectionPool.urlopen at 0x7f92585c0820>
           └ <urllib3.connectionpool.HTTPConnectionPool object at 0x7f9253d91940>
  File "/home/chase/.local/lib/python3.8/site-packages/urllib3/connectionpool.py", line 755, in urlopen
    retries = retries.increment(
              │       └ <function Retry.increment at 0x7f9258608b80>
              └ Retry(total=0, connect=None, read=False, redirect=None, status=None)
  File "/home/chase/.local/lib/python3.8/site-packages/urllib3/util/retry.py", line 574, in increment
    raise MaxRetryError(_pool, url, error or ResponseError(cause))
          │             │      │    │        │             └ 'unknown'
          │             │      │    │        └ <class 'urllib3.exceptions.ResponseError'>
          │             │      │    └ NewConnectionError('<urllib3.connection.HTTPConnection object at 0x7f91603cf2e0>: Failed to establish a new connection: [Errn...
          │             │      └ '/search-platform/front/search'
          │             └ <urllib3.connectionpool.HTTPConnectionPool object at 0x7f9253d91940>
          └ <class 'urllib3.exceptions.MaxRetryError'>

urllib3.exceptions.MaxRetryError: HTTPConnectionPool(host='search.people.cn', port=80): Max retries exceeded with url: /search-platform/front/search (Caused by NewConnectionError('<urllib3.connection.HTTPConnection object at 0x7f91603cf2e0>: Failed to establish a new connection: [Errno 111] Connection refused'))


During handling of the above exception, another exception occurred:


Traceback (most recent call last):

  File "/usr/lib/python3.8/threading.py", line 890, in _bootstrap
    self._bootstrap_inner()
    │    └ <function Thread._bootstrap_inner at 0x7f927a614a60>
    └ <Thread(Thread-26, started daemon 140262005266176)>
  File "/usr/lib/python3.8/threading.py", line 932, in _bootstrap_inner
    self.run()
    │    └ <function Thread.run at 0x7f927a614790>
    └ <Thread(Thread-26, started daemon 140262005266176)>
  File "/usr/lib/python3.8/threading.py", line 870, in run
    self._target(*self._args, **self._kwargs)
    │    │        │    │        │    └ {}
    │    │        │    │        └ <Thread(Thread-26, started daemon 140262005266176)>
    │    │        │    └ ('ProjectManager.run_func_by_thread',)
    │    │        └ <Thread(Thread-26, started daemon 140262005266176)>
    │    └ <bound method ProjectManager.get_request_from_keywords_hot of <monitor.projectManager.ProjectManager object at 0x7f9162af4700>>
    └ <Thread(Thread-26, started daemon 140262005266176)>

  File "/home/users/Scy/yuqing/spider/monitor/projectManager.py", line 795, in get_request_from_keywords_hot
    self.search_spider_manager.crawl_by_keyword(
    │    │                     └ <function SearchSpidersManager.crawl_by_keyword at 0x7f9162b00040>
    │    └ <monitor.spiderManager.SearchSpidersManager object at 0x7f916270f0d0>
    └ <monitor.projectManager.ProjectManager object at 0x7f9162af4700>

  File "/home/users/Scy/yuqing/spider/monitor/spiderManager.py", line 118, in crawl_by_keyword
    self.crawl_by_keyword_signal_platform(project_names, platform, keyword, crawl_time, project_times)
    │    │                                │              │         │        │           └ {'default': <monitor.TimeSection object at 0x7f91628317f0>}
    │    │                                │              │         │        └ <monitor.TimeSection object at 0x7f916047e6a0>
    │    │                                │              │         └ '非洲极端组织武器来源引关注'
    │    │                                │              └ '人民网'
    │    │                                └ ['default']
    │    └ <function SearchSpidersManager.crawl_by_keyword_signal_platform at 0x7f9162b000d0>
    └ <monitor.spiderManager.SearchSpidersManager object at 0x7f916270f0d0>

  File "/home/users/Scy/yuqing/spider/monitor/spiderManager.py", line 134, in crawl_by_keyword_signal_platform
    requests = self.get_request_from_keyword(platform, keyword, **crawl_time.to_dict())
               │    │                        │         │          │          └ <function TimeSection.to_dict at 0x7f925aaa8550>
               │    │                        │         │          └ <monitor.TimeSection object at 0x7f916047e6a0>
               │    │                        │         └ '非洲极端组织武器来源引关注'
               │    │                        └ '人民网'
               │    └ <function SearchSpidersManager.get_request_from_keyword at 0x7f9162b001f0>
               └ <monitor.spiderManager.SearchSpidersManager object at 0x7f916270f0d0>

  File "/home/users/Scy/yuqing/spider/monitor/spiderManager.py", line 191, in get_request_from_keyword
    for request in self.spiders[platform].get_request_from_keyword(headers, search_url, keyword, content_url,
                   │    │       │                                  │        │           │        └ <string.Template object at 0x7f9104203400>
                   │    │       │                                  │        │           └ '非洲极端组织武器来源引关注'
                   │    │       │                                  │        └ <string.Template object at 0x7f9124525760>
                   │    │       │                                  └ {'Accept': 'application/json, text/plain, */*', 'Accept-Language': 'zh-CN,zh;q=0.9', 'Connection': 'keep-alive', 'Origin': 'h...
                   │    │       └ '人民网'
                   │    └ {'凤凰网': <monitor.searchSpiders.ifeng.Ifeng object at 0x7f916270f220>, '头条': <monitor.searchSpiders.toutiao.Toutiao object at ...
                   └ <monitor.spiderManager.SearchSpidersManager object at 0x7f916270f0d0>

> File "/home/users/Scy/yuqing/spider/monitor/searchSpiders/people.py", line 28, in get_request_from_keyword
    response = requests.post(search_url.substitute(), json=data, headers=headers)
               │        │    │          │                  │             └ {'Accept': 'application/json, text/plain, */*', 'Accept-Language': 'zh-CN,zh;q=0.9', 'Connection': 'keep-alive', 'Origin': 'h...
               │        │    │          │                  └ {'key': '非洲极端组织武器来源引关注', 'page': 1, 'limit': 10, 'hasTitle': True, 'hasContent': True, 'isFuzzy': True, 'type': 0, 'sortType'...
               │        │    │          └ <function Template.substitute at 0x7f927a5fd0d0>
               │        │    └ <string.Template object at 0x7f9124525760>
               │        └ <function post at 0x7f92583e73a0>
               └ <module 'requests' from '/home/chase/.local/lib/python3.8/site-packages/requests/__init__.py'>

  File "/home/chase/.local/lib/python3.8/site-packages/requests/api.py", line 117, in post
    return request('post', url, data=data, json=json, **kwargs)
           │               │         │          │       └ {'headers': {'Accept': 'application/json, text/plain, */*', 'Accept-Language': 'zh-CN,zh;q=0.9', 'Connection': 'keep-alive', ...
           │               │         │          └ {'key': '非洲极端组织武器来源引关注', 'page': 1, 'limit': 10, 'hasTitle': True, 'hasContent': True, 'isFuzzy': True, 'type': 0, 'sortType'...
           │               │         └ None
           │               └ 'http://search.people.cn/search-platform/front/search'
           └ <function request at 0x7f9258455040>
  File "/home/chase/.local/lib/python3.8/site-packages/requests/api.py", line 61, in request
    return session.request(method=method, url=url, **kwargs)
           │       │              │           │      └ {'data': None, 'json': {'key': '非洲极端组织武器来源引关注', 'page': 1, 'limit': 10, 'hasTitle': True, 'hasContent': True, 'isFuzzy': True...
           │       │              │           └ 'http://search.people.cn/search-platform/front/search'
           │       │              └ 'post'
           │       └ <function Session.request at 0x7f92583e6940>
           └ <requests.sessions.Session object at 0x7f91480fc6a0>
  File "/home/chase/.local/lib/python3.8/site-packages/requests/sessions.py", line 542, in request
    resp = self.send(prep, **send_kwargs)
           │    │    │       └ {'timeout': None, 'allow_redirects': True, 'verify': True, 'proxies': OrderedDict(), 'stream': False, 'cert': None}
           │    │    └ <PreparedRequest [POST]>
           │    └ <function Session.send at 0x7f92583e6dc0>
           └ <requests.sessions.Session object at 0x7f91480fc6a0>
  File "/home/chase/.local/lib/python3.8/site-packages/requests/sessions.py", line 655, in send
    r = adapter.send(request, **kwargs)
        │       │    │          └ {'timeout': None, 'verify': True, 'proxies': OrderedDict(), 'stream': False, 'cert': None}
        │       │    └ <PreparedRequest [POST]>
        │       └ <function HTTPAdapter.send at 0x7f92583e6280>
        └ <requests.adapters.HTTPAdapter object at 0x7f90e44d61f0>
  File "/home/chase/.local/lib/python3.8/site-packages/requests/adapters.py", line 516, in send
    raise ConnectionError(e, request=request)
          │                          └ <PreparedRequest [POST]>
          └ <class 'requests.exceptions.ConnectionError'>

requests.exceptions.ConnectionError: HTTPConnectionPool(host='search.people.cn', port=80): Max retries exceeded with url: /search-platform/front/search (Caused by NewConnectionError('<urllib3.connection.HTTPConnection object at 0x7f91603cf2e0>: Failed to establish a new connection: [Errno 111] Connection refused'))
2022-05-12 15:51:36.087 | ERROR    | monitor.searchSpiders.qinagguoLT:get_request_from_keyword:27 - E 强国论坛错误HTTPConnectionPool(host='bbs1.people.com.cn', port=80): Max retries exceeded with url: /board/1.html (Caused by NewConnectionError('<urllib3.connection.HTTPConnection object at 0x7f91485e7160>: Failed to establish a new connection: [Errno 111] Connection refused'))
Traceback (most recent call last):

  File "/home/chase/.local/lib/python3.8/site-packages/urllib3/connection.py", line 174, in _new_conn
    conn = connection.create_connection(
           │          └ <function create_connection at 0x7f92585fd1f0>
           └ <module 'urllib3.util.connection' from '/home/chase/.local/lib/python3.8/site-packages/urllib3/util/connection.py'>
  File "/home/chase/.local/lib/python3.8/site-packages/urllib3/util/connection.py", line 96, in create_connection
    raise err
          └ ConnectionRefusedError(111, 'Connection refused')
  File "/home/chase/.local/lib/python3.8/site-packages/urllib3/util/connection.py", line 86, in create_connection
    sock.connect(sa)
    │            └ ('118.212.233.223', 80)
    └ None

ConnectionRefusedError: [Errno 111] Connection refused


During handling of the above exception, another exception occurred:


Traceback (most recent call last):

  File "/home/chase/.local/lib/python3.8/site-packages/urllib3/connectionpool.py", line 699, in urlopen
    httplib_response = self._make_request(
                       │    └ <function HTTPConnectionPool._make_request at 0x7f92585c05e0>
                       └ <urllib3.connectionpool.HTTPConnectionPool object at 0x7f91603cf4f0>
  File "/home/chase/.local/lib/python3.8/site-packages/urllib3/connectionpool.py", line 394, in _make_request
    conn.request(method, url, **httplib_request_kw)
    │    │       │       │      └ {'body': None, 'headers': {'User-Agent': 'Mozilla/5.0 (X11; Linux x86_64) AppleWebKit/537.36 (KHTML, like Gecko) Chrome/93.0....
    │    │       │       └ '/board/1.html'
    │    │       └ 'GET'
    │    └ <function HTTPConnection.request at 0x7f92585b0f70>
    └ <urllib3.connection.HTTPConnection object at 0x7f91485e7160>
  File "/home/chase/.local/lib/python3.8/site-packages/urllib3/connection.py", line 239, in request
    super(HTTPConnection, self).request(method, url, body=body, headers=headers)
          │               │             │       │         │             └ {'User-Agent': 'Mozilla/5.0 (X11; Linux x86_64) AppleWebKit/537.36 (KHTML, like Gecko) Chrome/93.0.4577.63 Safari/537.36', 'A...
          │               │             │       │         └ None
          │               │             │       └ '/board/1.html'
          │               │             └ 'GET'
          │               └ <urllib3.connection.HTTPConnection object at 0x7f91485e7160>
          └ <class 'urllib3.connection.HTTPConnection'>
  File "/usr/lib/python3.8/http/client.py", line 1256, in request
    self._send_request(method, url, body, headers, encode_chunked)
    │    │             │       │    │     │        └ False
    │    │             │       │    │     └ {'User-Agent': 'Mozilla/5.0 (X11; Linux x86_64) AppleWebKit/537.36 (KHTML, like Gecko) Chrome/93.0.4577.63 Safari/537.36', 'A...
    │    │             │       │    └ None
    │    │             │       └ '/board/1.html'
    │    │             └ 'GET'
    │    └ <function HTTPConnection._send_request at 0x7f926be50280>
    └ <urllib3.connection.HTTPConnection object at 0x7f91485e7160>
  File "/usr/lib/python3.8/http/client.py", line 1302, in _send_request
    self.endheaders(body, encode_chunked=encode_chunked)
    │    │          │                    └ False
    │    │          └ None
    │    └ <function HTTPConnection.endheaders at 0x7f926be50160>
    └ <urllib3.connection.HTTPConnection object at 0x7f91485e7160>
  File "/usr/lib/python3.8/http/client.py", line 1251, in endheaders
    self._send_output(message_body, encode_chunked=encode_chunked)
    │    │            │                            └ False
    │    │            └ None
    │    └ <function HTTPConnection._send_output at 0x7f926beb7d30>
    └ <urllib3.connection.HTTPConnection object at 0x7f91485e7160>
  File "/usr/lib/python3.8/http/client.py", line 1011, in _send_output
    self.send(msg)
    │    │    └ b'GET /board/1.html HTTP/1.1\r\nHost: bbs1.people.com.cn\r\nUser-Agent: Mozilla/5.0 (X11; Linux x86_64) AppleWebKit/537.36 (K...
    │    └ <function HTTPConnection.send at 0x7f926beb7b80>
    └ <urllib3.connection.HTTPConnection object at 0x7f91485e7160>
  File "/usr/lib/python3.8/http/client.py", line 951, in send
    self.connect()
    │    └ <function HTTPConnection.connect at 0x7f92585b0dc0>
    └ <urllib3.connection.HTTPConnection object at 0x7f91485e7160>
  File "/home/chase/.local/lib/python3.8/site-packages/urllib3/connection.py", line 205, in connect
    conn = self._new_conn()
           │    └ <function HTTPConnection._new_conn at 0x7f92585b0c10>
           └ <urllib3.connection.HTTPConnection object at 0x7f91485e7160>
  File "/home/chase/.local/lib/python3.8/site-packages/urllib3/connection.py", line 186, in _new_conn
    raise NewConnectionError(
          └ <class 'urllib3.exceptions.NewConnectionError'>

urllib3.exceptions.NewConnectionError: <urllib3.connection.HTTPConnection object at 0x7f91485e7160>: Failed to establish a new connection: [Errno 111] Connection refused


During handling of the above exception, another exception occurred:


Traceback (most recent call last):

  File "/home/chase/.local/lib/python3.8/site-packages/requests/adapters.py", line 439, in send
    resp = conn.urlopen(
           │    └ <function HTTPConnectionPool.urlopen at 0x7f92585c0820>
           └ <urllib3.connectionpool.HTTPConnectionPool object at 0x7f91603cf4f0>
  File "/home/chase/.local/lib/python3.8/site-packages/urllib3/connectionpool.py", line 755, in urlopen
    retries = retries.increment(
              │       └ <function Retry.increment at 0x7f9258608b80>
              └ Retry(total=0, connect=None, read=False, redirect=None, status=None)
  File "/home/chase/.local/lib/python3.8/site-packages/urllib3/util/retry.py", line 574, in increment
    raise MaxRetryError(_pool, url, error or ResponseError(cause))
          │             │      │    │        │             └ 'unknown'
          │             │      │    │        └ <class 'urllib3.exceptions.ResponseError'>
          │             │      │    └ NewConnectionError('<urllib3.connection.HTTPConnection object at 0x7f91485e7160>: Failed to establish a new connection: [Errn...
          │             │      └ '/board/1.html'
          │             └ <urllib3.connectionpool.HTTPConnectionPool object at 0x7f91603cf4f0>
          └ <class 'urllib3.exceptions.MaxRetryError'>

urllib3.exceptions.MaxRetryError: HTTPConnectionPool(host='bbs1.people.com.cn', port=80): Max retries exceeded with url: /board/1.html (Caused by NewConnectionError('<urllib3.connection.HTTPConnection object at 0x7f91485e7160>: Failed to establish a new connection: [Errno 111] Connection refused'))


During handling of the above exception, another exception occurred:


Traceback (most recent call last):

  File "/usr/lib/python3.8/threading.py", line 890, in _bootstrap
    self._bootstrap_inner()
    │    └ <function Thread._bootstrap_inner at 0x7f927a614a60>
    └ <Thread(Thread-367, started daemon 140257072748288)>
  File "/usr/lib/python3.8/threading.py", line 932, in _bootstrap_inner
    self.run()
    │    └ <function Thread.run at 0x7f927a614790>
    └ <Thread(Thread-367, started daemon 140257072748288)>
  File "/usr/lib/python3.8/threading.py", line 870, in run
    self._target(*self._args, **self._kwargs)
    │    │        │    │        │    └ {}
    │    │        │    │        └ <Thread(Thread-367, started daemon 140257072748288)>
    │    │        │    └ ('ProjectManager.run_func_by_thread',)
    │    │        └ <Thread(Thread-367, started daemon 140257072748288)>
    │    └ <bound method ProjectManager.get_request_from_keywords_hot of <monitor.projectManager.ProjectManager object at 0x7f9162af4700>>
    └ <Thread(Thread-367, started daemon 140257072748288)>

  File "/home/users/Scy/yuqing/spider/monitor/projectManager.py", line 795, in get_request_from_keywords_hot
    self.search_spider_manager.crawl_by_keyword(
    │    │                     └ <function SearchSpidersManager.crawl_by_keyword at 0x7f9162b00040>
    │    └ <monitor.spiderManager.SearchSpidersManager object at 0x7f916270f0d0>
    └ <monitor.projectManager.ProjectManager object at 0x7f9162af4700>

  File "/home/users/Scy/yuqing/spider/monitor/spiderManager.py", line 118, in crawl_by_keyword
    self.crawl_by_keyword_signal_platform(project_names, platform, keyword, crawl_time, project_times)
    │    │                                │              │         │        │           └ {'default': <monitor.TimeSection object at 0x7f91628317f0>}
    │    │                                │              │         │        └ <monitor.TimeSection object at 0x7f914821f670>
    │    │                                │              │         └ '俄罗斯举行胜利日阅兵'
    │    │                                │              └ '强国论坛'
    │    │                                └ ['default']
    │    └ <function SearchSpidersManager.crawl_by_keyword_signal_platform at 0x7f9162b000d0>
    └ <monitor.spiderManager.SearchSpidersManager object at 0x7f916270f0d0>

  File "/home/users/Scy/yuqing/spider/monitor/spiderManager.py", line 134, in crawl_by_keyword_signal_platform
    requests = self.get_request_from_keyword(platform, keyword, **crawl_time.to_dict())
               │    │                        │         │          │          └ <function TimeSection.to_dict at 0x7f925aaa8550>
               │    │                        │         │          └ <monitor.TimeSection object at 0x7f914821f670>
               │    │                        │         └ '俄罗斯举行胜利日阅兵'
               │    │                        └ '强国论坛'
               │    └ <function SearchSpidersManager.get_request_from_keyword at 0x7f9162b001f0>
               └ <monitor.spiderManager.SearchSpidersManager object at 0x7f916270f0d0>

  File "/home/users/Scy/yuqing/spider/monitor/spiderManager.py", line 191, in get_request_from_keyword
    for request in self.spiders[platform].get_request_from_keyword(headers, search_url, keyword, content_url,
                   │    │       │                                  │        │           │        └ <string.Template object at 0x7f90e46bf8e0>
                   │    │       │                                  │        │           └ '俄罗斯举行胜利日阅兵'
                   │    │       │                                  │        └ <string.Template object at 0x7f91246894c0>
                   │    │       │                                  └ {'Connection': 'keep-alive', 'Cache-Control': 'max-age=0', 'Upgrade-Insecure-Requests': '1', 'User-Agent': 'Mozilla/5.0 (X11;...
                   │    │       └ '强国论坛'
                   │    └ {'凤凰网': <monitor.searchSpiders.ifeng.Ifeng object at 0x7f916270f220>, '头条': <monitor.searchSpiders.toutiao.Toutiao object at ...
                   └ <monitor.spiderManager.SearchSpidersManager object at 0x7f916270f0d0>

> File "/home/users/Scy/yuqing/spider/monitor/searchSpiders/qinagguoLT.py", line 18, in get_request_from_keyword
    response = requests.get(search_url.substitute(), headers=headers)
               │        │   │          │                     └ {'Connection': 'keep-alive', 'Cache-Control': 'max-age=0', 'Upgrade-Insecure-Requests': '1', 'User-Agent': 'Mozilla/5.0 (X11;...
               │        │   │          └ <function Template.substitute at 0x7f927a5fd0d0>
               │        │   └ <string.Template object at 0x7f91246894c0>
               │        └ <function get at 0x7f92583e71f0>
               └ <module 'requests' from '/home/chase/.local/lib/python3.8/site-packages/requests/__init__.py'>

  File "/home/chase/.local/lib/python3.8/site-packages/requests/api.py", line 75, in get
    return request('get', url, params=params, **kwargs)
           │              │           │         └ {'headers': {'Connection': 'keep-alive', 'Cache-Control': 'max-age=0', 'Upgrade-Insecure-Requests': '1', 'User-Agent': 'Mozil...
           │              │           └ None
           │              └ 'http://bbs1.people.com.cn/board/1.html'
           └ <function request at 0x7f9258455040>
  File "/home/chase/.local/lib/python3.8/site-packages/requests/api.py", line 61, in request
    return session.request(method=method, url=url, **kwargs)
           │       │              │           │      └ {'params': None, 'headers': {'Connection': 'keep-alive', 'Cache-Control': 'max-age=0', 'Upgrade-Insecure-Requests': '1', 'Use...
           │       │              │           └ 'http://bbs1.people.com.cn/board/1.html'
           │       │              └ 'get'
           │       └ <function Session.request at 0x7f92583e6940>
           └ <requests.sessions.Session object at 0x7f912421c850>
  File "/home/chase/.local/lib/python3.8/site-packages/requests/sessions.py", line 542, in request
    resp = self.send(prep, **send_kwargs)
           │    │    │       └ {'timeout': None, 'allow_redirects': True, 'verify': True, 'proxies': OrderedDict(), 'stream': False, 'cert': None}
           │    │    └ <PreparedRequest [GET]>
           │    └ <function Session.send at 0x7f92583e6dc0>
           └ <requests.sessions.Session object at 0x7f912421c850>
  File "/home/chase/.local/lib/python3.8/site-packages/requests/sessions.py", line 655, in send
    r = adapter.send(request, **kwargs)
        │       │    │          └ {'timeout': None, 'verify': True, 'proxies': OrderedDict(), 'stream': False, 'cert': None}
        │       │    └ <PreparedRequest [GET]>
        │       └ <function HTTPAdapter.send at 0x7f92583e6280>
        └ <requests.adapters.HTTPAdapter object at 0x7f91242112e0>
  File "/home/chase/.local/lib/python3.8/site-packages/requests/adapters.py", line 516, in send
    raise ConnectionError(e, request=request)
          │                          └ <PreparedRequest [GET]>
          └ <class 'requests.exceptions.ConnectionError'>

requests.exceptions.ConnectionError: HTTPConnectionPool(host='bbs1.people.com.cn', port=80): Max retries exceeded with url: /board/1.html (Caused by NewConnectionError('<urllib3.connection.HTTPConnection object at 0x7f91485e7160>: Failed to establish a new connection: [Errno 111] Connection refused'))
2022-05-12 15:51:37.379 | ERROR    | monitor.searchSpiders.people:get_request_from_keyword:45 - E 人民网错误HTTPConnectionPool(host='search.people.cn', port=80): Max retries exceeded with url: /search-platform/front/search (Caused by NewConnectionError('<urllib3.connection.HTTPConnection object at 0x7f914815c160>: Failed to establish a new connection: [Errno 111] Connection refused'))
Traceback (most recent call last):

  File "/home/chase/.local/lib/python3.8/site-packages/urllib3/connection.py", line 174, in _new_conn
    conn = connection.create_connection(
           │          └ <function create_connection at 0x7f92585fd1f0>
           └ <module 'urllib3.util.connection' from '/home/chase/.local/lib/python3.8/site-packages/urllib3/util/connection.py'>
  File "/home/chase/.local/lib/python3.8/site-packages/urllib3/util/connection.py", line 96, in create_connection
    raise err
          └ ConnectionRefusedError(111, 'Connection refused')
  File "/home/chase/.local/lib/python3.8/site-packages/urllib3/util/connection.py", line 86, in create_connection
    sock.connect(sa)
    │            └ ('1.31.128.250', 80)
    └ None

ConnectionRefusedError: [Errno 111] Connection refused


During handling of the above exception, another exception occurred:


Traceback (most recent call last):

  File "/home/chase/.local/lib/python3.8/site-packages/urllib3/connectionpool.py", line 699, in urlopen
    httplib_response = self._make_request(
                       │    └ <function HTTPConnectionPool._make_request at 0x7f92585c05e0>
                       └ <urllib3.connectionpool.HTTPConnectionPool object at 0x7f9124666460>
  File "/home/chase/.local/lib/python3.8/site-packages/urllib3/connectionpool.py", line 394, in _make_request
    conn.request(method, url, **httplib_request_kw)
    │    │       │       │      └ {'body': b'{"key": "\\u4e1c\\u90e8\\u6218\\u533a\\u7ec4\\u7ec7\\u5175\\u529b\\u5728\\u53f0\\u5c9b\\u4ee5\\u4e1c\\u548c\\u897f...
    │    │       │       └ '/search-platform/front/search'
    │    │       └ 'POST'
    │    └ <function HTTPConnection.request at 0x7f92585b0f70>
    └ <urllib3.connection.HTTPConnection object at 0x7f914815c160>
  File "/home/chase/.local/lib/python3.8/site-packages/urllib3/connection.py", line 239, in request
    super(HTTPConnection, self).request(method, url, body=body, headers=headers)
          │               │             │       │         │             └ {'User-Agent': 'Mozilla/5.0 (Windows NT 10.0; Win64; x64) AppleWebKit/537.36 (KHTML, like Gecko) Chrome/101.0.4951.54 Safari/...
          │               │             │       │         └ b'{"key": "\\u4e1c\\u90e8\\u6218\\u533a\\u7ec4\\u7ec7\\u5175\\u529b\\u5728\\u53f0\\u5c9b\\u4ee5\\u4e1c\\u548c\\u897f\\u5357\\...
          │               │             │       └ '/search-platform/front/search'
          │               │             └ 'POST'
          │               └ <urllib3.connection.HTTPConnection object at 0x7f914815c160>
          └ <class 'urllib3.connection.HTTPConnection'>
  File "/usr/lib/python3.8/http/client.py", line 1256, in request
    self._send_request(method, url, body, headers, encode_chunked)
    │    │             │       │    │     │        └ False
    │    │             │       │    │     └ {'User-Agent': 'Mozilla/5.0 (Windows NT 10.0; Win64; x64) AppleWebKit/537.36 (KHTML, like Gecko) Chrome/101.0.4951.54 Safari/...
    │    │             │       │    └ b'{"key": "\\u4e1c\\u90e8\\u6218\\u533a\\u7ec4\\u7ec7\\u5175\\u529b\\u5728\\u53f0\\u5c9b\\u4ee5\\u4e1c\\u548c\\u897f\\u5357\\...
    │    │             │       └ '/search-platform/front/search'
    │    │             └ 'POST'
    │    └ <function HTTPConnection._send_request at 0x7f926be50280>
    └ <urllib3.connection.HTTPConnection object at 0x7f914815c160>
  File "/usr/lib/python3.8/http/client.py", line 1302, in _send_request
    self.endheaders(body, encode_chunked=encode_chunked)
    │    │          │                    └ False
    │    │          └ b'{"key": "\\u4e1c\\u90e8\\u6218\\u533a\\u7ec4\\u7ec7\\u5175\\u529b\\u5728\\u53f0\\u5c9b\\u4ee5\\u4e1c\\u548c\\u897f\\u5357\\...
    │    └ <function HTTPConnection.endheaders at 0x7f926be50160>
    └ <urllib3.connection.HTTPConnection object at 0x7f914815c160>
  File "/usr/lib/python3.8/http/client.py", line 1251, in endheaders
    self._send_output(message_body, encode_chunked=encode_chunked)
    │    │            │                            └ False
    │    │            └ b'{"key": "\\u4e1c\\u90e8\\u6218\\u533a\\u7ec4\\u7ec7\\u5175\\u529b\\u5728\\u53f0\\u5c9b\\u4ee5\\u4e1c\\u548c\\u897f\\u5357\\...
    │    └ <function HTTPConnection._send_output at 0x7f926beb7d30>
    └ <urllib3.connection.HTTPConnection object at 0x7f914815c160>
  File "/usr/lib/python3.8/http/client.py", line 1011, in _send_output
    self.send(msg)
    │    │    └ b'POST /search-platform/front/search HTTP/1.1\r\nHost: search.people.cn\r\nUser-Agent: Mozilla/5.0 (Windows NT 10.0; Win64; x...
    │    └ <function HTTPConnection.send at 0x7f926beb7b80>
    └ <urllib3.connection.HTTPConnection object at 0x7f914815c160>
  File "/usr/lib/python3.8/http/client.py", line 951, in send
    self.connect()
    │    └ <function HTTPConnection.connect at 0x7f92585b0dc0>
    └ <urllib3.connection.HTTPConnection object at 0x7f914815c160>
  File "/home/chase/.local/lib/python3.8/site-packages/urllib3/connection.py", line 205, in connect
    conn = self._new_conn()
           │    └ <function HTTPConnection._new_conn at 0x7f92585b0c10>
           └ <urllib3.connection.HTTPConnection object at 0x7f914815c160>
  File "/home/chase/.local/lib/python3.8/site-packages/urllib3/connection.py", line 186, in _new_conn
    raise NewConnectionError(
          └ <class 'urllib3.exceptions.NewConnectionError'>

urllib3.exceptions.NewConnectionError: <urllib3.connection.HTTPConnection object at 0x7f914815c160>: Failed to establish a new connection: [Errno 111] Connection refused


During handling of the above exception, another exception occurred:


Traceback (most recent call last):

  File "/home/chase/.local/lib/python3.8/site-packages/requests/adapters.py", line 439, in send
    resp = conn.urlopen(
           │    └ <function HTTPConnectionPool.urlopen at 0x7f92585c0820>
           └ <urllib3.connectionpool.HTTPConnectionPool object at 0x7f9124666460>
  File "/home/chase/.local/lib/python3.8/site-packages/urllib3/connectionpool.py", line 755, in urlopen
    retries = retries.increment(
              │       └ <function Retry.increment at 0x7f9258608b80>
              └ Retry(total=0, connect=None, read=False, redirect=None, status=None)
  File "/home/chase/.local/lib/python3.8/site-packages/urllib3/util/retry.py", line 574, in increment
    raise MaxRetryError(_pool, url, error or ResponseError(cause))
          │             │      │    │        │             └ 'unknown'
          │             │      │    │        └ <class 'urllib3.exceptions.ResponseError'>
          │             │      │    └ NewConnectionError('<urllib3.connection.HTTPConnection object at 0x7f914815c160>: Failed to establish a new connection: [Errn...
          │             │      └ '/search-platform/front/search'
          │             └ <urllib3.connectionpool.HTTPConnectionPool object at 0x7f9124666460>
          └ <class 'urllib3.exceptions.MaxRetryError'>

urllib3.exceptions.MaxRetryError: HTTPConnectionPool(host='search.people.cn', port=80): Max retries exceeded with url: /search-platform/front/search (Caused by NewConnectionError('<urllib3.connection.HTTPConnection object at 0x7f914815c160>: Failed to establish a new connection: [Errno 111] Connection refused'))


During handling of the above exception, another exception occurred:


Traceback (most recent call last):

  File "/usr/lib/python3.8/threading.py", line 890, in _bootstrap
    self._bootstrap_inner()
    │    └ <function Thread._bootstrap_inner at 0x7f927a614a60>
    └ <Thread(Thread-239, started daemon 140258691753728)>
  File "/usr/lib/python3.8/threading.py", line 932, in _bootstrap_inner
    self.run()
    │    └ <function Thread.run at 0x7f927a614790>
    └ <Thread(Thread-239, started daemon 140258691753728)>
  File "/usr/lib/python3.8/threading.py", line 870, in run
    self._target(*self._args, **self._kwargs)
    │    │        │    │        │    └ {}
    │    │        │    │        └ <Thread(Thread-239, started daemon 140258691753728)>
    │    │        │    └ ('ProjectManager.run_func_by_thread',)
    │    │        └ <Thread(Thread-239, started daemon 140258691753728)>
    │    └ <bound method ProjectManager.get_request_from_keywords_hot of <monitor.projectManager.ProjectManager object at 0x7f9162af4700>>
    └ <Thread(Thread-239, started daemon 140258691753728)>

  File "/home/users/Scy/yuqing/spider/monitor/projectManager.py", line 795, in get_request_from_keywords_hot
    self.search_spider_manager.crawl_by_keyword(
    │    │                     └ <function SearchSpidersManager.crawl_by_keyword at 0x7f9162b00040>
    │    └ <monitor.spiderManager.SearchSpidersManager object at 0x7f916270f0d0>
    └ <monitor.projectManager.ProjectManager object at 0x7f9162af4700>

  File "/home/users/Scy/yuqing/spider/monitor/spiderManager.py", line 118, in crawl_by_keyword
    self.crawl_by_keyword_signal_platform(project_names, platform, keyword, crawl_time, project_times)
    │    │                                │              │         │        │           └ {'default': <monitor.TimeSection object at 0x7f91628317f0>}
    │    │                                │              │         │        └ <monitor.TimeSection object at 0x7f91487aac70>
    │    │                                │              │         └ '东部战区组织兵力在台岛以东和西南海空域进行实兵演练'
    │    │                                │              └ '人民网'
    │    │                                └ ['default']
    │    └ <function SearchSpidersManager.crawl_by_keyword_signal_platform at 0x7f9162b000d0>
    └ <monitor.spiderManager.SearchSpidersManager object at 0x7f916270f0d0>

  File "/home/users/Scy/yuqing/spider/monitor/spiderManager.py", line 134, in crawl_by_keyword_signal_platform
    requests = self.get_request_from_keyword(platform, keyword, **crawl_time.to_dict())
               │    │                        │         │          │          └ <function TimeSection.to_dict at 0x7f925aaa8550>
               │    │                        │         │          └ <monitor.TimeSection object at 0x7f91487aac70>
               │    │                        │         └ '东部战区组织兵力在台岛以东和西南海空域进行实兵演练'
               │    │                        └ '人民网'
               │    └ <function SearchSpidersManager.get_request_from_keyword at 0x7f9162b001f0>
               └ <monitor.spiderManager.SearchSpidersManager object at 0x7f916270f0d0>

  File "/home/users/Scy/yuqing/spider/monitor/spiderManager.py", line 191, in get_request_from_keyword
    for request in self.spiders[platform].get_request_from_keyword(headers, search_url, keyword, content_url,
                   │    │       │                                  │        │           │        └ <string.Template object at 0x7f9104068f10>
                   │    │       │                                  │        │           └ '东部战区组织兵力在台岛以东和西南海空域进行实兵演练'
                   │    │       │                                  │        └ <string.Template object at 0x7f9104068910>
                   │    │       │                                  └ {'Accept': 'application/json, text/plain, */*', 'Accept-Language': 'zh-CN,zh;q=0.9', 'Connection': 'keep-alive', 'Origin': 'h...
                   │    │       └ '人民网'
                   │    └ {'凤凰网': <monitor.searchSpiders.ifeng.Ifeng object at 0x7f916270f220>, '头条': <monitor.searchSpiders.toutiao.Toutiao object at ...
                   └ <monitor.spiderManager.SearchSpidersManager object at 0x7f916270f0d0>

> File "/home/users/Scy/yuqing/spider/monitor/searchSpiders/people.py", line 28, in get_request_from_keyword
    response = requests.post(search_url.substitute(), json=data, headers=headers)
               │        │    │          │                  │             └ {'Accept': 'application/json, text/plain, */*', 'Accept-Language': 'zh-CN,zh;q=0.9', 'Connection': 'keep-alive', 'Origin': 'h...
               │        │    │          │                  └ {'key': '东部战区组织兵力在台岛以东和西南海空域进行实兵演练', 'page': 1, 'limit': 10, 'hasTitle': True, 'hasContent': True, 'isFuzzy': True, 'type': 0...
               │        │    │          └ <function Template.substitute at 0x7f927a5fd0d0>
               │        │    └ <string.Template object at 0x7f9104068910>
               │        └ <function post at 0x7f92583e73a0>
               └ <module 'requests' from '/home/chase/.local/lib/python3.8/site-packages/requests/__init__.py'>

  File "/home/chase/.local/lib/python3.8/site-packages/requests/api.py", line 117, in post
    return request('post', url, data=data, json=json, **kwargs)
           │               │         │          │       └ {'headers': {'Accept': 'application/json, text/plain, */*', 'Accept-Language': 'zh-CN,zh;q=0.9', 'Connection': 'keep-alive', ...
           │               │         │          └ {'key': '东部战区组织兵力在台岛以东和西南海空域进行实兵演练', 'page': 1, 'limit': 10, 'hasTitle': True, 'hasContent': True, 'isFuzzy': True, 'type': 0...
           │               │         └ None
           │               └ 'http://search.people.cn/search-platform/front/search'
           └ <function request at 0x7f9258455040>
  File "/home/chase/.local/lib/python3.8/site-packages/requests/api.py", line 61, in request
    return session.request(method=method, url=url, **kwargs)
           │       │              │           │      └ {'data': None, 'json': {'key': '东部战区组织兵力在台岛以东和西南海空域进行实兵演练', 'page': 1, 'limit': 10, 'hasTitle': True, 'hasContent': True, 'is...
           │       │              │           └ 'http://search.people.cn/search-platform/front/search'
           │       │              └ 'post'
           │       └ <function Session.request at 0x7f92583e6940>
           └ <requests.sessions.Session object at 0x7f91487396d0>
  File "/home/chase/.local/lib/python3.8/site-packages/requests/sessions.py", line 542, in request
    resp = self.send(prep, **send_kwargs)
           │    │    │       └ {'timeout': None, 'allow_redirects': True, 'verify': True, 'proxies': OrderedDict(), 'stream': False, 'cert': None}
           │    │    └ <PreparedRequest [POST]>
           │    └ <function Session.send at 0x7f92583e6dc0>
           └ <requests.sessions.Session object at 0x7f91487396d0>
  File "/home/chase/.local/lib/python3.8/site-packages/requests/sessions.py", line 655, in send
    r = adapter.send(request, **kwargs)
        │       │    │          └ {'timeout': None, 'verify': True, 'proxies': OrderedDict(), 'stream': False, 'cert': None}
        │       │    └ <PreparedRequest [POST]>
        │       └ <function HTTPAdapter.send at 0x7f92583e6280>
        └ <requests.adapters.HTTPAdapter object at 0x7f91240b8b80>
  File "/home/chase/.local/lib/python3.8/site-packages/requests/adapters.py", line 516, in send
    raise ConnectionError(e, request=request)
          │                          └ <PreparedRequest [POST]>
          └ <class 'requests.exceptions.ConnectionError'>

requests.exceptions.ConnectionError: HTTPConnectionPool(host='search.people.cn', port=80): Max retries exceeded with url: /search-platform/front/search (Caused by NewConnectionError('<urllib3.connection.HTTPConnection object at 0x7f914815c160>: Failed to establish a new connection: [Errno 111] Connection refused'))
2022-05-12 15:51:37.572 | ERROR    | monitor.searchSpiders.qinagguoLT:get_request_from_keyword:27 - E 强国论坛错误HTTPConnectionPool(host='bbs1.people.com.cn', port=80): Max retries exceeded with url: /board/1.html (Caused by NewConnectionError('<urllib3.connection.HTTPConnection object at 0x7f914820ef10>: Failed to establish a new connection: [Errno 111] Connection refused'))
Traceback (most recent call last):

  File "/home/chase/.local/lib/python3.8/site-packages/urllib3/connection.py", line 174, in _new_conn
    conn = connection.create_connection(
           │          └ <function create_connection at 0x7f92585fd1f0>
           └ <module 'urllib3.util.connection' from '/home/chase/.local/lib/python3.8/site-packages/urllib3/util/connection.py'>
  File "/home/chase/.local/lib/python3.8/site-packages/urllib3/util/connection.py", line 96, in create_connection
    raise err
          └ ConnectionRefusedError(111, 'Connection refused')
  File "/home/chase/.local/lib/python3.8/site-packages/urllib3/util/connection.py", line 86, in create_connection
    sock.connect(sa)
    │            └ ('118.212.233.223', 80)
    └ None

ConnectionRefusedError: [Errno 111] Connection refused


During handling of the above exception, another exception occurred:


Traceback (most recent call last):

  File "/home/chase/.local/lib/python3.8/site-packages/urllib3/connectionpool.py", line 699, in urlopen
    httplib_response = self._make_request(
                       │    └ <function HTTPConnectionPool._make_request at 0x7f92585c05e0>
                       └ <urllib3.connectionpool.HTTPConnectionPool object at 0x7f9160165970>
  File "/home/chase/.local/lib/python3.8/site-packages/urllib3/connectionpool.py", line 394, in _make_request
    conn.request(method, url, **httplib_request_kw)
    │    │       │       │      └ {'body': None, 'headers': {'User-Agent': 'Mozilla/5.0 (X11; Linux x86_64) AppleWebKit/537.36 (KHTML, like Gecko) Chrome/93.0....
    │    │       │       └ '/board/1.html'
    │    │       └ 'GET'
    │    └ <function HTTPConnection.request at 0x7f92585b0f70>
    └ <urllib3.connection.HTTPConnection object at 0x7f914820ef10>
  File "/home/chase/.local/lib/python3.8/site-packages/urllib3/connection.py", line 239, in request
    super(HTTPConnection, self).request(method, url, body=body, headers=headers)
          │               │             │       │         │             └ {'User-Agent': 'Mozilla/5.0 (X11; Linux x86_64) AppleWebKit/537.36 (KHTML, like Gecko) Chrome/93.0.4577.63 Safari/537.36', 'A...
          │               │             │       │         └ None
          │               │             │       └ '/board/1.html'
          │               │             └ 'GET'
          │               └ <urllib3.connection.HTTPConnection object at 0x7f914820ef10>
          └ <class 'urllib3.connection.HTTPConnection'>
  File "/usr/lib/python3.8/http/client.py", line 1256, in request
    self._send_request(method, url, body, headers, encode_chunked)
    │    │             │       │    │     │        └ False
    │    │             │       │    │     └ {'User-Agent': 'Mozilla/5.0 (X11; Linux x86_64) AppleWebKit/537.36 (KHTML, like Gecko) Chrome/93.0.4577.63 Safari/537.36', 'A...
    │    │             │       │    └ None
    │    │             │       └ '/board/1.html'
    │    │             └ 'GET'
    │    └ <function HTTPConnection._send_request at 0x7f926be50280>
    └ <urllib3.connection.HTTPConnection object at 0x7f914820ef10>
  File "/usr/lib/python3.8/http/client.py", line 1302, in _send_request
    self.endheaders(body, encode_chunked=encode_chunked)
    │    │          │                    └ False
    │    │          └ None
    │    └ <function HTTPConnection.endheaders at 0x7f926be50160>
    └ <urllib3.connection.HTTPConnection object at 0x7f914820ef10>
  File "/usr/lib/python3.8/http/client.py", line 1251, in endheaders
    self._send_output(message_body, encode_chunked=encode_chunked)
    │    │            │                            └ False
    │    │            └ None
    │    └ <function HTTPConnection._send_output at 0x7f926beb7d30>
    └ <urllib3.connection.HTTPConnection object at 0x7f914820ef10>
  File "/usr/lib/python3.8/http/client.py", line 1011, in _send_output
    self.send(msg)
    │    │    └ b'GET /board/1.html HTTP/1.1\r\nHost: bbs1.people.com.cn\r\nUser-Agent: Mozilla/5.0 (X11; Linux x86_64) AppleWebKit/537.36 (K...
    │    └ <function HTTPConnection.send at 0x7f926beb7b80>
    └ <urllib3.connection.HTTPConnection object at 0x7f914820ef10>
  File "/usr/lib/python3.8/http/client.py", line 951, in send
    self.connect()
    │    └ <function HTTPConnection.connect at 0x7f92585b0dc0>
    └ <urllib3.connection.HTTPConnection object at 0x7f914820ef10>
  File "/home/chase/.local/lib/python3.8/site-packages/urllib3/connection.py", line 205, in connect
    conn = self._new_conn()
           │    └ <function HTTPConnection._new_conn at 0x7f92585b0c10>
           └ <urllib3.connection.HTTPConnection object at 0x7f914820ef10>
  File "/home/chase/.local/lib/python3.8/site-packages/urllib3/connection.py", line 186, in _new_conn
    raise NewConnectionError(
          └ <class 'urllib3.exceptions.NewConnectionError'>

urllib3.exceptions.NewConnectionError: <urllib3.connection.HTTPConnection object at 0x7f914820ef10>: Failed to establish a new connection: [Errno 111] Connection refused


During handling of the above exception, another exception occurred:


Traceback (most recent call last):

  File "/home/chase/.local/lib/python3.8/site-packages/requests/adapters.py", line 439, in send
    resp = conn.urlopen(
           │    └ <function HTTPConnectionPool.urlopen at 0x7f92585c0820>
           └ <urllib3.connectionpool.HTTPConnectionPool object at 0x7f9160165970>
  File "/home/chase/.local/lib/python3.8/site-packages/urllib3/connectionpool.py", line 755, in urlopen
    retries = retries.increment(
              │       └ <function Retry.increment at 0x7f9258608b80>
              └ Retry(total=0, connect=None, read=False, redirect=None, status=None)
  File "/home/chase/.local/lib/python3.8/site-packages/urllib3/util/retry.py", line 574, in increment
    raise MaxRetryError(_pool, url, error or ResponseError(cause))
          │             │      │    │        │             └ 'unknown'
          │             │      │    │        └ <class 'urllib3.exceptions.ResponseError'>
          │             │      │    └ NewConnectionError('<urllib3.connection.HTTPConnection object at 0x7f914820ef10>: Failed to establish a new connection: [Errn...
          │             │      └ '/board/1.html'
          │             └ <urllib3.connectionpool.HTTPConnectionPool object at 0x7f9160165970>
          └ <class 'urllib3.exceptions.MaxRetryError'>

urllib3.exceptions.MaxRetryError: HTTPConnectionPool(host='bbs1.people.com.cn', port=80): Max retries exceeded with url: /board/1.html (Caused by NewConnectionError('<urllib3.connection.HTTPConnection object at 0x7f914820ef10>: Failed to establish a new connection: [Errno 111] Connection refused'))


During handling of the above exception, another exception occurred:


Traceback (most recent call last):

  File "/usr/lib/python3.8/threading.py", line 890, in _bootstrap
    self._bootstrap_inner()
    │    └ <function Thread._bootstrap_inner at 0x7f927a614a60>
    └ <Thread(Thread-244, started daemon 140258196846336)>
  File "/usr/lib/python3.8/threading.py", line 932, in _bootstrap_inner
    self.run()
    │    └ <function Thread.run at 0x7f927a614790>
    └ <Thread(Thread-244, started daemon 140258196846336)>
  File "/usr/lib/python3.8/threading.py", line 870, in run
    self._target(*self._args, **self._kwargs)
    │    │        │    │        │    └ {}
    │    │        │    │        └ <Thread(Thread-244, started daemon 140258196846336)>
    │    │        │    └ ('ProjectManager.run_func_by_thread',)
    │    │        └ <Thread(Thread-244, started daemon 140258196846336)>
    │    └ <bound method ProjectManager.get_request_from_keywords_hot of <monitor.projectManager.ProjectManager object at 0x7f9162af4700>>
    └ <Thread(Thread-244, started daemon 140258196846336)>

  File "/home/users/Scy/yuqing/spider/monitor/projectManager.py", line 795, in get_request_from_keywords_hot
    self.search_spider_manager.crawl_by_keyword(
    │    │                     └ <function SearchSpidersManager.crawl_by_keyword at 0x7f9162b00040>
    │    └ <monitor.spiderManager.SearchSpidersManager object at 0x7f916270f0d0>
    └ <monitor.projectManager.ProjectManager object at 0x7f9162af4700>

  File "/home/users/Scy/yuqing/spider/monitor/spiderManager.py", line 118, in crawl_by_keyword
    self.crawl_by_keyword_signal_platform(project_names, platform, keyword, crawl_time, project_times)
    │    │                                │              │         │        │           └ {'default': <monitor.TimeSection object at 0x7f91628317f0>}
    │    │                                │              │         │        └ <monitor.TimeSection object at 0x7f91247aeb50>
    │    │                                │              │         └ '东部战区组织兵力在台岛以东和西南海空域进行实兵演练'
    │    │                                │              └ '强国论坛'
    │    │                                └ ['default']
    │    └ <function SearchSpidersManager.crawl_by_keyword_signal_platform at 0x7f9162b000d0>
    └ <monitor.spiderManager.SearchSpidersManager object at 0x7f916270f0d0>

  File "/home/users/Scy/yuqing/spider/monitor/spiderManager.py", line 134, in crawl_by_keyword_signal_platform
    requests = self.get_request_from_keyword(platform, keyword, **crawl_time.to_dict())
               │    │                        │         │          │          └ <function TimeSection.to_dict at 0x7f925aaa8550>
               │    │                        │         │          └ <monitor.TimeSection object at 0x7f91247aeb50>
               │    │                        │         └ '东部战区组织兵力在台岛以东和西南海空域进行实兵演练'
               │    │                        └ '强国论坛'
               │    └ <function SearchSpidersManager.get_request_from_keyword at 0x7f9162b001f0>
               └ <monitor.spiderManager.SearchSpidersManager object at 0x7f916270f0d0>

  File "/home/users/Scy/yuqing/spider/monitor/spiderManager.py", line 191, in get_request_from_keyword
    for request in self.spiders[platform].get_request_from_keyword(headers, search_url, keyword, content_url,
                   │    │       │                                  │        │           │        └ <string.Template object at 0x7f91042c8730>
                   │    │       │                                  │        │           └ '东部战区组织兵力在台岛以东和西南海空域进行实兵演练'
                   │    │       │                                  │        └ <string.Template object at 0x7f91482d10a0>
                   │    │       │                                  └ {'Connection': 'keep-alive', 'Cache-Control': 'max-age=0', 'Upgrade-Insecure-Requests': '1', 'User-Agent': 'Mozilla/5.0 (X11;...
                   │    │       └ '强国论坛'
                   │    └ {'凤凰网': <monitor.searchSpiders.ifeng.Ifeng object at 0x7f916270f220>, '头条': <monitor.searchSpiders.toutiao.Toutiao object at ...
                   └ <monitor.spiderManager.SearchSpidersManager object at 0x7f916270f0d0>

> File "/home/users/Scy/yuqing/spider/monitor/searchSpiders/qinagguoLT.py", line 18, in get_request_from_keyword
    response = requests.get(search_url.substitute(), headers=headers)
               │        │   │          │                     └ {'Connection': 'keep-alive', 'Cache-Control': 'max-age=0', 'Upgrade-Insecure-Requests': '1', 'User-Agent': 'Mozilla/5.0 (X11;...
               │        │   │          └ <function Template.substitute at 0x7f927a5fd0d0>
               │        │   └ <string.Template object at 0x7f91482d10a0>
               │        └ <function get at 0x7f92583e71f0>
               └ <module 'requests' from '/home/chase/.local/lib/python3.8/site-packages/requests/__init__.py'>

  File "/home/chase/.local/lib/python3.8/site-packages/requests/api.py", line 75, in get
    return request('get', url, params=params, **kwargs)
           │              │           │         └ {'headers': {'Connection': 'keep-alive', 'Cache-Control': 'max-age=0', 'Upgrade-Insecure-Requests': '1', 'User-Agent': 'Mozil...
           │              │           └ None
           │              └ 'http://bbs1.people.com.cn/board/1.html'
           └ <function request at 0x7f9258455040>
  File "/home/chase/.local/lib/python3.8/site-packages/requests/api.py", line 61, in request
    return session.request(method=method, url=url, **kwargs)
           │       │              │           │      └ {'params': None, 'headers': {'Connection': 'keep-alive', 'Cache-Control': 'max-age=0', 'Upgrade-Insecure-Requests': '1', 'Use...
           │       │              │           └ 'http://bbs1.people.com.cn/board/1.html'
           │       │              └ 'get'
           │       └ <function Session.request at 0x7f92583e6940>
           └ <requests.sessions.Session object at 0x7f91240500d0>
  File "/home/chase/.local/lib/python3.8/site-packages/requests/sessions.py", line 542, in request
    resp = self.send(prep, **send_kwargs)
           │    │    │       └ {'timeout': None, 'allow_redirects': True, 'verify': True, 'proxies': OrderedDict(), 'stream': False, 'cert': None}
           │    │    └ <PreparedRequest [GET]>
           │    └ <function Session.send at 0x7f92583e6dc0>
           └ <requests.sessions.Session object at 0x7f91240500d0>
  File "/home/chase/.local/lib/python3.8/site-packages/requests/sessions.py", line 655, in send
    r = adapter.send(request, **kwargs)
        │       │    │          └ {'timeout': None, 'verify': True, 'proxies': OrderedDict(), 'stream': False, 'cert': None}
        │       │    └ <PreparedRequest [GET]>
        │       └ <function HTTPAdapter.send at 0x7f92583e6280>
        └ <requests.adapters.HTTPAdapter object at 0x7f9160394ee0>
  File "/home/chase/.local/lib/python3.8/site-packages/requests/adapters.py", line 516, in send
    raise ConnectionError(e, request=request)
          │                          └ <PreparedRequest [GET]>
          └ <class 'requests.exceptions.ConnectionError'>

requests.exceptions.ConnectionError: HTTPConnectionPool(host='bbs1.people.com.cn', port=80): Max retries exceeded with url: /board/1.html (Caused by NewConnectionError('<urllib3.connection.HTTPConnection object at 0x7f914820ef10>: Failed to establish a new connection: [Errno 111] Connection refused'))
2022-05-12 15:51:37.506 | ERROR    | monitor.searchSpiders.people:get_request_from_keyword:45 - E 人民网错误HTTPConnectionPool(host='search.people.cn', port=80): Max retries exceeded with url: /search-platform/front/search (Caused by NewConnectionError('<urllib3.connection.HTTPConnection object at 0x7f91244a17f0>: Failed to establish a new connection: [Errno 111] Connection refused'))
Traceback (most recent call last):

  File "/home/chase/.local/lib/python3.8/site-packages/urllib3/connection.py", line 174, in _new_conn
    conn = connection.create_connection(
           │          └ <function create_connection at 0x7f92585fd1f0>
           └ <module 'urllib3.util.connection' from '/home/chase/.local/lib/python3.8/site-packages/urllib3/util/connection.py'>
  File "/home/chase/.local/lib/python3.8/site-packages/urllib3/util/connection.py", line 96, in create_connection
    raise err
          └ ConnectionRefusedError(111, 'Connection refused')
  File "/home/chase/.local/lib/python3.8/site-packages/urllib3/util/connection.py", line 86, in create_connection
    sock.connect(sa)
    │            └ ('1.31.128.250', 80)
    └ None

ConnectionRefusedError: [Errno 111] Connection refused


During handling of the above exception, another exception occurred:


Traceback (most recent call last):

  File "/home/chase/.local/lib/python3.8/site-packages/urllib3/connectionpool.py", line 699, in urlopen
    httplib_response = self._make_request(
                       │    └ <function HTTPConnectionPool._make_request at 0x7f92585c05e0>
                       └ <urllib3.connectionpool.HTTPConnectionPool object at 0x7f91240808b0>
  File "/home/chase/.local/lib/python3.8/site-packages/urllib3/connectionpool.py", line 394, in _make_request
    conn.request(method, url, **httplib_request_kw)
    │    │       │       │      └ {'body': b'{"key": "\\u610f\\u5927\\u5229\\u4f5b\\u7f57\\u4f26\\u8428\\u57ce\\u5e02\\u666f\\u89c2\\u58ee\\u4e3d", "page": 1, ...
    │    │       │       └ '/search-platform/front/search'
    │    │       └ 'POST'
    │    └ <function HTTPConnection.request at 0x7f92585b0f70>
    └ <urllib3.connection.HTTPConnection object at 0x7f91244a17f0>
  File "/home/chase/.local/lib/python3.8/site-packages/urllib3/connection.py", line 239, in request
    super(HTTPConnection, self).request(method, url, body=body, headers=headers)
          │               │             │       │         │             └ {'User-Agent': 'Mozilla/5.0 (Windows NT 10.0; Win64; x64) AppleWebKit/537.36 (KHTML, like Gecko) Chrome/101.0.4951.54 Safari/...
          │               │             │       │         └ b'{"key": "\\u610f\\u5927\\u5229\\u4f5b\\u7f57\\u4f26\\u8428\\u57ce\\u5e02\\u666f\\u89c2\\u58ee\\u4e3d", "page": 1, "limit": ...
          │               │             │       └ '/search-platform/front/search'
          │               │             └ 'POST'
          │               └ <urllib3.connection.HTTPConnection object at 0x7f91244a17f0>
          └ <class 'urllib3.connection.HTTPConnection'>
  File "/usr/lib/python3.8/http/client.py", line 1256, in request
    self._send_request(method, url, body, headers, encode_chunked)
    │    │             │       │    │     │        └ False
    │    │             │       │    │     └ {'User-Agent': 'Mozilla/5.0 (Windows NT 10.0; Win64; x64) AppleWebKit/537.36 (KHTML, like Gecko) Chrome/101.0.4951.54 Safari/...
    │    │             │       │    └ b'{"key": "\\u610f\\u5927\\u5229\\u4f5b\\u7f57\\u4f26\\u8428\\u57ce\\u5e02\\u666f\\u89c2\\u58ee\\u4e3d", "page": 1, "limit": ...
    │    │             │       └ '/search-platform/front/search'
    │    │             └ 'POST'
    │    └ <function HTTPConnection._send_request at 0x7f926be50280>
    └ <urllib3.connection.HTTPConnection object at 0x7f91244a17f0>
  File "/usr/lib/python3.8/http/client.py", line 1302, in _send_request
    self.endheaders(body, encode_chunked=encode_chunked)
    │    │          │                    └ False
    │    │          └ b'{"key": "\\u610f\\u5927\\u5229\\u4f5b\\u7f57\\u4f26\\u8428\\u57ce\\u5e02\\u666f\\u89c2\\u58ee\\u4e3d", "page": 1, "limit": ...
    │    └ <function HTTPConnection.endheaders at 0x7f926be50160>
    └ <urllib3.connection.HTTPConnection object at 0x7f91244a17f0>
  File "/usr/lib/python3.8/http/client.py", line 1251, in endheaders
    self._send_output(message_body, encode_chunked=encode_chunked)
    │    │            │                            └ False
    │    │            └ b'{"key": "\\u610f\\u5927\\u5229\\u4f5b\\u7f57\\u4f26\\u8428\\u57ce\\u5e02\\u666f\\u89c2\\u58ee\\u4e3d", "page": 1, "limit": ...
    │    └ <function HTTPConnection._send_output at 0x7f926beb7d30>
    └ <urllib3.connection.HTTPConnection object at 0x7f91244a17f0>
  File "/usr/lib/python3.8/http/client.py", line 1011, in _send_output
    self.send(msg)
    │    │    └ b'POST /search-platform/front/search HTTP/1.1\r\nHost: search.people.cn\r\nUser-Agent: Mozilla/5.0 (Windows NT 10.0; Win64; x...
    │    └ <function HTTPConnection.send at 0x7f926beb7b80>
    └ <urllib3.connection.HTTPConnection object at 0x7f91244a17f0>
  File "/usr/lib/python3.8/http/client.py", line 951, in send
    self.connect()
    │    └ <function HTTPConnection.connect at 0x7f92585b0dc0>
    └ <urllib3.connection.HTTPConnection object at 0x7f91244a17f0>
  File "/home/chase/.local/lib/python3.8/site-packages/urllib3/connection.py", line 205, in connect
    conn = self._new_conn()
           │    └ <function HTTPConnection._new_conn at 0x7f92585b0c10>
           └ <urllib3.connection.HTTPConnection object at 0x7f91244a17f0>
  File "/home/chase/.local/lib/python3.8/site-packages/urllib3/connection.py", line 186, in _new_conn
    raise NewConnectionError(
          └ <class 'urllib3.exceptions.NewConnectionError'>

urllib3.exceptions.NewConnectionError: <urllib3.connection.HTTPConnection object at 0x7f91244a17f0>: Failed to establish a new connection: [Errno 111] Connection refused


During handling of the above exception, another exception occurred:


Traceback (most recent call last):

  File "/home/chase/.local/lib/python3.8/site-packages/requests/adapters.py", line 439, in send
    resp = conn.urlopen(
           │    └ <function HTTPConnectionPool.urlopen at 0x7f92585c0820>
           └ <urllib3.connectionpool.HTTPConnectionPool object at 0x7f91240808b0>
  File "/home/chase/.local/lib/python3.8/site-packages/urllib3/connectionpool.py", line 755, in urlopen
    retries = retries.increment(
              │       └ <function Retry.increment at 0x7f9258608b80>
              └ Retry(total=0, connect=None, read=False, redirect=None, status=None)
  File "/home/chase/.local/lib/python3.8/site-packages/urllib3/util/retry.py", line 574, in increment
    raise MaxRetryError(_pool, url, error or ResponseError(cause))
          │             │      │    │        │             └ 'unknown'
          │             │      │    │        └ <class 'urllib3.exceptions.ResponseError'>
          │             │      │    └ NewConnectionError('<urllib3.connection.HTTPConnection object at 0x7f91244a17f0>: Failed to establish a new connection: [Errn...
          │             │      └ '/search-platform/front/search'
          │             └ <urllib3.connectionpool.HTTPConnectionPool object at 0x7f91240808b0>
          └ <class 'urllib3.exceptions.MaxRetryError'>

urllib3.exceptions.MaxRetryError: HTTPConnectionPool(host='search.people.cn', port=80): Max retries exceeded with url: /search-platform/front/search (Caused by NewConnectionError('<urllib3.connection.HTTPConnection object at 0x7f91244a17f0>: Failed to establish a new connection: [Errno 111] Connection refused'))


During handling of the above exception, another exception occurred:


Traceback (most recent call last):

  File "/usr/lib/python3.8/threading.py", line 890, in _bootstrap
    self._bootstrap_inner()
    │    └ <function Thread._bootstrap_inner at 0x7f927a614a60>
    └ <Thread(Thread-51, started daemon 140261409679104)>
  File "/usr/lib/python3.8/threading.py", line 932, in _bootstrap_inner
    self.run()
    │    └ <function Thread.run at 0x7f927a614790>
    └ <Thread(Thread-51, started daemon 140261409679104)>
  File "/usr/lib/python3.8/threading.py", line 870, in run
    self._target(*self._args, **self._kwargs)
    │    │        │    │        │    └ {}
    │    │        │    │        └ <Thread(Thread-51, started daemon 140261409679104)>
    │    │        │    └ ('ProjectManager.run_func_by_thread',)
    │    │        └ <Thread(Thread-51, started daemon 140261409679104)>
    │    └ <bound method ProjectManager.get_request_from_keywords_hot of <monitor.projectManager.ProjectManager object at 0x7f9162af4700>>
    └ <Thread(Thread-51, started daemon 140261409679104)>

  File "/home/users/Scy/yuqing/spider/monitor/projectManager.py", line 795, in get_request_from_keywords_hot
    self.search_spider_manager.crawl_by_keyword(
    │    │                     └ <function SearchSpidersManager.crawl_by_keyword at 0x7f9162b00040>
    │    └ <monitor.spiderManager.SearchSpidersManager object at 0x7f916270f0d0>
    └ <monitor.projectManager.ProjectManager object at 0x7f9162af4700>

  File "/home/users/Scy/yuqing/spider/monitor/spiderManager.py", line 118, in crawl_by_keyword
    self.crawl_by_keyword_signal_platform(project_names, platform, keyword, crawl_time, project_times)
    │    │                                │              │         │        │           └ {'default': <monitor.TimeSection object at 0x7f91628317f0>}
    │    │                                │              │         │        └ <monitor.TimeSection object at 0x7f9160260070>
    │    │                                │              │         └ '意大利佛罗伦萨城市景观壮丽'
    │    │                                │              └ '人民网'
    │    │                                └ ['default']
    │    └ <function SearchSpidersManager.crawl_by_keyword_signal_platform at 0x7f9162b000d0>
    └ <monitor.spiderManager.SearchSpidersManager object at 0x7f916270f0d0>

  File "/home/users/Scy/yuqing/spider/monitor/spiderManager.py", line 134, in crawl_by_keyword_signal_platform
    requests = self.get_request_from_keyword(platform, keyword, **crawl_time.to_dict())
               │    │                        │         │          │          └ <function TimeSection.to_dict at 0x7f925aaa8550>
               │    │                        │         │          └ <monitor.TimeSection object at 0x7f9160260070>
               │    │                        │         └ '意大利佛罗伦萨城市景观壮丽'
               │    │                        └ '人民网'
               │    └ <function SearchSpidersManager.get_request_from_keyword at 0x7f9162b001f0>
               └ <monitor.spiderManager.SearchSpidersManager object at 0x7f916270f0d0>

  File "/home/users/Scy/yuqing/spider/monitor/spiderManager.py", line 191, in get_request_from_keyword
    for request in self.spiders[platform].get_request_from_keyword(headers, search_url, keyword, content_url,
                   │    │       │                                  │        │           │        └ <string.Template object at 0x7f91486b7580>
                   │    │       │                                  │        │           └ '意大利佛罗伦萨城市景观壮丽'
                   │    │       │                                  │        └ <string.Template object at 0x7f9124050c10>
                   │    │       │                                  └ {'Accept': 'application/json, text/plain, */*', 'Accept-Language': 'zh-CN,zh;q=0.9', 'Connection': 'keep-alive', 'Origin': 'h...
                   │    │       └ '人民网'
                   │    └ {'凤凰网': <monitor.searchSpiders.ifeng.Ifeng object at 0x7f916270f220>, '头条': <monitor.searchSpiders.toutiao.Toutiao object at ...
                   └ <monitor.spiderManager.SearchSpidersManager object at 0x7f916270f0d0>

> File "/home/users/Scy/yuqing/spider/monitor/searchSpiders/people.py", line 28, in get_request_from_keyword
    response = requests.post(search_url.substitute(), json=data, headers=headers)
               │        │    │          │                  │             └ {'Accept': 'application/json, text/plain, */*', 'Accept-Language': 'zh-CN,zh;q=0.9', 'Connection': 'keep-alive', 'Origin': 'h...
               │        │    │          │                  └ {'key': '意大利佛罗伦萨城市景观壮丽', 'page': 1, 'limit': 10, 'hasTitle': True, 'hasContent': True, 'isFuzzy': True, 'type': 0, 'sortType'...
               │        │    │          └ <function Template.substitute at 0x7f927a5fd0d0>
               │        │    └ <string.Template object at 0x7f9124050c10>
               │        └ <function post at 0x7f92583e73a0>
               └ <module 'requests' from '/home/chase/.local/lib/python3.8/site-packages/requests/__init__.py'>

  File "/home/chase/.local/lib/python3.8/site-packages/requests/api.py", line 117, in post
    return request('post', url, data=data, json=json, **kwargs)
           │               │         │          │       └ {'headers': {'Accept': 'application/json, text/plain, */*', 'Accept-Language': 'zh-CN,zh;q=0.9', 'Connection': 'keep-alive', ...
           │               │         │          └ {'key': '意大利佛罗伦萨城市景观壮丽', 'page': 1, 'limit': 10, 'hasTitle': True, 'hasContent': True, 'isFuzzy': True, 'type': 0, 'sortType'...
           │               │         └ None
           │               └ 'http://search.people.cn/search-platform/front/search'
           └ <function request at 0x7f9258455040>
  File "/home/chase/.local/lib/python3.8/site-packages/requests/api.py", line 61, in request
    return session.request(method=method, url=url, **kwargs)
           │       │              │           │      └ {'data': None, 'json': {'key': '意大利佛罗伦萨城市景观壮丽', 'page': 1, 'limit': 10, 'hasTitle': True, 'hasContent': True, 'isFuzzy': True...
           │       │              │           └ 'http://search.people.cn/search-platform/front/search'
           │       │              └ 'post'
           │       └ <function Session.request at 0x7f92583e6940>
           └ <requests.sessions.Session object at 0x7f916008c5e0>
  File "/home/chase/.local/lib/python3.8/site-packages/requests/sessions.py", line 542, in request
    resp = self.send(prep, **send_kwargs)
           │    │    │       └ {'timeout': None, 'allow_redirects': True, 'verify': True, 'proxies': OrderedDict(), 'stream': False, 'cert': None}
           │    │    └ <PreparedRequest [POST]>
           │    └ <function Session.send at 0x7f92583e6dc0>
           └ <requests.sessions.Session object at 0x7f916008c5e0>
  File "/home/chase/.local/lib/python3.8/site-packages/requests/sessions.py", line 655, in send
    r = adapter.send(request, **kwargs)
        │       │    │          └ {'timeout': None, 'verify': True, 'proxies': OrderedDict(), 'stream': False, 'cert': None}
        │       │    └ <PreparedRequest [POST]>
        │       └ <function HTTPAdapter.send at 0x7f92583e6280>
        └ <requests.adapters.HTTPAdapter object at 0x7f90e47b0370>
  File "/home/chase/.local/lib/python3.8/site-packages/requests/adapters.py", line 516, in send
    raise ConnectionError(e, request=request)
          │                          └ <PreparedRequest [POST]>
          └ <class 'requests.exceptions.ConnectionError'>

requests.exceptions.ConnectionError: HTTPConnectionPool(host='search.people.cn', port=80): Max retries exceeded with url: /search-platform/front/search (Caused by NewConnectionError('<urllib3.connection.HTTPConnection object at 0x7f91244a17f0>: Failed to establish a new connection: [Errno 111] Connection refused'))
2022-05-12 15:51:37.814 | ERROR    | monitor.searchSpiders.people:get_request_from_keyword:45 - E 人民网错误HTTPConnectionPool(host='search.people.cn', port=80): Max retries exceeded with url: /search-platform/front/search (Caused by NewConnectionError('<urllib3.connection.HTTPConnection object at 0x7f914810c430>: Failed to establish a new connection: [Errno 111] Connection refused'))
Traceback (most recent call last):

  File "/home/chase/.local/lib/python3.8/site-packages/urllib3/connection.py", line 174, in _new_conn
    conn = connection.create_connection(
           │          └ <function create_connection at 0x7f92585fd1f0>
           └ <module 'urllib3.util.connection' from '/home/chase/.local/lib/python3.8/site-packages/urllib3/util/connection.py'>
  File "/home/chase/.local/lib/python3.8/site-packages/urllib3/util/connection.py", line 96, in create_connection
    raise err
          └ ConnectionRefusedError(111, 'Connection refused')
  File "/home/chase/.local/lib/python3.8/site-packages/urllib3/util/connection.py", line 86, in create_connection
    sock.connect(sa)
    │            └ ('1.31.128.250', 80)
    └ None

ConnectionRefusedError: [Errno 111] Connection refused


During handling of the above exception, another exception occurred:


Traceback (most recent call last):

  File "/home/chase/.local/lib/python3.8/site-packages/urllib3/connectionpool.py", line 699, in urlopen
    httplib_response = self._make_request(
                       │    └ <function HTTPConnectionPool._make_request at 0x7f92585c05e0>
                       └ <urllib3.connectionpool.HTTPConnectionPool object at 0x7f91601af130>
  File "/home/chase/.local/lib/python3.8/site-packages/urllib3/connectionpool.py", line 394, in _make_request
    conn.request(method, url, **httplib_request_kw)
    │    │       │       │      └ {'body': b'{"key": "\\u610f\\u5927\\u5229\\u4f5b\\u7f57\\u4f26\\u8428\\u57ce\\u5e02\\u666f\\u89c2\\u58ee\\u4e3d", "page": 1, ...
    │    │       │       └ '/search-platform/front/search'
    │    │       └ 'POST'
    │    └ <function HTTPConnection.request at 0x7f92585b0f70>
    └ <urllib3.connection.HTTPConnection object at 0x7f914810c430>
  File "/home/chase/.local/lib/python3.8/site-packages/urllib3/connection.py", line 239, in request
    super(HTTPConnection, self).request(method, url, body=body, headers=headers)
          │               │             │       │         │             └ {'User-Agent': 'Mozilla/5.0 (Windows NT 10.0; Win64; x64) AppleWebKit/537.36 (KHTML, like Gecko) Chrome/101.0.4951.54 Safari/...
          │               │             │       │         └ b'{"key": "\\u610f\\u5927\\u5229\\u4f5b\\u7f57\\u4f26\\u8428\\u57ce\\u5e02\\u666f\\u89c2\\u58ee\\u4e3d", "page": 1, "limit": ...
          │               │             │       └ '/search-platform/front/search'
          │               │             └ 'POST'
          │               └ <urllib3.connection.HTTPConnection object at 0x7f914810c430>
          └ <class 'urllib3.connection.HTTPConnection'>
  File "/usr/lib/python3.8/http/client.py", line 1256, in request
    self._send_request(method, url, body, headers, encode_chunked)
    │    │             │       │    │     │        └ False
    │    │             │       │    │     └ {'User-Agent': 'Mozilla/5.0 (Windows NT 10.0; Win64; x64) AppleWebKit/537.36 (KHTML, like Gecko) Chrome/101.0.4951.54 Safari/...
    │    │             │       │    └ b'{"key": "\\u610f\\u5927\\u5229\\u4f5b\\u7f57\\u4f26\\u8428\\u57ce\\u5e02\\u666f\\u89c2\\u58ee\\u4e3d", "page": 1, "limit": ...
    │    │             │       └ '/search-platform/front/search'
    │    │             └ 'POST'
    │    └ <function HTTPConnection._send_request at 0x7f926be50280>
    └ <urllib3.connection.HTTPConnection object at 0x7f914810c430>
  File "/usr/lib/python3.8/http/client.py", line 1302, in _send_request
    self.endheaders(body, encode_chunked=encode_chunked)
    │    │          │                    └ False
    │    │          └ b'{"key": "\\u610f\\u5927\\u5229\\u4f5b\\u7f57\\u4f26\\u8428\\u57ce\\u5e02\\u666f\\u89c2\\u58ee\\u4e3d", "page": 1, "limit": ...
    │    └ <function HTTPConnection.endheaders at 0x7f926be50160>
    └ <urllib3.connection.HTTPConnection object at 0x7f914810c430>
  File "/usr/lib/python3.8/http/client.py", line 1251, in endheaders
    self._send_output(message_body, encode_chunked=encode_chunked)
    │    │            │                            └ False
    │    │            └ b'{"key": "\\u610f\\u5927\\u5229\\u4f5b\\u7f57\\u4f26\\u8428\\u57ce\\u5e02\\u666f\\u89c2\\u58ee\\u4e3d", "page": 1, "limit": ...
    │    └ <function HTTPConnection._send_output at 0x7f926beb7d30>
    └ <urllib3.connection.HTTPConnection object at 0x7f914810c430>
  File "/usr/lib/python3.8/http/client.py", line 1011, in _send_output
    self.send(msg)
    │    │    └ b'POST /search-platform/front/search HTTP/1.1\r\nHost: search.people.cn\r\nUser-Agent: Mozilla/5.0 (Windows NT 10.0; Win64; x...
    │    └ <function HTTPConnection.send at 0x7f926beb7b80>
    └ <urllib3.connection.HTTPConnection object at 0x7f914810c430>
  File "/usr/lib/python3.8/http/client.py", line 951, in send
    self.connect()
    │    └ <function HTTPConnection.connect at 0x7f92585b0dc0>
    └ <urllib3.connection.HTTPConnection object at 0x7f914810c430>
  File "/home/chase/.local/lib/python3.8/site-packages/urllib3/connection.py", line 205, in connect
    conn = self._new_conn()
           │    └ <function HTTPConnection._new_conn at 0x7f92585b0c10>
           └ <urllib3.connection.HTTPConnection object at 0x7f914810c430>
  File "/home/chase/.local/lib/python3.8/site-packages/urllib3/connection.py", line 186, in _new_conn
    raise NewConnectionError(
          └ <class 'urllib3.exceptions.NewConnectionError'>

urllib3.exceptions.NewConnectionError: <urllib3.connection.HTTPConnection object at 0x7f914810c430>: Failed to establish a new connection: [Errno 111] Connection refused


During handling of the above exception, another exception occurred:


Traceback (most recent call last):

  File "/home/chase/.local/lib/python3.8/site-packages/requests/adapters.py", line 439, in send
    resp = conn.urlopen(
           │    └ <function HTTPConnectionPool.urlopen at 0x7f92585c0820>
           └ <urllib3.connectionpool.HTTPConnectionPool object at 0x7f91601af130>
  File "/home/chase/.local/lib/python3.8/site-packages/urllib3/connectionpool.py", line 755, in urlopen
    retries = retries.increment(
              │       └ <function Retry.increment at 0x7f9258608b80>
              └ Retry(total=0, connect=None, read=False, redirect=None, status=None)
  File "/home/chase/.local/lib/python3.8/site-packages/urllib3/util/retry.py", line 574, in increment
    raise MaxRetryError(_pool, url, error or ResponseError(cause))
          │             │      │    │        │             └ 'unknown'
          │             │      │    │        └ <class 'urllib3.exceptions.ResponseError'>
          │             │      │    └ NewConnectionError('<urllib3.connection.HTTPConnection object at 0x7f914810c430>: Failed to establish a new connection: [Errn...
          │             │      └ '/search-platform/front/search'
          │             └ <urllib3.connectionpool.HTTPConnectionPool object at 0x7f91601af130>
          └ <class 'urllib3.exceptions.MaxRetryError'>

urllib3.exceptions.MaxRetryError: HTTPConnectionPool(host='search.people.cn', port=80): Max retries exceeded with url: /search-platform/front/search (Caused by NewConnectionError('<urllib3.connection.HTTPConnection object at 0x7f914810c430>: Failed to establish a new connection: [Errno 111] Connection refused'))


During handling of the above exception, another exception occurred:


Traceback (most recent call last):

  File "/usr/lib/python3.8/threading.py", line 890, in _bootstrap
    self._bootstrap_inner()
    │    └ <function Thread._bootstrap_inner at 0x7f927a614a60>
    └ <Thread(Thread-60, started daemon 140261401286400)>
  File "/usr/lib/python3.8/threading.py", line 932, in _bootstrap_inner
    self.run()
    │    └ <function Thread.run at 0x7f927a614790>
    └ <Thread(Thread-60, started daemon 140261401286400)>
  File "/usr/lib/python3.8/threading.py", line 870, in run
    self._target(*self._args, **self._kwargs)
    │    │        │    │        │    └ {}
    │    │        │    │        └ <Thread(Thread-60, started daemon 140261401286400)>
    │    │        │    └ ('ProjectManager.run_func_by_thread',)
    │    │        └ <Thread(Thread-60, started daemon 140261401286400)>
    │    └ <bound method ProjectManager.get_request_from_keywords_hot of <monitor.projectManager.ProjectManager object at 0x7f9162af4700>>
    └ <Thread(Thread-60, started daemon 140261401286400)>

  File "/home/users/Scy/yuqing/spider/monitor/projectManager.py", line 795, in get_request_from_keywords_hot
    self.search_spider_manager.crawl_by_keyword(
    │    │                     └ <function SearchSpidersManager.crawl_by_keyword at 0x7f9162b00040>
    │    └ <monitor.spiderManager.SearchSpidersManager object at 0x7f916270f0d0>
    └ <monitor.projectManager.ProjectManager object at 0x7f9162af4700>

  File "/home/users/Scy/yuqing/spider/monitor/spiderManager.py", line 118, in crawl_by_keyword
    self.crawl_by_keyword_signal_platform(project_names, platform, keyword, crawl_time, project_times)
    │    │                                │              │         │        │           └ {'default': <monitor.TimeSection object at 0x7f91628317f0>}
    │    │                                │              │         │        └ <monitor.TimeSection object at 0x7f9160459ee0>
    │    │                                │              │         └ '意大利佛罗伦萨城市景观壮丽'
    │    │                                │              └ '人民网'
    │    │                                └ ['default']
    │    └ <function SearchSpidersManager.crawl_by_keyword_signal_platform at 0x7f9162b000d0>
    └ <monitor.spiderManager.SearchSpidersManager object at 0x7f916270f0d0>

  File "/home/users/Scy/yuqing/spider/monitor/spiderManager.py", line 134, in crawl_by_keyword_signal_platform
    requests = self.get_request_from_keyword(platform, keyword, **crawl_time.to_dict())
               │    │                        │         │          │          └ <function TimeSection.to_dict at 0x7f925aaa8550>
               │    │                        │         │          └ <monitor.TimeSection object at 0x7f9160459ee0>
               │    │                        │         └ '意大利佛罗伦萨城市景观壮丽'
               │    │                        └ '人民网'
               │    └ <function SearchSpidersManager.get_request_from_keyword at 0x7f9162b001f0>
               └ <monitor.spiderManager.SearchSpidersManager object at 0x7f916270f0d0>

  File "/home/users/Scy/yuqing/spider/monitor/spiderManager.py", line 191, in get_request_from_keyword
    for request in self.spiders[platform].get_request_from_keyword(headers, search_url, keyword, content_url,
                   │    │       │                                  │        │           │        └ <string.Template object at 0x7f9124206310>
                   │    │       │                                  │        │           └ '意大利佛罗伦萨城市景观壮丽'
                   │    │       │                                  │        └ <string.Template object at 0x7f9104235880>
                   │    │       │                                  └ {'Accept': 'application/json, text/plain, */*', 'Accept-Language': 'zh-CN,zh;q=0.9', 'Connection': 'keep-alive', 'Origin': 'h...
                   │    │       └ '人民网'
                   │    └ {'凤凰网': <monitor.searchSpiders.ifeng.Ifeng object at 0x7f916270f220>, '头条': <monitor.searchSpiders.toutiao.Toutiao object at ...
                   └ <monitor.spiderManager.SearchSpidersManager object at 0x7f916270f0d0>

> File "/home/users/Scy/yuqing/spider/monitor/searchSpiders/people.py", line 28, in get_request_from_keyword
    response = requests.post(search_url.substitute(), json=data, headers=headers)
               │        │    │          │                  │             └ {'Accept': 'application/json, text/plain, */*', 'Accept-Language': 'zh-CN,zh;q=0.9', 'Connection': 'keep-alive', 'Origin': 'h...
               │        │    │          │                  └ {'key': '意大利佛罗伦萨城市景观壮丽', 'page': 1, 'limit': 10, 'hasTitle': True, 'hasContent': True, 'isFuzzy': True, 'type': 0, 'sortType'...
               │        │    │          └ <function Template.substitute at 0x7f927a5fd0d0>
               │        │    └ <string.Template object at 0x7f9104235880>
               │        └ <function post at 0x7f92583e73a0>
               └ <module 'requests' from '/home/chase/.local/lib/python3.8/site-packages/requests/__init__.py'>

  File "/home/chase/.local/lib/python3.8/site-packages/requests/api.py", line 117, in post
    return request('post', url, data=data, json=json, **kwargs)
           │               │         │          │       └ {'headers': {'Accept': 'application/json, text/plain, */*', 'Accept-Language': 'zh-CN,zh;q=0.9', 'Connection': 'keep-alive', ...
           │               │         │          └ {'key': '意大利佛罗伦萨城市景观壮丽', 'page': 1, 'limit': 10, 'hasTitle': True, 'hasContent': True, 'isFuzzy': True, 'type': 0, 'sortType'...
           │               │         └ None
           │               └ 'http://search.people.cn/search-platform/front/search'
           └ <function request at 0x7f9258455040>
  File "/home/chase/.local/lib/python3.8/site-packages/requests/api.py", line 61, in request
    return session.request(method=method, url=url, **kwargs)
           │       │              │           │      └ {'data': None, 'json': {'key': '意大利佛罗伦萨城市景观壮丽', 'page': 1, 'limit': 10, 'hasTitle': True, 'hasContent': True, 'isFuzzy': True...
           │       │              │           └ 'http://search.people.cn/search-platform/front/search'
           │       │              └ 'post'
           │       └ <function Session.request at 0x7f92583e6940>
           └ <requests.sessions.Session object at 0x7f91243ef340>
  File "/home/chase/.local/lib/python3.8/site-packages/requests/sessions.py", line 542, in request
    resp = self.send(prep, **send_kwargs)
           │    │    │       └ {'timeout': None, 'allow_redirects': True, 'verify': True, 'proxies': OrderedDict(), 'stream': False, 'cert': None}
           │    │    └ <PreparedRequest [POST]>
           │    └ <function Session.send at 0x7f92583e6dc0>
           └ <requests.sessions.Session object at 0x7f91243ef340>
  File "/home/chase/.local/lib/python3.8/site-packages/requests/sessions.py", line 655, in send
    r = adapter.send(request, **kwargs)
        │       │    │          └ {'timeout': None, 'verify': True, 'proxies': OrderedDict(), 'stream': False, 'cert': None}
        │       │    └ <PreparedRequest [POST]>
        │       └ <function HTTPAdapter.send at 0x7f92583e6280>
        └ <requests.adapters.HTTPAdapter object at 0x7f91601af880>
  File "/home/chase/.local/lib/python3.8/site-packages/requests/adapters.py", line 516, in send
    raise ConnectionError(e, request=request)
          │                          └ <PreparedRequest [POST]>
          └ <class 'requests.exceptions.ConnectionError'>

requests.exceptions.ConnectionError: HTTPConnectionPool(host='search.people.cn', port=80): Max retries exceeded with url: /search-platform/front/search (Caused by NewConnectionError('<urllib3.connection.HTTPConnection object at 0x7f914810c430>: Failed to establish a new connection: [Errno 111] Connection refused'))
2022-05-12 15:51:37.862 | ERROR    | monitor.searchSpiders.qinagguoLT:get_request_from_keyword:27 - E 强国论坛错误HTTPConnectionPool(host='bbs1.people.com.cn', port=80): Max retries exceeded with url: /board/1.html (Caused by NewConnectionError('<urllib3.connection.HTTPConnection object at 0x7f9124666ca0>: Failed to establish a new connection: [Errno 111] Connection refused'))
Traceback (most recent call last):

  File "/home/chase/.local/lib/python3.8/site-packages/urllib3/connection.py", line 174, in _new_conn
    conn = connection.create_connection(
           │          └ <function create_connection at 0x7f92585fd1f0>
           └ <module 'urllib3.util.connection' from '/home/chase/.local/lib/python3.8/site-packages/urllib3/util/connection.py'>
  File "/home/chase/.local/lib/python3.8/site-packages/urllib3/util/connection.py", line 96, in create_connection
    raise err
          └ ConnectionRefusedError(111, 'Connection refused')
  File "/home/chase/.local/lib/python3.8/site-packages/urllib3/util/connection.py", line 86, in create_connection
    sock.connect(sa)
    │            └ ('118.212.233.223', 80)
    └ None

ConnectionRefusedError: [Errno 111] Connection refused


During handling of the above exception, another exception occurred:


Traceback (most recent call last):

  File "/home/chase/.local/lib/python3.8/site-packages/urllib3/connectionpool.py", line 699, in urlopen
    httplib_response = self._make_request(
                       │    └ <function HTTPConnectionPool._make_request at 0x7f92585c05e0>
                       └ <urllib3.connectionpool.HTTPConnectionPool object at 0x7f91601856d0>
  File "/home/chase/.local/lib/python3.8/site-packages/urllib3/connectionpool.py", line 394, in _make_request
    conn.request(method, url, **httplib_request_kw)
    │    │       │       │      └ {'body': None, 'headers': {'User-Agent': 'Mozilla/5.0 (X11; Linux x86_64) AppleWebKit/537.36 (KHTML, like Gecko) Chrome/93.0....
    │    │       │       └ '/board/1.html'
    │    │       └ 'GET'
    │    └ <function HTTPConnection.request at 0x7f92585b0f70>
    └ <urllib3.connection.HTTPConnection object at 0x7f9124666ca0>
  File "/home/chase/.local/lib/python3.8/site-packages/urllib3/connection.py", line 239, in request
    super(HTTPConnection, self).request(method, url, body=body, headers=headers)
          │               │             │       │         │             └ {'User-Agent': 'Mozilla/5.0 (X11; Linux x86_64) AppleWebKit/537.36 (KHTML, like Gecko) Chrome/93.0.4577.63 Safari/537.36', 'A...
          │               │             │       │         └ None
          │               │             │       └ '/board/1.html'
          │               │             └ 'GET'
          │               └ <urllib3.connection.HTTPConnection object at 0x7f9124666ca0>
          └ <class 'urllib3.connection.HTTPConnection'>
  File "/usr/lib/python3.8/http/client.py", line 1256, in request
    self._send_request(method, url, body, headers, encode_chunked)
    │    │             │       │    │     │        └ False
    │    │             │       │    │     └ {'User-Agent': 'Mozilla/5.0 (X11; Linux x86_64) AppleWebKit/537.36 (KHTML, like Gecko) Chrome/93.0.4577.63 Safari/537.36', 'A...
    │    │             │       │    └ None
    │    │             │       └ '/board/1.html'
    │    │             └ 'GET'
    │    └ <function HTTPConnection._send_request at 0x7f926be50280>
    └ <urllib3.connection.HTTPConnection object at 0x7f9124666ca0>
  File "/usr/lib/python3.8/http/client.py", line 1302, in _send_request
    self.endheaders(body, encode_chunked=encode_chunked)
    │    │          │                    └ False
    │    │          └ None
    │    └ <function HTTPConnection.endheaders at 0x7f926be50160>
    └ <urllib3.connection.HTTPConnection object at 0x7f9124666ca0>
  File "/usr/lib/python3.8/http/client.py", line 1251, in endheaders
    self._send_output(message_body, encode_chunked=encode_chunked)
    │    │            │                            └ False
    │    │            └ None
    │    └ <function HTTPConnection._send_output at 0x7f926beb7d30>
    └ <urllib3.connection.HTTPConnection object at 0x7f9124666ca0>
  File "/usr/lib/python3.8/http/client.py", line 1011, in _send_output
    self.send(msg)
    │    │    └ b'GET /board/1.html HTTP/1.1\r\nHost: bbs1.people.com.cn\r\nUser-Agent: Mozilla/5.0 (X11; Linux x86_64) AppleWebKit/537.36 (K...
    │    └ <function HTTPConnection.send at 0x7f926beb7b80>
    └ <urllib3.connection.HTTPConnection object at 0x7f9124666ca0>
  File "/usr/lib/python3.8/http/client.py", line 951, in send
    self.connect()
    │    └ <function HTTPConnection.connect at 0x7f92585b0dc0>
    └ <urllib3.connection.HTTPConnection object at 0x7f9124666ca0>
  File "/home/chase/.local/lib/python3.8/site-packages/urllib3/connection.py", line 205, in connect
    conn = self._new_conn()
           │    └ <function HTTPConnection._new_conn at 0x7f92585b0c10>
           └ <urllib3.connection.HTTPConnection object at 0x7f9124666ca0>
  File "/home/chase/.local/lib/python3.8/site-packages/urllib3/connection.py", line 186, in _new_conn
    raise NewConnectionError(
          └ <class 'urllib3.exceptions.NewConnectionError'>

urllib3.exceptions.NewConnectionError: <urllib3.connection.HTTPConnection object at 0x7f9124666ca0>: Failed to establish a new connection: [Errno 111] Connection refused


During handling of the above exception, another exception occurred:


Traceback (most recent call last):

  File "/home/chase/.local/lib/python3.8/site-packages/requests/adapters.py", line 439, in send
    resp = conn.urlopen(
           │    └ <function HTTPConnectionPool.urlopen at 0x7f92585c0820>
           └ <urllib3.connectionpool.HTTPConnectionPool object at 0x7f91601856d0>
  File "/home/chase/.local/lib/python3.8/site-packages/urllib3/connectionpool.py", line 755, in urlopen
    retries = retries.increment(
              │       └ <function Retry.increment at 0x7f9258608b80>
              └ Retry(total=0, connect=None, read=False, redirect=None, status=None)
  File "/home/chase/.local/lib/python3.8/site-packages/urllib3/util/retry.py", line 574, in increment
    raise MaxRetryError(_pool, url, error or ResponseError(cause))
          │             │      │    │        │             └ 'unknown'
          │             │      │    │        └ <class 'urllib3.exceptions.ResponseError'>
          │             │      │    └ NewConnectionError('<urllib3.connection.HTTPConnection object at 0x7f9124666ca0>: Failed to establish a new connection: [Errn...
          │             │      └ '/board/1.html'
          │             └ <urllib3.connectionpool.HTTPConnectionPool object at 0x7f91601856d0>
          └ <class 'urllib3.exceptions.MaxRetryError'>

urllib3.exceptions.MaxRetryError: HTTPConnectionPool(host='bbs1.people.com.cn', port=80): Max retries exceeded with url: /board/1.html (Caused by NewConnectionError('<urllib3.connection.HTTPConnection object at 0x7f9124666ca0>: Failed to establish a new connection: [Errno 111] Connection refused'))


During handling of the above exception, another exception occurred:


Traceback (most recent call last):

  File "/usr/lib/python3.8/threading.py", line 890, in _bootstrap
    self._bootstrap_inner()
    │    └ <function Thread._bootstrap_inner at 0x7f927a614a60>
    └ <Thread(Thread-42, started daemon 140261980088064)>
  File "/usr/lib/python3.8/threading.py", line 932, in _bootstrap_inner
    self.run()
    │    └ <function Thread.run at 0x7f927a614790>
    └ <Thread(Thread-42, started daemon 140261980088064)>
  File "/usr/lib/python3.8/threading.py", line 870, in run
    self._target(*self._args, **self._kwargs)
    │    │        │    │        │    └ {}
    │    │        │    │        └ <Thread(Thread-42, started daemon 140261980088064)>
    │    │        │    └ ('ProjectManager.run_func_by_thread',)
    │    │        └ <Thread(Thread-42, started daemon 140261980088064)>
    │    └ <bound method ProjectManager.get_request_from_keywords_hot of <monitor.projectManager.ProjectManager object at 0x7f9162af4700>>
    └ <Thread(Thread-42, started daemon 140261980088064)>

  File "/home/users/Scy/yuqing/spider/monitor/projectManager.py", line 795, in get_request_from_keywords_hot
    self.search_spider_manager.crawl_by_keyword(
    │    │                     └ <function SearchSpidersManager.crawl_by_keyword at 0x7f9162b00040>
    │    └ <monitor.spiderManager.SearchSpidersManager object at 0x7f916270f0d0>
    └ <monitor.projectManager.ProjectManager object at 0x7f9162af4700>

  File "/home/users/Scy/yuqing/spider/monitor/spiderManager.py", line 118, in crawl_by_keyword
    self.crawl_by_keyword_signal_platform(project_names, platform, keyword, crawl_time, project_times)
    │    │                                │              │         │        │           └ {'default': <monitor.TimeSection object at 0x7f91628317f0>}
    │    │                                │              │         │        └ <monitor.TimeSection object at 0x7f91603ec070>
    │    │                                │              │         └ '华南有持续性强降雨 多地气象部门强化应急联动全力防范应对强降雨'
    │    │                                │              └ '强国论坛'
    │    │                                └ ['default']
    │    └ <function SearchSpidersManager.crawl_by_keyword_signal_platform at 0x7f9162b000d0>
    └ <monitor.spiderManager.SearchSpidersManager object at 0x7f916270f0d0>

  File "/home/users/Scy/yuqing/spider/monitor/spiderManager.py", line 134, in crawl_by_keyword_signal_platform
    requests = self.get_request_from_keyword(platform, keyword, **crawl_time.to_dict())
               │    │                        │         │          │          └ <function TimeSection.to_dict at 0x7f925aaa8550>
               │    │                        │         │          └ <monitor.TimeSection object at 0x7f91603ec070>
               │    │                        │         └ '华南有持续性强降雨 多地气象部门强化应急联动全力防范应对强降雨'
               │    │                        └ '强国论坛'
               │    └ <function SearchSpidersManager.get_request_from_keyword at 0x7f9162b001f0>
               └ <monitor.spiderManager.SearchSpidersManager object at 0x7f916270f0d0>

  File "/home/users/Scy/yuqing/spider/monitor/spiderManager.py", line 191, in get_request_from_keyword
    for request in self.spiders[platform].get_request_from_keyword(headers, search_url, keyword, content_url,
                   │    │       │                                  │        │           │        └ <string.Template object at 0x7f91601f9670>
                   │    │       │                                  │        │           └ '华南有持续性强降雨 多地气象部门强化应急联动全力防范应对强降雨'
                   │    │       │                                  │        └ <string.Template object at 0x7f91601f9b50>
                   │    │       │                                  └ {'Connection': 'keep-alive', 'Cache-Control': 'max-age=0', 'Upgrade-Insecure-Requests': '1', 'User-Agent': 'Mozilla/5.0 (X11;...
                   │    │       └ '强国论坛'
                   │    └ {'凤凰网': <monitor.searchSpiders.ifeng.Ifeng object at 0x7f916270f220>, '头条': <monitor.searchSpiders.toutiao.Toutiao object at ...
                   └ <monitor.spiderManager.SearchSpidersManager object at 0x7f916270f0d0>

> File "/home/users/Scy/yuqing/spider/monitor/searchSpiders/qinagguoLT.py", line 18, in get_request_from_keyword
    response = requests.get(search_url.substitute(), headers=headers)
               │        │   │          │                     └ {'Connection': 'keep-alive', 'Cache-Control': 'max-age=0', 'Upgrade-Insecure-Requests': '1', 'User-Agent': 'Mozilla/5.0 (X11;...
               │        │   │          └ <function Template.substitute at 0x7f927a5fd0d0>
               │        │   └ <string.Template object at 0x7f91601f9b50>
               │        └ <function get at 0x7f92583e71f0>
               └ <module 'requests' from '/home/chase/.local/lib/python3.8/site-packages/requests/__init__.py'>

  File "/home/chase/.local/lib/python3.8/site-packages/requests/api.py", line 75, in get
    return request('get', url, params=params, **kwargs)
           │              │           │         └ {'headers': {'Connection': 'keep-alive', 'Cache-Control': 'max-age=0', 'Upgrade-Insecure-Requests': '1', 'User-Agent': 'Mozil...
           │              │           └ None
           │              └ 'http://bbs1.people.com.cn/board/1.html'
           └ <function request at 0x7f9258455040>
  File "/home/chase/.local/lib/python3.8/site-packages/requests/api.py", line 61, in request
    return session.request(method=method, url=url, **kwargs)
           │       │              │           │      └ {'params': None, 'headers': {'Connection': 'keep-alive', 'Cache-Control': 'max-age=0', 'Upgrade-Insecure-Requests': '1', 'Use...
           │       │              │           └ 'http://bbs1.people.com.cn/board/1.html'
           │       │              └ 'get'
           │       └ <function Session.request at 0x7f92583e6940>
           └ <requests.sessions.Session object at 0x7f9253efecd0>
  File "/home/chase/.local/lib/python3.8/site-packages/requests/sessions.py", line 542, in request
    resp = self.send(prep, **send_kwargs)
           │    │    │       └ {'timeout': None, 'allow_redirects': True, 'verify': True, 'proxies': OrderedDict(), 'stream': False, 'cert': None}
           │    │    └ <PreparedRequest [GET]>
           │    └ <function Session.send at 0x7f92583e6dc0>
           └ <requests.sessions.Session object at 0x7f9253efecd0>
  File "/home/chase/.local/lib/python3.8/site-packages/requests/sessions.py", line 655, in send
    r = adapter.send(request, **kwargs)
        │       │    │          └ {'timeout': None, 'verify': True, 'proxies': OrderedDict(), 'stream': False, 'cert': None}
        │       │    └ <PreparedRequest [GET]>
        │       └ <function HTTPAdapter.send at 0x7f92583e6280>
        └ <requests.adapters.HTTPAdapter object at 0x7f91601f9b80>
  File "/home/chase/.local/lib/python3.8/site-packages/requests/adapters.py", line 516, in send
    raise ConnectionError(e, request=request)
          │                          └ <PreparedRequest [GET]>
          └ <class 'requests.exceptions.ConnectionError'>

requests.exceptions.ConnectionError: HTTPConnectionPool(host='bbs1.people.com.cn', port=80): Max retries exceeded with url: /board/1.html (Caused by NewConnectionError('<urllib3.connection.HTTPConnection object at 0x7f9124666ca0>: Failed to establish a new connection: [Errno 111] Connection refused'))
2022-05-12 15:51:38.023 | ERROR    | monitor.searchSpiders.qinagguoLT:get_request_from_keyword:27 - E 强国论坛错误HTTPConnectionPool(host='bbs1.people.com.cn', port=80): Max retries exceeded with url: /board/1.html (Caused by NewConnectionError('<urllib3.connection.HTTPConnection object at 0x7f9124344dc0>: Failed to establish a new connection: [Errno 111] Connection refused'))
Traceback (most recent call last):

  File "/home/chase/.local/lib/python3.8/site-packages/urllib3/connection.py", line 174, in _new_conn
    conn = connection.create_connection(
           │          └ <function create_connection at 0x7f92585fd1f0>
           └ <module 'urllib3.util.connection' from '/home/chase/.local/lib/python3.8/site-packages/urllib3/util/connection.py'>
  File "/home/chase/.local/lib/python3.8/site-packages/urllib3/util/connection.py", line 96, in create_connection
    raise err
          └ ConnectionRefusedError(111, 'Connection refused')
  File "/home/chase/.local/lib/python3.8/site-packages/urllib3/util/connection.py", line 86, in create_connection
    sock.connect(sa)
    │            └ ('118.212.233.223', 80)
    └ None

ConnectionRefusedError: [Errno 111] Connection refused


During handling of the above exception, another exception occurred:


Traceback (most recent call last):

  File "/home/chase/.local/lib/python3.8/site-packages/urllib3/connectionpool.py", line 699, in urlopen
    httplib_response = self._make_request(
                       │    └ <function HTTPConnectionPool._make_request at 0x7f92585c05e0>
                       └ <urllib3.connectionpool.HTTPConnectionPool object at 0x7f91247aea60>
  File "/home/chase/.local/lib/python3.8/site-packages/urllib3/connectionpool.py", line 394, in _make_request
    conn.request(method, url, **httplib_request_kw)
    │    │       │       │      └ {'body': None, 'headers': {'User-Agent': 'Mozilla/5.0 (X11; Linux x86_64) AppleWebKit/537.36 (KHTML, like Gecko) Chrome/93.0....
    │    │       │       └ '/board/1.html'
    │    │       └ 'GET'
    │    └ <function HTTPConnection.request at 0x7f92585b0f70>
    └ <urllib3.connection.HTTPConnection object at 0x7f9124344dc0>
  File "/home/chase/.local/lib/python3.8/site-packages/urllib3/connection.py", line 239, in request
    super(HTTPConnection, self).request(method, url, body=body, headers=headers)
          │               │             │       │         │             └ {'User-Agent': 'Mozilla/5.0 (X11; Linux x86_64) AppleWebKit/537.36 (KHTML, like Gecko) Chrome/93.0.4577.63 Safari/537.36', 'A...
          │               │             │       │         └ None
          │               │             │       └ '/board/1.html'
          │               │             └ 'GET'
          │               └ <urllib3.connection.HTTPConnection object at 0x7f9124344dc0>
          └ <class 'urllib3.connection.HTTPConnection'>
  File "/usr/lib/python3.8/http/client.py", line 1256, in request
    self._send_request(method, url, body, headers, encode_chunked)
    │    │             │       │    │     │        └ False
    │    │             │       │    │     └ {'User-Agent': 'Mozilla/5.0 (X11; Linux x86_64) AppleWebKit/537.36 (KHTML, like Gecko) Chrome/93.0.4577.63 Safari/537.36', 'A...
    │    │             │       │    └ None
    │    │             │       └ '/board/1.html'
    │    │             └ 'GET'
    │    └ <function HTTPConnection._send_request at 0x7f926be50280>
    └ <urllib3.connection.HTTPConnection object at 0x7f9124344dc0>
  File "/usr/lib/python3.8/http/client.py", line 1302, in _send_request
    self.endheaders(body, encode_chunked=encode_chunked)
    │    │          │                    └ False
    │    │          └ None
    │    └ <function HTTPConnection.endheaders at 0x7f926be50160>
    └ <urllib3.connection.HTTPConnection object at 0x7f9124344dc0>
  File "/usr/lib/python3.8/http/client.py", line 1251, in endheaders
    self._send_output(message_body, encode_chunked=encode_chunked)
    │    │            │                            └ False
    │    │            └ None
    │    └ <function HTTPConnection._send_output at 0x7f926beb7d30>
    └ <urllib3.connection.HTTPConnection object at 0x7f9124344dc0>
  File "/usr/lib/python3.8/http/client.py", line 1011, in _send_output
    self.send(msg)
    │    │    └ b'GET /board/1.html HTTP/1.1\r\nHost: bbs1.people.com.cn\r\nUser-Agent: Mozilla/5.0 (X11; Linux x86_64) AppleWebKit/537.36 (K...
    │    └ <function HTTPConnection.send at 0x7f926beb7b80>
    └ <urllib3.connection.HTTPConnection object at 0x7f9124344dc0>
  File "/usr/lib/python3.8/http/client.py", line 951, in send
    self.connect()
    │    └ <function HTTPConnection.connect at 0x7f92585b0dc0>
    └ <urllib3.connection.HTTPConnection object at 0x7f9124344dc0>
  File "/home/chase/.local/lib/python3.8/site-packages/urllib3/connection.py", line 205, in connect
    conn = self._new_conn()
           │    └ <function HTTPConnection._new_conn at 0x7f92585b0c10>
           └ <urllib3.connection.HTTPConnection object at 0x7f9124344dc0>
  File "/home/chase/.local/lib/python3.8/site-packages/urllib3/connection.py", line 186, in _new_conn
    raise NewConnectionError(
          └ <class 'urllib3.exceptions.NewConnectionError'>

urllib3.exceptions.NewConnectionError: <urllib3.connection.HTTPConnection object at 0x7f9124344dc0>: Failed to establish a new connection: [Errno 111] Connection refused


During handling of the above exception, another exception occurred:


Traceback (most recent call last):

  File "/home/chase/.local/lib/python3.8/site-packages/requests/adapters.py", line 439, in send
    resp = conn.urlopen(
           │    └ <function HTTPConnectionPool.urlopen at 0x7f92585c0820>
           └ <urllib3.connectionpool.HTTPConnectionPool object at 0x7f91247aea60>
  File "/home/chase/.local/lib/python3.8/site-packages/urllib3/connectionpool.py", line 755, in urlopen
    retries = retries.increment(
              │       └ <function Retry.increment at 0x7f9258608b80>
              └ Retry(total=0, connect=None, read=False, redirect=None, status=None)
  File "/home/chase/.local/lib/python3.8/site-packages/urllib3/util/retry.py", line 574, in increment
    raise MaxRetryError(_pool, url, error or ResponseError(cause))
          │             │      │    │        │             └ 'unknown'
          │             │      │    │        └ <class 'urllib3.exceptions.ResponseError'>
          │             │      │    └ NewConnectionError('<urllib3.connection.HTTPConnection object at 0x7f9124344dc0>: Failed to establish a new connection: [Errn...
          │             │      └ '/board/1.html'
          │             └ <urllib3.connectionpool.HTTPConnectionPool object at 0x7f91247aea60>
          └ <class 'urllib3.exceptions.MaxRetryError'>

urllib3.exceptions.MaxRetryError: HTTPConnectionPool(host='bbs1.people.com.cn', port=80): Max retries exceeded with url: /board/1.html (Caused by NewConnectionError('<urllib3.connection.HTTPConnection object at 0x7f9124344dc0>: Failed to establish a new connection: [Errno 111] Connection refused'))


During handling of the above exception, another exception occurred:


Traceback (most recent call last):

  File "/usr/lib/python3.8/threading.py", line 890, in _bootstrap
    self._bootstrap_inner()
    │    └ <function Thread._bootstrap_inner at 0x7f927a614a60>
    └ <Thread(Thread-78, started daemon 140261376108288)>
  File "/usr/lib/python3.8/threading.py", line 932, in _bootstrap_inner
    self.run()
    │    └ <function Thread.run at 0x7f927a614790>
    └ <Thread(Thread-78, started daemon 140261376108288)>
  File "/usr/lib/python3.8/threading.py", line 870, in run
    self._target(*self._args, **self._kwargs)
    │    │        │    │        │    └ {}
    │    │        │    │        └ <Thread(Thread-78, started daemon 140261376108288)>
    │    │        │    └ ('ProjectManager.run_func_by_thread',)
    │    │        └ <Thread(Thread-78, started daemon 140261376108288)>
    │    └ <bound method ProjectManager.get_request_from_keywords_hot of <monitor.projectManager.ProjectManager object at 0x7f9162af4700>>
    └ <Thread(Thread-78, started daemon 140261376108288)>

  File "/home/users/Scy/yuqing/spider/monitor/projectManager.py", line 795, in get_request_from_keywords_hot
    self.search_spider_manager.crawl_by_keyword(
    │    │                     └ <function SearchSpidersManager.crawl_by_keyword at 0x7f9162b00040>
    │    └ <monitor.spiderManager.SearchSpidersManager object at 0x7f916270f0d0>
    └ <monitor.projectManager.ProjectManager object at 0x7f9162af4700>

  File "/home/users/Scy/yuqing/spider/monitor/spiderManager.py", line 118, in crawl_by_keyword
    self.crawl_by_keyword_signal_platform(project_names, platform, keyword, crawl_time, project_times)
    │    │                                │              │         │        │           └ {'default': <monitor.TimeSection object at 0x7f91628317f0>}
    │    │                                │              │         │        └ <monitor.TimeSection object at 0x7f91601652e0>
    │    │                                │              │         └ '非洲极端组织武器来源引关注'
    │    │                                │              └ '强国论坛'
    │    │                                └ ['default']
    │    └ <function SearchSpidersManager.crawl_by_keyword_signal_platform at 0x7f9162b000d0>
    └ <monitor.spiderManager.SearchSpidersManager object at 0x7f916270f0d0>

  File "/home/users/Scy/yuqing/spider/monitor/spiderManager.py", line 134, in crawl_by_keyword_signal_platform
    requests = self.get_request_from_keyword(platform, keyword, **crawl_time.to_dict())
               │    │                        │         │          │          └ <function TimeSection.to_dict at 0x7f925aaa8550>
               │    │                        │         │          └ <monitor.TimeSection object at 0x7f91601652e0>
               │    │                        │         └ '非洲极端组织武器来源引关注'
               │    │                        └ '强国论坛'
               │    └ <function SearchSpidersManager.get_request_from_keyword at 0x7f9162b001f0>
               └ <monitor.spiderManager.SearchSpidersManager object at 0x7f916270f0d0>

  File "/home/users/Scy/yuqing/spider/monitor/spiderManager.py", line 191, in get_request_from_keyword
    for request in self.spiders[platform].get_request_from_keyword(headers, search_url, keyword, content_url,
                   │    │       │                                  │        │           │        └ <string.Template object at 0x7f91240dc3a0>
                   │    │       │                                  │        │           └ '非洲极端组织武器来源引关注'
                   │    │       │                                  │        └ <string.Template object at 0x7f91483db7f0>
                   │    │       │                                  └ {'Connection': 'keep-alive', 'Cache-Control': 'max-age=0', 'Upgrade-Insecure-Requests': '1', 'User-Agent': 'Mozilla/5.0 (X11;...
                   │    │       └ '强国论坛'
                   │    └ {'凤凰网': <monitor.searchSpiders.ifeng.Ifeng object at 0x7f916270f220>, '头条': <monitor.searchSpiders.toutiao.Toutiao object at ...
                   └ <monitor.spiderManager.SearchSpidersManager object at 0x7f916270f0d0>

> File "/home/users/Scy/yuqing/spider/monitor/searchSpiders/qinagguoLT.py", line 18, in get_request_from_keyword
    response = requests.get(search_url.substitute(), headers=headers)
               │        │   │          │                     └ {'Connection': 'keep-alive', 'Cache-Control': 'max-age=0', 'Upgrade-Insecure-Requests': '1', 'User-Agent': 'Mozilla/5.0 (X11;...
               │        │   │          └ <function Template.substitute at 0x7f927a5fd0d0>
               │        │   └ <string.Template object at 0x7f91483db7f0>
               │        └ <function get at 0x7f92583e71f0>
               └ <module 'requests' from '/home/chase/.local/lib/python3.8/site-packages/requests/__init__.py'>

  File "/home/chase/.local/lib/python3.8/site-packages/requests/api.py", line 75, in get
    return request('get', url, params=params, **kwargs)
           │              │           │         └ {'headers': {'Connection': 'keep-alive', 'Cache-Control': 'max-age=0', 'Upgrade-Insecure-Requests': '1', 'User-Agent': 'Mozil...
           │              │           └ None
           │              └ 'http://bbs1.people.com.cn/board/1.html'
           └ <function request at 0x7f9258455040>
  File "/home/chase/.local/lib/python3.8/site-packages/requests/api.py", line 61, in request
    return session.request(method=method, url=url, **kwargs)
           │       │              │           │      └ {'params': None, 'headers': {'Connection': 'keep-alive', 'Cache-Control': 'max-age=0', 'Upgrade-Insecure-Requests': '1', 'Use...
           │       │              │           └ 'http://bbs1.people.com.cn/board/1.html'
           │       │              └ 'get'
           │       └ <function Session.request at 0x7f92583e6940>
           └ <requests.sessions.Session object at 0x7f90e4663970>
  File "/home/chase/.local/lib/python3.8/site-packages/requests/sessions.py", line 542, in request
    resp = self.send(prep, **send_kwargs)
           │    │    │       └ {'timeout': None, 'allow_redirects': True, 'verify': True, 'proxies': OrderedDict(), 'stream': False, 'cert': None}
           │    │    └ <PreparedRequest [GET]>
           │    └ <function Session.send at 0x7f92583e6dc0>
           └ <requests.sessions.Session object at 0x7f90e4663970>
  File "/home/chase/.local/lib/python3.8/site-packages/requests/sessions.py", line 655, in send
    r = adapter.send(request, **kwargs)
        │       │    │          └ {'timeout': None, 'verify': True, 'proxies': OrderedDict(), 'stream': False, 'cert': None}
        │       │    └ <PreparedRequest [GET]>
        │       └ <function HTTPAdapter.send at 0x7f92583e6280>
        └ <requests.adapters.HTTPAdapter object at 0x7f91480dbbe0>
  File "/home/chase/.local/lib/python3.8/site-packages/requests/adapters.py", line 516, in send
    raise ConnectionError(e, request=request)
          │                          └ <PreparedRequest [GET]>
          └ <class 'requests.exceptions.ConnectionError'>

requests.exceptions.ConnectionError: HTTPConnectionPool(host='bbs1.people.com.cn', port=80): Max retries exceeded with url: /board/1.html (Caused by NewConnectionError('<urllib3.connection.HTTPConnection object at 0x7f9124344dc0>: Failed to establish a new connection: [Errno 111] Connection refused'))
2022-05-12 15:51:38.344 | ERROR    | monitor.searchSpiders.people:get_request_from_keyword:45 - E 人民网错误HTTPConnectionPool(host='search.people.cn', port=80): Max retries exceeded with url: /search-platform/front/search (Caused by NewConnectionError('<urllib3.connection.HTTPConnection object at 0x7f9124506040>: Failed to establish a new connection: [Errno 111] Connection refused'))
Traceback (most recent call last):

  File "/home/chase/.local/lib/python3.8/site-packages/urllib3/connection.py", line 174, in _new_conn
    conn = connection.create_connection(
           │          └ <function create_connection at 0x7f92585fd1f0>
           └ <module 'urllib3.util.connection' from '/home/chase/.local/lib/python3.8/site-packages/urllib3/util/connection.py'>
  File "/home/chase/.local/lib/python3.8/site-packages/urllib3/util/connection.py", line 96, in create_connection
    raise err
          └ ConnectionRefusedError(111, 'Connection refused')
  File "/home/chase/.local/lib/python3.8/site-packages/urllib3/util/connection.py", line 86, in create_connection
    sock.connect(sa)
    │            └ ('1.31.128.250', 80)
    └ None

ConnectionRefusedError: [Errno 111] Connection refused


During handling of the above exception, another exception occurred:


Traceback (most recent call last):

  File "/home/chase/.local/lib/python3.8/site-packages/urllib3/connectionpool.py", line 699, in urlopen
    httplib_response = self._make_request(
                       │    └ <function HTTPConnectionPool._make_request at 0x7f92585c05e0>
                       └ <urllib3.connectionpool.HTTPConnectionPool object at 0x7f91601654c0>
  File "/home/chase/.local/lib/python3.8/site-packages/urllib3/connectionpool.py", line 394, in _make_request
    conn.request(method, url, **httplib_request_kw)
    │    │       │       │      └ {'body': b'{"key": "\\u4e1c\\u90e8\\u6218\\u533a\\u7ec4\\u7ec7\\u5175\\u529b\\u5728\\u53f0\\u5c9b\\u4ee5\\u4e1c\\u548c\\u897f...
    │    │       │       └ '/search-platform/front/search'
    │    │       └ 'POST'
    │    └ <function HTTPConnection.request at 0x7f92585b0f70>
    └ <urllib3.connection.HTTPConnection object at 0x7f9124506040>
  File "/home/chase/.local/lib/python3.8/site-packages/urllib3/connection.py", line 239, in request
    super(HTTPConnection, self).request(method, url, body=body, headers=headers)
          │               │             │       │         │             └ {'User-Agent': 'Mozilla/5.0 (Windows NT 10.0; Win64; x64) AppleWebKit/537.36 (KHTML, like Gecko) Chrome/101.0.4951.54 Safari/...
          │               │             │       │         └ b'{"key": "\\u4e1c\\u90e8\\u6218\\u533a\\u7ec4\\u7ec7\\u5175\\u529b\\u5728\\u53f0\\u5c9b\\u4ee5\\u4e1c\\u548c\\u897f\\u5357\\...
          │               │             │       └ '/search-platform/front/search'
          │               │             └ 'POST'
          │               └ <urllib3.connection.HTTPConnection object at 0x7f9124506040>
          └ <class 'urllib3.connection.HTTPConnection'>
  File "/usr/lib/python3.8/http/client.py", line 1256, in request
    self._send_request(method, url, body, headers, encode_chunked)
    │    │             │       │    │     │        └ False
    │    │             │       │    │     └ {'User-Agent': 'Mozilla/5.0 (Windows NT 10.0; Win64; x64) AppleWebKit/537.36 (KHTML, like Gecko) Chrome/101.0.4951.54 Safari/...
    │    │             │       │    └ b'{"key": "\\u4e1c\\u90e8\\u6218\\u533a\\u7ec4\\u7ec7\\u5175\\u529b\\u5728\\u53f0\\u5c9b\\u4ee5\\u4e1c\\u548c\\u897f\\u5357\\...
    │    │             │       └ '/search-platform/front/search'
    │    │             └ 'POST'
    │    └ <function HTTPConnection._send_request at 0x7f926be50280>
    └ <urllib3.connection.HTTPConnection object at 0x7f9124506040>
  File "/usr/lib/python3.8/http/client.py", line 1302, in _send_request
    self.endheaders(body, encode_chunked=encode_chunked)
    │    │          │                    └ False
    │    │          └ b'{"key": "\\u4e1c\\u90e8\\u6218\\u533a\\u7ec4\\u7ec7\\u5175\\u529b\\u5728\\u53f0\\u5c9b\\u4ee5\\u4e1c\\u548c\\u897f\\u5357\\...
    │    └ <function HTTPConnection.endheaders at 0x7f926be50160>
    └ <urllib3.connection.HTTPConnection object at 0x7f9124506040>
  File "/usr/lib/python3.8/http/client.py", line 1251, in endheaders
    self._send_output(message_body, encode_chunked=encode_chunked)
    │    │            │                            └ False
    │    │            └ b'{"key": "\\u4e1c\\u90e8\\u6218\\u533a\\u7ec4\\u7ec7\\u5175\\u529b\\u5728\\u53f0\\u5c9b\\u4ee5\\u4e1c\\u548c\\u897f\\u5357\\...
    │    └ <function HTTPConnection._send_output at 0x7f926beb7d30>
    └ <urllib3.connection.HTTPConnection object at 0x7f9124506040>
  File "/usr/lib/python3.8/http/client.py", line 1011, in _send_output
    self.send(msg)
    │    │    └ b'POST /search-platform/front/search HTTP/1.1\r\nHost: search.people.cn\r\nUser-Agent: Mozilla/5.0 (Windows NT 10.0; Win64; x...
    │    └ <function HTTPConnection.send at 0x7f926beb7b80>
    └ <urllib3.connection.HTTPConnection object at 0x7f9124506040>
  File "/usr/lib/python3.8/http/client.py", line 951, in send
    self.connect()
    │    └ <function HTTPConnection.connect at 0x7f92585b0dc0>
    └ <urllib3.connection.HTTPConnection object at 0x7f9124506040>
  File "/home/chase/.local/lib/python3.8/site-packages/urllib3/connection.py", line 205, in connect
    conn = self._new_conn()
           │    └ <function HTTPConnection._new_conn at 0x7f92585b0c10>
           └ <urllib3.connection.HTTPConnection object at 0x7f9124506040>
  File "/home/chase/.local/lib/python3.8/site-packages/urllib3/connection.py", line 186, in _new_conn
    raise NewConnectionError(
          └ <class 'urllib3.exceptions.NewConnectionError'>

urllib3.exceptions.NewConnectionError: <urllib3.connection.HTTPConnection object at 0x7f9124506040>: Failed to establish a new connection: [Errno 111] Connection refused


During handling of the above exception, another exception occurred:


Traceback (most recent call last):

  File "/home/chase/.local/lib/python3.8/site-packages/requests/adapters.py", line 439, in send
    resp = conn.urlopen(
           │    └ <function HTTPConnectionPool.urlopen at 0x7f92585c0820>
           └ <urllib3.connectionpool.HTTPConnectionPool object at 0x7f91601654c0>
  File "/home/chase/.local/lib/python3.8/site-packages/urllib3/connectionpool.py", line 755, in urlopen
    retries = retries.increment(
              │       └ <function Retry.increment at 0x7f9258608b80>
              └ Retry(total=0, connect=None, read=False, redirect=None, status=None)
  File "/home/chase/.local/lib/python3.8/site-packages/urllib3/util/retry.py", line 574, in increment
    raise MaxRetryError(_pool, url, error or ResponseError(cause))
          │             │      │    │        │             └ 'unknown'
          │             │      │    │        └ <class 'urllib3.exceptions.ResponseError'>
          │             │      │    └ NewConnectionError('<urllib3.connection.HTTPConnection object at 0x7f9124506040>: Failed to establish a new connection: [Errn...
          │             │      └ '/search-platform/front/search'
          │             └ <urllib3.connectionpool.HTTPConnectionPool object at 0x7f91601654c0>
          └ <class 'urllib3.exceptions.MaxRetryError'>

urllib3.exceptions.MaxRetryError: HTTPConnectionPool(host='search.people.cn', port=80): Max retries exceeded with url: /search-platform/front/search (Caused by NewConnectionError('<urllib3.connection.HTTPConnection object at 0x7f9124506040>: Failed to establish a new connection: [Errno 111] Connection refused'))


During handling of the above exception, another exception occurred:


Traceback (most recent call last):

  File "/usr/lib/python3.8/threading.py", line 890, in _bootstrap
    self._bootstrap_inner()
    │    └ <function Thread._bootstrap_inner at 0x7f927a614a60>
    └ <Thread(Thread-221, started daemon 140258716931840)>
  File "/usr/lib/python3.8/threading.py", line 932, in _bootstrap_inner
    self.run()
    │    └ <function Thread.run at 0x7f927a614790>
    └ <Thread(Thread-221, started daemon 140258716931840)>
  File "/usr/lib/python3.8/threading.py", line 870, in run
    self._target(*self._args, **self._kwargs)
    │    │        │    │        │    └ {}
    │    │        │    │        └ <Thread(Thread-221, started daemon 140258716931840)>
    │    │        │    └ ('ProjectManager.run_func_by_thread',)
    │    │        └ <Thread(Thread-221, started daemon 140258716931840)>
    │    └ <bound method ProjectManager.get_request_from_keywords_hot of <monitor.projectManager.ProjectManager object at 0x7f9162af4700>>
    └ <Thread(Thread-221, started daemon 140258716931840)>

  File "/home/users/Scy/yuqing/spider/monitor/projectManager.py", line 795, in get_request_from_keywords_hot
    self.search_spider_manager.crawl_by_keyword(
    │    │                     └ <function SearchSpidersManager.crawl_by_keyword at 0x7f9162b00040>
    │    └ <monitor.spiderManager.SearchSpidersManager object at 0x7f916270f0d0>
    └ <monitor.projectManager.ProjectManager object at 0x7f9162af4700>

  File "/home/users/Scy/yuqing/spider/monitor/spiderManager.py", line 118, in crawl_by_keyword
    self.crawl_by_keyword_signal_platform(project_names, platform, keyword, crawl_time, project_times)
    │    │                                │              │         │        │           └ {'default': <monitor.TimeSection object at 0x7f91628317f0>}
    │    │                                │              │         │        └ <monitor.TimeSection object at 0x7f9148591b20>
    │    │                                │              │         └ '东部战区组织兵力在台岛以东和西南海空域进行实兵演练'
    │    │                                │              └ '人民网'
    │    │                                └ ['default']
    │    └ <function SearchSpidersManager.crawl_by_keyword_signal_platform at 0x7f9162b000d0>
    └ <monitor.spiderManager.SearchSpidersManager object at 0x7f916270f0d0>

  File "/home/users/Scy/yuqing/spider/monitor/spiderManager.py", line 134, in crawl_by_keyword_signal_platform
    requests = self.get_request_from_keyword(platform, keyword, **crawl_time.to_dict())
               │    │                        │         │          │          └ <function TimeSection.to_dict at 0x7f925aaa8550>
               │    │                        │         │          └ <monitor.TimeSection object at 0x7f9148591b20>
               │    │                        │         └ '东部战区组织兵力在台岛以东和西南海空域进行实兵演练'
               │    │                        └ '人民网'
               │    └ <function SearchSpidersManager.get_request_from_keyword at 0x7f9162b001f0>
               └ <monitor.spiderManager.SearchSpidersManager object at 0x7f916270f0d0>

  File "/home/users/Scy/yuqing/spider/monitor/spiderManager.py", line 191, in get_request_from_keyword
    for request in self.spiders[platform].get_request_from_keyword(headers, search_url, keyword, content_url,
                   │    │       │                                  │        │           │        └ <string.Template object at 0x7f91482d1e20>
                   │    │       │                                  │        │           └ '东部战区组织兵力在台岛以东和西南海空域进行实兵演练'
                   │    │       │                                  │        └ <string.Template object at 0x7f91604ff8b0>
                   │    │       │                                  └ {'Accept': 'application/json, text/plain, */*', 'Accept-Language': 'zh-CN,zh;q=0.9', 'Connection': 'keep-alive', 'Origin': 'h...
                   │    │       └ '人民网'
                   │    └ {'凤凰网': <monitor.searchSpiders.ifeng.Ifeng object at 0x7f916270f220>, '头条': <monitor.searchSpiders.toutiao.Toutiao object at ...
                   └ <monitor.spiderManager.SearchSpidersManager object at 0x7f916270f0d0>

> File "/home/users/Scy/yuqing/spider/monitor/searchSpiders/people.py", line 28, in get_request_from_keyword
    response = requests.post(search_url.substitute(), json=data, headers=headers)
               │        │    │          │                  │             └ {'Accept': 'application/json, text/plain, */*', 'Accept-Language': 'zh-CN,zh;q=0.9', 'Connection': 'keep-alive', 'Origin': 'h...
               │        │    │          │                  └ {'key': '东部战区组织兵力在台岛以东和西南海空域进行实兵演练', 'page': 1, 'limit': 10, 'hasTitle': True, 'hasContent': True, 'isFuzzy': True, 'type': 0...
               │        │    │          └ <function Template.substitute at 0x7f927a5fd0d0>
               │        │    └ <string.Template object at 0x7f91604ff8b0>
               │        └ <function post at 0x7f92583e73a0>
               └ <module 'requests' from '/home/chase/.local/lib/python3.8/site-packages/requests/__init__.py'>

  File "/home/chase/.local/lib/python3.8/site-packages/requests/api.py", line 117, in post
    return request('post', url, data=data, json=json, **kwargs)
           │               │         │          │       └ {'headers': {'Accept': 'application/json, text/plain, */*', 'Accept-Language': 'zh-CN,zh;q=0.9', 'Connection': 'keep-alive', ...
           │               │         │          └ {'key': '东部战区组织兵力在台岛以东和西南海空域进行实兵演练', 'page': 1, 'limit': 10, 'hasTitle': True, 'hasContent': True, 'isFuzzy': True, 'type': 0...
           │               │         └ None
           │               └ 'http://search.people.cn/search-platform/front/search'
           └ <function request at 0x7f9258455040>
  File "/home/chase/.local/lib/python3.8/site-packages/requests/api.py", line 61, in request
    return session.request(method=method, url=url, **kwargs)
           │       │              │           │      └ {'data': None, 'json': {'key': '东部战区组织兵力在台岛以东和西南海空域进行实兵演练', 'page': 1, 'limit': 10, 'hasTitle': True, 'hasContent': True, 'is...
           │       │              │           └ 'http://search.people.cn/search-platform/front/search'
           │       │              └ 'post'
           │       └ <function Session.request at 0x7f92583e6940>
           └ <requests.sessions.Session object at 0x7f91041387c0>
  File "/home/chase/.local/lib/python3.8/site-packages/requests/sessions.py", line 542, in request
    resp = self.send(prep, **send_kwargs)
           │    │    │       └ {'timeout': None, 'allow_redirects': True, 'verify': True, 'proxies': OrderedDict(), 'stream': False, 'cert': None}
           │    │    └ <PreparedRequest [POST]>
           │    └ <function Session.send at 0x7f92583e6dc0>
           └ <requests.sessions.Session object at 0x7f91041387c0>
  File "/home/chase/.local/lib/python3.8/site-packages/requests/sessions.py", line 655, in send
    r = adapter.send(request, **kwargs)
        │       │    │          └ {'timeout': None, 'verify': True, 'proxies': OrderedDict(), 'stream': False, 'cert': None}
        │       │    └ <PreparedRequest [POST]>
        │       └ <function HTTPAdapter.send at 0x7f92583e6280>
        └ <requests.adapters.HTTPAdapter object at 0x7f91243fd400>
  File "/home/chase/.local/lib/python3.8/site-packages/requests/adapters.py", line 516, in send
    raise ConnectionError(e, request=request)
          │                          └ <PreparedRequest [POST]>
          └ <class 'requests.exceptions.ConnectionError'>

requests.exceptions.ConnectionError: HTTPConnectionPool(host='search.people.cn', port=80): Max retries exceeded with url: /search-platform/front/search (Caused by NewConnectionError('<urllib3.connection.HTTPConnection object at 0x7f9124506040>: Failed to establish a new connection: [Errno 111] Connection refused'))
2022-05-12 15:51:38.757 | ERROR    | monitor.searchSpiders.qinagguoLT:get_request_from_keyword:27 - E 强国论坛错误HTTPConnectionPool(host='bbs1.people.com.cn', port=80): Max retries exceeded with url: /board/1.html (Caused by NewConnectionError('<urllib3.connection.HTTPConnection object at 0x7f91485dc6d0>: Failed to establish a new connection: [Errno 111] Connection refused'))
Traceback (most recent call last):

  File "/home/chase/.local/lib/python3.8/site-packages/urllib3/connection.py", line 174, in _new_conn
    conn = connection.create_connection(
           │          └ <function create_connection at 0x7f92585fd1f0>
           └ <module 'urllib3.util.connection' from '/home/chase/.local/lib/python3.8/site-packages/urllib3/util/connection.py'>
  File "/home/chase/.local/lib/python3.8/site-packages/urllib3/util/connection.py", line 96, in create_connection
    raise err
          └ ConnectionRefusedError(111, 'Connection refused')
  File "/home/chase/.local/lib/python3.8/site-packages/urllib3/util/connection.py", line 86, in create_connection
    sock.connect(sa)
    │            └ ('118.212.233.223', 80)
    └ None

ConnectionRefusedError: [Errno 111] Connection refused


During handling of the above exception, another exception occurred:


Traceback (most recent call last):

  File "/home/chase/.local/lib/python3.8/site-packages/urllib3/connectionpool.py", line 699, in urlopen
    httplib_response = self._make_request(
                       │    └ <function HTTPConnectionPool._make_request at 0x7f92585c05e0>
                       └ <urllib3.connectionpool.HTTPConnectionPool object at 0x7f91604a1ac0>
  File "/home/chase/.local/lib/python3.8/site-packages/urllib3/connectionpool.py", line 394, in _make_request
    conn.request(method, url, **httplib_request_kw)
    │    │       │       │      └ {'body': None, 'headers': {'User-Agent': 'Mozilla/5.0 (X11; Linux x86_64) AppleWebKit/537.36 (KHTML, like Gecko) Chrome/93.0....
    │    │       │       └ '/board/1.html'
    │    │       └ 'GET'
    │    └ <function HTTPConnection.request at 0x7f92585b0f70>
    └ <urllib3.connection.HTTPConnection object at 0x7f91485dc6d0>
  File "/home/chase/.local/lib/python3.8/site-packages/urllib3/connection.py", line 239, in request
    super(HTTPConnection, self).request(method, url, body=body, headers=headers)
          │               │             │       │         │             └ {'User-Agent': 'Mozilla/5.0 (X11; Linux x86_64) AppleWebKit/537.36 (KHTML, like Gecko) Chrome/93.0.4577.63 Safari/537.36', 'A...
          │               │             │       │         └ None
          │               │             │       └ '/board/1.html'
          │               │             └ 'GET'
          │               └ <urllib3.connection.HTTPConnection object at 0x7f91485dc6d0>
          └ <class 'urllib3.connection.HTTPConnection'>
  File "/usr/lib/python3.8/http/client.py", line 1256, in request
    self._send_request(method, url, body, headers, encode_chunked)
    │    │             │       │    │     │        └ False
    │    │             │       │    │     └ {'User-Agent': 'Mozilla/5.0 (X11; Linux x86_64) AppleWebKit/537.36 (KHTML, like Gecko) Chrome/93.0.4577.63 Safari/537.36', 'A...
    │    │             │       │    └ None
    │    │             │       └ '/board/1.html'
    │    │             └ 'GET'
    │    └ <function HTTPConnection._send_request at 0x7f926be50280>
    └ <urllib3.connection.HTTPConnection object at 0x7f91485dc6d0>
  File "/usr/lib/python3.8/http/client.py", line 1302, in _send_request
    self.endheaders(body, encode_chunked=encode_chunked)
    │    │          │                    └ False
    │    │          └ None
    │    └ <function HTTPConnection.endheaders at 0x7f926be50160>
    └ <urllib3.connection.HTTPConnection object at 0x7f91485dc6d0>
  File "/usr/lib/python3.8/http/client.py", line 1251, in endheaders
    self._send_output(message_body, encode_chunked=encode_chunked)
    │    │            │                            └ False
    │    │            └ None
    │    └ <function HTTPConnection._send_output at 0x7f926beb7d30>
    └ <urllib3.connection.HTTPConnection object at 0x7f91485dc6d0>
  File "/usr/lib/python3.8/http/client.py", line 1011, in _send_output
    self.send(msg)
    │    │    └ b'GET /board/1.html HTTP/1.1\r\nHost: bbs1.people.com.cn\r\nUser-Agent: Mozilla/5.0 (X11; Linux x86_64) AppleWebKit/537.36 (K...
    │    └ <function HTTPConnection.send at 0x7f926beb7b80>
    └ <urllib3.connection.HTTPConnection object at 0x7f91485dc6d0>
  File "/usr/lib/python3.8/http/client.py", line 951, in send
    self.connect()
    │    └ <function HTTPConnection.connect at 0x7f92585b0dc0>
    └ <urllib3.connection.HTTPConnection object at 0x7f91485dc6d0>
  File "/home/chase/.local/lib/python3.8/site-packages/urllib3/connection.py", line 205, in connect
    conn = self._new_conn()
           │    └ <function HTTPConnection._new_conn at 0x7f92585b0c10>
           └ <urllib3.connection.HTTPConnection object at 0x7f91485dc6d0>
  File "/home/chase/.local/lib/python3.8/site-packages/urllib3/connection.py", line 186, in _new_conn
    raise NewConnectionError(
          └ <class 'urllib3.exceptions.NewConnectionError'>

urllib3.exceptions.NewConnectionError: <urllib3.connection.HTTPConnection object at 0x7f91485dc6d0>: Failed to establish a new connection: [Errno 111] Connection refused


During handling of the above exception, another exception occurred:


Traceback (most recent call last):

  File "/home/chase/.local/lib/python3.8/site-packages/requests/adapters.py", line 439, in send
    resp = conn.urlopen(
           │    └ <function HTTPConnectionPool.urlopen at 0x7f92585c0820>
           └ <urllib3.connectionpool.HTTPConnectionPool object at 0x7f91604a1ac0>
  File "/home/chase/.local/lib/python3.8/site-packages/urllib3/connectionpool.py", line 755, in urlopen
    retries = retries.increment(
              │       └ <function Retry.increment at 0x7f9258608b80>
              └ Retry(total=0, connect=None, read=False, redirect=None, status=None)
  File "/home/chase/.local/lib/python3.8/site-packages/urllib3/util/retry.py", line 574, in increment
    raise MaxRetryError(_pool, url, error or ResponseError(cause))
          │             │      │    │        │             └ 'unknown'
          │             │      │    │        └ <class 'urllib3.exceptions.ResponseError'>
          │             │      │    └ NewConnectionError('<urllib3.connection.HTTPConnection object at 0x7f91485dc6d0>: Failed to establish a new connection: [Errn...
          │             │      └ '/board/1.html'
          │             └ <urllib3.connectionpool.HTTPConnectionPool object at 0x7f91604a1ac0>
          └ <class 'urllib3.exceptions.MaxRetryError'>

urllib3.exceptions.MaxRetryError: HTTPConnectionPool(host='bbs1.people.com.cn', port=80): Max retries exceeded with url: /board/1.html (Caused by NewConnectionError('<urllib3.connection.HTTPConnection object at 0x7f91485dc6d0>: Failed to establish a new connection: [Errno 111] Connection refused'))


During handling of the above exception, another exception occurred:


Traceback (most recent call last):

  File "/usr/lib/python3.8/threading.py", line 890, in _bootstrap
    self._bootstrap_inner()
    │    └ <function Thread._bootstrap_inner at 0x7f927a614a60>
    └ <Thread(Thread-55, started daemon 140261418071808)>
  File "/usr/lib/python3.8/threading.py", line 932, in _bootstrap_inner
    self.run()
    │    └ <function Thread.run at 0x7f927a614790>
    └ <Thread(Thread-55, started daemon 140261418071808)>
  File "/usr/lib/python3.8/threading.py", line 870, in run
    self._target(*self._args, **self._kwargs)
    │    │        │    │        │    └ {}
    │    │        │    │        └ <Thread(Thread-55, started daemon 140261418071808)>
    │    │        │    └ ('ProjectManager.run_func_by_thread',)
    │    │        └ <Thread(Thread-55, started daemon 140261418071808)>
    │    └ <bound method ProjectManager.get_request_from_keywords_hot of <monitor.projectManager.ProjectManager object at 0x7f9162af4700>>
    └ <Thread(Thread-55, started daemon 140261418071808)>

  File "/home/users/Scy/yuqing/spider/monitor/projectManager.py", line 795, in get_request_from_keywords_hot
    self.search_spider_manager.crawl_by_keyword(
    │    │                     └ <function SearchSpidersManager.crawl_by_keyword at 0x7f9162b00040>
    │    └ <monitor.spiderManager.SearchSpidersManager object at 0x7f916270f0d0>
    └ <monitor.projectManager.ProjectManager object at 0x7f9162af4700>

  File "/home/users/Scy/yuqing/spider/monitor/spiderManager.py", line 118, in crawl_by_keyword
    self.crawl_by_keyword_signal_platform(project_names, platform, keyword, crawl_time, project_times)
    │    │                                │              │         │        │           └ {'default': <monitor.TimeSection object at 0x7f91628317f0>}
    │    │                                │              │         │        └ <monitor.TimeSection object at 0x7f91604259d0>
    │    │                                │              │         └ '非洲极端组织武器来源引关注'
    │    │                                │              └ '强国论坛'
    │    │                                └ ['default']
    │    └ <function SearchSpidersManager.crawl_by_keyword_signal_platform at 0x7f9162b000d0>
    └ <monitor.spiderManager.SearchSpidersManager object at 0x7f916270f0d0>

  File "/home/users/Scy/yuqing/spider/monitor/spiderManager.py", line 134, in crawl_by_keyword_signal_platform
    requests = self.get_request_from_keyword(platform, keyword, **crawl_time.to_dict())
               │    │                        │         │          │          └ <function TimeSection.to_dict at 0x7f925aaa8550>
               │    │                        │         │          └ <monitor.TimeSection object at 0x7f91604259d0>
               │    │                        │         └ '非洲极端组织武器来源引关注'
               │    │                        └ '强国论坛'
               │    └ <function SearchSpidersManager.get_request_from_keyword at 0x7f9162b001f0>
               └ <monitor.spiderManager.SearchSpidersManager object at 0x7f916270f0d0>

  File "/home/users/Scy/yuqing/spider/monitor/spiderManager.py", line 191, in get_request_from_keyword
    for request in self.spiders[platform].get_request_from_keyword(headers, search_url, keyword, content_url,
                   │    │       │                                  │        │           │        └ <string.Template object at 0x7f91244cc280>
                   │    │       │                                  │        │           └ '非洲极端组织武器来源引关注'
                   │    │       │                                  │        └ <string.Template object at 0x7f91604ffb20>
                   │    │       │                                  └ {'Connection': 'keep-alive', 'Cache-Control': 'max-age=0', 'Upgrade-Insecure-Requests': '1', 'User-Agent': 'Mozilla/5.0 (X11;...
                   │    │       └ '强国论坛'
                   │    └ {'凤凰网': <monitor.searchSpiders.ifeng.Ifeng object at 0x7f916270f220>, '头条': <monitor.searchSpiders.toutiao.Toutiao object at ...
                   └ <monitor.spiderManager.SearchSpidersManager object at 0x7f916270f0d0>

> File "/home/users/Scy/yuqing/spider/monitor/searchSpiders/qinagguoLT.py", line 18, in get_request_from_keyword
    response = requests.get(search_url.substitute(), headers=headers)
               │        │   │          │                     └ {'Connection': 'keep-alive', 'Cache-Control': 'max-age=0', 'Upgrade-Insecure-Requests': '1', 'User-Agent': 'Mozilla/5.0 (X11;...
               │        │   │          └ <function Template.substitute at 0x7f927a5fd0d0>
               │        │   └ <string.Template object at 0x7f91604ffb20>
               │        └ <function get at 0x7f92583e71f0>
               └ <module 'requests' from '/home/chase/.local/lib/python3.8/site-packages/requests/__init__.py'>

  File "/home/chase/.local/lib/python3.8/site-packages/requests/api.py", line 75, in get
    return request('get', url, params=params, **kwargs)
           │              │           │         └ {'headers': {'Connection': 'keep-alive', 'Cache-Control': 'max-age=0', 'Upgrade-Insecure-Requests': '1', 'User-Agent': 'Mozil...
           │              │           └ None
           │              └ 'http://bbs1.people.com.cn/board/1.html'
           └ <function request at 0x7f9258455040>
  File "/home/chase/.local/lib/python3.8/site-packages/requests/api.py", line 61, in request
    return session.request(method=method, url=url, **kwargs)
           │       │              │           │      └ {'params': None, 'headers': {'Connection': 'keep-alive', 'Cache-Control': 'max-age=0', 'Upgrade-Insecure-Requests': '1', 'Use...
           │       │              │           └ 'http://bbs1.people.com.cn/board/1.html'
           │       │              └ 'get'
           │       └ <function Session.request at 0x7f92583e6940>
           └ <requests.sessions.Session object at 0x7f91241e97c0>
  File "/home/chase/.local/lib/python3.8/site-packages/requests/sessions.py", line 542, in request
    resp = self.send(prep, **send_kwargs)
           │    │    │       └ {'timeout': None, 'allow_redirects': True, 'verify': True, 'proxies': OrderedDict(), 'stream': False, 'cert': None}
           │    │    └ <PreparedRequest [GET]>
           │    └ <function Session.send at 0x7f92583e6dc0>
           └ <requests.sessions.Session object at 0x7f91241e97c0>
  File "/home/chase/.local/lib/python3.8/site-packages/requests/sessions.py", line 655, in send
    r = adapter.send(request, **kwargs)
        │       │    │          └ {'timeout': None, 'verify': True, 'proxies': OrderedDict(), 'stream': False, 'cert': None}
        │       │    └ <PreparedRequest [GET]>
        │       └ <function HTTPAdapter.send at 0x7f92583e6280>
        └ <requests.adapters.HTTPAdapter object at 0x7f90e4488e20>
  File "/home/chase/.local/lib/python3.8/site-packages/requests/adapters.py", line 516, in send
    raise ConnectionError(e, request=request)
          │                          └ <PreparedRequest [GET]>
          └ <class 'requests.exceptions.ConnectionError'>

requests.exceptions.ConnectionError: HTTPConnectionPool(host='bbs1.people.com.cn', port=80): Max retries exceeded with url: /board/1.html (Caused by NewConnectionError('<urllib3.connection.HTTPConnection object at 0x7f91485dc6d0>: Failed to establish a new connection: [Errno 111] Connection refused'))
