2022-05-12 15:53:11.454 | ERROR    | monitor.searchSpiders.qinagguoLT:get_request_from_keyword:27 - E 强国论坛错误HTTPConnectionPool(host='bbs1.people.com.cn', port=80): Max retries exceeded with url: /board/1.html (Caused by NewConnectionError('<urllib3.connection.HTTPConnection object at 0x7f91041566d0>: Failed to establish a new connection: [Errno 111] Connection refused'))
Traceback (most recent call last):

  File "/home/chase/.local/lib/python3.8/site-packages/urllib3/connection.py", line 174, in _new_conn
    conn = connection.create_connection(
           │          └ <function create_connection at 0x7f92585fd1f0>
           └ <module 'urllib3.util.connection' from '/home/chase/.local/lib/python3.8/site-packages/urllib3/util/connection.py'>
  File "/home/chase/.local/lib/python3.8/site-packages/urllib3/util/connection.py", line 96, in create_connection
    raise err
          └ ConnectionRefusedError(111, 'Connection refused')
  File "/home/chase/.local/lib/python3.8/site-packages/urllib3/util/connection.py", line 86, in create_connection
    sock.connect(sa)
    │            └ ('1.31.128.212', 80)
    └ None

ConnectionRefusedError: [Errno 111] Connection refused


During handling of the above exception, another exception occurred:


Traceback (most recent call last):

  File "/home/chase/.local/lib/python3.8/site-packages/urllib3/connectionpool.py", line 699, in urlopen
    httplib_response = self._make_request(
                       │    └ <function HTTPConnectionPool._make_request at 0x7f92585c05e0>
                       └ <urllib3.connectionpool.HTTPConnectionPool object at 0x7f9124618280>
  File "/home/chase/.local/lib/python3.8/site-packages/urllib3/connectionpool.py", line 394, in _make_request
    conn.request(method, url, **httplib_request_kw)
    │    │       │       │      └ {'body': None, 'headers': {'User-Agent': 'Mozilla/5.0 (X11; Linux x86_64) AppleWebKit/537.36 (KHTML, like Gecko) Chrome/93.0....
    │    │       │       └ '/board/1.html'
    │    │       └ 'GET'
    │    └ <function HTTPConnection.request at 0x7f92585b0f70>
    └ <urllib3.connection.HTTPConnection object at 0x7f91041566d0>
  File "/home/chase/.local/lib/python3.8/site-packages/urllib3/connection.py", line 239, in request
    super(HTTPConnection, self).request(method, url, body=body, headers=headers)
          │               │             │       │         │             └ {'User-Agent': 'Mozilla/5.0 (X11; Linux x86_64) AppleWebKit/537.36 (KHTML, like Gecko) Chrome/93.0.4577.63 Safari/537.36', 'A...
          │               │             │       │         └ None
          │               │             │       └ '/board/1.html'
          │               │             └ 'GET'
          │               └ <urllib3.connection.HTTPConnection object at 0x7f91041566d0>
          └ <class 'urllib3.connection.HTTPConnection'>
  File "/usr/lib/python3.8/http/client.py", line 1256, in request
    self._send_request(method, url, body, headers, encode_chunked)
    │    │             │       │    │     │        └ False
    │    │             │       │    │     └ {'User-Agent': 'Mozilla/5.0 (X11; Linux x86_64) AppleWebKit/537.36 (KHTML, like Gecko) Chrome/93.0.4577.63 Safari/537.36', 'A...
    │    │             │       │    └ None
    │    │             │       └ '/board/1.html'
    │    │             └ 'GET'
    │    └ <function HTTPConnection._send_request at 0x7f926be50280>
    └ <urllib3.connection.HTTPConnection object at 0x7f91041566d0>
  File "/usr/lib/python3.8/http/client.py", line 1302, in _send_request
    self.endheaders(body, encode_chunked=encode_chunked)
    │    │          │                    └ False
    │    │          └ None
    │    └ <function HTTPConnection.endheaders at 0x7f926be50160>
    └ <urllib3.connection.HTTPConnection object at 0x7f91041566d0>
  File "/usr/lib/python3.8/http/client.py", line 1251, in endheaders
    self._send_output(message_body, encode_chunked=encode_chunked)
    │    │            │                            └ False
    │    │            └ None
    │    └ <function HTTPConnection._send_output at 0x7f926beb7d30>
    └ <urllib3.connection.HTTPConnection object at 0x7f91041566d0>
  File "/usr/lib/python3.8/http/client.py", line 1011, in _send_output
    self.send(msg)
    │    │    └ b'GET /board/1.html HTTP/1.1\r\nHost: bbs1.people.com.cn\r\nUser-Agent: Mozilla/5.0 (X11; Linux x86_64) AppleWebKit/537.36 (K...
    │    └ <function HTTPConnection.send at 0x7f926beb7b80>
    └ <urllib3.connection.HTTPConnection object at 0x7f91041566d0>
  File "/usr/lib/python3.8/http/client.py", line 951, in send
    self.connect()
    │    └ <function HTTPConnection.connect at 0x7f92585b0dc0>
    └ <urllib3.connection.HTTPConnection object at 0x7f91041566d0>
  File "/home/chase/.local/lib/python3.8/site-packages/urllib3/connection.py", line 205, in connect
    conn = self._new_conn()
           │    └ <function HTTPConnection._new_conn at 0x7f92585b0c10>
           └ <urllib3.connection.HTTPConnection object at 0x7f91041566d0>
  File "/home/chase/.local/lib/python3.8/site-packages/urllib3/connection.py", line 186, in _new_conn
    raise NewConnectionError(
          └ <class 'urllib3.exceptions.NewConnectionError'>

urllib3.exceptions.NewConnectionError: <urllib3.connection.HTTPConnection object at 0x7f91041566d0>: Failed to establish a new connection: [Errno 111] Connection refused


During handling of the above exception, another exception occurred:


Traceback (most recent call last):

  File "/home/chase/.local/lib/python3.8/site-packages/requests/adapters.py", line 439, in send
    resp = conn.urlopen(
           │    └ <function HTTPConnectionPool.urlopen at 0x7f92585c0820>
           └ <urllib3.connectionpool.HTTPConnectionPool object at 0x7f9124618280>
  File "/home/chase/.local/lib/python3.8/site-packages/urllib3/connectionpool.py", line 755, in urlopen
    retries = retries.increment(
              │       └ <function Retry.increment at 0x7f9258608b80>
              └ Retry(total=0, connect=None, read=False, redirect=None, status=None)
  File "/home/chase/.local/lib/python3.8/site-packages/urllib3/util/retry.py", line 574, in increment
    raise MaxRetryError(_pool, url, error or ResponseError(cause))
          │             │      │    │        │             └ 'unknown'
          │             │      │    │        └ <class 'urllib3.exceptions.ResponseError'>
          │             │      │    └ NewConnectionError('<urllib3.connection.HTTPConnection object at 0x7f91041566d0>: Failed to establish a new connection: [Errn...
          │             │      └ '/board/1.html'
          │             └ <urllib3.connectionpool.HTTPConnectionPool object at 0x7f9124618280>
          └ <class 'urllib3.exceptions.MaxRetryError'>

urllib3.exceptions.MaxRetryError: HTTPConnectionPool(host='bbs1.people.com.cn', port=80): Max retries exceeded with url: /board/1.html (Caused by NewConnectionError('<urllib3.connection.HTTPConnection object at 0x7f91041566d0>: Failed to establish a new connection: [Errno 111] Connection refused'))


During handling of the above exception, another exception occurred:


Traceback (most recent call last):

  File "/usr/lib/python3.8/threading.py", line 890, in _bootstrap
    self._bootstrap_inner()
    │    └ <function Thread._bootstrap_inner at 0x7f927a614a60>
    └ <Thread(Thread-139, started daemon 140260302366464)>
  File "/usr/lib/python3.8/threading.py", line 932, in _bootstrap_inner
    self.run()
    │    └ <function Thread.run at 0x7f927a614790>
    └ <Thread(Thread-139, started daemon 140260302366464)>
  File "/usr/lib/python3.8/threading.py", line 870, in run
    self._target(*self._args, **self._kwargs)
    │    │        │    │        │    └ {}
    │    │        │    │        └ <Thread(Thread-139, started daemon 140260302366464)>
    │    │        │    └ ('ProjectManager.run_func_by_thread',)
    │    │        └ <Thread(Thread-139, started daemon 140260302366464)>
    │    └ <bound method ProjectManager.get_request_from_keywords_hot of <monitor.projectManager.ProjectManager object at 0x7f9162af4700>>
    └ <Thread(Thread-139, started daemon 140260302366464)>

  File "/home/users/Scy/yuqing/spider/monitor/projectManager.py", line 795, in get_request_from_keywords_hot
    self.search_spider_manager.crawl_by_keyword(
    │    │                     └ <function SearchSpidersManager.crawl_by_keyword at 0x7f9162b00040>
    │    └ <monitor.spiderManager.SearchSpidersManager object at 0x7f916270f0d0>
    └ <monitor.projectManager.ProjectManager object at 0x7f9162af4700>

  File "/home/users/Scy/yuqing/spider/monitor/spiderManager.py", line 118, in crawl_by_keyword
    self.crawl_by_keyword_signal_platform(project_names, platform, keyword, crawl_time, project_times)
    │    │                                │              │         │        │           └ {'default': <monitor.TimeSection object at 0x7f91628317f0>}
    │    │                                │              │         │        └ <monitor.TimeSection object at 0x7f9148612850>
    │    │                                │              │         └ '伊拉克底格里斯河水位下降'
    │    │                                │              └ '强国论坛'
    │    │                                └ ['default']
    │    └ <function SearchSpidersManager.crawl_by_keyword_signal_platform at 0x7f9162b000d0>
    └ <monitor.spiderManager.SearchSpidersManager object at 0x7f916270f0d0>

  File "/home/users/Scy/yuqing/spider/monitor/spiderManager.py", line 134, in crawl_by_keyword_signal_platform
    requests = self.get_request_from_keyword(platform, keyword, **crawl_time.to_dict())
               │    │                        │         │          │          └ <function TimeSection.to_dict at 0x7f925aaa8550>
               │    │                        │         │          └ <monitor.TimeSection object at 0x7f9148612850>
               │    │                        │         └ '伊拉克底格里斯河水位下降'
               │    │                        └ '强国论坛'
               │    └ <function SearchSpidersManager.get_request_from_keyword at 0x7f9162b001f0>
               └ <monitor.spiderManager.SearchSpidersManager object at 0x7f916270f0d0>

  File "/home/users/Scy/yuqing/spider/monitor/spiderManager.py", line 191, in get_request_from_keyword
    for request in self.spiders[platform].get_request_from_keyword(headers, search_url, keyword, content_url,
                   │    │       │                                  │        │           │        └ <string.Template object at 0x7f9124679190>
                   │    │       │                                  │        │           └ '伊拉克底格里斯河水位下降'
                   │    │       │                                  │        └ <string.Template object at 0x7f9253fdea90>
                   │    │       │                                  └ {'Connection': 'keep-alive', 'Cache-Control': 'max-age=0', 'Upgrade-Insecure-Requests': '1', 'User-Agent': 'Mozilla/5.0 (X11;...
                   │    │       └ '强国论坛'
                   │    └ {'凤凰网': <monitor.searchSpiders.ifeng.Ifeng object at 0x7f916270f220>, '头条': <monitor.searchSpiders.toutiao.Toutiao object at ...
                   └ <monitor.spiderManager.SearchSpidersManager object at 0x7f916270f0d0>

> File "/home/users/Scy/yuqing/spider/monitor/searchSpiders/qinagguoLT.py", line 18, in get_request_from_keyword
    response = requests.get(search_url.substitute(), headers=headers)
               │        │   │          │                     └ {'Connection': 'keep-alive', 'Cache-Control': 'max-age=0', 'Upgrade-Insecure-Requests': '1', 'User-Agent': 'Mozilla/5.0 (X11;...
               │        │   │          └ <function Template.substitute at 0x7f927a5fd0d0>
               │        │   └ <string.Template object at 0x7f9253fdea90>
               │        └ <function get at 0x7f92583e71f0>
               └ <module 'requests' from '/home/chase/.local/lib/python3.8/site-packages/requests/__init__.py'>

  File "/home/chase/.local/lib/python3.8/site-packages/requests/api.py", line 75, in get
    return request('get', url, params=params, **kwargs)
           │              │           │         └ {'headers': {'Connection': 'keep-alive', 'Cache-Control': 'max-age=0', 'Upgrade-Insecure-Requests': '1', 'User-Agent': 'Mozil...
           │              │           └ None
           │              └ 'http://bbs1.people.com.cn/board/1.html'
           └ <function request at 0x7f9258455040>
  File "/home/chase/.local/lib/python3.8/site-packages/requests/api.py", line 61, in request
    return session.request(method=method, url=url, **kwargs)
           │       │              │           │      └ {'params': None, 'headers': {'Connection': 'keep-alive', 'Cache-Control': 'max-age=0', 'Upgrade-Insecure-Requests': '1', 'Use...
           │       │              │           └ 'http://bbs1.people.com.cn/board/1.html'
           │       │              └ 'get'
           │       └ <function Session.request at 0x7f92583e6940>
           └ <requests.sessions.Session object at 0x7f90e4663af0>
  File "/home/chase/.local/lib/python3.8/site-packages/requests/sessions.py", line 542, in request
    resp = self.send(prep, **send_kwargs)
           │    │    │       └ {'timeout': None, 'allow_redirects': True, 'verify': True, 'proxies': OrderedDict(), 'stream': False, 'cert': None}
           │    │    └ <PreparedRequest [GET]>
           │    └ <function Session.send at 0x7f92583e6dc0>
           └ <requests.sessions.Session object at 0x7f90e4663af0>
  File "/home/chase/.local/lib/python3.8/site-packages/requests/sessions.py", line 655, in send
    r = adapter.send(request, **kwargs)
        │       │    │          └ {'timeout': None, 'verify': True, 'proxies': OrderedDict(), 'stream': False, 'cert': None}
        │       │    └ <PreparedRequest [GET]>
        │       └ <function HTTPAdapter.send at 0x7f92583e6280>
        └ <requests.adapters.HTTPAdapter object at 0x7f9124233f40>
  File "/home/chase/.local/lib/python3.8/site-packages/requests/adapters.py", line 516, in send
    raise ConnectionError(e, request=request)
          │                          └ <PreparedRequest [GET]>
          └ <class 'requests.exceptions.ConnectionError'>

requests.exceptions.ConnectionError: HTTPConnectionPool(host='bbs1.people.com.cn', port=80): Max retries exceeded with url: /board/1.html (Caused by NewConnectionError('<urllib3.connection.HTTPConnection object at 0x7f91041566d0>: Failed to establish a new connection: [Errno 111] Connection refused'))
2022-05-12 15:53:12.285 | ERROR    | monitor.searchSpiders.qinagguoLT:get_request_from_keyword:27 - E 强国论坛错误HTTPConnectionPool(host='bbs1.people.com.cn', port=80): Max retries exceeded with url: /board/1.html (Caused by NewConnectionError('<urllib3.connection.HTTPConnection object at 0x7f9124080ac0>: Failed to establish a new connection: [Errno 111] Connection refused'))
Traceback (most recent call last):

  File "/home/chase/.local/lib/python3.8/site-packages/urllib3/connection.py", line 174, in _new_conn
    conn = connection.create_connection(
           │          └ <function create_connection at 0x7f92585fd1f0>
           └ <module 'urllib3.util.connection' from '/home/chase/.local/lib/python3.8/site-packages/urllib3/util/connection.py'>
  File "/home/chase/.local/lib/python3.8/site-packages/urllib3/util/connection.py", line 96, in create_connection
    raise err
          └ ConnectionRefusedError(111, 'Connection refused')
  File "/home/chase/.local/lib/python3.8/site-packages/urllib3/util/connection.py", line 86, in create_connection
    sock.connect(sa)
    │            └ ('1.31.128.212', 80)
    └ None

ConnectionRefusedError: [Errno 111] Connection refused


During handling of the above exception, another exception occurred:


Traceback (most recent call last):

  File "/home/chase/.local/lib/python3.8/site-packages/urllib3/connectionpool.py", line 699, in urlopen
    httplib_response = self._make_request(
                       │    └ <function HTTPConnectionPool._make_request at 0x7f92585c05e0>
                       └ <urllib3.connectionpool.HTTPConnectionPool object at 0x7f91603a45e0>
  File "/home/chase/.local/lib/python3.8/site-packages/urllib3/connectionpool.py", line 394, in _make_request
    conn.request(method, url, **httplib_request_kw)
    │    │       │       │      └ {'body': None, 'headers': {'User-Agent': 'Mozilla/5.0 (X11; Linux x86_64) AppleWebKit/537.36 (KHTML, like Gecko) Chrome/93.0....
    │    │       │       └ '/board/1.html'
    │    │       └ 'GET'
    │    └ <function HTTPConnection.request at 0x7f92585b0f70>
    └ <urllib3.connection.HTTPConnection object at 0x7f9124080ac0>
  File "/home/chase/.local/lib/python3.8/site-packages/urllib3/connection.py", line 239, in request
    super(HTTPConnection, self).request(method, url, body=body, headers=headers)
          │               │             │       │         │             └ {'User-Agent': 'Mozilla/5.0 (X11; Linux x86_64) AppleWebKit/537.36 (KHTML, like Gecko) Chrome/93.0.4577.63 Safari/537.36', 'A...
          │               │             │       │         └ None
          │               │             │       └ '/board/1.html'
          │               │             └ 'GET'
          │               └ <urllib3.connection.HTTPConnection object at 0x7f9124080ac0>
          └ <class 'urllib3.connection.HTTPConnection'>
  File "/usr/lib/python3.8/http/client.py", line 1256, in request
    self._send_request(method, url, body, headers, encode_chunked)
    │    │             │       │    │     │        └ False
    │    │             │       │    │     └ {'User-Agent': 'Mozilla/5.0 (X11; Linux x86_64) AppleWebKit/537.36 (KHTML, like Gecko) Chrome/93.0.4577.63 Safari/537.36', 'A...
    │    │             │       │    └ None
    │    │             │       └ '/board/1.html'
    │    │             └ 'GET'
    │    └ <function HTTPConnection._send_request at 0x7f926be50280>
    └ <urllib3.connection.HTTPConnection object at 0x7f9124080ac0>
  File "/usr/lib/python3.8/http/client.py", line 1302, in _send_request
    self.endheaders(body, encode_chunked=encode_chunked)
    │    │          │                    └ False
    │    │          └ None
    │    └ <function HTTPConnection.endheaders at 0x7f926be50160>
    └ <urllib3.connection.HTTPConnection object at 0x7f9124080ac0>
  File "/usr/lib/python3.8/http/client.py", line 1251, in endheaders
    self._send_output(message_body, encode_chunked=encode_chunked)
    │    │            │                            └ False
    │    │            └ None
    │    └ <function HTTPConnection._send_output at 0x7f926beb7d30>
    └ <urllib3.connection.HTTPConnection object at 0x7f9124080ac0>
  File "/usr/lib/python3.8/http/client.py", line 1011, in _send_output
    self.send(msg)
    │    │    └ b'GET /board/1.html HTTP/1.1\r\nHost: bbs1.people.com.cn\r\nUser-Agent: Mozilla/5.0 (X11; Linux x86_64) AppleWebKit/537.36 (K...
    │    └ <function HTTPConnection.send at 0x7f926beb7b80>
    └ <urllib3.connection.HTTPConnection object at 0x7f9124080ac0>
  File "/usr/lib/python3.8/http/client.py", line 951, in send
    self.connect()
    │    └ <function HTTPConnection.connect at 0x7f92585b0dc0>
    └ <urllib3.connection.HTTPConnection object at 0x7f9124080ac0>
  File "/home/chase/.local/lib/python3.8/site-packages/urllib3/connection.py", line 205, in connect
    conn = self._new_conn()
           │    └ <function HTTPConnection._new_conn at 0x7f92585b0c10>
           └ <urllib3.connection.HTTPConnection object at 0x7f9124080ac0>
  File "/home/chase/.local/lib/python3.8/site-packages/urllib3/connection.py", line 186, in _new_conn
    raise NewConnectionError(
          └ <class 'urllib3.exceptions.NewConnectionError'>

urllib3.exceptions.NewConnectionError: <urllib3.connection.HTTPConnection object at 0x7f9124080ac0>: Failed to establish a new connection: [Errno 111] Connection refused


During handling of the above exception, another exception occurred:


Traceback (most recent call last):

  File "/home/chase/.local/lib/python3.8/site-packages/requests/adapters.py", line 439, in send
    resp = conn.urlopen(
           │    └ <function HTTPConnectionPool.urlopen at 0x7f92585c0820>
           └ <urllib3.connectionpool.HTTPConnectionPool object at 0x7f91603a45e0>
  File "/home/chase/.local/lib/python3.8/site-packages/urllib3/connectionpool.py", line 755, in urlopen
    retries = retries.increment(
              │       └ <function Retry.increment at 0x7f9258608b80>
              └ Retry(total=0, connect=None, read=False, redirect=None, status=None)
  File "/home/chase/.local/lib/python3.8/site-packages/urllib3/util/retry.py", line 574, in increment
    raise MaxRetryError(_pool, url, error or ResponseError(cause))
          │             │      │    │        │             └ 'unknown'
          │             │      │    │        └ <class 'urllib3.exceptions.ResponseError'>
          │             │      │    └ NewConnectionError('<urllib3.connection.HTTPConnection object at 0x7f9124080ac0>: Failed to establish a new connection: [Errn...
          │             │      └ '/board/1.html'
          │             └ <urllib3.connectionpool.HTTPConnectionPool object at 0x7f91603a45e0>
          └ <class 'urllib3.exceptions.MaxRetryError'>

urllib3.exceptions.MaxRetryError: HTTPConnectionPool(host='bbs1.people.com.cn', port=80): Max retries exceeded with url: /board/1.html (Caused by NewConnectionError('<urllib3.connection.HTTPConnection object at 0x7f9124080ac0>: Failed to establish a new connection: [Errno 111] Connection refused'))


During handling of the above exception, another exception occurred:


Traceback (most recent call last):

  File "/usr/lib/python3.8/threading.py", line 890, in _bootstrap
    self._bootstrap_inner()
    │    └ <function Thread._bootstrap_inner at 0x7f927a614a60>
    └ <Thread(Thread-152, started daemon 140259799066368)>
  File "/usr/lib/python3.8/threading.py", line 932, in _bootstrap_inner
    self.run()
    │    └ <function Thread.run at 0x7f927a614790>
    └ <Thread(Thread-152, started daemon 140259799066368)>
  File "/usr/lib/python3.8/threading.py", line 870, in run
    self._target(*self._args, **self._kwargs)
    │    │        │    │        │    └ {}
    │    │        │    │        └ <Thread(Thread-152, started daemon 140259799066368)>
    │    │        │    └ ('ProjectManager.run_func_by_thread',)
    │    │        └ <Thread(Thread-152, started daemon 140259799066368)>
    │    └ <bound method ProjectManager.get_request_from_keywords_hot of <monitor.projectManager.ProjectManager object at 0x7f9162af4700>>
    └ <Thread(Thread-152, started daemon 140259799066368)>

  File "/home/users/Scy/yuqing/spider/monitor/projectManager.py", line 795, in get_request_from_keywords_hot
    self.search_spider_manager.crawl_by_keyword(
    │    │                     └ <function SearchSpidersManager.crawl_by_keyword at 0x7f9162b00040>
    │    └ <monitor.spiderManager.SearchSpidersManager object at 0x7f916270f0d0>
    └ <monitor.projectManager.ProjectManager object at 0x7f9162af4700>

  File "/home/users/Scy/yuqing/spider/monitor/spiderManager.py", line 118, in crawl_by_keyword
    self.crawl_by_keyword_signal_platform(project_names, platform, keyword, crawl_time, project_times)
    │    │                                │              │         │        │           └ {'default': <monitor.TimeSection object at 0x7f91628317f0>}
    │    │                                │              │         │        └ <monitor.TimeSection object at 0x7f916012db50>
    │    │                                │              │         └ '埃及安全部队打死14名恐怖分子'
    │    │                                │              └ '强国论坛'
    │    │                                └ ['default']
    │    └ <function SearchSpidersManager.crawl_by_keyword_signal_platform at 0x7f9162b000d0>
    └ <monitor.spiderManager.SearchSpidersManager object at 0x7f916270f0d0>

  File "/home/users/Scy/yuqing/spider/monitor/spiderManager.py", line 134, in crawl_by_keyword_signal_platform
    requests = self.get_request_from_keyword(platform, keyword, **crawl_time.to_dict())
               │    │                        │         │          │          └ <function TimeSection.to_dict at 0x7f925aaa8550>
               │    │                        │         │          └ <monitor.TimeSection object at 0x7f916012db50>
               │    │                        │         └ '埃及安全部队打死14名恐怖分子'
               │    │                        └ '强国论坛'
               │    └ <function SearchSpidersManager.get_request_from_keyword at 0x7f9162b001f0>
               └ <monitor.spiderManager.SearchSpidersManager object at 0x7f916270f0d0>

  File "/home/users/Scy/yuqing/spider/monitor/spiderManager.py", line 191, in get_request_from_keyword
    for request in self.spiders[platform].get_request_from_keyword(headers, search_url, keyword, content_url,
                   │    │       │                                  │        │           │        └ <string.Template object at 0x7f9124206be0>
                   │    │       │                                  │        │           └ '埃及安全部队打死14名恐怖分子'
                   │    │       │                                  │        └ <string.Template object at 0x7f91604ff130>
                   │    │       │                                  └ {'Connection': 'keep-alive', 'Cache-Control': 'max-age=0', 'Upgrade-Insecure-Requests': '1', 'User-Agent': 'Mozilla/5.0 (X11;...
                   │    │       └ '强国论坛'
                   │    └ {'凤凰网': <monitor.searchSpiders.ifeng.Ifeng object at 0x7f916270f220>, '头条': <monitor.searchSpiders.toutiao.Toutiao object at ...
                   └ <monitor.spiderManager.SearchSpidersManager object at 0x7f916270f0d0>

> File "/home/users/Scy/yuqing/spider/monitor/searchSpiders/qinagguoLT.py", line 18, in get_request_from_keyword
    response = requests.get(search_url.substitute(), headers=headers)
               │        │   │          │                     └ {'Connection': 'keep-alive', 'Cache-Control': 'max-age=0', 'Upgrade-Insecure-Requests': '1', 'User-Agent': 'Mozilla/5.0 (X11;...
               │        │   │          └ <function Template.substitute at 0x7f927a5fd0d0>
               │        │   └ <string.Template object at 0x7f91604ff130>
               │        └ <function get at 0x7f92583e71f0>
               └ <module 'requests' from '/home/chase/.local/lib/python3.8/site-packages/requests/__init__.py'>

  File "/home/chase/.local/lib/python3.8/site-packages/requests/api.py", line 75, in get
    return request('get', url, params=params, **kwargs)
           │              │           │         └ {'headers': {'Connection': 'keep-alive', 'Cache-Control': 'max-age=0', 'Upgrade-Insecure-Requests': '1', 'User-Agent': 'Mozil...
           │              │           └ None
           │              └ 'http://bbs1.people.com.cn/board/1.html'
           └ <function request at 0x7f9258455040>
  File "/home/chase/.local/lib/python3.8/site-packages/requests/api.py", line 61, in request
    return session.request(method=method, url=url, **kwargs)
           │       │              │           │      └ {'params': None, 'headers': {'Connection': 'keep-alive', 'Cache-Control': 'max-age=0', 'Upgrade-Insecure-Requests': '1', 'Use...
           │       │              │           └ 'http://bbs1.people.com.cn/board/1.html'
           │       │              └ 'get'
           │       └ <function Session.request at 0x7f92583e6940>
           └ <requests.sessions.Session object at 0x7f91486bbf40>
  File "/home/chase/.local/lib/python3.8/site-packages/requests/sessions.py", line 542, in request
    resp = self.send(prep, **send_kwargs)
           │    │    │       └ {'timeout': None, 'allow_redirects': True, 'verify': True, 'proxies': OrderedDict(), 'stream': False, 'cert': None}
           │    │    └ <PreparedRequest [GET]>
           │    └ <function Session.send at 0x7f92583e6dc0>
           └ <requests.sessions.Session object at 0x7f91486bbf40>
  File "/home/chase/.local/lib/python3.8/site-packages/requests/sessions.py", line 655, in send
    r = adapter.send(request, **kwargs)
        │       │    │          └ {'timeout': None, 'verify': True, 'proxies': OrderedDict(), 'stream': False, 'cert': None}
        │       │    └ <PreparedRequest [GET]>
        │       └ <function HTTPAdapter.send at 0x7f92583e6280>
        └ <requests.adapters.HTTPAdapter object at 0x7f910411c160>
  File "/home/chase/.local/lib/python3.8/site-packages/requests/adapters.py", line 516, in send
    raise ConnectionError(e, request=request)
          │                          └ <PreparedRequest [GET]>
          └ <class 'requests.exceptions.ConnectionError'>

requests.exceptions.ConnectionError: HTTPConnectionPool(host='bbs1.people.com.cn', port=80): Max retries exceeded with url: /board/1.html (Caused by NewConnectionError('<urllib3.connection.HTTPConnection object at 0x7f9124080ac0>: Failed to establish a new connection: [Errno 111] Connection refused'))
2022-05-12 15:53:12.696 | ERROR    | monitor.searchSpiders.qinagguoLT:get_request_from_keyword:27 - E 强国论坛错误HTTPConnectionPool(host='bbs1.people.com.cn', port=80): Max retries exceeded with url: /board/1.html (Caused by NewConnectionError('<urllib3.connection.HTTPConnection object at 0x7f910425b850>: Failed to establish a new connection: [Errno 111] Connection refused'))
Traceback (most recent call last):

  File "/home/chase/.local/lib/python3.8/site-packages/urllib3/connection.py", line 174, in _new_conn
    conn = connection.create_connection(
           │          └ <function create_connection at 0x7f92585fd1f0>
           └ <module 'urllib3.util.connection' from '/home/chase/.local/lib/python3.8/site-packages/urllib3/util/connection.py'>
  File "/home/chase/.local/lib/python3.8/site-packages/urllib3/util/connection.py", line 96, in create_connection
    raise err
          └ ConnectionRefusedError(111, 'Connection refused')
  File "/home/chase/.local/lib/python3.8/site-packages/urllib3/util/connection.py", line 86, in create_connection
    sock.connect(sa)
    │            └ ('1.31.128.212', 80)
    └ None

ConnectionRefusedError: [Errno 111] Connection refused


During handling of the above exception, another exception occurred:


Traceback (most recent call last):

  File "/home/chase/.local/lib/python3.8/site-packages/urllib3/connectionpool.py", line 699, in urlopen
    httplib_response = self._make_request(
                       │    └ <function HTTPConnectionPool._make_request at 0x7f92585c05e0>
                       └ <urllib3.connectionpool.HTTPConnectionPool object at 0x7f91040809d0>
  File "/home/chase/.local/lib/python3.8/site-packages/urllib3/connectionpool.py", line 394, in _make_request
    conn.request(method, url, **httplib_request_kw)
    │    │       │       │      └ {'body': None, 'headers': {'User-Agent': 'Mozilla/5.0 (X11; Linux x86_64) AppleWebKit/537.36 (KHTML, like Gecko) Chrome/93.0....
    │    │       │       └ '/board/1.html'
    │    │       └ 'GET'
    │    └ <function HTTPConnection.request at 0x7f92585b0f70>
    └ <urllib3.connection.HTTPConnection object at 0x7f910425b850>
  File "/home/chase/.local/lib/python3.8/site-packages/urllib3/connection.py", line 239, in request
    super(HTTPConnection, self).request(method, url, body=body, headers=headers)
          │               │             │       │         │             └ {'User-Agent': 'Mozilla/5.0 (X11; Linux x86_64) AppleWebKit/537.36 (KHTML, like Gecko) Chrome/93.0.4577.63 Safari/537.36', 'A...
          │               │             │       │         └ None
          │               │             │       └ '/board/1.html'
          │               │             └ 'GET'
          │               └ <urllib3.connection.HTTPConnection object at 0x7f910425b850>
          └ <class 'urllib3.connection.HTTPConnection'>
  File "/usr/lib/python3.8/http/client.py", line 1256, in request
    self._send_request(method, url, body, headers, encode_chunked)
    │    │             │       │    │     │        └ False
    │    │             │       │    │     └ {'User-Agent': 'Mozilla/5.0 (X11; Linux x86_64) AppleWebKit/537.36 (KHTML, like Gecko) Chrome/93.0.4577.63 Safari/537.36', 'A...
    │    │             │       │    └ None
    │    │             │       └ '/board/1.html'
    │    │             └ 'GET'
    │    └ <function HTTPConnection._send_request at 0x7f926be50280>
    └ <urllib3.connection.HTTPConnection object at 0x7f910425b850>
  File "/usr/lib/python3.8/http/client.py", line 1302, in _send_request
    self.endheaders(body, encode_chunked=encode_chunked)
    │    │          │                    └ False
    │    │          └ None
    │    └ <function HTTPConnection.endheaders at 0x7f926be50160>
    └ <urllib3.connection.HTTPConnection object at 0x7f910425b850>
  File "/usr/lib/python3.8/http/client.py", line 1251, in endheaders
    self._send_output(message_body, encode_chunked=encode_chunked)
    │    │            │                            └ False
    │    │            └ None
    │    └ <function HTTPConnection._send_output at 0x7f926beb7d30>
    └ <urllib3.connection.HTTPConnection object at 0x7f910425b850>
  File "/usr/lib/python3.8/http/client.py", line 1011, in _send_output
    self.send(msg)
    │    │    └ b'GET /board/1.html HTTP/1.1\r\nHost: bbs1.people.com.cn\r\nUser-Agent: Mozilla/5.0 (X11; Linux x86_64) AppleWebKit/537.36 (K...
    │    └ <function HTTPConnection.send at 0x7f926beb7b80>
    └ <urllib3.connection.HTTPConnection object at 0x7f910425b850>
  File "/usr/lib/python3.8/http/client.py", line 951, in send
    self.connect()
    │    └ <function HTTPConnection.connect at 0x7f92585b0dc0>
    └ <urllib3.connection.HTTPConnection object at 0x7f910425b850>
  File "/home/chase/.local/lib/python3.8/site-packages/urllib3/connection.py", line 205, in connect
    conn = self._new_conn()
           │    └ <function HTTPConnection._new_conn at 0x7f92585b0c10>
           └ <urllib3.connection.HTTPConnection object at 0x7f910425b850>
  File "/home/chase/.local/lib/python3.8/site-packages/urllib3/connection.py", line 186, in _new_conn
    raise NewConnectionError(
          └ <class 'urllib3.exceptions.NewConnectionError'>

urllib3.exceptions.NewConnectionError: <urllib3.connection.HTTPConnection object at 0x7f910425b850>: Failed to establish a new connection: [Errno 111] Connection refused


During handling of the above exception, another exception occurred:


Traceback (most recent call last):

  File "/home/chase/.local/lib/python3.8/site-packages/requests/adapters.py", line 439, in send
    resp = conn.urlopen(
           │    └ <function HTTPConnectionPool.urlopen at 0x7f92585c0820>
           └ <urllib3.connectionpool.HTTPConnectionPool object at 0x7f91040809d0>
  File "/home/chase/.local/lib/python3.8/site-packages/urllib3/connectionpool.py", line 755, in urlopen
    retries = retries.increment(
              │       └ <function Retry.increment at 0x7f9258608b80>
              └ Retry(total=0, connect=None, read=False, redirect=None, status=None)
  File "/home/chase/.local/lib/python3.8/site-packages/urllib3/util/retry.py", line 574, in increment
    raise MaxRetryError(_pool, url, error or ResponseError(cause))
          │             │      │    │        │             └ 'unknown'
          │             │      │    │        └ <class 'urllib3.exceptions.ResponseError'>
          │             │      │    └ NewConnectionError('<urllib3.connection.HTTPConnection object at 0x7f910425b850>: Failed to establish a new connection: [Errn...
          │             │      └ '/board/1.html'
          │             └ <urllib3.connectionpool.HTTPConnectionPool object at 0x7f91040809d0>
          └ <class 'urllib3.exceptions.MaxRetryError'>

urllib3.exceptions.MaxRetryError: HTTPConnectionPool(host='bbs1.people.com.cn', port=80): Max retries exceeded with url: /board/1.html (Caused by NewConnectionError('<urllib3.connection.HTTPConnection object at 0x7f910425b850>: Failed to establish a new connection: [Errno 111] Connection refused'))


During handling of the above exception, another exception occurred:


Traceback (most recent call last):

  File "/usr/lib/python3.8/threading.py", line 890, in _bootstrap
    self._bootstrap_inner()
    │    └ <function Thread._bootstrap_inner at 0x7f927a614a60>
    └ <Thread(Thread-175, started daemon 140259757102848)>
  File "/usr/lib/python3.8/threading.py", line 932, in _bootstrap_inner
    self.run()
    │    └ <function Thread.run at 0x7f927a614790>
    └ <Thread(Thread-175, started daemon 140259757102848)>
  File "/usr/lib/python3.8/threading.py", line 870, in run
    self._target(*self._args, **self._kwargs)
    │    │        │    │        │    └ {}
    │    │        │    │        └ <Thread(Thread-175, started daemon 140259757102848)>
    │    │        │    └ ('ProjectManager.run_func_by_thread',)
    │    │        └ <Thread(Thread-175, started daemon 140259757102848)>
    │    └ <bound method ProjectManager.get_request_from_keywords_hot of <monitor.projectManager.ProjectManager object at 0x7f9162af4700>>
    └ <Thread(Thread-175, started daemon 140259757102848)>

  File "/home/users/Scy/yuqing/spider/monitor/projectManager.py", line 795, in get_request_from_keywords_hot
    self.search_spider_manager.crawl_by_keyword(
    │    │                     └ <function SearchSpidersManager.crawl_by_keyword at 0x7f9162b00040>
    │    └ <monitor.spiderManager.SearchSpidersManager object at 0x7f916270f0d0>
    └ <monitor.projectManager.ProjectManager object at 0x7f9162af4700>

  File "/home/users/Scy/yuqing/spider/monitor/spiderManager.py", line 118, in crawl_by_keyword
    self.crawl_by_keyword_signal_platform(project_names, platform, keyword, crawl_time, project_times)
    │    │                                │              │         │        │           └ {'default': <monitor.TimeSection object at 0x7f91628317f0>}
    │    │                                │              │         │        └ <monitor.TimeSection object at 0x7f91480a4040>
    │    │                                │              │         └ '非洲极端组织武器来源引关注'
    │    │                                │              └ '强国论坛'
    │    │                                └ ['default']
    │    └ <function SearchSpidersManager.crawl_by_keyword_signal_platform at 0x7f9162b000d0>
    └ <monitor.spiderManager.SearchSpidersManager object at 0x7f916270f0d0>

  File "/home/users/Scy/yuqing/spider/monitor/spiderManager.py", line 134, in crawl_by_keyword_signal_platform
    requests = self.get_request_from_keyword(platform, keyword, **crawl_time.to_dict())
               │    │                        │         │          │          └ <function TimeSection.to_dict at 0x7f925aaa8550>
               │    │                        │         │          └ <monitor.TimeSection object at 0x7f91480a4040>
               │    │                        │         └ '非洲极端组织武器来源引关注'
               │    │                        └ '强国论坛'
               │    └ <function SearchSpidersManager.get_request_from_keyword at 0x7f9162b001f0>
               └ <monitor.spiderManager.SearchSpidersManager object at 0x7f916270f0d0>

  File "/home/users/Scy/yuqing/spider/monitor/spiderManager.py", line 191, in get_request_from_keyword
    for request in self.spiders[platform].get_request_from_keyword(headers, search_url, keyword, content_url,
                   │    │       │                                  │        │           │        └ <string.Template object at 0x7f90e44f6970>
                   │    │       │                                  │        │           └ '非洲极端组织武器来源引关注'
                   │    │       │                                  │        └ <string.Template object at 0x7f9104138af0>
                   │    │       │                                  └ {'Connection': 'keep-alive', 'Cache-Control': 'max-age=0', 'Upgrade-Insecure-Requests': '1', 'User-Agent': 'Mozilla/5.0 (X11;...
                   │    │       └ '强国论坛'
                   │    └ {'凤凰网': <monitor.searchSpiders.ifeng.Ifeng object at 0x7f916270f220>, '头条': <monitor.searchSpiders.toutiao.Toutiao object at ...
                   └ <monitor.spiderManager.SearchSpidersManager object at 0x7f916270f0d0>

> File "/home/users/Scy/yuqing/spider/monitor/searchSpiders/qinagguoLT.py", line 18, in get_request_from_keyword
    response = requests.get(search_url.substitute(), headers=headers)
               │        │   │          │                     └ {'Connection': 'keep-alive', 'Cache-Control': 'max-age=0', 'Upgrade-Insecure-Requests': '1', 'User-Agent': 'Mozilla/5.0 (X11;...
               │        │   │          └ <function Template.substitute at 0x7f927a5fd0d0>
               │        │   └ <string.Template object at 0x7f9104138af0>
               │        └ <function get at 0x7f92583e71f0>
               └ <module 'requests' from '/home/chase/.local/lib/python3.8/site-packages/requests/__init__.py'>

  File "/home/chase/.local/lib/python3.8/site-packages/requests/api.py", line 75, in get
    return request('get', url, params=params, **kwargs)
           │              │           │         └ {'headers': {'Connection': 'keep-alive', 'Cache-Control': 'max-age=0', 'Upgrade-Insecure-Requests': '1', 'User-Agent': 'Mozil...
           │              │           └ None
           │              └ 'http://bbs1.people.com.cn/board/1.html'
           └ <function request at 0x7f9258455040>
  File "/home/chase/.local/lib/python3.8/site-packages/requests/api.py", line 61, in request
    return session.request(method=method, url=url, **kwargs)
           │       │              │           │      └ {'params': None, 'headers': {'Connection': 'keep-alive', 'Cache-Control': 'max-age=0', 'Upgrade-Insecure-Requests': '1', 'Use...
           │       │              │           └ 'http://bbs1.people.com.cn/board/1.html'
           │       │              └ 'get'
           │       └ <function Session.request at 0x7f92583e6940>
           └ <requests.sessions.Session object at 0x7f91246661f0>
  File "/home/chase/.local/lib/python3.8/site-packages/requests/sessions.py", line 542, in request
    resp = self.send(prep, **send_kwargs)
           │    │    │       └ {'timeout': None, 'allow_redirects': True, 'verify': True, 'proxies': OrderedDict(), 'stream': False, 'cert': None}
           │    │    └ <PreparedRequest [GET]>
           │    └ <function Session.send at 0x7f92583e6dc0>
           └ <requests.sessions.Session object at 0x7f91246661f0>
  File "/home/chase/.local/lib/python3.8/site-packages/requests/sessions.py", line 655, in send
    r = adapter.send(request, **kwargs)
        │       │    │          └ {'timeout': None, 'verify': True, 'proxies': OrderedDict(), 'stream': False, 'cert': None}
        │       │    └ <PreparedRequest [GET]>
        │       └ <function HTTPAdapter.send at 0x7f92583e6280>
        └ <requests.adapters.HTTPAdapter object at 0x7f91604fffd0>
  File "/home/chase/.local/lib/python3.8/site-packages/requests/adapters.py", line 516, in send
    raise ConnectionError(e, request=request)
          │                          └ <PreparedRequest [GET]>
          └ <class 'requests.exceptions.ConnectionError'>

requests.exceptions.ConnectionError: HTTPConnectionPool(host='bbs1.people.com.cn', port=80): Max retries exceeded with url: /board/1.html (Caused by NewConnectionError('<urllib3.connection.HTTPConnection object at 0x7f910425b850>: Failed to establish a new connection: [Errno 111] Connection refused'))
2022-05-12 15:53:13.617 | ERROR    | monitor.searchSpiders.qinagguoLT:get_request_from_keyword:27 - E 强国论坛错误HTTPConnectionPool(host='bbs1.people.com.cn', port=80): Max retries exceeded with url: /board/1.html (Caused by NewConnectionError('<urllib3.connection.HTTPConnection object at 0x7f91604d0c70>: Failed to establish a new connection: [Errno 111] Connection refused'))
Traceback (most recent call last):

  File "/home/chase/.local/lib/python3.8/site-packages/urllib3/connection.py", line 174, in _new_conn
    conn = connection.create_connection(
           │          └ <function create_connection at 0x7f92585fd1f0>
           └ <module 'urllib3.util.connection' from '/home/chase/.local/lib/python3.8/site-packages/urllib3/util/connection.py'>
  File "/home/chase/.local/lib/python3.8/site-packages/urllib3/util/connection.py", line 96, in create_connection
    raise err
          └ ConnectionRefusedError(111, 'Connection refused')
  File "/home/chase/.local/lib/python3.8/site-packages/urllib3/util/connection.py", line 86, in create_connection
    sock.connect(sa)
    │            └ ('118.212.233.223', 80)
    └ None

ConnectionRefusedError: [Errno 111] Connection refused


During handling of the above exception, another exception occurred:


Traceback (most recent call last):

  File "/home/chase/.local/lib/python3.8/site-packages/urllib3/connectionpool.py", line 699, in urlopen
    httplib_response = self._make_request(
                       │    └ <function HTTPConnectionPool._make_request at 0x7f92585c05e0>
                       └ <urllib3.connectionpool.HTTPConnectionPool object at 0x7f91601a6910>
  File "/home/chase/.local/lib/python3.8/site-packages/urllib3/connectionpool.py", line 394, in _make_request
    conn.request(method, url, **httplib_request_kw)
    │    │       │       │      └ {'body': None, 'headers': {'User-Agent': 'Mozilla/5.0 (X11; Linux x86_64) AppleWebKit/537.36 (KHTML, like Gecko) Chrome/93.0....
    │    │       │       └ '/board/1.html'
    │    │       └ 'GET'
    │    └ <function HTTPConnection.request at 0x7f92585b0f70>
    └ <urllib3.connection.HTTPConnection object at 0x7f91604d0c70>
  File "/home/chase/.local/lib/python3.8/site-packages/urllib3/connection.py", line 239, in request
    super(HTTPConnection, self).request(method, url, body=body, headers=headers)
          │               │             │       │         │             └ {'User-Agent': 'Mozilla/5.0 (X11; Linux x86_64) AppleWebKit/537.36 (KHTML, like Gecko) Chrome/93.0.4577.63 Safari/537.36', 'A...
          │               │             │       │         └ None
          │               │             │       └ '/board/1.html'
          │               │             └ 'GET'
          │               └ <urllib3.connection.HTTPConnection object at 0x7f91604d0c70>
          └ <class 'urllib3.connection.HTTPConnection'>
  File "/usr/lib/python3.8/http/client.py", line 1256, in request
    self._send_request(method, url, body, headers, encode_chunked)
    │    │             │       │    │     │        └ False
    │    │             │       │    │     └ {'User-Agent': 'Mozilla/5.0 (X11; Linux x86_64) AppleWebKit/537.36 (KHTML, like Gecko) Chrome/93.0.4577.63 Safari/537.36', 'A...
    │    │             │       │    └ None
    │    │             │       └ '/board/1.html'
    │    │             └ 'GET'
    │    └ <function HTTPConnection._send_request at 0x7f926be50280>
    └ <urllib3.connection.HTTPConnection object at 0x7f91604d0c70>
  File "/usr/lib/python3.8/http/client.py", line 1302, in _send_request
    self.endheaders(body, encode_chunked=encode_chunked)
    │    │          │                    └ False
    │    │          └ None
    │    └ <function HTTPConnection.endheaders at 0x7f926be50160>
    └ <urllib3.connection.HTTPConnection object at 0x7f91604d0c70>
  File "/usr/lib/python3.8/http/client.py", line 1251, in endheaders
    self._send_output(message_body, encode_chunked=encode_chunked)
    │    │            │                            └ False
    │    │            └ None
    │    └ <function HTTPConnection._send_output at 0x7f926beb7d30>
    └ <urllib3.connection.HTTPConnection object at 0x7f91604d0c70>
  File "/usr/lib/python3.8/http/client.py", line 1011, in _send_output
    self.send(msg)
    │    │    └ b'GET /board/1.html HTTP/1.1\r\nHost: bbs1.people.com.cn\r\nUser-Agent: Mozilla/5.0 (X11; Linux x86_64) AppleWebKit/537.36 (K...
    │    └ <function HTTPConnection.send at 0x7f926beb7b80>
    └ <urllib3.connection.HTTPConnection object at 0x7f91604d0c70>
  File "/usr/lib/python3.8/http/client.py", line 951, in send
    self.connect()
    │    └ <function HTTPConnection.connect at 0x7f92585b0dc0>
    └ <urllib3.connection.HTTPConnection object at 0x7f91604d0c70>
  File "/home/chase/.local/lib/python3.8/site-packages/urllib3/connection.py", line 205, in connect
    conn = self._new_conn()
           │    └ <function HTTPConnection._new_conn at 0x7f92585b0c10>
           └ <urllib3.connection.HTTPConnection object at 0x7f91604d0c70>
  File "/home/chase/.local/lib/python3.8/site-packages/urllib3/connection.py", line 186, in _new_conn
    raise NewConnectionError(
          └ <class 'urllib3.exceptions.NewConnectionError'>

urllib3.exceptions.NewConnectionError: <urllib3.connection.HTTPConnection object at 0x7f91604d0c70>: Failed to establish a new connection: [Errno 111] Connection refused


During handling of the above exception, another exception occurred:


Traceback (most recent call last):

  File "/home/chase/.local/lib/python3.8/site-packages/requests/adapters.py", line 439, in send
    resp = conn.urlopen(
           │    └ <function HTTPConnectionPool.urlopen at 0x7f92585c0820>
           └ <urllib3.connectionpool.HTTPConnectionPool object at 0x7f91601a6910>
  File "/home/chase/.local/lib/python3.8/site-packages/urllib3/connectionpool.py", line 755, in urlopen
    retries = retries.increment(
              │       └ <function Retry.increment at 0x7f9258608b80>
              └ Retry(total=0, connect=None, read=False, redirect=None, status=None)
  File "/home/chase/.local/lib/python3.8/site-packages/urllib3/util/retry.py", line 574, in increment
    raise MaxRetryError(_pool, url, error or ResponseError(cause))
          │             │      │    │        │             └ 'unknown'
          │             │      │    │        └ <class 'urllib3.exceptions.ResponseError'>
          │             │      │    └ NewConnectionError('<urllib3.connection.HTTPConnection object at 0x7f91604d0c70>: Failed to establish a new connection: [Errn...
          │             │      └ '/board/1.html'
          │             └ <urllib3.connectionpool.HTTPConnectionPool object at 0x7f91601a6910>
          └ <class 'urllib3.exceptions.MaxRetryError'>

urllib3.exceptions.MaxRetryError: HTTPConnectionPool(host='bbs1.people.com.cn', port=80): Max retries exceeded with url: /board/1.html (Caused by NewConnectionError('<urllib3.connection.HTTPConnection object at 0x7f91604d0c70>: Failed to establish a new connection: [Errno 111] Connection refused'))


During handling of the above exception, another exception occurred:


Traceback (most recent call last):

  File "/usr/lib/python3.8/threading.py", line 890, in _bootstrap
    self._bootstrap_inner()
    │    └ <function Thread._bootstrap_inner at 0x7f927a614a60>
    └ <Thread(Thread-435, started daemon 140256007399168)>
  File "/usr/lib/python3.8/threading.py", line 932, in _bootstrap_inner
    self.run()
    │    └ <function Thread.run at 0x7f927a614790>
    └ <Thread(Thread-435, started daemon 140256007399168)>
  File "/usr/lib/python3.8/threading.py", line 870, in run
    self._target(*self._args, **self._kwargs)
    │    │        │    │        │    └ {}
    │    │        │    │        └ <Thread(Thread-435, started daemon 140256007399168)>
    │    │        │    └ ('ProjectManager.run_func_by_thread',)
    │    │        └ <Thread(Thread-435, started daemon 140256007399168)>
    │    └ <bound method ProjectManager.get_request_from_keywords_hot of <monitor.projectManager.ProjectManager object at 0x7f9162af4700>>
    └ <Thread(Thread-435, started daemon 140256007399168)>

  File "/home/users/Scy/yuqing/spider/monitor/projectManager.py", line 795, in get_request_from_keywords_hot
    self.search_spider_manager.crawl_by_keyword(
    │    │                     └ <function SearchSpidersManager.crawl_by_keyword at 0x7f9162b00040>
    │    └ <monitor.spiderManager.SearchSpidersManager object at 0x7f916270f0d0>
    └ <monitor.projectManager.ProjectManager object at 0x7f9162af4700>

  File "/home/users/Scy/yuqing/spider/monitor/spiderManager.py", line 118, in crawl_by_keyword
    self.crawl_by_keyword_signal_platform(project_names, platform, keyword, crawl_time, project_times)
    │    │                                │              │         │        │           └ {'default': <monitor.TimeSection object at 0x7f91628317f0>}
    │    │                                │              │         │        └ <monitor.TimeSection object at 0x7f91244020d0>
    │    │                                │              │         └ '克罗地亚前总统高度评价中克建交30年关系发展'
    │    │                                │              └ '强国论坛'
    │    │                                └ ['default']
    │    └ <function SearchSpidersManager.crawl_by_keyword_signal_platform at 0x7f9162b000d0>
    └ <monitor.spiderManager.SearchSpidersManager object at 0x7f916270f0d0>

  File "/home/users/Scy/yuqing/spider/monitor/spiderManager.py", line 134, in crawl_by_keyword_signal_platform
    requests = self.get_request_from_keyword(platform, keyword, **crawl_time.to_dict())
               │    │                        │         │          │          └ <function TimeSection.to_dict at 0x7f925aaa8550>
               │    │                        │         │          └ <monitor.TimeSection object at 0x7f91244020d0>
               │    │                        │         └ '克罗地亚前总统高度评价中克建交30年关系发展'
               │    │                        └ '强国论坛'
               │    └ <function SearchSpidersManager.get_request_from_keyword at 0x7f9162b001f0>
               └ <monitor.spiderManager.SearchSpidersManager object at 0x7f916270f0d0>

  File "/home/users/Scy/yuqing/spider/monitor/spiderManager.py", line 191, in get_request_from_keyword
    for request in self.spiders[platform].get_request_from_keyword(headers, search_url, keyword, content_url,
                   │    │       │                                  │        │           │        └ <string.Template object at 0x7f90e441ac10>
                   │    │       │                                  │        │           └ '克罗地亚前总统高度评价中克建交30年关系发展'
                   │    │       │                                  │        └ <string.Template object at 0x7f914827a610>
                   │    │       │                                  └ {'Connection': 'keep-alive', 'Cache-Control': 'max-age=0', 'Upgrade-Insecure-Requests': '1', 'User-Agent': 'Mozilla/5.0 (X11;...
                   │    │       └ '强国论坛'
                   │    └ {'凤凰网': <monitor.searchSpiders.ifeng.Ifeng object at 0x7f916270f220>, '头条': <monitor.searchSpiders.toutiao.Toutiao object at ...
                   └ <monitor.spiderManager.SearchSpidersManager object at 0x7f916270f0d0>

> File "/home/users/Scy/yuqing/spider/monitor/searchSpiders/qinagguoLT.py", line 18, in get_request_from_keyword
    response = requests.get(search_url.substitute(), headers=headers)
               │        │   │          │                     └ {'Connection': 'keep-alive', 'Cache-Control': 'max-age=0', 'Upgrade-Insecure-Requests': '1', 'User-Agent': 'Mozilla/5.0 (X11;...
               │        │   │          └ <function Template.substitute at 0x7f927a5fd0d0>
               │        │   └ <string.Template object at 0x7f914827a610>
               │        └ <function get at 0x7f92583e71f0>
               └ <module 'requests' from '/home/chase/.local/lib/python3.8/site-packages/requests/__init__.py'>

  File "/home/chase/.local/lib/python3.8/site-packages/requests/api.py", line 75, in get
    return request('get', url, params=params, **kwargs)
           │              │           │         └ {'headers': {'Connection': 'keep-alive', 'Cache-Control': 'max-age=0', 'Upgrade-Insecure-Requests': '1', 'User-Agent': 'Mozil...
           │              │           └ None
           │              └ 'http://bbs1.people.com.cn/board/1.html'
           └ <function request at 0x7f9258455040>
  File "/home/chase/.local/lib/python3.8/site-packages/requests/api.py", line 61, in request
    return session.request(method=method, url=url, **kwargs)
           │       │              │           │      └ {'params': None, 'headers': {'Connection': 'keep-alive', 'Cache-Control': 'max-age=0', 'Upgrade-Insecure-Requests': '1', 'Use...
           │       │              │           └ 'http://bbs1.people.com.cn/board/1.html'
           │       │              └ 'get'
           │       └ <function Session.request at 0x7f92583e6940>
           └ <requests.sessions.Session object at 0x7f91601f9af0>
  File "/home/chase/.local/lib/python3.8/site-packages/requests/sessions.py", line 542, in request
    resp = self.send(prep, **send_kwargs)
           │    │    │       └ {'timeout': None, 'allow_redirects': True, 'verify': True, 'proxies': OrderedDict(), 'stream': False, 'cert': None}
           │    │    └ <PreparedRequest [GET]>
           │    └ <function Session.send at 0x7f92583e6dc0>
           └ <requests.sessions.Session object at 0x7f91601f9af0>
  File "/home/chase/.local/lib/python3.8/site-packages/requests/sessions.py", line 655, in send
    r = adapter.send(request, **kwargs)
        │       │    │          └ {'timeout': None, 'verify': True, 'proxies': OrderedDict(), 'stream': False, 'cert': None}
        │       │    └ <PreparedRequest [GET]>
        │       └ <function HTTPAdapter.send at 0x7f92583e6280>
        └ <requests.adapters.HTTPAdapter object at 0x7f9253e22520>
  File "/home/chase/.local/lib/python3.8/site-packages/requests/adapters.py", line 516, in send
    raise ConnectionError(e, request=request)
          │                          └ <PreparedRequest [GET]>
          └ <class 'requests.exceptions.ConnectionError'>

requests.exceptions.ConnectionError: HTTPConnectionPool(host='bbs1.people.com.cn', port=80): Max retries exceeded with url: /board/1.html (Caused by NewConnectionError('<urllib3.connection.HTTPConnection object at 0x7f91604d0c70>: Failed to establish a new connection: [Errno 111] Connection refused'))
2022-05-12 15:53:14.312 | ERROR    | monitor.searchSpiders.qinagguoLT:get_request_from_keyword:27 - E 强国论坛错误HTTPConnectionPool(host='bbs1.people.com.cn', port=80): Max retries exceeded with url: /board/1.html (Caused by NewConnectionError('<urllib3.connection.HTTPConnection object at 0x7f9124085460>: Failed to establish a new connection: [Errno 111] Connection refused'))
Traceback (most recent call last):

  File "/home/chase/.local/lib/python3.8/site-packages/urllib3/connection.py", line 174, in _new_conn
    conn = connection.create_connection(
           │          └ <function create_connection at 0x7f92585fd1f0>
           └ <module 'urllib3.util.connection' from '/home/chase/.local/lib/python3.8/site-packages/urllib3/util/connection.py'>
  File "/home/chase/.local/lib/python3.8/site-packages/urllib3/util/connection.py", line 96, in create_connection
    raise err
          └ ConnectionRefusedError(111, 'Connection refused')
  File "/home/chase/.local/lib/python3.8/site-packages/urllib3/util/connection.py", line 86, in create_connection
    sock.connect(sa)
    │            └ ('118.212.233.223', 80)
    └ None

ConnectionRefusedError: [Errno 111] Connection refused


During handling of the above exception, another exception occurred:


Traceback (most recent call last):

  File "/home/chase/.local/lib/python3.8/site-packages/urllib3/connectionpool.py", line 699, in urlopen
    httplib_response = self._make_request(
                       │    └ <function HTTPConnectionPool._make_request at 0x7f92585c05e0>
                       └ <urllib3.connectionpool.HTTPConnectionPool object at 0x7f91042029d0>
  File "/home/chase/.local/lib/python3.8/site-packages/urllib3/connectionpool.py", line 394, in _make_request
    conn.request(method, url, **httplib_request_kw)
    │    │       │       │      └ {'body': None, 'headers': {'User-Agent': 'Mozilla/5.0 (X11; Linux x86_64) AppleWebKit/537.36 (KHTML, like Gecko) Chrome/93.0....
    │    │       │       └ '/board/1.html'
    │    │       └ 'GET'
    │    └ <function HTTPConnection.request at 0x7f92585b0f70>
    └ <urllib3.connection.HTTPConnection object at 0x7f9124085460>
  File "/home/chase/.local/lib/python3.8/site-packages/urllib3/connection.py", line 239, in request
    super(HTTPConnection, self).request(method, url, body=body, headers=headers)
          │               │             │       │         │             └ {'User-Agent': 'Mozilla/5.0 (X11; Linux x86_64) AppleWebKit/537.36 (KHTML, like Gecko) Chrome/93.0.4577.63 Safari/537.36', 'A...
          │               │             │       │         └ None
          │               │             │       └ '/board/1.html'
          │               │             └ 'GET'
          │               └ <urllib3.connection.HTTPConnection object at 0x7f9124085460>
          └ <class 'urllib3.connection.HTTPConnection'>
  File "/usr/lib/python3.8/http/client.py", line 1256, in request
    self._send_request(method, url, body, headers, encode_chunked)
    │    │             │       │    │     │        └ False
    │    │             │       │    │     └ {'User-Agent': 'Mozilla/5.0 (X11; Linux x86_64) AppleWebKit/537.36 (KHTML, like Gecko) Chrome/93.0.4577.63 Safari/537.36', 'A...
    │    │             │       │    └ None
    │    │             │       └ '/board/1.html'
    │    │             └ 'GET'
    │    └ <function HTTPConnection._send_request at 0x7f926be50280>
    └ <urllib3.connection.HTTPConnection object at 0x7f9124085460>
  File "/usr/lib/python3.8/http/client.py", line 1302, in _send_request
    self.endheaders(body, encode_chunked=encode_chunked)
    │    │          │                    └ False
    │    │          └ None
    │    └ <function HTTPConnection.endheaders at 0x7f926be50160>
    └ <urllib3.connection.HTTPConnection object at 0x7f9124085460>
  File "/usr/lib/python3.8/http/client.py", line 1251, in endheaders
    self._send_output(message_body, encode_chunked=encode_chunked)
    │    │            │                            └ False
    │    │            └ None
    │    └ <function HTTPConnection._send_output at 0x7f926beb7d30>
    └ <urllib3.connection.HTTPConnection object at 0x7f9124085460>
  File "/usr/lib/python3.8/http/client.py", line 1011, in _send_output
    self.send(msg)
    │    │    └ b'GET /board/1.html HTTP/1.1\r\nHost: bbs1.people.com.cn\r\nUser-Agent: Mozilla/5.0 (X11; Linux x86_64) AppleWebKit/537.36 (K...
    │    └ <function HTTPConnection.send at 0x7f926beb7b80>
    └ <urllib3.connection.HTTPConnection object at 0x7f9124085460>
  File "/usr/lib/python3.8/http/client.py", line 951, in send
    self.connect()
    │    └ <function HTTPConnection.connect at 0x7f92585b0dc0>
    └ <urllib3.connection.HTTPConnection object at 0x7f9124085460>
  File "/home/chase/.local/lib/python3.8/site-packages/urllib3/connection.py", line 205, in connect
    conn = self._new_conn()
           │    └ <function HTTPConnection._new_conn at 0x7f92585b0c10>
           └ <urllib3.connection.HTTPConnection object at 0x7f9124085460>
  File "/home/chase/.local/lib/python3.8/site-packages/urllib3/connection.py", line 186, in _new_conn
    raise NewConnectionError(
          └ <class 'urllib3.exceptions.NewConnectionError'>

urllib3.exceptions.NewConnectionError: <urllib3.connection.HTTPConnection object at 0x7f9124085460>: Failed to establish a new connection: [Errno 111] Connection refused


During handling of the above exception, another exception occurred:


Traceback (most recent call last):

  File "/home/chase/.local/lib/python3.8/site-packages/requests/adapters.py", line 439, in send
    resp = conn.urlopen(
           │    └ <function HTTPConnectionPool.urlopen at 0x7f92585c0820>
           └ <urllib3.connectionpool.HTTPConnectionPool object at 0x7f91042029d0>
  File "/home/chase/.local/lib/python3.8/site-packages/urllib3/connectionpool.py", line 755, in urlopen
    retries = retries.increment(
              │       └ <function Retry.increment at 0x7f9258608b80>
              └ Retry(total=0, connect=None, read=False, redirect=None, status=None)
  File "/home/chase/.local/lib/python3.8/site-packages/urllib3/util/retry.py", line 574, in increment
    raise MaxRetryError(_pool, url, error or ResponseError(cause))
          │             │      │    │        │             └ 'unknown'
          │             │      │    │        └ <class 'urllib3.exceptions.ResponseError'>
          │             │      │    └ NewConnectionError('<urllib3.connection.HTTPConnection object at 0x7f9124085460>: Failed to establish a new connection: [Errn...
          │             │      └ '/board/1.html'
          │             └ <urllib3.connectionpool.HTTPConnectionPool object at 0x7f91042029d0>
          └ <class 'urllib3.exceptions.MaxRetryError'>

urllib3.exceptions.MaxRetryError: HTTPConnectionPool(host='bbs1.people.com.cn', port=80): Max retries exceeded with url: /board/1.html (Caused by NewConnectionError('<urllib3.connection.HTTPConnection object at 0x7f9124085460>: Failed to establish a new connection: [Errno 111] Connection refused'))


During handling of the above exception, another exception occurred:


Traceback (most recent call last):

  File "/usr/lib/python3.8/threading.py", line 890, in _bootstrap
    self._bootstrap_inner()
    │    └ <function Thread._bootstrap_inner at 0x7f927a614a60>
    └ <Thread(Thread-315, started daemon 140257626404608)>
  File "/usr/lib/python3.8/threading.py", line 932, in _bootstrap_inner
    self.run()
    │    └ <function Thread.run at 0x7f927a614790>
    └ <Thread(Thread-315, started daemon 140257626404608)>
  File "/usr/lib/python3.8/threading.py", line 870, in run
    self._target(*self._args, **self._kwargs)
    │    │        │    │        │    └ {}
    │    │        │    │        └ <Thread(Thread-315, started daemon 140257626404608)>
    │    │        │    └ ('ProjectManager.run_func_by_thread',)
    │    │        └ <Thread(Thread-315, started daemon 140257626404608)>
    │    └ <bound method ProjectManager.get_request_from_keywords_hot of <monitor.projectManager.ProjectManager object at 0x7f9162af4700>>
    └ <Thread(Thread-315, started daemon 140257626404608)>

  File "/home/users/Scy/yuqing/spider/monitor/projectManager.py", line 795, in get_request_from_keywords_hot
    self.search_spider_manager.crawl_by_keyword(
    │    │                     └ <function SearchSpidersManager.crawl_by_keyword at 0x7f9162b00040>
    │    └ <monitor.spiderManager.SearchSpidersManager object at 0x7f916270f0d0>
    └ <monitor.projectManager.ProjectManager object at 0x7f9162af4700>

  File "/home/users/Scy/yuqing/spider/monitor/spiderManager.py", line 118, in crawl_by_keyword
    self.crawl_by_keyword_signal_platform(project_names, platform, keyword, crawl_time, project_times)
    │    │                                │              │         │        │           └ {'default': <monitor.TimeSection object at 0x7f91628317f0>}
    │    │                                │              │         │        └ <monitor.TimeSection object at 0x7f91247a8a00>
    │    │                                │              │         └ '埃及安全部队打死14名恐怖分子'
    │    │                                │              └ '强国论坛'
    │    │                                └ ['default']
    │    └ <function SearchSpidersManager.crawl_by_keyword_signal_platform at 0x7f9162b000d0>
    └ <monitor.spiderManager.SearchSpidersManager object at 0x7f916270f0d0>

  File "/home/users/Scy/yuqing/spider/monitor/spiderManager.py", line 134, in crawl_by_keyword_signal_platform
    requests = self.get_request_from_keyword(platform, keyword, **crawl_time.to_dict())
               │    │                        │         │          │          └ <function TimeSection.to_dict at 0x7f925aaa8550>
               │    │                        │         │          └ <monitor.TimeSection object at 0x7f91247a8a00>
               │    │                        │         └ '埃及安全部队打死14名恐怖分子'
               │    │                        └ '强国论坛'
               │    └ <function SearchSpidersManager.get_request_from_keyword at 0x7f9162b001f0>
               └ <monitor.spiderManager.SearchSpidersManager object at 0x7f916270f0d0>

  File "/home/users/Scy/yuqing/spider/monitor/spiderManager.py", line 191, in get_request_from_keyword
    for request in self.spiders[platform].get_request_from_keyword(headers, search_url, keyword, content_url,
                   │    │       │                                  │        │           │        └ <string.Template object at 0x7f91604d7280>
                   │    │       │                                  │        │           └ '埃及安全部队打死14名恐怖分子'
                   │    │       │                                  │        └ <string.Template object at 0x7f91604d7430>
                   │    │       │                                  └ {'Connection': 'keep-alive', 'Cache-Control': 'max-age=0', 'Upgrade-Insecure-Requests': '1', 'User-Agent': 'Mozilla/5.0 (X11;...
                   │    │       └ '强国论坛'
                   │    └ {'凤凰网': <monitor.searchSpiders.ifeng.Ifeng object at 0x7f916270f220>, '头条': <monitor.searchSpiders.toutiao.Toutiao object at ...
                   └ <monitor.spiderManager.SearchSpidersManager object at 0x7f916270f0d0>

> File "/home/users/Scy/yuqing/spider/monitor/searchSpiders/qinagguoLT.py", line 18, in get_request_from_keyword
    response = requests.get(search_url.substitute(), headers=headers)
               │        │   │          │                     └ {'Connection': 'keep-alive', 'Cache-Control': 'max-age=0', 'Upgrade-Insecure-Requests': '1', 'User-Agent': 'Mozilla/5.0 (X11;...
               │        │   │          └ <function Template.substitute at 0x7f927a5fd0d0>
               │        │   └ <string.Template object at 0x7f91604d7430>
               │        └ <function get at 0x7f92583e71f0>
               └ <module 'requests' from '/home/chase/.local/lib/python3.8/site-packages/requests/__init__.py'>

  File "/home/chase/.local/lib/python3.8/site-packages/requests/api.py", line 75, in get
    return request('get', url, params=params, **kwargs)
           │              │           │         └ {'headers': {'Connection': 'keep-alive', 'Cache-Control': 'max-age=0', 'Upgrade-Insecure-Requests': '1', 'User-Agent': 'Mozil...
           │              │           └ None
           │              └ 'http://bbs1.people.com.cn/board/1.html'
           └ <function request at 0x7f9258455040>
  File "/home/chase/.local/lib/python3.8/site-packages/requests/api.py", line 61, in request
    return session.request(method=method, url=url, **kwargs)
           │       │              │           │      └ {'params': None, 'headers': {'Connection': 'keep-alive', 'Cache-Control': 'max-age=0', 'Upgrade-Insecure-Requests': '1', 'Use...
           │       │              │           └ 'http://bbs1.people.com.cn/board/1.html'
           │       │              └ 'get'
           │       └ <function Session.request at 0x7f92583e6940>
           └ <requests.sessions.Session object at 0x7f91240ded00>
  File "/home/chase/.local/lib/python3.8/site-packages/requests/sessions.py", line 542, in request
    resp = self.send(prep, **send_kwargs)
           │    │    │       └ {'timeout': None, 'allow_redirects': True, 'verify': True, 'proxies': OrderedDict(), 'stream': False, 'cert': None}
           │    │    └ <PreparedRequest [GET]>
           │    └ <function Session.send at 0x7f92583e6dc0>
           └ <requests.sessions.Session object at 0x7f91240ded00>
  File "/home/chase/.local/lib/python3.8/site-packages/requests/sessions.py", line 655, in send
    r = adapter.send(request, **kwargs)
        │       │    │          └ {'timeout': None, 'verify': True, 'proxies': OrderedDict(), 'stream': False, 'cert': None}
        │       │    └ <PreparedRequest [GET]>
        │       └ <function HTTPAdapter.send at 0x7f92583e6280>
        └ <requests.adapters.HTTPAdapter object at 0x7f912469f610>
  File "/home/chase/.local/lib/python3.8/site-packages/requests/adapters.py", line 516, in send
    raise ConnectionError(e, request=request)
          │                          └ <PreparedRequest [GET]>
          └ <class 'requests.exceptions.ConnectionError'>

requests.exceptions.ConnectionError: HTTPConnectionPool(host='bbs1.people.com.cn', port=80): Max retries exceeded with url: /board/1.html (Caused by NewConnectionError('<urllib3.connection.HTTPConnection object at 0x7f9124085460>: Failed to establish a new connection: [Errno 111] Connection refused'))
2022-05-12 15:53:14.306 | ERROR    | monitor.searchSpiders.people:get_request_from_keyword:45 - E 人民网错误HTTPConnectionPool(host='search.people.cn', port=80): Max retries exceeded with url: /search-platform/front/search (Caused by NewConnectionError('<urllib3.connection.HTTPConnection object at 0x7f9253e33e50>: Failed to establish a new connection: [Errno 111] Connection refused'))
Traceback (most recent call last):

  File "/home/chase/.local/lib/python3.8/site-packages/urllib3/connection.py", line 174, in _new_conn
    conn = connection.create_connection(
           │          └ <function create_connection at 0x7f92585fd1f0>
           └ <module 'urllib3.util.connection' from '/home/chase/.local/lib/python3.8/site-packages/urllib3/util/connection.py'>
  File "/home/chase/.local/lib/python3.8/site-packages/urllib3/util/connection.py", line 96, in create_connection
    raise err
          └ ConnectionRefusedError(111, 'Connection refused')
  File "/home/chase/.local/lib/python3.8/site-packages/urllib3/util/connection.py", line 86, in create_connection
    sock.connect(sa)
    │            └ ('1.31.128.250', 80)
    └ None

ConnectionRefusedError: [Errno 111] Connection refused


During handling of the above exception, another exception occurred:


Traceback (most recent call last):

  File "/home/chase/.local/lib/python3.8/site-packages/urllib3/connectionpool.py", line 699, in urlopen
    httplib_response = self._make_request(
                       │    └ <function HTTPConnectionPool._make_request at 0x7f92585c05e0>
                       └ <urllib3.connectionpool.HTTPConnectionPool object at 0x7f90e46d1a60>
  File "/home/chase/.local/lib/python3.8/site-packages/urllib3/connectionpool.py", line 394, in _make_request
    conn.request(method, url, **httplib_request_kw)
    │    │       │       │      └ {'body': b'{"key": "\\u514b\\u7f57\\u5730\\u4e9a\\u524d\\u603b\\u7edf\\u9ad8\\u5ea6\\u8bc4\\u4ef7\\u4e2d\\u514b\\u5efa\\u4ea4...
    │    │       │       └ '/search-platform/front/search'
    │    │       └ 'POST'
    │    └ <function HTTPConnection.request at 0x7f92585b0f70>
    └ <urllib3.connection.HTTPConnection object at 0x7f9253e33e50>
  File "/home/chase/.local/lib/python3.8/site-packages/urllib3/connection.py", line 239, in request
    super(HTTPConnection, self).request(method, url, body=body, headers=headers)
          │               │             │       │         │             └ {'User-Agent': 'Mozilla/5.0 (Windows NT 10.0; Win64; x64) AppleWebKit/537.36 (KHTML, like Gecko) Chrome/101.0.4951.54 Safari/...
          │               │             │       │         └ b'{"key": "\\u514b\\u7f57\\u5730\\u4e9a\\u524d\\u603b\\u7edf\\u9ad8\\u5ea6\\u8bc4\\u4ef7\\u4e2d\\u514b\\u5efa\\u4ea430\\u5e74...
          │               │             │       └ '/search-platform/front/search'
          │               │             └ 'POST'
          │               └ <urllib3.connection.HTTPConnection object at 0x7f9253e33e50>
          └ <class 'urllib3.connection.HTTPConnection'>
  File "/usr/lib/python3.8/http/client.py", line 1256, in request
    self._send_request(method, url, body, headers, encode_chunked)
    │    │             │       │    │     │        └ False
    │    │             │       │    │     └ {'User-Agent': 'Mozilla/5.0 (Windows NT 10.0; Win64; x64) AppleWebKit/537.36 (KHTML, like Gecko) Chrome/101.0.4951.54 Safari/...
    │    │             │       │    └ b'{"key": "\\u514b\\u7f57\\u5730\\u4e9a\\u524d\\u603b\\u7edf\\u9ad8\\u5ea6\\u8bc4\\u4ef7\\u4e2d\\u514b\\u5efa\\u4ea430\\u5e74...
    │    │             │       └ '/search-platform/front/search'
    │    │             └ 'POST'
    │    └ <function HTTPConnection._send_request at 0x7f926be50280>
    └ <urllib3.connection.HTTPConnection object at 0x7f9253e33e50>
  File "/usr/lib/python3.8/http/client.py", line 1302, in _send_request
    self.endheaders(body, encode_chunked=encode_chunked)
    │    │          │                    └ False
    │    │          └ b'{"key": "\\u514b\\u7f57\\u5730\\u4e9a\\u524d\\u603b\\u7edf\\u9ad8\\u5ea6\\u8bc4\\u4ef7\\u4e2d\\u514b\\u5efa\\u4ea430\\u5e74...
    │    └ <function HTTPConnection.endheaders at 0x7f926be50160>
    └ <urllib3.connection.HTTPConnection object at 0x7f9253e33e50>
  File "/usr/lib/python3.8/http/client.py", line 1251, in endheaders
    self._send_output(message_body, encode_chunked=encode_chunked)
    │    │            │                            └ False
    │    │            └ b'{"key": "\\u514b\\u7f57\\u5730\\u4e9a\\u524d\\u603b\\u7edf\\u9ad8\\u5ea6\\u8bc4\\u4ef7\\u4e2d\\u514b\\u5efa\\u4ea430\\u5e74...
    │    └ <function HTTPConnection._send_output at 0x7f926beb7d30>
    └ <urllib3.connection.HTTPConnection object at 0x7f9253e33e50>
  File "/usr/lib/python3.8/http/client.py", line 1011, in _send_output
    self.send(msg)
    │    │    └ b'POST /search-platform/front/search HTTP/1.1\r\nHost: search.people.cn\r\nUser-Agent: Mozilla/5.0 (Windows NT 10.0; Win64; x...
    │    └ <function HTTPConnection.send at 0x7f926beb7b80>
    └ <urllib3.connection.HTTPConnection object at 0x7f9253e33e50>
  File "/usr/lib/python3.8/http/client.py", line 951, in send
    self.connect()
    │    └ <function HTTPConnection.connect at 0x7f92585b0dc0>
    └ <urllib3.connection.HTTPConnection object at 0x7f9253e33e50>
  File "/home/chase/.local/lib/python3.8/site-packages/urllib3/connection.py", line 205, in connect
    conn = self._new_conn()
           │    └ <function HTTPConnection._new_conn at 0x7f92585b0c10>
           └ <urllib3.connection.HTTPConnection object at 0x7f9253e33e50>
  File "/home/chase/.local/lib/python3.8/site-packages/urllib3/connection.py", line 186, in _new_conn
    raise NewConnectionError(
          └ <class 'urllib3.exceptions.NewConnectionError'>

urllib3.exceptions.NewConnectionError: <urllib3.connection.HTTPConnection object at 0x7f9253e33e50>: Failed to establish a new connection: [Errno 111] Connection refused


During handling of the above exception, another exception occurred:


Traceback (most recent call last):

  File "/home/chase/.local/lib/python3.8/site-packages/requests/adapters.py", line 439, in send
    resp = conn.urlopen(
           │    └ <function HTTPConnectionPool.urlopen at 0x7f92585c0820>
           └ <urllib3.connectionpool.HTTPConnectionPool object at 0x7f90e46d1a60>
  File "/home/chase/.local/lib/python3.8/site-packages/urllib3/connectionpool.py", line 755, in urlopen
    retries = retries.increment(
              │       └ <function Retry.increment at 0x7f9258608b80>
              └ Retry(total=0, connect=None, read=False, redirect=None, status=None)
  File "/home/chase/.local/lib/python3.8/site-packages/urllib3/util/retry.py", line 574, in increment
    raise MaxRetryError(_pool, url, error or ResponseError(cause))
          │             │      │    │        │             └ 'unknown'
          │             │      │    │        └ <class 'urllib3.exceptions.ResponseError'>
          │             │      │    └ NewConnectionError('<urllib3.connection.HTTPConnection object at 0x7f9253e33e50>: Failed to establish a new connection: [Errn...
          │             │      └ '/search-platform/front/search'
          │             └ <urllib3.connectionpool.HTTPConnectionPool object at 0x7f90e46d1a60>
          └ <class 'urllib3.exceptions.MaxRetryError'>

urllib3.exceptions.MaxRetryError: HTTPConnectionPool(host='search.people.cn', port=80): Max retries exceeded with url: /search-platform/front/search (Caused by NewConnectionError('<urllib3.connection.HTTPConnection object at 0x7f9253e33e50>: Failed to establish a new connection: [Errno 111] Connection refused'))


During handling of the above exception, another exception occurred:


Traceback (most recent call last):

  File "/usr/lib/python3.8/threading.py", line 890, in _bootstrap
    self._bootstrap_inner()
    │    └ <function Thread._bootstrap_inner at 0x7f927a614a60>
    └ <Thread(Thread-435, started daemon 140256007399168)>
  File "/usr/lib/python3.8/threading.py", line 932, in _bootstrap_inner
    self.run()
    │    └ <function Thread.run at 0x7f927a614790>
    └ <Thread(Thread-435, started daemon 140256007399168)>
  File "/usr/lib/python3.8/threading.py", line 870, in run
    self._target(*self._args, **self._kwargs)
    │    │        │    │        │    └ {}
    │    │        │    │        └ <Thread(Thread-435, started daemon 140256007399168)>
    │    │        │    └ ('ProjectManager.run_func_by_thread',)
    │    │        └ <Thread(Thread-435, started daemon 140256007399168)>
    │    └ <bound method ProjectManager.get_request_from_keywords_hot of <monitor.projectManager.ProjectManager object at 0x7f9162af4700>>
    └ <Thread(Thread-435, started daemon 140256007399168)>

  File "/home/users/Scy/yuqing/spider/monitor/projectManager.py", line 795, in get_request_from_keywords_hot
    self.search_spider_manager.crawl_by_keyword(
    │    │                     └ <function SearchSpidersManager.crawl_by_keyword at 0x7f9162b00040>
    │    └ <monitor.spiderManager.SearchSpidersManager object at 0x7f916270f0d0>
    └ <monitor.projectManager.ProjectManager object at 0x7f9162af4700>

  File "/home/users/Scy/yuqing/spider/monitor/spiderManager.py", line 118, in crawl_by_keyword
    self.crawl_by_keyword_signal_platform(project_names, platform, keyword, crawl_time, project_times)
    │    │                                │              │         │        │           └ {'default': <monitor.TimeSection object at 0x7f91628317f0>}
    │    │                                │              │         │        └ <monitor.TimeSection object at 0x7f91244020d0>
    │    │                                │              │         └ '克罗地亚前总统高度评价中克建交30年关系发展'
    │    │                                │              └ '人民网'
    │    │                                └ ['default']
    │    └ <function SearchSpidersManager.crawl_by_keyword_signal_platform at 0x7f9162b000d0>
    └ <monitor.spiderManager.SearchSpidersManager object at 0x7f916270f0d0>

  File "/home/users/Scy/yuqing/spider/monitor/spiderManager.py", line 134, in crawl_by_keyword_signal_platform
    requests = self.get_request_from_keyword(platform, keyword, **crawl_time.to_dict())
               │    │                        │         │          │          └ <function TimeSection.to_dict at 0x7f925aaa8550>
               │    │                        │         │          └ <monitor.TimeSection object at 0x7f91244020d0>
               │    │                        │         └ '克罗地亚前总统高度评价中克建交30年关系发展'
               │    │                        └ '人民网'
               │    └ <function SearchSpidersManager.get_request_from_keyword at 0x7f9162b001f0>
               └ <monitor.spiderManager.SearchSpidersManager object at 0x7f916270f0d0>

  File "/home/users/Scy/yuqing/spider/monitor/spiderManager.py", line 191, in get_request_from_keyword
    for request in self.spiders[platform].get_request_from_keyword(headers, search_url, keyword, content_url,
                   │    │       │                                  │        │           │        └ <string.Template object at 0x7f91487f03a0>
                   │    │       │                                  │        │           └ '克罗地亚前总统高度评价中克建交30年关系发展'
                   │    │       │                                  │        └ <string.Template object at 0x7f91241e8bb0>
                   │    │       │                                  └ {'Accept': 'application/json, text/plain, */*', 'Accept-Language': 'zh-CN,zh;q=0.9', 'Connection': 'keep-alive', 'Origin': 'h...
                   │    │       └ '人民网'
                   │    └ {'凤凰网': <monitor.searchSpiders.ifeng.Ifeng object at 0x7f916270f220>, '头条': <monitor.searchSpiders.toutiao.Toutiao object at ...
                   └ <monitor.spiderManager.SearchSpidersManager object at 0x7f916270f0d0>

> File "/home/users/Scy/yuqing/spider/monitor/searchSpiders/people.py", line 28, in get_request_from_keyword
    response = requests.post(search_url.substitute(), json=data, headers=headers)
               │        │    │          │                  │             └ {'Accept': 'application/json, text/plain, */*', 'Accept-Language': 'zh-CN,zh;q=0.9', 'Connection': 'keep-alive', 'Origin': 'h...
               │        │    │          │                  └ {'key': '克罗地亚前总统高度评价中克建交30年关系发展', 'page': 1, 'limit': 10, 'hasTitle': True, 'hasContent': True, 'isFuzzy': True, 'type': 0, '...
               │        │    │          └ <function Template.substitute at 0x7f927a5fd0d0>
               │        │    └ <string.Template object at 0x7f91241e8bb0>
               │        └ <function post at 0x7f92583e73a0>
               └ <module 'requests' from '/home/chase/.local/lib/python3.8/site-packages/requests/__init__.py'>

  File "/home/chase/.local/lib/python3.8/site-packages/requests/api.py", line 117, in post
    return request('post', url, data=data, json=json, **kwargs)
           │               │         │          │       └ {'headers': {'Accept': 'application/json, text/plain, */*', 'Accept-Language': 'zh-CN,zh;q=0.9', 'Connection': 'keep-alive', ...
           │               │         │          └ {'key': '克罗地亚前总统高度评价中克建交30年关系发展', 'page': 1, 'limit': 10, 'hasTitle': True, 'hasContent': True, 'isFuzzy': True, 'type': 0, '...
           │               │         └ None
           │               └ 'http://search.people.cn/search-platform/front/search'
           └ <function request at 0x7f9258455040>
  File "/home/chase/.local/lib/python3.8/site-packages/requests/api.py", line 61, in request
    return session.request(method=method, url=url, **kwargs)
           │       │              │           │      └ {'data': None, 'json': {'key': '克罗地亚前总统高度评价中克建交30年关系发展', 'page': 1, 'limit': 10, 'hasTitle': True, 'hasContent': True, 'isFuz...
           │       │              │           └ 'http://search.people.cn/search-platform/front/search'
           │       │              └ 'post'
           │       └ <function Session.request at 0x7f92583e6940>
           └ <requests.sessions.Session object at 0x7f9160251a60>
  File "/home/chase/.local/lib/python3.8/site-packages/requests/sessions.py", line 542, in request
    resp = self.send(prep, **send_kwargs)
           │    │    │       └ {'timeout': None, 'allow_redirects': True, 'verify': True, 'proxies': OrderedDict(), 'stream': False, 'cert': None}
           │    │    └ <PreparedRequest [POST]>
           │    └ <function Session.send at 0x7f92583e6dc0>
           └ <requests.sessions.Session object at 0x7f9160251a60>
  File "/home/chase/.local/lib/python3.8/site-packages/requests/sessions.py", line 655, in send
    r = adapter.send(request, **kwargs)
        │       │    │          └ {'timeout': None, 'verify': True, 'proxies': OrderedDict(), 'stream': False, 'cert': None}
        │       │    └ <PreparedRequest [POST]>
        │       └ <function HTTPAdapter.send at 0x7f92583e6280>
        └ <requests.adapters.HTTPAdapter object at 0x7f9104040970>
  File "/home/chase/.local/lib/python3.8/site-packages/requests/adapters.py", line 516, in send
    raise ConnectionError(e, request=request)
          │                          └ <PreparedRequest [POST]>
          └ <class 'requests.exceptions.ConnectionError'>

requests.exceptions.ConnectionError: HTTPConnectionPool(host='search.people.cn', port=80): Max retries exceeded with url: /search-platform/front/search (Caused by NewConnectionError('<urllib3.connection.HTTPConnection object at 0x7f9253e33e50>: Failed to establish a new connection: [Errno 111] Connection refused'))
2022-05-12 15:53:14.764 | ERROR    | monitor.searchSpiders.qinagguoLT:get_request_from_keyword:27 - E 强国论坛错误HTTPConnectionPool(host='bbs1.people.com.cn', port=80): Max retries exceeded with url: /board/1.html (Caused by NewConnectionError('<urllib3.connection.HTTPConnection object at 0x7f9124331b20>: Failed to establish a new connection: [Errno 111] Connection refused'))
Traceback (most recent call last):

  File "/home/chase/.local/lib/python3.8/site-packages/urllib3/connection.py", line 174, in _new_conn
    conn = connection.create_connection(
           │          └ <function create_connection at 0x7f92585fd1f0>
           └ <module 'urllib3.util.connection' from '/home/chase/.local/lib/python3.8/site-packages/urllib3/util/connection.py'>
  File "/home/chase/.local/lib/python3.8/site-packages/urllib3/util/connection.py", line 96, in create_connection
    raise err
          └ ConnectionRefusedError(111, 'Connection refused')
  File "/home/chase/.local/lib/python3.8/site-packages/urllib3/util/connection.py", line 86, in create_connection
    sock.connect(sa)
    │            └ ('118.212.233.223', 80)
    └ None

ConnectionRefusedError: [Errno 111] Connection refused


During handling of the above exception, another exception occurred:


Traceback (most recent call last):

  File "/home/chase/.local/lib/python3.8/site-packages/urllib3/connectionpool.py", line 699, in urlopen
    httplib_response = self._make_request(
                       │    └ <function HTTPConnectionPool._make_request at 0x7f92585c05e0>
                       └ <urllib3.connectionpool.HTTPConnectionPool object at 0x7f9148350e80>
  File "/home/chase/.local/lib/python3.8/site-packages/urllib3/connectionpool.py", line 394, in _make_request
    conn.request(method, url, **httplib_request_kw)
    │    │       │       │      └ {'body': None, 'headers': {'User-Agent': 'Mozilla/5.0 (X11; Linux x86_64) AppleWebKit/537.36 (KHTML, like Gecko) Chrome/93.0....
    │    │       │       └ '/board/1.html'
    │    │       └ 'GET'
    │    └ <function HTTPConnection.request at 0x7f92585b0f70>
    └ <urllib3.connection.HTTPConnection object at 0x7f9124331b20>
  File "/home/chase/.local/lib/python3.8/site-packages/urllib3/connection.py", line 239, in request
    super(HTTPConnection, self).request(method, url, body=body, headers=headers)
          │               │             │       │         │             └ {'User-Agent': 'Mozilla/5.0 (X11; Linux x86_64) AppleWebKit/537.36 (KHTML, like Gecko) Chrome/93.0.4577.63 Safari/537.36', 'A...
          │               │             │       │         └ None
          │               │             │       └ '/board/1.html'
          │               │             └ 'GET'
          │               └ <urllib3.connection.HTTPConnection object at 0x7f9124331b20>
          └ <class 'urllib3.connection.HTTPConnection'>
  File "/usr/lib/python3.8/http/client.py", line 1256, in request
    self._send_request(method, url, body, headers, encode_chunked)
    │    │             │       │    │     │        └ False
    │    │             │       │    │     └ {'User-Agent': 'Mozilla/5.0 (X11; Linux x86_64) AppleWebKit/537.36 (KHTML, like Gecko) Chrome/93.0.4577.63 Safari/537.36', 'A...
    │    │             │       │    └ None
    │    │             │       └ '/board/1.html'
    │    │             └ 'GET'
    │    └ <function HTTPConnection._send_request at 0x7f926be50280>
    └ <urllib3.connection.HTTPConnection object at 0x7f9124331b20>
  File "/usr/lib/python3.8/http/client.py", line 1302, in _send_request
    self.endheaders(body, encode_chunked=encode_chunked)
    │    │          │                    └ False
    │    │          └ None
    │    └ <function HTTPConnection.endheaders at 0x7f926be50160>
    └ <urllib3.connection.HTTPConnection object at 0x7f9124331b20>
  File "/usr/lib/python3.8/http/client.py", line 1251, in endheaders
    self._send_output(message_body, encode_chunked=encode_chunked)
    │    │            │                            └ False
    │    │            └ None
    │    └ <function HTTPConnection._send_output at 0x7f926beb7d30>
    └ <urllib3.connection.HTTPConnection object at 0x7f9124331b20>
  File "/usr/lib/python3.8/http/client.py", line 1011, in _send_output
    self.send(msg)
    │    │    └ b'GET /board/1.html HTTP/1.1\r\nHost: bbs1.people.com.cn\r\nUser-Agent: Mozilla/5.0 (X11; Linux x86_64) AppleWebKit/537.36 (K...
    │    └ <function HTTPConnection.send at 0x7f926beb7b80>
    └ <urllib3.connection.HTTPConnection object at 0x7f9124331b20>
  File "/usr/lib/python3.8/http/client.py", line 951, in send
    self.connect()
    │    └ <function HTTPConnection.connect at 0x7f92585b0dc0>
    └ <urllib3.connection.HTTPConnection object at 0x7f9124331b20>
  File "/home/chase/.local/lib/python3.8/site-packages/urllib3/connection.py", line 205, in connect
    conn = self._new_conn()
           │    └ <function HTTPConnection._new_conn at 0x7f92585b0c10>
           └ <urllib3.connection.HTTPConnection object at 0x7f9124331b20>
  File "/home/chase/.local/lib/python3.8/site-packages/urllib3/connection.py", line 186, in _new_conn
    raise NewConnectionError(
          └ <class 'urllib3.exceptions.NewConnectionError'>

urllib3.exceptions.NewConnectionError: <urllib3.connection.HTTPConnection object at 0x7f9124331b20>: Failed to establish a new connection: [Errno 111] Connection refused


During handling of the above exception, another exception occurred:


Traceback (most recent call last):

  File "/home/chase/.local/lib/python3.8/site-packages/requests/adapters.py", line 439, in send
    resp = conn.urlopen(
           │    └ <function HTTPConnectionPool.urlopen at 0x7f92585c0820>
           └ <urllib3.connectionpool.HTTPConnectionPool object at 0x7f9148350e80>
  File "/home/chase/.local/lib/python3.8/site-packages/urllib3/connectionpool.py", line 755, in urlopen
    retries = retries.increment(
              │       └ <function Retry.increment at 0x7f9258608b80>
              └ Retry(total=0, connect=None, read=False, redirect=None, status=None)
  File "/home/chase/.local/lib/python3.8/site-packages/urllib3/util/retry.py", line 574, in increment
    raise MaxRetryError(_pool, url, error or ResponseError(cause))
          │             │      │    │        │             └ 'unknown'
          │             │      │    │        └ <class 'urllib3.exceptions.ResponseError'>
          │             │      │    └ NewConnectionError('<urllib3.connection.HTTPConnection object at 0x7f9124331b20>: Failed to establish a new connection: [Errn...
          │             │      └ '/board/1.html'
          │             └ <urllib3.connectionpool.HTTPConnectionPool object at 0x7f9148350e80>
          └ <class 'urllib3.exceptions.MaxRetryError'>

urllib3.exceptions.MaxRetryError: HTTPConnectionPool(host='bbs1.people.com.cn', port=80): Max retries exceeded with url: /board/1.html (Caused by NewConnectionError('<urllib3.connection.HTTPConnection object at 0x7f9124331b20>: Failed to establish a new connection: [Errno 111] Connection refused'))


During handling of the above exception, another exception occurred:


Traceback (most recent call last):

  File "/usr/lib/python3.8/threading.py", line 890, in _bootstrap
    self._bootstrap_inner()
    │    └ <function Thread._bootstrap_inner at 0x7f927a614a60>
    └ <Thread(Thread-37, started daemon 140261988480768)>
  File "/usr/lib/python3.8/threading.py", line 932, in _bootstrap_inner
    self.run()
    │    └ <function Thread.run at 0x7f927a614790>
    └ <Thread(Thread-37, started daemon 140261988480768)>
  File "/usr/lib/python3.8/threading.py", line 870, in run
    self._target(*self._args, **self._kwargs)
    │    │        │    │        │    └ {}
    │    │        │    │        └ <Thread(Thread-37, started daemon 140261988480768)>
    │    │        │    └ ('ProjectManager.run_func_by_thread',)
    │    │        └ <Thread(Thread-37, started daemon 140261988480768)>
    │    └ <bound method ProjectManager.get_request_from_keywords_hot of <monitor.projectManager.ProjectManager object at 0x7f9162af4700>>
    └ <Thread(Thread-37, started daemon 140261988480768)>

  File "/home/users/Scy/yuqing/spider/monitor/projectManager.py", line 795, in get_request_from_keywords_hot
    self.search_spider_manager.crawl_by_keyword(
    │    │                     └ <function SearchSpidersManager.crawl_by_keyword at 0x7f9162b00040>
    │    └ <monitor.spiderManager.SearchSpidersManager object at 0x7f916270f0d0>
    └ <monitor.projectManager.ProjectManager object at 0x7f9162af4700>

  File "/home/users/Scy/yuqing/spider/monitor/spiderManager.py", line 118, in crawl_by_keyword
    self.crawl_by_keyword_signal_platform(project_names, platform, keyword, crawl_time, project_times)
    │    │                                │              │         │        │           └ {'default': <monitor.TimeSection object at 0x7f91628317f0>}
    │    │                                │              │         │        └ <monitor.TimeSection object at 0x7f916062e6a0>
    │    │                                │              │         └ '华南有持续性强降雨 多地气象部门强化应急联动全力防范应对强降雨'
    │    │                                │              └ '强国论坛'
    │    │                                └ ['default']
    │    └ <function SearchSpidersManager.crawl_by_keyword_signal_platform at 0x7f9162b000d0>
    └ <monitor.spiderManager.SearchSpidersManager object at 0x7f916270f0d0>

  File "/home/users/Scy/yuqing/spider/monitor/spiderManager.py", line 134, in crawl_by_keyword_signal_platform
    requests = self.get_request_from_keyword(platform, keyword, **crawl_time.to_dict())
               │    │                        │         │          │          └ <function TimeSection.to_dict at 0x7f925aaa8550>
               │    │                        │         │          └ <monitor.TimeSection object at 0x7f916062e6a0>
               │    │                        │         └ '华南有持续性强降雨 多地气象部门强化应急联动全力防范应对强降雨'
               │    │                        └ '强国论坛'
               │    └ <function SearchSpidersManager.get_request_from_keyword at 0x7f9162b001f0>
               └ <monitor.spiderManager.SearchSpidersManager object at 0x7f916270f0d0>

  File "/home/users/Scy/yuqing/spider/monitor/spiderManager.py", line 191, in get_request_from_keyword
    for request in self.spiders[platform].get_request_from_keyword(headers, search_url, keyword, content_url,
                   │    │       │                                  │        │           │        └ <string.Template object at 0x7f91240dc4f0>
                   │    │       │                                  │        │           └ '华南有持续性强降雨 多地气象部门强化应急联动全力防范应对强降雨'
                   │    │       │                                  │        └ <string.Template object at 0x7f91042b7a30>
                   │    │       │                                  └ {'Connection': 'keep-alive', 'Cache-Control': 'max-age=0', 'Upgrade-Insecure-Requests': '1', 'User-Agent': 'Mozilla/5.0 (X11;...
                   │    │       └ '强国论坛'
                   │    └ {'凤凰网': <monitor.searchSpiders.ifeng.Ifeng object at 0x7f916270f220>, '头条': <monitor.searchSpiders.toutiao.Toutiao object at ...
                   └ <monitor.spiderManager.SearchSpidersManager object at 0x7f916270f0d0>

> File "/home/users/Scy/yuqing/spider/monitor/searchSpiders/qinagguoLT.py", line 18, in get_request_from_keyword
    response = requests.get(search_url.substitute(), headers=headers)
               │        │   │          │                     └ {'Connection': 'keep-alive', 'Cache-Control': 'max-age=0', 'Upgrade-Insecure-Requests': '1', 'User-Agent': 'Mozilla/5.0 (X11;...
               │        │   │          └ <function Template.substitute at 0x7f927a5fd0d0>
               │        │   └ <string.Template object at 0x7f91042b7a30>
               │        └ <function get at 0x7f92583e71f0>
               └ <module 'requests' from '/home/chase/.local/lib/python3.8/site-packages/requests/__init__.py'>

  File "/home/chase/.local/lib/python3.8/site-packages/requests/api.py", line 75, in get
    return request('get', url, params=params, **kwargs)
           │              │           │         └ {'headers': {'Connection': 'keep-alive', 'Cache-Control': 'max-age=0', 'Upgrade-Insecure-Requests': '1', 'User-Agent': 'Mozil...
           │              │           └ None
           │              └ 'http://bbs1.people.com.cn/board/1.html'
           └ <function request at 0x7f9258455040>
  File "/home/chase/.local/lib/python3.8/site-packages/requests/api.py", line 61, in request
    return session.request(method=method, url=url, **kwargs)
           │       │              │           │      └ {'params': None, 'headers': {'Connection': 'keep-alive', 'Cache-Control': 'max-age=0', 'Upgrade-Insecure-Requests': '1', 'Use...
           │       │              │           └ 'http://bbs1.people.com.cn/board/1.html'
           │       │              └ 'get'
           │       └ <function Session.request at 0x7f92583e6940>
           └ <requests.sessions.Session object at 0x7f912454de50>
  File "/home/chase/.local/lib/python3.8/site-packages/requests/sessions.py", line 542, in request
    resp = self.send(prep, **send_kwargs)
           │    │    │       └ {'timeout': None, 'allow_redirects': True, 'verify': True, 'proxies': OrderedDict(), 'stream': False, 'cert': None}
           │    │    └ <PreparedRequest [GET]>
           │    └ <function Session.send at 0x7f92583e6dc0>
           └ <requests.sessions.Session object at 0x7f912454de50>
  File "/home/chase/.local/lib/python3.8/site-packages/requests/sessions.py", line 655, in send
    r = adapter.send(request, **kwargs)
        │       │    │          └ {'timeout': None, 'verify': True, 'proxies': OrderedDict(), 'stream': False, 'cert': None}
        │       │    └ <PreparedRequest [GET]>
        │       └ <function HTTPAdapter.send at 0x7f92583e6280>
        └ <requests.adapters.HTTPAdapter object at 0x7f9253e2df70>
  File "/home/chase/.local/lib/python3.8/site-packages/requests/adapters.py", line 516, in send
    raise ConnectionError(e, request=request)
          │                          └ <PreparedRequest [GET]>
          └ <class 'requests.exceptions.ConnectionError'>

requests.exceptions.ConnectionError: HTTPConnectionPool(host='bbs1.people.com.cn', port=80): Max retries exceeded with url: /board/1.html (Caused by NewConnectionError('<urllib3.connection.HTTPConnection object at 0x7f9124331b20>: Failed to establish a new connection: [Errno 111] Connection refused'))
2022-05-12 15:53:15.118 | ERROR    | monitor.searchSpiders.qinagguoLT:get_request_from_keyword:27 - E 强国论坛错误HTTPConnectionPool(host='bbs1.people.com.cn', port=80): Max retries exceeded with url: /board/1.html (Caused by NewConnectionError('<urllib3.connection.HTTPConnection object at 0x7f9160165190>: Failed to establish a new connection: [Errno 111] Connection refused'))
Traceback (most recent call last):

  File "/home/chase/.local/lib/python3.8/site-packages/urllib3/connection.py", line 174, in _new_conn
    conn = connection.create_connection(
           │          └ <function create_connection at 0x7f92585fd1f0>
           └ <module 'urllib3.util.connection' from '/home/chase/.local/lib/python3.8/site-packages/urllib3/util/connection.py'>
  File "/home/chase/.local/lib/python3.8/site-packages/urllib3/util/connection.py", line 96, in create_connection
    raise err
          └ ConnectionRefusedError(111, 'Connection refused')
  File "/home/chase/.local/lib/python3.8/site-packages/urllib3/util/connection.py", line 86, in create_connection
    sock.connect(sa)
    │            └ ('118.212.233.223', 80)
    └ None

ConnectionRefusedError: [Errno 111] Connection refused


During handling of the above exception, another exception occurred:


Traceback (most recent call last):

  File "/home/chase/.local/lib/python3.8/site-packages/urllib3/connectionpool.py", line 699, in urlopen
    httplib_response = self._make_request(
                       │    └ <function HTTPConnectionPool._make_request at 0x7f92585c05e0>
                       └ <urllib3.connectionpool.HTTPConnectionPool object at 0x7f9160204b20>
  File "/home/chase/.local/lib/python3.8/site-packages/urllib3/connectionpool.py", line 394, in _make_request
    conn.request(method, url, **httplib_request_kw)
    │    │       │       │      └ {'body': None, 'headers': {'User-Agent': 'Mozilla/5.0 (X11; Linux x86_64) AppleWebKit/537.36 (KHTML, like Gecko) Chrome/93.0....
    │    │       │       └ '/board/1.html'
    │    │       └ 'GET'
    │    └ <function HTTPConnection.request at 0x7f92585b0f70>
    └ <urllib3.connection.HTTPConnection object at 0x7f9160165190>
  File "/home/chase/.local/lib/python3.8/site-packages/urllib3/connection.py", line 239, in request
    super(HTTPConnection, self).request(method, url, body=body, headers=headers)
          │               │             │       │         │             └ {'User-Agent': 'Mozilla/5.0 (X11; Linux x86_64) AppleWebKit/537.36 (KHTML, like Gecko) Chrome/93.0.4577.63 Safari/537.36', 'A...
          │               │             │       │         └ None
          │               │             │       └ '/board/1.html'
          │               │             └ 'GET'
          │               └ <urllib3.connection.HTTPConnection object at 0x7f9160165190>
          └ <class 'urllib3.connection.HTTPConnection'>
  File "/usr/lib/python3.8/http/client.py", line 1256, in request
    self._send_request(method, url, body, headers, encode_chunked)
    │    │             │       │    │     │        └ False
    │    │             │       │    │     └ {'User-Agent': 'Mozilla/5.0 (X11; Linux x86_64) AppleWebKit/537.36 (KHTML, like Gecko) Chrome/93.0.4577.63 Safari/537.36', 'A...
    │    │             │       │    └ None
    │    │             │       └ '/board/1.html'
    │    │             └ 'GET'
    │    └ <function HTTPConnection._send_request at 0x7f926be50280>
    └ <urllib3.connection.HTTPConnection object at 0x7f9160165190>
  File "/usr/lib/python3.8/http/client.py", line 1302, in _send_request
    self.endheaders(body, encode_chunked=encode_chunked)
    │    │          │                    └ False
    │    │          └ None
    │    └ <function HTTPConnection.endheaders at 0x7f926be50160>
    └ <urllib3.connection.HTTPConnection object at 0x7f9160165190>
  File "/usr/lib/python3.8/http/client.py", line 1251, in endheaders
    self._send_output(message_body, encode_chunked=encode_chunked)
    │    │            │                            └ False
    │    │            └ None
    │    └ <function HTTPConnection._send_output at 0x7f926beb7d30>
    └ <urllib3.connection.HTTPConnection object at 0x7f9160165190>
  File "/usr/lib/python3.8/http/client.py", line 1011, in _send_output
    self.send(msg)
    │    │    └ b'GET /board/1.html HTTP/1.1\r\nHost: bbs1.people.com.cn\r\nUser-Agent: Mozilla/5.0 (X11; Linux x86_64) AppleWebKit/537.36 (K...
    │    └ <function HTTPConnection.send at 0x7f926beb7b80>
    └ <urllib3.connection.HTTPConnection object at 0x7f9160165190>
  File "/usr/lib/python3.8/http/client.py", line 951, in send
    self.connect()
    │    └ <function HTTPConnection.connect at 0x7f92585b0dc0>
    └ <urllib3.connection.HTTPConnection object at 0x7f9160165190>
  File "/home/chase/.local/lib/python3.8/site-packages/urllib3/connection.py", line 205, in connect
    conn = self._new_conn()
           │    └ <function HTTPConnection._new_conn at 0x7f92585b0c10>
           └ <urllib3.connection.HTTPConnection object at 0x7f9160165190>
  File "/home/chase/.local/lib/python3.8/site-packages/urllib3/connection.py", line 186, in _new_conn
    raise NewConnectionError(
          └ <class 'urllib3.exceptions.NewConnectionError'>

urllib3.exceptions.NewConnectionError: <urllib3.connection.HTTPConnection object at 0x7f9160165190>: Failed to establish a new connection: [Errno 111] Connection refused


During handling of the above exception, another exception occurred:


Traceback (most recent call last):

  File "/home/chase/.local/lib/python3.8/site-packages/requests/adapters.py", line 439, in send
    resp = conn.urlopen(
           │    └ <function HTTPConnectionPool.urlopen at 0x7f92585c0820>
           └ <urllib3.connectionpool.HTTPConnectionPool object at 0x7f9160204b20>
  File "/home/chase/.local/lib/python3.8/site-packages/urllib3/connectionpool.py", line 755, in urlopen
    retries = retries.increment(
              │       └ <function Retry.increment at 0x7f9258608b80>
              └ Retry(total=0, connect=None, read=False, redirect=None, status=None)
  File "/home/chase/.local/lib/python3.8/site-packages/urllib3/util/retry.py", line 574, in increment
    raise MaxRetryError(_pool, url, error or ResponseError(cause))
          │             │      │    │        │             └ 'unknown'
          │             │      │    │        └ <class 'urllib3.exceptions.ResponseError'>
          │             │      │    └ NewConnectionError('<urllib3.connection.HTTPConnection object at 0x7f9160165190>: Failed to establish a new connection: [Errn...
          │             │      └ '/board/1.html'
          │             └ <urllib3.connectionpool.HTTPConnectionPool object at 0x7f9160204b20>
          └ <class 'urllib3.exceptions.MaxRetryError'>

urllib3.exceptions.MaxRetryError: HTTPConnectionPool(host='bbs1.people.com.cn', port=80): Max retries exceeded with url: /board/1.html (Caused by NewConnectionError('<urllib3.connection.HTTPConnection object at 0x7f9160165190>: Failed to establish a new connection: [Errno 111] Connection refused'))


During handling of the above exception, another exception occurred:


Traceback (most recent call last):

  File "/usr/lib/python3.8/threading.py", line 890, in _bootstrap
    self._bootstrap_inner()
    │    └ <function Thread._bootstrap_inner at 0x7f927a614a60>
    └ <Thread(Thread-258, started daemon 140258163275520)>
  File "/usr/lib/python3.8/threading.py", line 932, in _bootstrap_inner
    self.run()
    │    └ <function Thread.run at 0x7f927a614790>
    └ <Thread(Thread-258, started daemon 140258163275520)>
  File "/usr/lib/python3.8/threading.py", line 870, in run
    self._target(*self._args, **self._kwargs)
    │    │        │    │        │    └ {}
    │    │        │    │        └ <Thread(Thread-258, started daemon 140258163275520)>
    │    │        │    └ ('ProjectManager.run_func_by_thread',)
    │    │        └ <Thread(Thread-258, started daemon 140258163275520)>
    │    └ <bound method ProjectManager.get_request_from_keywords_hot of <monitor.projectManager.ProjectManager object at 0x7f9162af4700>>
    └ <Thread(Thread-258, started daemon 140258163275520)>

  File "/home/users/Scy/yuqing/spider/monitor/projectManager.py", line 795, in get_request_from_keywords_hot
    self.search_spider_manager.crawl_by_keyword(
    │    │                     └ <function SearchSpidersManager.crawl_by_keyword at 0x7f9162b00040>
    │    └ <monitor.spiderManager.SearchSpidersManager object at 0x7f916270f0d0>
    └ <monitor.projectManager.ProjectManager object at 0x7f9162af4700>

  File "/home/users/Scy/yuqing/spider/monitor/spiderManager.py", line 118, in crawl_by_keyword
    self.crawl_by_keyword_signal_platform(project_names, platform, keyword, crawl_time, project_times)
    │    │                                │              │         │        │           └ {'default': <monitor.TimeSection object at 0x7f91628317f0>}
    │    │                                │              │         │        └ <monitor.TimeSection object at 0x7f9124542c40>
    │    │                                │              │         └ '意大利佛罗伦萨城市景观壮丽'
    │    │                                │              └ '强国论坛'
    │    │                                └ ['default']
    │    └ <function SearchSpidersManager.crawl_by_keyword_signal_platform at 0x7f9162b000d0>
    └ <monitor.spiderManager.SearchSpidersManager object at 0x7f916270f0d0>

  File "/home/users/Scy/yuqing/spider/monitor/spiderManager.py", line 134, in crawl_by_keyword_signal_platform
    requests = self.get_request_from_keyword(platform, keyword, **crawl_time.to_dict())
               │    │                        │         │          │          └ <function TimeSection.to_dict at 0x7f925aaa8550>
               │    │                        │         │          └ <monitor.TimeSection object at 0x7f9124542c40>
               │    │                        │         └ '意大利佛罗伦萨城市景观壮丽'
               │    │                        └ '强国论坛'
               │    └ <function SearchSpidersManager.get_request_from_keyword at 0x7f9162b001f0>
               └ <monitor.spiderManager.SearchSpidersManager object at 0x7f916270f0d0>

  File "/home/users/Scy/yuqing/spider/monitor/spiderManager.py", line 191, in get_request_from_keyword
    for request in self.spiders[platform].get_request_from_keyword(headers, search_url, keyword, content_url,
                   │    │       │                                  │        │           │        └ <string.Template object at 0x7f912471e1c0>
                   │    │       │                                  │        │           └ '意大利佛罗伦萨城市景观壮丽'
                   │    │       │                                  │        └ <string.Template object at 0x7f91040b58e0>
                   │    │       │                                  └ {'Connection': 'keep-alive', 'Cache-Control': 'max-age=0', 'Upgrade-Insecure-Requests': '1', 'User-Agent': 'Mozilla/5.0 (X11;...
                   │    │       └ '强国论坛'
                   │    └ {'凤凰网': <monitor.searchSpiders.ifeng.Ifeng object at 0x7f916270f220>, '头条': <monitor.searchSpiders.toutiao.Toutiao object at ...
                   └ <monitor.spiderManager.SearchSpidersManager object at 0x7f916270f0d0>

> File "/home/users/Scy/yuqing/spider/monitor/searchSpiders/qinagguoLT.py", line 18, in get_request_from_keyword
    response = requests.get(search_url.substitute(), headers=headers)
               │        │   │          │                     └ {'Connection': 'keep-alive', 'Cache-Control': 'max-age=0', 'Upgrade-Insecure-Requests': '1', 'User-Agent': 'Mozilla/5.0 (X11;...
               │        │   │          └ <function Template.substitute at 0x7f927a5fd0d0>
               │        │   └ <string.Template object at 0x7f91040b58e0>
               │        └ <function get at 0x7f92583e71f0>
               └ <module 'requests' from '/home/chase/.local/lib/python3.8/site-packages/requests/__init__.py'>

  File "/home/chase/.local/lib/python3.8/site-packages/requests/api.py", line 75, in get
    return request('get', url, params=params, **kwargs)
           │              │           │         └ {'headers': {'Connection': 'keep-alive', 'Cache-Control': 'max-age=0', 'Upgrade-Insecure-Requests': '1', 'User-Agent': 'Mozil...
           │              │           └ None
           │              └ 'http://bbs1.people.com.cn/board/1.html'
           └ <function request at 0x7f9258455040>
  File "/home/chase/.local/lib/python3.8/site-packages/requests/api.py", line 61, in request
    return session.request(method=method, url=url, **kwargs)
           │       │              │           │      └ {'params': None, 'headers': {'Connection': 'keep-alive', 'Cache-Control': 'max-age=0', 'Upgrade-Insecure-Requests': '1', 'Use...
           │       │              │           └ 'http://bbs1.people.com.cn/board/1.html'
           │       │              └ 'get'
           │       └ <function Session.request at 0x7f92583e6940>
           └ <requests.sessions.Session object at 0x7f914824f490>
  File "/home/chase/.local/lib/python3.8/site-packages/requests/sessions.py", line 542, in request
    resp = self.send(prep, **send_kwargs)
           │    │    │       └ {'timeout': None, 'allow_redirects': True, 'verify': True, 'proxies': OrderedDict(), 'stream': False, 'cert': None}
           │    │    └ <PreparedRequest [GET]>
           │    └ <function Session.send at 0x7f92583e6dc0>
           └ <requests.sessions.Session object at 0x7f914824f490>
  File "/home/chase/.local/lib/python3.8/site-packages/requests/sessions.py", line 655, in send
    r = adapter.send(request, **kwargs)
        │       │    │          └ {'timeout': None, 'verify': True, 'proxies': OrderedDict(), 'stream': False, 'cert': None}
        │       │    └ <PreparedRequest [GET]>
        │       └ <function HTTPAdapter.send at 0x7f92583e6280>
        └ <requests.adapters.HTTPAdapter object at 0x7f9124607700>
  File "/home/chase/.local/lib/python3.8/site-packages/requests/adapters.py", line 516, in send
    raise ConnectionError(e, request=request)
          │                          └ <PreparedRequest [GET]>
          └ <class 'requests.exceptions.ConnectionError'>

requests.exceptions.ConnectionError: HTTPConnectionPool(host='bbs1.people.com.cn', port=80): Max retries exceeded with url: /board/1.html (Caused by NewConnectionError('<urllib3.connection.HTTPConnection object at 0x7f9160165190>: Failed to establish a new connection: [Errno 111] Connection refused'))
2022-05-12 15:53:15.361 | ERROR    | monitor.searchSpiders.qinagguoLT:get_request_from_keyword:27 - E 强国论坛错误HTTPConnectionPool(host='bbs1.people.com.cn', port=80): Max retries exceeded with url: /board/1.html (Caused by NewConnectionError('<urllib3.connection.HTTPConnection object at 0x7f916008ae50>: Failed to establish a new connection: [Errno 111] Connection refused'))
Traceback (most recent call last):

  File "/home/chase/.local/lib/python3.8/site-packages/urllib3/connection.py", line 174, in _new_conn
    conn = connection.create_connection(
           │          └ <function create_connection at 0x7f92585fd1f0>
           └ <module 'urllib3.util.connection' from '/home/chase/.local/lib/python3.8/site-packages/urllib3/util/connection.py'>
  File "/home/chase/.local/lib/python3.8/site-packages/urllib3/util/connection.py", line 96, in create_connection
    raise err
          └ ConnectionRefusedError(111, 'Connection refused')
  File "/home/chase/.local/lib/python3.8/site-packages/urllib3/util/connection.py", line 86, in create_connection
    sock.connect(sa)
    │            └ ('118.212.233.223', 80)
    └ None

ConnectionRefusedError: [Errno 111] Connection refused


During handling of the above exception, another exception occurred:


Traceback (most recent call last):

  File "/home/chase/.local/lib/python3.8/site-packages/urllib3/connectionpool.py", line 699, in urlopen
    httplib_response = self._make_request(
                       │    └ <function HTTPConnectionPool._make_request at 0x7f92585c05e0>
                       └ <urllib3.connectionpool.HTTPConnectionPool object at 0x7f916003d040>
  File "/home/chase/.local/lib/python3.8/site-packages/urllib3/connectionpool.py", line 394, in _make_request
    conn.request(method, url, **httplib_request_kw)
    │    │       │       │      └ {'body': None, 'headers': {'User-Agent': 'Mozilla/5.0 (X11; Linux x86_64) AppleWebKit/537.36 (KHTML, like Gecko) Chrome/93.0....
    │    │       │       └ '/board/1.html'
    │    │       └ 'GET'
    │    └ <function HTTPConnection.request at 0x7f92585b0f70>
    └ <urllib3.connection.HTTPConnection object at 0x7f916008ae50>
  File "/home/chase/.local/lib/python3.8/site-packages/urllib3/connection.py", line 239, in request
    super(HTTPConnection, self).request(method, url, body=body, headers=headers)
          │               │             │       │         │             └ {'User-Agent': 'Mozilla/5.0 (X11; Linux x86_64) AppleWebKit/537.36 (KHTML, like Gecko) Chrome/93.0.4577.63 Safari/537.36', 'A...
          │               │             │       │         └ None
          │               │             │       └ '/board/1.html'
          │               │             └ 'GET'
          │               └ <urllib3.connection.HTTPConnection object at 0x7f916008ae50>
          └ <class 'urllib3.connection.HTTPConnection'>
  File "/usr/lib/python3.8/http/client.py", line 1256, in request
    self._send_request(method, url, body, headers, encode_chunked)
    │    │             │       │    │     │        └ False
    │    │             │       │    │     └ {'User-Agent': 'Mozilla/5.0 (X11; Linux x86_64) AppleWebKit/537.36 (KHTML, like Gecko) Chrome/93.0.4577.63 Safari/537.36', 'A...
    │    │             │       │    └ None
    │    │             │       └ '/board/1.html'
    │    │             └ 'GET'
    │    └ <function HTTPConnection._send_request at 0x7f926be50280>
    └ <urllib3.connection.HTTPConnection object at 0x7f916008ae50>
  File "/usr/lib/python3.8/http/client.py", line 1302, in _send_request
    self.endheaders(body, encode_chunked=encode_chunked)
    │    │          │                    └ False
    │    │          └ None
    │    └ <function HTTPConnection.endheaders at 0x7f926be50160>
    └ <urllib3.connection.HTTPConnection object at 0x7f916008ae50>
  File "/usr/lib/python3.8/http/client.py", line 1251, in endheaders
    self._send_output(message_body, encode_chunked=encode_chunked)
    │    │            │                            └ False
    │    │            └ None
    │    └ <function HTTPConnection._send_output at 0x7f926beb7d30>
    └ <urllib3.connection.HTTPConnection object at 0x7f916008ae50>
  File "/usr/lib/python3.8/http/client.py", line 1011, in _send_output
    self.send(msg)
    │    │    └ b'GET /board/1.html HTTP/1.1\r\nHost: bbs1.people.com.cn\r\nUser-Agent: Mozilla/5.0 (X11; Linux x86_64) AppleWebKit/537.36 (K...
    │    └ <function HTTPConnection.send at 0x7f926beb7b80>
    └ <urllib3.connection.HTTPConnection object at 0x7f916008ae50>
  File "/usr/lib/python3.8/http/client.py", line 951, in send
    self.connect()
    │    └ <function HTTPConnection.connect at 0x7f92585b0dc0>
    └ <urllib3.connection.HTTPConnection object at 0x7f916008ae50>
  File "/home/chase/.local/lib/python3.8/site-packages/urllib3/connection.py", line 205, in connect
    conn = self._new_conn()
           │    └ <function HTTPConnection._new_conn at 0x7f92585b0c10>
           └ <urllib3.connection.HTTPConnection object at 0x7f916008ae50>
  File "/home/chase/.local/lib/python3.8/site-packages/urllib3/connection.py", line 186, in _new_conn
    raise NewConnectionError(
          └ <class 'urllib3.exceptions.NewConnectionError'>

urllib3.exceptions.NewConnectionError: <urllib3.connection.HTTPConnection object at 0x7f916008ae50>: Failed to establish a new connection: [Errno 111] Connection refused


During handling of the above exception, another exception occurred:


Traceback (most recent call last):

  File "/home/chase/.local/lib/python3.8/site-packages/requests/adapters.py", line 439, in send
    resp = conn.urlopen(
           │    └ <function HTTPConnectionPool.urlopen at 0x7f92585c0820>
           └ <urllib3.connectionpool.HTTPConnectionPool object at 0x7f916003d040>
  File "/home/chase/.local/lib/python3.8/site-packages/urllib3/connectionpool.py", line 755, in urlopen
    retries = retries.increment(
              │       └ <function Retry.increment at 0x7f9258608b80>
              └ Retry(total=0, connect=None, read=False, redirect=None, status=None)
  File "/home/chase/.local/lib/python3.8/site-packages/urllib3/util/retry.py", line 574, in increment
    raise MaxRetryError(_pool, url, error or ResponseError(cause))
          │             │      │    │        │             └ 'unknown'
          │             │      │    │        └ <class 'urllib3.exceptions.ResponseError'>
          │             │      │    └ NewConnectionError('<urllib3.connection.HTTPConnection object at 0x7f916008ae50>: Failed to establish a new connection: [Errn...
          │             │      └ '/board/1.html'
          │             └ <urllib3.connectionpool.HTTPConnectionPool object at 0x7f916003d040>
          └ <class 'urllib3.exceptions.MaxRetryError'>

urllib3.exceptions.MaxRetryError: HTTPConnectionPool(host='bbs1.people.com.cn', port=80): Max retries exceeded with url: /board/1.html (Caused by NewConnectionError('<urllib3.connection.HTTPConnection object at 0x7f916008ae50>: Failed to establish a new connection: [Errno 111] Connection refused'))


During handling of the above exception, another exception occurred:


Traceback (most recent call last):

  File "/usr/lib/python3.8/threading.py", line 890, in _bootstrap
    self._bootstrap_inner()
    │    └ <function Thread._bootstrap_inner at 0x7f927a614a60>
    └ <Thread(Thread-226, started daemon 140258708539136)>
  File "/usr/lib/python3.8/threading.py", line 932, in _bootstrap_inner
    self.run()
    │    └ <function Thread.run at 0x7f927a614790>
    └ <Thread(Thread-226, started daemon 140258708539136)>
  File "/usr/lib/python3.8/threading.py", line 870, in run
    self._target(*self._args, **self._kwargs)
    │    │        │    │        │    └ {}
    │    │        │    │        └ <Thread(Thread-226, started daemon 140258708539136)>
    │    │        │    └ ('ProjectManager.run_func_by_thread',)
    │    │        └ <Thread(Thread-226, started daemon 140258708539136)>
    │    └ <bound method ProjectManager.get_request_from_keywords_hot of <monitor.projectManager.ProjectManager object at 0x7f9162af4700>>
    └ <Thread(Thread-226, started daemon 140258708539136)>

  File "/home/users/Scy/yuqing/spider/monitor/projectManager.py", line 795, in get_request_from_keywords_hot
    self.search_spider_manager.crawl_by_keyword(
    │    │                     └ <function SearchSpidersManager.crawl_by_keyword at 0x7f9162b00040>
    │    └ <monitor.spiderManager.SearchSpidersManager object at 0x7f916270f0d0>
    └ <monitor.projectManager.ProjectManager object at 0x7f9162af4700>

  File "/home/users/Scy/yuqing/spider/monitor/spiderManager.py", line 118, in crawl_by_keyword
    self.crawl_by_keyword_signal_platform(project_names, platform, keyword, crawl_time, project_times)
    │    │                                │              │         │        │           └ {'default': <monitor.TimeSection object at 0x7f91628317f0>}
    │    │                                │              │         │        └ <monitor.TimeSection object at 0x7f91481ea730>
    │    │                                │              │         └ '伊拉克底格里斯河水位下降'
    │    │                                │              └ '强国论坛'
    │    │                                └ ['default']
    │    └ <function SearchSpidersManager.crawl_by_keyword_signal_platform at 0x7f9162b000d0>
    └ <monitor.spiderManager.SearchSpidersManager object at 0x7f916270f0d0>

  File "/home/users/Scy/yuqing/spider/monitor/spiderManager.py", line 134, in crawl_by_keyword_signal_platform
    requests = self.get_request_from_keyword(platform, keyword, **crawl_time.to_dict())
               │    │                        │         │          │          └ <function TimeSection.to_dict at 0x7f925aaa8550>
               │    │                        │         │          └ <monitor.TimeSection object at 0x7f91481ea730>
               │    │                        │         └ '伊拉克底格里斯河水位下降'
               │    │                        └ '强国论坛'
               │    └ <function SearchSpidersManager.get_request_from_keyword at 0x7f9162b001f0>
               └ <monitor.spiderManager.SearchSpidersManager object at 0x7f916270f0d0>

  File "/home/users/Scy/yuqing/spider/monitor/spiderManager.py", line 191, in get_request_from_keyword
    for request in self.spiders[platform].get_request_from_keyword(headers, search_url, keyword, content_url,
                   │    │       │                                  │        │           │        └ <string.Template object at 0x7f91243e3070>
                   │    │       │                                  │        │           └ '伊拉克底格里斯河水位下降'
                   │    │       │                                  │        └ <string.Template object at 0x7f9253f9e670>
                   │    │       │                                  └ {'Connection': 'keep-alive', 'Cache-Control': 'max-age=0', 'Upgrade-Insecure-Requests': '1', 'User-Agent': 'Mozilla/5.0 (X11;...
                   │    │       └ '强国论坛'
                   │    └ {'凤凰网': <monitor.searchSpiders.ifeng.Ifeng object at 0x7f916270f220>, '头条': <monitor.searchSpiders.toutiao.Toutiao object at ...
                   └ <monitor.spiderManager.SearchSpidersManager object at 0x7f916270f0d0>

> File "/home/users/Scy/yuqing/spider/monitor/searchSpiders/qinagguoLT.py", line 18, in get_request_from_keyword
    response = requests.get(search_url.substitute(), headers=headers)
               │        │   │          │                     └ {'Connection': 'keep-alive', 'Cache-Control': 'max-age=0', 'Upgrade-Insecure-Requests': '1', 'User-Agent': 'Mozilla/5.0 (X11;...
               │        │   │          └ <function Template.substitute at 0x7f927a5fd0d0>
               │        │   └ <string.Template object at 0x7f9253f9e670>
               │        └ <function get at 0x7f92583e71f0>
               └ <module 'requests' from '/home/chase/.local/lib/python3.8/site-packages/requests/__init__.py'>

  File "/home/chase/.local/lib/python3.8/site-packages/requests/api.py", line 75, in get
    return request('get', url, params=params, **kwargs)
           │              │           │         └ {'headers': {'Connection': 'keep-alive', 'Cache-Control': 'max-age=0', 'Upgrade-Insecure-Requests': '1', 'User-Agent': 'Mozil...
           │              │           └ None
           │              └ 'http://bbs1.people.com.cn/board/1.html'
           └ <function request at 0x7f9258455040>
  File "/home/chase/.local/lib/python3.8/site-packages/requests/api.py", line 61, in request
    return session.request(method=method, url=url, **kwargs)
           │       │              │           │      └ {'params': None, 'headers': {'Connection': 'keep-alive', 'Cache-Control': 'max-age=0', 'Upgrade-Insecure-Requests': '1', 'Use...
           │       │              │           └ 'http://bbs1.people.com.cn/board/1.html'
           │       │              └ 'get'
           │       └ <function Session.request at 0x7f92583e6940>
           └ <requests.sessions.Session object at 0x7f9124618490>
  File "/home/chase/.local/lib/python3.8/site-packages/requests/sessions.py", line 542, in request
    resp = self.send(prep, **send_kwargs)
           │    │    │       └ {'timeout': None, 'allow_redirects': True, 'verify': True, 'proxies': OrderedDict(), 'stream': False, 'cert': None}
           │    │    └ <PreparedRequest [GET]>
           │    └ <function Session.send at 0x7f92583e6dc0>
           └ <requests.sessions.Session object at 0x7f9124618490>
  File "/home/chase/.local/lib/python3.8/site-packages/requests/sessions.py", line 655, in send
    r = adapter.send(request, **kwargs)
        │       │    │          └ {'timeout': None, 'verify': True, 'proxies': OrderedDict(), 'stream': False, 'cert': None}
        │       │    └ <PreparedRequest [GET]>
        │       └ <function HTTPAdapter.send at 0x7f92583e6280>
        └ <requests.adapters.HTTPAdapter object at 0x7f90e4611fd0>
  File "/home/chase/.local/lib/python3.8/site-packages/requests/adapters.py", line 516, in send
    raise ConnectionError(e, request=request)
          │                          └ <PreparedRequest [GET]>
          └ <class 'requests.exceptions.ConnectionError'>

requests.exceptions.ConnectionError: HTTPConnectionPool(host='bbs1.people.com.cn', port=80): Max retries exceeded with url: /board/1.html (Caused by NewConnectionError('<urllib3.connection.HTTPConnection object at 0x7f916008ae50>: Failed to establish a new connection: [Errno 111] Connection refused'))
2022-05-12 15:53:15.791 | ERROR    | monitor.searchSpiders.qinagguoLT:get_request_from_keyword:27 - E 强国论坛错误HTTPConnectionPool(host='bbs1.people.com.cn', port=80): Max retries exceeded with url: /board/1.html (Caused by NewConnectionError('<urllib3.connection.HTTPConnection object at 0x7f9253e7c130>: Failed to establish a new connection: [Errno 111] Connection refused'))
Traceback (most recent call last):

  File "/home/chase/.local/lib/python3.8/site-packages/urllib3/connection.py", line 174, in _new_conn
    conn = connection.create_connection(
           │          └ <function create_connection at 0x7f92585fd1f0>
           └ <module 'urllib3.util.connection' from '/home/chase/.local/lib/python3.8/site-packages/urllib3/util/connection.py'>
  File "/home/chase/.local/lib/python3.8/site-packages/urllib3/util/connection.py", line 96, in create_connection
    raise err
          └ ConnectionRefusedError(111, 'Connection refused')
  File "/home/chase/.local/lib/python3.8/site-packages/urllib3/util/connection.py", line 86, in create_connection
    sock.connect(sa)
    │            └ ('118.212.233.223', 80)
    └ None

ConnectionRefusedError: [Errno 111] Connection refused


During handling of the above exception, another exception occurred:


Traceback (most recent call last):

  File "/home/chase/.local/lib/python3.8/site-packages/urllib3/connectionpool.py", line 699, in urlopen
    httplib_response = self._make_request(
                       │    └ <function HTTPConnectionPool._make_request at 0x7f92585c05e0>
                       └ <urllib3.connectionpool.HTTPConnectionPool object at 0x7f910428d190>
  File "/home/chase/.local/lib/python3.8/site-packages/urllib3/connectionpool.py", line 394, in _make_request
    conn.request(method, url, **httplib_request_kw)
    │    │       │       │      └ {'body': None, 'headers': {'User-Agent': 'Mozilla/5.0 (X11; Linux x86_64) AppleWebKit/537.36 (KHTML, like Gecko) Chrome/93.0....
    │    │       │       └ '/board/1.html'
    │    │       └ 'GET'
    │    └ <function HTTPConnection.request at 0x7f92585b0f70>
    └ <urllib3.connection.HTTPConnection object at 0x7f9253e7c130>
  File "/home/chase/.local/lib/python3.8/site-packages/urllib3/connection.py", line 239, in request
    super(HTTPConnection, self).request(method, url, body=body, headers=headers)
          │               │             │       │         │             └ {'User-Agent': 'Mozilla/5.0 (X11; Linux x86_64) AppleWebKit/537.36 (KHTML, like Gecko) Chrome/93.0.4577.63 Safari/537.36', 'A...
          │               │             │       │         └ None
          │               │             │       └ '/board/1.html'
          │               │             └ 'GET'
          │               └ <urllib3.connection.HTTPConnection object at 0x7f9253e7c130>
          └ <class 'urllib3.connection.HTTPConnection'>
  File "/usr/lib/python3.8/http/client.py", line 1256, in request
    self._send_request(method, url, body, headers, encode_chunked)
    │    │             │       │    │     │        └ False
    │    │             │       │    │     └ {'User-Agent': 'Mozilla/5.0 (X11; Linux x86_64) AppleWebKit/537.36 (KHTML, like Gecko) Chrome/93.0.4577.63 Safari/537.36', 'A...
    │    │             │       │    └ None
    │    │             │       └ '/board/1.html'
    │    │             └ 'GET'
    │    └ <function HTTPConnection._send_request at 0x7f926be50280>
    └ <urllib3.connection.HTTPConnection object at 0x7f9253e7c130>
  File "/usr/lib/python3.8/http/client.py", line 1302, in _send_request
    self.endheaders(body, encode_chunked=encode_chunked)
    │    │          │                    └ False
    │    │          └ None
    │    └ <function HTTPConnection.endheaders at 0x7f926be50160>
    └ <urllib3.connection.HTTPConnection object at 0x7f9253e7c130>
  File "/usr/lib/python3.8/http/client.py", line 1251, in endheaders
    self._send_output(message_body, encode_chunked=encode_chunked)
    │    │            │                            └ False
    │    │            └ None
    │    └ <function HTTPConnection._send_output at 0x7f926beb7d30>
    └ <urllib3.connection.HTTPConnection object at 0x7f9253e7c130>
  File "/usr/lib/python3.8/http/client.py", line 1011, in _send_output
    self.send(msg)
    │    │    └ b'GET /board/1.html HTTP/1.1\r\nHost: bbs1.people.com.cn\r\nUser-Agent: Mozilla/5.0 (X11; Linux x86_64) AppleWebKit/537.36 (K...
    │    └ <function HTTPConnection.send at 0x7f926beb7b80>
    └ <urllib3.connection.HTTPConnection object at 0x7f9253e7c130>
  File "/usr/lib/python3.8/http/client.py", line 951, in send
    self.connect()
    │    └ <function HTTPConnection.connect at 0x7f92585b0dc0>
    └ <urllib3.connection.HTTPConnection object at 0x7f9253e7c130>
  File "/home/chase/.local/lib/python3.8/site-packages/urllib3/connection.py", line 205, in connect
    conn = self._new_conn()
           │    └ <function HTTPConnection._new_conn at 0x7f92585b0c10>
           └ <urllib3.connection.HTTPConnection object at 0x7f9253e7c130>
  File "/home/chase/.local/lib/python3.8/site-packages/urllib3/connection.py", line 186, in _new_conn
    raise NewConnectionError(
          └ <class 'urllib3.exceptions.NewConnectionError'>

urllib3.exceptions.NewConnectionError: <urllib3.connection.HTTPConnection object at 0x7f9253e7c130>: Failed to establish a new connection: [Errno 111] Connection refused


During handling of the above exception, another exception occurred:


Traceback (most recent call last):

  File "/home/chase/.local/lib/python3.8/site-packages/requests/adapters.py", line 439, in send
    resp = conn.urlopen(
           │    └ <function HTTPConnectionPool.urlopen at 0x7f92585c0820>
           └ <urllib3.connectionpool.HTTPConnectionPool object at 0x7f910428d190>
  File "/home/chase/.local/lib/python3.8/site-packages/urllib3/connectionpool.py", line 755, in urlopen
    retries = retries.increment(
              │       └ <function Retry.increment at 0x7f9258608b80>
              └ Retry(total=0, connect=None, read=False, redirect=None, status=None)
  File "/home/chase/.local/lib/python3.8/site-packages/urllib3/util/retry.py", line 574, in increment
    raise MaxRetryError(_pool, url, error or ResponseError(cause))
          │             │      │    │        │             └ 'unknown'
          │             │      │    │        └ <class 'urllib3.exceptions.ResponseError'>
          │             │      │    └ NewConnectionError('<urllib3.connection.HTTPConnection object at 0x7f9253e7c130>: Failed to establish a new connection: [Errn...
          │             │      └ '/board/1.html'
          │             └ <urllib3.connectionpool.HTTPConnectionPool object at 0x7f910428d190>
          └ <class 'urllib3.exceptions.MaxRetryError'>

urllib3.exceptions.MaxRetryError: HTTPConnectionPool(host='bbs1.people.com.cn', port=80): Max retries exceeded with url: /board/1.html (Caused by NewConnectionError('<urllib3.connection.HTTPConnection object at 0x7f9253e7c130>: Failed to establish a new connection: [Errno 111] Connection refused'))


During handling of the above exception, another exception occurred:


Traceback (most recent call last):

  File "/usr/lib/python3.8/threading.py", line 890, in _bootstrap
    self._bootstrap_inner()
    │    └ <function Thread._bootstrap_inner at 0x7f927a614a60>
    └ <Thread(Thread-124, started daemon 140260335937280)>
  File "/usr/lib/python3.8/threading.py", line 932, in _bootstrap_inner
    self.run()
    │    └ <function Thread.run at 0x7f927a614790>
    └ <Thread(Thread-124, started daemon 140260335937280)>
  File "/usr/lib/python3.8/threading.py", line 870, in run
    self._target(*self._args, **self._kwargs)
    │    │        │    │        │    └ {}
    │    │        │    │        └ <Thread(Thread-124, started daemon 140260335937280)>
    │    │        │    └ ('ProjectManager.run_func_by_thread',)
    │    │        └ <Thread(Thread-124, started daemon 140260335937280)>
    │    └ <bound method ProjectManager.get_request_from_keywords_hot of <monitor.projectManager.ProjectManager object at 0x7f9162af4700>>
    └ <Thread(Thread-124, started daemon 140260335937280)>

  File "/home/users/Scy/yuqing/spider/monitor/projectManager.py", line 795, in get_request_from_keywords_hot
    self.search_spider_manager.crawl_by_keyword(
    │    │                     └ <function SearchSpidersManager.crawl_by_keyword at 0x7f9162b00040>
    │    └ <monitor.spiderManager.SearchSpidersManager object at 0x7f916270f0d0>
    └ <monitor.projectManager.ProjectManager object at 0x7f9162af4700>

  File "/home/users/Scy/yuqing/spider/monitor/spiderManager.py", line 118, in crawl_by_keyword
    self.crawl_by_keyword_signal_platform(project_names, platform, keyword, crawl_time, project_times)
    │    │                                │              │         │        │           └ {'default': <monitor.TimeSection object at 0x7f91628317f0>}
    │    │                                │              │         │        └ <monitor.TimeSection object at 0x7f91484a1fa0>
    │    │                                │              │         └ '埃及安全部队打死14名恐怖分子'
    │    │                                │              └ '强国论坛'
    │    │                                └ ['default']
    │    └ <function SearchSpidersManager.crawl_by_keyword_signal_platform at 0x7f9162b000d0>
    └ <monitor.spiderManager.SearchSpidersManager object at 0x7f916270f0d0>

  File "/home/users/Scy/yuqing/spider/monitor/spiderManager.py", line 134, in crawl_by_keyword_signal_platform
    requests = self.get_request_from_keyword(platform, keyword, **crawl_time.to_dict())
               │    │                        │         │          │          └ <function TimeSection.to_dict at 0x7f925aaa8550>
               │    │                        │         │          └ <monitor.TimeSection object at 0x7f91484a1fa0>
               │    │                        │         └ '埃及安全部队打死14名恐怖分子'
               │    │                        └ '强国论坛'
               │    └ <function SearchSpidersManager.get_request_from_keyword at 0x7f9162b001f0>
               └ <monitor.spiderManager.SearchSpidersManager object at 0x7f916270f0d0>

  File "/home/users/Scy/yuqing/spider/monitor/spiderManager.py", line 191, in get_request_from_keyword
    for request in self.spiders[platform].get_request_from_keyword(headers, search_url, keyword, content_url,
                   │    │       │                                  │        │           │        └ <string.Template object at 0x7f912436ae50>
                   │    │       │                                  │        │           └ '埃及安全部队打死14名恐怖分子'
                   │    │       │                                  │        └ <string.Template object at 0x7f90e46bf220>
                   │    │       │                                  └ {'Connection': 'keep-alive', 'Cache-Control': 'max-age=0', 'Upgrade-Insecure-Requests': '1', 'User-Agent': 'Mozilla/5.0 (X11;...
                   │    │       └ '强国论坛'
                   │    └ {'凤凰网': <monitor.searchSpiders.ifeng.Ifeng object at 0x7f916270f220>, '头条': <monitor.searchSpiders.toutiao.Toutiao object at ...
                   └ <monitor.spiderManager.SearchSpidersManager object at 0x7f916270f0d0>

> File "/home/users/Scy/yuqing/spider/monitor/searchSpiders/qinagguoLT.py", line 18, in get_request_from_keyword
    response = requests.get(search_url.substitute(), headers=headers)
               │        │   │          │                     └ {'Connection': 'keep-alive', 'Cache-Control': 'max-age=0', 'Upgrade-Insecure-Requests': '1', 'User-Agent': 'Mozilla/5.0 (X11;...
               │        │   │          └ <function Template.substitute at 0x7f927a5fd0d0>
               │        │   └ <string.Template object at 0x7f90e46bf220>
               │        └ <function get at 0x7f92583e71f0>
               └ <module 'requests' from '/home/chase/.local/lib/python3.8/site-packages/requests/__init__.py'>

  File "/home/chase/.local/lib/python3.8/site-packages/requests/api.py", line 75, in get
    return request('get', url, params=params, **kwargs)
           │              │           │         └ {'headers': {'Connection': 'keep-alive', 'Cache-Control': 'max-age=0', 'Upgrade-Insecure-Requests': '1', 'User-Agent': 'Mozil...
           │              │           └ None
           │              └ 'http://bbs1.people.com.cn/board/1.html'
           └ <function request at 0x7f9258455040>
  File "/home/chase/.local/lib/python3.8/site-packages/requests/api.py", line 61, in request
    return session.request(method=method, url=url, **kwargs)
           │       │              │           │      └ {'params': None, 'headers': {'Connection': 'keep-alive', 'Cache-Control': 'max-age=0', 'Upgrade-Insecure-Requests': '1', 'Use...
           │       │              │           └ 'http://bbs1.people.com.cn/board/1.html'
           │       │              └ 'get'
           │       └ <function Session.request at 0x7f92583e6940>
           └ <requests.sessions.Session object at 0x7f91247290a0>
  File "/home/chase/.local/lib/python3.8/site-packages/requests/sessions.py", line 542, in request
    resp = self.send(prep, **send_kwargs)
           │    │    │       └ {'timeout': None, 'allow_redirects': True, 'verify': True, 'proxies': OrderedDict(), 'stream': False, 'cert': None}
           │    │    └ <PreparedRequest [GET]>
           │    └ <function Session.send at 0x7f92583e6dc0>
           └ <requests.sessions.Session object at 0x7f91247290a0>
  File "/home/chase/.local/lib/python3.8/site-packages/requests/sessions.py", line 655, in send
    r = adapter.send(request, **kwargs)
        │       │    │          └ {'timeout': None, 'verify': True, 'proxies': OrderedDict(), 'stream': False, 'cert': None}
        │       │    └ <PreparedRequest [GET]>
        │       └ <function HTTPAdapter.send at 0x7f92583e6280>
        └ <requests.adapters.HTTPAdapter object at 0x7f91486ac0d0>
  File "/home/chase/.local/lib/python3.8/site-packages/requests/adapters.py", line 516, in send
    raise ConnectionError(e, request=request)
          │                          └ <PreparedRequest [GET]>
          └ <class 'requests.exceptions.ConnectionError'>

requests.exceptions.ConnectionError: HTTPConnectionPool(host='bbs1.people.com.cn', port=80): Max retries exceeded with url: /board/1.html (Caused by NewConnectionError('<urllib3.connection.HTTPConnection object at 0x7f9253e7c130>: Failed to establish a new connection: [Errno 111] Connection refused'))
2022-05-12 15:53:16.395 | ERROR    | monitor.searchSpiders.qinagguoLT:get_request_from_keyword:27 - E 强国论坛错误HTTPConnectionPool(host='bbs1.people.com.cn', port=80): Max retries exceeded with url: /board/1.html (Caused by NewConnectionError('<urllib3.connection.HTTPConnection object at 0x7f90e4583580>: Failed to establish a new connection: [Errno 111] Connection refused'))
Traceback (most recent call last):

  File "/home/chase/.local/lib/python3.8/site-packages/urllib3/connection.py", line 174, in _new_conn
    conn = connection.create_connection(
           │          └ <function create_connection at 0x7f92585fd1f0>
           └ <module 'urllib3.util.connection' from '/home/chase/.local/lib/python3.8/site-packages/urllib3/util/connection.py'>
  File "/home/chase/.local/lib/python3.8/site-packages/urllib3/util/connection.py", line 96, in create_connection
    raise err
          └ ConnectionRefusedError(111, 'Connection refused')
  File "/home/chase/.local/lib/python3.8/site-packages/urllib3/util/connection.py", line 86, in create_connection
    sock.connect(sa)
    │            └ ('118.212.233.223', 80)
    └ None

ConnectionRefusedError: [Errno 111] Connection refused


During handling of the above exception, another exception occurred:


Traceback (most recent call last):

  File "/home/chase/.local/lib/python3.8/site-packages/urllib3/connectionpool.py", line 699, in urlopen
    httplib_response = self._make_request(
                       │    └ <function HTTPConnectionPool._make_request at 0x7f92585c05e0>
                       └ <urllib3.connectionpool.HTTPConnectionPool object at 0x7f9253e8ca60>
  File "/home/chase/.local/lib/python3.8/site-packages/urllib3/connectionpool.py", line 394, in _make_request
    conn.request(method, url, **httplib_request_kw)
    │    │       │       │      └ {'body': None, 'headers': {'User-Agent': 'Mozilla/5.0 (X11; Linux x86_64) AppleWebKit/537.36 (KHTML, like Gecko) Chrome/93.0....
    │    │       │       └ '/board/1.html'
    │    │       └ 'GET'
    │    └ <function HTTPConnection.request at 0x7f92585b0f70>
    └ <urllib3.connection.HTTPConnection object at 0x7f90e4583580>
  File "/home/chase/.local/lib/python3.8/site-packages/urllib3/connection.py", line 239, in request
    super(HTTPConnection, self).request(method, url, body=body, headers=headers)
          │               │             │       │         │             └ {'User-Agent': 'Mozilla/5.0 (X11; Linux x86_64) AppleWebKit/537.36 (KHTML, like Gecko) Chrome/93.0.4577.63 Safari/537.36', 'A...
          │               │             │       │         └ None
          │               │             │       └ '/board/1.html'
          │               │             └ 'GET'
          │               └ <urllib3.connection.HTTPConnection object at 0x7f90e4583580>
          └ <class 'urllib3.connection.HTTPConnection'>
  File "/usr/lib/python3.8/http/client.py", line 1256, in request
    self._send_request(method, url, body, headers, encode_chunked)
    │    │             │       │    │     │        └ False
    │    │             │       │    │     └ {'User-Agent': 'Mozilla/5.0 (X11; Linux x86_64) AppleWebKit/537.36 (KHTML, like Gecko) Chrome/93.0.4577.63 Safari/537.36', 'A...
    │    │             │       │    └ None
    │    │             │       └ '/board/1.html'
    │    │             └ 'GET'
    │    └ <function HTTPConnection._send_request at 0x7f926be50280>
    └ <urllib3.connection.HTTPConnection object at 0x7f90e4583580>
  File "/usr/lib/python3.8/http/client.py", line 1302, in _send_request
    self.endheaders(body, encode_chunked=encode_chunked)
    │    │          │                    └ False
    │    │          └ None
    │    └ <function HTTPConnection.endheaders at 0x7f926be50160>
    └ <urllib3.connection.HTTPConnection object at 0x7f90e4583580>
  File "/usr/lib/python3.8/http/client.py", line 1251, in endheaders
    self._send_output(message_body, encode_chunked=encode_chunked)
    │    │            │                            └ False
    │    │            └ None
    │    └ <function HTTPConnection._send_output at 0x7f926beb7d30>
    └ <urllib3.connection.HTTPConnection object at 0x7f90e4583580>
  File "/usr/lib/python3.8/http/client.py", line 1011, in _send_output
    self.send(msg)
    │    │    └ b'GET /board/1.html HTTP/1.1\r\nHost: bbs1.people.com.cn\r\nUser-Agent: Mozilla/5.0 (X11; Linux x86_64) AppleWebKit/537.36 (K...
    │    └ <function HTTPConnection.send at 0x7f926beb7b80>
    └ <urllib3.connection.HTTPConnection object at 0x7f90e4583580>
  File "/usr/lib/python3.8/http/client.py", line 951, in send
    self.connect()
    │    └ <function HTTPConnection.connect at 0x7f92585b0dc0>
    └ <urllib3.connection.HTTPConnection object at 0x7f90e4583580>
  File "/home/chase/.local/lib/python3.8/site-packages/urllib3/connection.py", line 205, in connect
    conn = self._new_conn()
           │    └ <function HTTPConnection._new_conn at 0x7f92585b0c10>
           └ <urllib3.connection.HTTPConnection object at 0x7f90e4583580>
  File "/home/chase/.local/lib/python3.8/site-packages/urllib3/connection.py", line 186, in _new_conn
    raise NewConnectionError(
          └ <class 'urllib3.exceptions.NewConnectionError'>

urllib3.exceptions.NewConnectionError: <urllib3.connection.HTTPConnection object at 0x7f90e4583580>: Failed to establish a new connection: [Errno 111] Connection refused


During handling of the above exception, another exception occurred:


Traceback (most recent call last):

  File "/home/chase/.local/lib/python3.8/site-packages/requests/adapters.py", line 439, in send
    resp = conn.urlopen(
           │    └ <function HTTPConnectionPool.urlopen at 0x7f92585c0820>
           └ <urllib3.connectionpool.HTTPConnectionPool object at 0x7f9253e8ca60>
  File "/home/chase/.local/lib/python3.8/site-packages/urllib3/connectionpool.py", line 755, in urlopen
    retries = retries.increment(
              │       └ <function Retry.increment at 0x7f9258608b80>
              └ Retry(total=0, connect=None, read=False, redirect=None, status=None)
  File "/home/chase/.local/lib/python3.8/site-packages/urllib3/util/retry.py", line 574, in increment
    raise MaxRetryError(_pool, url, error or ResponseError(cause))
          │             │      │    │        │             └ 'unknown'
          │             │      │    │        └ <class 'urllib3.exceptions.ResponseError'>
          │             │      │    └ NewConnectionError('<urllib3.connection.HTTPConnection object at 0x7f90e4583580>: Failed to establish a new connection: [Errn...
          │             │      └ '/board/1.html'
          │             └ <urllib3.connectionpool.HTTPConnectionPool object at 0x7f9253e8ca60>
          └ <class 'urllib3.exceptions.MaxRetryError'>

urllib3.exceptions.MaxRetryError: HTTPConnectionPool(host='bbs1.people.com.cn', port=80): Max retries exceeded with url: /board/1.html (Caused by NewConnectionError('<urllib3.connection.HTTPConnection object at 0x7f90e4583580>: Failed to establish a new connection: [Errno 111] Connection refused'))


During handling of the above exception, another exception occurred:


Traceback (most recent call last):

  File "/usr/lib/python3.8/threading.py", line 890, in _bootstrap
    self._bootstrap_inner()
    │    └ <function Thread._bootstrap_inner at 0x7f927a614a60>
    └ <Thread(Thread-101, started daemon 140260856022784)>
  File "/usr/lib/python3.8/threading.py", line 932, in _bootstrap_inner
    self.run()
    │    └ <function Thread.run at 0x7f927a614790>
    └ <Thread(Thread-101, started daemon 140260856022784)>
  File "/usr/lib/python3.8/threading.py", line 870, in run
    self._target(*self._args, **self._kwargs)
    │    │        │    │        │    └ {}
    │    │        │    │        └ <Thread(Thread-101, started daemon 140260856022784)>
    │    │        │    └ ('ProjectManager.run_func_by_thread',)
    │    │        └ <Thread(Thread-101, started daemon 140260856022784)>
    │    └ <bound method ProjectManager.get_request_from_keywords_hot of <monitor.projectManager.ProjectManager object at 0x7f9162af4700>>
    └ <Thread(Thread-101, started daemon 140260856022784)>

  File "/home/users/Scy/yuqing/spider/monitor/projectManager.py", line 795, in get_request_from_keywords_hot
    self.search_spider_manager.crawl_by_keyword(
    │    │                     └ <function SearchSpidersManager.crawl_by_keyword at 0x7f9162b00040>
    │    └ <monitor.spiderManager.SearchSpidersManager object at 0x7f916270f0d0>
    └ <monitor.projectManager.ProjectManager object at 0x7f9162af4700>

  File "/home/users/Scy/yuqing/spider/monitor/spiderManager.py", line 118, in crawl_by_keyword
    self.crawl_by_keyword_signal_platform(project_names, platform, keyword, crawl_time, project_times)
    │    │                                │              │         │        │           └ {'default': <monitor.TimeSection object at 0x7f91628317f0>}
    │    │                                │              │         │        └ <monitor.TimeSection object at 0x7f91600dc550>
    │    │                                │              │         └ '非洲极端组织武器来源引关注'
    │    │                                │              └ '强国论坛'
    │    │                                └ ['default']
    │    └ <function SearchSpidersManager.crawl_by_keyword_signal_platform at 0x7f9162b000d0>
    └ <monitor.spiderManager.SearchSpidersManager object at 0x7f916270f0d0>

  File "/home/users/Scy/yuqing/spider/monitor/spiderManager.py", line 134, in crawl_by_keyword_signal_platform
    requests = self.get_request_from_keyword(platform, keyword, **crawl_time.to_dict())
               │    │                        │         │          │          └ <function TimeSection.to_dict at 0x7f925aaa8550>
               │    │                        │         │          └ <monitor.TimeSection object at 0x7f91600dc550>
               │    │                        │         └ '非洲极端组织武器来源引关注'
               │    │                        └ '强国论坛'
               │    └ <function SearchSpidersManager.get_request_from_keyword at 0x7f9162b001f0>
               └ <monitor.spiderManager.SearchSpidersManager object at 0x7f916270f0d0>

  File "/home/users/Scy/yuqing/spider/monitor/spiderManager.py", line 191, in get_request_from_keyword
    for request in self.spiders[platform].get_request_from_keyword(headers, search_url, keyword, content_url,
                   │    │       │                                  │        │           │        └ <string.Template object at 0x7f90e4663340>
                   │    │       │                                  │        │           └ '非洲极端组织武器来源引关注'
                   │    │       │                                  │        └ <string.Template object at 0x7f9104182b50>
                   │    │       │                                  └ {'Connection': 'keep-alive', 'Cache-Control': 'max-age=0', 'Upgrade-Insecure-Requests': '1', 'User-Agent': 'Mozilla/5.0 (X11;...
                   │    │       └ '强国论坛'
                   │    └ {'凤凰网': <monitor.searchSpiders.ifeng.Ifeng object at 0x7f916270f220>, '头条': <monitor.searchSpiders.toutiao.Toutiao object at ...
                   └ <monitor.spiderManager.SearchSpidersManager object at 0x7f916270f0d0>

> File "/home/users/Scy/yuqing/spider/monitor/searchSpiders/qinagguoLT.py", line 18, in get_request_from_keyword
    response = requests.get(search_url.substitute(), headers=headers)
               │        │   │          │                     └ {'Connection': 'keep-alive', 'Cache-Control': 'max-age=0', 'Upgrade-Insecure-Requests': '1', 'User-Agent': 'Mozilla/5.0 (X11;...
               │        │   │          └ <function Template.substitute at 0x7f927a5fd0d0>
               │        │   └ <string.Template object at 0x7f9104182b50>
               │        └ <function get at 0x7f92583e71f0>
               └ <module 'requests' from '/home/chase/.local/lib/python3.8/site-packages/requests/__init__.py'>

  File "/home/chase/.local/lib/python3.8/site-packages/requests/api.py", line 75, in get
    return request('get', url, params=params, **kwargs)
           │              │           │         └ {'headers': {'Connection': 'keep-alive', 'Cache-Control': 'max-age=0', 'Upgrade-Insecure-Requests': '1', 'User-Agent': 'Mozil...
           │              │           └ None
           │              └ 'http://bbs1.people.com.cn/board/1.html'
           └ <function request at 0x7f9258455040>
  File "/home/chase/.local/lib/python3.8/site-packages/requests/api.py", line 61, in request
    return session.request(method=method, url=url, **kwargs)
           │       │              │           │      └ {'params': None, 'headers': {'Connection': 'keep-alive', 'Cache-Control': 'max-age=0', 'Upgrade-Insecure-Requests': '1', 'Use...
           │       │              │           └ 'http://bbs1.people.com.cn/board/1.html'
           │       │              └ 'get'
           │       └ <function Session.request at 0x7f92583e6940>
           └ <requests.sessions.Session object at 0x7f91240dc3a0>
  File "/home/chase/.local/lib/python3.8/site-packages/requests/sessions.py", line 542, in request
    resp = self.send(prep, **send_kwargs)
           │    │    │       └ {'timeout': None, 'allow_redirects': True, 'verify': True, 'proxies': OrderedDict(), 'stream': False, 'cert': None}
           │    │    └ <PreparedRequest [GET]>
           │    └ <function Session.send at 0x7f92583e6dc0>
           └ <requests.sessions.Session object at 0x7f91240dc3a0>
  File "/home/chase/.local/lib/python3.8/site-packages/requests/sessions.py", line 655, in send
    r = adapter.send(request, **kwargs)
        │       │    │          └ {'timeout': None, 'verify': True, 'proxies': OrderedDict(), 'stream': False, 'cert': None}
        │       │    └ <PreparedRequest [GET]>
        │       └ <function HTTPAdapter.send at 0x7f92583e6280>
        └ <requests.adapters.HTTPAdapter object at 0x7f91247e9d90>
  File "/home/chase/.local/lib/python3.8/site-packages/requests/adapters.py", line 516, in send
    raise ConnectionError(e, request=request)
          │                          └ <PreparedRequest [GET]>
          └ <class 'requests.exceptions.ConnectionError'>

requests.exceptions.ConnectionError: HTTPConnectionPool(host='bbs1.people.com.cn', port=80): Max retries exceeded with url: /board/1.html (Caused by NewConnectionError('<urllib3.connection.HTTPConnection object at 0x7f90e4583580>: Failed to establish a new connection: [Errno 111] Connection refused'))
2022-05-12 15:53:17.362 | ERROR    | monitor.searchSpiders.qinagguoLT:get_request_from_keyword:27 - E 强国论坛错误HTTPConnectionPool(host='bbs1.people.com.cn', port=80): Max retries exceeded with url: /board/1.html (Caused by NewConnectionError('<urllib3.connection.HTTPConnection object at 0x7f90e47198b0>: Failed to establish a new connection: [Errno 111] Connection refused'))
Traceback (most recent call last):

  File "/home/chase/.local/lib/python3.8/site-packages/urllib3/connection.py", line 174, in _new_conn
    conn = connection.create_connection(
           │          └ <function create_connection at 0x7f92585fd1f0>
           └ <module 'urllib3.util.connection' from '/home/chase/.local/lib/python3.8/site-packages/urllib3/util/connection.py'>
  File "/home/chase/.local/lib/python3.8/site-packages/urllib3/util/connection.py", line 96, in create_connection
    raise err
          └ ConnectionRefusedError(111, 'Connection refused')
  File "/home/chase/.local/lib/python3.8/site-packages/urllib3/util/connection.py", line 86, in create_connection
    sock.connect(sa)
    │            └ ('118.212.233.223', 80)
    └ None

ConnectionRefusedError: [Errno 111] Connection refused


During handling of the above exception, another exception occurred:


Traceback (most recent call last):

  File "/home/chase/.local/lib/python3.8/site-packages/urllib3/connectionpool.py", line 699, in urlopen
    httplib_response = self._make_request(
                       │    └ <function HTTPConnectionPool._make_request at 0x7f92585c05e0>
                       └ <urllib3.connectionpool.HTTPConnectionPool object at 0x7f9160199af0>
  File "/home/chase/.local/lib/python3.8/site-packages/urllib3/connectionpool.py", line 394, in _make_request
    conn.request(method, url, **httplib_request_kw)
    │    │       │       │      └ {'body': None, 'headers': {'User-Agent': 'Mozilla/5.0 (X11; Linux x86_64) AppleWebKit/537.36 (KHTML, like Gecko) Chrome/93.0....
    │    │       │       └ '/board/1.html'
    │    │       └ 'GET'
    │    └ <function HTTPConnection.request at 0x7f92585b0f70>
    └ <urllib3.connection.HTTPConnection object at 0x7f90e47198b0>
  File "/home/chase/.local/lib/python3.8/site-packages/urllib3/connection.py", line 239, in request
    super(HTTPConnection, self).request(method, url, body=body, headers=headers)
          │               │             │       │         │             └ {'User-Agent': 'Mozilla/5.0 (X11; Linux x86_64) AppleWebKit/537.36 (KHTML, like Gecko) Chrome/93.0.4577.63 Safari/537.36', 'A...
          │               │             │       │         └ None
          │               │             │       └ '/board/1.html'
          │               │             └ 'GET'
          │               └ <urllib3.connection.HTTPConnection object at 0x7f90e47198b0>
          └ <class 'urllib3.connection.HTTPConnection'>
  File "/usr/lib/python3.8/http/client.py", line 1256, in request
    self._send_request(method, url, body, headers, encode_chunked)
    │    │             │       │    │     │        └ False
    │    │             │       │    │     └ {'User-Agent': 'Mozilla/5.0 (X11; Linux x86_64) AppleWebKit/537.36 (KHTML, like Gecko) Chrome/93.0.4577.63 Safari/537.36', 'A...
    │    │             │       │    └ None
    │    │             │       └ '/board/1.html'
    │    │             └ 'GET'
    │    └ <function HTTPConnection._send_request at 0x7f926be50280>
    └ <urllib3.connection.HTTPConnection object at 0x7f90e47198b0>
  File "/usr/lib/python3.8/http/client.py", line 1302, in _send_request
    self.endheaders(body, encode_chunked=encode_chunked)
    │    │          │                    └ False
    │    │          └ None
    │    └ <function HTTPConnection.endheaders at 0x7f926be50160>
    └ <urllib3.connection.HTTPConnection object at 0x7f90e47198b0>
  File "/usr/lib/python3.8/http/client.py", line 1251, in endheaders
    self._send_output(message_body, encode_chunked=encode_chunked)
    │    │            │                            └ False
    │    │            └ None
    │    └ <function HTTPConnection._send_output at 0x7f926beb7d30>
    └ <urllib3.connection.HTTPConnection object at 0x7f90e47198b0>
  File "/usr/lib/python3.8/http/client.py", line 1011, in _send_output
    self.send(msg)
    │    │    └ b'GET /board/1.html HTTP/1.1\r\nHost: bbs1.people.com.cn\r\nUser-Agent: Mozilla/5.0 (X11; Linux x86_64) AppleWebKit/537.36 (K...
    │    └ <function HTTPConnection.send at 0x7f926beb7b80>
    └ <urllib3.connection.HTTPConnection object at 0x7f90e47198b0>
  File "/usr/lib/python3.8/http/client.py", line 951, in send
    self.connect()
    │    └ <function HTTPConnection.connect at 0x7f92585b0dc0>
    └ <urllib3.connection.HTTPConnection object at 0x7f90e47198b0>
  File "/home/chase/.local/lib/python3.8/site-packages/urllib3/connection.py", line 205, in connect
    conn = self._new_conn()
           │    └ <function HTTPConnection._new_conn at 0x7f92585b0c10>
           └ <urllib3.connection.HTTPConnection object at 0x7f90e47198b0>
  File "/home/chase/.local/lib/python3.8/site-packages/urllib3/connection.py", line 186, in _new_conn
    raise NewConnectionError(
          └ <class 'urllib3.exceptions.NewConnectionError'>

urllib3.exceptions.NewConnectionError: <urllib3.connection.HTTPConnection object at 0x7f90e47198b0>: Failed to establish a new connection: [Errno 111] Connection refused


During handling of the above exception, another exception occurred:


Traceback (most recent call last):

  File "/home/chase/.local/lib/python3.8/site-packages/requests/adapters.py", line 439, in send
    resp = conn.urlopen(
           │    └ <function HTTPConnectionPool.urlopen at 0x7f92585c0820>
           └ <urllib3.connectionpool.HTTPConnectionPool object at 0x7f9160199af0>
  File "/home/chase/.local/lib/python3.8/site-packages/urllib3/connectionpool.py", line 755, in urlopen
    retries = retries.increment(
              │       └ <function Retry.increment at 0x7f9258608b80>
              └ Retry(total=0, connect=None, read=False, redirect=None, status=None)
  File "/home/chase/.local/lib/python3.8/site-packages/urllib3/util/retry.py", line 574, in increment
    raise MaxRetryError(_pool, url, error or ResponseError(cause))
          │             │      │    │        │             └ 'unknown'
          │             │      │    │        └ <class 'urllib3.exceptions.ResponseError'>
          │             │      │    └ NewConnectionError('<urllib3.connection.HTTPConnection object at 0x7f90e47198b0>: Failed to establish a new connection: [Errn...
          │             │      └ '/board/1.html'
          │             └ <urllib3.connectionpool.HTTPConnectionPool object at 0x7f9160199af0>
          └ <class 'urllib3.exceptions.MaxRetryError'>

urllib3.exceptions.MaxRetryError: HTTPConnectionPool(host='bbs1.people.com.cn', port=80): Max retries exceeded with url: /board/1.html (Caused by NewConnectionError('<urllib3.connection.HTTPConnection object at 0x7f90e47198b0>: Failed to establish a new connection: [Errno 111] Connection refused'))


During handling of the above exception, another exception occurred:


Traceback (most recent call last):

  File "/usr/lib/python3.8/threading.py", line 890, in _bootstrap
    self._bootstrap_inner()
    │    └ <function Thread._bootstrap_inner at 0x7f927a614a60>
    └ <Thread(Thread-180, started daemon 140259270588160)>
  File "/usr/lib/python3.8/threading.py", line 932, in _bootstrap_inner
    self.run()
    │    └ <function Thread.run at 0x7f927a614790>
    └ <Thread(Thread-180, started daemon 140259270588160)>
  File "/usr/lib/python3.8/threading.py", line 870, in run
    self._target(*self._args, **self._kwargs)
    │    │        │    │        │    └ {}
    │    │        │    │        └ <Thread(Thread-180, started daemon 140259270588160)>
    │    │        │    └ ('ProjectManager.run_func_by_thread',)
    │    │        └ <Thread(Thread-180, started daemon 140259270588160)>
    │    └ <bound method ProjectManager.get_request_from_keywords_hot of <monitor.projectManager.ProjectManager object at 0x7f9162af4700>>
    └ <Thread(Thread-180, started daemon 140259270588160)>

  File "/home/users/Scy/yuqing/spider/monitor/projectManager.py", line 795, in get_request_from_keywords_hot
    self.search_spider_manager.crawl_by_keyword(
    │    │                     └ <function SearchSpidersManager.crawl_by_keyword at 0x7f9162b00040>
    │    └ <monitor.spiderManager.SearchSpidersManager object at 0x7f916270f0d0>
    └ <monitor.projectManager.ProjectManager object at 0x7f9162af4700>

  File "/home/users/Scy/yuqing/spider/monitor/spiderManager.py", line 118, in crawl_by_keyword
    self.crawl_by_keyword_signal_platform(project_names, platform, keyword, crawl_time, project_times)
    │    │                                │              │         │        │           └ {'default': <monitor.TimeSection object at 0x7f91628317f0>}
    │    │                                │              │         │        └ <monitor.TimeSection object at 0x7f916040aa90>
    │    │                                │              │         └ '伊拉克底格里斯河水位下降'
    │    │                                │              └ '强国论坛'
    │    │                                └ ['default']
    │    └ <function SearchSpidersManager.crawl_by_keyword_signal_platform at 0x7f9162b000d0>
    └ <monitor.spiderManager.SearchSpidersManager object at 0x7f916270f0d0>

  File "/home/users/Scy/yuqing/spider/monitor/spiderManager.py", line 134, in crawl_by_keyword_signal_platform
    requests = self.get_request_from_keyword(platform, keyword, **crawl_time.to_dict())
               │    │                        │         │          │          └ <function TimeSection.to_dict at 0x7f925aaa8550>
               │    │                        │         │          └ <monitor.TimeSection object at 0x7f916040aa90>
               │    │                        │         └ '伊拉克底格里斯河水位下降'
               │    │                        └ '强国论坛'
               │    └ <function SearchSpidersManager.get_request_from_keyword at 0x7f9162b001f0>
               └ <monitor.spiderManager.SearchSpidersManager object at 0x7f916270f0d0>

  File "/home/users/Scy/yuqing/spider/monitor/spiderManager.py", line 191, in get_request_from_keyword
    for request in self.spiders[platform].get_request_from_keyword(headers, search_url, keyword, content_url,
                   │    │       │                                  │        │           │        └ <string.Template object at 0x7f91487691f0>
                   │    │       │                                  │        │           └ '伊拉克底格里斯河水位下降'
                   │    │       │                                  │        └ <string.Template object at 0x7f91240f3c70>
                   │    │       │                                  └ {'Connection': 'keep-alive', 'Cache-Control': 'max-age=0', 'Upgrade-Insecure-Requests': '1', 'User-Agent': 'Mozilla/5.0 (X11;...
                   │    │       └ '强国论坛'
                   │    └ {'凤凰网': <monitor.searchSpiders.ifeng.Ifeng object at 0x7f916270f220>, '头条': <monitor.searchSpiders.toutiao.Toutiao object at ...
                   └ <monitor.spiderManager.SearchSpidersManager object at 0x7f916270f0d0>

> File "/home/users/Scy/yuqing/spider/monitor/searchSpiders/qinagguoLT.py", line 18, in get_request_from_keyword
    response = requests.get(search_url.substitute(), headers=headers)
               │        │   │          │                     └ {'Connection': 'keep-alive', 'Cache-Control': 'max-age=0', 'Upgrade-Insecure-Requests': '1', 'User-Agent': 'Mozilla/5.0 (X11;...
               │        │   │          └ <function Template.substitute at 0x7f927a5fd0d0>
               │        │   └ <string.Template object at 0x7f91240f3c70>
               │        └ <function get at 0x7f92583e71f0>
               └ <module 'requests' from '/home/chase/.local/lib/python3.8/site-packages/requests/__init__.py'>

  File "/home/chase/.local/lib/python3.8/site-packages/requests/api.py", line 75, in get
    return request('get', url, params=params, **kwargs)
           │              │           │         └ {'headers': {'Connection': 'keep-alive', 'Cache-Control': 'max-age=0', 'Upgrade-Insecure-Requests': '1', 'User-Agent': 'Mozil...
           │              │           └ None
           │              └ 'http://bbs1.people.com.cn/board/1.html'
           └ <function request at 0x7f9258455040>
  File "/home/chase/.local/lib/python3.8/site-packages/requests/api.py", line 61, in request
    return session.request(method=method, url=url, **kwargs)
           │       │              │           │      └ {'params': None, 'headers': {'Connection': 'keep-alive', 'Cache-Control': 'max-age=0', 'Upgrade-Insecure-Requests': '1', 'Use...
           │       │              │           └ 'http://bbs1.people.com.cn/board/1.html'
           │       │              └ 'get'
           │       └ <function Session.request at 0x7f92583e6940>
           └ <requests.sessions.Session object at 0x7f90e46dabb0>
  File "/home/chase/.local/lib/python3.8/site-packages/requests/sessions.py", line 542, in request
    resp = self.send(prep, **send_kwargs)
           │    │    │       └ {'timeout': None, 'allow_redirects': True, 'verify': True, 'proxies': OrderedDict(), 'stream': False, 'cert': None}
           │    │    └ <PreparedRequest [GET]>
           │    └ <function Session.send at 0x7f92583e6dc0>
           └ <requests.sessions.Session object at 0x7f90e46dabb0>
  File "/home/chase/.local/lib/python3.8/site-packages/requests/sessions.py", line 655, in send
    r = adapter.send(request, **kwargs)
        │       │    │          └ {'timeout': None, 'verify': True, 'proxies': OrderedDict(), 'stream': False, 'cert': None}
        │       │    └ <PreparedRequest [GET]>
        │       └ <function HTTPAdapter.send at 0x7f92583e6280>
        └ <requests.adapters.HTTPAdapter object at 0x7f91241e72e0>
  File "/home/chase/.local/lib/python3.8/site-packages/requests/adapters.py", line 516, in send
    raise ConnectionError(e, request=request)
          │                          └ <PreparedRequest [GET]>
          └ <class 'requests.exceptions.ConnectionError'>

requests.exceptions.ConnectionError: HTTPConnectionPool(host='bbs1.people.com.cn', port=80): Max retries exceeded with url: /board/1.html (Caused by NewConnectionError('<urllib3.connection.HTTPConnection object at 0x7f90e47198b0>: Failed to establish a new connection: [Errno 111] Connection refused'))
2022-05-12 15:53:18.122 | ERROR    | monitor.searchSpiders.qinagguoLT:get_request_from_keyword:27 - E 强国论坛错误HTTPConnectionPool(host='bbs1.people.com.cn', port=80): Max retries exceeded with url: /board/1.html (Caused by NewConnectionError('<urllib3.connection.HTTPConnection object at 0x7f91241e01c0>: Failed to establish a new connection: [Errno 111] Connection refused'))
Traceback (most recent call last):

  File "/home/chase/.local/lib/python3.8/site-packages/urllib3/connection.py", line 174, in _new_conn
    conn = connection.create_connection(
           │          └ <function create_connection at 0x7f92585fd1f0>
           └ <module 'urllib3.util.connection' from '/home/chase/.local/lib/python3.8/site-packages/urllib3/util/connection.py'>
  File "/home/chase/.local/lib/python3.8/site-packages/urllib3/util/connection.py", line 96, in create_connection
    raise err
          └ ConnectionRefusedError(111, 'Connection refused')
  File "/home/chase/.local/lib/python3.8/site-packages/urllib3/util/connection.py", line 86, in create_connection
    sock.connect(sa)
    │            └ ('1.31.128.212', 80)
    └ None

ConnectionRefusedError: [Errno 111] Connection refused


During handling of the above exception, another exception occurred:


Traceback (most recent call last):

  File "/home/chase/.local/lib/python3.8/site-packages/urllib3/connectionpool.py", line 699, in urlopen
    httplib_response = self._make_request(
                       │    └ <function HTTPConnectionPool._make_request at 0x7f92585c05e0>
                       └ <urllib3.connectionpool.HTTPConnectionPool object at 0x7f914858f8b0>
  File "/home/chase/.local/lib/python3.8/site-packages/urllib3/connectionpool.py", line 394, in _make_request
    conn.request(method, url, **httplib_request_kw)
    │    │       │       │      └ {'body': None, 'headers': {'User-Agent': 'Mozilla/5.0 (X11; Linux x86_64) AppleWebKit/537.36 (KHTML, like Gecko) Chrome/93.0....
    │    │       │       └ '/board/1.html'
    │    │       └ 'GET'
    │    └ <function HTTPConnection.request at 0x7f92585b0f70>
    └ <urllib3.connection.HTTPConnection object at 0x7f91241e01c0>
  File "/home/chase/.local/lib/python3.8/site-packages/urllib3/connection.py", line 239, in request
    super(HTTPConnection, self).request(method, url, body=body, headers=headers)
          │               │             │       │         │             └ {'User-Agent': 'Mozilla/5.0 (X11; Linux x86_64) AppleWebKit/537.36 (KHTML, like Gecko) Chrome/93.0.4577.63 Safari/537.36', 'A...
          │               │             │       │         └ None
          │               │             │       └ '/board/1.html'
          │               │             └ 'GET'
          │               └ <urllib3.connection.HTTPConnection object at 0x7f91241e01c0>
          └ <class 'urllib3.connection.HTTPConnection'>
  File "/usr/lib/python3.8/http/client.py", line 1256, in request
    self._send_request(method, url, body, headers, encode_chunked)
    │    │             │       │    │     │        └ False
    │    │             │       │    │     └ {'User-Agent': 'Mozilla/5.0 (X11; Linux x86_64) AppleWebKit/537.36 (KHTML, like Gecko) Chrome/93.0.4577.63 Safari/537.36', 'A...
    │    │             │       │    └ None
    │    │             │       └ '/board/1.html'
    │    │             └ 'GET'
    │    └ <function HTTPConnection._send_request at 0x7f926be50280>
    └ <urllib3.connection.HTTPConnection object at 0x7f91241e01c0>
  File "/usr/lib/python3.8/http/client.py", line 1302, in _send_request
    self.endheaders(body, encode_chunked=encode_chunked)
    │    │          │                    └ False
    │    │          └ None
    │    └ <function HTTPConnection.endheaders at 0x7f926be50160>
    └ <urllib3.connection.HTTPConnection object at 0x7f91241e01c0>
  File "/usr/lib/python3.8/http/client.py", line 1251, in endheaders
    self._send_output(message_body, encode_chunked=encode_chunked)
    │    │            │                            └ False
    │    │            └ None
    │    └ <function HTTPConnection._send_output at 0x7f926beb7d30>
    └ <urllib3.connection.HTTPConnection object at 0x7f91241e01c0>
  File "/usr/lib/python3.8/http/client.py", line 1011, in _send_output
    self.send(msg)
    │    │    └ b'GET /board/1.html HTTP/1.1\r\nHost: bbs1.people.com.cn\r\nUser-Agent: Mozilla/5.0 (X11; Linux x86_64) AppleWebKit/537.36 (K...
    │    └ <function HTTPConnection.send at 0x7f926beb7b80>
    └ <urllib3.connection.HTTPConnection object at 0x7f91241e01c0>
  File "/usr/lib/python3.8/http/client.py", line 951, in send
    self.connect()
    │    └ <function HTTPConnection.connect at 0x7f92585b0dc0>
    └ <urllib3.connection.HTTPConnection object at 0x7f91241e01c0>
  File "/home/chase/.local/lib/python3.8/site-packages/urllib3/connection.py", line 205, in connect
    conn = self._new_conn()
           │    └ <function HTTPConnection._new_conn at 0x7f92585b0c10>
           └ <urllib3.connection.HTTPConnection object at 0x7f91241e01c0>
  File "/home/chase/.local/lib/python3.8/site-packages/urllib3/connection.py", line 186, in _new_conn
    raise NewConnectionError(
          └ <class 'urllib3.exceptions.NewConnectionError'>

urllib3.exceptions.NewConnectionError: <urllib3.connection.HTTPConnection object at 0x7f91241e01c0>: Failed to establish a new connection: [Errno 111] Connection refused


During handling of the above exception, another exception occurred:


Traceback (most recent call last):

  File "/home/chase/.local/lib/python3.8/site-packages/requests/adapters.py", line 439, in send
    resp = conn.urlopen(
           │    └ <function HTTPConnectionPool.urlopen at 0x7f92585c0820>
           └ <urllib3.connectionpool.HTTPConnectionPool object at 0x7f914858f8b0>
  File "/home/chase/.local/lib/python3.8/site-packages/urllib3/connectionpool.py", line 755, in urlopen
    retries = retries.increment(
              │       └ <function Retry.increment at 0x7f9258608b80>
              └ Retry(total=0, connect=None, read=False, redirect=None, status=None)
  File "/home/chase/.local/lib/python3.8/site-packages/urllib3/util/retry.py", line 574, in increment
    raise MaxRetryError(_pool, url, error or ResponseError(cause))
          │             │      │    │        │             └ 'unknown'
          │             │      │    │        └ <class 'urllib3.exceptions.ResponseError'>
          │             │      │    └ NewConnectionError('<urllib3.connection.HTTPConnection object at 0x7f91241e01c0>: Failed to establish a new connection: [Errn...
          │             │      └ '/board/1.html'
          │             └ <urllib3.connectionpool.HTTPConnectionPool object at 0x7f914858f8b0>
          └ <class 'urllib3.exceptions.MaxRetryError'>

urllib3.exceptions.MaxRetryError: HTTPConnectionPool(host='bbs1.people.com.cn', port=80): Max retries exceeded with url: /board/1.html (Caused by NewConnectionError('<urllib3.connection.HTTPConnection object at 0x7f91241e01c0>: Failed to establish a new connection: [Errno 111] Connection refused'))


During handling of the above exception, another exception occurred:


Traceback (most recent call last):

  File "/usr/lib/python3.8/threading.py", line 890, in _bootstrap
    self._bootstrap_inner()
    │    └ <function Thread._bootstrap_inner at 0x7f927a614a60>
    └ <Thread(Thread-185, started daemon 140259262195456)>
  File "/usr/lib/python3.8/threading.py", line 932, in _bootstrap_inner
    self.run()
    │    └ <function Thread.run at 0x7f927a614790>
    └ <Thread(Thread-185, started daemon 140259262195456)>
  File "/usr/lib/python3.8/threading.py", line 870, in run
    self._target(*self._args, **self._kwargs)
    │    │        │    │        │    └ {}
    │    │        │    │        └ <Thread(Thread-185, started daemon 140259262195456)>
    │    │        │    └ ('ProjectManager.run_func_by_thread',)
    │    │        └ <Thread(Thread-185, started daemon 140259262195456)>
    │    └ <bound method ProjectManager.get_request_from_keywords_hot of <monitor.projectManager.ProjectManager object at 0x7f9162af4700>>
    └ <Thread(Thread-185, started daemon 140259262195456)>

  File "/home/users/Scy/yuqing/spider/monitor/projectManager.py", line 795, in get_request_from_keywords_hot
    self.search_spider_manager.crawl_by_keyword(
    │    │                     └ <function SearchSpidersManager.crawl_by_keyword at 0x7f9162b00040>
    │    └ <monitor.spiderManager.SearchSpidersManager object at 0x7f916270f0d0>
    └ <monitor.projectManager.ProjectManager object at 0x7f9162af4700>

  File "/home/users/Scy/yuqing/spider/monitor/spiderManager.py", line 118, in crawl_by_keyword
    self.crawl_by_keyword_signal_platform(project_names, platform, keyword, crawl_time, project_times)
    │    │                                │              │         │        │           └ {'default': <monitor.TimeSection object at 0x7f91628317f0>}
    │    │                                │              │         │        └ <monitor.TimeSection object at 0x7f9148263820>
    │    │                                │              │         └ '意大利佛罗伦萨城市景观壮丽'
    │    │                                │              └ '强国论坛'
    │    │                                └ ['default']
    │    └ <function SearchSpidersManager.crawl_by_keyword_signal_platform at 0x7f9162b000d0>
    └ <monitor.spiderManager.SearchSpidersManager object at 0x7f916270f0d0>

  File "/home/users/Scy/yuqing/spider/monitor/spiderManager.py", line 134, in crawl_by_keyword_signal_platform
    requests = self.get_request_from_keyword(platform, keyword, **crawl_time.to_dict())
               │    │                        │         │          │          └ <function TimeSection.to_dict at 0x7f925aaa8550>
               │    │                        │         │          └ <monitor.TimeSection object at 0x7f9148263820>
               │    │                        │         └ '意大利佛罗伦萨城市景观壮丽'
               │    │                        └ '强国论坛'
               │    └ <function SearchSpidersManager.get_request_from_keyword at 0x7f9162b001f0>
               └ <monitor.spiderManager.SearchSpidersManager object at 0x7f916270f0d0>

  File "/home/users/Scy/yuqing/spider/monitor/spiderManager.py", line 191, in get_request_from_keyword
    for request in self.spiders[platform].get_request_from_keyword(headers, search_url, keyword, content_url,
                   │    │       │                                  │        │           │        └ <string.Template object at 0x7f90e4632f40>
                   │    │       │                                  │        │           └ '意大利佛罗伦萨城市景观壮丽'
                   │    │       │                                  │        └ <string.Template object at 0x7f91605c5370>
                   │    │       │                                  └ {'Connection': 'keep-alive', 'Cache-Control': 'max-age=0', 'Upgrade-Insecure-Requests': '1', 'User-Agent': 'Mozilla/5.0 (X11;...
                   │    │       └ '强国论坛'
                   │    └ {'凤凰网': <monitor.searchSpiders.ifeng.Ifeng object at 0x7f916270f220>, '头条': <monitor.searchSpiders.toutiao.Toutiao object at ...
                   └ <monitor.spiderManager.SearchSpidersManager object at 0x7f916270f0d0>

> File "/home/users/Scy/yuqing/spider/monitor/searchSpiders/qinagguoLT.py", line 18, in get_request_from_keyword
    response = requests.get(search_url.substitute(), headers=headers)
               │        │   │          │                     └ {'Connection': 'keep-alive', 'Cache-Control': 'max-age=0', 'Upgrade-Insecure-Requests': '1', 'User-Agent': 'Mozilla/5.0 (X11;...
               │        │   │          └ <function Template.substitute at 0x7f927a5fd0d0>
               │        │   └ <string.Template object at 0x7f91605c5370>
               │        └ <function get at 0x7f92583e71f0>
               └ <module 'requests' from '/home/chase/.local/lib/python3.8/site-packages/requests/__init__.py'>

  File "/home/chase/.local/lib/python3.8/site-packages/requests/api.py", line 75, in get
    return request('get', url, params=params, **kwargs)
           │              │           │         └ {'headers': {'Connection': 'keep-alive', 'Cache-Control': 'max-age=0', 'Upgrade-Insecure-Requests': '1', 'User-Agent': 'Mozil...
           │              │           └ None
           │              └ 'http://bbs1.people.com.cn/board/1.html'
           └ <function request at 0x7f9258455040>
  File "/home/chase/.local/lib/python3.8/site-packages/requests/api.py", line 61, in request
    return session.request(method=method, url=url, **kwargs)
           │       │              │           │      └ {'params': None, 'headers': {'Connection': 'keep-alive', 'Cache-Control': 'max-age=0', 'Upgrade-Insecure-Requests': '1', 'Use...
           │       │              │           └ 'http://bbs1.people.com.cn/board/1.html'
           │       │              └ 'get'
           │       └ <function Session.request at 0x7f92583e6940>
           └ <requests.sessions.Session object at 0x7f90e447f310>
  File "/home/chase/.local/lib/python3.8/site-packages/requests/sessions.py", line 542, in request
    resp = self.send(prep, **send_kwargs)
           │    │    │       └ {'timeout': None, 'allow_redirects': True, 'verify': True, 'proxies': OrderedDict(), 'stream': False, 'cert': None}
           │    │    └ <PreparedRequest [GET]>
           │    └ <function Session.send at 0x7f92583e6dc0>
           └ <requests.sessions.Session object at 0x7f90e447f310>
  File "/home/chase/.local/lib/python3.8/site-packages/requests/sessions.py", line 655, in send
    r = adapter.send(request, **kwargs)
        │       │    │          └ {'timeout': None, 'verify': True, 'proxies': OrderedDict(), 'stream': False, 'cert': None}
        │       │    └ <PreparedRequest [GET]>
        │       └ <function HTTPAdapter.send at 0x7f92583e6280>
        └ <requests.adapters.HTTPAdapter object at 0x7f90e470ed00>
  File "/home/chase/.local/lib/python3.8/site-packages/requests/adapters.py", line 516, in send
    raise ConnectionError(e, request=request)
          │                          └ <PreparedRequest [GET]>
          └ <class 'requests.exceptions.ConnectionError'>

requests.exceptions.ConnectionError: HTTPConnectionPool(host='bbs1.people.com.cn', port=80): Max retries exceeded with url: /board/1.html (Caused by NewConnectionError('<urllib3.connection.HTTPConnection object at 0x7f91241e01c0>: Failed to establish a new connection: [Errno 111] Connection refused'))
