2022-05-12 15:48:42.299 | ERROR    | monitor.searchSpiders.qinagguoLT:get_request_from_keyword:27 - E 强国论坛错误HTTPConnectionPool(host='bbs1.people.com.cn', port=80): Max retries exceeded with url: /board/1.html (Caused by NewConnectionError('<urllib3.connection.HTTPConnection object at 0x7f912418f190>: Failed to establish a new connection: [Errno 111] Connection refused'))
Traceback (most recent call last):

  File "/home/chase/.local/lib/python3.8/site-packages/urllib3/connection.py", line 174, in _new_conn
    conn = connection.create_connection(
           │          └ <function create_connection at 0x7f92585fd1f0>
           └ <module 'urllib3.util.connection' from '/home/chase/.local/lib/python3.8/site-packages/urllib3/util/connection.py'>
  File "/home/chase/.local/lib/python3.8/site-packages/urllib3/util/connection.py", line 96, in create_connection
    raise err
          └ ConnectionRefusedError(111, 'Connection refused')
  File "/home/chase/.local/lib/python3.8/site-packages/urllib3/util/connection.py", line 86, in create_connection
    sock.connect(sa)
    │            └ ('118.212.233.223', 80)
    └ None

ConnectionRefusedError: [Errno 111] Connection refused


During handling of the above exception, another exception occurred:


Traceback (most recent call last):

  File "/home/chase/.local/lib/python3.8/site-packages/urllib3/connectionpool.py", line 699, in urlopen
    httplib_response = self._make_request(
                       │    └ <function HTTPConnectionPool._make_request at 0x7f92585c05e0>
                       └ <urllib3.connectionpool.HTTPConnectionPool object at 0x7f91243e3340>
  File "/home/chase/.local/lib/python3.8/site-packages/urllib3/connectionpool.py", line 394, in _make_request
    conn.request(method, url, **httplib_request_kw)
    │    │       │       │      └ {'body': None, 'headers': {'User-Agent': 'Mozilla/5.0 (X11; Linux x86_64) AppleWebKit/537.36 (KHTML, like Gecko) Chrome/93.0....
    │    │       │       └ '/board/1.html'
    │    │       └ 'GET'
    │    └ <function HTTPConnection.request at 0x7f92585b0f70>
    └ <urllib3.connection.HTTPConnection object at 0x7f912418f190>
  File "/home/chase/.local/lib/python3.8/site-packages/urllib3/connection.py", line 239, in request
    super(HTTPConnection, self).request(method, url, body=body, headers=headers)
          │               │             │       │         │             └ {'User-Agent': 'Mozilla/5.0 (X11; Linux x86_64) AppleWebKit/537.36 (KHTML, like Gecko) Chrome/93.0.4577.63 Safari/537.36', 'A...
          │               │             │       │         └ None
          │               │             │       └ '/board/1.html'
          │               │             └ 'GET'
          │               └ <urllib3.connection.HTTPConnection object at 0x7f912418f190>
          └ <class 'urllib3.connection.HTTPConnection'>
  File "/usr/lib/python3.8/http/client.py", line 1256, in request
    self._send_request(method, url, body, headers, encode_chunked)
    │    │             │       │    │     │        └ False
    │    │             │       │    │     └ {'User-Agent': 'Mozilla/5.0 (X11; Linux x86_64) AppleWebKit/537.36 (KHTML, like Gecko) Chrome/93.0.4577.63 Safari/537.36', 'A...
    │    │             │       │    └ None
    │    │             │       └ '/board/1.html'
    │    │             └ 'GET'
    │    └ <function HTTPConnection._send_request at 0x7f926be50280>
    └ <urllib3.connection.HTTPConnection object at 0x7f912418f190>
  File "/usr/lib/python3.8/http/client.py", line 1302, in _send_request
    self.endheaders(body, encode_chunked=encode_chunked)
    │    │          │                    └ False
    │    │          └ None
    │    └ <function HTTPConnection.endheaders at 0x7f926be50160>
    └ <urllib3.connection.HTTPConnection object at 0x7f912418f190>
  File "/usr/lib/python3.8/http/client.py", line 1251, in endheaders
    self._send_output(message_body, encode_chunked=encode_chunked)
    │    │            │                            └ False
    │    │            └ None
    │    └ <function HTTPConnection._send_output at 0x7f926beb7d30>
    └ <urllib3.connection.HTTPConnection object at 0x7f912418f190>
  File "/usr/lib/python3.8/http/client.py", line 1011, in _send_output
    self.send(msg)
    │    │    └ b'GET /board/1.html HTTP/1.1\r\nHost: bbs1.people.com.cn\r\nUser-Agent: Mozilla/5.0 (X11; Linux x86_64) AppleWebKit/537.36 (K...
    │    └ <function HTTPConnection.send at 0x7f926beb7b80>
    └ <urllib3.connection.HTTPConnection object at 0x7f912418f190>
  File "/usr/lib/python3.8/http/client.py", line 951, in send
    self.connect()
    │    └ <function HTTPConnection.connect at 0x7f92585b0dc0>
    └ <urllib3.connection.HTTPConnection object at 0x7f912418f190>
  File "/home/chase/.local/lib/python3.8/site-packages/urllib3/connection.py", line 205, in connect
    conn = self._new_conn()
           │    └ <function HTTPConnection._new_conn at 0x7f92585b0c10>
           └ <urllib3.connection.HTTPConnection object at 0x7f912418f190>
  File "/home/chase/.local/lib/python3.8/site-packages/urllib3/connection.py", line 186, in _new_conn
    raise NewConnectionError(
          └ <class 'urllib3.exceptions.NewConnectionError'>

urllib3.exceptions.NewConnectionError: <urllib3.connection.HTTPConnection object at 0x7f912418f190>: Failed to establish a new connection: [Errno 111] Connection refused


During handling of the above exception, another exception occurred:


Traceback (most recent call last):

  File "/home/chase/.local/lib/python3.8/site-packages/requests/adapters.py", line 439, in send
    resp = conn.urlopen(
           │    └ <function HTTPConnectionPool.urlopen at 0x7f92585c0820>
           └ <urllib3.connectionpool.HTTPConnectionPool object at 0x7f91243e3340>
  File "/home/chase/.local/lib/python3.8/site-packages/urllib3/connectionpool.py", line 755, in urlopen
    retries = retries.increment(
              │       └ <function Retry.increment at 0x7f9258608b80>
              └ Retry(total=0, connect=None, read=False, redirect=None, status=None)
  File "/home/chase/.local/lib/python3.8/site-packages/urllib3/util/retry.py", line 574, in increment
    raise MaxRetryError(_pool, url, error or ResponseError(cause))
          │             │      │    │        │             └ 'unknown'
          │             │      │    │        └ <class 'urllib3.exceptions.ResponseError'>
          │             │      │    └ NewConnectionError('<urllib3.connection.HTTPConnection object at 0x7f912418f190>: Failed to establish a new connection: [Errn...
          │             │      └ '/board/1.html'
          │             └ <urllib3.connectionpool.HTTPConnectionPool object at 0x7f91243e3340>
          └ <class 'urllib3.exceptions.MaxRetryError'>

urllib3.exceptions.MaxRetryError: HTTPConnectionPool(host='bbs1.people.com.cn', port=80): Max retries exceeded with url: /board/1.html (Caused by NewConnectionError('<urllib3.connection.HTTPConnection object at 0x7f912418f190>: Failed to establish a new connection: [Errno 111] Connection refused'))


During handling of the above exception, another exception occurred:


Traceback (most recent call last):

  File "/usr/lib/python3.8/threading.py", line 890, in _bootstrap
    self._bootstrap_inner()
    │    └ <function Thread._bootstrap_inner at 0x7f927a614a60>
    └ <Thread(Thread-120, started daemon 140260327544576)>
  File "/usr/lib/python3.8/threading.py", line 932, in _bootstrap_inner
    self.run()
    │    └ <function Thread.run at 0x7f927a614790>
    └ <Thread(Thread-120, started daemon 140260327544576)>
  File "/usr/lib/python3.8/threading.py", line 870, in run
    self._target(*self._args, **self._kwargs)
    │    │        │    │        │    └ {}
    │    │        │    │        └ <Thread(Thread-120, started daemon 140260327544576)>
    │    │        │    └ ('ProjectManager.run_func_by_thread',)
    │    │        └ <Thread(Thread-120, started daemon 140260327544576)>
    │    └ <bound method ProjectManager.get_request_from_keywords_hot of <monitor.projectManager.ProjectManager object at 0x7f9162af4700>>
    └ <Thread(Thread-120, started daemon 140260327544576)>

  File "/home/users/Scy/yuqing/spider/monitor/projectManager.py", line 795, in get_request_from_keywords_hot
    self.search_spider_manager.crawl_by_keyword(
    │    │                     └ <function SearchSpidersManager.crawl_by_keyword at 0x7f9162b00040>
    │    └ <monitor.spiderManager.SearchSpidersManager object at 0x7f916270f0d0>
    └ <monitor.projectManager.ProjectManager object at 0x7f9162af4700>

  File "/home/users/Scy/yuqing/spider/monitor/spiderManager.py", line 118, in crawl_by_keyword
    self.crawl_by_keyword_signal_platform(project_names, platform, keyword, crawl_time, project_times)
    │    │                                │              │         │        │           └ {'default': <monitor.TimeSection object at 0x7f91628317f0>}
    │    │                                │              │         │        └ <monitor.TimeSection object at 0x7f9160073700>
    │    │                                │              │         └ '埃及南部发掘出85座古代墓葬'
    │    │                                │              └ '强国论坛'
    │    │                                └ ['default']
    │    └ <function SearchSpidersManager.crawl_by_keyword_signal_platform at 0x7f9162b000d0>
    └ <monitor.spiderManager.SearchSpidersManager object at 0x7f916270f0d0>

  File "/home/users/Scy/yuqing/spider/monitor/spiderManager.py", line 134, in crawl_by_keyword_signal_platform
    requests = self.get_request_from_keyword(platform, keyword, **crawl_time.to_dict())
               │    │                        │         │          │          └ <function TimeSection.to_dict at 0x7f925aaa8550>
               │    │                        │         │          └ <monitor.TimeSection object at 0x7f9160073700>
               │    │                        │         └ '埃及南部发掘出85座古代墓葬'
               │    │                        └ '强国论坛'
               │    └ <function SearchSpidersManager.get_request_from_keyword at 0x7f9162b001f0>
               └ <monitor.spiderManager.SearchSpidersManager object at 0x7f916270f0d0>

  File "/home/users/Scy/yuqing/spider/monitor/spiderManager.py", line 191, in get_request_from_keyword
    for request in self.spiders[platform].get_request_from_keyword(headers, search_url, keyword, content_url,
                   │    │       │                                  │        │           │        └ <string.Template object at 0x7f91486349d0>
                   │    │       │                                  │        │           └ '埃及南部发掘出85座古代墓葬'
                   │    │       │                                  │        └ <string.Template object at 0x7f91483db7f0>
                   │    │       │                                  └ {'Connection': 'keep-alive', 'Cache-Control': 'max-age=0', 'Upgrade-Insecure-Requests': '1', 'User-Agent': 'Mozilla/5.0 (X11;...
                   │    │       └ '强国论坛'
                   │    └ {'凤凰网': <monitor.searchSpiders.ifeng.Ifeng object at 0x7f916270f220>, '头条': <monitor.searchSpiders.toutiao.Toutiao object at ...
                   └ <monitor.spiderManager.SearchSpidersManager object at 0x7f916270f0d0>

> File "/home/users/Scy/yuqing/spider/monitor/searchSpiders/qinagguoLT.py", line 18, in get_request_from_keyword
    response = requests.get(search_url.substitute(), headers=headers)
               │        │   │          │                     └ {'Connection': 'keep-alive', 'Cache-Control': 'max-age=0', 'Upgrade-Insecure-Requests': '1', 'User-Agent': 'Mozilla/5.0 (X11;...
               │        │   │          └ <function Template.substitute at 0x7f927a5fd0d0>
               │        │   └ <string.Template object at 0x7f91483db7f0>
               │        └ <function get at 0x7f92583e71f0>
               └ <module 'requests' from '/home/chase/.local/lib/python3.8/site-packages/requests/__init__.py'>

  File "/home/chase/.local/lib/python3.8/site-packages/requests/api.py", line 75, in get
    return request('get', url, params=params, **kwargs)
           │              │           │         └ {'headers': {'Connection': 'keep-alive', 'Cache-Control': 'max-age=0', 'Upgrade-Insecure-Requests': '1', 'User-Agent': 'Mozil...
           │              │           └ None
           │              └ 'http://bbs1.people.com.cn/board/1.html'
           └ <function request at 0x7f9258455040>
  File "/home/chase/.local/lib/python3.8/site-packages/requests/api.py", line 61, in request
    return session.request(method=method, url=url, **kwargs)
           │       │              │           │      └ {'params': None, 'headers': {'Connection': 'keep-alive', 'Cache-Control': 'max-age=0', 'Upgrade-Insecure-Requests': '1', 'Use...
           │       │              │           └ 'http://bbs1.people.com.cn/board/1.html'
           │       │              └ 'get'
           │       └ <function Session.request at 0x7f92583e6940>
           └ <requests.sessions.Session object at 0x7f91243fd790>
  File "/home/chase/.local/lib/python3.8/site-packages/requests/sessions.py", line 542, in request
    resp = self.send(prep, **send_kwargs)
           │    │    │       └ {'timeout': None, 'allow_redirects': True, 'verify': True, 'proxies': OrderedDict(), 'stream': False, 'cert': None}
           │    │    └ <PreparedRequest [GET]>
           │    └ <function Session.send at 0x7f92583e6dc0>
           └ <requests.sessions.Session object at 0x7f91243fd790>
  File "/home/chase/.local/lib/python3.8/site-packages/requests/sessions.py", line 655, in send
    r = adapter.send(request, **kwargs)
        │       │    │          └ {'timeout': None, 'verify': True, 'proxies': OrderedDict(), 'stream': False, 'cert': None}
        │       │    └ <PreparedRequest [GET]>
        │       └ <function HTTPAdapter.send at 0x7f92583e6280>
        └ <requests.adapters.HTTPAdapter object at 0x7f9148581490>
  File "/home/chase/.local/lib/python3.8/site-packages/requests/adapters.py", line 516, in send
    raise ConnectionError(e, request=request)
          │                          └ <PreparedRequest [GET]>
          └ <class 'requests.exceptions.ConnectionError'>

requests.exceptions.ConnectionError: HTTPConnectionPool(host='bbs1.people.com.cn', port=80): Max retries exceeded with url: /board/1.html (Caused by NewConnectionError('<urllib3.connection.HTTPConnection object at 0x7f912418f190>: Failed to establish a new connection: [Errno 111] Connection refused'))
2022-05-12 15:48:43.094 | ERROR    | monitor.searchSpiders.people:get_request_from_keyword:45 - E 人民网错误HTTPConnectionPool(host='search.people.cn', port=80): Max retries exceeded with url: /search-platform/front/search (Caused by NewConnectionError('<urllib3.connection.HTTPConnection object at 0x7f91040393a0>: Failed to establish a new connection: [Errno 111] Connection refused'))
Traceback (most recent call last):

  File "/home/chase/.local/lib/python3.8/site-packages/urllib3/connection.py", line 174, in _new_conn
    conn = connection.create_connection(
           │          └ <function create_connection at 0x7f92585fd1f0>
           └ <module 'urllib3.util.connection' from '/home/chase/.local/lib/python3.8/site-packages/urllib3/util/connection.py'>
  File "/home/chase/.local/lib/python3.8/site-packages/urllib3/util/connection.py", line 96, in create_connection
    raise err
          └ ConnectionRefusedError(111, 'Connection refused')
  File "/home/chase/.local/lib/python3.8/site-packages/urllib3/util/connection.py", line 86, in create_connection
    sock.connect(sa)
    │            └ ('1.31.128.246', 80)
    └ None

ConnectionRefusedError: [Errno 111] Connection refused


During handling of the above exception, another exception occurred:


Traceback (most recent call last):

  File "/home/chase/.local/lib/python3.8/site-packages/urllib3/connectionpool.py", line 699, in urlopen
    httplib_response = self._make_request(
                       │    └ <function HTTPConnectionPool._make_request at 0x7f92585c05e0>
                       └ <urllib3.connectionpool.HTTPConnectionPool object at 0x7f91601086a0>
  File "/home/chase/.local/lib/python3.8/site-packages/urllib3/connectionpool.py", line 394, in _make_request
    conn.request(method, url, **httplib_request_kw)
    │    │       │       │      └ {'body': b'{"key": "\\u610f\\u5927\\u5229\\u4f5b\\u7f57\\u4f26\\u8428\\u57ce\\u5e02\\u666f\\u89c2\\u58ee\\u4e3d", "page": 1, ...
    │    │       │       └ '/search-platform/front/search'
    │    │       └ 'POST'
    │    └ <function HTTPConnection.request at 0x7f92585b0f70>
    └ <urllib3.connection.HTTPConnection object at 0x7f91040393a0>
  File "/home/chase/.local/lib/python3.8/site-packages/urllib3/connection.py", line 239, in request
    super(HTTPConnection, self).request(method, url, body=body, headers=headers)
          │               │             │       │         │             └ {'User-Agent': 'Mozilla/5.0 (Windows NT 10.0; Win64; x64) AppleWebKit/537.36 (KHTML, like Gecko) Chrome/101.0.4951.54 Safari/...
          │               │             │       │         └ b'{"key": "\\u610f\\u5927\\u5229\\u4f5b\\u7f57\\u4f26\\u8428\\u57ce\\u5e02\\u666f\\u89c2\\u58ee\\u4e3d", "page": 1, "limit": ...
          │               │             │       └ '/search-platform/front/search'
          │               │             └ 'POST'
          │               └ <urllib3.connection.HTTPConnection object at 0x7f91040393a0>
          └ <class 'urllib3.connection.HTTPConnection'>
  File "/usr/lib/python3.8/http/client.py", line 1256, in request
    self._send_request(method, url, body, headers, encode_chunked)
    │    │             │       │    │     │        └ False
    │    │             │       │    │     └ {'User-Agent': 'Mozilla/5.0 (Windows NT 10.0; Win64; x64) AppleWebKit/537.36 (KHTML, like Gecko) Chrome/101.0.4951.54 Safari/...
    │    │             │       │    └ b'{"key": "\\u610f\\u5927\\u5229\\u4f5b\\u7f57\\u4f26\\u8428\\u57ce\\u5e02\\u666f\\u89c2\\u58ee\\u4e3d", "page": 1, "limit": ...
    │    │             │       └ '/search-platform/front/search'
    │    │             └ 'POST'
    │    └ <function HTTPConnection._send_request at 0x7f926be50280>
    └ <urllib3.connection.HTTPConnection object at 0x7f91040393a0>
  File "/usr/lib/python3.8/http/client.py", line 1302, in _send_request
    self.endheaders(body, encode_chunked=encode_chunked)
    │    │          │                    └ False
    │    │          └ b'{"key": "\\u610f\\u5927\\u5229\\u4f5b\\u7f57\\u4f26\\u8428\\u57ce\\u5e02\\u666f\\u89c2\\u58ee\\u4e3d", "page": 1, "limit": ...
    │    └ <function HTTPConnection.endheaders at 0x7f926be50160>
    └ <urllib3.connection.HTTPConnection object at 0x7f91040393a0>
  File "/usr/lib/python3.8/http/client.py", line 1251, in endheaders
    self._send_output(message_body, encode_chunked=encode_chunked)
    │    │            │                            └ False
    │    │            └ b'{"key": "\\u610f\\u5927\\u5229\\u4f5b\\u7f57\\u4f26\\u8428\\u57ce\\u5e02\\u666f\\u89c2\\u58ee\\u4e3d", "page": 1, "limit": ...
    │    └ <function HTTPConnection._send_output at 0x7f926beb7d30>
    └ <urllib3.connection.HTTPConnection object at 0x7f91040393a0>
  File "/usr/lib/python3.8/http/client.py", line 1011, in _send_output
    self.send(msg)
    │    │    └ b'POST /search-platform/front/search HTTP/1.1\r\nHost: search.people.cn\r\nUser-Agent: Mozilla/5.0 (Windows NT 10.0; Win64; x...
    │    └ <function HTTPConnection.send at 0x7f926beb7b80>
    └ <urllib3.connection.HTTPConnection object at 0x7f91040393a0>
  File "/usr/lib/python3.8/http/client.py", line 951, in send
    self.connect()
    │    └ <function HTTPConnection.connect at 0x7f92585b0dc0>
    └ <urllib3.connection.HTTPConnection object at 0x7f91040393a0>
  File "/home/chase/.local/lib/python3.8/site-packages/urllib3/connection.py", line 205, in connect
    conn = self._new_conn()
           │    └ <function HTTPConnection._new_conn at 0x7f92585b0c10>
           └ <urllib3.connection.HTTPConnection object at 0x7f91040393a0>
  File "/home/chase/.local/lib/python3.8/site-packages/urllib3/connection.py", line 186, in _new_conn
    raise NewConnectionError(
          └ <class 'urllib3.exceptions.NewConnectionError'>

urllib3.exceptions.NewConnectionError: <urllib3.connection.HTTPConnection object at 0x7f91040393a0>: Failed to establish a new connection: [Errno 111] Connection refused


During handling of the above exception, another exception occurred:


Traceback (most recent call last):

  File "/home/chase/.local/lib/python3.8/site-packages/requests/adapters.py", line 439, in send
    resp = conn.urlopen(
           │    └ <function HTTPConnectionPool.urlopen at 0x7f92585c0820>
           └ <urllib3.connectionpool.HTTPConnectionPool object at 0x7f91601086a0>
  File "/home/chase/.local/lib/python3.8/site-packages/urllib3/connectionpool.py", line 755, in urlopen
    retries = retries.increment(
              │       └ <function Retry.increment at 0x7f9258608b80>
              └ Retry(total=0, connect=None, read=False, redirect=None, status=None)
  File "/home/chase/.local/lib/python3.8/site-packages/urllib3/util/retry.py", line 574, in increment
    raise MaxRetryError(_pool, url, error or ResponseError(cause))
          │             │      │    │        │             └ 'unknown'
          │             │      │    │        └ <class 'urllib3.exceptions.ResponseError'>
          │             │      │    └ NewConnectionError('<urllib3.connection.HTTPConnection object at 0x7f91040393a0>: Failed to establish a new connection: [Errn...
          │             │      └ '/search-platform/front/search'
          │             └ <urllib3.connectionpool.HTTPConnectionPool object at 0x7f91601086a0>
          └ <class 'urllib3.exceptions.MaxRetryError'>

urllib3.exceptions.MaxRetryError: HTTPConnectionPool(host='search.people.cn', port=80): Max retries exceeded with url: /search-platform/front/search (Caused by NewConnectionError('<urllib3.connection.HTTPConnection object at 0x7f91040393a0>: Failed to establish a new connection: [Errno 111] Connection refused'))


During handling of the above exception, another exception occurred:


Traceback (most recent call last):

  File "/usr/lib/python3.8/threading.py", line 890, in _bootstrap
    self._bootstrap_inner()
    │    └ <function Thread._bootstrap_inner at 0x7f927a614a60>
    └ <Thread(Thread-47, started daemon 140261971695360)>
  File "/usr/lib/python3.8/threading.py", line 932, in _bootstrap_inner
    self.run()
    │    └ <function Thread.run at 0x7f927a614790>
    └ <Thread(Thread-47, started daemon 140261971695360)>
  File "/usr/lib/python3.8/threading.py", line 870, in run
    self._target(*self._args, **self._kwargs)
    │    │        │    │        │    └ {}
    │    │        │    │        └ <Thread(Thread-47, started daemon 140261971695360)>
    │    │        │    └ ('ProjectManager.run_func_by_thread',)
    │    │        └ <Thread(Thread-47, started daemon 140261971695360)>
    │    └ <bound method ProjectManager.get_request_from_keywords_hot of <monitor.projectManager.ProjectManager object at 0x7f9162af4700>>
    └ <Thread(Thread-47, started daemon 140261971695360)>

  File "/home/users/Scy/yuqing/spider/monitor/projectManager.py", line 795, in get_request_from_keywords_hot
    self.search_spider_manager.crawl_by_keyword(
    │    │                     └ <function SearchSpidersManager.crawl_by_keyword at 0x7f9162b00040>
    │    └ <monitor.spiderManager.SearchSpidersManager object at 0x7f916270f0d0>
    └ <monitor.projectManager.ProjectManager object at 0x7f9162af4700>

  File "/home/users/Scy/yuqing/spider/monitor/spiderManager.py", line 118, in crawl_by_keyword
    self.crawl_by_keyword_signal_platform(project_names, platform, keyword, crawl_time, project_times)
    │    │                                │              │         │        │           └ {'default': <monitor.TimeSection object at 0x7f91628317f0>}
    │    │                                │              │         │        └ <monitor.TimeSection object at 0x7f91603f2520>
    │    │                                │              │         └ '意大利佛罗伦萨城市景观壮丽'
    │    │                                │              └ '人民网'
    │    │                                └ ['default']
    │    └ <function SearchSpidersManager.crawl_by_keyword_signal_platform at 0x7f9162b000d0>
    └ <monitor.spiderManager.SearchSpidersManager object at 0x7f916270f0d0>

  File "/home/users/Scy/yuqing/spider/monitor/spiderManager.py", line 134, in crawl_by_keyword_signal_platform
    requests = self.get_request_from_keyword(platform, keyword, **crawl_time.to_dict())
               │    │                        │         │          │          └ <function TimeSection.to_dict at 0x7f925aaa8550>
               │    │                        │         │          └ <monitor.TimeSection object at 0x7f91603f2520>
               │    │                        │         └ '意大利佛罗伦萨城市景观壮丽'
               │    │                        └ '人民网'
               │    └ <function SearchSpidersManager.get_request_from_keyword at 0x7f9162b001f0>
               └ <monitor.spiderManager.SearchSpidersManager object at 0x7f916270f0d0>

  File "/home/users/Scy/yuqing/spider/monitor/spiderManager.py", line 191, in get_request_from_keyword
    for request in self.spiders[platform].get_request_from_keyword(headers, search_url, keyword, content_url,
                   │    │       │                                  │        │           │        └ <string.Template object at 0x7f9148232e50>
                   │    │       │                                  │        │           └ '意大利佛罗伦萨城市景观壮丽'
                   │    │       │                                  │        └ <string.Template object at 0x7f914854e070>
                   │    │       │                                  └ {'Accept': 'application/json, text/plain, */*', 'Accept-Language': 'zh-CN,zh;q=0.9', 'Connection': 'keep-alive', 'Origin': 'h...
                   │    │       └ '人民网'
                   │    └ {'凤凰网': <monitor.searchSpiders.ifeng.Ifeng object at 0x7f916270f220>, '头条': <monitor.searchSpiders.toutiao.Toutiao object at ...
                   └ <monitor.spiderManager.SearchSpidersManager object at 0x7f916270f0d0>

> File "/home/users/Scy/yuqing/spider/monitor/searchSpiders/people.py", line 28, in get_request_from_keyword
    response = requests.post(search_url.substitute(), json=data, headers=headers)
               │        │    │          │                  │             └ {'Accept': 'application/json, text/plain, */*', 'Accept-Language': 'zh-CN,zh;q=0.9', 'Connection': 'keep-alive', 'Origin': 'h...
               │        │    │          │                  └ {'key': '意大利佛罗伦萨城市景观壮丽', 'page': 1, 'limit': 10, 'hasTitle': True, 'hasContent': True, 'isFuzzy': True, 'type': 0, 'sortType'...
               │        │    │          └ <function Template.substitute at 0x7f927a5fd0d0>
               │        │    └ <string.Template object at 0x7f914854e070>
               │        └ <function post at 0x7f92583e73a0>
               └ <module 'requests' from '/home/chase/.local/lib/python3.8/site-packages/requests/__init__.py'>

  File "/home/chase/.local/lib/python3.8/site-packages/requests/api.py", line 117, in post
    return request('post', url, data=data, json=json, **kwargs)
           │               │         │          │       └ {'headers': {'Accept': 'application/json, text/plain, */*', 'Accept-Language': 'zh-CN,zh;q=0.9', 'Connection': 'keep-alive', ...
           │               │         │          └ {'key': '意大利佛罗伦萨城市景观壮丽', 'page': 1, 'limit': 10, 'hasTitle': True, 'hasContent': True, 'isFuzzy': True, 'type': 0, 'sortType'...
           │               │         └ None
           │               └ 'http://search.people.cn/search-platform/front/search'
           └ <function request at 0x7f9258455040>
  File "/home/chase/.local/lib/python3.8/site-packages/requests/api.py", line 61, in request
    return session.request(method=method, url=url, **kwargs)
           │       │              │           │      └ {'data': None, 'json': {'key': '意大利佛罗伦萨城市景观壮丽', 'page': 1, 'limit': 10, 'hasTitle': True, 'hasContent': True, 'isFuzzy': True...
           │       │              │           └ 'http://search.people.cn/search-platform/front/search'
           │       │              └ 'post'
           │       └ <function Session.request at 0x7f92583e6940>
           └ <requests.sessions.Session object at 0x7f9148263430>
  File "/home/chase/.local/lib/python3.8/site-packages/requests/sessions.py", line 542, in request
    resp = self.send(prep, **send_kwargs)
           │    │    │       └ {'timeout': None, 'allow_redirects': True, 'verify': True, 'proxies': OrderedDict(), 'stream': False, 'cert': None}
           │    │    └ <PreparedRequest [POST]>
           │    └ <function Session.send at 0x7f92583e6dc0>
           └ <requests.sessions.Session object at 0x7f9148263430>
  File "/home/chase/.local/lib/python3.8/site-packages/requests/sessions.py", line 655, in send
    r = adapter.send(request, **kwargs)
        │       │    │          └ {'timeout': None, 'verify': True, 'proxies': OrderedDict(), 'stream': False, 'cert': None}
        │       │    └ <PreparedRequest [POST]>
        │       └ <function HTTPAdapter.send at 0x7f92583e6280>
        └ <requests.adapters.HTTPAdapter object at 0x7f91040d9b20>
  File "/home/chase/.local/lib/python3.8/site-packages/requests/adapters.py", line 516, in send
    raise ConnectionError(e, request=request)
          │                          └ <PreparedRequest [POST]>
          └ <class 'requests.exceptions.ConnectionError'>

requests.exceptions.ConnectionError: HTTPConnectionPool(host='search.people.cn', port=80): Max retries exceeded with url: /search-platform/front/search (Caused by NewConnectionError('<urllib3.connection.HTTPConnection object at 0x7f91040393a0>: Failed to establish a new connection: [Errno 111] Connection refused'))
2022-05-12 15:48:43.683 | ERROR    | monitor.searchSpiders.people:get_request_from_keyword:45 - E 人民网错误HTTPConnectionPool(host='search.people.cn', port=80): Max retries exceeded with url: /search-platform/front/search (Caused by NewConnectionError('<urllib3.connection.HTTPConnection object at 0x7f90e476f070>: Failed to establish a new connection: [Errno 111] Connection refused'))
Traceback (most recent call last):

  File "/home/chase/.local/lib/python3.8/site-packages/urllib3/connection.py", line 174, in _new_conn
    conn = connection.create_connection(
           │          └ <function create_connection at 0x7f92585fd1f0>
           └ <module 'urllib3.util.connection' from '/home/chase/.local/lib/python3.8/site-packages/urllib3/util/connection.py'>
  File "/home/chase/.local/lib/python3.8/site-packages/urllib3/util/connection.py", line 96, in create_connection
    raise err
          └ ConnectionRefusedError(111, 'Connection refused')
  File "/home/chase/.local/lib/python3.8/site-packages/urllib3/util/connection.py", line 86, in create_connection
    sock.connect(sa)
    │            └ ('1.31.128.246', 80)
    └ None

ConnectionRefusedError: [Errno 111] Connection refused


During handling of the above exception, another exception occurred:


Traceback (most recent call last):

  File "/home/chase/.local/lib/python3.8/site-packages/urllib3/connectionpool.py", line 699, in urlopen
    httplib_response = self._make_request(
                       │    └ <function HTTPConnectionPool._make_request at 0x7f92585c05e0>
                       └ <urllib3.connectionpool.HTTPConnectionPool object at 0x7f90e476b700>
  File "/home/chase/.local/lib/python3.8/site-packages/urllib3/connectionpool.py", line 394, in _make_request
    conn.request(method, url, **httplib_request_kw)
    │    │       │       │      └ {'body': b'{"key": "\\u7b2c78\\u96c6\\u56e2\\u519b\\u67d0\\u65c5\\uff1a\\u201c\\u4f34\\u968f\\u4fdd\\u969c\\u201d\\u5f3a\\u53...
    │    │       │       └ '/search-platform/front/search'
    │    │       └ 'POST'
    │    └ <function HTTPConnection.request at 0x7f92585b0f70>
    └ <urllib3.connection.HTTPConnection object at 0x7f90e476f070>
  File "/home/chase/.local/lib/python3.8/site-packages/urllib3/connection.py", line 239, in request
    super(HTTPConnection, self).request(method, url, body=body, headers=headers)
          │               │             │       │         │             └ {'User-Agent': 'Mozilla/5.0 (Windows NT 10.0; Win64; x64) AppleWebKit/537.36 (KHTML, like Gecko) Chrome/101.0.4951.54 Safari/...
          │               │             │       │         └ b'{"key": "\\u7b2c78\\u96c6\\u56e2\\u519b\\u67d0\\u65c5\\uff1a\\u201c\\u4f34\\u968f\\u4fdd\\u969c\\u201d\\u5f3a\\u5316\\u6218...
          │               │             │       └ '/search-platform/front/search'
          │               │             └ 'POST'
          │               └ <urllib3.connection.HTTPConnection object at 0x7f90e476f070>
          └ <class 'urllib3.connection.HTTPConnection'>
  File "/usr/lib/python3.8/http/client.py", line 1256, in request
    self._send_request(method, url, body, headers, encode_chunked)
    │    │             │       │    │     │        └ False
    │    │             │       │    │     └ {'User-Agent': 'Mozilla/5.0 (Windows NT 10.0; Win64; x64) AppleWebKit/537.36 (KHTML, like Gecko) Chrome/101.0.4951.54 Safari/...
    │    │             │       │    └ b'{"key": "\\u7b2c78\\u96c6\\u56e2\\u519b\\u67d0\\u65c5\\uff1a\\u201c\\u4f34\\u968f\\u4fdd\\u969c\\u201d\\u5f3a\\u5316\\u6218...
    │    │             │       └ '/search-platform/front/search'
    │    │             └ 'POST'
    │    └ <function HTTPConnection._send_request at 0x7f926be50280>
    └ <urllib3.connection.HTTPConnection object at 0x7f90e476f070>
  File "/usr/lib/python3.8/http/client.py", line 1302, in _send_request
    self.endheaders(body, encode_chunked=encode_chunked)
    │    │          │                    └ False
    │    │          └ b'{"key": "\\u7b2c78\\u96c6\\u56e2\\u519b\\u67d0\\u65c5\\uff1a\\u201c\\u4f34\\u968f\\u4fdd\\u969c\\u201d\\u5f3a\\u5316\\u6218...
    │    └ <function HTTPConnection.endheaders at 0x7f926be50160>
    └ <urllib3.connection.HTTPConnection object at 0x7f90e476f070>
  File "/usr/lib/python3.8/http/client.py", line 1251, in endheaders
    self._send_output(message_body, encode_chunked=encode_chunked)
    │    │            │                            └ False
    │    │            └ b'{"key": "\\u7b2c78\\u96c6\\u56e2\\u519b\\u67d0\\u65c5\\uff1a\\u201c\\u4f34\\u968f\\u4fdd\\u969c\\u201d\\u5f3a\\u5316\\u6218...
    │    └ <function HTTPConnection._send_output at 0x7f926beb7d30>
    └ <urllib3.connection.HTTPConnection object at 0x7f90e476f070>
  File "/usr/lib/python3.8/http/client.py", line 1011, in _send_output
    self.send(msg)
    │    │    └ b'POST /search-platform/front/search HTTP/1.1\r\nHost: search.people.cn\r\nUser-Agent: Mozilla/5.0 (Windows NT 10.0; Win64; x...
    │    └ <function HTTPConnection.send at 0x7f926beb7b80>
    └ <urllib3.connection.HTTPConnection object at 0x7f90e476f070>
  File "/usr/lib/python3.8/http/client.py", line 951, in send
    self.connect()
    │    └ <function HTTPConnection.connect at 0x7f92585b0dc0>
    └ <urllib3.connection.HTTPConnection object at 0x7f90e476f070>
  File "/home/chase/.local/lib/python3.8/site-packages/urllib3/connection.py", line 205, in connect
    conn = self._new_conn()
           │    └ <function HTTPConnection._new_conn at 0x7f92585b0c10>
           └ <urllib3.connection.HTTPConnection object at 0x7f90e476f070>
  File "/home/chase/.local/lib/python3.8/site-packages/urllib3/connection.py", line 186, in _new_conn
    raise NewConnectionError(
          └ <class 'urllib3.exceptions.NewConnectionError'>

urllib3.exceptions.NewConnectionError: <urllib3.connection.HTTPConnection object at 0x7f90e476f070>: Failed to establish a new connection: [Errno 111] Connection refused


During handling of the above exception, another exception occurred:


Traceback (most recent call last):

  File "/home/chase/.local/lib/python3.8/site-packages/requests/adapters.py", line 439, in send
    resp = conn.urlopen(
           │    └ <function HTTPConnectionPool.urlopen at 0x7f92585c0820>
           └ <urllib3.connectionpool.HTTPConnectionPool object at 0x7f90e476b700>
  File "/home/chase/.local/lib/python3.8/site-packages/urllib3/connectionpool.py", line 755, in urlopen
    retries = retries.increment(
              │       └ <function Retry.increment at 0x7f9258608b80>
              └ Retry(total=0, connect=None, read=False, redirect=None, status=None)
  File "/home/chase/.local/lib/python3.8/site-packages/urllib3/util/retry.py", line 574, in increment
    raise MaxRetryError(_pool, url, error or ResponseError(cause))
          │             │      │    │        │             └ 'unknown'
          │             │      │    │        └ <class 'urllib3.exceptions.ResponseError'>
          │             │      │    └ NewConnectionError('<urllib3.connection.HTTPConnection object at 0x7f90e476f070>: Failed to establish a new connection: [Errn...
          │             │      └ '/search-platform/front/search'
          │             └ <urllib3.connectionpool.HTTPConnectionPool object at 0x7f90e476b700>
          └ <class 'urllib3.exceptions.MaxRetryError'>

urllib3.exceptions.MaxRetryError: HTTPConnectionPool(host='search.people.cn', port=80): Max retries exceeded with url: /search-platform/front/search (Caused by NewConnectionError('<urllib3.connection.HTTPConnection object at 0x7f90e476f070>: Failed to establish a new connection: [Errno 111] Connection refused'))


During handling of the above exception, another exception occurred:


Traceback (most recent call last):

  File "/usr/lib/python3.8/threading.py", line 890, in _bootstrap
    self._bootstrap_inner()
    │    └ <function Thread._bootstrap_inner at 0x7f927a614a60>
    └ <Thread(Thread-249, started daemon 140258188453632)>
  File "/usr/lib/python3.8/threading.py", line 932, in _bootstrap_inner
    self.run()
    │    └ <function Thread.run at 0x7f927a614790>
    └ <Thread(Thread-249, started daemon 140258188453632)>
  File "/usr/lib/python3.8/threading.py", line 870, in run
    self._target(*self._args, **self._kwargs)
    │    │        │    │        │    └ {}
    │    │        │    │        └ <Thread(Thread-249, started daemon 140258188453632)>
    │    │        │    └ ('ProjectManager.run_func_by_thread',)
    │    │        └ <Thread(Thread-249, started daemon 140258188453632)>
    │    └ <bound method ProjectManager.get_request_from_keywords_hot of <monitor.projectManager.ProjectManager object at 0x7f9162af4700>>
    └ <Thread(Thread-249, started daemon 140258188453632)>

  File "/home/users/Scy/yuqing/spider/monitor/projectManager.py", line 795, in get_request_from_keywords_hot
    self.search_spider_manager.crawl_by_keyword(
    │    │                     └ <function SearchSpidersManager.crawl_by_keyword at 0x7f9162b00040>
    │    └ <monitor.spiderManager.SearchSpidersManager object at 0x7f916270f0d0>
    └ <monitor.projectManager.ProjectManager object at 0x7f9162af4700>

  File "/home/users/Scy/yuqing/spider/monitor/spiderManager.py", line 118, in crawl_by_keyword
    self.crawl_by_keyword_signal_platform(project_names, platform, keyword, crawl_time, project_times)
    │    │                                │              │         │        │           └ {'default': <monitor.TimeSection object at 0x7f91628317f0>}
    │    │                                │              │         │        └ <monitor.TimeSection object at 0x7f9253e89700>
    │    │                                │              │         └ '第78集团军某旅：“伴随保障”强化战场意识'
    │    │                                │              └ '人民网'
    │    │                                └ ['default']
    │    └ <function SearchSpidersManager.crawl_by_keyword_signal_platform at 0x7f9162b000d0>
    └ <monitor.spiderManager.SearchSpidersManager object at 0x7f916270f0d0>

  File "/home/users/Scy/yuqing/spider/monitor/spiderManager.py", line 134, in crawl_by_keyword_signal_platform
    requests = self.get_request_from_keyword(platform, keyword, **crawl_time.to_dict())
               │    │                        │         │          │          └ <function TimeSection.to_dict at 0x7f925aaa8550>
               │    │                        │         │          └ <monitor.TimeSection object at 0x7f9253e89700>
               │    │                        │         └ '第78集团军某旅：“伴随保障”强化战场意识'
               │    │                        └ '人民网'
               │    └ <function SearchSpidersManager.get_request_from_keyword at 0x7f9162b001f0>
               └ <monitor.spiderManager.SearchSpidersManager object at 0x7f916270f0d0>

  File "/home/users/Scy/yuqing/spider/monitor/spiderManager.py", line 191, in get_request_from_keyword
    for request in self.spiders[platform].get_request_from_keyword(headers, search_url, keyword, content_url,
                   │    │       │                                  │        │           │        └ <string.Template object at 0x7f90e47436a0>
                   │    │       │                                  │        │           └ '第78集团军某旅：“伴随保障”强化战场意识'
                   │    │       │                                  │        └ <string.Template object at 0x7f9148769be0>
                   │    │       │                                  └ {'Accept': 'application/json, text/plain, */*', 'Accept-Language': 'zh-CN,zh;q=0.9', 'Connection': 'keep-alive', 'Origin': 'h...
                   │    │       └ '人民网'
                   │    └ {'凤凰网': <monitor.searchSpiders.ifeng.Ifeng object at 0x7f916270f220>, '头条': <monitor.searchSpiders.toutiao.Toutiao object at ...
                   └ <monitor.spiderManager.SearchSpidersManager object at 0x7f916270f0d0>

> File "/home/users/Scy/yuqing/spider/monitor/searchSpiders/people.py", line 28, in get_request_from_keyword
    response = requests.post(search_url.substitute(), json=data, headers=headers)
               │        │    │          │                  │             └ {'Accept': 'application/json, text/plain, */*', 'Accept-Language': 'zh-CN,zh;q=0.9', 'Connection': 'keep-alive', 'Origin': 'h...
               │        │    │          │                  └ {'key': '第78集团军某旅：“伴随保障”强化战场意识', 'page': 1, 'limit': 10, 'hasTitle': True, 'hasContent': True, 'isFuzzy': True, 'type': 0, 's...
               │        │    │          └ <function Template.substitute at 0x7f927a5fd0d0>
               │        │    └ <string.Template object at 0x7f9148769be0>
               │        └ <function post at 0x7f92583e73a0>
               └ <module 'requests' from '/home/chase/.local/lib/python3.8/site-packages/requests/__init__.py'>

  File "/home/chase/.local/lib/python3.8/site-packages/requests/api.py", line 117, in post
    return request('post', url, data=data, json=json, **kwargs)
           │               │         │          │       └ {'headers': {'Accept': 'application/json, text/plain, */*', 'Accept-Language': 'zh-CN,zh;q=0.9', 'Connection': 'keep-alive', ...
           │               │         │          └ {'key': '第78集团军某旅：“伴随保障”强化战场意识', 'page': 1, 'limit': 10, 'hasTitle': True, 'hasContent': True, 'isFuzzy': True, 'type': 0, 's...
           │               │         └ None
           │               └ 'http://search.people.cn/search-platform/front/search'
           └ <function request at 0x7f9258455040>
  File "/home/chase/.local/lib/python3.8/site-packages/requests/api.py", line 61, in request
    return session.request(method=method, url=url, **kwargs)
           │       │              │           │      └ {'data': None, 'json': {'key': '第78集团军某旅：“伴随保障”强化战场意识', 'page': 1, 'limit': 10, 'hasTitle': True, 'hasContent': True, 'isFuzz...
           │       │              │           └ 'http://search.people.cn/search-platform/front/search'
           │       │              └ 'post'
           │       └ <function Session.request at 0x7f92583e6940>
           └ <requests.sessions.Session object at 0x7f90e477f580>
  File "/home/chase/.local/lib/python3.8/site-packages/requests/sessions.py", line 542, in request
    resp = self.send(prep, **send_kwargs)
           │    │    │       └ {'timeout': None, 'allow_redirects': True, 'verify': True, 'proxies': OrderedDict(), 'stream': False, 'cert': None}
           │    │    └ <PreparedRequest [POST]>
           │    └ <function Session.send at 0x7f92583e6dc0>
           └ <requests.sessions.Session object at 0x7f90e477f580>
  File "/home/chase/.local/lib/python3.8/site-packages/requests/sessions.py", line 655, in send
    r = adapter.send(request, **kwargs)
        │       │    │          └ {'timeout': None, 'verify': True, 'proxies': OrderedDict(), 'stream': False, 'cert': None}
        │       │    └ <PreparedRequest [POST]>
        │       └ <function HTTPAdapter.send at 0x7f92583e6280>
        └ <requests.adapters.HTTPAdapter object at 0x7f90e4767a90>
  File "/home/chase/.local/lib/python3.8/site-packages/requests/adapters.py", line 516, in send
    raise ConnectionError(e, request=request)
          │                          └ <PreparedRequest [POST]>
          └ <class 'requests.exceptions.ConnectionError'>

requests.exceptions.ConnectionError: HTTPConnectionPool(host='search.people.cn', port=80): Max retries exceeded with url: /search-platform/front/search (Caused by NewConnectionError('<urllib3.connection.HTTPConnection object at 0x7f90e476f070>: Failed to establish a new connection: [Errno 111] Connection refused'))
2022-05-12 15:48:43.920 | ERROR    | monitor.searchSpiders.people:get_request_from_keyword:45 - E 人民网错误HTTPConnectionPool(host='search.people.cn', port=80): Max retries exceeded with url: /search-platform/front/search (Caused by NewConnectionError('<urllib3.connection.HTTPConnection object at 0x7f90e476f370>: Failed to establish a new connection: [Errno 111] Connection refused'))
Traceback (most recent call last):

  File "/home/chase/.local/lib/python3.8/site-packages/urllib3/connection.py", line 174, in _new_conn
    conn = connection.create_connection(
           │          └ <function create_connection at 0x7f92585fd1f0>
           └ <module 'urllib3.util.connection' from '/home/chase/.local/lib/python3.8/site-packages/urllib3/util/connection.py'>
  File "/home/chase/.local/lib/python3.8/site-packages/urllib3/util/connection.py", line 96, in create_connection
    raise err
          └ ConnectionRefusedError(111, 'Connection refused')
  File "/home/chase/.local/lib/python3.8/site-packages/urllib3/util/connection.py", line 86, in create_connection
    sock.connect(sa)
    │            └ ('1.31.128.246', 80)
    └ None

ConnectionRefusedError: [Errno 111] Connection refused


During handling of the above exception, another exception occurred:


Traceback (most recent call last):

  File "/home/chase/.local/lib/python3.8/site-packages/urllib3/connectionpool.py", line 699, in urlopen
    httplib_response = self._make_request(
                       │    └ <function HTTPConnectionPool._make_request at 0x7f92585c05e0>
                       └ <urllib3.connectionpool.HTTPConnectionPool object at 0x7f91485dca00>
  File "/home/chase/.local/lib/python3.8/site-packages/urllib3/connectionpool.py", line 394, in _make_request
    conn.request(method, url, **httplib_request_kw)
    │    │       │       │      └ {'body': b'{"key": "\\u7b2c78\\u96c6\\u56e2\\u519b\\u67d0\\u65c5\\uff1a\\u201c\\u4f34\\u968f\\u4fdd\\u969c\\u201d\\u5f3a\\u53...
    │    │       │       └ '/search-platform/front/search'
    │    │       └ 'POST'
    │    └ <function HTTPConnection.request at 0x7f92585b0f70>
    └ <urllib3.connection.HTTPConnection object at 0x7f90e476f370>
  File "/home/chase/.local/lib/python3.8/site-packages/urllib3/connection.py", line 239, in request
    super(HTTPConnection, self).request(method, url, body=body, headers=headers)
          │               │             │       │         │             └ {'User-Agent': 'Mozilla/5.0 (Windows NT 10.0; Win64; x64) AppleWebKit/537.36 (KHTML, like Gecko) Chrome/101.0.4951.54 Safari/...
          │               │             │       │         └ b'{"key": "\\u7b2c78\\u96c6\\u56e2\\u519b\\u67d0\\u65c5\\uff1a\\u201c\\u4f34\\u968f\\u4fdd\\u969c\\u201d\\u5f3a\\u5316\\u6218...
          │               │             │       └ '/search-platform/front/search'
          │               │             └ 'POST'
          │               └ <urllib3.connection.HTTPConnection object at 0x7f90e476f370>
          └ <class 'urllib3.connection.HTTPConnection'>
  File "/usr/lib/python3.8/http/client.py", line 1256, in request
    self._send_request(method, url, body, headers, encode_chunked)
    │    │             │       │    │     │        └ False
    │    │             │       │    │     └ {'User-Agent': 'Mozilla/5.0 (Windows NT 10.0; Win64; x64) AppleWebKit/537.36 (KHTML, like Gecko) Chrome/101.0.4951.54 Safari/...
    │    │             │       │    └ b'{"key": "\\u7b2c78\\u96c6\\u56e2\\u519b\\u67d0\\u65c5\\uff1a\\u201c\\u4f34\\u968f\\u4fdd\\u969c\\u201d\\u5f3a\\u5316\\u6218...
    │    │             │       └ '/search-platform/front/search'
    │    │             └ 'POST'
    │    └ <function HTTPConnection._send_request at 0x7f926be50280>
    └ <urllib3.connection.HTTPConnection object at 0x7f90e476f370>
  File "/usr/lib/python3.8/http/client.py", line 1302, in _send_request
    self.endheaders(body, encode_chunked=encode_chunked)
    │    │          │                    └ False
    │    │          └ b'{"key": "\\u7b2c78\\u96c6\\u56e2\\u519b\\u67d0\\u65c5\\uff1a\\u201c\\u4f34\\u968f\\u4fdd\\u969c\\u201d\\u5f3a\\u5316\\u6218...
    │    └ <function HTTPConnection.endheaders at 0x7f926be50160>
    └ <urllib3.connection.HTTPConnection object at 0x7f90e476f370>
  File "/usr/lib/python3.8/http/client.py", line 1251, in endheaders
    self._send_output(message_body, encode_chunked=encode_chunked)
    │    │            │                            └ False
    │    │            └ b'{"key": "\\u7b2c78\\u96c6\\u56e2\\u519b\\u67d0\\u65c5\\uff1a\\u201c\\u4f34\\u968f\\u4fdd\\u969c\\u201d\\u5f3a\\u5316\\u6218...
    │    └ <function HTTPConnection._send_output at 0x7f926beb7d30>
    └ <urllib3.connection.HTTPConnection object at 0x7f90e476f370>
  File "/usr/lib/python3.8/http/client.py", line 1011, in _send_output
    self.send(msg)
    │    │    └ b'POST /search-platform/front/search HTTP/1.1\r\nHost: search.people.cn\r\nUser-Agent: Mozilla/5.0 (Windows NT 10.0; Win64; x...
    │    └ <function HTTPConnection.send at 0x7f926beb7b80>
    └ <urllib3.connection.HTTPConnection object at 0x7f90e476f370>
  File "/usr/lib/python3.8/http/client.py", line 951, in send
    self.connect()
    │    └ <function HTTPConnection.connect at 0x7f92585b0dc0>
    └ <urllib3.connection.HTTPConnection object at 0x7f90e476f370>
  File "/home/chase/.local/lib/python3.8/site-packages/urllib3/connection.py", line 205, in connect
    conn = self._new_conn()
           │    └ <function HTTPConnection._new_conn at 0x7f92585b0c10>
           └ <urllib3.connection.HTTPConnection object at 0x7f90e476f370>
  File "/home/chase/.local/lib/python3.8/site-packages/urllib3/connection.py", line 186, in _new_conn
    raise NewConnectionError(
          └ <class 'urllib3.exceptions.NewConnectionError'>

urllib3.exceptions.NewConnectionError: <urllib3.connection.HTTPConnection object at 0x7f90e476f370>: Failed to establish a new connection: [Errno 111] Connection refused


During handling of the above exception, another exception occurred:


Traceback (most recent call last):

  File "/home/chase/.local/lib/python3.8/site-packages/requests/adapters.py", line 439, in send
    resp = conn.urlopen(
           │    └ <function HTTPConnectionPool.urlopen at 0x7f92585c0820>
           └ <urllib3.connectionpool.HTTPConnectionPool object at 0x7f91485dca00>
  File "/home/chase/.local/lib/python3.8/site-packages/urllib3/connectionpool.py", line 755, in urlopen
    retries = retries.increment(
              │       └ <function Retry.increment at 0x7f9258608b80>
              └ Retry(total=0, connect=None, read=False, redirect=None, status=None)
  File "/home/chase/.local/lib/python3.8/site-packages/urllib3/util/retry.py", line 574, in increment
    raise MaxRetryError(_pool, url, error or ResponseError(cause))
          │             │      │    │        │             └ 'unknown'
          │             │      │    │        └ <class 'urllib3.exceptions.ResponseError'>
          │             │      │    └ NewConnectionError('<urllib3.connection.HTTPConnection object at 0x7f90e476f370>: Failed to establish a new connection: [Errn...
          │             │      └ '/search-platform/front/search'
          │             └ <urllib3.connectionpool.HTTPConnectionPool object at 0x7f91485dca00>
          └ <class 'urllib3.exceptions.MaxRetryError'>

urllib3.exceptions.MaxRetryError: HTTPConnectionPool(host='search.people.cn', port=80): Max retries exceeded with url: /search-platform/front/search (Caused by NewConnectionError('<urllib3.connection.HTTPConnection object at 0x7f90e476f370>: Failed to establish a new connection: [Errno 111] Connection refused'))


During handling of the above exception, another exception occurred:


Traceback (most recent call last):

  File "/usr/lib/python3.8/threading.py", line 890, in _bootstrap
    self._bootstrap_inner()
    │    └ <function Thread._bootstrap_inner at 0x7f927a614a60>
    └ <Thread(Thread-267, started daemon 140258154882816)>
  File "/usr/lib/python3.8/threading.py", line 932, in _bootstrap_inner
    self.run()
    │    └ <function Thread.run at 0x7f927a614790>
    └ <Thread(Thread-267, started daemon 140258154882816)>
  File "/usr/lib/python3.8/threading.py", line 870, in run
    self._target(*self._args, **self._kwargs)
    │    │        │    │        │    └ {}
    │    │        │    │        └ <Thread(Thread-267, started daemon 140258154882816)>
    │    │        │    └ ('ProjectManager.run_func_by_thread',)
    │    │        └ <Thread(Thread-267, started daemon 140258154882816)>
    │    └ <bound method ProjectManager.get_request_from_keywords_hot of <monitor.projectManager.ProjectManager object at 0x7f9162af4700>>
    └ <Thread(Thread-267, started daemon 140258154882816)>

  File "/home/users/Scy/yuqing/spider/monitor/projectManager.py", line 795, in get_request_from_keywords_hot
    self.search_spider_manager.crawl_by_keyword(
    │    │                     └ <function SearchSpidersManager.crawl_by_keyword at 0x7f9162b00040>
    │    └ <monitor.spiderManager.SearchSpidersManager object at 0x7f916270f0d0>
    └ <monitor.projectManager.ProjectManager object at 0x7f9162af4700>

  File "/home/users/Scy/yuqing/spider/monitor/spiderManager.py", line 118, in crawl_by_keyword
    self.crawl_by_keyword_signal_platform(project_names, platform, keyword, crawl_time, project_times)
    │    │                                │              │         │        │           └ {'default': <monitor.TimeSection object at 0x7f91628317f0>}
    │    │                                │              │         │        └ <monitor.TimeSection object at 0x7f9253d81550>
    │    │                                │              │         └ '第78集团军某旅：“伴随保障”强化战场意识'
    │    │                                │              └ '人民网'
    │    │                                └ ['default']
    │    └ <function SearchSpidersManager.crawl_by_keyword_signal_platform at 0x7f9162b000d0>
    └ <monitor.spiderManager.SearchSpidersManager object at 0x7f916270f0d0>

  File "/home/users/Scy/yuqing/spider/monitor/spiderManager.py", line 134, in crawl_by_keyword_signal_platform
    requests = self.get_request_from_keyword(platform, keyword, **crawl_time.to_dict())
               │    │                        │         │          │          └ <function TimeSection.to_dict at 0x7f925aaa8550>
               │    │                        │         │          └ <monitor.TimeSection object at 0x7f9253d81550>
               │    │                        │         └ '第78集团军某旅：“伴随保障”强化战场意识'
               │    │                        └ '人民网'
               │    └ <function SearchSpidersManager.get_request_from_keyword at 0x7f9162b001f0>
               └ <monitor.spiderManager.SearchSpidersManager object at 0x7f916270f0d0>

  File "/home/users/Scy/yuqing/spider/monitor/spiderManager.py", line 191, in get_request_from_keyword
    for request in self.spiders[platform].get_request_from_keyword(headers, search_url, keyword, content_url,
                   │    │       │                                  │        │           │        └ <string.Template object at 0x7f9104077520>
                   │    │       │                                  │        │           └ '第78集团军某旅：“伴随保障”强化战场意识'
                   │    │       │                                  │        └ <string.Template object at 0x7f9253fda760>
                   │    │       │                                  └ {'Accept': 'application/json, text/plain, */*', 'Accept-Language': 'zh-CN,zh;q=0.9', 'Connection': 'keep-alive', 'Origin': 'h...
                   │    │       └ '人民网'
                   │    └ {'凤凰网': <monitor.searchSpiders.ifeng.Ifeng object at 0x7f916270f220>, '头条': <monitor.searchSpiders.toutiao.Toutiao object at ...
                   └ <monitor.spiderManager.SearchSpidersManager object at 0x7f916270f0d0>

> File "/home/users/Scy/yuqing/spider/monitor/searchSpiders/people.py", line 28, in get_request_from_keyword
    response = requests.post(search_url.substitute(), json=data, headers=headers)
               │        │    │          │                  │             └ {'Accept': 'application/json, text/plain, */*', 'Accept-Language': 'zh-CN,zh;q=0.9', 'Connection': 'keep-alive', 'Origin': 'h...
               │        │    │          │                  └ {'key': '第78集团军某旅：“伴随保障”强化战场意识', 'page': 1, 'limit': 10, 'hasTitle': True, 'hasContent': True, 'isFuzzy': True, 'type': 0, 's...
               │        │    │          └ <function Template.substitute at 0x7f927a5fd0d0>
               │        │    └ <string.Template object at 0x7f9253fda760>
               │        └ <function post at 0x7f92583e73a0>
               └ <module 'requests' from '/home/chase/.local/lib/python3.8/site-packages/requests/__init__.py'>

  File "/home/chase/.local/lib/python3.8/site-packages/requests/api.py", line 117, in post
    return request('post', url, data=data, json=json, **kwargs)
           │               │         │          │       └ {'headers': {'Accept': 'application/json, text/plain, */*', 'Accept-Language': 'zh-CN,zh;q=0.9', 'Connection': 'keep-alive', ...
           │               │         │          └ {'key': '第78集团军某旅：“伴随保障”强化战场意识', 'page': 1, 'limit': 10, 'hasTitle': True, 'hasContent': True, 'isFuzzy': True, 'type': 0, 's...
           │               │         └ None
           │               └ 'http://search.people.cn/search-platform/front/search'
           └ <function request at 0x7f9258455040>
  File "/home/chase/.local/lib/python3.8/site-packages/requests/api.py", line 61, in request
    return session.request(method=method, url=url, **kwargs)
           │       │              │           │      └ {'data': None, 'json': {'key': '第78集团军某旅：“伴随保障”强化战场意识', 'page': 1, 'limit': 10, 'hasTitle': True, 'hasContent': True, 'isFuzz...
           │       │              │           └ 'http://search.people.cn/search-platform/front/search'
           │       │              └ 'post'
           │       └ <function Session.request at 0x7f92583e6940>
           └ <requests.sessions.Session object at 0x7f90e4760e20>
  File "/home/chase/.local/lib/python3.8/site-packages/requests/sessions.py", line 542, in request
    resp = self.send(prep, **send_kwargs)
           │    │    │       └ {'timeout': None, 'allow_redirects': True, 'verify': True, 'proxies': OrderedDict(), 'stream': False, 'cert': None}
           │    │    └ <PreparedRequest [POST]>
           │    └ <function Session.send at 0x7f92583e6dc0>
           └ <requests.sessions.Session object at 0x7f90e4760e20>
  File "/home/chase/.local/lib/python3.8/site-packages/requests/sessions.py", line 655, in send
    r = adapter.send(request, **kwargs)
        │       │    │          └ {'timeout': None, 'verify': True, 'proxies': OrderedDict(), 'stream': False, 'cert': None}
        │       │    └ <PreparedRequest [POST]>
        │       └ <function HTTPAdapter.send at 0x7f92583e6280>
        └ <requests.adapters.HTTPAdapter object at 0x7f90e475cc10>
  File "/home/chase/.local/lib/python3.8/site-packages/requests/adapters.py", line 516, in send
    raise ConnectionError(e, request=request)
          │                          └ <PreparedRequest [POST]>
          └ <class 'requests.exceptions.ConnectionError'>

requests.exceptions.ConnectionError: HTTPConnectionPool(host='search.people.cn', port=80): Max retries exceeded with url: /search-platform/front/search (Caused by NewConnectionError('<urllib3.connection.HTTPConnection object at 0x7f90e476f370>: Failed to establish a new connection: [Errno 111] Connection refused'))
2022-05-12 15:48:45.388 | ERROR    | monitor.searchSpiders.qinagguoLT:get_request_from_keyword:27 - E 强国论坛错误HTTPConnectionPool(host='bbs1.people.com.cn', port=80): Max retries exceeded with url: /board/1.html (Caused by NewConnectionError('<urllib3.connection.HTTPConnection object at 0x7f90e47306a0>: Failed to establish a new connection: [Errno 111] Connection refused'))
Traceback (most recent call last):

  File "/home/chase/.local/lib/python3.8/site-packages/urllib3/connection.py", line 174, in _new_conn
    conn = connection.create_connection(
           │          └ <function create_connection at 0x7f92585fd1f0>
           └ <module 'urllib3.util.connection' from '/home/chase/.local/lib/python3.8/site-packages/urllib3/util/connection.py'>
  File "/home/chase/.local/lib/python3.8/site-packages/urllib3/util/connection.py", line 96, in create_connection
    raise err
          └ ConnectionRefusedError(111, 'Connection refused')
  File "/home/chase/.local/lib/python3.8/site-packages/urllib3/util/connection.py", line 86, in create_connection
    sock.connect(sa)
    │            └ ('118.212.233.223', 80)
    └ None

ConnectionRefusedError: [Errno 111] Connection refused


During handling of the above exception, another exception occurred:


Traceback (most recent call last):

  File "/home/chase/.local/lib/python3.8/site-packages/urllib3/connectionpool.py", line 699, in urlopen
    httplib_response = self._make_request(
                       │    └ <function HTTPConnectionPool._make_request at 0x7f92585c05e0>
                       └ <urllib3.connectionpool.HTTPConnectionPool object at 0x7f90e4740850>
  File "/home/chase/.local/lib/python3.8/site-packages/urllib3/connectionpool.py", line 394, in _make_request
    conn.request(method, url, **httplib_request_kw)
    │    │       │       │      └ {'body': None, 'headers': {'User-Agent': 'Mozilla/5.0 (X11; Linux x86_64) AppleWebKit/537.36 (KHTML, like Gecko) Chrome/93.0....
    │    │       │       └ '/board/1.html'
    │    │       └ 'GET'
    │    └ <function HTTPConnection.request at 0x7f92585b0f70>
    └ <urllib3.connection.HTTPConnection object at 0x7f90e47306a0>
  File "/home/chase/.local/lib/python3.8/site-packages/urllib3/connection.py", line 239, in request
    super(HTTPConnection, self).request(method, url, body=body, headers=headers)
          │               │             │       │         │             └ {'User-Agent': 'Mozilla/5.0 (X11; Linux x86_64) AppleWebKit/537.36 (KHTML, like Gecko) Chrome/93.0.4577.63 Safari/537.36', 'A...
          │               │             │       │         └ None
          │               │             │       └ '/board/1.html'
          │               │             └ 'GET'
          │               └ <urllib3.connection.HTTPConnection object at 0x7f90e47306a0>
          └ <class 'urllib3.connection.HTTPConnection'>
  File "/usr/lib/python3.8/http/client.py", line 1256, in request
    self._send_request(method, url, body, headers, encode_chunked)
    │    │             │       │    │     │        └ False
    │    │             │       │    │     └ {'User-Agent': 'Mozilla/5.0 (X11; Linux x86_64) AppleWebKit/537.36 (KHTML, like Gecko) Chrome/93.0.4577.63 Safari/537.36', 'A...
    │    │             │       │    └ None
    │    │             │       └ '/board/1.html'
    │    │             └ 'GET'
    │    └ <function HTTPConnection._send_request at 0x7f926be50280>
    └ <urllib3.connection.HTTPConnection object at 0x7f90e47306a0>
  File "/usr/lib/python3.8/http/client.py", line 1302, in _send_request
    self.endheaders(body, encode_chunked=encode_chunked)
    │    │          │                    └ False
    │    │          └ None
    │    └ <function HTTPConnection.endheaders at 0x7f926be50160>
    └ <urllib3.connection.HTTPConnection object at 0x7f90e47306a0>
  File "/usr/lib/python3.8/http/client.py", line 1251, in endheaders
    self._send_output(message_body, encode_chunked=encode_chunked)
    │    │            │                            └ False
    │    │            └ None
    │    └ <function HTTPConnection._send_output at 0x7f926beb7d30>
    └ <urllib3.connection.HTTPConnection object at 0x7f90e47306a0>
  File "/usr/lib/python3.8/http/client.py", line 1011, in _send_output
    self.send(msg)
    │    │    └ b'GET /board/1.html HTTP/1.1\r\nHost: bbs1.people.com.cn\r\nUser-Agent: Mozilla/5.0 (X11; Linux x86_64) AppleWebKit/537.36 (K...
    │    └ <function HTTPConnection.send at 0x7f926beb7b80>
    └ <urllib3.connection.HTTPConnection object at 0x7f90e47306a0>
  File "/usr/lib/python3.8/http/client.py", line 951, in send
    self.connect()
    │    └ <function HTTPConnection.connect at 0x7f92585b0dc0>
    └ <urllib3.connection.HTTPConnection object at 0x7f90e47306a0>
  File "/home/chase/.local/lib/python3.8/site-packages/urllib3/connection.py", line 205, in connect
    conn = self._new_conn()
           │    └ <function HTTPConnection._new_conn at 0x7f92585b0c10>
           └ <urllib3.connection.HTTPConnection object at 0x7f90e47306a0>
  File "/home/chase/.local/lib/python3.8/site-packages/urllib3/connection.py", line 186, in _new_conn
    raise NewConnectionError(
          └ <class 'urllib3.exceptions.NewConnectionError'>

urllib3.exceptions.NewConnectionError: <urllib3.connection.HTTPConnection object at 0x7f90e47306a0>: Failed to establish a new connection: [Errno 111] Connection refused


During handling of the above exception, another exception occurred:


Traceback (most recent call last):

  File "/home/chase/.local/lib/python3.8/site-packages/requests/adapters.py", line 439, in send
    resp = conn.urlopen(
           │    └ <function HTTPConnectionPool.urlopen at 0x7f92585c0820>
           └ <urllib3.connectionpool.HTTPConnectionPool object at 0x7f90e4740850>
  File "/home/chase/.local/lib/python3.8/site-packages/urllib3/connectionpool.py", line 755, in urlopen
    retries = retries.increment(
              │       └ <function Retry.increment at 0x7f9258608b80>
              └ Retry(total=0, connect=None, read=False, redirect=None, status=None)
  File "/home/chase/.local/lib/python3.8/site-packages/urllib3/util/retry.py", line 574, in increment
    raise MaxRetryError(_pool, url, error or ResponseError(cause))
          │             │      │    │        │             └ 'unknown'
          │             │      │    │        └ <class 'urllib3.exceptions.ResponseError'>
          │             │      │    └ NewConnectionError('<urllib3.connection.HTTPConnection object at 0x7f90e47306a0>: Failed to establish a new connection: [Errn...
          │             │      └ '/board/1.html'
          │             └ <urllib3.connectionpool.HTTPConnectionPool object at 0x7f90e4740850>
          └ <class 'urllib3.exceptions.MaxRetryError'>

urllib3.exceptions.MaxRetryError: HTTPConnectionPool(host='bbs1.people.com.cn', port=80): Max retries exceeded with url: /board/1.html (Caused by NewConnectionError('<urllib3.connection.HTTPConnection object at 0x7f90e47306a0>: Failed to establish a new connection: [Errno 111] Connection refused'))


During handling of the above exception, another exception occurred:


Traceback (most recent call last):

  File "/usr/lib/python3.8/threading.py", line 890, in _bootstrap
    self._bootstrap_inner()
    │    └ <function Thread._bootstrap_inner at 0x7f927a614a60>
    └ <Thread(Thread-226, started daemon 140258708539136)>
  File "/usr/lib/python3.8/threading.py", line 932, in _bootstrap_inner
    self.run()
    │    └ <function Thread.run at 0x7f927a614790>
    └ <Thread(Thread-226, started daemon 140258708539136)>
  File "/usr/lib/python3.8/threading.py", line 870, in run
    self._target(*self._args, **self._kwargs)
    │    │        │    │        │    └ {}
    │    │        │    │        └ <Thread(Thread-226, started daemon 140258708539136)>
    │    │        │    └ ('ProjectManager.run_func_by_thread',)
    │    │        └ <Thread(Thread-226, started daemon 140258708539136)>
    │    └ <bound method ProjectManager.get_request_from_keywords_hot of <monitor.projectManager.ProjectManager object at 0x7f9162af4700>>
    └ <Thread(Thread-226, started daemon 140258708539136)>

  File "/home/users/Scy/yuqing/spider/monitor/projectManager.py", line 795, in get_request_from_keywords_hot
    self.search_spider_manager.crawl_by_keyword(
    │    │                     └ <function SearchSpidersManager.crawl_by_keyword at 0x7f9162b00040>
    │    └ <monitor.spiderManager.SearchSpidersManager object at 0x7f916270f0d0>
    └ <monitor.projectManager.ProjectManager object at 0x7f9162af4700>

  File "/home/users/Scy/yuqing/spider/monitor/spiderManager.py", line 118, in crawl_by_keyword
    self.crawl_by_keyword_signal_platform(project_names, platform, keyword, crawl_time, project_times)
    │    │                                │              │         │        │           └ {'default': <monitor.TimeSection object at 0x7f91628317f0>}
    │    │                                │              │         │        └ <monitor.TimeSection object at 0x7f91481ea730>
    │    │                                │              │         └ '应对气候变化，中国重信守诺（国际论坛）'
    │    │                                │              └ '强国论坛'
    │    │                                └ ['default']
    │    └ <function SearchSpidersManager.crawl_by_keyword_signal_platform at 0x7f9162b000d0>
    └ <monitor.spiderManager.SearchSpidersManager object at 0x7f916270f0d0>

  File "/home/users/Scy/yuqing/spider/monitor/spiderManager.py", line 134, in crawl_by_keyword_signal_platform
    requests = self.get_request_from_keyword(platform, keyword, **crawl_time.to_dict())
               │    │                        │         │          │          └ <function TimeSection.to_dict at 0x7f925aaa8550>
               │    │                        │         │          └ <monitor.TimeSection object at 0x7f91481ea730>
               │    │                        │         └ '应对气候变化，中国重信守诺（国际论坛）'
               │    │                        └ '强国论坛'
               │    └ <function SearchSpidersManager.get_request_from_keyword at 0x7f9162b001f0>
               └ <monitor.spiderManager.SearchSpidersManager object at 0x7f916270f0d0>

  File "/home/users/Scy/yuqing/spider/monitor/spiderManager.py", line 191, in get_request_from_keyword
    for request in self.spiders[platform].get_request_from_keyword(headers, search_url, keyword, content_url,
                   │    │       │                                  │        │           │        └ <string.Template object at 0x7f90e4701a90>
                   │    │       │                                  │        │           └ '应对气候变化，中国重信守诺（国际论坛）'
                   │    │       │                                  │        └ <string.Template object at 0x7f910404ab20>
                   │    │       │                                  └ {'Connection': 'keep-alive', 'Cache-Control': 'max-age=0', 'Upgrade-Insecure-Requests': '1', 'User-Agent': 'Mozilla/5.0 (X11;...
                   │    │       └ '强国论坛'
                   │    └ {'凤凰网': <monitor.searchSpiders.ifeng.Ifeng object at 0x7f916270f220>, '头条': <monitor.searchSpiders.toutiao.Toutiao object at ...
                   └ <monitor.spiderManager.SearchSpidersManager object at 0x7f916270f0d0>

> File "/home/users/Scy/yuqing/spider/monitor/searchSpiders/qinagguoLT.py", line 18, in get_request_from_keyword
    response = requests.get(search_url.substitute(), headers=headers)
               │        │   │          │                     └ {'Connection': 'keep-alive', 'Cache-Control': 'max-age=0', 'Upgrade-Insecure-Requests': '1', 'User-Agent': 'Mozilla/5.0 (X11;...
               │        │   │          └ <function Template.substitute at 0x7f927a5fd0d0>
               │        │   └ <string.Template object at 0x7f910404ab20>
               │        └ <function get at 0x7f92583e71f0>
               └ <module 'requests' from '/home/chase/.local/lib/python3.8/site-packages/requests/__init__.py'>

  File "/home/chase/.local/lib/python3.8/site-packages/requests/api.py", line 75, in get
    return request('get', url, params=params, **kwargs)
           │              │           │         └ {'headers': {'Connection': 'keep-alive', 'Cache-Control': 'max-age=0', 'Upgrade-Insecure-Requests': '1', 'User-Agent': 'Mozil...
           │              │           └ None
           │              └ 'http://bbs1.people.com.cn/board/1.html'
           └ <function request at 0x7f9258455040>
  File "/home/chase/.local/lib/python3.8/site-packages/requests/api.py", line 61, in request
    return session.request(method=method, url=url, **kwargs)
           │       │              │           │      └ {'params': None, 'headers': {'Connection': 'keep-alive', 'Cache-Control': 'max-age=0', 'Upgrade-Insecure-Requests': '1', 'Use...
           │       │              │           └ 'http://bbs1.people.com.cn/board/1.html'
           │       │              └ 'get'
           │       └ <function Session.request at 0x7f92583e6940>
           └ <requests.sessions.Session object at 0x7f91600c3310>
  File "/home/chase/.local/lib/python3.8/site-packages/requests/sessions.py", line 542, in request
    resp = self.send(prep, **send_kwargs)
           │    │    │       └ {'timeout': None, 'allow_redirects': True, 'verify': True, 'proxies': OrderedDict(), 'stream': False, 'cert': None}
           │    │    └ <PreparedRequest [GET]>
           │    └ <function Session.send at 0x7f92583e6dc0>
           └ <requests.sessions.Session object at 0x7f91600c3310>
  File "/home/chase/.local/lib/python3.8/site-packages/requests/sessions.py", line 655, in send
    r = adapter.send(request, **kwargs)
        │       │    │          └ {'timeout': None, 'verify': True, 'proxies': OrderedDict(), 'stream': False, 'cert': None}
        │       │    └ <PreparedRequest [GET]>
        │       └ <function HTTPAdapter.send at 0x7f92583e6280>
        └ <requests.adapters.HTTPAdapter object at 0x7f91247e7d60>
  File "/home/chase/.local/lib/python3.8/site-packages/requests/adapters.py", line 516, in send
    raise ConnectionError(e, request=request)
          │                          └ <PreparedRequest [GET]>
          └ <class 'requests.exceptions.ConnectionError'>

requests.exceptions.ConnectionError: HTTPConnectionPool(host='bbs1.people.com.cn', port=80): Max retries exceeded with url: /board/1.html (Caused by NewConnectionError('<urllib3.connection.HTTPConnection object at 0x7f90e47306a0>: Failed to establish a new connection: [Errno 111] Connection refused'))
2022-05-12 15:48:45.488 | ERROR    | monitor.searchSpiders.people:get_request_from_keyword:45 - E 人民网错误HTTPConnectionPool(host='search.people.cn', port=80): Max retries exceeded with url: /search-platform/front/search (Caused by NewConnectionError('<urllib3.connection.HTTPConnection object at 0x7f91040f0df0>: Failed to establish a new connection: [Errno 111] Connection refused'))
Traceback (most recent call last):

  File "/home/chase/.local/lib/python3.8/site-packages/urllib3/connection.py", line 174, in _new_conn
    conn = connection.create_connection(
           │          └ <function create_connection at 0x7f92585fd1f0>
           └ <module 'urllib3.util.connection' from '/home/chase/.local/lib/python3.8/site-packages/urllib3/util/connection.py'>
  File "/home/chase/.local/lib/python3.8/site-packages/urllib3/util/connection.py", line 96, in create_connection
    raise err
          └ ConnectionRefusedError(111, 'Connection refused')
  File "/home/chase/.local/lib/python3.8/site-packages/urllib3/util/connection.py", line 86, in create_connection
    sock.connect(sa)
    │            └ ('1.31.128.246', 80)
    └ None

ConnectionRefusedError: [Errno 111] Connection refused


During handling of the above exception, another exception occurred:


Traceback (most recent call last):

  File "/home/chase/.local/lib/python3.8/site-packages/urllib3/connectionpool.py", line 699, in urlopen
    httplib_response = self._make_request(
                       │    └ <function HTTPConnectionPool._make_request at 0x7f92585c05e0>
                       └ <urllib3.connectionpool.HTTPConnectionPool object at 0x7f90e47285e0>
  File "/home/chase/.local/lib/python3.8/site-packages/urllib3/connectionpool.py", line 394, in _make_request
    conn.request(method, url, **httplib_request_kw)
    │    │       │       │      └ {'body': b'{"key": "\\u7b2c71\\u96c6\\u56e2\\u519b\\u67d0\\u65c5\\u8425\\u9020\\u79d1\\u5b66\\u9009\\u4eba\\u7528\\u4eba\\u80...
    │    │       │       └ '/search-platform/front/search'
    │    │       └ 'POST'
    │    └ <function HTTPConnection.request at 0x7f92585b0f70>
    └ <urllib3.connection.HTTPConnection object at 0x7f91040f0df0>
  File "/home/chase/.local/lib/python3.8/site-packages/urllib3/connection.py", line 239, in request
    super(HTTPConnection, self).request(method, url, body=body, headers=headers)
          │               │             │       │         │             └ {'User-Agent': 'Mozilla/5.0 (Windows NT 10.0; Win64; x64) AppleWebKit/537.36 (KHTML, like Gecko) Chrome/101.0.4951.54 Safari/...
          │               │             │       │         └ b'{"key": "\\u7b2c71\\u96c6\\u56e2\\u519b\\u67d0\\u65c5\\u8425\\u9020\\u79d1\\u5b66\\u9009\\u4eba\\u7528\\u4eba\\u80b2\\u4eba...
          │               │             │       └ '/search-platform/front/search'
          │               │             └ 'POST'
          │               └ <urllib3.connection.HTTPConnection object at 0x7f91040f0df0>
          └ <class 'urllib3.connection.HTTPConnection'>
  File "/usr/lib/python3.8/http/client.py", line 1256, in request
    self._send_request(method, url, body, headers, encode_chunked)
    │    │             │       │    │     │        └ False
    │    │             │       │    │     └ {'User-Agent': 'Mozilla/5.0 (Windows NT 10.0; Win64; x64) AppleWebKit/537.36 (KHTML, like Gecko) Chrome/101.0.4951.54 Safari/...
    │    │             │       │    └ b'{"key": "\\u7b2c71\\u96c6\\u56e2\\u519b\\u67d0\\u65c5\\u8425\\u9020\\u79d1\\u5b66\\u9009\\u4eba\\u7528\\u4eba\\u80b2\\u4eba...
    │    │             │       └ '/search-platform/front/search'
    │    │             └ 'POST'
    │    └ <function HTTPConnection._send_request at 0x7f926be50280>
    └ <urllib3.connection.HTTPConnection object at 0x7f91040f0df0>
  File "/usr/lib/python3.8/http/client.py", line 1302, in _send_request
    self.endheaders(body, encode_chunked=encode_chunked)
    │    │          │                    └ False
    │    │          └ b'{"key": "\\u7b2c71\\u96c6\\u56e2\\u519b\\u67d0\\u65c5\\u8425\\u9020\\u79d1\\u5b66\\u9009\\u4eba\\u7528\\u4eba\\u80b2\\u4eba...
    │    └ <function HTTPConnection.endheaders at 0x7f926be50160>
    └ <urllib3.connection.HTTPConnection object at 0x7f91040f0df0>
  File "/usr/lib/python3.8/http/client.py", line 1251, in endheaders
    self._send_output(message_body, encode_chunked=encode_chunked)
    │    │            │                            └ False
    │    │            └ b'{"key": "\\u7b2c71\\u96c6\\u56e2\\u519b\\u67d0\\u65c5\\u8425\\u9020\\u79d1\\u5b66\\u9009\\u4eba\\u7528\\u4eba\\u80b2\\u4eba...
    │    └ <function HTTPConnection._send_output at 0x7f926beb7d30>
    └ <urllib3.connection.HTTPConnection object at 0x7f91040f0df0>
  File "/usr/lib/python3.8/http/client.py", line 1011, in _send_output
    self.send(msg)
    │    │    └ b'POST /search-platform/front/search HTTP/1.1\r\nHost: search.people.cn\r\nUser-Agent: Mozilla/5.0 (Windows NT 10.0; Win64; x...
    │    └ <function HTTPConnection.send at 0x7f926beb7b80>
    └ <urllib3.connection.HTTPConnection object at 0x7f91040f0df0>
  File "/usr/lib/python3.8/http/client.py", line 951, in send
    self.connect()
    │    └ <function HTTPConnection.connect at 0x7f92585b0dc0>
    └ <urllib3.connection.HTTPConnection object at 0x7f91040f0df0>
  File "/home/chase/.local/lib/python3.8/site-packages/urllib3/connection.py", line 205, in connect
    conn = self._new_conn()
           │    └ <function HTTPConnection._new_conn at 0x7f92585b0c10>
           └ <urllib3.connection.HTTPConnection object at 0x7f91040f0df0>
  File "/home/chase/.local/lib/python3.8/site-packages/urllib3/connection.py", line 186, in _new_conn
    raise NewConnectionError(
          └ <class 'urllib3.exceptions.NewConnectionError'>

urllib3.exceptions.NewConnectionError: <urllib3.connection.HTTPConnection object at 0x7f91040f0df0>: Failed to establish a new connection: [Errno 111] Connection refused


During handling of the above exception, another exception occurred:


Traceback (most recent call last):

  File "/home/chase/.local/lib/python3.8/site-packages/requests/adapters.py", line 439, in send
    resp = conn.urlopen(
           │    └ <function HTTPConnectionPool.urlopen at 0x7f92585c0820>
           └ <urllib3.connectionpool.HTTPConnectionPool object at 0x7f90e47285e0>
  File "/home/chase/.local/lib/python3.8/site-packages/urllib3/connectionpool.py", line 755, in urlopen
    retries = retries.increment(
              │       └ <function Retry.increment at 0x7f9258608b80>
              └ Retry(total=0, connect=None, read=False, redirect=None, status=None)
  File "/home/chase/.local/lib/python3.8/site-packages/urllib3/util/retry.py", line 574, in increment
    raise MaxRetryError(_pool, url, error or ResponseError(cause))
          │             │      │    │        │             └ 'unknown'
          │             │      │    │        └ <class 'urllib3.exceptions.ResponseError'>
          │             │      │    └ NewConnectionError('<urllib3.connection.HTTPConnection object at 0x7f91040f0df0>: Failed to establish a new connection: [Errn...
          │             │      └ '/search-platform/front/search'
          │             └ <urllib3.connectionpool.HTTPConnectionPool object at 0x7f90e47285e0>
          └ <class 'urllib3.exceptions.MaxRetryError'>

urllib3.exceptions.MaxRetryError: HTTPConnectionPool(host='search.people.cn', port=80): Max retries exceeded with url: /search-platform/front/search (Caused by NewConnectionError('<urllib3.connection.HTTPConnection object at 0x7f91040f0df0>: Failed to establish a new connection: [Errno 111] Connection refused'))


During handling of the above exception, another exception occurred:


Traceback (most recent call last):

  File "/usr/lib/python3.8/threading.py", line 890, in _bootstrap
    self._bootstrap_inner()
    │    └ <function Thread._bootstrap_inner at 0x7f927a614a60>
    └ <Thread(Thread-231, started daemon 140258700146432)>
  File "/usr/lib/python3.8/threading.py", line 932, in _bootstrap_inner
    self.run()
    │    └ <function Thread.run at 0x7f927a614790>
    └ <Thread(Thread-231, started daemon 140258700146432)>
  File "/usr/lib/python3.8/threading.py", line 870, in run
    self._target(*self._args, **self._kwargs)
    │    │        │    │        │    └ {}
    │    │        │    │        └ <Thread(Thread-231, started daemon 140258700146432)>
    │    │        │    └ ('ProjectManager.run_func_by_thread',)
    │    │        └ <Thread(Thread-231, started daemon 140258700146432)>
    │    └ <bound method ProjectManager.get_request_from_keywords_hot of <monitor.projectManager.ProjectManager object at 0x7f9162af4700>>
    └ <Thread(Thread-231, started daemon 140258700146432)>

  File "/home/users/Scy/yuqing/spider/monitor/projectManager.py", line 795, in get_request_from_keywords_hot
    self.search_spider_manager.crawl_by_keyword(
    │    │                     └ <function SearchSpidersManager.crawl_by_keyword at 0x7f9162b00040>
    │    └ <monitor.spiderManager.SearchSpidersManager object at 0x7f916270f0d0>
    └ <monitor.projectManager.ProjectManager object at 0x7f9162af4700>

  File "/home/users/Scy/yuqing/spider/monitor/spiderManager.py", line 118, in crawl_by_keyword
    self.crawl_by_keyword_signal_platform(project_names, platform, keyword, crawl_time, project_times)
    │    │                                │              │         │        │           └ {'default': <monitor.TimeSection object at 0x7f91628317f0>}
    │    │                                │              │         │        └ <monitor.TimeSection object at 0x7f9148139100>
    │    │                                │              │         └ '第71集团军某旅营造科学选人用人育人环境'
    │    │                                │              └ '人民网'
    │    │                                └ ['default']
    │    └ <function SearchSpidersManager.crawl_by_keyword_signal_platform at 0x7f9162b000d0>
    └ <monitor.spiderManager.SearchSpidersManager object at 0x7f916270f0d0>

  File "/home/users/Scy/yuqing/spider/monitor/spiderManager.py", line 134, in crawl_by_keyword_signal_platform
    requests = self.get_request_from_keyword(platform, keyword, **crawl_time.to_dict())
               │    │                        │         │          │          └ <function TimeSection.to_dict at 0x7f925aaa8550>
               │    │                        │         │          └ <monitor.TimeSection object at 0x7f9148139100>
               │    │                        │         └ '第71集团军某旅营造科学选人用人育人环境'
               │    │                        └ '人民网'
               │    └ <function SearchSpidersManager.get_request_from_keyword at 0x7f9162b001f0>
               └ <monitor.spiderManager.SearchSpidersManager object at 0x7f916270f0d0>

  File "/home/users/Scy/yuqing/spider/monitor/spiderManager.py", line 191, in get_request_from_keyword
    for request in self.spiders[platform].get_request_from_keyword(headers, search_url, keyword, content_url,
                   │    │       │                                  │        │           │        └ <string.Template object at 0x7f91042d8370>
                   │    │       │                                  │        │           └ '第71集团军某旅营造科学选人用人育人环境'
                   │    │       │                                  │        └ <string.Template object at 0x7f91041e33a0>
                   │    │       │                                  └ {'Accept': 'application/json, text/plain, */*', 'Accept-Language': 'zh-CN,zh;q=0.9', 'Connection': 'keep-alive', 'Origin': 'h...
                   │    │       └ '人民网'
                   │    └ {'凤凰网': <monitor.searchSpiders.ifeng.Ifeng object at 0x7f916270f220>, '头条': <monitor.searchSpiders.toutiao.Toutiao object at ...
                   └ <monitor.spiderManager.SearchSpidersManager object at 0x7f916270f0d0>

> File "/home/users/Scy/yuqing/spider/monitor/searchSpiders/people.py", line 28, in get_request_from_keyword
    response = requests.post(search_url.substitute(), json=data, headers=headers)
               │        │    │          │                  │             └ {'Accept': 'application/json, text/plain, */*', 'Accept-Language': 'zh-CN,zh;q=0.9', 'Connection': 'keep-alive', 'Origin': 'h...
               │        │    │          │                  └ {'key': '第71集团军某旅营造科学选人用人育人环境', 'page': 1, 'limit': 10, 'hasTitle': True, 'hasContent': True, 'isFuzzy': True, 'type': 0, 'so...
               │        │    │          └ <function Template.substitute at 0x7f927a5fd0d0>
               │        │    └ <string.Template object at 0x7f91041e33a0>
               │        └ <function post at 0x7f92583e73a0>
               └ <module 'requests' from '/home/chase/.local/lib/python3.8/site-packages/requests/__init__.py'>

  File "/home/chase/.local/lib/python3.8/site-packages/requests/api.py", line 117, in post
    return request('post', url, data=data, json=json, **kwargs)
           │               │         │          │       └ {'headers': {'Accept': 'application/json, text/plain, */*', 'Accept-Language': 'zh-CN,zh;q=0.9', 'Connection': 'keep-alive', ...
           │               │         │          └ {'key': '第71集团军某旅营造科学选人用人育人环境', 'page': 1, 'limit': 10, 'hasTitle': True, 'hasContent': True, 'isFuzzy': True, 'type': 0, 'so...
           │               │         └ None
           │               └ 'http://search.people.cn/search-platform/front/search'
           └ <function request at 0x7f9258455040>
  File "/home/chase/.local/lib/python3.8/site-packages/requests/api.py", line 61, in request
    return session.request(method=method, url=url, **kwargs)
           │       │              │           │      └ {'data': None, 'json': {'key': '第71集团军某旅营造科学选人用人育人环境', 'page': 1, 'limit': 10, 'hasTitle': True, 'hasContent': True, 'isFuzzy...
           │       │              │           └ 'http://search.people.cn/search-platform/front/search'
           │       │              └ 'post'
           │       └ <function Session.request at 0x7f92583e6940>
           └ <requests.sessions.Session object at 0x7f90e47375e0>
  File "/home/chase/.local/lib/python3.8/site-packages/requests/sessions.py", line 542, in request
    resp = self.send(prep, **send_kwargs)
           │    │    │       └ {'timeout': None, 'allow_redirects': True, 'verify': True, 'proxies': OrderedDict(), 'stream': False, 'cert': None}
           │    │    └ <PreparedRequest [POST]>
           │    └ <function Session.send at 0x7f92583e6dc0>
           └ <requests.sessions.Session object at 0x7f90e47375e0>
  File "/home/chase/.local/lib/python3.8/site-packages/requests/sessions.py", line 655, in send
    r = adapter.send(request, **kwargs)
        │       │    │          └ {'timeout': None, 'verify': True, 'proxies': OrderedDict(), 'stream': False, 'cert': None}
        │       │    └ <PreparedRequest [POST]>
        │       └ <function HTTPAdapter.send at 0x7f92583e6280>
        └ <requests.adapters.HTTPAdapter object at 0x7f9148591dc0>
  File "/home/chase/.local/lib/python3.8/site-packages/requests/adapters.py", line 516, in send
    raise ConnectionError(e, request=request)
          │                          └ <PreparedRequest [POST]>
          └ <class 'requests.exceptions.ConnectionError'>

requests.exceptions.ConnectionError: HTTPConnectionPool(host='search.people.cn', port=80): Max retries exceeded with url: /search-platform/front/search (Caused by NewConnectionError('<urllib3.connection.HTTPConnection object at 0x7f91040f0df0>: Failed to establish a new connection: [Errno 111] Connection refused'))
2022-05-12 15:48:45.895 | ERROR    | monitor.searchSpiders.people:get_request_from_keyword:45 - E 人民网错误HTTPConnectionPool(host='search.people.cn', port=80): Max retries exceeded with url: /search-platform/front/search (Caused by NewConnectionError('<urllib3.connection.HTTPConnection object at 0x7f9104189400>: Failed to establish a new connection: [Errno 111] Connection refused'))
Traceback (most recent call last):

  File "/home/chase/.local/lib/python3.8/site-packages/urllib3/connection.py", line 174, in _new_conn
    conn = connection.create_connection(
           │          └ <function create_connection at 0x7f92585fd1f0>
           └ <module 'urllib3.util.connection' from '/home/chase/.local/lib/python3.8/site-packages/urllib3/util/connection.py'>
  File "/home/chase/.local/lib/python3.8/site-packages/urllib3/util/connection.py", line 96, in create_connection
    raise err
          └ ConnectionRefusedError(111, 'Connection refused')
  File "/home/chase/.local/lib/python3.8/site-packages/urllib3/util/connection.py", line 86, in create_connection
    sock.connect(sa)
    │            └ ('1.31.128.246', 80)
    └ None

ConnectionRefusedError: [Errno 111] Connection refused


During handling of the above exception, another exception occurred:


Traceback (most recent call last):

  File "/home/chase/.local/lib/python3.8/site-packages/urllib3/connectionpool.py", line 699, in urlopen
    httplib_response = self._make_request(
                       │    └ <function HTTPConnectionPool._make_request at 0x7f92585c05e0>
                       └ <urllib3.connectionpool.HTTPConnectionPool object at 0x7f91480b9370>
  File "/home/chase/.local/lib/python3.8/site-packages/urllib3/connectionpool.py", line 394, in _make_request
    conn.request(method, url, **httplib_request_kw)
    │    │       │       │      └ {'body': b'{"key": "\\u5e94\\u5bf9\\u6c14\\u5019\\u53d8\\u5316\\uff0c\\u4e2d\\u56fd\\u91cd\\u4fe1\\u5b88\\u8bfa\\uff08\\u56fd...
    │    │       │       └ '/search-platform/front/search'
    │    │       └ 'POST'
    │    └ <function HTTPConnection.request at 0x7f92585b0f70>
    └ <urllib3.connection.HTTPConnection object at 0x7f9104189400>
  File "/home/chase/.local/lib/python3.8/site-packages/urllib3/connection.py", line 239, in request
    super(HTTPConnection, self).request(method, url, body=body, headers=headers)
          │               │             │       │         │             └ {'User-Agent': 'Mozilla/5.0 (Windows NT 10.0; Win64; x64) AppleWebKit/537.36 (KHTML, like Gecko) Chrome/101.0.4951.54 Safari/...
          │               │             │       │         └ b'{"key": "\\u5e94\\u5bf9\\u6c14\\u5019\\u53d8\\u5316\\uff0c\\u4e2d\\u56fd\\u91cd\\u4fe1\\u5b88\\u8bfa\\uff08\\u56fd\\u9645\\...
          │               │             │       └ '/search-platform/front/search'
          │               │             └ 'POST'
          │               └ <urllib3.connection.HTTPConnection object at 0x7f9104189400>
          └ <class 'urllib3.connection.HTTPConnection'>
  File "/usr/lib/python3.8/http/client.py", line 1256, in request
    self._send_request(method, url, body, headers, encode_chunked)
    │    │             │       │    │     │        └ False
    │    │             │       │    │     └ {'User-Agent': 'Mozilla/5.0 (Windows NT 10.0; Win64; x64) AppleWebKit/537.36 (KHTML, like Gecko) Chrome/101.0.4951.54 Safari/...
    │    │             │       │    └ b'{"key": "\\u5e94\\u5bf9\\u6c14\\u5019\\u53d8\\u5316\\uff0c\\u4e2d\\u56fd\\u91cd\\u4fe1\\u5b88\\u8bfa\\uff08\\u56fd\\u9645\\...
    │    │             │       └ '/search-platform/front/search'
    │    │             └ 'POST'
    │    └ <function HTTPConnection._send_request at 0x7f926be50280>
    └ <urllib3.connection.HTTPConnection object at 0x7f9104189400>
  File "/usr/lib/python3.8/http/client.py", line 1302, in _send_request
    self.endheaders(body, encode_chunked=encode_chunked)
    │    │          │                    └ False
    │    │          └ b'{"key": "\\u5e94\\u5bf9\\u6c14\\u5019\\u53d8\\u5316\\uff0c\\u4e2d\\u56fd\\u91cd\\u4fe1\\u5b88\\u8bfa\\uff08\\u56fd\\u9645\\...
    │    └ <function HTTPConnection.endheaders at 0x7f926be50160>
    └ <urllib3.connection.HTTPConnection object at 0x7f9104189400>
  File "/usr/lib/python3.8/http/client.py", line 1251, in endheaders
    self._send_output(message_body, encode_chunked=encode_chunked)
    │    │            │                            └ False
    │    │            └ b'{"key": "\\u5e94\\u5bf9\\u6c14\\u5019\\u53d8\\u5316\\uff0c\\u4e2d\\u56fd\\u91cd\\u4fe1\\u5b88\\u8bfa\\uff08\\u56fd\\u9645\\...
    │    └ <function HTTPConnection._send_output at 0x7f926beb7d30>
    └ <urllib3.connection.HTTPConnection object at 0x7f9104189400>
  File "/usr/lib/python3.8/http/client.py", line 1011, in _send_output
    self.send(msg)
    │    │    └ b'POST /search-platform/front/search HTTP/1.1\r\nHost: search.people.cn\r\nUser-Agent: Mozilla/5.0 (Windows NT 10.0; Win64; x...
    │    └ <function HTTPConnection.send at 0x7f926beb7b80>
    └ <urllib3.connection.HTTPConnection object at 0x7f9104189400>
  File "/usr/lib/python3.8/http/client.py", line 951, in send
    self.connect()
    │    └ <function HTTPConnection.connect at 0x7f92585b0dc0>
    └ <urllib3.connection.HTTPConnection object at 0x7f9104189400>
  File "/home/chase/.local/lib/python3.8/site-packages/urllib3/connection.py", line 205, in connect
    conn = self._new_conn()
           │    └ <function HTTPConnection._new_conn at 0x7f92585b0c10>
           └ <urllib3.connection.HTTPConnection object at 0x7f9104189400>
  File "/home/chase/.local/lib/python3.8/site-packages/urllib3/connection.py", line 186, in _new_conn
    raise NewConnectionError(
          └ <class 'urllib3.exceptions.NewConnectionError'>

urllib3.exceptions.NewConnectionError: <urllib3.connection.HTTPConnection object at 0x7f9104189400>: Failed to establish a new connection: [Errno 111] Connection refused


During handling of the above exception, another exception occurred:


Traceback (most recent call last):

  File "/home/chase/.local/lib/python3.8/site-packages/requests/adapters.py", line 439, in send
    resp = conn.urlopen(
           │    └ <function HTTPConnectionPool.urlopen at 0x7f92585c0820>
           └ <urllib3.connectionpool.HTTPConnectionPool object at 0x7f91480b9370>
  File "/home/chase/.local/lib/python3.8/site-packages/urllib3/connectionpool.py", line 755, in urlopen
    retries = retries.increment(
              │       └ <function Retry.increment at 0x7f9258608b80>
              └ Retry(total=0, connect=None, read=False, redirect=None, status=None)
  File "/home/chase/.local/lib/python3.8/site-packages/urllib3/util/retry.py", line 574, in increment
    raise MaxRetryError(_pool, url, error or ResponseError(cause))
          │             │      │    │        │             └ 'unknown'
          │             │      │    │        └ <class 'urllib3.exceptions.ResponseError'>
          │             │      │    └ NewConnectionError('<urllib3.connection.HTTPConnection object at 0x7f9104189400>: Failed to establish a new connection: [Errn...
          │             │      └ '/search-platform/front/search'
          │             └ <urllib3.connectionpool.HTTPConnectionPool object at 0x7f91480b9370>
          └ <class 'urllib3.exceptions.MaxRetryError'>

urllib3.exceptions.MaxRetryError: HTTPConnectionPool(host='search.people.cn', port=80): Max retries exceeded with url: /search-platform/front/search (Caused by NewConnectionError('<urllib3.connection.HTTPConnection object at 0x7f9104189400>: Failed to establish a new connection: [Errno 111] Connection refused'))


During handling of the above exception, another exception occurred:


Traceback (most recent call last):

  File "/usr/lib/python3.8/threading.py", line 890, in _bootstrap
    self._bootstrap_inner()
    │    └ <function Thread._bootstrap_inner at 0x7f927a614a60>
    └ <Thread(Thread-139, started daemon 140260302366464)>
  File "/usr/lib/python3.8/threading.py", line 932, in _bootstrap_inner
    self.run()
    │    └ <function Thread.run at 0x7f927a614790>
    └ <Thread(Thread-139, started daemon 140260302366464)>
  File "/usr/lib/python3.8/threading.py", line 870, in run
    self._target(*self._args, **self._kwargs)
    │    │        │    │        │    └ {}
    │    │        │    │        └ <Thread(Thread-139, started daemon 140260302366464)>
    │    │        │    └ ('ProjectManager.run_func_by_thread',)
    │    │        └ <Thread(Thread-139, started daemon 140260302366464)>
    │    └ <bound method ProjectManager.get_request_from_keywords_hot of <monitor.projectManager.ProjectManager object at 0x7f9162af4700>>
    └ <Thread(Thread-139, started daemon 140260302366464)>

  File "/home/users/Scy/yuqing/spider/monitor/projectManager.py", line 795, in get_request_from_keywords_hot
    self.search_spider_manager.crawl_by_keyword(
    │    │                     └ <function SearchSpidersManager.crawl_by_keyword at 0x7f9162b00040>
    │    └ <monitor.spiderManager.SearchSpidersManager object at 0x7f916270f0d0>
    └ <monitor.projectManager.ProjectManager object at 0x7f9162af4700>

  File "/home/users/Scy/yuqing/spider/monitor/spiderManager.py", line 118, in crawl_by_keyword
    self.crawl_by_keyword_signal_platform(project_names, platform, keyword, crawl_time, project_times)
    │    │                                │              │         │        │           └ {'default': <monitor.TimeSection object at 0x7f91628317f0>}
    │    │                                │              │         │        └ <monitor.TimeSection object at 0x7f9148612850>
    │    │                                │              │         └ '应对气候变化，中国重信守诺（国际论坛）'
    │    │                                │              └ '人民网'
    │    │                                └ ['default']
    │    └ <function SearchSpidersManager.crawl_by_keyword_signal_platform at 0x7f9162b000d0>
    └ <monitor.spiderManager.SearchSpidersManager object at 0x7f916270f0d0>

  File "/home/users/Scy/yuqing/spider/monitor/spiderManager.py", line 134, in crawl_by_keyword_signal_platform
    requests = self.get_request_from_keyword(platform, keyword, **crawl_time.to_dict())
               │    │                        │         │          │          └ <function TimeSection.to_dict at 0x7f925aaa8550>
               │    │                        │         │          └ <monitor.TimeSection object at 0x7f9148612850>
               │    │                        │         └ '应对气候变化，中国重信守诺（国际论坛）'
               │    │                        └ '人民网'
               │    └ <function SearchSpidersManager.get_request_from_keyword at 0x7f9162b001f0>
               └ <monitor.spiderManager.SearchSpidersManager object at 0x7f916270f0d0>

  File "/home/users/Scy/yuqing/spider/monitor/spiderManager.py", line 191, in get_request_from_keyword
    for request in self.spiders[platform].get_request_from_keyword(headers, search_url, keyword, content_url,
                   │    │       │                                  │        │           │        └ <string.Template object at 0x7f91601b78e0>
                   │    │       │                                  │        │           └ '应对气候变化，中国重信守诺（国际论坛）'
                   │    │       │                                  │        └ <string.Template object at 0x7f914814f7c0>
                   │    │       │                                  └ {'Accept': 'application/json, text/plain, */*', 'Accept-Language': 'zh-CN,zh;q=0.9', 'Connection': 'keep-alive', 'Origin': 'h...
                   │    │       └ '人民网'
                   │    └ {'凤凰网': <monitor.searchSpiders.ifeng.Ifeng object at 0x7f916270f220>, '头条': <monitor.searchSpiders.toutiao.Toutiao object at ...
                   └ <monitor.spiderManager.SearchSpidersManager object at 0x7f916270f0d0>

> File "/home/users/Scy/yuqing/spider/monitor/searchSpiders/people.py", line 28, in get_request_from_keyword
    response = requests.post(search_url.substitute(), json=data, headers=headers)
               │        │    │          │                  │             └ {'Accept': 'application/json, text/plain, */*', 'Accept-Language': 'zh-CN,zh;q=0.9', 'Connection': 'keep-alive', 'Origin': 'h...
               │        │    │          │                  └ {'key': '应对气候变化，中国重信守诺（国际论坛）', 'page': 1, 'limit': 10, 'hasTitle': True, 'hasContent': True, 'isFuzzy': True, 'type': 0, 'sor...
               │        │    │          └ <function Template.substitute at 0x7f927a5fd0d0>
               │        │    └ <string.Template object at 0x7f914814f7c0>
               │        └ <function post at 0x7f92583e73a0>
               └ <module 'requests' from '/home/chase/.local/lib/python3.8/site-packages/requests/__init__.py'>

  File "/home/chase/.local/lib/python3.8/site-packages/requests/api.py", line 117, in post
    return request('post', url, data=data, json=json, **kwargs)
           │               │         │          │       └ {'headers': {'Accept': 'application/json, text/plain, */*', 'Accept-Language': 'zh-CN,zh;q=0.9', 'Connection': 'keep-alive', ...
           │               │         │          └ {'key': '应对气候变化，中国重信守诺（国际论坛）', 'page': 1, 'limit': 10, 'hasTitle': True, 'hasContent': True, 'isFuzzy': True, 'type': 0, 'sor...
           │               │         └ None
           │               └ 'http://search.people.cn/search-platform/front/search'
           └ <function request at 0x7f9258455040>
  File "/home/chase/.local/lib/python3.8/site-packages/requests/api.py", line 61, in request
    return session.request(method=method, url=url, **kwargs)
           │       │              │           │      └ {'data': None, 'json': {'key': '应对气候变化，中国重信守诺（国际论坛）', 'page': 1, 'limit': 10, 'hasTitle': True, 'hasContent': True, 'isFuzzy'...
           │       │              │           └ 'http://search.people.cn/search-platform/front/search'
           │       │              └ 'post'
           │       └ <function Session.request at 0x7f92583e6940>
           └ <requests.sessions.Session object at 0x7f91247a82e0>
  File "/home/chase/.local/lib/python3.8/site-packages/requests/sessions.py", line 542, in request
    resp = self.send(prep, **send_kwargs)
           │    │    │       └ {'timeout': None, 'allow_redirects': True, 'verify': True, 'proxies': OrderedDict(), 'stream': False, 'cert': None}
           │    │    └ <PreparedRequest [POST]>
           │    └ <function Session.send at 0x7f92583e6dc0>
           └ <requests.sessions.Session object at 0x7f91247a82e0>
  File "/home/chase/.local/lib/python3.8/site-packages/requests/sessions.py", line 655, in send
    r = adapter.send(request, **kwargs)
        │       │    │          └ {'timeout': None, 'verify': True, 'proxies': OrderedDict(), 'stream': False, 'cert': None}
        │       │    └ <PreparedRequest [POST]>
        │       └ <function HTTPAdapter.send at 0x7f92583e6280>
        └ <requests.adapters.HTTPAdapter object at 0x7f9148347070>
  File "/home/chase/.local/lib/python3.8/site-packages/requests/adapters.py", line 516, in send
    raise ConnectionError(e, request=request)
          │                          └ <PreparedRequest [POST]>
          └ <class 'requests.exceptions.ConnectionError'>

requests.exceptions.ConnectionError: HTTPConnectionPool(host='search.people.cn', port=80): Max retries exceeded with url: /search-platform/front/search (Caused by NewConnectionError('<urllib3.connection.HTTPConnection object at 0x7f9104189400>: Failed to establish a new connection: [Errno 111] Connection refused'))
2022-05-12 15:48:46.126 | ERROR    | monitor.searchSpiders.qinagguoLT:get_request_from_keyword:27 - E 强国论坛错误HTTPConnectionPool(host='bbs1.people.com.cn', port=80): Max retries exceeded with url: /board/1.html (Caused by NewConnectionError('<urllib3.connection.HTTPConnection object at 0x7f90e46f9fa0>: Failed to establish a new connection: [Errno 111] Connection refused'))
Traceback (most recent call last):

  File "/home/chase/.local/lib/python3.8/site-packages/urllib3/connection.py", line 174, in _new_conn
    conn = connection.create_connection(
           │          └ <function create_connection at 0x7f92585fd1f0>
           └ <module 'urllib3.util.connection' from '/home/chase/.local/lib/python3.8/site-packages/urllib3/util/connection.py'>
  File "/home/chase/.local/lib/python3.8/site-packages/urllib3/util/connection.py", line 96, in create_connection
    raise err
          └ ConnectionRefusedError(111, 'Connection refused')
  File "/home/chase/.local/lib/python3.8/site-packages/urllib3/util/connection.py", line 86, in create_connection
    sock.connect(sa)
    │            └ ('118.212.233.223', 80)
    └ None

ConnectionRefusedError: [Errno 111] Connection refused


During handling of the above exception, another exception occurred:


Traceback (most recent call last):

  File "/home/chase/.local/lib/python3.8/site-packages/urllib3/connectionpool.py", line 699, in urlopen
    httplib_response = self._make_request(
                       │    └ <function HTTPConnectionPool._make_request at 0x7f92585c05e0>
                       └ <urllib3.connectionpool.HTTPConnectionPool object at 0x7f90e4764fa0>
  File "/home/chase/.local/lib/python3.8/site-packages/urllib3/connectionpool.py", line 394, in _make_request
    conn.request(method, url, **httplib_request_kw)
    │    │       │       │      └ {'body': None, 'headers': {'User-Agent': 'Mozilla/5.0 (X11; Linux x86_64) AppleWebKit/537.36 (KHTML, like Gecko) Chrome/93.0....
    │    │       │       └ '/board/1.html'
    │    │       └ 'GET'
    │    └ <function HTTPConnection.request at 0x7f92585b0f70>
    └ <urllib3.connection.HTTPConnection object at 0x7f90e46f9fa0>
  File "/home/chase/.local/lib/python3.8/site-packages/urllib3/connection.py", line 239, in request
    super(HTTPConnection, self).request(method, url, body=body, headers=headers)
          │               │             │       │         │             └ {'User-Agent': 'Mozilla/5.0 (X11; Linux x86_64) AppleWebKit/537.36 (KHTML, like Gecko) Chrome/93.0.4577.63 Safari/537.36', 'A...
          │               │             │       │         └ None
          │               │             │       └ '/board/1.html'
          │               │             └ 'GET'
          │               └ <urllib3.connection.HTTPConnection object at 0x7f90e46f9fa0>
          └ <class 'urllib3.connection.HTTPConnection'>
  File "/usr/lib/python3.8/http/client.py", line 1256, in request
    self._send_request(method, url, body, headers, encode_chunked)
    │    │             │       │    │     │        └ False
    │    │             │       │    │     └ {'User-Agent': 'Mozilla/5.0 (X11; Linux x86_64) AppleWebKit/537.36 (KHTML, like Gecko) Chrome/93.0.4577.63 Safari/537.36', 'A...
    │    │             │       │    └ None
    │    │             │       └ '/board/1.html'
    │    │             └ 'GET'
    │    └ <function HTTPConnection._send_request at 0x7f926be50280>
    └ <urllib3.connection.HTTPConnection object at 0x7f90e46f9fa0>
  File "/usr/lib/python3.8/http/client.py", line 1302, in _send_request
    self.endheaders(body, encode_chunked=encode_chunked)
    │    │          │                    └ False
    │    │          └ None
    │    └ <function HTTPConnection.endheaders at 0x7f926be50160>
    └ <urllib3.connection.HTTPConnection object at 0x7f90e46f9fa0>
  File "/usr/lib/python3.8/http/client.py", line 1251, in endheaders
    self._send_output(message_body, encode_chunked=encode_chunked)
    │    │            │                            └ False
    │    │            └ None
    │    └ <function HTTPConnection._send_output at 0x7f926beb7d30>
    └ <urllib3.connection.HTTPConnection object at 0x7f90e46f9fa0>
  File "/usr/lib/python3.8/http/client.py", line 1011, in _send_output
    self.send(msg)
    │    │    └ b'GET /board/1.html HTTP/1.1\r\nHost: bbs1.people.com.cn\r\nUser-Agent: Mozilla/5.0 (X11; Linux x86_64) AppleWebKit/537.36 (K...
    │    └ <function HTTPConnection.send at 0x7f926beb7b80>
    └ <urllib3.connection.HTTPConnection object at 0x7f90e46f9fa0>
  File "/usr/lib/python3.8/http/client.py", line 951, in send
    self.connect()
    │    └ <function HTTPConnection.connect at 0x7f92585b0dc0>
    └ <urllib3.connection.HTTPConnection object at 0x7f90e46f9fa0>
  File "/home/chase/.local/lib/python3.8/site-packages/urllib3/connection.py", line 205, in connect
    conn = self._new_conn()
           │    └ <function HTTPConnection._new_conn at 0x7f92585b0c10>
           └ <urllib3.connection.HTTPConnection object at 0x7f90e46f9fa0>
  File "/home/chase/.local/lib/python3.8/site-packages/urllib3/connection.py", line 186, in _new_conn
    raise NewConnectionError(
          └ <class 'urllib3.exceptions.NewConnectionError'>

urllib3.exceptions.NewConnectionError: <urllib3.connection.HTTPConnection object at 0x7f90e46f9fa0>: Failed to establish a new connection: [Errno 111] Connection refused


During handling of the above exception, another exception occurred:


Traceback (most recent call last):

  File "/home/chase/.local/lib/python3.8/site-packages/requests/adapters.py", line 439, in send
    resp = conn.urlopen(
           │    └ <function HTTPConnectionPool.urlopen at 0x7f92585c0820>
           └ <urllib3.connectionpool.HTTPConnectionPool object at 0x7f90e4764fa0>
  File "/home/chase/.local/lib/python3.8/site-packages/urllib3/connectionpool.py", line 755, in urlopen
    retries = retries.increment(
              │       └ <function Retry.increment at 0x7f9258608b80>
              └ Retry(total=0, connect=None, read=False, redirect=None, status=None)
  File "/home/chase/.local/lib/python3.8/site-packages/urllib3/util/retry.py", line 574, in increment
    raise MaxRetryError(_pool, url, error or ResponseError(cause))
          │             │      │    │        │             └ 'unknown'
          │             │      │    │        └ <class 'urllib3.exceptions.ResponseError'>
          │             │      │    └ NewConnectionError('<urllib3.connection.HTTPConnection object at 0x7f90e46f9fa0>: Failed to establish a new connection: [Errn...
          │             │      └ '/board/1.html'
          │             └ <urllib3.connectionpool.HTTPConnectionPool object at 0x7f90e4764fa0>
          └ <class 'urllib3.exceptions.MaxRetryError'>

urllib3.exceptions.MaxRetryError: HTTPConnectionPool(host='bbs1.people.com.cn', port=80): Max retries exceeded with url: /board/1.html (Caused by NewConnectionError('<urllib3.connection.HTTPConnection object at 0x7f90e46f9fa0>: Failed to establish a new connection: [Errno 111] Connection refused'))


During handling of the above exception, another exception occurred:


Traceback (most recent call last):

  File "/usr/lib/python3.8/threading.py", line 890, in _bootstrap
    self._bootstrap_inner()
    │    └ <function Thread._bootstrap_inner at 0x7f927a614a60>
    └ <Thread(Thread-180, started daemon 140259270588160)>
  File "/usr/lib/python3.8/threading.py", line 932, in _bootstrap_inner
    self.run()
    │    └ <function Thread.run at 0x7f927a614790>
    └ <Thread(Thread-180, started daemon 140259270588160)>
  File "/usr/lib/python3.8/threading.py", line 870, in run
    self._target(*self._args, **self._kwargs)
    │    │        │    │        │    └ {}
    │    │        │    │        └ <Thread(Thread-180, started daemon 140259270588160)>
    │    │        │    └ ('ProjectManager.run_func_by_thread',)
    │    │        └ <Thread(Thread-180, started daemon 140259270588160)>
    │    └ <bound method ProjectManager.get_request_from_keywords_hot of <monitor.projectManager.ProjectManager object at 0x7f9162af4700>>
    └ <Thread(Thread-180, started daemon 140259270588160)>

  File "/home/users/Scy/yuqing/spider/monitor/projectManager.py", line 795, in get_request_from_keywords_hot
    self.search_spider_manager.crawl_by_keyword(
    │    │                     └ <function SearchSpidersManager.crawl_by_keyword at 0x7f9162b00040>
    │    └ <monitor.spiderManager.SearchSpidersManager object at 0x7f916270f0d0>
    └ <monitor.projectManager.ProjectManager object at 0x7f9162af4700>

  File "/home/users/Scy/yuqing/spider/monitor/spiderManager.py", line 118, in crawl_by_keyword
    self.crawl_by_keyword_signal_platform(project_names, platform, keyword, crawl_time, project_times)
    │    │                                │              │         │        │           └ {'default': <monitor.TimeSection object at 0x7f91628317f0>}
    │    │                                │              │         │        └ <monitor.TimeSection object at 0x7f916040aa90>
    │    │                                │              │         └ '应对气候变化，中国重信守诺（国际论坛）'
    │    │                                │              └ '强国论坛'
    │    │                                └ ['default']
    │    └ <function SearchSpidersManager.crawl_by_keyword_signal_platform at 0x7f9162b000d0>
    └ <monitor.spiderManager.SearchSpidersManager object at 0x7f916270f0d0>

  File "/home/users/Scy/yuqing/spider/monitor/spiderManager.py", line 134, in crawl_by_keyword_signal_platform
    requests = self.get_request_from_keyword(platform, keyword, **crawl_time.to_dict())
               │    │                        │         │          │          └ <function TimeSection.to_dict at 0x7f925aaa8550>
               │    │                        │         │          └ <monitor.TimeSection object at 0x7f916040aa90>
               │    │                        │         └ '应对气候变化，中国重信守诺（国际论坛）'
               │    │                        └ '强国论坛'
               │    └ <function SearchSpidersManager.get_request_from_keyword at 0x7f9162b001f0>
               └ <monitor.spiderManager.SearchSpidersManager object at 0x7f916270f0d0>

  File "/home/users/Scy/yuqing/spider/monitor/spiderManager.py", line 191, in get_request_from_keyword
    for request in self.spiders[platform].get_request_from_keyword(headers, search_url, keyword, content_url,
                   │    │       │                                  │        │           │        └ <string.Template object at 0x7f90e4717a90>
                   │    │       │                                  │        │           └ '应对气候变化，中国重信守诺（国际论坛）'
                   │    │       │                                  │        └ <string.Template object at 0x7f90e4717790>
                   │    │       │                                  └ {'Connection': 'keep-alive', 'Cache-Control': 'max-age=0', 'Upgrade-Insecure-Requests': '1', 'User-Agent': 'Mozilla/5.0 (X11;...
                   │    │       └ '强国论坛'
                   │    └ {'凤凰网': <monitor.searchSpiders.ifeng.Ifeng object at 0x7f916270f220>, '头条': <monitor.searchSpiders.toutiao.Toutiao object at ...
                   └ <monitor.spiderManager.SearchSpidersManager object at 0x7f916270f0d0>

> File "/home/users/Scy/yuqing/spider/monitor/searchSpiders/qinagguoLT.py", line 18, in get_request_from_keyword
    response = requests.get(search_url.substitute(), headers=headers)
               │        │   │          │                     └ {'Connection': 'keep-alive', 'Cache-Control': 'max-age=0', 'Upgrade-Insecure-Requests': '1', 'User-Agent': 'Mozilla/5.0 (X11;...
               │        │   │          └ <function Template.substitute at 0x7f927a5fd0d0>
               │        │   └ <string.Template object at 0x7f90e4717790>
               │        └ <function get at 0x7f92583e71f0>
               └ <module 'requests' from '/home/chase/.local/lib/python3.8/site-packages/requests/__init__.py'>

  File "/home/chase/.local/lib/python3.8/site-packages/requests/api.py", line 75, in get
    return request('get', url, params=params, **kwargs)
           │              │           │         └ {'headers': {'Connection': 'keep-alive', 'Cache-Control': 'max-age=0', 'Upgrade-Insecure-Requests': '1', 'User-Agent': 'Mozil...
           │              │           └ None
           │              └ 'http://bbs1.people.com.cn/board/1.html'
           └ <function request at 0x7f9258455040>
  File "/home/chase/.local/lib/python3.8/site-packages/requests/api.py", line 61, in request
    return session.request(method=method, url=url, **kwargs)
           │       │              │           │      └ {'params': None, 'headers': {'Connection': 'keep-alive', 'Cache-Control': 'max-age=0', 'Upgrade-Insecure-Requests': '1', 'Use...
           │       │              │           └ 'http://bbs1.people.com.cn/board/1.html'
           │       │              └ 'get'
           │       └ <function Session.request at 0x7f92583e6940>
           └ <requests.sessions.Session object at 0x7f9253e00e20>
  File "/home/chase/.local/lib/python3.8/site-packages/requests/sessions.py", line 542, in request
    resp = self.send(prep, **send_kwargs)
           │    │    │       └ {'timeout': None, 'allow_redirects': True, 'verify': True, 'proxies': OrderedDict(), 'stream': False, 'cert': None}
           │    │    └ <PreparedRequest [GET]>
           │    └ <function Session.send at 0x7f92583e6dc0>
           └ <requests.sessions.Session object at 0x7f9253e00e20>
  File "/home/chase/.local/lib/python3.8/site-packages/requests/sessions.py", line 655, in send
    r = adapter.send(request, **kwargs)
        │       │    │          └ {'timeout': None, 'verify': True, 'proxies': OrderedDict(), 'stream': False, 'cert': None}
        │       │    └ <PreparedRequest [GET]>
        │       └ <function HTTPAdapter.send at 0x7f92583e6280>
        └ <requests.adapters.HTTPAdapter object at 0x7f90e4717310>
  File "/home/chase/.local/lib/python3.8/site-packages/requests/adapters.py", line 516, in send
    raise ConnectionError(e, request=request)
          │                          └ <PreparedRequest [GET]>
          └ <class 'requests.exceptions.ConnectionError'>

requests.exceptions.ConnectionError: HTTPConnectionPool(host='bbs1.people.com.cn', port=80): Max retries exceeded with url: /board/1.html (Caused by NewConnectionError('<urllib3.connection.HTTPConnection object at 0x7f90e46f9fa0>: Failed to establish a new connection: [Errno 111] Connection refused'))
2022-05-12 15:48:46.259 | ERROR    | monitor.searchSpiders.qinagguoLT:get_request_from_keyword:27 - E 强国论坛错误HTTPConnectionPool(host='bbs1.people.com.cn', port=80): Max retries exceeded with url: /board/1.html (Caused by NewConnectionError('<urllib3.connection.HTTPConnection object at 0x7f9104257040>: Failed to establish a new connection: [Errno 111] Connection refused'))
Traceback (most recent call last):

  File "/home/chase/.local/lib/python3.8/site-packages/urllib3/connection.py", line 174, in _new_conn
    conn = connection.create_connection(
           │          └ <function create_connection at 0x7f92585fd1f0>
           └ <module 'urllib3.util.connection' from '/home/chase/.local/lib/python3.8/site-packages/urllib3/util/connection.py'>
  File "/home/chase/.local/lib/python3.8/site-packages/urllib3/util/connection.py", line 96, in create_connection
    raise err
          └ ConnectionRefusedError(111, 'Connection refused')
  File "/home/chase/.local/lib/python3.8/site-packages/urllib3/util/connection.py", line 86, in create_connection
    sock.connect(sa)
    │            └ ('118.212.233.223', 80)
    └ None

ConnectionRefusedError: [Errno 111] Connection refused


During handling of the above exception, another exception occurred:


Traceback (most recent call last):

  File "/home/chase/.local/lib/python3.8/site-packages/urllib3/connectionpool.py", line 699, in urlopen
    httplib_response = self._make_request(
                       │    └ <function HTTPConnectionPool._make_request at 0x7f92585c05e0>
                       └ <urllib3.connectionpool.HTTPConnectionPool object at 0x7f9148539e80>
  File "/home/chase/.local/lib/python3.8/site-packages/urllib3/connectionpool.py", line 394, in _make_request
    conn.request(method, url, **httplib_request_kw)
    │    │       │       │      └ {'body': None, 'headers': {'User-Agent': 'Mozilla/5.0 (X11; Linux x86_64) AppleWebKit/537.36 (KHTML, like Gecko) Chrome/93.0....
    │    │       │       └ '/board/1.html'
    │    │       └ 'GET'
    │    └ <function HTTPConnection.request at 0x7f92585b0f70>
    └ <urllib3.connection.HTTPConnection object at 0x7f9104257040>
  File "/home/chase/.local/lib/python3.8/site-packages/urllib3/connection.py", line 239, in request
    super(HTTPConnection, self).request(method, url, body=body, headers=headers)
          │               │             │       │         │             └ {'User-Agent': 'Mozilla/5.0 (X11; Linux x86_64) AppleWebKit/537.36 (KHTML, like Gecko) Chrome/93.0.4577.63 Safari/537.36', 'A...
          │               │             │       │         └ None
          │               │             │       └ '/board/1.html'
          │               │             └ 'GET'
          │               └ <urllib3.connection.HTTPConnection object at 0x7f9104257040>
          └ <class 'urllib3.connection.HTTPConnection'>
  File "/usr/lib/python3.8/http/client.py", line 1256, in request
    self._send_request(method, url, body, headers, encode_chunked)
    │    │             │       │    │     │        └ False
    │    │             │       │    │     └ {'User-Agent': 'Mozilla/5.0 (X11; Linux x86_64) AppleWebKit/537.36 (KHTML, like Gecko) Chrome/93.0.4577.63 Safari/537.36', 'A...
    │    │             │       │    └ None
    │    │             │       └ '/board/1.html'
    │    │             └ 'GET'
    │    └ <function HTTPConnection._send_request at 0x7f926be50280>
    └ <urllib3.connection.HTTPConnection object at 0x7f9104257040>
  File "/usr/lib/python3.8/http/client.py", line 1302, in _send_request
    self.endheaders(body, encode_chunked=encode_chunked)
    │    │          │                    └ False
    │    │          └ None
    │    └ <function HTTPConnection.endheaders at 0x7f926be50160>
    └ <urllib3.connection.HTTPConnection object at 0x7f9104257040>
  File "/usr/lib/python3.8/http/client.py", line 1251, in endheaders
    self._send_output(message_body, encode_chunked=encode_chunked)
    │    │            │                            └ False
    │    │            └ None
    │    └ <function HTTPConnection._send_output at 0x7f926beb7d30>
    └ <urllib3.connection.HTTPConnection object at 0x7f9104257040>
  File "/usr/lib/python3.8/http/client.py", line 1011, in _send_output
    self.send(msg)
    │    │    └ b'GET /board/1.html HTTP/1.1\r\nHost: bbs1.people.com.cn\r\nUser-Agent: Mozilla/5.0 (X11; Linux x86_64) AppleWebKit/537.36 (K...
    │    └ <function HTTPConnection.send at 0x7f926beb7b80>
    └ <urllib3.connection.HTTPConnection object at 0x7f9104257040>
  File "/usr/lib/python3.8/http/client.py", line 951, in send
    self.connect()
    │    └ <function HTTPConnection.connect at 0x7f92585b0dc0>
    └ <urllib3.connection.HTTPConnection object at 0x7f9104257040>
  File "/home/chase/.local/lib/python3.8/site-packages/urllib3/connection.py", line 205, in connect
    conn = self._new_conn()
           │    └ <function HTTPConnection._new_conn at 0x7f92585b0c10>
           └ <urllib3.connection.HTTPConnection object at 0x7f9104257040>
  File "/home/chase/.local/lib/python3.8/site-packages/urllib3/connection.py", line 186, in _new_conn
    raise NewConnectionError(
          └ <class 'urllib3.exceptions.NewConnectionError'>

urllib3.exceptions.NewConnectionError: <urllib3.connection.HTTPConnection object at 0x7f9104257040>: Failed to establish a new connection: [Errno 111] Connection refused


During handling of the above exception, another exception occurred:


Traceback (most recent call last):

  File "/home/chase/.local/lib/python3.8/site-packages/requests/adapters.py", line 439, in send
    resp = conn.urlopen(
           │    └ <function HTTPConnectionPool.urlopen at 0x7f92585c0820>
           └ <urllib3.connectionpool.HTTPConnectionPool object at 0x7f9148539e80>
  File "/home/chase/.local/lib/python3.8/site-packages/urllib3/connectionpool.py", line 755, in urlopen
    retries = retries.increment(
              │       └ <function Retry.increment at 0x7f9258608b80>
              └ Retry(total=0, connect=None, read=False, redirect=None, status=None)
  File "/home/chase/.local/lib/python3.8/site-packages/urllib3/util/retry.py", line 574, in increment
    raise MaxRetryError(_pool, url, error or ResponseError(cause))
          │             │      │    │        │             └ 'unknown'
          │             │      │    │        └ <class 'urllib3.exceptions.ResponseError'>
          │             │      │    └ NewConnectionError('<urllib3.connection.HTTPConnection object at 0x7f9104257040>: Failed to establish a new connection: [Errn...
          │             │      └ '/board/1.html'
          │             └ <urllib3.connectionpool.HTTPConnectionPool object at 0x7f9148539e80>
          └ <class 'urllib3.exceptions.MaxRetryError'>

urllib3.exceptions.MaxRetryError: HTTPConnectionPool(host='bbs1.people.com.cn', port=80): Max retries exceeded with url: /board/1.html (Caused by NewConnectionError('<urllib3.connection.HTTPConnection object at 0x7f9104257040>: Failed to establish a new connection: [Errno 111] Connection refused'))


During handling of the above exception, another exception occurred:


Traceback (most recent call last):

  File "/usr/lib/python3.8/threading.py", line 890, in _bootstrap
    self._bootstrap_inner()
    │    └ <function Thread._bootstrap_inner at 0x7f927a614a60>
    └ <Thread(Thread-262, started daemon 140258171668224)>
  File "/usr/lib/python3.8/threading.py", line 932, in _bootstrap_inner
    self.run()
    │    └ <function Thread.run at 0x7f927a614790>
    └ <Thread(Thread-262, started daemon 140258171668224)>
  File "/usr/lib/python3.8/threading.py", line 870, in run
    self._target(*self._args, **self._kwargs)
    │    │        │    │        │    └ {}
    │    │        │    │        └ <Thread(Thread-262, started daemon 140258171668224)>
    │    │        │    └ ('ProjectManager.run_func_by_thread',)
    │    │        └ <Thread(Thread-262, started daemon 140258171668224)>
    │    └ <bound method ProjectManager.get_request_from_keywords_hot of <monitor.projectManager.ProjectManager object at 0x7f9162af4700>>
    └ <Thread(Thread-262, started daemon 140258171668224)>

  File "/home/users/Scy/yuqing/spider/monitor/projectManager.py", line 795, in get_request_from_keywords_hot
    self.search_spider_manager.crawl_by_keyword(
    │    │                     └ <function SearchSpidersManager.crawl_by_keyword at 0x7f9162b00040>
    │    └ <monitor.spiderManager.SearchSpidersManager object at 0x7f916270f0d0>
    └ <monitor.projectManager.ProjectManager object at 0x7f9162af4700>

  File "/home/users/Scy/yuqing/spider/monitor/spiderManager.py", line 118, in crawl_by_keyword
    self.crawl_by_keyword_signal_platform(project_names, platform, keyword, crawl_time, project_times)
    │    │                                │              │         │        │           └ {'default': <monitor.TimeSection object at 0x7f91628317f0>}
    │    │                                │              │         │        └ <monitor.TimeSection object at 0x7f9160384d90>
    │    │                                │              │         └ '土耳其通货膨胀率持续高位运行'
    │    │                                │              └ '强国论坛'
    │    │                                └ ['default']
    │    └ <function SearchSpidersManager.crawl_by_keyword_signal_platform at 0x7f9162b000d0>
    └ <monitor.spiderManager.SearchSpidersManager object at 0x7f916270f0d0>

  File "/home/users/Scy/yuqing/spider/monitor/spiderManager.py", line 134, in crawl_by_keyword_signal_platform
    requests = self.get_request_from_keyword(platform, keyword, **crawl_time.to_dict())
               │    │                        │         │          │          └ <function TimeSection.to_dict at 0x7f925aaa8550>
               │    │                        │         │          └ <monitor.TimeSection object at 0x7f9160384d90>
               │    │                        │         └ '土耳其通货膨胀率持续高位运行'
               │    │                        └ '强国论坛'
               │    └ <function SearchSpidersManager.get_request_from_keyword at 0x7f9162b001f0>
               └ <monitor.spiderManager.SearchSpidersManager object at 0x7f916270f0d0>

  File "/home/users/Scy/yuqing/spider/monitor/spiderManager.py", line 191, in get_request_from_keyword
    for request in self.spiders[platform].get_request_from_keyword(headers, search_url, keyword, content_url,
                   │    │       │                                  │        │           │        └ <string.Template object at 0x7f91244f7910>
                   │    │       │                                  │        │           └ '土耳其通货膨胀率持续高位运行'
                   │    │       │                                  │        └ <string.Template object at 0x7f916169aa60>
                   │    │       │                                  └ {'Connection': 'keep-alive', 'Cache-Control': 'max-age=0', 'Upgrade-Insecure-Requests': '1', 'User-Agent': 'Mozilla/5.0 (X11;...
                   │    │       └ '强国论坛'
                   │    └ {'凤凰网': <monitor.searchSpiders.ifeng.Ifeng object at 0x7f916270f220>, '头条': <monitor.searchSpiders.toutiao.Toutiao object at ...
                   └ <monitor.spiderManager.SearchSpidersManager object at 0x7f916270f0d0>

> File "/home/users/Scy/yuqing/spider/monitor/searchSpiders/qinagguoLT.py", line 18, in get_request_from_keyword
    response = requests.get(search_url.substitute(), headers=headers)
               │        │   │          │                     └ {'Connection': 'keep-alive', 'Cache-Control': 'max-age=0', 'Upgrade-Insecure-Requests': '1', 'User-Agent': 'Mozilla/5.0 (X11;...
               │        │   │          └ <function Template.substitute at 0x7f927a5fd0d0>
               │        │   └ <string.Template object at 0x7f916169aa60>
               │        └ <function get at 0x7f92583e71f0>
               └ <module 'requests' from '/home/chase/.local/lib/python3.8/site-packages/requests/__init__.py'>

  File "/home/chase/.local/lib/python3.8/site-packages/requests/api.py", line 75, in get
    return request('get', url, params=params, **kwargs)
           │              │           │         └ {'headers': {'Connection': 'keep-alive', 'Cache-Control': 'max-age=0', 'Upgrade-Insecure-Requests': '1', 'User-Agent': 'Mozil...
           │              │           └ None
           │              └ 'http://bbs1.people.com.cn/board/1.html'
           └ <function request at 0x7f9258455040>
  File "/home/chase/.local/lib/python3.8/site-packages/requests/api.py", line 61, in request
    return session.request(method=method, url=url, **kwargs)
           │       │              │           │      └ {'params': None, 'headers': {'Connection': 'keep-alive', 'Cache-Control': 'max-age=0', 'Upgrade-Insecure-Requests': '1', 'Use...
           │       │              │           └ 'http://bbs1.people.com.cn/board/1.html'
           │       │              └ 'get'
           │       └ <function Session.request at 0x7f92583e6940>
           └ <requests.sessions.Session object at 0x7f91604653d0>
  File "/home/chase/.local/lib/python3.8/site-packages/requests/sessions.py", line 542, in request
    resp = self.send(prep, **send_kwargs)
           │    │    │       └ {'timeout': None, 'allow_redirects': True, 'verify': True, 'proxies': OrderedDict(), 'stream': False, 'cert': None}
           │    │    └ <PreparedRequest [GET]>
           │    └ <function Session.send at 0x7f92583e6dc0>
           └ <requests.sessions.Session object at 0x7f91604653d0>
  File "/home/chase/.local/lib/python3.8/site-packages/requests/sessions.py", line 655, in send
    r = adapter.send(request, **kwargs)
        │       │    │          └ {'timeout': None, 'verify': True, 'proxies': OrderedDict(), 'stream': False, 'cert': None}
        │       │    └ <PreparedRequest [GET]>
        │       └ <function HTTPAdapter.send at 0x7f92583e6280>
        └ <requests.adapters.HTTPAdapter object at 0x7f91603f2f40>
  File "/home/chase/.local/lib/python3.8/site-packages/requests/adapters.py", line 516, in send
    raise ConnectionError(e, request=request)
          │                          └ <PreparedRequest [GET]>
          └ <class 'requests.exceptions.ConnectionError'>

requests.exceptions.ConnectionError: HTTPConnectionPool(host='bbs1.people.com.cn', port=80): Max retries exceeded with url: /board/1.html (Caused by NewConnectionError('<urllib3.connection.HTTPConnection object at 0x7f9104257040>: Failed to establish a new connection: [Errno 111] Connection refused'))
2022-05-12 15:48:47.243 | ERROR    | monitor.searchSpiders.qinagguoLT:get_request_from_keyword:27 - E 强国论坛错误HTTPConnectionPool(host='bbs1.people.com.cn', port=80): Max retries exceeded with url: /board/1.html (Caused by NewConnectionError('<urllib3.connection.HTTPConnection object at 0x7f9104189340>: Failed to establish a new connection: [Errno 111] Connection refused'))
Traceback (most recent call last):

  File "/home/chase/.local/lib/python3.8/site-packages/urllib3/connection.py", line 174, in _new_conn
    conn = connection.create_connection(
           │          └ <function create_connection at 0x7f92585fd1f0>
           └ <module 'urllib3.util.connection' from '/home/chase/.local/lib/python3.8/site-packages/urllib3/util/connection.py'>
  File "/home/chase/.local/lib/python3.8/site-packages/urllib3/util/connection.py", line 96, in create_connection
    raise err
          └ ConnectionRefusedError(111, 'Connection refused')
  File "/home/chase/.local/lib/python3.8/site-packages/urllib3/util/connection.py", line 86, in create_connection
    sock.connect(sa)
    │            └ ('118.212.233.223', 80)
    └ None

ConnectionRefusedError: [Errno 111] Connection refused


During handling of the above exception, another exception occurred:


Traceback (most recent call last):

  File "/home/chase/.local/lib/python3.8/site-packages/urllib3/connectionpool.py", line 699, in urlopen
    httplib_response = self._make_request(
                       │    └ <function HTTPConnectionPool._make_request at 0x7f92585c05e0>
                       └ <urllib3.connectionpool.HTTPConnectionPool object at 0x7f9253f5e7f0>
  File "/home/chase/.local/lib/python3.8/site-packages/urllib3/connectionpool.py", line 394, in _make_request
    conn.request(method, url, **httplib_request_kw)
    │    │       │       │      └ {'body': None, 'headers': {'User-Agent': 'Mozilla/5.0 (X11; Linux x86_64) AppleWebKit/537.36 (KHTML, like Gecko) Chrome/93.0....
    │    │       │       └ '/board/1.html'
    │    │       └ 'GET'
    │    └ <function HTTPConnection.request at 0x7f92585b0f70>
    └ <urllib3.connection.HTTPConnection object at 0x7f9104189340>
  File "/home/chase/.local/lib/python3.8/site-packages/urllib3/connection.py", line 239, in request
    super(HTTPConnection, self).request(method, url, body=body, headers=headers)
          │               │             │       │         │             └ {'User-Agent': 'Mozilla/5.0 (X11; Linux x86_64) AppleWebKit/537.36 (KHTML, like Gecko) Chrome/93.0.4577.63 Safari/537.36', 'A...
          │               │             │       │         └ None
          │               │             │       └ '/board/1.html'
          │               │             └ 'GET'
          │               └ <urllib3.connection.HTTPConnection object at 0x7f9104189340>
          └ <class 'urllib3.connection.HTTPConnection'>
  File "/usr/lib/python3.8/http/client.py", line 1256, in request
    self._send_request(method, url, body, headers, encode_chunked)
    │    │             │       │    │     │        └ False
    │    │             │       │    │     └ {'User-Agent': 'Mozilla/5.0 (X11; Linux x86_64) AppleWebKit/537.36 (KHTML, like Gecko) Chrome/93.0.4577.63 Safari/537.36', 'A...
    │    │             │       │    └ None
    │    │             │       └ '/board/1.html'
    │    │             └ 'GET'
    │    └ <function HTTPConnection._send_request at 0x7f926be50280>
    └ <urllib3.connection.HTTPConnection object at 0x7f9104189340>
  File "/usr/lib/python3.8/http/client.py", line 1302, in _send_request
    self.endheaders(body, encode_chunked=encode_chunked)
    │    │          │                    └ False
    │    │          └ None
    │    └ <function HTTPConnection.endheaders at 0x7f926be50160>
    └ <urllib3.connection.HTTPConnection object at 0x7f9104189340>
  File "/usr/lib/python3.8/http/client.py", line 1251, in endheaders
    self._send_output(message_body, encode_chunked=encode_chunked)
    │    │            │                            └ False
    │    │            └ None
    │    └ <function HTTPConnection._send_output at 0x7f926beb7d30>
    └ <urllib3.connection.HTTPConnection object at 0x7f9104189340>
  File "/usr/lib/python3.8/http/client.py", line 1011, in _send_output
    self.send(msg)
    │    │    └ b'GET /board/1.html HTTP/1.1\r\nHost: bbs1.people.com.cn\r\nUser-Agent: Mozilla/5.0 (X11; Linux x86_64) AppleWebKit/537.36 (K...
    │    └ <function HTTPConnection.send at 0x7f926beb7b80>
    └ <urllib3.connection.HTTPConnection object at 0x7f9104189340>
  File "/usr/lib/python3.8/http/client.py", line 951, in send
    self.connect()
    │    └ <function HTTPConnection.connect at 0x7f92585b0dc0>
    └ <urllib3.connection.HTTPConnection object at 0x7f9104189340>
  File "/home/chase/.local/lib/python3.8/site-packages/urllib3/connection.py", line 205, in connect
    conn = self._new_conn()
           │    └ <function HTTPConnection._new_conn at 0x7f92585b0c10>
           └ <urllib3.connection.HTTPConnection object at 0x7f9104189340>
  File "/home/chase/.local/lib/python3.8/site-packages/urllib3/connection.py", line 186, in _new_conn
    raise NewConnectionError(
          └ <class 'urllib3.exceptions.NewConnectionError'>

urllib3.exceptions.NewConnectionError: <urllib3.connection.HTTPConnection object at 0x7f9104189340>: Failed to establish a new connection: [Errno 111] Connection refused


During handling of the above exception, another exception occurred:


Traceback (most recent call last):

  File "/home/chase/.local/lib/python3.8/site-packages/requests/adapters.py", line 439, in send
    resp = conn.urlopen(
           │    └ <function HTTPConnectionPool.urlopen at 0x7f92585c0820>
           └ <urllib3.connectionpool.HTTPConnectionPool object at 0x7f9253f5e7f0>
  File "/home/chase/.local/lib/python3.8/site-packages/urllib3/connectionpool.py", line 755, in urlopen
    retries = retries.increment(
              │       └ <function Retry.increment at 0x7f9258608b80>
              └ Retry(total=0, connect=None, read=False, redirect=None, status=None)
  File "/home/chase/.local/lib/python3.8/site-packages/urllib3/util/retry.py", line 574, in increment
    raise MaxRetryError(_pool, url, error or ResponseError(cause))
          │             │      │    │        │             └ 'unknown'
          │             │      │    │        └ <class 'urllib3.exceptions.ResponseError'>
          │             │      │    └ NewConnectionError('<urllib3.connection.HTTPConnection object at 0x7f9104189340>: Failed to establish a new connection: [Errn...
          │             │      └ '/board/1.html'
          │             └ <urllib3.connectionpool.HTTPConnectionPool object at 0x7f9253f5e7f0>
          └ <class 'urllib3.exceptions.MaxRetryError'>

urllib3.exceptions.MaxRetryError: HTTPConnectionPool(host='bbs1.people.com.cn', port=80): Max retries exceeded with url: /board/1.html (Caused by NewConnectionError('<urllib3.connection.HTTPConnection object at 0x7f9104189340>: Failed to establish a new connection: [Errno 111] Connection refused'))


During handling of the above exception, another exception occurred:


Traceback (most recent call last):

  File "/usr/lib/python3.8/threading.py", line 890, in _bootstrap
    self._bootstrap_inner()
    │    └ <function Thread._bootstrap_inner at 0x7f927a614a60>
    └ <Thread(Thread-116, started daemon 140260344329984)>
  File "/usr/lib/python3.8/threading.py", line 932, in _bootstrap_inner
    self.run()
    │    └ <function Thread.run at 0x7f927a614790>
    └ <Thread(Thread-116, started daemon 140260344329984)>
  File "/usr/lib/python3.8/threading.py", line 870, in run
    self._target(*self._args, **self._kwargs)
    │    │        │    │        │    └ {}
    │    │        │    │        └ <Thread(Thread-116, started daemon 140260344329984)>
    │    │        │    └ ('ProjectManager.run_func_by_thread',)
    │    │        └ <Thread(Thread-116, started daemon 140260344329984)>
    │    └ <bound method ProjectManager.get_request_from_keywords_hot of <monitor.projectManager.ProjectManager object at 0x7f9162af4700>>
    └ <Thread(Thread-116, started daemon 140260344329984)>

  File "/home/users/Scy/yuqing/spider/monitor/projectManager.py", line 795, in get_request_from_keywords_hot
    self.search_spider_manager.crawl_by_keyword(
    │    │                     └ <function SearchSpidersManager.crawl_by_keyword at 0x7f9162b00040>
    │    └ <monitor.spiderManager.SearchSpidersManager object at 0x7f916270f0d0>
    └ <monitor.projectManager.ProjectManager object at 0x7f9162af4700>

  File "/home/users/Scy/yuqing/spider/monitor/spiderManager.py", line 118, in crawl_by_keyword
    self.crawl_by_keyword_signal_platform(project_names, platform, keyword, crawl_time, project_times)
    │    │                                │              │         │        │           └ {'default': <monitor.TimeSection object at 0x7f91628317f0>}
    │    │                                │              │         │        └ <monitor.TimeSection object at 0x7f916271da30>
    │    │                                │              │         └ '东部战区组织兵力在台岛以东和西南海空域进行实兵演练'
    │    │                                │              └ '强国论坛'
    │    │                                └ ['default']
    │    └ <function SearchSpidersManager.crawl_by_keyword_signal_platform at 0x7f9162b000d0>
    └ <monitor.spiderManager.SearchSpidersManager object at 0x7f916270f0d0>

  File "/home/users/Scy/yuqing/spider/monitor/spiderManager.py", line 134, in crawl_by_keyword_signal_platform
    requests = self.get_request_from_keyword(platform, keyword, **crawl_time.to_dict())
               │    │                        │         │          │          └ <function TimeSection.to_dict at 0x7f925aaa8550>
               │    │                        │         │          └ <monitor.TimeSection object at 0x7f916271da30>
               │    │                        │         └ '东部战区组织兵力在台岛以东和西南海空域进行实兵演练'
               │    │                        └ '强国论坛'
               │    └ <function SearchSpidersManager.get_request_from_keyword at 0x7f9162b001f0>
               └ <monitor.spiderManager.SearchSpidersManager object at 0x7f916270f0d0>

  File "/home/users/Scy/yuqing/spider/monitor/spiderManager.py", line 191, in get_request_from_keyword
    for request in self.spiders[platform].get_request_from_keyword(headers, search_url, keyword, content_url,
                   │    │       │                                  │        │           │        └ <string.Template object at 0x7f91242333a0>
                   │    │       │                                  │        │           └ '东部战区组织兵力在台岛以东和西南海空域进行实兵演练'
                   │    │       │                                  │        └ <string.Template object at 0x7f91604d7100>
                   │    │       │                                  └ {'Connection': 'keep-alive', 'Cache-Control': 'max-age=0', 'Upgrade-Insecure-Requests': '1', 'User-Agent': 'Mozilla/5.0 (X11;...
                   │    │       └ '强国论坛'
                   │    └ {'凤凰网': <monitor.searchSpiders.ifeng.Ifeng object at 0x7f916270f220>, '头条': <monitor.searchSpiders.toutiao.Toutiao object at ...
                   └ <monitor.spiderManager.SearchSpidersManager object at 0x7f916270f0d0>

> File "/home/users/Scy/yuqing/spider/monitor/searchSpiders/qinagguoLT.py", line 18, in get_request_from_keyword
    response = requests.get(search_url.substitute(), headers=headers)
               │        │   │          │                     └ {'Connection': 'keep-alive', 'Cache-Control': 'max-age=0', 'Upgrade-Insecure-Requests': '1', 'User-Agent': 'Mozilla/5.0 (X11;...
               │        │   │          └ <function Template.substitute at 0x7f927a5fd0d0>
               │        │   └ <string.Template object at 0x7f91604d7100>
               │        └ <function get at 0x7f92583e71f0>
               └ <module 'requests' from '/home/chase/.local/lib/python3.8/site-packages/requests/__init__.py'>

  File "/home/chase/.local/lib/python3.8/site-packages/requests/api.py", line 75, in get
    return request('get', url, params=params, **kwargs)
           │              │           │         └ {'headers': {'Connection': 'keep-alive', 'Cache-Control': 'max-age=0', 'Upgrade-Insecure-Requests': '1', 'User-Agent': 'Mozil...
           │              │           └ None
           │              └ 'http://bbs1.people.com.cn/board/1.html'
           └ <function request at 0x7f9258455040>
  File "/home/chase/.local/lib/python3.8/site-packages/requests/api.py", line 61, in request
    return session.request(method=method, url=url, **kwargs)
           │       │              │           │      └ {'params': None, 'headers': {'Connection': 'keep-alive', 'Cache-Control': 'max-age=0', 'Upgrade-Insecure-Requests': '1', 'Use...
           │       │              │           └ 'http://bbs1.people.com.cn/board/1.html'
           │       │              └ 'get'
           │       └ <function Session.request at 0x7f92583e6940>
           └ <requests.sessions.Session object at 0x7f9148777850>
  File "/home/chase/.local/lib/python3.8/site-packages/requests/sessions.py", line 542, in request
    resp = self.send(prep, **send_kwargs)
           │    │    │       └ {'timeout': None, 'allow_redirects': True, 'verify': True, 'proxies': OrderedDict(), 'stream': False, 'cert': None}
           │    │    └ <PreparedRequest [GET]>
           │    └ <function Session.send at 0x7f92583e6dc0>
           └ <requests.sessions.Session object at 0x7f9148777850>
  File "/home/chase/.local/lib/python3.8/site-packages/requests/sessions.py", line 655, in send
    r = adapter.send(request, **kwargs)
        │       │    │          └ {'timeout': None, 'verify': True, 'proxies': OrderedDict(), 'stream': False, 'cert': None}
        │       │    └ <PreparedRequest [GET]>
        │       └ <function HTTPAdapter.send at 0x7f92583e6280>
        └ <requests.adapters.HTTPAdapter object at 0x7f91041c4a30>
  File "/home/chase/.local/lib/python3.8/site-packages/requests/adapters.py", line 516, in send
    raise ConnectionError(e, request=request)
          │                          └ <PreparedRequest [GET]>
          └ <class 'requests.exceptions.ConnectionError'>

requests.exceptions.ConnectionError: HTTPConnectionPool(host='bbs1.people.com.cn', port=80): Max retries exceeded with url: /board/1.html (Caused by NewConnectionError('<urllib3.connection.HTTPConnection object at 0x7f9104189340>: Failed to establish a new connection: [Errno 111] Connection refused'))
2022-05-12 15:48:47.267 | ERROR    | monitor.searchSpiders.qinagguoLT:get_request_from_keyword:27 - E 强国论坛错误HTTPConnectionPool(host='bbs1.people.com.cn', port=80): Max retries exceeded with url: /board/1.html (Caused by NewConnectionError('<urllib3.connection.HTTPConnection object at 0x7f91483a29d0>: Failed to establish a new connection: [Errno 111] Connection refused'))
Traceback (most recent call last):

  File "/home/chase/.local/lib/python3.8/site-packages/urllib3/connection.py", line 174, in _new_conn
    conn = connection.create_connection(
           │          └ <function create_connection at 0x7f92585fd1f0>
           └ <module 'urllib3.util.connection' from '/home/chase/.local/lib/python3.8/site-packages/urllib3/util/connection.py'>
  File "/home/chase/.local/lib/python3.8/site-packages/urllib3/util/connection.py", line 96, in create_connection
    raise err
          └ ConnectionRefusedError(111, 'Connection refused')
  File "/home/chase/.local/lib/python3.8/site-packages/urllib3/util/connection.py", line 86, in create_connection
    sock.connect(sa)
    │            └ ('118.212.233.223', 80)
    └ None

ConnectionRefusedError: [Errno 111] Connection refused


During handling of the above exception, another exception occurred:


Traceback (most recent call last):

  File "/home/chase/.local/lib/python3.8/site-packages/urllib3/connectionpool.py", line 699, in urlopen
    httplib_response = self._make_request(
                       │    └ <function HTTPConnectionPool._make_request at 0x7f92585c05e0>
                       └ <urllib3.connectionpool.HTTPConnectionPool object at 0x7f914858e7c0>
  File "/home/chase/.local/lib/python3.8/site-packages/urllib3/connectionpool.py", line 394, in _make_request
    conn.request(method, url, **httplib_request_kw)
    │    │       │       │      └ {'body': None, 'headers': {'User-Agent': 'Mozilla/5.0 (X11; Linux x86_64) AppleWebKit/537.36 (KHTML, like Gecko) Chrome/93.0....
    │    │       │       └ '/board/1.html'
    │    │       └ 'GET'
    │    └ <function HTTPConnection.request at 0x7f92585b0f70>
    └ <urllib3.connection.HTTPConnection object at 0x7f91483a29d0>
  File "/home/chase/.local/lib/python3.8/site-packages/urllib3/connection.py", line 239, in request
    super(HTTPConnection, self).request(method, url, body=body, headers=headers)
          │               │             │       │         │             └ {'User-Agent': 'Mozilla/5.0 (X11; Linux x86_64) AppleWebKit/537.36 (KHTML, like Gecko) Chrome/93.0.4577.63 Safari/537.36', 'A...
          │               │             │       │         └ None
          │               │             │       └ '/board/1.html'
          │               │             └ 'GET'
          │               └ <urllib3.connection.HTTPConnection object at 0x7f91483a29d0>
          └ <class 'urllib3.connection.HTTPConnection'>
  File "/usr/lib/python3.8/http/client.py", line 1256, in request
    self._send_request(method, url, body, headers, encode_chunked)
    │    │             │       │    │     │        └ False
    │    │             │       │    │     └ {'User-Agent': 'Mozilla/5.0 (X11; Linux x86_64) AppleWebKit/537.36 (KHTML, like Gecko) Chrome/93.0.4577.63 Safari/537.36', 'A...
    │    │             │       │    └ None
    │    │             │       └ '/board/1.html'
    │    │             └ 'GET'
    │    └ <function HTTPConnection._send_request at 0x7f926be50280>
    └ <urllib3.connection.HTTPConnection object at 0x7f91483a29d0>
  File "/usr/lib/python3.8/http/client.py", line 1302, in _send_request
    self.endheaders(body, encode_chunked=encode_chunked)
    │    │          │                    └ False
    │    │          └ None
    │    └ <function HTTPConnection.endheaders at 0x7f926be50160>
    └ <urllib3.connection.HTTPConnection object at 0x7f91483a29d0>
  File "/usr/lib/python3.8/http/client.py", line 1251, in endheaders
    self._send_output(message_body, encode_chunked=encode_chunked)
    │    │            │                            └ False
    │    │            └ None
    │    └ <function HTTPConnection._send_output at 0x7f926beb7d30>
    └ <urllib3.connection.HTTPConnection object at 0x7f91483a29d0>
  File "/usr/lib/python3.8/http/client.py", line 1011, in _send_output
    self.send(msg)
    │    │    └ b'GET /board/1.html HTTP/1.1\r\nHost: bbs1.people.com.cn\r\nUser-Agent: Mozilla/5.0 (X11; Linux x86_64) AppleWebKit/537.36 (K...
    │    └ <function HTTPConnection.send at 0x7f926beb7b80>
    └ <urllib3.connection.HTTPConnection object at 0x7f91483a29d0>
  File "/usr/lib/python3.8/http/client.py", line 951, in send
    self.connect()
    │    └ <function HTTPConnection.connect at 0x7f92585b0dc0>
    └ <urllib3.connection.HTTPConnection object at 0x7f91483a29d0>
  File "/home/chase/.local/lib/python3.8/site-packages/urllib3/connection.py", line 205, in connect
    conn = self._new_conn()
           │    └ <function HTTPConnection._new_conn at 0x7f92585b0c10>
           └ <urllib3.connection.HTTPConnection object at 0x7f91483a29d0>
  File "/home/chase/.local/lib/python3.8/site-packages/urllib3/connection.py", line 186, in _new_conn
    raise NewConnectionError(
          └ <class 'urllib3.exceptions.NewConnectionError'>

urllib3.exceptions.NewConnectionError: <urllib3.connection.HTTPConnection object at 0x7f91483a29d0>: Failed to establish a new connection: [Errno 111] Connection refused


During handling of the above exception, another exception occurred:


Traceback (most recent call last):

  File "/home/chase/.local/lib/python3.8/site-packages/requests/adapters.py", line 439, in send
    resp = conn.urlopen(
           │    └ <function HTTPConnectionPool.urlopen at 0x7f92585c0820>
           └ <urllib3.connectionpool.HTTPConnectionPool object at 0x7f914858e7c0>
  File "/home/chase/.local/lib/python3.8/site-packages/urllib3/connectionpool.py", line 755, in urlopen
    retries = retries.increment(
              │       └ <function Retry.increment at 0x7f9258608b80>
              └ Retry(total=0, connect=None, read=False, redirect=None, status=None)
  File "/home/chase/.local/lib/python3.8/site-packages/urllib3/util/retry.py", line 574, in increment
    raise MaxRetryError(_pool, url, error or ResponseError(cause))
          │             │      │    │        │             └ 'unknown'
          │             │      │    │        └ <class 'urllib3.exceptions.ResponseError'>
          │             │      │    └ NewConnectionError('<urllib3.connection.HTTPConnection object at 0x7f91483a29d0>: Failed to establish a new connection: [Errn...
          │             │      └ '/board/1.html'
          │             └ <urllib3.connectionpool.HTTPConnectionPool object at 0x7f914858e7c0>
          └ <class 'urllib3.exceptions.MaxRetryError'>

urllib3.exceptions.MaxRetryError: HTTPConnectionPool(host='bbs1.people.com.cn', port=80): Max retries exceeded with url: /board/1.html (Caused by NewConnectionError('<urllib3.connection.HTTPConnection object at 0x7f91483a29d0>: Failed to establish a new connection: [Errno 111] Connection refused'))


During handling of the above exception, another exception occurred:


Traceback (most recent call last):

  File "/usr/lib/python3.8/threading.py", line 890, in _bootstrap
    self._bootstrap_inner()
    │    └ <function Thread._bootstrap_inner at 0x7f927a614a60>
    └ <Thread(Thread-129, started daemon 140260319151872)>
  File "/usr/lib/python3.8/threading.py", line 932, in _bootstrap_inner
    self.run()
    │    └ <function Thread.run at 0x7f927a614790>
    └ <Thread(Thread-129, started daemon 140260319151872)>
  File "/usr/lib/python3.8/threading.py", line 870, in run
    self._target(*self._args, **self._kwargs)
    │    │        │    │        │    └ {}
    │    │        │    │        └ <Thread(Thread-129, started daemon 140260319151872)>
    │    │        │    └ ('ProjectManager.run_func_by_thread',)
    │    │        └ <Thread(Thread-129, started daemon 140260319151872)>
    │    └ <bound method ProjectManager.get_request_from_keywords_hot of <monitor.projectManager.ProjectManager object at 0x7f9162af4700>>
    └ <Thread(Thread-129, started daemon 140260319151872)>

  File "/home/users/Scy/yuqing/spider/monitor/projectManager.py", line 795, in get_request_from_keywords_hot
    self.search_spider_manager.crawl_by_keyword(
    │    │                     └ <function SearchSpidersManager.crawl_by_keyword at 0x7f9162b00040>
    │    └ <monitor.spiderManager.SearchSpidersManager object at 0x7f916270f0d0>
    └ <monitor.projectManager.ProjectManager object at 0x7f9162af4700>

  File "/home/users/Scy/yuqing/spider/monitor/spiderManager.py", line 118, in crawl_by_keyword
    self.crawl_by_keyword_signal_platform(project_names, platform, keyword, crawl_time, project_times)
    │    │                                │              │         │        │           └ {'default': <monitor.TimeSection object at 0x7f91628317f0>}
    │    │                                │              │         │        └ <monitor.TimeSection object at 0x7f916011acd0>
    │    │                                │              │         └ '埃及安全部队打死14名恐怖分子'
    │    │                                │              └ '强国论坛'
    │    │                                └ ['default']
    │    └ <function SearchSpidersManager.crawl_by_keyword_signal_platform at 0x7f9162b000d0>
    └ <monitor.spiderManager.SearchSpidersManager object at 0x7f916270f0d0>

  File "/home/users/Scy/yuqing/spider/monitor/spiderManager.py", line 134, in crawl_by_keyword_signal_platform
    requests = self.get_request_from_keyword(platform, keyword, **crawl_time.to_dict())
               │    │                        │         │          │          └ <function TimeSection.to_dict at 0x7f925aaa8550>
               │    │                        │         │          └ <monitor.TimeSection object at 0x7f916011acd0>
               │    │                        │         └ '埃及安全部队打死14名恐怖分子'
               │    │                        └ '强国论坛'
               │    └ <function SearchSpidersManager.get_request_from_keyword at 0x7f9162b001f0>
               └ <monitor.spiderManager.SearchSpidersManager object at 0x7f916270f0d0>

  File "/home/users/Scy/yuqing/spider/monitor/spiderManager.py", line 191, in get_request_from_keyword
    for request in self.spiders[platform].get_request_from_keyword(headers, search_url, keyword, content_url,
                   │    │       │                                  │        │           │        └ <string.Template object at 0x7f916025d0a0>
                   │    │       │                                  │        │           └ '埃及安全部队打死14名恐怖分子'
                   │    │       │                                  │        └ <string.Template object at 0x7f90e47e8850>
                   │    │       │                                  └ {'Connection': 'keep-alive', 'Cache-Control': 'max-age=0', 'Upgrade-Insecure-Requests': '1', 'User-Agent': 'Mozilla/5.0 (X11;...
                   │    │       └ '强国论坛'
                   │    └ {'凤凰网': <monitor.searchSpiders.ifeng.Ifeng object at 0x7f916270f220>, '头条': <monitor.searchSpiders.toutiao.Toutiao object at ...
                   └ <monitor.spiderManager.SearchSpidersManager object at 0x7f916270f0d0>

> File "/home/users/Scy/yuqing/spider/monitor/searchSpiders/qinagguoLT.py", line 18, in get_request_from_keyword
    response = requests.get(search_url.substitute(), headers=headers)
               │        │   │          │                     └ {'Connection': 'keep-alive', 'Cache-Control': 'max-age=0', 'Upgrade-Insecure-Requests': '1', 'User-Agent': 'Mozilla/5.0 (X11;...
               │        │   │          └ <function Template.substitute at 0x7f927a5fd0d0>
               │        │   └ <string.Template object at 0x7f90e47e8850>
               │        └ <function get at 0x7f92583e71f0>
               └ <module 'requests' from '/home/chase/.local/lib/python3.8/site-packages/requests/__init__.py'>

  File "/home/chase/.local/lib/python3.8/site-packages/requests/api.py", line 75, in get
    return request('get', url, params=params, **kwargs)
           │              │           │         └ {'headers': {'Connection': 'keep-alive', 'Cache-Control': 'max-age=0', 'Upgrade-Insecure-Requests': '1', 'User-Agent': 'Mozil...
           │              │           └ None
           │              └ 'http://bbs1.people.com.cn/board/1.html'
           └ <function request at 0x7f9258455040>
  File "/home/chase/.local/lib/python3.8/site-packages/requests/api.py", line 61, in request
    return session.request(method=method, url=url, **kwargs)
           │       │              │           │      └ {'params': None, 'headers': {'Connection': 'keep-alive', 'Cache-Control': 'max-age=0', 'Upgrade-Insecure-Requests': '1', 'Use...
           │       │              │           └ 'http://bbs1.people.com.cn/board/1.html'
           │       │              └ 'get'
           │       └ <function Session.request at 0x7f92583e6940>
           └ <requests.sessions.Session object at 0x7f916002fcd0>
  File "/home/chase/.local/lib/python3.8/site-packages/requests/sessions.py", line 542, in request
    resp = self.send(prep, **send_kwargs)
           │    │    │       └ {'timeout': None, 'allow_redirects': True, 'verify': True, 'proxies': OrderedDict(), 'stream': False, 'cert': None}
           │    │    └ <PreparedRequest [GET]>
           │    └ <function Session.send at 0x7f92583e6dc0>
           └ <requests.sessions.Session object at 0x7f916002fcd0>
  File "/home/chase/.local/lib/python3.8/site-packages/requests/sessions.py", line 655, in send
    r = adapter.send(request, **kwargs)
        │       │    │          └ {'timeout': None, 'verify': True, 'proxies': OrderedDict(), 'stream': False, 'cert': None}
        │       │    └ <PreparedRequest [GET]>
        │       └ <function HTTPAdapter.send at 0x7f92583e6280>
        └ <requests.adapters.HTTPAdapter object at 0x7f9253e3bfd0>
  File "/home/chase/.local/lib/python3.8/site-packages/requests/adapters.py", line 516, in send
    raise ConnectionError(e, request=request)
          │                          └ <PreparedRequest [GET]>
          └ <class 'requests.exceptions.ConnectionError'>

requests.exceptions.ConnectionError: HTTPConnectionPool(host='bbs1.people.com.cn', port=80): Max retries exceeded with url: /board/1.html (Caused by NewConnectionError('<urllib3.connection.HTTPConnection object at 0x7f91483a29d0>: Failed to establish a new connection: [Errno 111] Connection refused'))
2022-05-12 15:48:47.467 | ERROR    | monitor.searchSpiders.qinagguoLT:get_request_from_keyword:27 - E 强国论坛错误HTTPConnectionPool(host='bbs1.people.com.cn', port=80): Max retries exceeded with url: /board/1.html (Caused by NewConnectionError('<urllib3.connection.HTTPConnection object at 0x7f91240d3460>: Failed to establish a new connection: [Errno 111] Connection refused'))
Traceback (most recent call last):

  File "/home/chase/.local/lib/python3.8/site-packages/urllib3/connection.py", line 174, in _new_conn
    conn = connection.create_connection(
           │          └ <function create_connection at 0x7f92585fd1f0>
           └ <module 'urllib3.util.connection' from '/home/chase/.local/lib/python3.8/site-packages/urllib3/util/connection.py'>
  File "/home/chase/.local/lib/python3.8/site-packages/urllib3/util/connection.py", line 96, in create_connection
    raise err
          └ ConnectionRefusedError(111, 'Connection refused')
  File "/home/chase/.local/lib/python3.8/site-packages/urllib3/util/connection.py", line 86, in create_connection
    sock.connect(sa)
    │            └ ('118.212.233.223', 80)
    └ None

ConnectionRefusedError: [Errno 111] Connection refused


During handling of the above exception, another exception occurred:


Traceback (most recent call last):

  File "/home/chase/.local/lib/python3.8/site-packages/urllib3/connectionpool.py", line 699, in urlopen
    httplib_response = self._make_request(
                       │    └ <function HTTPConnectionPool._make_request at 0x7f92585c05e0>
                       └ <urllib3.connectionpool.HTTPConnectionPool object at 0x7f914815cdc0>
  File "/home/chase/.local/lib/python3.8/site-packages/urllib3/connectionpool.py", line 394, in _make_request
    conn.request(method, url, **httplib_request_kw)
    │    │       │       │      └ {'body': None, 'headers': {'User-Agent': 'Mozilla/5.0 (X11; Linux x86_64) AppleWebKit/537.36 (KHTML, like Gecko) Chrome/93.0....
    │    │       │       └ '/board/1.html'
    │    │       └ 'GET'
    │    └ <function HTTPConnection.request at 0x7f92585b0f70>
    └ <urllib3.connection.HTTPConnection object at 0x7f91240d3460>
  File "/home/chase/.local/lib/python3.8/site-packages/urllib3/connection.py", line 239, in request
    super(HTTPConnection, self).request(method, url, body=body, headers=headers)
          │               │             │       │         │             └ {'User-Agent': 'Mozilla/5.0 (X11; Linux x86_64) AppleWebKit/537.36 (KHTML, like Gecko) Chrome/93.0.4577.63 Safari/537.36', 'A...
          │               │             │       │         └ None
          │               │             │       └ '/board/1.html'
          │               │             └ 'GET'
          │               └ <urllib3.connection.HTTPConnection object at 0x7f91240d3460>
          └ <class 'urllib3.connection.HTTPConnection'>
  File "/usr/lib/python3.8/http/client.py", line 1256, in request
    self._send_request(method, url, body, headers, encode_chunked)
    │    │             │       │    │     │        └ False
    │    │             │       │    │     └ {'User-Agent': 'Mozilla/5.0 (X11; Linux x86_64) AppleWebKit/537.36 (KHTML, like Gecko) Chrome/93.0.4577.63 Safari/537.36', 'A...
    │    │             │       │    └ None
    │    │             │       └ '/board/1.html'
    │    │             └ 'GET'
    │    └ <function HTTPConnection._send_request at 0x7f926be50280>
    └ <urllib3.connection.HTTPConnection object at 0x7f91240d3460>
  File "/usr/lib/python3.8/http/client.py", line 1302, in _send_request
    self.endheaders(body, encode_chunked=encode_chunked)
    │    │          │                    └ False
    │    │          └ None
    │    └ <function HTTPConnection.endheaders at 0x7f926be50160>
    └ <urllib3.connection.HTTPConnection object at 0x7f91240d3460>
  File "/usr/lib/python3.8/http/client.py", line 1251, in endheaders
    self._send_output(message_body, encode_chunked=encode_chunked)
    │    │            │                            └ False
    │    │            └ None
    │    └ <function HTTPConnection._send_output at 0x7f926beb7d30>
    └ <urllib3.connection.HTTPConnection object at 0x7f91240d3460>
  File "/usr/lib/python3.8/http/client.py", line 1011, in _send_output
    self.send(msg)
    │    │    └ b'GET /board/1.html HTTP/1.1\r\nHost: bbs1.people.com.cn\r\nUser-Agent: Mozilla/5.0 (X11; Linux x86_64) AppleWebKit/537.36 (K...
    │    └ <function HTTPConnection.send at 0x7f926beb7b80>
    └ <urllib3.connection.HTTPConnection object at 0x7f91240d3460>
  File "/usr/lib/python3.8/http/client.py", line 951, in send
    self.connect()
    │    └ <function HTTPConnection.connect at 0x7f92585b0dc0>
    └ <urllib3.connection.HTTPConnection object at 0x7f91240d3460>
  File "/home/chase/.local/lib/python3.8/site-packages/urllib3/connection.py", line 205, in connect
    conn = self._new_conn()
           │    └ <function HTTPConnection._new_conn at 0x7f92585b0c10>
           └ <urllib3.connection.HTTPConnection object at 0x7f91240d3460>
  File "/home/chase/.local/lib/python3.8/site-packages/urllib3/connection.py", line 186, in _new_conn
    raise NewConnectionError(
          └ <class 'urllib3.exceptions.NewConnectionError'>

urllib3.exceptions.NewConnectionError: <urllib3.connection.HTTPConnection object at 0x7f91240d3460>: Failed to establish a new connection: [Errno 111] Connection refused


During handling of the above exception, another exception occurred:


Traceback (most recent call last):

  File "/home/chase/.local/lib/python3.8/site-packages/requests/adapters.py", line 439, in send
    resp = conn.urlopen(
           │    └ <function HTTPConnectionPool.urlopen at 0x7f92585c0820>
           └ <urllib3.connectionpool.HTTPConnectionPool object at 0x7f914815cdc0>
  File "/home/chase/.local/lib/python3.8/site-packages/urllib3/connectionpool.py", line 755, in urlopen
    retries = retries.increment(
              │       └ <function Retry.increment at 0x7f9258608b80>
              └ Retry(total=0, connect=None, read=False, redirect=None, status=None)
  File "/home/chase/.local/lib/python3.8/site-packages/urllib3/util/retry.py", line 574, in increment
    raise MaxRetryError(_pool, url, error or ResponseError(cause))
          │             │      │    │        │             └ 'unknown'
          │             │      │    │        └ <class 'urllib3.exceptions.ResponseError'>
          │             │      │    └ NewConnectionError('<urllib3.connection.HTTPConnection object at 0x7f91240d3460>: Failed to establish a new connection: [Errn...
          │             │      └ '/board/1.html'
          │             └ <urllib3.connectionpool.HTTPConnectionPool object at 0x7f914815cdc0>
          └ <class 'urllib3.exceptions.MaxRetryError'>

urllib3.exceptions.MaxRetryError: HTTPConnectionPool(host='bbs1.people.com.cn', port=80): Max retries exceeded with url: /board/1.html (Caused by NewConnectionError('<urllib3.connection.HTTPConnection object at 0x7f91240d3460>: Failed to establish a new connection: [Errno 111] Connection refused'))


During handling of the above exception, another exception occurred:


Traceback (most recent call last):

  File "/usr/lib/python3.8/threading.py", line 890, in _bootstrap
    self._bootstrap_inner()
    │    └ <function Thread._bootstrap_inner at 0x7f927a614a60>
    └ <Thread(Thread-254, started daemon 140258180060928)>
  File "/usr/lib/python3.8/threading.py", line 932, in _bootstrap_inner
    self.run()
    │    └ <function Thread.run at 0x7f927a614790>
    └ <Thread(Thread-254, started daemon 140258180060928)>
  File "/usr/lib/python3.8/threading.py", line 870, in run
    self._target(*self._args, **self._kwargs)
    │    │        │    │        │    └ {}
    │    │        │    │        └ <Thread(Thread-254, started daemon 140258180060928)>
    │    │        │    └ ('ProjectManager.run_func_by_thread',)
    │    │        └ <Thread(Thread-254, started daemon 140258180060928)>
    │    └ <bound method ProjectManager.get_request_from_keywords_hot of <monitor.projectManager.ProjectManager object at 0x7f9162af4700>>
    └ <Thread(Thread-254, started daemon 140258180060928)>

  File "/home/users/Scy/yuqing/spider/monitor/projectManager.py", line 795, in get_request_from_keywords_hot
    self.search_spider_manager.crawl_by_keyword(
    │    │                     └ <function SearchSpidersManager.crawl_by_keyword at 0x7f9162b00040>
    │    └ <monitor.spiderManager.SearchSpidersManager object at 0x7f916270f0d0>
    └ <monitor.projectManager.ProjectManager object at 0x7f9162af4700>

  File "/home/users/Scy/yuqing/spider/monitor/spiderManager.py", line 118, in crawl_by_keyword
    self.crawl_by_keyword_signal_platform(project_names, platform, keyword, crawl_time, project_times)
    │    │                                │              │         │        │           └ {'default': <monitor.TimeSection object at 0x7f91628317f0>}
    │    │                                │              │         │        └ <monitor.TimeSection object at 0x7f9253eb9970>
    │    │                                │              │         └ '土耳其通货膨胀率持续高位运行'
    │    │                                │              └ '强国论坛'
    │    │                                └ ['default']
    │    └ <function SearchSpidersManager.crawl_by_keyword_signal_platform at 0x7f9162b000d0>
    └ <monitor.spiderManager.SearchSpidersManager object at 0x7f916270f0d0>

  File "/home/users/Scy/yuqing/spider/monitor/spiderManager.py", line 134, in crawl_by_keyword_signal_platform
    requests = self.get_request_from_keyword(platform, keyword, **crawl_time.to_dict())
               │    │                        │         │          │          └ <function TimeSection.to_dict at 0x7f925aaa8550>
               │    │                        │         │          └ <monitor.TimeSection object at 0x7f9253eb9970>
               │    │                        │         └ '土耳其通货膨胀率持续高位运行'
               │    │                        └ '强国论坛'
               │    └ <function SearchSpidersManager.get_request_from_keyword at 0x7f9162b001f0>
               └ <monitor.spiderManager.SearchSpidersManager object at 0x7f916270f0d0>

  File "/home/users/Scy/yuqing/spider/monitor/spiderManager.py", line 191, in get_request_from_keyword
    for request in self.spiders[platform].get_request_from_keyword(headers, search_url, keyword, content_url,
                   │    │       │                                  │        │           │        └ <string.Template object at 0x7f91241df280>
                   │    │       │                                  │        │           └ '土耳其通货膨胀率持续高位运行'
                   │    │       │                                  │        └ <string.Template object at 0x7f910421a310>
                   │    │       │                                  └ {'Connection': 'keep-alive', 'Cache-Control': 'max-age=0', 'Upgrade-Insecure-Requests': '1', 'User-Agent': 'Mozilla/5.0 (X11;...
                   │    │       └ '强国论坛'
                   │    └ {'凤凰网': <monitor.searchSpiders.ifeng.Ifeng object at 0x7f916270f220>, '头条': <monitor.searchSpiders.toutiao.Toutiao object at ...
                   └ <monitor.spiderManager.SearchSpidersManager object at 0x7f916270f0d0>

> File "/home/users/Scy/yuqing/spider/monitor/searchSpiders/qinagguoLT.py", line 18, in get_request_from_keyword
    response = requests.get(search_url.substitute(), headers=headers)
               │        │   │          │                     └ {'Connection': 'keep-alive', 'Cache-Control': 'max-age=0', 'Upgrade-Insecure-Requests': '1', 'User-Agent': 'Mozilla/5.0 (X11;...
               │        │   │          └ <function Template.substitute at 0x7f927a5fd0d0>
               │        │   └ <string.Template object at 0x7f910421a310>
               │        └ <function get at 0x7f92583e71f0>
               └ <module 'requests' from '/home/chase/.local/lib/python3.8/site-packages/requests/__init__.py'>

  File "/home/chase/.local/lib/python3.8/site-packages/requests/api.py", line 75, in get
    return request('get', url, params=params, **kwargs)
           │              │           │         └ {'headers': {'Connection': 'keep-alive', 'Cache-Control': 'max-age=0', 'Upgrade-Insecure-Requests': '1', 'User-Agent': 'Mozil...
           │              │           └ None
           │              └ 'http://bbs1.people.com.cn/board/1.html'
           └ <function request at 0x7f9258455040>
  File "/home/chase/.local/lib/python3.8/site-packages/requests/api.py", line 61, in request
    return session.request(method=method, url=url, **kwargs)
           │       │              │           │      └ {'params': None, 'headers': {'Connection': 'keep-alive', 'Cache-Control': 'max-age=0', 'Upgrade-Insecure-Requests': '1', 'Use...
           │       │              │           └ 'http://bbs1.people.com.cn/board/1.html'
           │       │              └ 'get'
           │       └ <function Session.request at 0x7f92583e6940>
           └ <requests.sessions.Session object at 0x7f9253e13a00>
  File "/home/chase/.local/lib/python3.8/site-packages/requests/sessions.py", line 542, in request
    resp = self.send(prep, **send_kwargs)
           │    │    │       └ {'timeout': None, 'allow_redirects': True, 'verify': True, 'proxies': OrderedDict(), 'stream': False, 'cert': None}
           │    │    └ <PreparedRequest [GET]>
           │    └ <function Session.send at 0x7f92583e6dc0>
           └ <requests.sessions.Session object at 0x7f9253e13a00>
  File "/home/chase/.local/lib/python3.8/site-packages/requests/sessions.py", line 655, in send
    r = adapter.send(request, **kwargs)
        │       │    │          └ {'timeout': None, 'verify': True, 'proxies': OrderedDict(), 'stream': False, 'cert': None}
        │       │    └ <PreparedRequest [GET]>
        │       └ <function HTTPAdapter.send at 0x7f92583e6280>
        └ <requests.adapters.HTTPAdapter object at 0x7f91241f17f0>
  File "/home/chase/.local/lib/python3.8/site-packages/requests/adapters.py", line 516, in send
    raise ConnectionError(e, request=request)
          │                          └ <PreparedRequest [GET]>
          └ <class 'requests.exceptions.ConnectionError'>

requests.exceptions.ConnectionError: HTTPConnectionPool(host='bbs1.people.com.cn', port=80): Max retries exceeded with url: /board/1.html (Caused by NewConnectionError('<urllib3.connection.HTTPConnection object at 0x7f91240d3460>: Failed to establish a new connection: [Errno 111] Connection refused'))
