2022-05-13 23:00:48.991 | ERROR    | base.db.mysql:update:390 - 【mysql更新数据出错】
Traceback (most recent call last):

  File "/home/chase/.local/lib/python3.8/site-packages/sqlalchemy/engine/base.py", line 1771, in _execute_context
    self.dialect.do_execute(
    │    │       └ <function DefaultDialect.do_execute at 0x7f31f38f75e0>
    │    └ <sqlalchemy.dialects.mysql.pymysql.MySQLDialect_pymysql object at 0x7f3103ffde20>
    └ <sqlalchemy.engine.base.Connection object at 0x7f30d827efa0>
  File "/home/chase/.local/lib/python3.8/site-packages/sqlalchemy/engine/default.py", line 717, in do_execute
    cursor.execute(statement, parameters)
    │      │       │          └ {'server_id': '180.201.163.246:6800', 'ip': '180.201.163.246', 'username': 'chase', 'password': '9992087644658889259278256241...
    │      │       └ 'UPDATE device SET server_id=%(server_id)s, ip=%(ip)s, username=%(username)s, password=%(password)s, address=%(address)s, por...
    │      └ <function Cursor.execute at 0x7f31f354cdc0>
    └ <pymysql.cursors.Cursor object at 0x7f31f931e2b0>
  File "/home/chase/.local/lib/python3.8/site-packages/pymysql/cursors.py", line 148, in execute
    result = self._query(query)
             │    │      └ "UPDATE device SET server_id='180.201.163.246:6800', ip='180.201.163.246', username='chase', password='9992087644658889259278...
             │    └ <function Cursor._query at 0x7f31f34d7280>
             └ <pymysql.cursors.Cursor object at 0x7f31f931e2b0>
  File "/home/chase/.local/lib/python3.8/site-packages/pymysql/cursors.py", line 310, in _query
    conn.query(q)
    │    │     └ "UPDATE device SET server_id='180.201.163.246:6800', ip='180.201.163.246', username='chase', password='9992087644658889259278...
    │    └ <function Connection.query at 0x7f31f34e5670>
    └ <pymysql.connections.Connection object at 0x7f30386cdb80>
  File "/home/chase/.local/lib/python3.8/site-packages/pymysql/connections.py", line 548, in query
    self._affected_rows = self._read_query_result(unbuffered=unbuffered)
    │    │                │    │                             └ False
    │    │                │    └ <function Connection._read_query_result at 0x7f31f34e5ca0>
    │    │                └ <pymysql.connections.Connection object at 0x7f30386cdb80>
    │    └ 1
    └ <pymysql.connections.Connection object at 0x7f30386cdb80>
  File "/home/chase/.local/lib/python3.8/site-packages/pymysql/connections.py", line 775, in _read_query_result
    result.read()
    │      └ <function MySQLResult.read at 0x7f31f34e64c0>
    └ <pymysql.connections.MySQLResult object at 0x7f30186549a0>
  File "/home/chase/.local/lib/python3.8/site-packages/pymysql/connections.py", line 1156, in read
    first_packet = self.connection._read_packet()
                   │    └ None
                   └ <pymysql.connections.MySQLResult object at 0x7f30186549a0>
  File "/home/chase/.local/lib/python3.8/site-packages/pymysql/connections.py", line 725, in _read_packet
    packet.raise_for_error()
    │      └ <function MysqlPacket.raise_for_error at 0x7f31f34ddee0>
    └ <pymysql.protocol.MysqlPacket object at 0x7f3018459fd0>
  File "/home/chase/.local/lib/python3.8/site-packages/pymysql/protocol.py", line 221, in raise_for_error
    err.raise_mysql_exception(self._data)
    │   │                     │    └ <member '_data' of 'MysqlPacket' objects>
    │   │                     └ <pymysql.protocol.MysqlPacket object at 0x7f3018459fd0>
    │   └ <function raise_mysql_exception at 0x7f31f358c670>
    └ <module 'pymysql.err' from '/home/chase/.local/lib/python3.8/site-packages/pymysql/err.py'>
  File "/home/chase/.local/lib/python3.8/site-packages/pymysql/err.py", line 143, in raise_mysql_exception
    raise errorclass(errno, errval)
          │          │      └ "Duplicate entry '180.201.163.246:6800' for key 'device.PRIMARY'"
          │          └ 1062
          └ <class 'pymysql.err.IntegrityError'>

pymysql.err.IntegrityError: (1062, "Duplicate entry '180.201.163.246:6800' for key 'device.PRIMARY'")


The above exception was the direct cause of the following exception:


Traceback (most recent call last):

  File "/usr/lib/python3.8/threading.py", line 890, in _bootstrap
    self._bootstrap_inner()
    │    └ <function Thread._bootstrap_inner at 0x7f321bf29a60>
    └ <Thread(Thread-5492, started daemon 139838353925888)>
  File "/usr/lib/python3.8/threading.py", line 932, in _bootstrap_inner
    self.run()
    │    └ <function Thread.run at 0x7f321bf29790>
    └ <Thread(Thread-5492, started daemon 139838353925888)>
  File "/usr/lib/python3.8/threading.py", line 870, in run
    self._target(*self._args, **self._kwargs)
    │    │        │    │        │    └ {}
    │    │        │    │        └ <Thread(Thread-5492, started daemon 139838353925888)>
    │    │        │    └ ('ProjectManager.run_func_by_thread',)
    │    │        └ <Thread(Thread-5492, started daemon 139838353925888)>
    │    └ <bound method ProjectManager.get_request_from_keywords_hot of <monitor.projectManager.ProjectManager object at 0x7f31042e52e0>>
    └ <Thread(Thread-5492, started daemon 139838353925888)>

  File "/home/users/Scy/yuqing/spider/monitor/projectManager.py", line 799, in get_request_from_keywords_hot
    self.start_finished_spider_every_interval(project_names)
    │    │                                    └ ['default', 'test']
    │    └ <function ProjectManager.start_finished_spider_every_interval at 0x7f3104005280>
    └ <monitor.projectManager.ProjectManager object at 0x7f31042e52e0>

  File "/home/users/Scy/yuqing/spider/monitor/projectManager.py", line 784, in start_finished_spider_every_interval
    self[name].start_spider()
    │    └ 'default'
    └ <monitor.projectManager.ProjectManager object at 0x7f31042e52e0>

  File "/home/users/Scy/yuqing/spider/monitor/projectManager.py", line 366, in start_spider
    self.update_device_valid(device)
    │    │                   └ <monitor.deviceManager.DeviceC object at 0x7f3104029220>
    │    └ <function Project.update_device_valid at 0x7f3104003280>
    └ <monitor.projectManager.Project object at 0x7f3104029460>

  File "/home/users/Scy/yuqing/spider/monitor/projectManager.py", line 421, in update_device_valid
    self.database_manager.mysql.update(Device(**device.to_item()))
    │    │                │     │      │        │      └ <function DeviceC.to_item at 0x7f31f34ed310>
    │    │                │     │      │        └ <monitor.deviceManager.DeviceC object at 0x7f3104029220>
    │    │                │     │      └ <class 'base.db.mysql.Device'>
    │    │                │     └ <function Mysql.update at 0x7f31f35f4790>
    │    │                └ <base.db.mysql.Mysql object at 0x7f3103ffdfd0>
    │    └ <base.db.dbSlot.Slot object at 0x7f3103ffdf10>
    └ <monitor.projectManager.Project object at 0x7f3104029460>

> File "/home/users/Scy/yuqing/spider/base/db/mysql.py", line 375, in update
    row.update(new)
    │   │      └ {'server_id': '180.201.163.246:6800', 'ip': '180.201.163.246', 'username': 'chase', 'password': '9992087644658889259278256241...
    │   └ <function Query.update at 0x7f31f37333a0>
    └ <sqlalchemy.orm.query.Query object at 0x7f30d82677c0>

  File "/home/chase/.local/lib/python3.8/site-packages/sqlalchemy/orm/query.py", line 3221, in update
    result = self.session.execute(
             │    │       └ <function Session.execute at 0x7f31f370faf0>
             │    └ <sqlalchemy.orm.session.Session object at 0x7f301813efd0>
             └ <sqlalchemy.orm.query.Query object at 0x7f30d82677c0>
  File "/home/chase/.local/lib/python3.8/site-packages/sqlalchemy/orm/session.py", line 1689, in execute
    result = conn._execute_20(statement, params or {}, execution_options)
             │    │           │          │             └ immutabledict({'synchronize_session': 'evaluate', '_sa_orm_update_options': default_update_options(_matched_objects=[], _reso...
             │    │           │          └ immutabledict({})
             │    │           └ <sqlalchemy.sql.annotation.AnnotatedUpdate object at 0x7f3100324d90>
             │    └ <function Connection._execute_20 at 0x7f31f39bc790>
             └ <sqlalchemy.engine.base.Connection object at 0x7f30d827efa0>
  File "/home/chase/.local/lib/python3.8/site-packages/sqlalchemy/engine/base.py", line 1583, in _execute_20
    return meth(self, args_10style, kwargs_10style, execution_options)
           │    │     │             │               └ immutabledict({'synchronize_session': 'evaluate', '_sa_orm_update_options': default_update_options(_matched_objects=[], _reso...
           │    │     │             └ immutabledict({})
           │    │     └ ({},)
           │    └ <sqlalchemy.engine.base.Connection object at 0x7f30d827efa0>
           └ <bound method ClauseElement._execute_on_connection of <sqlalchemy.sql.annotation.AnnotatedUpdate object at 0x7f3100324d90>>
  File "/home/chase/.local/lib/python3.8/site-packages/sqlalchemy/sql/elements.py", line 323, in _execute_on_connection
    return connection._execute_clauseelement(
           │          └ <function Connection._execute_clauseelement at 0x7f31f39bc5e0>
           └ <sqlalchemy.engine.base.Connection object at 0x7f30d827efa0>
  File "/home/chase/.local/lib/python3.8/site-packages/sqlalchemy/engine/base.py", line 1452, in _execute_clauseelement
    ret = self._execute_context(
          │    └ <function Connection._execute_context at 0x7f31f39bc8b0>
          └ <sqlalchemy.engine.base.Connection object at 0x7f30d827efa0>
  File "/home/chase/.local/lib/python3.8/site-packages/sqlalchemy/engine/base.py", line 1814, in _execute_context
    self._handle_dbapi_exception(
    │    └ <function Connection._handle_dbapi_exception at 0x7f31f39bca60>
    └ <sqlalchemy.engine.base.Connection object at 0x7f30d827efa0>
  File "/home/chase/.local/lib/python3.8/site-packages/sqlalchemy/engine/base.py", line 1995, in _handle_dbapi_exception
    util.raise_(
    │    └ <function raise_ at 0x7f31f3d7ea60>
    └ <module 'sqlalchemy.util' from '/home/chase/.local/lib/python3.8/site-packages/sqlalchemy/util/__init__.py'>
  File "/home/chase/.local/lib/python3.8/site-packages/sqlalchemy/util/compat.py", line 207, in raise_
    raise exception
  File "/home/chase/.local/lib/python3.8/site-packages/sqlalchemy/engine/base.py", line 1771, in _execute_context
    self.dialect.do_execute(
    │    │       └ <function DefaultDialect.do_execute at 0x7f31f38f75e0>
    │    └ <sqlalchemy.dialects.mysql.pymysql.MySQLDialect_pymysql object at 0x7f3103ffde20>
    └ <sqlalchemy.engine.base.Connection object at 0x7f30d827efa0>
  File "/home/chase/.local/lib/python3.8/site-packages/sqlalchemy/engine/default.py", line 717, in do_execute
    cursor.execute(statement, parameters)
    │      │       │          └ {'server_id': '180.201.163.246:6800', 'ip': '180.201.163.246', 'username': 'chase', 'password': '9992087644658889259278256241...
    │      │       └ 'UPDATE device SET server_id=%(server_id)s, ip=%(ip)s, username=%(username)s, password=%(password)s, address=%(address)s, por...
    │      └ <function Cursor.execute at 0x7f31f354cdc0>
    └ <pymysql.cursors.Cursor object at 0x7f31f931e2b0>
  File "/home/chase/.local/lib/python3.8/site-packages/pymysql/cursors.py", line 148, in execute
    result = self._query(query)
             │    │      └ "UPDATE device SET server_id='180.201.163.246:6800', ip='180.201.163.246', username='chase', password='9992087644658889259278...
             │    └ <function Cursor._query at 0x7f31f34d7280>
             └ <pymysql.cursors.Cursor object at 0x7f31f931e2b0>
  File "/home/chase/.local/lib/python3.8/site-packages/pymysql/cursors.py", line 310, in _query
    conn.query(q)
    │    │     └ "UPDATE device SET server_id='180.201.163.246:6800', ip='180.201.163.246', username='chase', password='9992087644658889259278...
    │    └ <function Connection.query at 0x7f31f34e5670>
    └ <pymysql.connections.Connection object at 0x7f30386cdb80>
  File "/home/chase/.local/lib/python3.8/site-packages/pymysql/connections.py", line 548, in query
    self._affected_rows = self._read_query_result(unbuffered=unbuffered)
    │    │                │    │                             └ False
    │    │                │    └ <function Connection._read_query_result at 0x7f31f34e5ca0>
    │    │                └ <pymysql.connections.Connection object at 0x7f30386cdb80>
    │    └ 1
    └ <pymysql.connections.Connection object at 0x7f30386cdb80>
  File "/home/chase/.local/lib/python3.8/site-packages/pymysql/connections.py", line 775, in _read_query_result
    result.read()
    │      └ <function MySQLResult.read at 0x7f31f34e64c0>
    └ <pymysql.connections.MySQLResult object at 0x7f30186549a0>
  File "/home/chase/.local/lib/python3.8/site-packages/pymysql/connections.py", line 1156, in read
    first_packet = self.connection._read_packet()
                   │    └ None
                   └ <pymysql.connections.MySQLResult object at 0x7f30186549a0>
  File "/home/chase/.local/lib/python3.8/site-packages/pymysql/connections.py", line 725, in _read_packet
    packet.raise_for_error()
    │      └ <function MysqlPacket.raise_for_error at 0x7f31f34ddee0>
    └ <pymysql.protocol.MysqlPacket object at 0x7f3018459fd0>
  File "/home/chase/.local/lib/python3.8/site-packages/pymysql/protocol.py", line 221, in raise_for_error
    err.raise_mysql_exception(self._data)
    │   │                     │    └ <member '_data' of 'MysqlPacket' objects>
    │   │                     └ <pymysql.protocol.MysqlPacket object at 0x7f3018459fd0>
    │   └ <function raise_mysql_exception at 0x7f31f358c670>
    └ <module 'pymysql.err' from '/home/chase/.local/lib/python3.8/site-packages/pymysql/err.py'>
  File "/home/chase/.local/lib/python3.8/site-packages/pymysql/err.py", line 143, in raise_mysql_exception
    raise errorclass(errno, errval)
          │          │      └ "Duplicate entry '180.201.163.246:6800' for key 'device.PRIMARY'"
          │          └ 1062
          └ <class 'pymysql.err.IntegrityError'>

sqlalchemy.exc.IntegrityError: (pymysql.err.IntegrityError) (1062, "Duplicate entry '180.201.163.246:6800' for key 'device.PRIMARY'")
[SQL: UPDATE device SET server_id=%(server_id)s, ip=%(ip)s, username=%(username)s, password=%(password)s, address=%(address)s, port=%(port)s, valid=%(valid)s WHERE device.ip = %(ip_1)s]
[parameters: {'server_id': '180.201.163.246:6800', 'ip': '180.201.163.246', 'username': 'chase', 'password': '99920876446588892592782562419101943027538644755877269205712650994357902186633116450476744940672475069734085907447293856311140080189569303058211600318 ... (10 characters truncated) ... 20485762614111294106888637987539963261331022553288458428956962492107643651156084491183625170771774757530863354679869701992270698332124805129617690741', 'address': '/home/users/CT/pycharmproject/spiders/', 'port': 6800, 'valid': 1, 'ip_1': '180.201.163.246'}]
(Background on this error at: https://sqlalche.me/e/14/gkpj)
2022-05-13 23:01:05.151 | ERROR    | base.db.mysql:update:390 - 【mysql更新数据出错】
Traceback (most recent call last):

  File "/home/chase/.local/lib/python3.8/site-packages/sqlalchemy/engine/base.py", line 1771, in _execute_context
    self.dialect.do_execute(
    │    │       └ <function DefaultDialect.do_execute at 0x7f31f38f75e0>
    │    └ <sqlalchemy.dialects.mysql.pymysql.MySQLDialect_pymysql object at 0x7f3103ffde20>
    └ <sqlalchemy.engine.base.Connection object at 0x7f30d8194670>
  File "/home/chase/.local/lib/python3.8/site-packages/sqlalchemy/engine/default.py", line 717, in do_execute
    cursor.execute(statement, parameters)
    │      │       │          └ {'server_id': '180.201.163.246:6800', 'ip': '180.201.163.246', 'username': 'chase', 'password': '8966316130557499964959567023...
    │      │       └ 'UPDATE device SET server_id=%(server_id)s, ip=%(ip)s, username=%(username)s, password=%(password)s, address=%(address)s, por...
    │      └ <function Cursor.execute at 0x7f31f354cdc0>
    └ <pymysql.cursors.Cursor object at 0x7f30782c6c70>
  File "/home/chase/.local/lib/python3.8/site-packages/pymysql/cursors.py", line 148, in execute
    result = self._query(query)
             │    │      └ "UPDATE device SET server_id='180.201.163.246:6800', ip='180.201.163.246', username='chase', password='8966316130557499964959...
             │    └ <function Cursor._query at 0x7f31f34d7280>
             └ <pymysql.cursors.Cursor object at 0x7f30782c6c70>
  File "/home/chase/.local/lib/python3.8/site-packages/pymysql/cursors.py", line 310, in _query
    conn.query(q)
    │    │     └ "UPDATE device SET server_id='180.201.163.246:6800', ip='180.201.163.246', username='chase', password='8966316130557499964959...
    │    └ <function Connection.query at 0x7f31f34e5670>
    └ <pymysql.connections.Connection object at 0x7f30585b4df0>
  File "/home/chase/.local/lib/python3.8/site-packages/pymysql/connections.py", line 548, in query
    self._affected_rows = self._read_query_result(unbuffered=unbuffered)
    │    │                │    │                             └ False
    │    │                │    └ <function Connection._read_query_result at 0x7f31f34e5ca0>
    │    │                └ <pymysql.connections.Connection object at 0x7f30585b4df0>
    │    └ 1
    └ <pymysql.connections.Connection object at 0x7f30585b4df0>
  File "/home/chase/.local/lib/python3.8/site-packages/pymysql/connections.py", line 775, in _read_query_result
    result.read()
    │      └ <function MySQLResult.read at 0x7f31f34e64c0>
    └ <pymysql.connections.MySQLResult object at 0x7f30982224c0>
  File "/home/chase/.local/lib/python3.8/site-packages/pymysql/connections.py", line 1156, in read
    first_packet = self.connection._read_packet()
                   │    └ None
                   └ <pymysql.connections.MySQLResult object at 0x7f30982224c0>
  File "/home/chase/.local/lib/python3.8/site-packages/pymysql/connections.py", line 725, in _read_packet
    packet.raise_for_error()
    │      └ <function MysqlPacket.raise_for_error at 0x7f31f34ddee0>
    └ <pymysql.protocol.MysqlPacket object at 0x7f301858dc40>
  File "/home/chase/.local/lib/python3.8/site-packages/pymysql/protocol.py", line 221, in raise_for_error
    err.raise_mysql_exception(self._data)
    │   │                     │    └ <member '_data' of 'MysqlPacket' objects>
    │   │                     └ <pymysql.protocol.MysqlPacket object at 0x7f301858dc40>
    │   └ <function raise_mysql_exception at 0x7f31f358c670>
    └ <module 'pymysql.err' from '/home/chase/.local/lib/python3.8/site-packages/pymysql/err.py'>
  File "/home/chase/.local/lib/python3.8/site-packages/pymysql/err.py", line 143, in raise_mysql_exception
    raise errorclass(errno, errval)
          │          │      └ "Duplicate entry '180.201.163.246:6800' for key 'device.PRIMARY'"
          │          └ 1062
          └ <class 'pymysql.err.IntegrityError'>

pymysql.err.IntegrityError: (1062, "Duplicate entry '180.201.163.246:6800' for key 'device.PRIMARY'")


The above exception was the direct cause of the following exception:


Traceback (most recent call last):

  File "/usr/lib/python3.8/threading.py", line 890, in _bootstrap
    self._bootstrap_inner()
    │    └ <function Thread._bootstrap_inner at 0x7f321bf29a60>
    └ <Thread(Thread-5496, started daemon 139838337140480)>
  File "/usr/lib/python3.8/threading.py", line 932, in _bootstrap_inner
    self.run()
    │    └ <function Thread.run at 0x7f321bf29790>
    └ <Thread(Thread-5496, started daemon 139838337140480)>
  File "/usr/lib/python3.8/threading.py", line 870, in run
    self._target(*self._args, **self._kwargs)
    │    │        │    │        │    └ {}
    │    │        │    │        └ <Thread(Thread-5496, started daemon 139838337140480)>
    │    │        │    └ ('ProjectManager.run_func_by_thread',)
    │    │        └ <Thread(Thread-5496, started daemon 139838337140480)>
    │    └ <bound method ProjectManager.get_request_from_keywords_hot of <monitor.projectManager.ProjectManager object at 0x7f31042e52e0>>
    └ <Thread(Thread-5496, started daemon 139838337140480)>

  File "/home/users/Scy/yuqing/spider/monitor/projectManager.py", line 799, in get_request_from_keywords_hot
    self.start_finished_spider_every_interval(project_names)
    │    │                                    └ ['default', 'test']
    │    └ <function ProjectManager.start_finished_spider_every_interval at 0x7f3104005280>
    └ <monitor.projectManager.ProjectManager object at 0x7f31042e52e0>

  File "/home/users/Scy/yuqing/spider/monitor/projectManager.py", line 784, in start_finished_spider_every_interval
    self[name].start_spider()
    │    └ 'default'
    └ <monitor.projectManager.ProjectManager object at 0x7f31042e52e0>

  File "/home/users/Scy/yuqing/spider/monitor/projectManager.py", line 366, in start_spider
    self.update_device_valid(device)
    │    │                   └ <monitor.deviceManager.DeviceC object at 0x7f3104029220>
    │    └ <function Project.update_device_valid at 0x7f3104003280>
    └ <monitor.projectManager.Project object at 0x7f3104029460>

  File "/home/users/Scy/yuqing/spider/monitor/projectManager.py", line 421, in update_device_valid
    self.database_manager.mysql.update(Device(**device.to_item()))
    │    │                │     │      │        │      └ <function DeviceC.to_item at 0x7f31f34ed310>
    │    │                │     │      │        └ <monitor.deviceManager.DeviceC object at 0x7f3104029220>
    │    │                │     │      └ <class 'base.db.mysql.Device'>
    │    │                │     └ <function Mysql.update at 0x7f31f35f4790>
    │    │                └ <base.db.mysql.Mysql object at 0x7f3103ffdfd0>
    │    └ <base.db.dbSlot.Slot object at 0x7f3103ffdf10>
    └ <monitor.projectManager.Project object at 0x7f3104029460>

> File "/home/users/Scy/yuqing/spider/base/db/mysql.py", line 375, in update
    row.update(new)
    │   │      └ {'server_id': '180.201.163.246:6800', 'ip': '180.201.163.246', 'username': 'chase', 'password': '8966316130557499964959567023...
    │   └ <function Query.update at 0x7f31f37333a0>
    └ <sqlalchemy.orm.query.Query object at 0x7f2fb8685c10>

  File "/home/chase/.local/lib/python3.8/site-packages/sqlalchemy/orm/query.py", line 3221, in update
    result = self.session.execute(
             │    │       └ <function Session.execute at 0x7f31f370faf0>
             │    └ <sqlalchemy.orm.session.Session object at 0x7f3038280b80>
             └ <sqlalchemy.orm.query.Query object at 0x7f2fb8685c10>
  File "/home/chase/.local/lib/python3.8/site-packages/sqlalchemy/orm/session.py", line 1689, in execute
    result = conn._execute_20(statement, params or {}, execution_options)
             │    │           │          │             └ immutabledict({'synchronize_session': 'evaluate', '_sa_orm_update_options': default_update_options(_matched_objects=[], _reso...
             │    │           │          └ immutabledict({})
             │    │           └ <sqlalchemy.sql.annotation.AnnotatedUpdate object at 0x7f30782c6b80>
             │    └ <function Connection._execute_20 at 0x7f31f39bc790>
             └ <sqlalchemy.engine.base.Connection object at 0x7f30d8194670>
  File "/home/chase/.local/lib/python3.8/site-packages/sqlalchemy/engine/base.py", line 1583, in _execute_20
    return meth(self, args_10style, kwargs_10style, execution_options)
           │    │     │             │               └ immutabledict({'synchronize_session': 'evaluate', '_sa_orm_update_options': default_update_options(_matched_objects=[], _reso...
           │    │     │             └ immutabledict({})
           │    │     └ ({},)
           │    └ <sqlalchemy.engine.base.Connection object at 0x7f30d8194670>
           └ <bound method ClauseElement._execute_on_connection of <sqlalchemy.sql.annotation.AnnotatedUpdate object at 0x7f30782c6b80>>
  File "/home/chase/.local/lib/python3.8/site-packages/sqlalchemy/sql/elements.py", line 323, in _execute_on_connection
    return connection._execute_clauseelement(
           │          └ <function Connection._execute_clauseelement at 0x7f31f39bc5e0>
           └ <sqlalchemy.engine.base.Connection object at 0x7f30d8194670>
  File "/home/chase/.local/lib/python3.8/site-packages/sqlalchemy/engine/base.py", line 1452, in _execute_clauseelement
    ret = self._execute_context(
          │    └ <function Connection._execute_context at 0x7f31f39bc8b0>
          └ <sqlalchemy.engine.base.Connection object at 0x7f30d8194670>
  File "/home/chase/.local/lib/python3.8/site-packages/sqlalchemy/engine/base.py", line 1814, in _execute_context
    self._handle_dbapi_exception(
    │    └ <function Connection._handle_dbapi_exception at 0x7f31f39bca60>
    └ <sqlalchemy.engine.base.Connection object at 0x7f30d8194670>
  File "/home/chase/.local/lib/python3.8/site-packages/sqlalchemy/engine/base.py", line 1995, in _handle_dbapi_exception
    util.raise_(
    │    └ <function raise_ at 0x7f31f3d7ea60>
    └ <module 'sqlalchemy.util' from '/home/chase/.local/lib/python3.8/site-packages/sqlalchemy/util/__init__.py'>
  File "/home/chase/.local/lib/python3.8/site-packages/sqlalchemy/util/compat.py", line 207, in raise_
    raise exception
  File "/home/chase/.local/lib/python3.8/site-packages/sqlalchemy/engine/base.py", line 1771, in _execute_context
    self.dialect.do_execute(
    │    │       └ <function DefaultDialect.do_execute at 0x7f31f38f75e0>
    │    └ <sqlalchemy.dialects.mysql.pymysql.MySQLDialect_pymysql object at 0x7f3103ffde20>
    └ <sqlalchemy.engine.base.Connection object at 0x7f30d8194670>
  File "/home/chase/.local/lib/python3.8/site-packages/sqlalchemy/engine/default.py", line 717, in do_execute
    cursor.execute(statement, parameters)
    │      │       │          └ {'server_id': '180.201.163.246:6800', 'ip': '180.201.163.246', 'username': 'chase', 'password': '8966316130557499964959567023...
    │      │       └ 'UPDATE device SET server_id=%(server_id)s, ip=%(ip)s, username=%(username)s, password=%(password)s, address=%(address)s, por...
    │      └ <function Cursor.execute at 0x7f31f354cdc0>
    └ <pymysql.cursors.Cursor object at 0x7f30782c6c70>
  File "/home/chase/.local/lib/python3.8/site-packages/pymysql/cursors.py", line 148, in execute
    result = self._query(query)
             │    │      └ "UPDATE device SET server_id='180.201.163.246:6800', ip='180.201.163.246', username='chase', password='8966316130557499964959...
             │    └ <function Cursor._query at 0x7f31f34d7280>
             └ <pymysql.cursors.Cursor object at 0x7f30782c6c70>
  File "/home/chase/.local/lib/python3.8/site-packages/pymysql/cursors.py", line 310, in _query
    conn.query(q)
    │    │     └ "UPDATE device SET server_id='180.201.163.246:6800', ip='180.201.163.246', username='chase', password='8966316130557499964959...
    │    └ <function Connection.query at 0x7f31f34e5670>
    └ <pymysql.connections.Connection object at 0x7f30585b4df0>
  File "/home/chase/.local/lib/python3.8/site-packages/pymysql/connections.py", line 548, in query
    self._affected_rows = self._read_query_result(unbuffered=unbuffered)
    │    │                │    │                             └ False
    │    │                │    └ <function Connection._read_query_result at 0x7f31f34e5ca0>
    │    │                └ <pymysql.connections.Connection object at 0x7f30585b4df0>
    │    └ 1
    └ <pymysql.connections.Connection object at 0x7f30585b4df0>
  File "/home/chase/.local/lib/python3.8/site-packages/pymysql/connections.py", line 775, in _read_query_result
    result.read()
    │      └ <function MySQLResult.read at 0x7f31f34e64c0>
    └ <pymysql.connections.MySQLResult object at 0x7f30982224c0>
  File "/home/chase/.local/lib/python3.8/site-packages/pymysql/connections.py", line 1156, in read
    first_packet = self.connection._read_packet()
                   │    └ None
                   └ <pymysql.connections.MySQLResult object at 0x7f30982224c0>
  File "/home/chase/.local/lib/python3.8/site-packages/pymysql/connections.py", line 725, in _read_packet
    packet.raise_for_error()
    │      └ <function MysqlPacket.raise_for_error at 0x7f31f34ddee0>
    └ <pymysql.protocol.MysqlPacket object at 0x7f301858dc40>
  File "/home/chase/.local/lib/python3.8/site-packages/pymysql/protocol.py", line 221, in raise_for_error
    err.raise_mysql_exception(self._data)
    │   │                     │    └ <member '_data' of 'MysqlPacket' objects>
    │   │                     └ <pymysql.protocol.MysqlPacket object at 0x7f301858dc40>
    │   └ <function raise_mysql_exception at 0x7f31f358c670>
    └ <module 'pymysql.err' from '/home/chase/.local/lib/python3.8/site-packages/pymysql/err.py'>
  File "/home/chase/.local/lib/python3.8/site-packages/pymysql/err.py", line 143, in raise_mysql_exception
    raise errorclass(errno, errval)
          │          │      └ "Duplicate entry '180.201.163.246:6800' for key 'device.PRIMARY'"
          │          └ 1062
          └ <class 'pymysql.err.IntegrityError'>

sqlalchemy.exc.IntegrityError: (pymysql.err.IntegrityError) (1062, "Duplicate entry '180.201.163.246:6800' for key 'device.PRIMARY'")
[SQL: UPDATE device SET server_id=%(server_id)s, ip=%(ip)s, username=%(username)s, password=%(password)s, address=%(address)s, port=%(port)s, valid=%(valid)s WHERE device.ip = %(ip_1)s]
[parameters: {'server_id': '180.201.163.246:6800', 'ip': '180.201.163.246', 'username': 'chase', 'password': '89663161305574999649595670231598265876677978696485980141392368704827413938781153111202477399093238532749333828797244296259656972274131021847359051268 ... (10 characters truncated) ... 66164522725641854279229478316970807286738084857271438464601959629304609291029446098912975229500232850158177503684340273130786846503303852775116202189', 'address': '/home/users/CT/pycharmproject/spiders/', 'port': 6800, 'valid': 1, 'ip_1': '180.201.163.246'}]
(Background on this error at: https://sqlalche.me/e/14/gkpj)
2022-05-13 23:01:23.487 | ERROR    | base.db.mysql:update:390 - 【mysql更新数据出错】
Traceback (most recent call last):

  File "/home/chase/.local/lib/python3.8/site-packages/sqlalchemy/engine/base.py", line 1771, in _execute_context
    self.dialect.do_execute(
    │    │       └ <function DefaultDialect.do_execute at 0x7f31f38f75e0>
    │    └ <sqlalchemy.dialects.mysql.pymysql.MySQLDialect_pymysql object at 0x7f3103ffde20>
    └ <sqlalchemy.engine.base.Connection object at 0x7f2fb85f0190>
  File "/home/chase/.local/lib/python3.8/site-packages/sqlalchemy/engine/default.py", line 717, in do_execute
    cursor.execute(statement, parameters)
    │      │       │          └ {'server_id': '180.201.163.246:6800', 'ip': '180.201.163.246', 'username': 'chase', 'password': '3439712027624520570000447583...
    │      │       └ 'UPDATE device SET server_id=%(server_id)s, ip=%(ip)s, username=%(username)s, password=%(password)s, address=%(address)s, por...
    │      └ <function Cursor.execute at 0x7f31f354cdc0>
    └ <pymysql.cursors.Cursor object at 0x7f3018603dc0>
  File "/home/chase/.local/lib/python3.8/site-packages/pymysql/cursors.py", line 148, in execute
    result = self._query(query)
             │    │      └ "UPDATE device SET server_id='180.201.163.246:6800', ip='180.201.163.246', username='chase', password='3439712027624520570000...
             │    └ <function Cursor._query at 0x7f31f34d7280>
             └ <pymysql.cursors.Cursor object at 0x7f3018603dc0>
  File "/home/chase/.local/lib/python3.8/site-packages/pymysql/cursors.py", line 310, in _query
    conn.query(q)
    │    │     └ "UPDATE device SET server_id='180.201.163.246:6800', ip='180.201.163.246', username='chase', password='3439712027624520570000...
    │    └ <function Connection.query at 0x7f31f34e5670>
    └ <pymysql.connections.Connection object at 0x7f30980ca880>
  File "/home/chase/.local/lib/python3.8/site-packages/pymysql/connections.py", line 548, in query
    self._affected_rows = self._read_query_result(unbuffered=unbuffered)
    │    │                │    │                             └ False
    │    │                │    └ <function Connection._read_query_result at 0x7f31f34e5ca0>
    │    │                └ <pymysql.connections.Connection object at 0x7f30980ca880>
    │    └ 1
    └ <pymysql.connections.Connection object at 0x7f30980ca880>
  File "/home/chase/.local/lib/python3.8/site-packages/pymysql/connections.py", line 775, in _read_query_result
    result.read()
    │      └ <function MySQLResult.read at 0x7f31f34e64c0>
    └ <pymysql.connections.MySQLResult object at 0x7f3038165370>
  File "/home/chase/.local/lib/python3.8/site-packages/pymysql/connections.py", line 1156, in read
    first_packet = self.connection._read_packet()
                   │    └ None
                   └ <pymysql.connections.MySQLResult object at 0x7f3038165370>
  File "/home/chase/.local/lib/python3.8/site-packages/pymysql/connections.py", line 725, in _read_packet
    packet.raise_for_error()
    │      └ <function MysqlPacket.raise_for_error at 0x7f31f34ddee0>
    └ <pymysql.protocol.MysqlPacket object at 0x7f2ff859d190>
  File "/home/chase/.local/lib/python3.8/site-packages/pymysql/protocol.py", line 221, in raise_for_error
    err.raise_mysql_exception(self._data)
    │   │                     │    └ <member '_data' of 'MysqlPacket' objects>
    │   │                     └ <pymysql.protocol.MysqlPacket object at 0x7f2ff859d190>
    │   └ <function raise_mysql_exception at 0x7f31f358c670>
    └ <module 'pymysql.err' from '/home/chase/.local/lib/python3.8/site-packages/pymysql/err.py'>
  File "/home/chase/.local/lib/python3.8/site-packages/pymysql/err.py", line 143, in raise_mysql_exception
    raise errorclass(errno, errval)
          │          │      └ "Duplicate entry '180.201.163.246:6800' for key 'device.PRIMARY'"
          │          └ 1062
          └ <class 'pymysql.err.IntegrityError'>

pymysql.err.IntegrityError: (1062, "Duplicate entry '180.201.163.246:6800' for key 'device.PRIMARY'")


The above exception was the direct cause of the following exception:


Traceback (most recent call last):

  File "/usr/lib/python3.8/threading.py", line 890, in _bootstrap
    self._bootstrap_inner()
    │    └ <function Thread._bootstrap_inner at 0x7f321bf29a60>
    └ <Thread(Thread-5500, started daemon 139838244820736)>
  File "/usr/lib/python3.8/threading.py", line 932, in _bootstrap_inner
    self.run()
    │    └ <function Thread.run at 0x7f321bf29790>
    └ <Thread(Thread-5500, started daemon 139838244820736)>
  File "/usr/lib/python3.8/threading.py", line 870, in run
    self._target(*self._args, **self._kwargs)
    │    │        │    │        │    └ {}
    │    │        │    │        └ <Thread(Thread-5500, started daemon 139838244820736)>
    │    │        │    └ ('ProjectManager.run_func_by_thread',)
    │    │        └ <Thread(Thread-5500, started daemon 139838244820736)>
    │    └ <bound method ProjectManager.get_request_from_keywords_hot of <monitor.projectManager.ProjectManager object at 0x7f31042e52e0>>
    └ <Thread(Thread-5500, started daemon 139838244820736)>

  File "/home/users/Scy/yuqing/spider/monitor/projectManager.py", line 799, in get_request_from_keywords_hot
    self.start_finished_spider_every_interval(project_names)
    │    │                                    └ ['default', 'test']
    │    └ <function ProjectManager.start_finished_spider_every_interval at 0x7f3104005280>
    └ <monitor.projectManager.ProjectManager object at 0x7f31042e52e0>

  File "/home/users/Scy/yuqing/spider/monitor/projectManager.py", line 784, in start_finished_spider_every_interval
    self[name].start_spider()
    │    └ 'default'
    └ <monitor.projectManager.ProjectManager object at 0x7f31042e52e0>

  File "/home/users/Scy/yuqing/spider/monitor/projectManager.py", line 366, in start_spider
    self.update_device_valid(device)
    │    │                   └ <monitor.deviceManager.DeviceC object at 0x7f3104029220>
    │    └ <function Project.update_device_valid at 0x7f3104003280>
    └ <monitor.projectManager.Project object at 0x7f3104029460>

  File "/home/users/Scy/yuqing/spider/monitor/projectManager.py", line 421, in update_device_valid
    self.database_manager.mysql.update(Device(**device.to_item()))
    │    │                │     │      │        │      └ <function DeviceC.to_item at 0x7f31f34ed310>
    │    │                │     │      │        └ <monitor.deviceManager.DeviceC object at 0x7f3104029220>
    │    │                │     │      └ <class 'base.db.mysql.Device'>
    │    │                │     └ <function Mysql.update at 0x7f31f35f4790>
    │    │                └ <base.db.mysql.Mysql object at 0x7f3103ffdfd0>
    │    └ <base.db.dbSlot.Slot object at 0x7f3103ffdf10>
    └ <monitor.projectManager.Project object at 0x7f3104029460>

> File "/home/users/Scy/yuqing/spider/base/db/mysql.py", line 375, in update
    row.update(new)
    │   │      └ {'server_id': '180.201.163.246:6800', 'ip': '180.201.163.246', 'username': 'chase', 'password': '3439712027624520570000447583...
    │   └ <function Query.update at 0x7f31f37333a0>
    └ <sqlalchemy.orm.query.Query object at 0x7f3018671730>

  File "/home/chase/.local/lib/python3.8/site-packages/sqlalchemy/orm/query.py", line 3221, in update
    result = self.session.execute(
             │    │       └ <function Session.execute at 0x7f31f370faf0>
             │    └ <sqlalchemy.orm.session.Session object at 0x7f31f935dd00>
             └ <sqlalchemy.orm.query.Query object at 0x7f3018671730>
  File "/home/chase/.local/lib/python3.8/site-packages/sqlalchemy/orm/session.py", line 1689, in execute
    result = conn._execute_20(statement, params or {}, execution_options)
             │    │           │          │             └ immutabledict({'synchronize_session': 'evaluate', '_sa_orm_update_options': default_update_options(_matched_objects=[], _reso...
             │    │           │          └ immutabledict({})
             │    │           └ <sqlalchemy.sql.annotation.AnnotatedUpdate object at 0x7f30b8095400>
             │    └ <function Connection._execute_20 at 0x7f31f39bc790>
             └ <sqlalchemy.engine.base.Connection object at 0x7f2fb85f0190>
  File "/home/chase/.local/lib/python3.8/site-packages/sqlalchemy/engine/base.py", line 1583, in _execute_20
    return meth(self, args_10style, kwargs_10style, execution_options)
           │    │     │             │               └ immutabledict({'synchronize_session': 'evaluate', '_sa_orm_update_options': default_update_options(_matched_objects=[], _reso...
           │    │     │             └ immutabledict({})
           │    │     └ ({},)
           │    └ <sqlalchemy.engine.base.Connection object at 0x7f2fb85f0190>
           └ <bound method ClauseElement._execute_on_connection of <sqlalchemy.sql.annotation.AnnotatedUpdate object at 0x7f30b8095400>>
  File "/home/chase/.local/lib/python3.8/site-packages/sqlalchemy/sql/elements.py", line 323, in _execute_on_connection
    return connection._execute_clauseelement(
           │          └ <function Connection._execute_clauseelement at 0x7f31f39bc5e0>
           └ <sqlalchemy.engine.base.Connection object at 0x7f2fb85f0190>
  File "/home/chase/.local/lib/python3.8/site-packages/sqlalchemy/engine/base.py", line 1452, in _execute_clauseelement
    ret = self._execute_context(
          │    └ <function Connection._execute_context at 0x7f31f39bc8b0>
          └ <sqlalchemy.engine.base.Connection object at 0x7f2fb85f0190>
  File "/home/chase/.local/lib/python3.8/site-packages/sqlalchemy/engine/base.py", line 1814, in _execute_context
    self._handle_dbapi_exception(
    │    └ <function Connection._handle_dbapi_exception at 0x7f31f39bca60>
    └ <sqlalchemy.engine.base.Connection object at 0x7f2fb85f0190>
  File "/home/chase/.local/lib/python3.8/site-packages/sqlalchemy/engine/base.py", line 1995, in _handle_dbapi_exception
    util.raise_(
    │    └ <function raise_ at 0x7f31f3d7ea60>
    └ <module 'sqlalchemy.util' from '/home/chase/.local/lib/python3.8/site-packages/sqlalchemy/util/__init__.py'>
  File "/home/chase/.local/lib/python3.8/site-packages/sqlalchemy/util/compat.py", line 207, in raise_
    raise exception
  File "/home/chase/.local/lib/python3.8/site-packages/sqlalchemy/engine/base.py", line 1771, in _execute_context
    self.dialect.do_execute(
    │    │       └ <function DefaultDialect.do_execute at 0x7f31f38f75e0>
    │    └ <sqlalchemy.dialects.mysql.pymysql.MySQLDialect_pymysql object at 0x7f3103ffde20>
    └ <sqlalchemy.engine.base.Connection object at 0x7f2fb85f0190>
  File "/home/chase/.local/lib/python3.8/site-packages/sqlalchemy/engine/default.py", line 717, in do_execute
    cursor.execute(statement, parameters)
    │      │       │          └ {'server_id': '180.201.163.246:6800', 'ip': '180.201.163.246', 'username': 'chase', 'password': '3439712027624520570000447583...
    │      │       └ 'UPDATE device SET server_id=%(server_id)s, ip=%(ip)s, username=%(username)s, password=%(password)s, address=%(address)s, por...
    │      └ <function Cursor.execute at 0x7f31f354cdc0>
    └ <pymysql.cursors.Cursor object at 0x7f3018603dc0>
  File "/home/chase/.local/lib/python3.8/site-packages/pymysql/cursors.py", line 148, in execute
    result = self._query(query)
             │    │      └ "UPDATE device SET server_id='180.201.163.246:6800', ip='180.201.163.246', username='chase', password='3439712027624520570000...
             │    └ <function Cursor._query at 0x7f31f34d7280>
             └ <pymysql.cursors.Cursor object at 0x7f3018603dc0>
  File "/home/chase/.local/lib/python3.8/site-packages/pymysql/cursors.py", line 310, in _query
    conn.query(q)
    │    │     └ "UPDATE device SET server_id='180.201.163.246:6800', ip='180.201.163.246', username='chase', password='3439712027624520570000...
    │    └ <function Connection.query at 0x7f31f34e5670>
    └ <pymysql.connections.Connection object at 0x7f30980ca880>
  File "/home/chase/.local/lib/python3.8/site-packages/pymysql/connections.py", line 548, in query
    self._affected_rows = self._read_query_result(unbuffered=unbuffered)
    │    │                │    │                             └ False
    │    │                │    └ <function Connection._read_query_result at 0x7f31f34e5ca0>
    │    │                └ <pymysql.connections.Connection object at 0x7f30980ca880>
    │    └ 1
    └ <pymysql.connections.Connection object at 0x7f30980ca880>
  File "/home/chase/.local/lib/python3.8/site-packages/pymysql/connections.py", line 775, in _read_query_result
    result.read()
    │      └ <function MySQLResult.read at 0x7f31f34e64c0>
    └ <pymysql.connections.MySQLResult object at 0x7f3038165370>
  File "/home/chase/.local/lib/python3.8/site-packages/pymysql/connections.py", line 1156, in read
    first_packet = self.connection._read_packet()
                   │    └ None
                   └ <pymysql.connections.MySQLResult object at 0x7f3038165370>
  File "/home/chase/.local/lib/python3.8/site-packages/pymysql/connections.py", line 725, in _read_packet
    packet.raise_for_error()
    │      └ <function MysqlPacket.raise_for_error at 0x7f31f34ddee0>
    └ <pymysql.protocol.MysqlPacket object at 0x7f2ff859d190>
  File "/home/chase/.local/lib/python3.8/site-packages/pymysql/protocol.py", line 221, in raise_for_error
    err.raise_mysql_exception(self._data)
    │   │                     │    └ <member '_data' of 'MysqlPacket' objects>
    │   │                     └ <pymysql.protocol.MysqlPacket object at 0x7f2ff859d190>
    │   └ <function raise_mysql_exception at 0x7f31f358c670>
    └ <module 'pymysql.err' from '/home/chase/.local/lib/python3.8/site-packages/pymysql/err.py'>
  File "/home/chase/.local/lib/python3.8/site-packages/pymysql/err.py", line 143, in raise_mysql_exception
    raise errorclass(errno, errval)
          │          │      └ "Duplicate entry '180.201.163.246:6800' for key 'device.PRIMARY'"
          │          └ 1062
          └ <class 'pymysql.err.IntegrityError'>

sqlalchemy.exc.IntegrityError: (pymysql.err.IntegrityError) (1062, "Duplicate entry '180.201.163.246:6800' for key 'device.PRIMARY'")
[SQL: UPDATE device SET server_id=%(server_id)s, ip=%(ip)s, username=%(username)s, password=%(password)s, address=%(address)s, port=%(port)s, valid=%(valid)s WHERE device.ip = %(ip_1)s]
[parameters: {'server_id': '180.201.163.246:6800', 'ip': '180.201.163.246', 'username': 'chase', 'password': '34397120276245205700004475833365023594596587924427123641646018318948723353912079794486550793845634223800137779740049751515863400733019366478646886168 ... (10 characters truncated) ... 47943333003951459483641373798029139080585594313996638372870354481713301447212898508087173264491371314474379155520621346731808820580658079560716012370', 'address': '/home/users/CT/pycharmproject/spiders/', 'port': 6800, 'valid': 1, 'ip_1': '180.201.163.246'}]
(Background on this error at: https://sqlalche.me/e/14/gkpj)
2022-05-13 23:01:41.305 | ERROR    | base.db.mysql:update:390 - 【mysql更新数据出错】
Traceback (most recent call last):

  File "/home/chase/.local/lib/python3.8/site-packages/sqlalchemy/engine/base.py", line 1771, in _execute_context
    self.dialect.do_execute(
    │    │       └ <function DefaultDialect.do_execute at 0x7f31f38f75e0>
    │    └ <sqlalchemy.dialects.mysql.pymysql.MySQLDialect_pymysql object at 0x7f3103ffde20>
    └ <sqlalchemy.engine.base.Connection object at 0x7f3101c41400>
  File "/home/chase/.local/lib/python3.8/site-packages/sqlalchemy/engine/default.py", line 717, in do_execute
    cursor.execute(statement, parameters)
    │      │       │          └ {'server_id': '180.201.163.246:6800', 'ip': '180.201.163.246', 'username': 'chase', 'password': '5667401747125871644534810072...
    │      │       └ 'UPDATE device SET server_id=%(server_id)s, ip=%(ip)s, username=%(username)s, password=%(password)s, address=%(address)s, por...
    │      └ <function Cursor.execute at 0x7f31f354cdc0>
    └ <pymysql.cursors.Cursor object at 0x7f30d81225b0>
  File "/home/chase/.local/lib/python3.8/site-packages/pymysql/cursors.py", line 148, in execute
    result = self._query(query)
             │    │      └ "UPDATE device SET server_id='180.201.163.246:6800', ip='180.201.163.246', username='chase', password='5667401747125871644534...
             │    └ <function Cursor._query at 0x7f31f34d7280>
             └ <pymysql.cursors.Cursor object at 0x7f30d81225b0>
  File "/home/chase/.local/lib/python3.8/site-packages/pymysql/cursors.py", line 310, in _query
    conn.query(q)
    │    │     └ "UPDATE device SET server_id='180.201.163.246:6800', ip='180.201.163.246', username='chase', password='5667401747125871644534...
    │    └ <function Connection.query at 0x7f31f34e5670>
    └ <pymysql.connections.Connection object at 0x7f30583ec5b0>
  File "/home/chase/.local/lib/python3.8/site-packages/pymysql/connections.py", line 548, in query
    self._affected_rows = self._read_query_result(unbuffered=unbuffered)
    │    │                │    │                             └ False
    │    │                │    └ <function Connection._read_query_result at 0x7f31f34e5ca0>
    │    │                └ <pymysql.connections.Connection object at 0x7f30583ec5b0>
    │    └ 1
    └ <pymysql.connections.Connection object at 0x7f30583ec5b0>
  File "/home/chase/.local/lib/python3.8/site-packages/pymysql/connections.py", line 775, in _read_query_result
    result.read()
    │      └ <function MySQLResult.read at 0x7f31f34e64c0>
    └ <pymysql.connections.MySQLResult object at 0x7f30d82ced30>
  File "/home/chase/.local/lib/python3.8/site-packages/pymysql/connections.py", line 1156, in read
    first_packet = self.connection._read_packet()
                   │    └ None
                   └ <pymysql.connections.MySQLResult object at 0x7f30d82ced30>
  File "/home/chase/.local/lib/python3.8/site-packages/pymysql/connections.py", line 725, in _read_packet
    packet.raise_for_error()
    │      └ <function MysqlPacket.raise_for_error at 0x7f31f34ddee0>
    └ <pymysql.protocol.MysqlPacket object at 0x7f3102431970>
  File "/home/chase/.local/lib/python3.8/site-packages/pymysql/protocol.py", line 221, in raise_for_error
    err.raise_mysql_exception(self._data)
    │   │                     │    └ <member '_data' of 'MysqlPacket' objects>
    │   │                     └ <pymysql.protocol.MysqlPacket object at 0x7f3102431970>
    │   └ <function raise_mysql_exception at 0x7f31f358c670>
    └ <module 'pymysql.err' from '/home/chase/.local/lib/python3.8/site-packages/pymysql/err.py'>
  File "/home/chase/.local/lib/python3.8/site-packages/pymysql/err.py", line 143, in raise_mysql_exception
    raise errorclass(errno, errval)
          │          │      └ "Duplicate entry '180.201.163.246:6800' for key 'device.PRIMARY'"
          │          └ 1062
          └ <class 'pymysql.err.IntegrityError'>

pymysql.err.IntegrityError: (1062, "Duplicate entry '180.201.163.246:6800' for key 'device.PRIMARY'")


The above exception was the direct cause of the following exception:


Traceback (most recent call last):

  File "/usr/lib/python3.8/threading.py", line 890, in _bootstrap
    self._bootstrap_inner()
    │    └ <function Thread._bootstrap_inner at 0x7f321bf29a60>
    └ <Thread(Thread-5505, started daemon 139838236428032)>
  File "/usr/lib/python3.8/threading.py", line 932, in _bootstrap_inner
    self.run()
    │    └ <function Thread.run at 0x7f321bf29790>
    └ <Thread(Thread-5505, started daemon 139838236428032)>
  File "/usr/lib/python3.8/threading.py", line 870, in run
    self._target(*self._args, **self._kwargs)
    │    │        │    │        │    └ {}
    │    │        │    │        └ <Thread(Thread-5505, started daemon 139838236428032)>
    │    │        │    └ ('ProjectManager.run_func_by_thread',)
    │    │        └ <Thread(Thread-5505, started daemon 139838236428032)>
    │    └ <bound method ProjectManager.get_request_from_keywords_hot of <monitor.projectManager.ProjectManager object at 0x7f31042e52e0>>
    └ <Thread(Thread-5505, started daemon 139838236428032)>

  File "/home/users/Scy/yuqing/spider/monitor/projectManager.py", line 799, in get_request_from_keywords_hot
    self.start_finished_spider_every_interval(project_names)
    │    │                                    └ ['default', 'test']
    │    └ <function ProjectManager.start_finished_spider_every_interval at 0x7f3104005280>
    └ <monitor.projectManager.ProjectManager object at 0x7f31042e52e0>

  File "/home/users/Scy/yuqing/spider/monitor/projectManager.py", line 784, in start_finished_spider_every_interval
    self[name].start_spider()
    │    └ 'default'
    └ <monitor.projectManager.ProjectManager object at 0x7f31042e52e0>

  File "/home/users/Scy/yuqing/spider/monitor/projectManager.py", line 366, in start_spider
    self.update_device_valid(device)
    │    │                   └ <monitor.deviceManager.DeviceC object at 0x7f3104029220>
    │    └ <function Project.update_device_valid at 0x7f3104003280>
    └ <monitor.projectManager.Project object at 0x7f3104029460>

  File "/home/users/Scy/yuqing/spider/monitor/projectManager.py", line 421, in update_device_valid
    self.database_manager.mysql.update(Device(**device.to_item()))
    │    │                │     │      │        │      └ <function DeviceC.to_item at 0x7f31f34ed310>
    │    │                │     │      │        └ <monitor.deviceManager.DeviceC object at 0x7f3104029220>
    │    │                │     │      └ <class 'base.db.mysql.Device'>
    │    │                │     └ <function Mysql.update at 0x7f31f35f4790>
    │    │                └ <base.db.mysql.Mysql object at 0x7f3103ffdfd0>
    │    └ <base.db.dbSlot.Slot object at 0x7f3103ffdf10>
    └ <monitor.projectManager.Project object at 0x7f3104029460>

> File "/home/users/Scy/yuqing/spider/base/db/mysql.py", line 375, in update
    row.update(new)
    │   │      └ {'server_id': '180.201.163.246:6800', 'ip': '180.201.163.246', 'username': 'chase', 'password': '5667401747125871644534810072...
    │   └ <function Query.update at 0x7f31f37333a0>
    └ <sqlalchemy.orm.query.Query object at 0x7f3098391f70>

  File "/home/chase/.local/lib/python3.8/site-packages/sqlalchemy/orm/query.py", line 3221, in update
    result = self.session.execute(
             │    │       └ <function Session.execute at 0x7f31f370faf0>
             │    └ <sqlalchemy.orm.session.Session object at 0x7f30585964c0>
             └ <sqlalchemy.orm.query.Query object at 0x7f3098391f70>
  File "/home/chase/.local/lib/python3.8/site-packages/sqlalchemy/orm/session.py", line 1689, in execute
    result = conn._execute_20(statement, params or {}, execution_options)
             │    │           │          │             └ immutabledict({'synchronize_session': 'evaluate', '_sa_orm_update_options': default_update_options(_matched_objects=[], _reso...
             │    │           │          └ immutabledict({})
             │    │           └ <sqlalchemy.sql.annotation.AnnotatedUpdate object at 0x7f30d8122880>
             │    └ <function Connection._execute_20 at 0x7f31f39bc790>
             └ <sqlalchemy.engine.base.Connection object at 0x7f3101c41400>
  File "/home/chase/.local/lib/python3.8/site-packages/sqlalchemy/engine/base.py", line 1583, in _execute_20
    return meth(self, args_10style, kwargs_10style, execution_options)
           │    │     │             │               └ immutabledict({'synchronize_session': 'evaluate', '_sa_orm_update_options': default_update_options(_matched_objects=[], _reso...
           │    │     │             └ immutabledict({})
           │    │     └ ({},)
           │    └ <sqlalchemy.engine.base.Connection object at 0x7f3101c41400>
           └ <bound method ClauseElement._execute_on_connection of <sqlalchemy.sql.annotation.AnnotatedUpdate object at 0x7f30d8122880>>
  File "/home/chase/.local/lib/python3.8/site-packages/sqlalchemy/sql/elements.py", line 323, in _execute_on_connection
    return connection._execute_clauseelement(
           │          └ <function Connection._execute_clauseelement at 0x7f31f39bc5e0>
           └ <sqlalchemy.engine.base.Connection object at 0x7f3101c41400>
  File "/home/chase/.local/lib/python3.8/site-packages/sqlalchemy/engine/base.py", line 1452, in _execute_clauseelement
    ret = self._execute_context(
          │    └ <function Connection._execute_context at 0x7f31f39bc8b0>
          └ <sqlalchemy.engine.base.Connection object at 0x7f3101c41400>
  File "/home/chase/.local/lib/python3.8/site-packages/sqlalchemy/engine/base.py", line 1814, in _execute_context
    self._handle_dbapi_exception(
    │    └ <function Connection._handle_dbapi_exception at 0x7f31f39bca60>
    └ <sqlalchemy.engine.base.Connection object at 0x7f3101c41400>
  File "/home/chase/.local/lib/python3.8/site-packages/sqlalchemy/engine/base.py", line 1995, in _handle_dbapi_exception
    util.raise_(
    │    └ <function raise_ at 0x7f31f3d7ea60>
    └ <module 'sqlalchemy.util' from '/home/chase/.local/lib/python3.8/site-packages/sqlalchemy/util/__init__.py'>
  File "/home/chase/.local/lib/python3.8/site-packages/sqlalchemy/util/compat.py", line 207, in raise_
    raise exception
  File "/home/chase/.local/lib/python3.8/site-packages/sqlalchemy/engine/base.py", line 1771, in _execute_context
    self.dialect.do_execute(
    │    │       └ <function DefaultDialect.do_execute at 0x7f31f38f75e0>
    │    └ <sqlalchemy.dialects.mysql.pymysql.MySQLDialect_pymysql object at 0x7f3103ffde20>
    └ <sqlalchemy.engine.base.Connection object at 0x7f3101c41400>
  File "/home/chase/.local/lib/python3.8/site-packages/sqlalchemy/engine/default.py", line 717, in do_execute
    cursor.execute(statement, parameters)
    │      │       │          └ {'server_id': '180.201.163.246:6800', 'ip': '180.201.163.246', 'username': 'chase', 'password': '5667401747125871644534810072...
    │      │       └ 'UPDATE device SET server_id=%(server_id)s, ip=%(ip)s, username=%(username)s, password=%(password)s, address=%(address)s, por...
    │      └ <function Cursor.execute at 0x7f31f354cdc0>
    └ <pymysql.cursors.Cursor object at 0x7f30d81225b0>
  File "/home/chase/.local/lib/python3.8/site-packages/pymysql/cursors.py", line 148, in execute
    result = self._query(query)
             │    │      └ "UPDATE device SET server_id='180.201.163.246:6800', ip='180.201.163.246', username='chase', password='5667401747125871644534...
             │    └ <function Cursor._query at 0x7f31f34d7280>
             └ <pymysql.cursors.Cursor object at 0x7f30d81225b0>
  File "/home/chase/.local/lib/python3.8/site-packages/pymysql/cursors.py", line 310, in _query
    conn.query(q)
    │    │     └ "UPDATE device SET server_id='180.201.163.246:6800', ip='180.201.163.246', username='chase', password='5667401747125871644534...
    │    └ <function Connection.query at 0x7f31f34e5670>
    └ <pymysql.connections.Connection object at 0x7f30583ec5b0>
  File "/home/chase/.local/lib/python3.8/site-packages/pymysql/connections.py", line 548, in query
    self._affected_rows = self._read_query_result(unbuffered=unbuffered)
    │    │                │    │                             └ False
    │    │                │    └ <function Connection._read_query_result at 0x7f31f34e5ca0>
    │    │                └ <pymysql.connections.Connection object at 0x7f30583ec5b0>
    │    └ 1
    └ <pymysql.connections.Connection object at 0x7f30583ec5b0>
  File "/home/chase/.local/lib/python3.8/site-packages/pymysql/connections.py", line 775, in _read_query_result
    result.read()
    │      └ <function MySQLResult.read at 0x7f31f34e64c0>
    └ <pymysql.connections.MySQLResult object at 0x7f30d82ced30>
  File "/home/chase/.local/lib/python3.8/site-packages/pymysql/connections.py", line 1156, in read
    first_packet = self.connection._read_packet()
                   │    └ None
                   └ <pymysql.connections.MySQLResult object at 0x7f30d82ced30>
  File "/home/chase/.local/lib/python3.8/site-packages/pymysql/connections.py", line 725, in _read_packet
    packet.raise_for_error()
    │      └ <function MysqlPacket.raise_for_error at 0x7f31f34ddee0>
    └ <pymysql.protocol.MysqlPacket object at 0x7f3102431970>
  File "/home/chase/.local/lib/python3.8/site-packages/pymysql/protocol.py", line 221, in raise_for_error
    err.raise_mysql_exception(self._data)
    │   │                     │    └ <member '_data' of 'MysqlPacket' objects>
    │   │                     └ <pymysql.protocol.MysqlPacket object at 0x7f3102431970>
    │   └ <function raise_mysql_exception at 0x7f31f358c670>
    └ <module 'pymysql.err' from '/home/chase/.local/lib/python3.8/site-packages/pymysql/err.py'>
  File "/home/chase/.local/lib/python3.8/site-packages/pymysql/err.py", line 143, in raise_mysql_exception
    raise errorclass(errno, errval)
          │          │      └ "Duplicate entry '180.201.163.246:6800' for key 'device.PRIMARY'"
          │          └ 1062
          └ <class 'pymysql.err.IntegrityError'>

sqlalchemy.exc.IntegrityError: (pymysql.err.IntegrityError) (1062, "Duplicate entry '180.201.163.246:6800' for key 'device.PRIMARY'")
[SQL: UPDATE device SET server_id=%(server_id)s, ip=%(ip)s, username=%(username)s, password=%(password)s, address=%(address)s, port=%(port)s, valid=%(valid)s WHERE device.ip = %(ip_1)s]
[parameters: {'server_id': '180.201.163.246:6800', 'ip': '180.201.163.246', 'username': 'chase', 'password': '56674017471258716445348100722541756302167729997708837821150818358590145383201924387800365542488340618889551604189094690827146029814994295755445118649 ... (10 characters truncated) ... 54374737620079892983210176086707489513531921881483871203536748582434889338838370124431216979134809418222177473838733630925272301467151216688379105575', 'address': '/home/users/CT/pycharmproject/spiders/', 'port': 6800, 'valid': 1, 'ip_1': '180.201.163.246'}]
(Background on this error at: https://sqlalche.me/e/14/gkpj)
2022-05-13 23:01:58.932 | ERROR    | base.db.mysql:update:390 - 【mysql更新数据出错】
Traceback (most recent call last):

  File "/home/chase/.local/lib/python3.8/site-packages/sqlalchemy/engine/base.py", line 1771, in _execute_context
    self.dialect.do_execute(
    │    │       └ <function DefaultDialect.do_execute at 0x7f31f38f75e0>
    │    └ <sqlalchemy.dialects.mysql.pymysql.MySQLDialect_pymysql object at 0x7f3103ffde20>
    └ <sqlalchemy.engine.base.Connection object at 0x7f3078632820>
  File "/home/chase/.local/lib/python3.8/site-packages/sqlalchemy/engine/default.py", line 717, in do_execute
    cursor.execute(statement, parameters)
    │      │       │          └ {'server_id': '180.201.163.246:6800', 'ip': '180.201.163.246', 'username': 'chase', 'password': '9607775597719702827484808029...
    │      │       └ 'UPDATE device SET server_id=%(server_id)s, ip=%(ip)s, username=%(username)s, password=%(password)s, address=%(address)s, por...
    │      └ <function Cursor.execute at 0x7f31f354cdc0>
    └ <pymysql.cursors.Cursor object at 0x7f3101d00760>
  File "/home/chase/.local/lib/python3.8/site-packages/pymysql/cursors.py", line 148, in execute
    result = self._query(query)
             │    │      └ "UPDATE device SET server_id='180.201.163.246:6800', ip='180.201.163.246', username='chase', password='9607775597719702827484...
             │    └ <function Cursor._query at 0x7f31f34d7280>
             └ <pymysql.cursors.Cursor object at 0x7f3101d00760>
  File "/home/chase/.local/lib/python3.8/site-packages/pymysql/cursors.py", line 310, in _query
    conn.query(q)
    │    │     └ "UPDATE device SET server_id='180.201.163.246:6800', ip='180.201.163.246', username='chase', password='9607775597719702827484...
    │    └ <function Connection.query at 0x7f31f34e5670>
    └ <pymysql.connections.Connection object at 0x7f3058618850>
  File "/home/chase/.local/lib/python3.8/site-packages/pymysql/connections.py", line 548, in query
    self._affected_rows = self._read_query_result(unbuffered=unbuffered)
    │    │                │    │                             └ False
    │    │                │    └ <function Connection._read_query_result at 0x7f31f34e5ca0>
    │    │                └ <pymysql.connections.Connection object at 0x7f3058618850>
    │    └ 1
    └ <pymysql.connections.Connection object at 0x7f3058618850>
  File "/home/chase/.local/lib/python3.8/site-packages/pymysql/connections.py", line 775, in _read_query_result
    result.read()
    │      └ <function MySQLResult.read at 0x7f31f34e64c0>
    └ <pymysql.connections.MySQLResult object at 0x7f3098147dc0>
  File "/home/chase/.local/lib/python3.8/site-packages/pymysql/connections.py", line 1156, in read
    first_packet = self.connection._read_packet()
                   │    └ None
                   └ <pymysql.connections.MySQLResult object at 0x7f3098147dc0>
  File "/home/chase/.local/lib/python3.8/site-packages/pymysql/connections.py", line 725, in _read_packet
    packet.raise_for_error()
    │      └ <function MysqlPacket.raise_for_error at 0x7f31f34ddee0>
    └ <pymysql.protocol.MysqlPacket object at 0x7f30384b6190>
  File "/home/chase/.local/lib/python3.8/site-packages/pymysql/protocol.py", line 221, in raise_for_error
    err.raise_mysql_exception(self._data)
    │   │                     │    └ <member '_data' of 'MysqlPacket' objects>
    │   │                     └ <pymysql.protocol.MysqlPacket object at 0x7f30384b6190>
    │   └ <function raise_mysql_exception at 0x7f31f358c670>
    └ <module 'pymysql.err' from '/home/chase/.local/lib/python3.8/site-packages/pymysql/err.py'>
  File "/home/chase/.local/lib/python3.8/site-packages/pymysql/err.py", line 143, in raise_mysql_exception
    raise errorclass(errno, errval)
          │          │      └ "Duplicate entry '180.201.163.246:6800' for key 'device.PRIMARY'"
          │          └ 1062
          └ <class 'pymysql.err.IntegrityError'>

pymysql.err.IntegrityError: (1062, "Duplicate entry '180.201.163.246:6800' for key 'device.PRIMARY'")


The above exception was the direct cause of the following exception:


Traceback (most recent call last):

  File "/usr/lib/python3.8/threading.py", line 890, in _bootstrap
    self._bootstrap_inner()
    │    └ <function Thread._bootstrap_inner at 0x7f321bf29a60>
    └ <Thread(Thread-5510, started daemon 139838345533184)>
  File "/usr/lib/python3.8/threading.py", line 932, in _bootstrap_inner
    self.run()
    │    └ <function Thread.run at 0x7f321bf29790>
    └ <Thread(Thread-5510, started daemon 139838345533184)>
  File "/usr/lib/python3.8/threading.py", line 870, in run
    self._target(*self._args, **self._kwargs)
    │    │        │    │        │    └ {}
    │    │        │    │        └ <Thread(Thread-5510, started daemon 139838345533184)>
    │    │        │    └ ('ProjectManager.run_func_by_thread',)
    │    │        └ <Thread(Thread-5510, started daemon 139838345533184)>
    │    └ <bound method ProjectManager.get_request_from_keywords_hot of <monitor.projectManager.ProjectManager object at 0x7f31042e52e0>>
    └ <Thread(Thread-5510, started daemon 139838345533184)>

  File "/home/users/Scy/yuqing/spider/monitor/projectManager.py", line 799, in get_request_from_keywords_hot
    self.start_finished_spider_every_interval(project_names)
    │    │                                    └ ['default', 'test']
    │    └ <function ProjectManager.start_finished_spider_every_interval at 0x7f3104005280>
    └ <monitor.projectManager.ProjectManager object at 0x7f31042e52e0>

  File "/home/users/Scy/yuqing/spider/monitor/projectManager.py", line 784, in start_finished_spider_every_interval
    self[name].start_spider()
    │    └ 'default'
    └ <monitor.projectManager.ProjectManager object at 0x7f31042e52e0>

  File "/home/users/Scy/yuqing/spider/monitor/projectManager.py", line 366, in start_spider
    self.update_device_valid(device)
    │    │                   └ <monitor.deviceManager.DeviceC object at 0x7f3104029220>
    │    └ <function Project.update_device_valid at 0x7f3104003280>
    └ <monitor.projectManager.Project object at 0x7f3104029460>

  File "/home/users/Scy/yuqing/spider/monitor/projectManager.py", line 421, in update_device_valid
    self.database_manager.mysql.update(Device(**device.to_item()))
    │    │                │     │      │        │      └ <function DeviceC.to_item at 0x7f31f34ed310>
    │    │                │     │      │        └ <monitor.deviceManager.DeviceC object at 0x7f3104029220>
    │    │                │     │      └ <class 'base.db.mysql.Device'>
    │    │                │     └ <function Mysql.update at 0x7f31f35f4790>
    │    │                └ <base.db.mysql.Mysql object at 0x7f3103ffdfd0>
    │    └ <base.db.dbSlot.Slot object at 0x7f3103ffdf10>
    └ <monitor.projectManager.Project object at 0x7f3104029460>

> File "/home/users/Scy/yuqing/spider/base/db/mysql.py", line 375, in update
    row.update(new)
    │   │      └ {'server_id': '180.201.163.246:6800', 'ip': '180.201.163.246', 'username': 'chase', 'password': '9607775597719702827484808029...
    │   └ <function Query.update at 0x7f31f37333a0>
    └ <sqlalchemy.orm.query.Query object at 0x7f30b80952b0>

  File "/home/chase/.local/lib/python3.8/site-packages/sqlalchemy/orm/query.py", line 3221, in update
    result = self.session.execute(
             │    │       └ <function Session.execute at 0x7f31f370faf0>
             │    └ <sqlalchemy.orm.session.Session object at 0x7f30583e71f0>
             └ <sqlalchemy.orm.query.Query object at 0x7f30b80952b0>
  File "/home/chase/.local/lib/python3.8/site-packages/sqlalchemy/orm/session.py", line 1689, in execute
    result = conn._execute_20(statement, params or {}, execution_options)
             │    │           │          │             └ immutabledict({'synchronize_session': 'evaluate', '_sa_orm_update_options': default_update_options(_matched_objects=[], _reso...
             │    │           │          └ immutabledict({})
             │    │           └ <sqlalchemy.sql.annotation.AnnotatedUpdate object at 0x7f3101d00f40>
             │    └ <function Connection._execute_20 at 0x7f31f39bc790>
             └ <sqlalchemy.engine.base.Connection object at 0x7f3078632820>
  File "/home/chase/.local/lib/python3.8/site-packages/sqlalchemy/engine/base.py", line 1583, in _execute_20
    return meth(self, args_10style, kwargs_10style, execution_options)
           │    │     │             │               └ immutabledict({'synchronize_session': 'evaluate', '_sa_orm_update_options': default_update_options(_matched_objects=[], _reso...
           │    │     │             └ immutabledict({})
           │    │     └ ({},)
           │    └ <sqlalchemy.engine.base.Connection object at 0x7f3078632820>
           └ <bound method ClauseElement._execute_on_connection of <sqlalchemy.sql.annotation.AnnotatedUpdate object at 0x7f3101d00f40>>
  File "/home/chase/.local/lib/python3.8/site-packages/sqlalchemy/sql/elements.py", line 323, in _execute_on_connection
    return connection._execute_clauseelement(
           │          └ <function Connection._execute_clauseelement at 0x7f31f39bc5e0>
           └ <sqlalchemy.engine.base.Connection object at 0x7f3078632820>
  File "/home/chase/.local/lib/python3.8/site-packages/sqlalchemy/engine/base.py", line 1452, in _execute_clauseelement
    ret = self._execute_context(
          │    └ <function Connection._execute_context at 0x7f31f39bc8b0>
          └ <sqlalchemy.engine.base.Connection object at 0x7f3078632820>
  File "/home/chase/.local/lib/python3.8/site-packages/sqlalchemy/engine/base.py", line 1814, in _execute_context
    self._handle_dbapi_exception(
    │    └ <function Connection._handle_dbapi_exception at 0x7f31f39bca60>
    └ <sqlalchemy.engine.base.Connection object at 0x7f3078632820>
  File "/home/chase/.local/lib/python3.8/site-packages/sqlalchemy/engine/base.py", line 1995, in _handle_dbapi_exception
    util.raise_(
    │    └ <function raise_ at 0x7f31f3d7ea60>
    └ <module 'sqlalchemy.util' from '/home/chase/.local/lib/python3.8/site-packages/sqlalchemy/util/__init__.py'>
  File "/home/chase/.local/lib/python3.8/site-packages/sqlalchemy/util/compat.py", line 207, in raise_
    raise exception
  File "/home/chase/.local/lib/python3.8/site-packages/sqlalchemy/engine/base.py", line 1771, in _execute_context
    self.dialect.do_execute(
    │    │       └ <function DefaultDialect.do_execute at 0x7f31f38f75e0>
    │    └ <sqlalchemy.dialects.mysql.pymysql.MySQLDialect_pymysql object at 0x7f3103ffde20>
    └ <sqlalchemy.engine.base.Connection object at 0x7f3078632820>
  File "/home/chase/.local/lib/python3.8/site-packages/sqlalchemy/engine/default.py", line 717, in do_execute
    cursor.execute(statement, parameters)
    │      │       │          └ {'server_id': '180.201.163.246:6800', 'ip': '180.201.163.246', 'username': 'chase', 'password': '9607775597719702827484808029...
    │      │       └ 'UPDATE device SET server_id=%(server_id)s, ip=%(ip)s, username=%(username)s, password=%(password)s, address=%(address)s, por...
    │      └ <function Cursor.execute at 0x7f31f354cdc0>
    └ <pymysql.cursors.Cursor object at 0x7f3101d00760>
  File "/home/chase/.local/lib/python3.8/site-packages/pymysql/cursors.py", line 148, in execute
    result = self._query(query)
             │    │      └ "UPDATE device SET server_id='180.201.163.246:6800', ip='180.201.163.246', username='chase', password='9607775597719702827484...
             │    └ <function Cursor._query at 0x7f31f34d7280>
             └ <pymysql.cursors.Cursor object at 0x7f3101d00760>
  File "/home/chase/.local/lib/python3.8/site-packages/pymysql/cursors.py", line 310, in _query
    conn.query(q)
    │    │     └ "UPDATE device SET server_id='180.201.163.246:6800', ip='180.201.163.246', username='chase', password='9607775597719702827484...
    │    └ <function Connection.query at 0x7f31f34e5670>
    └ <pymysql.connections.Connection object at 0x7f3058618850>
  File "/home/chase/.local/lib/python3.8/site-packages/pymysql/connections.py", line 548, in query
    self._affected_rows = self._read_query_result(unbuffered=unbuffered)
    │    │                │    │                             └ False
    │    │                │    └ <function Connection._read_query_result at 0x7f31f34e5ca0>
    │    │                └ <pymysql.connections.Connection object at 0x7f3058618850>
    │    └ 1
    └ <pymysql.connections.Connection object at 0x7f3058618850>
  File "/home/chase/.local/lib/python3.8/site-packages/pymysql/connections.py", line 775, in _read_query_result
    result.read()
    │      └ <function MySQLResult.read at 0x7f31f34e64c0>
    └ <pymysql.connections.MySQLResult object at 0x7f3098147dc0>
  File "/home/chase/.local/lib/python3.8/site-packages/pymysql/connections.py", line 1156, in read
    first_packet = self.connection._read_packet()
                   │    └ None
                   └ <pymysql.connections.MySQLResult object at 0x7f3098147dc0>
  File "/home/chase/.local/lib/python3.8/site-packages/pymysql/connections.py", line 725, in _read_packet
    packet.raise_for_error()
    │      └ <function MysqlPacket.raise_for_error at 0x7f31f34ddee0>
    └ <pymysql.protocol.MysqlPacket object at 0x7f30384b6190>
  File "/home/chase/.local/lib/python3.8/site-packages/pymysql/protocol.py", line 221, in raise_for_error
    err.raise_mysql_exception(self._data)
    │   │                     │    └ <member '_data' of 'MysqlPacket' objects>
    │   │                     └ <pymysql.protocol.MysqlPacket object at 0x7f30384b6190>
    │   └ <function raise_mysql_exception at 0x7f31f358c670>
    └ <module 'pymysql.err' from '/home/chase/.local/lib/python3.8/site-packages/pymysql/err.py'>
  File "/home/chase/.local/lib/python3.8/site-packages/pymysql/err.py", line 143, in raise_mysql_exception
    raise errorclass(errno, errval)
          │          │      └ "Duplicate entry '180.201.163.246:6800' for key 'device.PRIMARY'"
          │          └ 1062
          └ <class 'pymysql.err.IntegrityError'>

sqlalchemy.exc.IntegrityError: (pymysql.err.IntegrityError) (1062, "Duplicate entry '180.201.163.246:6800' for key 'device.PRIMARY'")
[SQL: UPDATE device SET server_id=%(server_id)s, ip=%(ip)s, username=%(username)s, password=%(password)s, address=%(address)s, port=%(port)s, valid=%(valid)s WHERE device.ip = %(ip_1)s]
[parameters: {'server_id': '180.201.163.246:6800', 'ip': '180.201.163.246', 'username': 'chase', 'password': '96077755977197028274848080295192018769338046917752706328441892151667430333781974208912010273945605538701043450257171555538681902321850900601525688285 ... (10 characters truncated) ... 38297899561625317495834835846225069962870511030388239039276208486544140223114219676452778241270226061903902827819962406730044989694329868677450678438', 'address': '/home/users/CT/pycharmproject/spiders/', 'port': 6800, 'valid': 1, 'ip_1': '180.201.163.246'}]
(Background on this error at: https://sqlalche.me/e/14/gkpj)
2022-05-13 23:02:17.736 | ERROR    | base.db.mysql:update:390 - 【mysql更新数据出错】
Traceback (most recent call last):

  File "/home/chase/.local/lib/python3.8/site-packages/sqlalchemy/engine/base.py", line 1771, in _execute_context
    self.dialect.do_execute(
    │    │       └ <function DefaultDialect.do_execute at 0x7f31f38f75e0>
    │    └ <sqlalchemy.dialects.mysql.pymysql.MySQLDialect_pymysql object at 0x7f3103ffde20>
    └ <sqlalchemy.engine.base.Connection object at 0x7f30d81f3e80>
  File "/home/chase/.local/lib/python3.8/site-packages/sqlalchemy/engine/default.py", line 717, in do_execute
    cursor.execute(statement, parameters)
    │      │       │          └ {'server_id': '180.201.163.246:6800', 'ip': '180.201.163.246', 'username': 'chase', 'password': '2569469653588909157113703241...
    │      │       └ 'UPDATE device SET server_id=%(server_id)s, ip=%(ip)s, username=%(username)s, password=%(password)s, address=%(address)s, por...
    │      └ <function Cursor.execute at 0x7f31f354cdc0>
    └ <pymysql.cursors.Cursor object at 0x7f30980d68b0>
  File "/home/chase/.local/lib/python3.8/site-packages/pymysql/cursors.py", line 148, in execute
    result = self._query(query)
             │    │      └ "UPDATE device SET server_id='180.201.163.246:6800', ip='180.201.163.246', username='chase', password='2569469653588909157113...
             │    └ <function Cursor._query at 0x7f31f34d7280>
             └ <pymysql.cursors.Cursor object at 0x7f30980d68b0>
  File "/home/chase/.local/lib/python3.8/site-packages/pymysql/cursors.py", line 310, in _query
    conn.query(q)
    │    │     └ "UPDATE device SET server_id='180.201.163.246:6800', ip='180.201.163.246', username='chase', password='2569469653588909157113...
    │    └ <function Connection.query at 0x7f31f34e5670>
    └ <pymysql.connections.Connection object at 0x7f3100245be0>
  File "/home/chase/.local/lib/python3.8/site-packages/pymysql/connections.py", line 548, in query
    self._affected_rows = self._read_query_result(unbuffered=unbuffered)
    │    │                │    │                             └ False
    │    │                │    └ <function Connection._read_query_result at 0x7f31f34e5ca0>
    │    │                └ <pymysql.connections.Connection object at 0x7f3100245be0>
    │    └ 1
    └ <pymysql.connections.Connection object at 0x7f3100245be0>
  File "/home/chase/.local/lib/python3.8/site-packages/pymysql/connections.py", line 775, in _read_query_result
    result.read()
    │      └ <function MySQLResult.read at 0x7f31f34e64c0>
    └ <pymysql.connections.MySQLResult object at 0x7f309853c640>
  File "/home/chase/.local/lib/python3.8/site-packages/pymysql/connections.py", line 1156, in read
    first_packet = self.connection._read_packet()
                   │    └ None
                   └ <pymysql.connections.MySQLResult object at 0x7f309853c640>
  File "/home/chase/.local/lib/python3.8/site-packages/pymysql/connections.py", line 725, in _read_packet
    packet.raise_for_error()
    │      └ <function MysqlPacket.raise_for_error at 0x7f31f34ddee0>
    └ <pymysql.protocol.MysqlPacket object at 0x7f3100b78940>
  File "/home/chase/.local/lib/python3.8/site-packages/pymysql/protocol.py", line 221, in raise_for_error
    err.raise_mysql_exception(self._data)
    │   │                     │    └ <member '_data' of 'MysqlPacket' objects>
    │   │                     └ <pymysql.protocol.MysqlPacket object at 0x7f3100b78940>
    │   └ <function raise_mysql_exception at 0x7f31f358c670>
    └ <module 'pymysql.err' from '/home/chase/.local/lib/python3.8/site-packages/pymysql/err.py'>
  File "/home/chase/.local/lib/python3.8/site-packages/pymysql/err.py", line 143, in raise_mysql_exception
    raise errorclass(errno, errval)
          │          │      └ "Duplicate entry '180.201.163.246:6800' for key 'device.PRIMARY'"
          │          └ 1062
          └ <class 'pymysql.err.IntegrityError'>

pymysql.err.IntegrityError: (1062, "Duplicate entry '180.201.163.246:6800' for key 'device.PRIMARY'")


The above exception was the direct cause of the following exception:


Traceback (most recent call last):

  File "/usr/lib/python3.8/threading.py", line 890, in _bootstrap
    self._bootstrap_inner()
    │    └ <function Thread._bootstrap_inner at 0x7f321bf29a60>
    └ <Thread(Thread-5515, started daemon 139838311962368)>
  File "/usr/lib/python3.8/threading.py", line 932, in _bootstrap_inner
    self.run()
    │    └ <function Thread.run at 0x7f321bf29790>
    └ <Thread(Thread-5515, started daemon 139838311962368)>
  File "/usr/lib/python3.8/threading.py", line 870, in run
    self._target(*self._args, **self._kwargs)
    │    │        │    │        │    └ {}
    │    │        │    │        └ <Thread(Thread-5515, started daemon 139838311962368)>
    │    │        │    └ ('ProjectManager.run_func_by_thread',)
    │    │        └ <Thread(Thread-5515, started daemon 139838311962368)>
    │    └ <bound method ProjectManager.get_request_from_keywords_hot of <monitor.projectManager.ProjectManager object at 0x7f31042e52e0>>
    └ <Thread(Thread-5515, started daemon 139838311962368)>

  File "/home/users/Scy/yuqing/spider/monitor/projectManager.py", line 799, in get_request_from_keywords_hot
    self.start_finished_spider_every_interval(project_names)
    │    │                                    └ ['default', 'test']
    │    └ <function ProjectManager.start_finished_spider_every_interval at 0x7f3104005280>
    └ <monitor.projectManager.ProjectManager object at 0x7f31042e52e0>

  File "/home/users/Scy/yuqing/spider/monitor/projectManager.py", line 784, in start_finished_spider_every_interval
    self[name].start_spider()
    │    └ 'default'
    └ <monitor.projectManager.ProjectManager object at 0x7f31042e52e0>

  File "/home/users/Scy/yuqing/spider/monitor/projectManager.py", line 366, in start_spider
    self.update_device_valid(device)
    │    │                   └ <monitor.deviceManager.DeviceC object at 0x7f3104029220>
    │    └ <function Project.update_device_valid at 0x7f3104003280>
    └ <monitor.projectManager.Project object at 0x7f3104029460>

  File "/home/users/Scy/yuqing/spider/monitor/projectManager.py", line 421, in update_device_valid
    self.database_manager.mysql.update(Device(**device.to_item()))
    │    │                │     │      │        │      └ <function DeviceC.to_item at 0x7f31f34ed310>
    │    │                │     │      │        └ <monitor.deviceManager.DeviceC object at 0x7f3104029220>
    │    │                │     │      └ <class 'base.db.mysql.Device'>
    │    │                │     └ <function Mysql.update at 0x7f31f35f4790>
    │    │                └ <base.db.mysql.Mysql object at 0x7f3103ffdfd0>
    │    └ <base.db.dbSlot.Slot object at 0x7f3103ffdf10>
    └ <monitor.projectManager.Project object at 0x7f3104029460>

> File "/home/users/Scy/yuqing/spider/base/db/mysql.py", line 375, in update
    row.update(new)
    │   │      └ {'server_id': '180.201.163.246:6800', 'ip': '180.201.163.246', 'username': 'chase', 'password': '2569469653588909157113703241...
    │   └ <function Query.update at 0x7f31f37333a0>
    └ <sqlalchemy.orm.query.Query object at 0x7f301817cbe0>

  File "/home/chase/.local/lib/python3.8/site-packages/sqlalchemy/orm/query.py", line 3221, in update
    result = self.session.execute(
             │    │       └ <function Session.execute at 0x7f31f370faf0>
             │    └ <sqlalchemy.orm.session.Session object at 0x7f31020ecd30>
             └ <sqlalchemy.orm.query.Query object at 0x7f301817cbe0>
  File "/home/chase/.local/lib/python3.8/site-packages/sqlalchemy/orm/session.py", line 1689, in execute
    result = conn._execute_20(statement, params or {}, execution_options)
             │    │           │          │             └ immutabledict({'synchronize_session': 'evaluate', '_sa_orm_update_options': default_update_options(_matched_objects=[], _reso...
             │    │           │          └ immutabledict({})
             │    │           └ <sqlalchemy.sql.annotation.AnnotatedUpdate object at 0x7f3101be06a0>
             │    └ <function Connection._execute_20 at 0x7f31f39bc790>
             └ <sqlalchemy.engine.base.Connection object at 0x7f30d81f3e80>
  File "/home/chase/.local/lib/python3.8/site-packages/sqlalchemy/engine/base.py", line 1583, in _execute_20
    return meth(self, args_10style, kwargs_10style, execution_options)
           │    │     │             │               └ immutabledict({'synchronize_session': 'evaluate', '_sa_orm_update_options': default_update_options(_matched_objects=[], _reso...
           │    │     │             └ immutabledict({})
           │    │     └ ({},)
           │    └ <sqlalchemy.engine.base.Connection object at 0x7f30d81f3e80>
           └ <bound method ClauseElement._execute_on_connection of <sqlalchemy.sql.annotation.AnnotatedUpdate object at 0x7f3101be06a0>>
  File "/home/chase/.local/lib/python3.8/site-packages/sqlalchemy/sql/elements.py", line 323, in _execute_on_connection
    return connection._execute_clauseelement(
           │          └ <function Connection._execute_clauseelement at 0x7f31f39bc5e0>
           └ <sqlalchemy.engine.base.Connection object at 0x7f30d81f3e80>
  File "/home/chase/.local/lib/python3.8/site-packages/sqlalchemy/engine/base.py", line 1452, in _execute_clauseelement
    ret = self._execute_context(
          │    └ <function Connection._execute_context at 0x7f31f39bc8b0>
          └ <sqlalchemy.engine.base.Connection object at 0x7f30d81f3e80>
  File "/home/chase/.local/lib/python3.8/site-packages/sqlalchemy/engine/base.py", line 1814, in _execute_context
    self._handle_dbapi_exception(
    │    └ <function Connection._handle_dbapi_exception at 0x7f31f39bca60>
    └ <sqlalchemy.engine.base.Connection object at 0x7f30d81f3e80>
  File "/home/chase/.local/lib/python3.8/site-packages/sqlalchemy/engine/base.py", line 1995, in _handle_dbapi_exception
    util.raise_(
    │    └ <function raise_ at 0x7f31f3d7ea60>
    └ <module 'sqlalchemy.util' from '/home/chase/.local/lib/python3.8/site-packages/sqlalchemy/util/__init__.py'>
  File "/home/chase/.local/lib/python3.8/site-packages/sqlalchemy/util/compat.py", line 207, in raise_
    raise exception
  File "/home/chase/.local/lib/python3.8/site-packages/sqlalchemy/engine/base.py", line 1771, in _execute_context
    self.dialect.do_execute(
    │    │       └ <function DefaultDialect.do_execute at 0x7f31f38f75e0>
    │    └ <sqlalchemy.dialects.mysql.pymysql.MySQLDialect_pymysql object at 0x7f3103ffde20>
    └ <sqlalchemy.engine.base.Connection object at 0x7f30d81f3e80>
  File "/home/chase/.local/lib/python3.8/site-packages/sqlalchemy/engine/default.py", line 717, in do_execute
    cursor.execute(statement, parameters)
    │      │       │          └ {'server_id': '180.201.163.246:6800', 'ip': '180.201.163.246', 'username': 'chase', 'password': '2569469653588909157113703241...
    │      │       └ 'UPDATE device SET server_id=%(server_id)s, ip=%(ip)s, username=%(username)s, password=%(password)s, address=%(address)s, por...
    │      └ <function Cursor.execute at 0x7f31f354cdc0>
    └ <pymysql.cursors.Cursor object at 0x7f30980d68b0>
  File "/home/chase/.local/lib/python3.8/site-packages/pymysql/cursors.py", line 148, in execute
    result = self._query(query)
             │    │      └ "UPDATE device SET server_id='180.201.163.246:6800', ip='180.201.163.246', username='chase', password='2569469653588909157113...
             │    └ <function Cursor._query at 0x7f31f34d7280>
             └ <pymysql.cursors.Cursor object at 0x7f30980d68b0>
  File "/home/chase/.local/lib/python3.8/site-packages/pymysql/cursors.py", line 310, in _query
    conn.query(q)
    │    │     └ "UPDATE device SET server_id='180.201.163.246:6800', ip='180.201.163.246', username='chase', password='2569469653588909157113...
    │    └ <function Connection.query at 0x7f31f34e5670>
    └ <pymysql.connections.Connection object at 0x7f3100245be0>
  File "/home/chase/.local/lib/python3.8/site-packages/pymysql/connections.py", line 548, in query
    self._affected_rows = self._read_query_result(unbuffered=unbuffered)
    │    │                │    │                             └ False
    │    │                │    └ <function Connection._read_query_result at 0x7f31f34e5ca0>
    │    │                └ <pymysql.connections.Connection object at 0x7f3100245be0>
    │    └ 1
    └ <pymysql.connections.Connection object at 0x7f3100245be0>
  File "/home/chase/.local/lib/python3.8/site-packages/pymysql/connections.py", line 775, in _read_query_result
    result.read()
    │      └ <function MySQLResult.read at 0x7f31f34e64c0>
    └ <pymysql.connections.MySQLResult object at 0x7f309853c640>
  File "/home/chase/.local/lib/python3.8/site-packages/pymysql/connections.py", line 1156, in read
    first_packet = self.connection._read_packet()
                   │    └ None
                   └ <pymysql.connections.MySQLResult object at 0x7f309853c640>
  File "/home/chase/.local/lib/python3.8/site-packages/pymysql/connections.py", line 725, in _read_packet
    packet.raise_for_error()
    │      └ <function MysqlPacket.raise_for_error at 0x7f31f34ddee0>
    └ <pymysql.protocol.MysqlPacket object at 0x7f3100b78940>
  File "/home/chase/.local/lib/python3.8/site-packages/pymysql/protocol.py", line 221, in raise_for_error
    err.raise_mysql_exception(self._data)
    │   │                     │    └ <member '_data' of 'MysqlPacket' objects>
    │   │                     └ <pymysql.protocol.MysqlPacket object at 0x7f3100b78940>
    │   └ <function raise_mysql_exception at 0x7f31f358c670>
    └ <module 'pymysql.err' from '/home/chase/.local/lib/python3.8/site-packages/pymysql/err.py'>
  File "/home/chase/.local/lib/python3.8/site-packages/pymysql/err.py", line 143, in raise_mysql_exception
    raise errorclass(errno, errval)
          │          │      └ "Duplicate entry '180.201.163.246:6800' for key 'device.PRIMARY'"
          │          └ 1062
          └ <class 'pymysql.err.IntegrityError'>

sqlalchemy.exc.IntegrityError: (pymysql.err.IntegrityError) (1062, "Duplicate entry '180.201.163.246:6800' for key 'device.PRIMARY'")
[SQL: UPDATE device SET server_id=%(server_id)s, ip=%(ip)s, username=%(username)s, password=%(password)s, address=%(address)s, port=%(port)s, valid=%(valid)s WHERE device.ip = %(ip_1)s]
[parameters: {'server_id': '180.201.163.246:6800', 'ip': '180.201.163.246', 'username': 'chase', 'password': '25694696535889091571137032414577379447303247752821051698682321464005746472844430532758240385677614189844205603026912858861339202992841505116700643109 ... (10 characters truncated) ... 46394493003089027973536771145615787608266653097896265871397526671712406343748945892682009328756605784736645771220215750371601329759706375596994108800', 'address': '/home/users/CT/pycharmproject/spiders/', 'port': 6800, 'valid': 1, 'ip_1': '180.201.163.246'}]
(Background on this error at: https://sqlalche.me/e/14/gkpj)
2022-05-13 23:02:34.859 | ERROR    | base.db.mysql:update:390 - 【mysql更新数据出错】
Traceback (most recent call last):

  File "/home/chase/.local/lib/python3.8/site-packages/sqlalchemy/engine/base.py", line 1771, in _execute_context
    self.dialect.do_execute(
    │    │       └ <function DefaultDialect.do_execute at 0x7f31f38f75e0>
    │    └ <sqlalchemy.dialects.mysql.pymysql.MySQLDialect_pymysql object at 0x7f3103ffde20>
    └ <sqlalchemy.engine.base.Connection object at 0x7f30180d1970>
  File "/home/chase/.local/lib/python3.8/site-packages/sqlalchemy/engine/default.py", line 717, in do_execute
    cursor.execute(statement, parameters)
    │      │       │          └ {'server_id': '180.201.163.246:6800', 'ip': '180.201.163.246', 'username': 'chase', 'password': '3900999320922538255048596090...
    │      │       └ 'UPDATE device SET server_id=%(server_id)s, ip=%(ip)s, username=%(username)s, password=%(password)s, address=%(address)s, por...
    │      └ <function Cursor.execute at 0x7f31f354cdc0>
    └ <pymysql.cursors.Cursor object at 0x7f30986e4160>
  File "/home/chase/.local/lib/python3.8/site-packages/pymysql/cursors.py", line 148, in execute
    result = self._query(query)
             │    │      └ "UPDATE device SET server_id='180.201.163.246:6800', ip='180.201.163.246', username='chase', password='3900999320922538255048...
             │    └ <function Cursor._query at 0x7f31f34d7280>
             └ <pymysql.cursors.Cursor object at 0x7f30986e4160>
  File "/home/chase/.local/lib/python3.8/site-packages/pymysql/cursors.py", line 310, in _query
    conn.query(q)
    │    │     └ "UPDATE device SET server_id='180.201.163.246:6800', ip='180.201.163.246', username='chase', password='3900999320922538255048...
    │    └ <function Connection.query at 0x7f31f34e5670>
    └ <pymysql.connections.Connection object at 0x7f2fb84c4670>
  File "/home/chase/.local/lib/python3.8/site-packages/pymysql/connections.py", line 548, in query
    self._affected_rows = self._read_query_result(unbuffered=unbuffered)
    │    │                │    │                             └ False
    │    │                │    └ <function Connection._read_query_result at 0x7f31f34e5ca0>
    │    │                └ <pymysql.connections.Connection object at 0x7f2fb84c4670>
    │    └ 1
    └ <pymysql.connections.Connection object at 0x7f2fb84c4670>
  File "/home/chase/.local/lib/python3.8/site-packages/pymysql/connections.py", line 775, in _read_query_result
    result.read()
    │      └ <function MySQLResult.read at 0x7f31f34e64c0>
    └ <pymysql.connections.MySQLResult object at 0x7f30d8358dc0>
  File "/home/chase/.local/lib/python3.8/site-packages/pymysql/connections.py", line 1156, in read
    first_packet = self.connection._read_packet()
                   │    └ None
                   └ <pymysql.connections.MySQLResult object at 0x7f30d8358dc0>
  File "/home/chase/.local/lib/python3.8/site-packages/pymysql/connections.py", line 725, in _read_packet
    packet.raise_for_error()
    │      └ <function MysqlPacket.raise_for_error at 0x7f31f34ddee0>
    └ <pymysql.protocol.MysqlPacket object at 0x7f30980de1c0>
  File "/home/chase/.local/lib/python3.8/site-packages/pymysql/protocol.py", line 221, in raise_for_error
    err.raise_mysql_exception(self._data)
    │   │                     │    └ <member '_data' of 'MysqlPacket' objects>
    │   │                     └ <pymysql.protocol.MysqlPacket object at 0x7f30980de1c0>
    │   └ <function raise_mysql_exception at 0x7f31f358c670>
    └ <module 'pymysql.err' from '/home/chase/.local/lib/python3.8/site-packages/pymysql/err.py'>
  File "/home/chase/.local/lib/python3.8/site-packages/pymysql/err.py", line 143, in raise_mysql_exception
    raise errorclass(errno, errval)
          │          │      └ "Duplicate entry '180.201.163.246:6800' for key 'device.PRIMARY'"
          │          └ 1062
          └ <class 'pymysql.err.IntegrityError'>

pymysql.err.IntegrityError: (1062, "Duplicate entry '180.201.163.246:6800' for key 'device.PRIMARY'")


The above exception was the direct cause of the following exception:


Traceback (most recent call last):

  File "/usr/lib/python3.8/threading.py", line 890, in _bootstrap
    self._bootstrap_inner()
    │    └ <function Thread._bootstrap_inner at 0x7f321bf29a60>
    └ <Thread(Thread-5519, started daemon 139838471423744)>
  File "/usr/lib/python3.8/threading.py", line 932, in _bootstrap_inner
    self.run()
    │    └ <function Thread.run at 0x7f321bf29790>
    └ <Thread(Thread-5519, started daemon 139838471423744)>
  File "/usr/lib/python3.8/threading.py", line 870, in run
    self._target(*self._args, **self._kwargs)
    │    │        │    │        │    └ {}
    │    │        │    │        └ <Thread(Thread-5519, started daemon 139838471423744)>
    │    │        │    └ ('ProjectManager.run_func_by_thread',)
    │    │        └ <Thread(Thread-5519, started daemon 139838471423744)>
    │    └ <bound method ProjectManager.get_request_from_keywords_hot of <monitor.projectManager.ProjectManager object at 0x7f31042e52e0>>
    └ <Thread(Thread-5519, started daemon 139838471423744)>

  File "/home/users/Scy/yuqing/spider/monitor/projectManager.py", line 799, in get_request_from_keywords_hot
    self.start_finished_spider_every_interval(project_names)
    │    │                                    └ ['default', 'test']
    │    └ <function ProjectManager.start_finished_spider_every_interval at 0x7f3104005280>
    └ <monitor.projectManager.ProjectManager object at 0x7f31042e52e0>

  File "/home/users/Scy/yuqing/spider/monitor/projectManager.py", line 784, in start_finished_spider_every_interval
    self[name].start_spider()
    │    └ 'default'
    └ <monitor.projectManager.ProjectManager object at 0x7f31042e52e0>

  File "/home/users/Scy/yuqing/spider/monitor/projectManager.py", line 366, in start_spider
    self.update_device_valid(device)
    │    │                   └ <monitor.deviceManager.DeviceC object at 0x7f3104029220>
    │    └ <function Project.update_device_valid at 0x7f3104003280>
    └ <monitor.projectManager.Project object at 0x7f3104029460>

  File "/home/users/Scy/yuqing/spider/monitor/projectManager.py", line 421, in update_device_valid
    self.database_manager.mysql.update(Device(**device.to_item()))
    │    │                │     │      │        │      └ <function DeviceC.to_item at 0x7f31f34ed310>
    │    │                │     │      │        └ <monitor.deviceManager.DeviceC object at 0x7f3104029220>
    │    │                │     │      └ <class 'base.db.mysql.Device'>
    │    │                │     └ <function Mysql.update at 0x7f31f35f4790>
    │    │                └ <base.db.mysql.Mysql object at 0x7f3103ffdfd0>
    │    └ <base.db.dbSlot.Slot object at 0x7f3103ffdf10>
    └ <monitor.projectManager.Project object at 0x7f3104029460>

> File "/home/users/Scy/yuqing/spider/base/db/mysql.py", line 375, in update
    row.update(new)
    │   │      └ {'server_id': '180.201.163.246:6800', 'ip': '180.201.163.246', 'username': 'chase', 'password': '3900999320922538255048596090...
    │   └ <function Query.update at 0x7f31f37333a0>
    └ <sqlalchemy.orm.query.Query object at 0x7f30180d13a0>

  File "/home/chase/.local/lib/python3.8/site-packages/sqlalchemy/orm/query.py", line 3221, in update
    result = self.session.execute(
             │    │       └ <function Session.execute at 0x7f31f370faf0>
             │    └ <sqlalchemy.orm.session.Session object at 0x7f310026bd00>
             └ <sqlalchemy.orm.query.Query object at 0x7f30180d13a0>
  File "/home/chase/.local/lib/python3.8/site-packages/sqlalchemy/orm/session.py", line 1689, in execute
    result = conn._execute_20(statement, params or {}, execution_options)
             │    │           │          │             └ immutabledict({'synchronize_session': 'evaluate', '_sa_orm_update_options': default_update_options(_matched_objects=[], _reso...
             │    │           │          └ immutabledict({})
             │    │           └ <sqlalchemy.sql.annotation.AnnotatedUpdate object at 0x7f30580ee550>
             │    └ <function Connection._execute_20 at 0x7f31f39bc790>
             └ <sqlalchemy.engine.base.Connection object at 0x7f30180d1970>
  File "/home/chase/.local/lib/python3.8/site-packages/sqlalchemy/engine/base.py", line 1583, in _execute_20
    return meth(self, args_10style, kwargs_10style, execution_options)
           │    │     │             │               └ immutabledict({'synchronize_session': 'evaluate', '_sa_orm_update_options': default_update_options(_matched_objects=[], _reso...
           │    │     │             └ immutabledict({})
           │    │     └ ({},)
           │    └ <sqlalchemy.engine.base.Connection object at 0x7f30180d1970>
           └ <bound method ClauseElement._execute_on_connection of <sqlalchemy.sql.annotation.AnnotatedUpdate object at 0x7f30580ee550>>
  File "/home/chase/.local/lib/python3.8/site-packages/sqlalchemy/sql/elements.py", line 323, in _execute_on_connection
    return connection._execute_clauseelement(
           │          └ <function Connection._execute_clauseelement at 0x7f31f39bc5e0>
           └ <sqlalchemy.engine.base.Connection object at 0x7f30180d1970>
  File "/home/chase/.local/lib/python3.8/site-packages/sqlalchemy/engine/base.py", line 1452, in _execute_clauseelement
    ret = self._execute_context(
          │    └ <function Connection._execute_context at 0x7f31f39bc8b0>
          └ <sqlalchemy.engine.base.Connection object at 0x7f30180d1970>
  File "/home/chase/.local/lib/python3.8/site-packages/sqlalchemy/engine/base.py", line 1814, in _execute_context
    self._handle_dbapi_exception(
    │    └ <function Connection._handle_dbapi_exception at 0x7f31f39bca60>
    └ <sqlalchemy.engine.base.Connection object at 0x7f30180d1970>
  File "/home/chase/.local/lib/python3.8/site-packages/sqlalchemy/engine/base.py", line 1995, in _handle_dbapi_exception
    util.raise_(
    │    └ <function raise_ at 0x7f31f3d7ea60>
    └ <module 'sqlalchemy.util' from '/home/chase/.local/lib/python3.8/site-packages/sqlalchemy/util/__init__.py'>
  File "/home/chase/.local/lib/python3.8/site-packages/sqlalchemy/util/compat.py", line 207, in raise_
    raise exception
  File "/home/chase/.local/lib/python3.8/site-packages/sqlalchemy/engine/base.py", line 1771, in _execute_context
    self.dialect.do_execute(
    │    │       └ <function DefaultDialect.do_execute at 0x7f31f38f75e0>
    │    └ <sqlalchemy.dialects.mysql.pymysql.MySQLDialect_pymysql object at 0x7f3103ffde20>
    └ <sqlalchemy.engine.base.Connection object at 0x7f30180d1970>
  File "/home/chase/.local/lib/python3.8/site-packages/sqlalchemy/engine/default.py", line 717, in do_execute
    cursor.execute(statement, parameters)
    │      │       │          └ {'server_id': '180.201.163.246:6800', 'ip': '180.201.163.246', 'username': 'chase', 'password': '3900999320922538255048596090...
    │      │       └ 'UPDATE device SET server_id=%(server_id)s, ip=%(ip)s, username=%(username)s, password=%(password)s, address=%(address)s, por...
    │      └ <function Cursor.execute at 0x7f31f354cdc0>
    └ <pymysql.cursors.Cursor object at 0x7f30986e4160>
  File "/home/chase/.local/lib/python3.8/site-packages/pymysql/cursors.py", line 148, in execute
    result = self._query(query)
             │    │      └ "UPDATE device SET server_id='180.201.163.246:6800', ip='180.201.163.246', username='chase', password='3900999320922538255048...
             │    └ <function Cursor._query at 0x7f31f34d7280>
             └ <pymysql.cursors.Cursor object at 0x7f30986e4160>
  File "/home/chase/.local/lib/python3.8/site-packages/pymysql/cursors.py", line 310, in _query
    conn.query(q)
    │    │     └ "UPDATE device SET server_id='180.201.163.246:6800', ip='180.201.163.246', username='chase', password='3900999320922538255048...
    │    └ <function Connection.query at 0x7f31f34e5670>
    └ <pymysql.connections.Connection object at 0x7f2fb84c4670>
  File "/home/chase/.local/lib/python3.8/site-packages/pymysql/connections.py", line 548, in query
    self._affected_rows = self._read_query_result(unbuffered=unbuffered)
    │    │                │    │                             └ False
    │    │                │    └ <function Connection._read_query_result at 0x7f31f34e5ca0>
    │    │                └ <pymysql.connections.Connection object at 0x7f2fb84c4670>
    │    └ 1
    └ <pymysql.connections.Connection object at 0x7f2fb84c4670>
  File "/home/chase/.local/lib/python3.8/site-packages/pymysql/connections.py", line 775, in _read_query_result
    result.read()
    │      └ <function MySQLResult.read at 0x7f31f34e64c0>
    └ <pymysql.connections.MySQLResult object at 0x7f30d8358dc0>
  File "/home/chase/.local/lib/python3.8/site-packages/pymysql/connections.py", line 1156, in read
    first_packet = self.connection._read_packet()
                   │    └ None
                   └ <pymysql.connections.MySQLResult object at 0x7f30d8358dc0>
  File "/home/chase/.local/lib/python3.8/site-packages/pymysql/connections.py", line 725, in _read_packet
    packet.raise_for_error()
    │      └ <function MysqlPacket.raise_for_error at 0x7f31f34ddee0>
    └ <pymysql.protocol.MysqlPacket object at 0x7f30980de1c0>
  File "/home/chase/.local/lib/python3.8/site-packages/pymysql/protocol.py", line 221, in raise_for_error
    err.raise_mysql_exception(self._data)
    │   │                     │    └ <member '_data' of 'MysqlPacket' objects>
    │   │                     └ <pymysql.protocol.MysqlPacket object at 0x7f30980de1c0>
    │   └ <function raise_mysql_exception at 0x7f31f358c670>
    └ <module 'pymysql.err' from '/home/chase/.local/lib/python3.8/site-packages/pymysql/err.py'>
  File "/home/chase/.local/lib/python3.8/site-packages/pymysql/err.py", line 143, in raise_mysql_exception
    raise errorclass(errno, errval)
          │          │      └ "Duplicate entry '180.201.163.246:6800' for key 'device.PRIMARY'"
          │          └ 1062
          └ <class 'pymysql.err.IntegrityError'>

sqlalchemy.exc.IntegrityError: (pymysql.err.IntegrityError) (1062, "Duplicate entry '180.201.163.246:6800' for key 'device.PRIMARY'")
[SQL: UPDATE device SET server_id=%(server_id)s, ip=%(ip)s, username=%(username)s, password=%(password)s, address=%(address)s, port=%(port)s, valid=%(valid)s WHERE device.ip = %(ip_1)s]
[parameters: {'server_id': '180.201.163.246:6800', 'ip': '180.201.163.246', 'username': 'chase', 'password': '39009993209225382550485960903922705693679444762686044461338081457059629931783785590136354456254380944555894991649049112659682986579868615741353927235 ... (10 characters truncated) ... 51068641063254046924245468825746318035623762751530035663691474885151741880037557968383632384341930581618462680753335440784903904512241693615341613546', 'address': '/home/users/CT/pycharmproject/spiders/', 'port': 6800, 'valid': 1, 'ip_1': '180.201.163.246'}]
(Background on this error at: https://sqlalche.me/e/14/gkpj)
2022-05-13 23:02:53.082 | ERROR    | base.db.mysql:update:390 - 【mysql更新数据出错】
Traceback (most recent call last):

  File "/home/chase/.local/lib/python3.8/site-packages/sqlalchemy/engine/base.py", line 1771, in _execute_context
    self.dialect.do_execute(
    │    │       └ <function DefaultDialect.do_execute at 0x7f31f38f75e0>
    │    └ <sqlalchemy.dialects.mysql.pymysql.MySQLDialect_pymysql object at 0x7f3103ffde20>
    └ <sqlalchemy.engine.base.Connection object at 0x7f3098566130>
  File "/home/chase/.local/lib/python3.8/site-packages/sqlalchemy/engine/default.py", line 717, in do_execute
    cursor.execute(statement, parameters)
    │      │       │          └ {'server_id': '180.201.163.246:6800', 'ip': '180.201.163.246', 'username': 'chase', 'password': '7019686846211521868460886263...
    │      │       └ 'UPDATE device SET server_id=%(server_id)s, ip=%(ip)s, username=%(username)s, password=%(password)s, address=%(address)s, por...
    │      └ <function Cursor.execute at 0x7f31f354cdc0>
    └ <pymysql.cursors.Cursor object at 0x7f3038165d00>
  File "/home/chase/.local/lib/python3.8/site-packages/pymysql/cursors.py", line 148, in execute
    result = self._query(query)
             │    │      └ "UPDATE device SET server_id='180.201.163.246:6800', ip='180.201.163.246', username='chase', password='7019686846211521868460...
             │    └ <function Cursor._query at 0x7f31f34d7280>
             └ <pymysql.cursors.Cursor object at 0x7f3038165d00>
  File "/home/chase/.local/lib/python3.8/site-packages/pymysql/cursors.py", line 310, in _query
    conn.query(q)
    │    │     └ "UPDATE device SET server_id='180.201.163.246:6800', ip='180.201.163.246', username='chase', password='7019686846211521868460...
    │    └ <function Connection.query at 0x7f31f34e5670>
    └ <pymysql.connections.Connection object at 0x7f30b83d8ee0>
  File "/home/chase/.local/lib/python3.8/site-packages/pymysql/connections.py", line 548, in query
    self._affected_rows = self._read_query_result(unbuffered=unbuffered)
    │    │                │    │                             └ False
    │    │                │    └ <function Connection._read_query_result at 0x7f31f34e5ca0>
    │    │                └ <pymysql.connections.Connection object at 0x7f30b83d8ee0>
    │    └ 1
    └ <pymysql.connections.Connection object at 0x7f30b83d8ee0>
  File "/home/chase/.local/lib/python3.8/site-packages/pymysql/connections.py", line 775, in _read_query_result
    result.read()
    │      └ <function MySQLResult.read at 0x7f31f34e64c0>
    └ <pymysql.connections.MySQLResult object at 0x7f30186e2ac0>
  File "/home/chase/.local/lib/python3.8/site-packages/pymysql/connections.py", line 1156, in read
    first_packet = self.connection._read_packet()
                   │    └ None
                   └ <pymysql.connections.MySQLResult object at 0x7f30186e2ac0>
  File "/home/chase/.local/lib/python3.8/site-packages/pymysql/connections.py", line 725, in _read_packet
    packet.raise_for_error()
    │      └ <function MysqlPacket.raise_for_error at 0x7f31f34ddee0>
    └ <pymysql.protocol.MysqlPacket object at 0x7f3018656820>
  File "/home/chase/.local/lib/python3.8/site-packages/pymysql/protocol.py", line 221, in raise_for_error
    err.raise_mysql_exception(self._data)
    │   │                     │    └ <member '_data' of 'MysqlPacket' objects>
    │   │                     └ <pymysql.protocol.MysqlPacket object at 0x7f3018656820>
    │   └ <function raise_mysql_exception at 0x7f31f358c670>
    └ <module 'pymysql.err' from '/home/chase/.local/lib/python3.8/site-packages/pymysql/err.py'>
  File "/home/chase/.local/lib/python3.8/site-packages/pymysql/err.py", line 143, in raise_mysql_exception
    raise errorclass(errno, errval)
          │          │      └ "Duplicate entry '180.201.163.246:6800' for key 'device.PRIMARY'"
          │          └ 1062
          └ <class 'pymysql.err.IntegrityError'>

pymysql.err.IntegrityError: (1062, "Duplicate entry '180.201.163.246:6800' for key 'device.PRIMARY'")


The above exception was the direct cause of the following exception:


Traceback (most recent call last):

  File "/usr/lib/python3.8/threading.py", line 890, in _bootstrap
    self._bootstrap_inner()
    │    └ <function Thread._bootstrap_inner at 0x7f321bf29a60>
    └ <Thread(Thread-5523, started daemon 139838127322880)>
  File "/usr/lib/python3.8/threading.py", line 932, in _bootstrap_inner
    self.run()
    │    └ <function Thread.run at 0x7f321bf29790>
    └ <Thread(Thread-5523, started daemon 139838127322880)>
  File "/usr/lib/python3.8/threading.py", line 870, in run
    self._target(*self._args, **self._kwargs)
    │    │        │    │        │    └ {}
    │    │        │    │        └ <Thread(Thread-5523, started daemon 139838127322880)>
    │    │        │    └ ('ProjectManager.run_func_by_thread',)
    │    │        └ <Thread(Thread-5523, started daemon 139838127322880)>
    │    └ <bound method ProjectManager.get_request_from_keywords_hot of <monitor.projectManager.ProjectManager object at 0x7f31042e52e0>>
    └ <Thread(Thread-5523, started daemon 139838127322880)>

  File "/home/users/Scy/yuqing/spider/monitor/projectManager.py", line 799, in get_request_from_keywords_hot
    self.start_finished_spider_every_interval(project_names)
    │    │                                    └ ['default', 'test']
    │    └ <function ProjectManager.start_finished_spider_every_interval at 0x7f3104005280>
    └ <monitor.projectManager.ProjectManager object at 0x7f31042e52e0>

  File "/home/users/Scy/yuqing/spider/monitor/projectManager.py", line 784, in start_finished_spider_every_interval
    self[name].start_spider()
    │    └ 'default'
    └ <monitor.projectManager.ProjectManager object at 0x7f31042e52e0>

  File "/home/users/Scy/yuqing/spider/monitor/projectManager.py", line 366, in start_spider
    self.update_device_valid(device)
    │    │                   └ <monitor.deviceManager.DeviceC object at 0x7f3104029220>
    │    └ <function Project.update_device_valid at 0x7f3104003280>
    └ <monitor.projectManager.Project object at 0x7f3104029460>

  File "/home/users/Scy/yuqing/spider/monitor/projectManager.py", line 421, in update_device_valid
    self.database_manager.mysql.update(Device(**device.to_item()))
    │    │                │     │      │        │      └ <function DeviceC.to_item at 0x7f31f34ed310>
    │    │                │     │      │        └ <monitor.deviceManager.DeviceC object at 0x7f3104029220>
    │    │                │     │      └ <class 'base.db.mysql.Device'>
    │    │                │     └ <function Mysql.update at 0x7f31f35f4790>
    │    │                └ <base.db.mysql.Mysql object at 0x7f3103ffdfd0>
    │    └ <base.db.dbSlot.Slot object at 0x7f3103ffdf10>
    └ <monitor.projectManager.Project object at 0x7f3104029460>

> File "/home/users/Scy/yuqing/spider/base/db/mysql.py", line 375, in update
    row.update(new)
    │   │      └ {'server_id': '180.201.163.246:6800', 'ip': '180.201.163.246', 'username': 'chase', 'password': '7019686846211521868460886263...
    │   └ <function Query.update at 0x7f31f37333a0>
    └ <sqlalchemy.orm.query.Query object at 0x7f31000aea90>

  File "/home/chase/.local/lib/python3.8/site-packages/sqlalchemy/orm/query.py", line 3221, in update
    result = self.session.execute(
             │    │       └ <function Session.execute at 0x7f31f370faf0>
             │    └ <sqlalchemy.orm.session.Session object at 0x7f30381d8f70>
             └ <sqlalchemy.orm.query.Query object at 0x7f31000aea90>
  File "/home/chase/.local/lib/python3.8/site-packages/sqlalchemy/orm/session.py", line 1689, in execute
    result = conn._execute_20(statement, params or {}, execution_options)
             │    │           │          │             └ immutabledict({'synchronize_session': 'evaluate', '_sa_orm_update_options': default_update_options(_matched_objects=[], _reso...
             │    │           │          └ immutabledict({})
             │    │           └ <sqlalchemy.sql.annotation.AnnotatedUpdate object at 0x7f3058300cd0>
             │    └ <function Connection._execute_20 at 0x7f31f39bc790>
             └ <sqlalchemy.engine.base.Connection object at 0x7f3098566130>
  File "/home/chase/.local/lib/python3.8/site-packages/sqlalchemy/engine/base.py", line 1583, in _execute_20
    return meth(self, args_10style, kwargs_10style, execution_options)
           │    │     │             │               └ immutabledict({'synchronize_session': 'evaluate', '_sa_orm_update_options': default_update_options(_matched_objects=[], _reso...
           │    │     │             └ immutabledict({})
           │    │     └ ({},)
           │    └ <sqlalchemy.engine.base.Connection object at 0x7f3098566130>
           └ <bound method ClauseElement._execute_on_connection of <sqlalchemy.sql.annotation.AnnotatedUpdate object at 0x7f3058300cd0>>
  File "/home/chase/.local/lib/python3.8/site-packages/sqlalchemy/sql/elements.py", line 323, in _execute_on_connection
    return connection._execute_clauseelement(
           │          └ <function Connection._execute_clauseelement at 0x7f31f39bc5e0>
           └ <sqlalchemy.engine.base.Connection object at 0x7f3098566130>
  File "/home/chase/.local/lib/python3.8/site-packages/sqlalchemy/engine/base.py", line 1452, in _execute_clauseelement
    ret = self._execute_context(
          │    └ <function Connection._execute_context at 0x7f31f39bc8b0>
          └ <sqlalchemy.engine.base.Connection object at 0x7f3098566130>
  File "/home/chase/.local/lib/python3.8/site-packages/sqlalchemy/engine/base.py", line 1814, in _execute_context
    self._handle_dbapi_exception(
    │    └ <function Connection._handle_dbapi_exception at 0x7f31f39bca60>
    └ <sqlalchemy.engine.base.Connection object at 0x7f3098566130>
  File "/home/chase/.local/lib/python3.8/site-packages/sqlalchemy/engine/base.py", line 1995, in _handle_dbapi_exception
    util.raise_(
    │    └ <function raise_ at 0x7f31f3d7ea60>
    └ <module 'sqlalchemy.util' from '/home/chase/.local/lib/python3.8/site-packages/sqlalchemy/util/__init__.py'>
  File "/home/chase/.local/lib/python3.8/site-packages/sqlalchemy/util/compat.py", line 207, in raise_
    raise exception
  File "/home/chase/.local/lib/python3.8/site-packages/sqlalchemy/engine/base.py", line 1771, in _execute_context
    self.dialect.do_execute(
    │    │       └ <function DefaultDialect.do_execute at 0x7f31f38f75e0>
    │    └ <sqlalchemy.dialects.mysql.pymysql.MySQLDialect_pymysql object at 0x7f3103ffde20>
    └ <sqlalchemy.engine.base.Connection object at 0x7f3098566130>
  File "/home/chase/.local/lib/python3.8/site-packages/sqlalchemy/engine/default.py", line 717, in do_execute
    cursor.execute(statement, parameters)
    │      │       │          └ {'server_id': '180.201.163.246:6800', 'ip': '180.201.163.246', 'username': 'chase', 'password': '7019686846211521868460886263...
    │      │       └ 'UPDATE device SET server_id=%(server_id)s, ip=%(ip)s, username=%(username)s, password=%(password)s, address=%(address)s, por...
    │      └ <function Cursor.execute at 0x7f31f354cdc0>
    └ <pymysql.cursors.Cursor object at 0x7f3038165d00>
  File "/home/chase/.local/lib/python3.8/site-packages/pymysql/cursors.py", line 148, in execute
    result = self._query(query)
             │    │      └ "UPDATE device SET server_id='180.201.163.246:6800', ip='180.201.163.246', username='chase', password='7019686846211521868460...
             │    └ <function Cursor._query at 0x7f31f34d7280>
             └ <pymysql.cursors.Cursor object at 0x7f3038165d00>
  File "/home/chase/.local/lib/python3.8/site-packages/pymysql/cursors.py", line 310, in _query
    conn.query(q)
    │    │     └ "UPDATE device SET server_id='180.201.163.246:6800', ip='180.201.163.246', username='chase', password='7019686846211521868460...
    │    └ <function Connection.query at 0x7f31f34e5670>
    └ <pymysql.connections.Connection object at 0x7f30b83d8ee0>
  File "/home/chase/.local/lib/python3.8/site-packages/pymysql/connections.py", line 548, in query
    self._affected_rows = self._read_query_result(unbuffered=unbuffered)
    │    │                │    │                             └ False
    │    │                │    └ <function Connection._read_query_result at 0x7f31f34e5ca0>
    │    │                └ <pymysql.connections.Connection object at 0x7f30b83d8ee0>
    │    └ 1
    └ <pymysql.connections.Connection object at 0x7f30b83d8ee0>
  File "/home/chase/.local/lib/python3.8/site-packages/pymysql/connections.py", line 775, in _read_query_result
    result.read()
    │      └ <function MySQLResult.read at 0x7f31f34e64c0>
    └ <pymysql.connections.MySQLResult object at 0x7f30186e2ac0>
  File "/home/chase/.local/lib/python3.8/site-packages/pymysql/connections.py", line 1156, in read
    first_packet = self.connection._read_packet()
                   │    └ None
                   └ <pymysql.connections.MySQLResult object at 0x7f30186e2ac0>
  File "/home/chase/.local/lib/python3.8/site-packages/pymysql/connections.py", line 725, in _read_packet
    packet.raise_for_error()
    │      └ <function MysqlPacket.raise_for_error at 0x7f31f34ddee0>
    └ <pymysql.protocol.MysqlPacket object at 0x7f3018656820>
  File "/home/chase/.local/lib/python3.8/site-packages/pymysql/protocol.py", line 221, in raise_for_error
    err.raise_mysql_exception(self._data)
    │   │                     │    └ <member '_data' of 'MysqlPacket' objects>
    │   │                     └ <pymysql.protocol.MysqlPacket object at 0x7f3018656820>
    │   └ <function raise_mysql_exception at 0x7f31f358c670>
    └ <module 'pymysql.err' from '/home/chase/.local/lib/python3.8/site-packages/pymysql/err.py'>
  File "/home/chase/.local/lib/python3.8/site-packages/pymysql/err.py", line 143, in raise_mysql_exception
    raise errorclass(errno, errval)
          │          │      └ "Duplicate entry '180.201.163.246:6800' for key 'device.PRIMARY'"
          │          └ 1062
          └ <class 'pymysql.err.IntegrityError'>

sqlalchemy.exc.IntegrityError: (pymysql.err.IntegrityError) (1062, "Duplicate entry '180.201.163.246:6800' for key 'device.PRIMARY'")
[SQL: UPDATE device SET server_id=%(server_id)s, ip=%(ip)s, username=%(username)s, password=%(password)s, address=%(address)s, port=%(port)s, valid=%(valid)s WHERE device.ip = %(ip_1)s]
[parameters: {'server_id': '180.201.163.246:6800', 'ip': '180.201.163.246', 'username': 'chase', 'password': '70196868462115218684608862636472112541240467338595373883929800293842965292310547563292146957979173793163710626806949958998358768663451431947328994834 ... (10 characters truncated) ... 24995313838233547829179764388093623847716138565701057278475335125958094759304705702691168252182473431986563919077674403358684674162613140237187696038', 'address': '/home/users/CT/pycharmproject/spiders/', 'port': 6800, 'valid': 1, 'ip_1': '180.201.163.246'}]
(Background on this error at: https://sqlalche.me/e/14/gkpj)
2022-05-13 23:03:13.148 | ERROR    | base.db.mysql:update:390 - 【mysql更新数据出错】
Traceback (most recent call last):

  File "/home/chase/.local/lib/python3.8/site-packages/sqlalchemy/engine/base.py", line 1771, in _execute_context
    self.dialect.do_execute(
    │    │       └ <function DefaultDialect.do_execute at 0x7f31f38f75e0>
    │    └ <sqlalchemy.dialects.mysql.pymysql.MySQLDialect_pymysql object at 0x7f3103ffde20>
    └ <sqlalchemy.engine.base.Connection object at 0x7f31020ec640>
  File "/home/chase/.local/lib/python3.8/site-packages/sqlalchemy/engine/default.py", line 717, in do_execute
    cursor.execute(statement, parameters)
    │      │       │          └ {'server_id': '180.201.163.246:6800', 'ip': '180.201.163.246', 'username': 'chase', 'password': '4838140952268150085709125264...
    │      │       └ 'UPDATE device SET server_id=%(server_id)s, ip=%(ip)s, username=%(username)s, password=%(password)s, address=%(address)s, por...
    │      └ <function Cursor.execute at 0x7f31f354cdc0>
    └ <pymysql.cursors.Cursor object at 0x7f303823b4f0>
  File "/home/chase/.local/lib/python3.8/site-packages/pymysql/cursors.py", line 148, in execute
    result = self._query(query)
             │    │      └ "UPDATE device SET server_id='180.201.163.246:6800', ip='180.201.163.246', username='chase', password='4838140952268150085709...
             │    └ <function Cursor._query at 0x7f31f34d7280>
             └ <pymysql.cursors.Cursor object at 0x7f303823b4f0>
  File "/home/chase/.local/lib/python3.8/site-packages/pymysql/cursors.py", line 310, in _query
    conn.query(q)
    │    │     └ "UPDATE device SET server_id='180.201.163.246:6800', ip='180.201.163.246', username='chase', password='4838140952268150085709...
    │    └ <function Connection.query at 0x7f31f34e5670>
    └ <pymysql.connections.Connection object at 0x7f31021d3520>
  File "/home/chase/.local/lib/python3.8/site-packages/pymysql/connections.py", line 548, in query
    self._affected_rows = self._read_query_result(unbuffered=unbuffered)
    │    │                │    │                             └ False
    │    │                │    └ <function Connection._read_query_result at 0x7f31f34e5ca0>
    │    │                └ <pymysql.connections.Connection object at 0x7f31021d3520>
    │    └ 1
    └ <pymysql.connections.Connection object at 0x7f31021d3520>
  File "/home/chase/.local/lib/python3.8/site-packages/pymysql/connections.py", line 775, in _read_query_result
    result.read()
    │      └ <function MySQLResult.read at 0x7f31f34e64c0>
    └ <pymysql.connections.MySQLResult object at 0x7f301868f070>
  File "/home/chase/.local/lib/python3.8/site-packages/pymysql/connections.py", line 1156, in read
    first_packet = self.connection._read_packet()
                   │    └ None
                   └ <pymysql.connections.MySQLResult object at 0x7f301868f070>
  File "/home/chase/.local/lib/python3.8/site-packages/pymysql/connections.py", line 725, in _read_packet
    packet.raise_for_error()
    │      └ <function MysqlPacket.raise_for_error at 0x7f31f34ddee0>
    └ <pymysql.protocol.MysqlPacket object at 0x7f301823a730>
  File "/home/chase/.local/lib/python3.8/site-packages/pymysql/protocol.py", line 221, in raise_for_error
    err.raise_mysql_exception(self._data)
    │   │                     │    └ <member '_data' of 'MysqlPacket' objects>
    │   │                     └ <pymysql.protocol.MysqlPacket object at 0x7f301823a730>
    │   └ <function raise_mysql_exception at 0x7f31f358c670>
    └ <module 'pymysql.err' from '/home/chase/.local/lib/python3.8/site-packages/pymysql/err.py'>
  File "/home/chase/.local/lib/python3.8/site-packages/pymysql/err.py", line 143, in raise_mysql_exception
    raise errorclass(errno, errval)
          │          │      └ "Duplicate entry '180.201.163.246:6800' for key 'device.PRIMARY'"
          │          └ 1062
          └ <class 'pymysql.err.IntegrityError'>

pymysql.err.IntegrityError: (1062, "Duplicate entry '180.201.163.246:6800' for key 'device.PRIMARY'")


The above exception was the direct cause of the following exception:


Traceback (most recent call last):

  File "/usr/lib/python3.8/threading.py", line 890, in _bootstrap
    self._bootstrap_inner()
    │    └ <function Thread._bootstrap_inner at 0x7f321bf29a60>
    └ <Thread(Thread-5528, started daemon 139838135715584)>
  File "/usr/lib/python3.8/threading.py", line 932, in _bootstrap_inner
    self.run()
    │    └ <function Thread.run at 0x7f321bf29790>
    └ <Thread(Thread-5528, started daemon 139838135715584)>
  File "/usr/lib/python3.8/threading.py", line 870, in run
    self._target(*self._args, **self._kwargs)
    │    │        │    │        │    └ {}
    │    │        │    │        └ <Thread(Thread-5528, started daemon 139838135715584)>
    │    │        │    └ ('ProjectManager.run_func_by_thread',)
    │    │        └ <Thread(Thread-5528, started daemon 139838135715584)>
    │    └ <bound method ProjectManager.get_request_from_keywords_hot of <monitor.projectManager.ProjectManager object at 0x7f31042e52e0>>
    └ <Thread(Thread-5528, started daemon 139838135715584)>

  File "/home/users/Scy/yuqing/spider/monitor/projectManager.py", line 799, in get_request_from_keywords_hot
    self.start_finished_spider_every_interval(project_names)
    │    │                                    └ ['default', 'test']
    │    └ <function ProjectManager.start_finished_spider_every_interval at 0x7f3104005280>
    └ <monitor.projectManager.ProjectManager object at 0x7f31042e52e0>

  File "/home/users/Scy/yuqing/spider/monitor/projectManager.py", line 784, in start_finished_spider_every_interval
    self[name].start_spider()
    │    └ 'default'
    └ <monitor.projectManager.ProjectManager object at 0x7f31042e52e0>

  File "/home/users/Scy/yuqing/spider/monitor/projectManager.py", line 366, in start_spider
    self.update_device_valid(device)
    │    │                   └ <monitor.deviceManager.DeviceC object at 0x7f3104029220>
    │    └ <function Project.update_device_valid at 0x7f3104003280>
    └ <monitor.projectManager.Project object at 0x7f3104029460>

  File "/home/users/Scy/yuqing/spider/monitor/projectManager.py", line 421, in update_device_valid
    self.database_manager.mysql.update(Device(**device.to_item()))
    │    │                │     │      │        │      └ <function DeviceC.to_item at 0x7f31f34ed310>
    │    │                │     │      │        └ <monitor.deviceManager.DeviceC object at 0x7f3104029220>
    │    │                │     │      └ <class 'base.db.mysql.Device'>
    │    │                │     └ <function Mysql.update at 0x7f31f35f4790>
    │    │                └ <base.db.mysql.Mysql object at 0x7f3103ffdfd0>
    │    └ <base.db.dbSlot.Slot object at 0x7f3103ffdf10>
    └ <monitor.projectManager.Project object at 0x7f3104029460>

> File "/home/users/Scy/yuqing/spider/base/db/mysql.py", line 375, in update
    row.update(new)
    │   │      └ {'server_id': '180.201.163.246:6800', 'ip': '180.201.163.246', 'username': 'chase', 'password': '4838140952268150085709125264...
    │   └ <function Query.update at 0x7f31f37333a0>
    └ <sqlalchemy.orm.query.Query object at 0x7f30183f6160>

  File "/home/chase/.local/lib/python3.8/site-packages/sqlalchemy/orm/query.py", line 3221, in update
    result = self.session.execute(
             │    │       └ <function Session.execute at 0x7f31f370faf0>
             │    └ <sqlalchemy.orm.session.Session object at 0x7f30b8770eb0>
             └ <sqlalchemy.orm.query.Query object at 0x7f30183f6160>
  File "/home/chase/.local/lib/python3.8/site-packages/sqlalchemy/orm/session.py", line 1689, in execute
    result = conn._execute_20(statement, params or {}, execution_options)
             │    │           │          │             └ immutabledict({'synchronize_session': 'evaluate', '_sa_orm_update_options': default_update_options(_matched_objects=[], _reso...
             │    │           │          └ immutabledict({})
             │    │           └ <sqlalchemy.sql.annotation.AnnotatedUpdate object at 0x7f303823b6a0>
             │    └ <function Connection._execute_20 at 0x7f31f39bc790>
             └ <sqlalchemy.engine.base.Connection object at 0x7f31020ec640>
  File "/home/chase/.local/lib/python3.8/site-packages/sqlalchemy/engine/base.py", line 1583, in _execute_20
    return meth(self, args_10style, kwargs_10style, execution_options)
           │    │     │             │               └ immutabledict({'synchronize_session': 'evaluate', '_sa_orm_update_options': default_update_options(_matched_objects=[], _reso...
           │    │     │             └ immutabledict({})
           │    │     └ ({},)
           │    └ <sqlalchemy.engine.base.Connection object at 0x7f31020ec640>
           └ <bound method ClauseElement._execute_on_connection of <sqlalchemy.sql.annotation.AnnotatedUpdate object at 0x7f303823b6a0>>
  File "/home/chase/.local/lib/python3.8/site-packages/sqlalchemy/sql/elements.py", line 323, in _execute_on_connection
    return connection._execute_clauseelement(
           │          └ <function Connection._execute_clauseelement at 0x7f31f39bc5e0>
           └ <sqlalchemy.engine.base.Connection object at 0x7f31020ec640>
  File "/home/chase/.local/lib/python3.8/site-packages/sqlalchemy/engine/base.py", line 1452, in _execute_clauseelement
    ret = self._execute_context(
          │    └ <function Connection._execute_context at 0x7f31f39bc8b0>
          └ <sqlalchemy.engine.base.Connection object at 0x7f31020ec640>
  File "/home/chase/.local/lib/python3.8/site-packages/sqlalchemy/engine/base.py", line 1814, in _execute_context
    self._handle_dbapi_exception(
    │    └ <function Connection._handle_dbapi_exception at 0x7f31f39bca60>
    └ <sqlalchemy.engine.base.Connection object at 0x7f31020ec640>
  File "/home/chase/.local/lib/python3.8/site-packages/sqlalchemy/engine/base.py", line 1995, in _handle_dbapi_exception
    util.raise_(
    │    └ <function raise_ at 0x7f31f3d7ea60>
    └ <module 'sqlalchemy.util' from '/home/chase/.local/lib/python3.8/site-packages/sqlalchemy/util/__init__.py'>
  File "/home/chase/.local/lib/python3.8/site-packages/sqlalchemy/util/compat.py", line 207, in raise_
    raise exception
  File "/home/chase/.local/lib/python3.8/site-packages/sqlalchemy/engine/base.py", line 1771, in _execute_context
    self.dialect.do_execute(
    │    │       └ <function DefaultDialect.do_execute at 0x7f31f38f75e0>
    │    └ <sqlalchemy.dialects.mysql.pymysql.MySQLDialect_pymysql object at 0x7f3103ffde20>
    └ <sqlalchemy.engine.base.Connection object at 0x7f31020ec640>
  File "/home/chase/.local/lib/python3.8/site-packages/sqlalchemy/engine/default.py", line 717, in do_execute
    cursor.execute(statement, parameters)
    │      │       │          └ {'server_id': '180.201.163.246:6800', 'ip': '180.201.163.246', 'username': 'chase', 'password': '4838140952268150085709125264...
    │      │       └ 'UPDATE device SET server_id=%(server_id)s, ip=%(ip)s, username=%(username)s, password=%(password)s, address=%(address)s, por...
    │      └ <function Cursor.execute at 0x7f31f354cdc0>
    └ <pymysql.cursors.Cursor object at 0x7f303823b4f0>
  File "/home/chase/.local/lib/python3.8/site-packages/pymysql/cursors.py", line 148, in execute
    result = self._query(query)
             │    │      └ "UPDATE device SET server_id='180.201.163.246:6800', ip='180.201.163.246', username='chase', password='4838140952268150085709...
             │    └ <function Cursor._query at 0x7f31f34d7280>
             └ <pymysql.cursors.Cursor object at 0x7f303823b4f0>
  File "/home/chase/.local/lib/python3.8/site-packages/pymysql/cursors.py", line 310, in _query
    conn.query(q)
    │    │     └ "UPDATE device SET server_id='180.201.163.246:6800', ip='180.201.163.246', username='chase', password='4838140952268150085709...
    │    └ <function Connection.query at 0x7f31f34e5670>
    └ <pymysql.connections.Connection object at 0x7f31021d3520>
  File "/home/chase/.local/lib/python3.8/site-packages/pymysql/connections.py", line 548, in query
    self._affected_rows = self._read_query_result(unbuffered=unbuffered)
    │    │                │    │                             └ False
    │    │                │    └ <function Connection._read_query_result at 0x7f31f34e5ca0>
    │    │                └ <pymysql.connections.Connection object at 0x7f31021d3520>
    │    └ 1
    └ <pymysql.connections.Connection object at 0x7f31021d3520>
  File "/home/chase/.local/lib/python3.8/site-packages/pymysql/connections.py", line 775, in _read_query_result
    result.read()
    │      └ <function MySQLResult.read at 0x7f31f34e64c0>
    └ <pymysql.connections.MySQLResult object at 0x7f301868f070>
  File "/home/chase/.local/lib/python3.8/site-packages/pymysql/connections.py", line 1156, in read
    first_packet = self.connection._read_packet()
                   │    └ None
                   └ <pymysql.connections.MySQLResult object at 0x7f301868f070>
  File "/home/chase/.local/lib/python3.8/site-packages/pymysql/connections.py", line 725, in _read_packet
    packet.raise_for_error()
    │      └ <function MysqlPacket.raise_for_error at 0x7f31f34ddee0>
    └ <pymysql.protocol.MysqlPacket object at 0x7f301823a730>
  File "/home/chase/.local/lib/python3.8/site-packages/pymysql/protocol.py", line 221, in raise_for_error
    err.raise_mysql_exception(self._data)
    │   │                     │    └ <member '_data' of 'MysqlPacket' objects>
    │   │                     └ <pymysql.protocol.MysqlPacket object at 0x7f301823a730>
    │   └ <function raise_mysql_exception at 0x7f31f358c670>
    └ <module 'pymysql.err' from '/home/chase/.local/lib/python3.8/site-packages/pymysql/err.py'>
  File "/home/chase/.local/lib/python3.8/site-packages/pymysql/err.py", line 143, in raise_mysql_exception
    raise errorclass(errno, errval)
          │          │      └ "Duplicate entry '180.201.163.246:6800' for key 'device.PRIMARY'"
          │          └ 1062
          └ <class 'pymysql.err.IntegrityError'>

sqlalchemy.exc.IntegrityError: (pymysql.err.IntegrityError) (1062, "Duplicate entry '180.201.163.246:6800' for key 'device.PRIMARY'")
[SQL: UPDATE device SET server_id=%(server_id)s, ip=%(ip)s, username=%(username)s, password=%(password)s, address=%(address)s, port=%(port)s, valid=%(valid)s WHERE device.ip = %(ip_1)s]
[parameters: {'server_id': '180.201.163.246:6800', 'ip': '180.201.163.246', 'username': 'chase', 'password': '48381409522681500857091252645252949731392402112906762159832576021346088390819121386115523812216882786574501454914728693125406193493675252264778474539 ... (10 characters truncated) ... 58822089091710560503499422992274243187446581905854194481623895305937635132838806750016255817076483408813110233579749637215028706627790840452768779525', 'address': '/home/users/CT/pycharmproject/spiders/', 'port': 6800, 'valid': 1, 'ip_1': '180.201.163.246'}]
(Background on this error at: https://sqlalche.me/e/14/gkpj)
2022-05-13 23:03:29.173 | ERROR    | base.db.mysql:update:390 - 【mysql更新数据出错】
Traceback (most recent call last):

  File "/home/chase/.local/lib/python3.8/site-packages/sqlalchemy/engine/base.py", line 1771, in _execute_context
    self.dialect.do_execute(
    │    │       └ <function DefaultDialect.do_execute at 0x7f31f38f75e0>
    │    └ <sqlalchemy.dialects.mysql.pymysql.MySQLDialect_pymysql object at 0x7f3103ffde20>
    └ <sqlalchemy.engine.base.Connection object at 0x7f30581f2c70>
  File "/home/chase/.local/lib/python3.8/site-packages/sqlalchemy/engine/default.py", line 717, in do_execute
    cursor.execute(statement, parameters)
    │      │       │          └ {'server_id': '180.201.163.246:6800', 'ip': '180.201.163.246', 'username': 'chase', 'password': '2913565735013397662267842557...
    │      │       └ 'UPDATE device SET server_id=%(server_id)s, ip=%(ip)s, username=%(username)s, password=%(password)s, address=%(address)s, por...
    │      └ <function Cursor.execute at 0x7f31f354cdc0>
    └ <pymysql.cursors.Cursor object at 0x7f3038445880>
  File "/home/chase/.local/lib/python3.8/site-packages/pymysql/cursors.py", line 148, in execute
    result = self._query(query)
             │    │      └ "UPDATE device SET server_id='180.201.163.246:6800', ip='180.201.163.246', username='chase', password='2913565735013397662267...
             │    └ <function Cursor._query at 0x7f31f34d7280>
             └ <pymysql.cursors.Cursor object at 0x7f3038445880>
  File "/home/chase/.local/lib/python3.8/site-packages/pymysql/cursors.py", line 310, in _query
    conn.query(q)
    │    │     └ "UPDATE device SET server_id='180.201.163.246:6800', ip='180.201.163.246', username='chase', password='2913565735013397662267...
    │    └ <function Connection.query at 0x7f31f34e5670>
    └ <pymysql.connections.Connection object at 0x7f3098362be0>
  File "/home/chase/.local/lib/python3.8/site-packages/pymysql/connections.py", line 548, in query
    self._affected_rows = self._read_query_result(unbuffered=unbuffered)
    │    │                │    │                             └ False
    │    │                │    └ <function Connection._read_query_result at 0x7f31f34e5ca0>
    │    │                └ <pymysql.connections.Connection object at 0x7f3098362be0>
    │    └ 1
    └ <pymysql.connections.Connection object at 0x7f3098362be0>
  File "/home/chase/.local/lib/python3.8/site-packages/pymysql/connections.py", line 775, in _read_query_result
    result.read()
    │      └ <function MySQLResult.read at 0x7f31f34e64c0>
    └ <pymysql.connections.MySQLResult object at 0x7f30783b5310>
  File "/home/chase/.local/lib/python3.8/site-packages/pymysql/connections.py", line 1156, in read
    first_packet = self.connection._read_packet()
                   │    └ None
                   └ <pymysql.connections.MySQLResult object at 0x7f30783b5310>
  File "/home/chase/.local/lib/python3.8/site-packages/pymysql/connections.py", line 725, in _read_packet
    packet.raise_for_error()
    │      └ <function MysqlPacket.raise_for_error at 0x7f31f34ddee0>
    └ <pymysql.protocol.MysqlPacket object at 0x7f3058430070>
  File "/home/chase/.local/lib/python3.8/site-packages/pymysql/protocol.py", line 221, in raise_for_error
    err.raise_mysql_exception(self._data)
    │   │                     │    └ <member '_data' of 'MysqlPacket' objects>
    │   │                     └ <pymysql.protocol.MysqlPacket object at 0x7f3058430070>
    │   └ <function raise_mysql_exception at 0x7f31f358c670>
    └ <module 'pymysql.err' from '/home/chase/.local/lib/python3.8/site-packages/pymysql/err.py'>
  File "/home/chase/.local/lib/python3.8/site-packages/pymysql/err.py", line 143, in raise_mysql_exception
    raise errorclass(errno, errval)
          │          │      └ "Duplicate entry '180.201.163.246:6800' for key 'device.PRIMARY'"
          │          └ 1062
          └ <class 'pymysql.err.IntegrityError'>

pymysql.err.IntegrityError: (1062, "Duplicate entry '180.201.163.246:6800' for key 'device.PRIMARY'")


The above exception was the direct cause of the following exception:


Traceback (most recent call last):

  File "/usr/lib/python3.8/threading.py", line 890, in _bootstrap
    self._bootstrap_inner()
    │    └ <function Thread._bootstrap_inner at 0x7f321bf29a60>
    └ <Thread(Thread-5533, started daemon 139837984646912)>
  File "/usr/lib/python3.8/threading.py", line 932, in _bootstrap_inner
    self.run()
    │    └ <function Thread.run at 0x7f321bf29790>
    └ <Thread(Thread-5533, started daemon 139837984646912)>
  File "/usr/lib/python3.8/threading.py", line 870, in run
    self._target(*self._args, **self._kwargs)
    │    │        │    │        │    └ {}
    │    │        │    │        └ <Thread(Thread-5533, started daemon 139837984646912)>
    │    │        │    └ ('ProjectManager.run_func_by_thread',)
    │    │        └ <Thread(Thread-5533, started daemon 139837984646912)>
    │    └ <bound method ProjectManager.get_request_from_keywords_hot of <monitor.projectManager.ProjectManager object at 0x7f31042e52e0>>
    └ <Thread(Thread-5533, started daemon 139837984646912)>

  File "/home/users/Scy/yuqing/spider/monitor/projectManager.py", line 799, in get_request_from_keywords_hot
    self.start_finished_spider_every_interval(project_names)
    │    │                                    └ ['default', 'test']
    │    └ <function ProjectManager.start_finished_spider_every_interval at 0x7f3104005280>
    └ <monitor.projectManager.ProjectManager object at 0x7f31042e52e0>

  File "/home/users/Scy/yuqing/spider/monitor/projectManager.py", line 784, in start_finished_spider_every_interval
    self[name].start_spider()
    │    └ 'default'
    └ <monitor.projectManager.ProjectManager object at 0x7f31042e52e0>

  File "/home/users/Scy/yuqing/spider/monitor/projectManager.py", line 366, in start_spider
    self.update_device_valid(device)
    │    │                   └ <monitor.deviceManager.DeviceC object at 0x7f3104029220>
    │    └ <function Project.update_device_valid at 0x7f3104003280>
    └ <monitor.projectManager.Project object at 0x7f3104029460>

  File "/home/users/Scy/yuqing/spider/monitor/projectManager.py", line 421, in update_device_valid
    self.database_manager.mysql.update(Device(**device.to_item()))
    │    │                │     │      │        │      └ <function DeviceC.to_item at 0x7f31f34ed310>
    │    │                │     │      │        └ <monitor.deviceManager.DeviceC object at 0x7f3104029220>
    │    │                │     │      └ <class 'base.db.mysql.Device'>
    │    │                │     └ <function Mysql.update at 0x7f31f35f4790>
    │    │                └ <base.db.mysql.Mysql object at 0x7f3103ffdfd0>
    │    └ <base.db.dbSlot.Slot object at 0x7f3103ffdf10>
    └ <monitor.projectManager.Project object at 0x7f3104029460>

> File "/home/users/Scy/yuqing/spider/base/db/mysql.py", line 375, in update
    row.update(new)
    │   │      └ {'server_id': '180.201.163.246:6800', 'ip': '180.201.163.246', 'username': 'chase', 'password': '2913565735013397662267842557...
    │   └ <function Query.update at 0x7f31f37333a0>
    └ <sqlalchemy.orm.query.Query object at 0x7f3101ff71c0>

  File "/home/chase/.local/lib/python3.8/site-packages/sqlalchemy/orm/query.py", line 3221, in update
    result = self.session.execute(
             │    │       └ <function Session.execute at 0x7f31f370faf0>
             │    └ <sqlalchemy.orm.session.Session object at 0x7f303852e520>
             └ <sqlalchemy.orm.query.Query object at 0x7f3101ff71c0>
  File "/home/chase/.local/lib/python3.8/site-packages/sqlalchemy/orm/session.py", line 1689, in execute
    result = conn._execute_20(statement, params or {}, execution_options)
             │    │           │          │             └ immutabledict({'synchronize_session': 'evaluate', '_sa_orm_update_options': default_update_options(_matched_objects=[], _reso...
             │    │           │          └ immutabledict({})
             │    │           └ <sqlalchemy.sql.annotation.AnnotatedUpdate object at 0x7f303809dcd0>
             │    └ <function Connection._execute_20 at 0x7f31f39bc790>
             └ <sqlalchemy.engine.base.Connection object at 0x7f30581f2c70>
  File "/home/chase/.local/lib/python3.8/site-packages/sqlalchemy/engine/base.py", line 1583, in _execute_20
    return meth(self, args_10style, kwargs_10style, execution_options)
           │    │     │             │               └ immutabledict({'synchronize_session': 'evaluate', '_sa_orm_update_options': default_update_options(_matched_objects=[], _reso...
           │    │     │             └ immutabledict({})
           │    │     └ ({},)
           │    └ <sqlalchemy.engine.base.Connection object at 0x7f30581f2c70>
           └ <bound method ClauseElement._execute_on_connection of <sqlalchemy.sql.annotation.AnnotatedUpdate object at 0x7f303809dcd0>>
  File "/home/chase/.local/lib/python3.8/site-packages/sqlalchemy/sql/elements.py", line 323, in _execute_on_connection
    return connection._execute_clauseelement(
           │          └ <function Connection._execute_clauseelement at 0x7f31f39bc5e0>
           └ <sqlalchemy.engine.base.Connection object at 0x7f30581f2c70>
  File "/home/chase/.local/lib/python3.8/site-packages/sqlalchemy/engine/base.py", line 1452, in _execute_clauseelement
    ret = self._execute_context(
          │    └ <function Connection._execute_context at 0x7f31f39bc8b0>
          └ <sqlalchemy.engine.base.Connection object at 0x7f30581f2c70>
  File "/home/chase/.local/lib/python3.8/site-packages/sqlalchemy/engine/base.py", line 1814, in _execute_context
    self._handle_dbapi_exception(
    │    └ <function Connection._handle_dbapi_exception at 0x7f31f39bca60>
    └ <sqlalchemy.engine.base.Connection object at 0x7f30581f2c70>
  File "/home/chase/.local/lib/python3.8/site-packages/sqlalchemy/engine/base.py", line 1995, in _handle_dbapi_exception
    util.raise_(
    │    └ <function raise_ at 0x7f31f3d7ea60>
    └ <module 'sqlalchemy.util' from '/home/chase/.local/lib/python3.8/site-packages/sqlalchemy/util/__init__.py'>
  File "/home/chase/.local/lib/python3.8/site-packages/sqlalchemy/util/compat.py", line 207, in raise_
    raise exception
  File "/home/chase/.local/lib/python3.8/site-packages/sqlalchemy/engine/base.py", line 1771, in _execute_context
    self.dialect.do_execute(
    │    │       └ <function DefaultDialect.do_execute at 0x7f31f38f75e0>
    │    └ <sqlalchemy.dialects.mysql.pymysql.MySQLDialect_pymysql object at 0x7f3103ffde20>
    └ <sqlalchemy.engine.base.Connection object at 0x7f30581f2c70>
  File "/home/chase/.local/lib/python3.8/site-packages/sqlalchemy/engine/default.py", line 717, in do_execute
    cursor.execute(statement, parameters)
    │      │       │          └ {'server_id': '180.201.163.246:6800', 'ip': '180.201.163.246', 'username': 'chase', 'password': '2913565735013397662267842557...
    │      │       └ 'UPDATE device SET server_id=%(server_id)s, ip=%(ip)s, username=%(username)s, password=%(password)s, address=%(address)s, por...
    │      └ <function Cursor.execute at 0x7f31f354cdc0>
    └ <pymysql.cursors.Cursor object at 0x7f3038445880>
  File "/home/chase/.local/lib/python3.8/site-packages/pymysql/cursors.py", line 148, in execute
    result = self._query(query)
             │    │      └ "UPDATE device SET server_id='180.201.163.246:6800', ip='180.201.163.246', username='chase', password='2913565735013397662267...
             │    └ <function Cursor._query at 0x7f31f34d7280>
             └ <pymysql.cursors.Cursor object at 0x7f3038445880>
  File "/home/chase/.local/lib/python3.8/site-packages/pymysql/cursors.py", line 310, in _query
    conn.query(q)
    │    │     └ "UPDATE device SET server_id='180.201.163.246:6800', ip='180.201.163.246', username='chase', password='2913565735013397662267...
    │    └ <function Connection.query at 0x7f31f34e5670>
    └ <pymysql.connections.Connection object at 0x7f3098362be0>
  File "/home/chase/.local/lib/python3.8/site-packages/pymysql/connections.py", line 548, in query
    self._affected_rows = self._read_query_result(unbuffered=unbuffered)
    │    │                │    │                             └ False
    │    │                │    └ <function Connection._read_query_result at 0x7f31f34e5ca0>
    │    │                └ <pymysql.connections.Connection object at 0x7f3098362be0>
    │    └ 1
    └ <pymysql.connections.Connection object at 0x7f3098362be0>
  File "/home/chase/.local/lib/python3.8/site-packages/pymysql/connections.py", line 775, in _read_query_result
    result.read()
    │      └ <function MySQLResult.read at 0x7f31f34e64c0>
    └ <pymysql.connections.MySQLResult object at 0x7f30783b5310>
  File "/home/chase/.local/lib/python3.8/site-packages/pymysql/connections.py", line 1156, in read
    first_packet = self.connection._read_packet()
                   │    └ None
                   └ <pymysql.connections.MySQLResult object at 0x7f30783b5310>
  File "/home/chase/.local/lib/python3.8/site-packages/pymysql/connections.py", line 725, in _read_packet
    packet.raise_for_error()
    │      └ <function MysqlPacket.raise_for_error at 0x7f31f34ddee0>
    └ <pymysql.protocol.MysqlPacket object at 0x7f3058430070>
  File "/home/chase/.local/lib/python3.8/site-packages/pymysql/protocol.py", line 221, in raise_for_error
    err.raise_mysql_exception(self._data)
    │   │                     │    └ <member '_data' of 'MysqlPacket' objects>
    │   │                     └ <pymysql.protocol.MysqlPacket object at 0x7f3058430070>
    │   └ <function raise_mysql_exception at 0x7f31f358c670>
    └ <module 'pymysql.err' from '/home/chase/.local/lib/python3.8/site-packages/pymysql/err.py'>
  File "/home/chase/.local/lib/python3.8/site-packages/pymysql/err.py", line 143, in raise_mysql_exception
    raise errorclass(errno, errval)
          │          │      └ "Duplicate entry '180.201.163.246:6800' for key 'device.PRIMARY'"
          │          └ 1062
          └ <class 'pymysql.err.IntegrityError'>

sqlalchemy.exc.IntegrityError: (pymysql.err.IntegrityError) (1062, "Duplicate entry '180.201.163.246:6800' for key 'device.PRIMARY'")
[SQL: UPDATE device SET server_id=%(server_id)s, ip=%(ip)s, username=%(username)s, password=%(password)s, address=%(address)s, port=%(port)s, valid=%(valid)s WHERE device.ip = %(ip_1)s]
[parameters: {'server_id': '180.201.163.246:6800', 'ip': '180.201.163.246', 'username': 'chase', 'password': '29135657350133976622678425576669430262404712814379136252937394454569317437406098731430733765434374659516747895595286282432148043966571010859846100623 ... (10 characters truncated) ... 45010571321538496067718265190952827665430741514445623602094047959621548368702005220345352388934459353927945987375085766750137159131940960221313191731', 'address': '/home/users/CT/pycharmproject/spiders/', 'port': 6800, 'valid': 1, 'ip_1': '180.201.163.246'}]
(Background on this error at: https://sqlalche.me/e/14/gkpj)
2022-05-13 23:03:48.120 | ERROR    | base.db.mysql:update:390 - 【mysql更新数据出错】
Traceback (most recent call last):

  File "/home/chase/.local/lib/python3.8/site-packages/sqlalchemy/engine/base.py", line 1771, in _execute_context
    self.dialect.do_execute(
    │    │       └ <function DefaultDialect.do_execute at 0x7f31f38f75e0>
    │    └ <sqlalchemy.dialects.mysql.pymysql.MySQLDialect_pymysql object at 0x7f3103ffde20>
    └ <sqlalchemy.engine.base.Connection object at 0x7f30583bf940>
  File "/home/chase/.local/lib/python3.8/site-packages/sqlalchemy/engine/default.py", line 717, in do_execute
    cursor.execute(statement, parameters)
    │      │       │          └ {'server_id': '180.201.163.246:6800', 'ip': '180.201.163.246', 'username': 'chase', 'password': '2623117199920443286212925788...
    │      │       └ 'UPDATE device SET server_id=%(server_id)s, ip=%(ip)s, username=%(username)s, password=%(password)s, address=%(address)s, por...
    │      └ <function Cursor.execute at 0x7f31f354cdc0>
    └ <pymysql.cursors.Cursor object at 0x7f310230dd30>
  File "/home/chase/.local/lib/python3.8/site-packages/pymysql/cursors.py", line 148, in execute
    result = self._query(query)
             │    │      └ "UPDATE device SET server_id='180.201.163.246:6800', ip='180.201.163.246', username='chase', password='2623117199920443286212...
             │    └ <function Cursor._query at 0x7f31f34d7280>
             └ <pymysql.cursors.Cursor object at 0x7f310230dd30>
  File "/home/chase/.local/lib/python3.8/site-packages/pymysql/cursors.py", line 310, in _query
    conn.query(q)
    │    │     └ "UPDATE device SET server_id='180.201.163.246:6800', ip='180.201.163.246', username='chase', password='2623117199920443286212...
    │    └ <function Connection.query at 0x7f31f34e5670>
    └ <pymysql.connections.Connection object at 0x7f3038418f10>
  File "/home/chase/.local/lib/python3.8/site-packages/pymysql/connections.py", line 548, in query
    self._affected_rows = self._read_query_result(unbuffered=unbuffered)
    │    │                │    │                             └ False
    │    │                │    └ <function Connection._read_query_result at 0x7f31f34e5ca0>
    │    │                └ <pymysql.connections.Connection object at 0x7f3038418f10>
    │    └ 1
    └ <pymysql.connections.Connection object at 0x7f3038418f10>
  File "/home/chase/.local/lib/python3.8/site-packages/pymysql/connections.py", line 775, in _read_query_result
    result.read()
    │      └ <function MySQLResult.read at 0x7f31f34e64c0>
    └ <pymysql.connections.MySQLResult object at 0x7f31000573a0>
  File "/home/chase/.local/lib/python3.8/site-packages/pymysql/connections.py", line 1156, in read
    first_packet = self.connection._read_packet()
                   │    └ None
                   └ <pymysql.connections.MySQLResult object at 0x7f31000573a0>
  File "/home/chase/.local/lib/python3.8/site-packages/pymysql/connections.py", line 725, in _read_packet
    packet.raise_for_error()
    │      └ <function MysqlPacket.raise_for_error at 0x7f31f34ddee0>
    └ <pymysql.protocol.MysqlPacket object at 0x7f307842c8e0>
  File "/home/chase/.local/lib/python3.8/site-packages/pymysql/protocol.py", line 221, in raise_for_error
    err.raise_mysql_exception(self._data)
    │   │                     │    └ <member '_data' of 'MysqlPacket' objects>
    │   │                     └ <pymysql.protocol.MysqlPacket object at 0x7f307842c8e0>
    │   └ <function raise_mysql_exception at 0x7f31f358c670>
    └ <module 'pymysql.err' from '/home/chase/.local/lib/python3.8/site-packages/pymysql/err.py'>
  File "/home/chase/.local/lib/python3.8/site-packages/pymysql/err.py", line 143, in raise_mysql_exception
    raise errorclass(errno, errval)
          │          │      └ "Duplicate entry '180.201.163.246:6800' for key 'device.PRIMARY'"
          │          └ 1062
          └ <class 'pymysql.err.IntegrityError'>

pymysql.err.IntegrityError: (1062, "Duplicate entry '180.201.163.246:6800' for key 'device.PRIMARY'")


The above exception was the direct cause of the following exception:


Traceback (most recent call last):

  File "/usr/lib/python3.8/threading.py", line 890, in _bootstrap
    self._bootstrap_inner()
    │    └ <function Thread._bootstrap_inner at 0x7f321bf29a60>
    └ <Thread(Thread-5538, started daemon 139838018217728)>
  File "/usr/lib/python3.8/threading.py", line 932, in _bootstrap_inner
    self.run()
    │    └ <function Thread.run at 0x7f321bf29790>
    └ <Thread(Thread-5538, started daemon 139838018217728)>
  File "/usr/lib/python3.8/threading.py", line 870, in run
    self._target(*self._args, **self._kwargs)
    │    │        │    │        │    └ {}
    │    │        │    │        └ <Thread(Thread-5538, started daemon 139838018217728)>
    │    │        │    └ ('ProjectManager.run_func_by_thread',)
    │    │        └ <Thread(Thread-5538, started daemon 139838018217728)>
    │    └ <bound method ProjectManager.get_request_from_keywords_hot of <monitor.projectManager.ProjectManager object at 0x7f31042e52e0>>
    └ <Thread(Thread-5538, started daemon 139838018217728)>

  File "/home/users/Scy/yuqing/spider/monitor/projectManager.py", line 799, in get_request_from_keywords_hot
    self.start_finished_spider_every_interval(project_names)
    │    │                                    └ ['default', 'test']
    │    └ <function ProjectManager.start_finished_spider_every_interval at 0x7f3104005280>
    └ <monitor.projectManager.ProjectManager object at 0x7f31042e52e0>

  File "/home/users/Scy/yuqing/spider/monitor/projectManager.py", line 784, in start_finished_spider_every_interval
    self[name].start_spider()
    │    └ 'default'
    └ <monitor.projectManager.ProjectManager object at 0x7f31042e52e0>

  File "/home/users/Scy/yuqing/spider/monitor/projectManager.py", line 366, in start_spider
    self.update_device_valid(device)
    │    │                   └ <monitor.deviceManager.DeviceC object at 0x7f3104029220>
    │    └ <function Project.update_device_valid at 0x7f3104003280>
    └ <monitor.projectManager.Project object at 0x7f3104029460>

  File "/home/users/Scy/yuqing/spider/monitor/projectManager.py", line 421, in update_device_valid
    self.database_manager.mysql.update(Device(**device.to_item()))
    │    │                │     │      │        │      └ <function DeviceC.to_item at 0x7f31f34ed310>
    │    │                │     │      │        └ <monitor.deviceManager.DeviceC object at 0x7f3104029220>
    │    │                │     │      └ <class 'base.db.mysql.Device'>
    │    │                │     └ <function Mysql.update at 0x7f31f35f4790>
    │    │                └ <base.db.mysql.Mysql object at 0x7f3103ffdfd0>
    │    └ <base.db.dbSlot.Slot object at 0x7f3103ffdf10>
    └ <monitor.projectManager.Project object at 0x7f3104029460>

> File "/home/users/Scy/yuqing/spider/base/db/mysql.py", line 375, in update
    row.update(new)
    │   │      └ {'server_id': '180.201.163.246:6800', 'ip': '180.201.163.246', 'username': 'chase', 'password': '2623117199920443286212925788...
    │   └ <function Query.update at 0x7f31f37333a0>
    └ <sqlalchemy.orm.query.Query object at 0x7f301821a550>

  File "/home/chase/.local/lib/python3.8/site-packages/sqlalchemy/orm/query.py", line 3221, in update
    result = self.session.execute(
             │    │       └ <function Session.execute at 0x7f31f370faf0>
             │    └ <sqlalchemy.orm.session.Session object at 0x7f3100157130>
             └ <sqlalchemy.orm.query.Query object at 0x7f301821a550>
  File "/home/chase/.local/lib/python3.8/site-packages/sqlalchemy/orm/session.py", line 1689, in execute
    result = conn._execute_20(statement, params or {}, execution_options)
             │    │           │          │             └ immutabledict({'synchronize_session': 'evaluate', '_sa_orm_update_options': default_update_options(_matched_objects=[], _reso...
             │    │           │          └ immutabledict({})
             │    │           └ <sqlalchemy.sql.annotation.AnnotatedUpdate object at 0x7f30b86f9dc0>
             │    └ <function Connection._execute_20 at 0x7f31f39bc790>
             └ <sqlalchemy.engine.base.Connection object at 0x7f30583bf940>
  File "/home/chase/.local/lib/python3.8/site-packages/sqlalchemy/engine/base.py", line 1583, in _execute_20
    return meth(self, args_10style, kwargs_10style, execution_options)
           │    │     │             │               └ immutabledict({'synchronize_session': 'evaluate', '_sa_orm_update_options': default_update_options(_matched_objects=[], _reso...
           │    │     │             └ immutabledict({})
           │    │     └ ({},)
           │    └ <sqlalchemy.engine.base.Connection object at 0x7f30583bf940>
           └ <bound method ClauseElement._execute_on_connection of <sqlalchemy.sql.annotation.AnnotatedUpdate object at 0x7f30b86f9dc0>>
  File "/home/chase/.local/lib/python3.8/site-packages/sqlalchemy/sql/elements.py", line 323, in _execute_on_connection
    return connection._execute_clauseelement(
           │          └ <function Connection._execute_clauseelement at 0x7f31f39bc5e0>
           └ <sqlalchemy.engine.base.Connection object at 0x7f30583bf940>
  File "/home/chase/.local/lib/python3.8/site-packages/sqlalchemy/engine/base.py", line 1452, in _execute_clauseelement
    ret = self._execute_context(
          │    └ <function Connection._execute_context at 0x7f31f39bc8b0>
          └ <sqlalchemy.engine.base.Connection object at 0x7f30583bf940>
  File "/home/chase/.local/lib/python3.8/site-packages/sqlalchemy/engine/base.py", line 1814, in _execute_context
    self._handle_dbapi_exception(
    │    └ <function Connection._handle_dbapi_exception at 0x7f31f39bca60>
    └ <sqlalchemy.engine.base.Connection object at 0x7f30583bf940>
  File "/home/chase/.local/lib/python3.8/site-packages/sqlalchemy/engine/base.py", line 1995, in _handle_dbapi_exception
    util.raise_(
    │    └ <function raise_ at 0x7f31f3d7ea60>
    └ <module 'sqlalchemy.util' from '/home/chase/.local/lib/python3.8/site-packages/sqlalchemy/util/__init__.py'>
  File "/home/chase/.local/lib/python3.8/site-packages/sqlalchemy/util/compat.py", line 207, in raise_
    raise exception
  File "/home/chase/.local/lib/python3.8/site-packages/sqlalchemy/engine/base.py", line 1771, in _execute_context
    self.dialect.do_execute(
    │    │       └ <function DefaultDialect.do_execute at 0x7f31f38f75e0>
    │    └ <sqlalchemy.dialects.mysql.pymysql.MySQLDialect_pymysql object at 0x7f3103ffde20>
    └ <sqlalchemy.engine.base.Connection object at 0x7f30583bf940>
  File "/home/chase/.local/lib/python3.8/site-packages/sqlalchemy/engine/default.py", line 717, in do_execute
    cursor.execute(statement, parameters)
    │      │       │          └ {'server_id': '180.201.163.246:6800', 'ip': '180.201.163.246', 'username': 'chase', 'password': '2623117199920443286212925788...
    │      │       └ 'UPDATE device SET server_id=%(server_id)s, ip=%(ip)s, username=%(username)s, password=%(password)s, address=%(address)s, por...
    │      └ <function Cursor.execute at 0x7f31f354cdc0>
    └ <pymysql.cursors.Cursor object at 0x7f310230dd30>
  File "/home/chase/.local/lib/python3.8/site-packages/pymysql/cursors.py", line 148, in execute
    result = self._query(query)
             │    │      └ "UPDATE device SET server_id='180.201.163.246:6800', ip='180.201.163.246', username='chase', password='2623117199920443286212...
             │    └ <function Cursor._query at 0x7f31f34d7280>
             └ <pymysql.cursors.Cursor object at 0x7f310230dd30>
  File "/home/chase/.local/lib/python3.8/site-packages/pymysql/cursors.py", line 310, in _query
    conn.query(q)
    │    │     └ "UPDATE device SET server_id='180.201.163.246:6800', ip='180.201.163.246', username='chase', password='2623117199920443286212...
    │    └ <function Connection.query at 0x7f31f34e5670>
    └ <pymysql.connections.Connection object at 0x7f3038418f10>
  File "/home/chase/.local/lib/python3.8/site-packages/pymysql/connections.py", line 548, in query
    self._affected_rows = self._read_query_result(unbuffered=unbuffered)
    │    │                │    │                             └ False
    │    │                │    └ <function Connection._read_query_result at 0x7f31f34e5ca0>
    │    │                └ <pymysql.connections.Connection object at 0x7f3038418f10>
    │    └ 1
    └ <pymysql.connections.Connection object at 0x7f3038418f10>
  File "/home/chase/.local/lib/python3.8/site-packages/pymysql/connections.py", line 775, in _read_query_result
    result.read()
    │      └ <function MySQLResult.read at 0x7f31f34e64c0>
    └ <pymysql.connections.MySQLResult object at 0x7f31000573a0>
  File "/home/chase/.local/lib/python3.8/site-packages/pymysql/connections.py", line 1156, in read
    first_packet = self.connection._read_packet()
                   │    └ None
                   └ <pymysql.connections.MySQLResult object at 0x7f31000573a0>
  File "/home/chase/.local/lib/python3.8/site-packages/pymysql/connections.py", line 725, in _read_packet
    packet.raise_for_error()
    │      └ <function MysqlPacket.raise_for_error at 0x7f31f34ddee0>
    └ <pymysql.protocol.MysqlPacket object at 0x7f307842c8e0>
  File "/home/chase/.local/lib/python3.8/site-packages/pymysql/protocol.py", line 221, in raise_for_error
    err.raise_mysql_exception(self._data)
    │   │                     │    └ <member '_data' of 'MysqlPacket' objects>
    │   │                     └ <pymysql.protocol.MysqlPacket object at 0x7f307842c8e0>
    │   └ <function raise_mysql_exception at 0x7f31f358c670>
    └ <module 'pymysql.err' from '/home/chase/.local/lib/python3.8/site-packages/pymysql/err.py'>
  File "/home/chase/.local/lib/python3.8/site-packages/pymysql/err.py", line 143, in raise_mysql_exception
    raise errorclass(errno, errval)
          │          │      └ "Duplicate entry '180.201.163.246:6800' for key 'device.PRIMARY'"
          │          └ 1062
          └ <class 'pymysql.err.IntegrityError'>

sqlalchemy.exc.IntegrityError: (pymysql.err.IntegrityError) (1062, "Duplicate entry '180.201.163.246:6800' for key 'device.PRIMARY'")
[SQL: UPDATE device SET server_id=%(server_id)s, ip=%(ip)s, username=%(username)s, password=%(password)s, address=%(address)s, port=%(port)s, valid=%(valid)s WHERE device.ip = %(ip_1)s]
[parameters: {'server_id': '180.201.163.246:6800', 'ip': '180.201.163.246', 'username': 'chase', 'password': '26231171999204432862129257889738654079595814670386992538120084469085877689516773092200047202052190596191613278530145418584656782402539371287768433631 ... (10 characters truncated) ... 94103842198785854063138901964603495287433966709412747428145347619602477533305481720177940556306378758249855270613983078297055784528574493004379410039', 'address': '/home/users/CT/pycharmproject/spiders/', 'port': 6800, 'valid': 1, 'ip_1': '180.201.163.246'}]
(Background on this error at: https://sqlalche.me/e/14/gkpj)
2022-05-13 23:04:04.684 | ERROR    | base.db.mysql:update:390 - 【mysql更新数据出错】
Traceback (most recent call last):

  File "/home/chase/.local/lib/python3.8/site-packages/sqlalchemy/engine/base.py", line 1771, in _execute_context
    self.dialect.do_execute(
    │    │       └ <function DefaultDialect.do_execute at 0x7f31f38f75e0>
    │    └ <sqlalchemy.dialects.mysql.pymysql.MySQLDialect_pymysql object at 0x7f3103ffde20>
    └ <sqlalchemy.engine.base.Connection object at 0x7f30786f29d0>
  File "/home/chase/.local/lib/python3.8/site-packages/sqlalchemy/engine/default.py", line 717, in do_execute
    cursor.execute(statement, parameters)
    │      │       │          └ {'server_id': '180.201.163.246:6800', 'ip': '180.201.163.246', 'username': 'chase', 'password': '7322450940600966835491851077...
    │      │       └ 'UPDATE device SET server_id=%(server_id)s, ip=%(ip)s, username=%(username)s, password=%(password)s, address=%(address)s, por...
    │      └ <function Cursor.execute at 0x7f31f354cdc0>
    └ <pymysql.cursors.Cursor object at 0x7f30d81209d0>
  File "/home/chase/.local/lib/python3.8/site-packages/pymysql/cursors.py", line 148, in execute
    result = self._query(query)
             │    │      └ "UPDATE device SET server_id='180.201.163.246:6800', ip='180.201.163.246', username='chase', password='7322450940600966835491...
             │    └ <function Cursor._query at 0x7f31f34d7280>
             └ <pymysql.cursors.Cursor object at 0x7f30d81209d0>
  File "/home/chase/.local/lib/python3.8/site-packages/pymysql/cursors.py", line 310, in _query
    conn.query(q)
    │    │     └ "UPDATE device SET server_id='180.201.163.246:6800', ip='180.201.163.246', username='chase', password='7322450940600966835491...
    │    └ <function Connection.query at 0x7f31f34e5670>
    └ <pymysql.connections.Connection object at 0x7f30d80b3970>
  File "/home/chase/.local/lib/python3.8/site-packages/pymysql/connections.py", line 548, in query
    self._affected_rows = self._read_query_result(unbuffered=unbuffered)
    │    │                │    │                             └ False
    │    │                │    └ <function Connection._read_query_result at 0x7f31f34e5ca0>
    │    │                └ <pymysql.connections.Connection object at 0x7f30d80b3970>
    │    └ 1
    └ <pymysql.connections.Connection object at 0x7f30d80b3970>
  File "/home/chase/.local/lib/python3.8/site-packages/pymysql/connections.py", line 775, in _read_query_result
    result.read()
    │      └ <function MySQLResult.read at 0x7f31f34e64c0>
    └ <pymysql.connections.MySQLResult object at 0x7f31023e0520>
  File "/home/chase/.local/lib/python3.8/site-packages/pymysql/connections.py", line 1156, in read
    first_packet = self.connection._read_packet()
                   │    └ None
                   └ <pymysql.connections.MySQLResult object at 0x7f31023e0520>
  File "/home/chase/.local/lib/python3.8/site-packages/pymysql/connections.py", line 725, in _read_packet
    packet.raise_for_error()
    │      └ <function MysqlPacket.raise_for_error at 0x7f31f34ddee0>
    └ <pymysql.protocol.MysqlPacket object at 0x7f3098599340>
  File "/home/chase/.local/lib/python3.8/site-packages/pymysql/protocol.py", line 221, in raise_for_error
    err.raise_mysql_exception(self._data)
    │   │                     │    └ <member '_data' of 'MysqlPacket' objects>
    │   │                     └ <pymysql.protocol.MysqlPacket object at 0x7f3098599340>
    │   └ <function raise_mysql_exception at 0x7f31f358c670>
    └ <module 'pymysql.err' from '/home/chase/.local/lib/python3.8/site-packages/pymysql/err.py'>
  File "/home/chase/.local/lib/python3.8/site-packages/pymysql/err.py", line 143, in raise_mysql_exception
    raise errorclass(errno, errval)
          │          │      └ "Duplicate entry '180.201.163.246:6800' for key 'device.PRIMARY'"
          │          └ 1062
          └ <class 'pymysql.err.IntegrityError'>

pymysql.err.IntegrityError: (1062, "Duplicate entry '180.201.163.246:6800' for key 'device.PRIMARY'")


The above exception was the direct cause of the following exception:


Traceback (most recent call last):

  File "/usr/lib/python3.8/threading.py", line 890, in _bootstrap
    self._bootstrap_inner()
    │    └ <function Thread._bootstrap_inner at 0x7f321bf29a60>
    └ <Thread(Thread-5542, started daemon 139837900719872)>
  File "/usr/lib/python3.8/threading.py", line 932, in _bootstrap_inner
    self.run()
    │    └ <function Thread.run at 0x7f321bf29790>
    └ <Thread(Thread-5542, started daemon 139837900719872)>
  File "/usr/lib/python3.8/threading.py", line 870, in run
    self._target(*self._args, **self._kwargs)
    │    │        │    │        │    └ {}
    │    │        │    │        └ <Thread(Thread-5542, started daemon 139837900719872)>
    │    │        │    └ ('ProjectManager.run_func_by_thread',)
    │    │        └ <Thread(Thread-5542, started daemon 139837900719872)>
    │    └ <bound method ProjectManager.get_request_from_keywords_hot of <monitor.projectManager.ProjectManager object at 0x7f31042e52e0>>
    └ <Thread(Thread-5542, started daemon 139837900719872)>

  File "/home/users/Scy/yuqing/spider/monitor/projectManager.py", line 799, in get_request_from_keywords_hot
    self.start_finished_spider_every_interval(project_names)
    │    │                                    └ ['default', 'test']
    │    └ <function ProjectManager.start_finished_spider_every_interval at 0x7f3104005280>
    └ <monitor.projectManager.ProjectManager object at 0x7f31042e52e0>

  File "/home/users/Scy/yuqing/spider/monitor/projectManager.py", line 784, in start_finished_spider_every_interval
    self[name].start_spider()
    │    └ 'default'
    └ <monitor.projectManager.ProjectManager object at 0x7f31042e52e0>

  File "/home/users/Scy/yuqing/spider/monitor/projectManager.py", line 366, in start_spider
    self.update_device_valid(device)
    │    │                   └ <monitor.deviceManager.DeviceC object at 0x7f3104029220>
    │    └ <function Project.update_device_valid at 0x7f3104003280>
    └ <monitor.projectManager.Project object at 0x7f3104029460>

  File "/home/users/Scy/yuqing/spider/monitor/projectManager.py", line 421, in update_device_valid
    self.database_manager.mysql.update(Device(**device.to_item()))
    │    │                │     │      │        │      └ <function DeviceC.to_item at 0x7f31f34ed310>
    │    │                │     │      │        └ <monitor.deviceManager.DeviceC object at 0x7f3104029220>
    │    │                │     │      └ <class 'base.db.mysql.Device'>
    │    │                │     └ <function Mysql.update at 0x7f31f35f4790>
    │    │                └ <base.db.mysql.Mysql object at 0x7f3103ffdfd0>
    │    └ <base.db.dbSlot.Slot object at 0x7f3103ffdf10>
    └ <monitor.projectManager.Project object at 0x7f3104029460>

> File "/home/users/Scy/yuqing/spider/base/db/mysql.py", line 375, in update
    row.update(new)
    │   │      └ {'server_id': '180.201.163.246:6800', 'ip': '180.201.163.246', 'username': 'chase', 'password': '7322450940600966835491851077...
    │   └ <function Query.update at 0x7f31f37333a0>
    └ <sqlalchemy.orm.query.Query object at 0x7f3078310f10>

  File "/home/chase/.local/lib/python3.8/site-packages/sqlalchemy/orm/query.py", line 3221, in update
    result = self.session.execute(
             │    │       └ <function Session.execute at 0x7f31f370faf0>
             │    └ <sqlalchemy.orm.session.Session object at 0x7f30180cbe80>
             └ <sqlalchemy.orm.query.Query object at 0x7f3078310f10>
  File "/home/chase/.local/lib/python3.8/site-packages/sqlalchemy/orm/session.py", line 1689, in execute
    result = conn._execute_20(statement, params or {}, execution_options)
             │    │           │          │             └ immutabledict({'synchronize_session': 'evaluate', '_sa_orm_update_options': default_update_options(_matched_objects=[], _reso...
             │    │           │          └ immutabledict({})
             │    │           └ <sqlalchemy.sql.annotation.AnnotatedUpdate object at 0x7f303821d970>
             │    └ <function Connection._execute_20 at 0x7f31f39bc790>
             └ <sqlalchemy.engine.base.Connection object at 0x7f30786f29d0>
  File "/home/chase/.local/lib/python3.8/site-packages/sqlalchemy/engine/base.py", line 1583, in _execute_20
    return meth(self, args_10style, kwargs_10style, execution_options)
           │    │     │             │               └ immutabledict({'synchronize_session': 'evaluate', '_sa_orm_update_options': default_update_options(_matched_objects=[], _reso...
           │    │     │             └ immutabledict({})
           │    │     └ ({},)
           │    └ <sqlalchemy.engine.base.Connection object at 0x7f30786f29d0>
           └ <bound method ClauseElement._execute_on_connection of <sqlalchemy.sql.annotation.AnnotatedUpdate object at 0x7f303821d970>>
  File "/home/chase/.local/lib/python3.8/site-packages/sqlalchemy/sql/elements.py", line 323, in _execute_on_connection
    return connection._execute_clauseelement(
           │          └ <function Connection._execute_clauseelement at 0x7f31f39bc5e0>
           └ <sqlalchemy.engine.base.Connection object at 0x7f30786f29d0>
  File "/home/chase/.local/lib/python3.8/site-packages/sqlalchemy/engine/base.py", line 1452, in _execute_clauseelement
    ret = self._execute_context(
          │    └ <function Connection._execute_context at 0x7f31f39bc8b0>
          └ <sqlalchemy.engine.base.Connection object at 0x7f30786f29d0>
  File "/home/chase/.local/lib/python3.8/site-packages/sqlalchemy/engine/base.py", line 1814, in _execute_context
    self._handle_dbapi_exception(
    │    └ <function Connection._handle_dbapi_exception at 0x7f31f39bca60>
    └ <sqlalchemy.engine.base.Connection object at 0x7f30786f29d0>
  File "/home/chase/.local/lib/python3.8/site-packages/sqlalchemy/engine/base.py", line 1995, in _handle_dbapi_exception
    util.raise_(
    │    └ <function raise_ at 0x7f31f3d7ea60>
    └ <module 'sqlalchemy.util' from '/home/chase/.local/lib/python3.8/site-packages/sqlalchemy/util/__init__.py'>
  File "/home/chase/.local/lib/python3.8/site-packages/sqlalchemy/util/compat.py", line 207, in raise_
    raise exception
  File "/home/chase/.local/lib/python3.8/site-packages/sqlalchemy/engine/base.py", line 1771, in _execute_context
    self.dialect.do_execute(
    │    │       └ <function DefaultDialect.do_execute at 0x7f31f38f75e0>
    │    └ <sqlalchemy.dialects.mysql.pymysql.MySQLDialect_pymysql object at 0x7f3103ffde20>
    └ <sqlalchemy.engine.base.Connection object at 0x7f30786f29d0>
  File "/home/chase/.local/lib/python3.8/site-packages/sqlalchemy/engine/default.py", line 717, in do_execute
    cursor.execute(statement, parameters)
    │      │       │          └ {'server_id': '180.201.163.246:6800', 'ip': '180.201.163.246', 'username': 'chase', 'password': '7322450940600966835491851077...
    │      │       └ 'UPDATE device SET server_id=%(server_id)s, ip=%(ip)s, username=%(username)s, password=%(password)s, address=%(address)s, por...
    │      └ <function Cursor.execute at 0x7f31f354cdc0>
    └ <pymysql.cursors.Cursor object at 0x7f30d81209d0>
  File "/home/chase/.local/lib/python3.8/site-packages/pymysql/cursors.py", line 148, in execute
    result = self._query(query)
             │    │      └ "UPDATE device SET server_id='180.201.163.246:6800', ip='180.201.163.246', username='chase', password='7322450940600966835491...
             │    └ <function Cursor._query at 0x7f31f34d7280>
             └ <pymysql.cursors.Cursor object at 0x7f30d81209d0>
  File "/home/chase/.local/lib/python3.8/site-packages/pymysql/cursors.py", line 310, in _query
    conn.query(q)
    │    │     └ "UPDATE device SET server_id='180.201.163.246:6800', ip='180.201.163.246', username='chase', password='7322450940600966835491...
    │    └ <function Connection.query at 0x7f31f34e5670>
    └ <pymysql.connections.Connection object at 0x7f30d80b3970>
  File "/home/chase/.local/lib/python3.8/site-packages/pymysql/connections.py", line 548, in query
    self._affected_rows = self._read_query_result(unbuffered=unbuffered)
    │    │                │    │                             └ False
    │    │                │    └ <function Connection._read_query_result at 0x7f31f34e5ca0>
    │    │                └ <pymysql.connections.Connection object at 0x7f30d80b3970>
    │    └ 1
    └ <pymysql.connections.Connection object at 0x7f30d80b3970>
  File "/home/chase/.local/lib/python3.8/site-packages/pymysql/connections.py", line 775, in _read_query_result
    result.read()
    │      └ <function MySQLResult.read at 0x7f31f34e64c0>
    └ <pymysql.connections.MySQLResult object at 0x7f31023e0520>
  File "/home/chase/.local/lib/python3.8/site-packages/pymysql/connections.py", line 1156, in read
    first_packet = self.connection._read_packet()
                   │    └ None
                   └ <pymysql.connections.MySQLResult object at 0x7f31023e0520>
  File "/home/chase/.local/lib/python3.8/site-packages/pymysql/connections.py", line 725, in _read_packet
    packet.raise_for_error()
    │      └ <function MysqlPacket.raise_for_error at 0x7f31f34ddee0>
    └ <pymysql.protocol.MysqlPacket object at 0x7f3098599340>
  File "/home/chase/.local/lib/python3.8/site-packages/pymysql/protocol.py", line 221, in raise_for_error
    err.raise_mysql_exception(self._data)
    │   │                     │    └ <member '_data' of 'MysqlPacket' objects>
    │   │                     └ <pymysql.protocol.MysqlPacket object at 0x7f3098599340>
    │   └ <function raise_mysql_exception at 0x7f31f358c670>
    └ <module 'pymysql.err' from '/home/chase/.local/lib/python3.8/site-packages/pymysql/err.py'>
  File "/home/chase/.local/lib/python3.8/site-packages/pymysql/err.py", line 143, in raise_mysql_exception
    raise errorclass(errno, errval)
          │          │      └ "Duplicate entry '180.201.163.246:6800' for key 'device.PRIMARY'"
          │          └ 1062
          └ <class 'pymysql.err.IntegrityError'>

sqlalchemy.exc.IntegrityError: (pymysql.err.IntegrityError) (1062, "Duplicate entry '180.201.163.246:6800' for key 'device.PRIMARY'")
[SQL: UPDATE device SET server_id=%(server_id)s, ip=%(ip)s, username=%(username)s, password=%(password)s, address=%(address)s, port=%(port)s, valid=%(valid)s WHERE device.ip = %(ip_1)s]
[parameters: {'server_id': '180.201.163.246:6800', 'ip': '180.201.163.246', 'username': 'chase', 'password': '73224509406009668354918510770282200407656382780105067558837874870404952503395461945891835855599903224705516783271244290238837072710019687614552988430 ... (10 characters truncated) ... 25541624273397361282775156650677319591683671036394820186656355073197655198944314758604347654667128757439199790618821648993942070348710490132984235321', 'address': '/home/users/CT/pycharmproject/spiders/', 'port': 6800, 'valid': 1, 'ip_1': '180.201.163.246'}]
(Background on this error at: https://sqlalche.me/e/14/gkpj)
