2022-05-14 05:58:59.025 | ERROR    | base.db.mysql:update:390 - 【mysql更新数据出错】
Traceback (most recent call last):

  File "/home/chase/.local/lib/python3.8/site-packages/sqlalchemy/engine/base.py", line 1771, in _execute_context
    self.dialect.do_execute(
    │    │       └ <function DefaultDialect.do_execute at 0x7f31f38f75e0>
    │    └ <sqlalchemy.dialects.mysql.pymysql.MySQLDialect_pymysql object at 0x7f3103ffde20>
    └ <sqlalchemy.engine.base.Connection object at 0x7f2e12c7d0d0>
  File "/home/chase/.local/lib/python3.8/site-packages/sqlalchemy/engine/default.py", line 717, in do_execute
    cursor.execute(statement, parameters)
    │      │       │          └ {'server_id': '180.201.163.246:6800', 'ip': '180.201.163.246', 'username': 'chase', 'password': '8614641090047119116878884553...
    │      │       └ 'UPDATE device SET server_id=%(server_id)s, ip=%(ip)s, username=%(username)s, password=%(password)s, address=%(address)s, por...
    │      └ <function Cursor.execute at 0x7f31f354cdc0>
    └ <pymysql.cursors.Cursor object at 0x7f2dc82d4550>
  File "/home/chase/.local/lib/python3.8/site-packages/pymysql/cursors.py", line 148, in execute
    result = self._query(query)
             │    │      └ "UPDATE device SET server_id='180.201.163.246:6800', ip='180.201.163.246', username='chase', password='8614641090047119116878...
             │    └ <function Cursor._query at 0x7f31f34d7280>
             └ <pymysql.cursors.Cursor object at 0x7f2dc82d4550>
  File "/home/chase/.local/lib/python3.8/site-packages/pymysql/cursors.py", line 310, in _query
    conn.query(q)
    │    │     └ "UPDATE device SET server_id='180.201.163.246:6800', ip='180.201.163.246', username='chase', password='8614641090047119116878...
    │    └ <function Connection.query at 0x7f31f34e5670>
    └ <pymysql.connections.Connection object at 0x7f2f781f2ca0>
  File "/home/chase/.local/lib/python3.8/site-packages/pymysql/connections.py", line 548, in query
    self._affected_rows = self._read_query_result(unbuffered=unbuffered)
    │    │                │    │                             └ False
    │    │                │    └ <function Connection._read_query_result at 0x7f31f34e5ca0>
    │    │                └ <pymysql.connections.Connection object at 0x7f2f781f2ca0>
    │    └ 1
    └ <pymysql.connections.Connection object at 0x7f2f781f2ca0>
  File "/home/chase/.local/lib/python3.8/site-packages/pymysql/connections.py", line 775, in _read_query_result
    result.read()
    │      └ <function MySQLResult.read at 0x7f31f34e64c0>
    └ <pymysql.connections.MySQLResult object at 0x7f30d8089fd0>
  File "/home/chase/.local/lib/python3.8/site-packages/pymysql/connections.py", line 1156, in read
    first_packet = self.connection._read_packet()
                   │    └ None
                   └ <pymysql.connections.MySQLResult object at 0x7f30d8089fd0>
  File "/home/chase/.local/lib/python3.8/site-packages/pymysql/connections.py", line 725, in _read_packet
    packet.raise_for_error()
    │      └ <function MysqlPacket.raise_for_error at 0x7f31f34ddee0>
    └ <pymysql.protocol.MysqlPacket object at 0x7f31f9308cd0>
  File "/home/chase/.local/lib/python3.8/site-packages/pymysql/protocol.py", line 221, in raise_for_error
    err.raise_mysql_exception(self._data)
    │   │                     │    └ <member '_data' of 'MysqlPacket' objects>
    │   │                     └ <pymysql.protocol.MysqlPacket object at 0x7f31f9308cd0>
    │   └ <function raise_mysql_exception at 0x7f31f358c670>
    └ <module 'pymysql.err' from '/home/chase/.local/lib/python3.8/site-packages/pymysql/err.py'>
  File "/home/chase/.local/lib/python3.8/site-packages/pymysql/err.py", line 143, in raise_mysql_exception
    raise errorclass(errno, errval)
          │          │      └ "Duplicate entry '180.201.163.246:6800' for key 'device.PRIMARY'"
          │          └ 1062
          └ <class 'pymysql.err.IntegrityError'>

pymysql.err.IntegrityError: (1062, "Duplicate entry '180.201.163.246:6800' for key 'device.PRIMARY'")


The above exception was the direct cause of the following exception:


Traceback (most recent call last):

  File "/usr/lib/python3.8/threading.py", line 890, in _bootstrap
    self._bootstrap_inner()
    │    └ <function Thread._bootstrap_inner at 0x7f321bf29a60>
    └ <Thread(Thread-11905, started daemon 139834058438400)>
  File "/usr/lib/python3.8/threading.py", line 932, in _bootstrap_inner
    self.run()
    │    └ <function Thread.run at 0x7f321bf29790>
    └ <Thread(Thread-11905, started daemon 139834058438400)>
  File "/usr/lib/python3.8/threading.py", line 870, in run
    self._target(*self._args, **self._kwargs)
    │    │        │    │        │    └ {}
    │    │        │    │        └ <Thread(Thread-11905, started daemon 139834058438400)>
    │    │        │    └ ('ProjectManager.run_func_by_thread',)
    │    │        └ <Thread(Thread-11905, started daemon 139834058438400)>
    │    └ <bound method ProjectManager.get_request_from_keywords_hot of <monitor.projectManager.ProjectManager object at 0x7f31042e52e0>>
    └ <Thread(Thread-11905, started daemon 139834058438400)>

  File "/home/users/Scy/yuqing/spider/monitor/projectManager.py", line 799, in get_request_from_keywords_hot
    self.start_finished_spider_every_interval(project_names)
    │    │                                    └ ['default', 'test']
    │    └ <function ProjectManager.start_finished_spider_every_interval at 0x7f3104005280>
    └ <monitor.projectManager.ProjectManager object at 0x7f31042e52e0>

  File "/home/users/Scy/yuqing/spider/monitor/projectManager.py", line 784, in start_finished_spider_every_interval
    self[name].start_spider()
    │    └ 'default'
    └ <monitor.projectManager.ProjectManager object at 0x7f31042e52e0>

  File "/home/users/Scy/yuqing/spider/monitor/projectManager.py", line 366, in start_spider
    self.update_device_valid(device)
    │    │                   └ <monitor.deviceManager.DeviceC object at 0x7f3104029220>
    │    └ <function Project.update_device_valid at 0x7f3104003280>
    └ <monitor.projectManager.Project object at 0x7f3104029460>

  File "/home/users/Scy/yuqing/spider/monitor/projectManager.py", line 421, in update_device_valid
    self.database_manager.mysql.update(Device(**device.to_item()))
    │    │                │     │      │        │      └ <function DeviceC.to_item at 0x7f31f34ed310>
    │    │                │     │      │        └ <monitor.deviceManager.DeviceC object at 0x7f3104029220>
    │    │                │     │      └ <class 'base.db.mysql.Device'>
    │    │                │     └ <function Mysql.update at 0x7f31f35f4790>
    │    │                └ <base.db.mysql.Mysql object at 0x7f3103ffdfd0>
    │    └ <base.db.dbSlot.Slot object at 0x7f3103ffdf10>
    └ <monitor.projectManager.Project object at 0x7f3104029460>

> File "/home/users/Scy/yuqing/spider/base/db/mysql.py", line 375, in update
    row.update(new)
    │   │      └ {'server_id': '180.201.163.246:6800', 'ip': '180.201.163.246', 'username': 'chase', 'password': '8614641090047119116878884553...
    │   └ <function Query.update at 0x7f31f37333a0>
    └ <sqlalchemy.orm.query.Query object at 0x7f2e12c7dbe0>

  File "/home/chase/.local/lib/python3.8/site-packages/sqlalchemy/orm/query.py", line 3221, in update
    result = self.session.execute(
             │    │       └ <function Session.execute at 0x7f31f370faf0>
             │    └ <sqlalchemy.orm.session.Session object at 0x7f2f786b21c0>
             └ <sqlalchemy.orm.query.Query object at 0x7f2e12c7dbe0>
  File "/home/chase/.local/lib/python3.8/site-packages/sqlalchemy/orm/session.py", line 1689, in execute
    result = conn._execute_20(statement, params or {}, execution_options)
             │    │           │          │             └ immutabledict({'synchronize_session': 'evaluate', '_sa_orm_update_options': default_update_options(_matched_objects=[], _reso...
             │    │           │          └ immutabledict({})
             │    │           └ <sqlalchemy.sql.annotation.AnnotatedUpdate object at 0x7f301858d340>
             │    └ <function Connection._execute_20 at 0x7f31f39bc790>
             └ <sqlalchemy.engine.base.Connection object at 0x7f2e12c7d0d0>
  File "/home/chase/.local/lib/python3.8/site-packages/sqlalchemy/engine/base.py", line 1583, in _execute_20
    return meth(self, args_10style, kwargs_10style, execution_options)
           │    │     │             │               └ immutabledict({'synchronize_session': 'evaluate', '_sa_orm_update_options': default_update_options(_matched_objects=[], _reso...
           │    │     │             └ immutabledict({})
           │    │     └ ({},)
           │    └ <sqlalchemy.engine.base.Connection object at 0x7f2e12c7d0d0>
           └ <bound method ClauseElement._execute_on_connection of <sqlalchemy.sql.annotation.AnnotatedUpdate object at 0x7f301858d340>>
  File "/home/chase/.local/lib/python3.8/site-packages/sqlalchemy/sql/elements.py", line 323, in _execute_on_connection
    return connection._execute_clauseelement(
           │          └ <function Connection._execute_clauseelement at 0x7f31f39bc5e0>
           └ <sqlalchemy.engine.base.Connection object at 0x7f2e12c7d0d0>
  File "/home/chase/.local/lib/python3.8/site-packages/sqlalchemy/engine/base.py", line 1452, in _execute_clauseelement
    ret = self._execute_context(
          │    └ <function Connection._execute_context at 0x7f31f39bc8b0>
          └ <sqlalchemy.engine.base.Connection object at 0x7f2e12c7d0d0>
  File "/home/chase/.local/lib/python3.8/site-packages/sqlalchemy/engine/base.py", line 1814, in _execute_context
    self._handle_dbapi_exception(
    │    └ <function Connection._handle_dbapi_exception at 0x7f31f39bca60>
    └ <sqlalchemy.engine.base.Connection object at 0x7f2e12c7d0d0>
  File "/home/chase/.local/lib/python3.8/site-packages/sqlalchemy/engine/base.py", line 1995, in _handle_dbapi_exception
    util.raise_(
    │    └ <function raise_ at 0x7f31f3d7ea60>
    └ <module 'sqlalchemy.util' from '/home/chase/.local/lib/python3.8/site-packages/sqlalchemy/util/__init__.py'>
  File "/home/chase/.local/lib/python3.8/site-packages/sqlalchemy/util/compat.py", line 207, in raise_
    raise exception
  File "/home/chase/.local/lib/python3.8/site-packages/sqlalchemy/engine/base.py", line 1771, in _execute_context
    self.dialect.do_execute(
    │    │       └ <function DefaultDialect.do_execute at 0x7f31f38f75e0>
    │    └ <sqlalchemy.dialects.mysql.pymysql.MySQLDialect_pymysql object at 0x7f3103ffde20>
    └ <sqlalchemy.engine.base.Connection object at 0x7f2e12c7d0d0>
  File "/home/chase/.local/lib/python3.8/site-packages/sqlalchemy/engine/default.py", line 717, in do_execute
    cursor.execute(statement, parameters)
    │      │       │          └ {'server_id': '180.201.163.246:6800', 'ip': '180.201.163.246', 'username': 'chase', 'password': '8614641090047119116878884553...
    │      │       └ 'UPDATE device SET server_id=%(server_id)s, ip=%(ip)s, username=%(username)s, password=%(password)s, address=%(address)s, por...
    │      └ <function Cursor.execute at 0x7f31f354cdc0>
    └ <pymysql.cursors.Cursor object at 0x7f2dc82d4550>
  File "/home/chase/.local/lib/python3.8/site-packages/pymysql/cursors.py", line 148, in execute
    result = self._query(query)
             │    │      └ "UPDATE device SET server_id='180.201.163.246:6800', ip='180.201.163.246', username='chase', password='8614641090047119116878...
             │    └ <function Cursor._query at 0x7f31f34d7280>
             └ <pymysql.cursors.Cursor object at 0x7f2dc82d4550>
  File "/home/chase/.local/lib/python3.8/site-packages/pymysql/cursors.py", line 310, in _query
    conn.query(q)
    │    │     └ "UPDATE device SET server_id='180.201.163.246:6800', ip='180.201.163.246', username='chase', password='8614641090047119116878...
    │    └ <function Connection.query at 0x7f31f34e5670>
    └ <pymysql.connections.Connection object at 0x7f2f781f2ca0>
  File "/home/chase/.local/lib/python3.8/site-packages/pymysql/connections.py", line 548, in query
    self._affected_rows = self._read_query_result(unbuffered=unbuffered)
    │    │                │    │                             └ False
    │    │                │    └ <function Connection._read_query_result at 0x7f31f34e5ca0>
    │    │                └ <pymysql.connections.Connection object at 0x7f2f781f2ca0>
    │    └ 1
    └ <pymysql.connections.Connection object at 0x7f2f781f2ca0>
  File "/home/chase/.local/lib/python3.8/site-packages/pymysql/connections.py", line 775, in _read_query_result
    result.read()
    │      └ <function MySQLResult.read at 0x7f31f34e64c0>
    └ <pymysql.connections.MySQLResult object at 0x7f30d8089fd0>
  File "/home/chase/.local/lib/python3.8/site-packages/pymysql/connections.py", line 1156, in read
    first_packet = self.connection._read_packet()
                   │    └ None
                   └ <pymysql.connections.MySQLResult object at 0x7f30d8089fd0>
  File "/home/chase/.local/lib/python3.8/site-packages/pymysql/connections.py", line 725, in _read_packet
    packet.raise_for_error()
    │      └ <function MysqlPacket.raise_for_error at 0x7f31f34ddee0>
    └ <pymysql.protocol.MysqlPacket object at 0x7f31f9308cd0>
  File "/home/chase/.local/lib/python3.8/site-packages/pymysql/protocol.py", line 221, in raise_for_error
    err.raise_mysql_exception(self._data)
    │   │                     │    └ <member '_data' of 'MysqlPacket' objects>
    │   │                     └ <pymysql.protocol.MysqlPacket object at 0x7f31f9308cd0>
    │   └ <function raise_mysql_exception at 0x7f31f358c670>
    └ <module 'pymysql.err' from '/home/chase/.local/lib/python3.8/site-packages/pymysql/err.py'>
  File "/home/chase/.local/lib/python3.8/site-packages/pymysql/err.py", line 143, in raise_mysql_exception
    raise errorclass(errno, errval)
          │          │      └ "Duplicate entry '180.201.163.246:6800' for key 'device.PRIMARY'"
          │          └ 1062
          └ <class 'pymysql.err.IntegrityError'>

sqlalchemy.exc.IntegrityError: (pymysql.err.IntegrityError) (1062, "Duplicate entry '180.201.163.246:6800' for key 'device.PRIMARY'")
[SQL: UPDATE device SET server_id=%(server_id)s, ip=%(ip)s, username=%(username)s, password=%(password)s, address=%(address)s, port=%(port)s, valid=%(valid)s WHERE device.ip = %(ip_1)s]
[parameters: {'server_id': '180.201.163.246:6800', 'ip': '180.201.163.246', 'username': 'chase', 'password': '86146410900471191168788845534021092186966172566762774422627032215605133968935705266660783564406361082515552769208129694445556436247954952797498996768 ... (10 characters truncated) ... 86803465416710354344220414755981440691282624646032054790182294534312373087280065735306322728773687921265192891765345685676871400322783702552102712468', 'address': '/home/users/CT/pycharmproject/spiders/', 'port': 6800, 'valid': 1, 'ip_1': '180.201.163.246'}]
(Background on this error at: https://sqlalche.me/e/14/gkpj)
2022-05-14 05:59:16.892 | ERROR    | base.db.mysql:update:390 - 【mysql更新数据出错】
Traceback (most recent call last):

  File "/home/chase/.local/lib/python3.8/site-packages/sqlalchemy/engine/base.py", line 1771, in _execute_context
    self.dialect.do_execute(
    │    │       └ <function DefaultDialect.do_execute at 0x7f31f38f75e0>
    │    └ <sqlalchemy.dialects.mysql.pymysql.MySQLDialect_pymysql object at 0x7f3103ffde20>
    └ <sqlalchemy.engine.base.Connection object at 0x7f2de9cd67f0>
  File "/home/chase/.local/lib/python3.8/site-packages/sqlalchemy/engine/default.py", line 717, in do_execute
    cursor.execute(statement, parameters)
    │      │       │          └ {'server_id': '180.201.163.246:6800', 'ip': '180.201.163.246', 'username': 'chase', 'password': '2970499977961531201133858565...
    │      │       └ 'UPDATE device SET server_id=%(server_id)s, ip=%(ip)s, username=%(username)s, password=%(password)s, address=%(address)s, por...
    │      └ <function Cursor.execute at 0x7f31f354cdc0>
    └ <pymysql.cursors.Cursor object at 0x7f3018185910>
  File "/home/chase/.local/lib/python3.8/site-packages/pymysql/cursors.py", line 148, in execute
    result = self._query(query)
             │    │      └ "UPDATE device SET server_id='180.201.163.246:6800', ip='180.201.163.246', username='chase', password='2970499977961531201133...
             │    └ <function Cursor._query at 0x7f31f34d7280>
             └ <pymysql.cursors.Cursor object at 0x7f3018185910>
  File "/home/chase/.local/lib/python3.8/site-packages/pymysql/cursors.py", line 310, in _query
    conn.query(q)
    │    │     └ "UPDATE device SET server_id='180.201.163.246:6800', ip='180.201.163.246', username='chase', password='2970499977961531201133...
    │    └ <function Connection.query at 0x7f31f34e5670>
    └ <pymysql.connections.Connection object at 0x7f309833d850>
  File "/home/chase/.local/lib/python3.8/site-packages/pymysql/connections.py", line 548, in query
    self._affected_rows = self._read_query_result(unbuffered=unbuffered)
    │    │                │    │                             └ False
    │    │                │    └ <function Connection._read_query_result at 0x7f31f34e5ca0>
    │    │                └ <pymysql.connections.Connection object at 0x7f309833d850>
    │    └ 1
    └ <pymysql.connections.Connection object at 0x7f309833d850>
  File "/home/chase/.local/lib/python3.8/site-packages/pymysql/connections.py", line 775, in _read_query_result
    result.read()
    │      └ <function MySQLResult.read at 0x7f31f34e64c0>
    └ <pymysql.connections.MySQLResult object at 0x7f30784e5ee0>
  File "/home/chase/.local/lib/python3.8/site-packages/pymysql/connections.py", line 1156, in read
    first_packet = self.connection._read_packet()
                   │    └ None
                   └ <pymysql.connections.MySQLResult object at 0x7f30784e5ee0>
  File "/home/chase/.local/lib/python3.8/site-packages/pymysql/connections.py", line 725, in _read_packet
    packet.raise_for_error()
    │      └ <function MysqlPacket.raise_for_error at 0x7f31f34ddee0>
    └ <pymysql.protocol.MysqlPacket object at 0x7f2ff85782b0>
  File "/home/chase/.local/lib/python3.8/site-packages/pymysql/protocol.py", line 221, in raise_for_error
    err.raise_mysql_exception(self._data)
    │   │                     │    └ <member '_data' of 'MysqlPacket' objects>
    │   │                     └ <pymysql.protocol.MysqlPacket object at 0x7f2ff85782b0>
    │   └ <function raise_mysql_exception at 0x7f31f358c670>
    └ <module 'pymysql.err' from '/home/chase/.local/lib/python3.8/site-packages/pymysql/err.py'>
  File "/home/chase/.local/lib/python3.8/site-packages/pymysql/err.py", line 143, in raise_mysql_exception
    raise errorclass(errno, errval)
          │          │      └ "Duplicate entry '180.201.163.246:6800' for key 'device.PRIMARY'"
          │          └ 1062
          └ <class 'pymysql.err.IntegrityError'>

pymysql.err.IntegrityError: (1062, "Duplicate entry '180.201.163.246:6800' for key 'device.PRIMARY'")


The above exception was the direct cause of the following exception:


Traceback (most recent call last):

  File "/usr/lib/python3.8/threading.py", line 890, in _bootstrap
    self._bootstrap_inner()
    │    └ <function Thread._bootstrap_inner at 0x7f321bf29a60>
    └ <Thread(Thread-11910, started daemon 139834050045696)>
  File "/usr/lib/python3.8/threading.py", line 932, in _bootstrap_inner
    self.run()
    │    └ <function Thread.run at 0x7f321bf29790>
    └ <Thread(Thread-11910, started daemon 139834050045696)>
  File "/usr/lib/python3.8/threading.py", line 870, in run
    self._target(*self._args, **self._kwargs)
    │    │        │    │        │    └ {}
    │    │        │    │        └ <Thread(Thread-11910, started daemon 139834050045696)>
    │    │        │    └ ('ProjectManager.run_func_by_thread',)
    │    │        └ <Thread(Thread-11910, started daemon 139834050045696)>
    │    └ <bound method ProjectManager.get_request_from_keywords_hot of <monitor.projectManager.ProjectManager object at 0x7f31042e52e0>>
    └ <Thread(Thread-11910, started daemon 139834050045696)>

  File "/home/users/Scy/yuqing/spider/monitor/projectManager.py", line 799, in get_request_from_keywords_hot
    self.start_finished_spider_every_interval(project_names)
    │    │                                    └ ['default', 'test']
    │    └ <function ProjectManager.start_finished_spider_every_interval at 0x7f3104005280>
    └ <monitor.projectManager.ProjectManager object at 0x7f31042e52e0>

  File "/home/users/Scy/yuqing/spider/monitor/projectManager.py", line 784, in start_finished_spider_every_interval
    self[name].start_spider()
    │    └ 'default'
    └ <monitor.projectManager.ProjectManager object at 0x7f31042e52e0>

  File "/home/users/Scy/yuqing/spider/monitor/projectManager.py", line 366, in start_spider
    self.update_device_valid(device)
    │    │                   └ <monitor.deviceManager.DeviceC object at 0x7f3104029220>
    │    └ <function Project.update_device_valid at 0x7f3104003280>
    └ <monitor.projectManager.Project object at 0x7f3104029460>

  File "/home/users/Scy/yuqing/spider/monitor/projectManager.py", line 421, in update_device_valid
    self.database_manager.mysql.update(Device(**device.to_item()))
    │    │                │     │      │        │      └ <function DeviceC.to_item at 0x7f31f34ed310>
    │    │                │     │      │        └ <monitor.deviceManager.DeviceC object at 0x7f3104029220>
    │    │                │     │      └ <class 'base.db.mysql.Device'>
    │    │                │     └ <function Mysql.update at 0x7f31f35f4790>
    │    │                └ <base.db.mysql.Mysql object at 0x7f3103ffdfd0>
    │    └ <base.db.dbSlot.Slot object at 0x7f3103ffdf10>
    └ <monitor.projectManager.Project object at 0x7f3104029460>

> File "/home/users/Scy/yuqing/spider/base/db/mysql.py", line 375, in update
    row.update(new)
    │   │      └ {'server_id': '180.201.163.246:6800', 'ip': '180.201.163.246', 'username': 'chase', 'password': '2970499977961531201133858565...
    │   └ <function Query.update at 0x7f31f37333a0>
    └ <sqlalchemy.orm.query.Query object at 0x7f2de9cd6640>

  File "/home/chase/.local/lib/python3.8/site-packages/sqlalchemy/orm/query.py", line 3221, in update
    result = self.session.execute(
             │    │       └ <function Session.execute at 0x7f31f370faf0>
             │    └ <sqlalchemy.orm.session.Session object at 0x7f2de9cd6520>
             └ <sqlalchemy.orm.query.Query object at 0x7f2de9cd6640>
  File "/home/chase/.local/lib/python3.8/site-packages/sqlalchemy/orm/session.py", line 1689, in execute
    result = conn._execute_20(statement, params or {}, execution_options)
             │    │           │          │             └ immutabledict({'synchronize_session': 'evaluate', '_sa_orm_update_options': default_update_options(_matched_objects=[], _reso...
             │    │           │          └ immutabledict({})
             │    │           └ <sqlalchemy.sql.annotation.AnnotatedUpdate object at 0x7f2fb81e1520>
             │    └ <function Connection._execute_20 at 0x7f31f39bc790>
             └ <sqlalchemy.engine.base.Connection object at 0x7f2de9cd67f0>
  File "/home/chase/.local/lib/python3.8/site-packages/sqlalchemy/engine/base.py", line 1583, in _execute_20
    return meth(self, args_10style, kwargs_10style, execution_options)
           │    │     │             │               └ immutabledict({'synchronize_session': 'evaluate', '_sa_orm_update_options': default_update_options(_matched_objects=[], _reso...
           │    │     │             └ immutabledict({})
           │    │     └ ({},)
           │    └ <sqlalchemy.engine.base.Connection object at 0x7f2de9cd67f0>
           └ <bound method ClauseElement._execute_on_connection of <sqlalchemy.sql.annotation.AnnotatedUpdate object at 0x7f2fb81e1520>>
  File "/home/chase/.local/lib/python3.8/site-packages/sqlalchemy/sql/elements.py", line 323, in _execute_on_connection
    return connection._execute_clauseelement(
           │          └ <function Connection._execute_clauseelement at 0x7f31f39bc5e0>
           └ <sqlalchemy.engine.base.Connection object at 0x7f2de9cd67f0>
  File "/home/chase/.local/lib/python3.8/site-packages/sqlalchemy/engine/base.py", line 1452, in _execute_clauseelement
    ret = self._execute_context(
          │    └ <function Connection._execute_context at 0x7f31f39bc8b0>
          └ <sqlalchemy.engine.base.Connection object at 0x7f2de9cd67f0>
  File "/home/chase/.local/lib/python3.8/site-packages/sqlalchemy/engine/base.py", line 1814, in _execute_context
    self._handle_dbapi_exception(
    │    └ <function Connection._handle_dbapi_exception at 0x7f31f39bca60>
    └ <sqlalchemy.engine.base.Connection object at 0x7f2de9cd67f0>
  File "/home/chase/.local/lib/python3.8/site-packages/sqlalchemy/engine/base.py", line 1995, in _handle_dbapi_exception
    util.raise_(
    │    └ <function raise_ at 0x7f31f3d7ea60>
    └ <module 'sqlalchemy.util' from '/home/chase/.local/lib/python3.8/site-packages/sqlalchemy/util/__init__.py'>
  File "/home/chase/.local/lib/python3.8/site-packages/sqlalchemy/util/compat.py", line 207, in raise_
    raise exception
  File "/home/chase/.local/lib/python3.8/site-packages/sqlalchemy/engine/base.py", line 1771, in _execute_context
    self.dialect.do_execute(
    │    │       └ <function DefaultDialect.do_execute at 0x7f31f38f75e0>
    │    └ <sqlalchemy.dialects.mysql.pymysql.MySQLDialect_pymysql object at 0x7f3103ffde20>
    └ <sqlalchemy.engine.base.Connection object at 0x7f2de9cd67f0>
  File "/home/chase/.local/lib/python3.8/site-packages/sqlalchemy/engine/default.py", line 717, in do_execute
    cursor.execute(statement, parameters)
    │      │       │          └ {'server_id': '180.201.163.246:6800', 'ip': '180.201.163.246', 'username': 'chase', 'password': '2970499977961531201133858565...
    │      │       └ 'UPDATE device SET server_id=%(server_id)s, ip=%(ip)s, username=%(username)s, password=%(password)s, address=%(address)s, por...
    │      └ <function Cursor.execute at 0x7f31f354cdc0>
    └ <pymysql.cursors.Cursor object at 0x7f3018185910>
  File "/home/chase/.local/lib/python3.8/site-packages/pymysql/cursors.py", line 148, in execute
    result = self._query(query)
             │    │      └ "UPDATE device SET server_id='180.201.163.246:6800', ip='180.201.163.246', username='chase', password='2970499977961531201133...
             │    └ <function Cursor._query at 0x7f31f34d7280>
             └ <pymysql.cursors.Cursor object at 0x7f3018185910>
  File "/home/chase/.local/lib/python3.8/site-packages/pymysql/cursors.py", line 310, in _query
    conn.query(q)
    │    │     └ "UPDATE device SET server_id='180.201.163.246:6800', ip='180.201.163.246', username='chase', password='2970499977961531201133...
    │    └ <function Connection.query at 0x7f31f34e5670>
    └ <pymysql.connections.Connection object at 0x7f309833d850>
  File "/home/chase/.local/lib/python3.8/site-packages/pymysql/connections.py", line 548, in query
    self._affected_rows = self._read_query_result(unbuffered=unbuffered)
    │    │                │    │                             └ False
    │    │                │    └ <function Connection._read_query_result at 0x7f31f34e5ca0>
    │    │                └ <pymysql.connections.Connection object at 0x7f309833d850>
    │    └ 1
    └ <pymysql.connections.Connection object at 0x7f309833d850>
  File "/home/chase/.local/lib/python3.8/site-packages/pymysql/connections.py", line 775, in _read_query_result
    result.read()
    │      └ <function MySQLResult.read at 0x7f31f34e64c0>
    └ <pymysql.connections.MySQLResult object at 0x7f30784e5ee0>
  File "/home/chase/.local/lib/python3.8/site-packages/pymysql/connections.py", line 1156, in read
    first_packet = self.connection._read_packet()
                   │    └ None
                   └ <pymysql.connections.MySQLResult object at 0x7f30784e5ee0>
  File "/home/chase/.local/lib/python3.8/site-packages/pymysql/connections.py", line 725, in _read_packet
    packet.raise_for_error()
    │      └ <function MysqlPacket.raise_for_error at 0x7f31f34ddee0>
    └ <pymysql.protocol.MysqlPacket object at 0x7f2ff85782b0>
  File "/home/chase/.local/lib/python3.8/site-packages/pymysql/protocol.py", line 221, in raise_for_error
    err.raise_mysql_exception(self._data)
    │   │                     │    └ <member '_data' of 'MysqlPacket' objects>
    │   │                     └ <pymysql.protocol.MysqlPacket object at 0x7f2ff85782b0>
    │   └ <function raise_mysql_exception at 0x7f31f358c670>
    └ <module 'pymysql.err' from '/home/chase/.local/lib/python3.8/site-packages/pymysql/err.py'>
  File "/home/chase/.local/lib/python3.8/site-packages/pymysql/err.py", line 143, in raise_mysql_exception
    raise errorclass(errno, errval)
          │          │      └ "Duplicate entry '180.201.163.246:6800' for key 'device.PRIMARY'"
          │          └ 1062
          └ <class 'pymysql.err.IntegrityError'>

sqlalchemy.exc.IntegrityError: (pymysql.err.IntegrityError) (1062, "Duplicate entry '180.201.163.246:6800' for key 'device.PRIMARY'")
[SQL: UPDATE device SET server_id=%(server_id)s, ip=%(ip)s, username=%(username)s, password=%(password)s, address=%(address)s, port=%(port)s, valid=%(valid)s WHERE device.ip = %(ip_1)s]
[parameters: {'server_id': '180.201.163.246:6800', 'ip': '180.201.163.246', 'username': 'chase', 'password': '29704999779615312011338585658360680626476657628326973131486913369724362780098107901801853443375530317336832149027475303098221074322046907083943895547 ... (10 characters truncated) ... 48830805065568760248753122824940320804979691366406464831119209342150225347463642587083742538804988288157918496034788898322327090538093610045505562928', 'address': '/home/users/CT/pycharmproject/spiders/', 'port': 6800, 'valid': 1, 'ip_1': '180.201.163.246'}]
(Background on this error at: https://sqlalche.me/e/14/gkpj)
2022-05-14 05:59:24.585 | ERROR    | monitor.hotSpiders.people:get_title:52 - HTTPConnectionPool(host='world.people.com.cn', port=80): Max retries exceeded with url: /GB/157278/index.html (Caused by NewConnectionError('<urllib3.connection.HTTPConnection object at 0x7f2de9d81ee0>: Failed to establish a new connection: [Errno 22] Invalid argument'))
2022-05-14 05:59:25.372 | ERROR    | monitor.hotSpiders.weibo:get_title:40 - url:https://weibo.com/ajax/side/hotSearch  HTTPSConnectionPool(host='weibo.com', port=443): Max retries exceeded with url: /ajax/side/hotSearch (Caused by NewConnectionError('<urllib3.connection.HTTPSConnection object at 0x7f30782e6a60>: Failed to establish a new connection: [Errno 22] Invalid argument'))
Traceback (most recent call last):

  File "/home/chase/.local/lib/python3.8/site-packages/urllib3/connection.py", line 174, in _new_conn
  File "/home/chase/.local/lib/python3.8/site-packages/urllib3/util/connection.py", line 73, in create_connection
  File "/usr/lib/python3.8/socket.py", line 918, in getaddrinfo

OSError: [Errno 22] Invalid argument


During handling of the above exception, another exception occurred:


Traceback (most recent call last):

  File "/home/chase/.local/lib/python3.8/site-packages/urllib3/connectionpool.py", line 699, in urlopen
  File "/home/chase/.local/lib/python3.8/site-packages/urllib3/connectionpool.py", line 382, in _make_request
  File "/home/chase/.local/lib/python3.8/site-packages/urllib3/connectionpool.py", line 1010, in _validate_conn
  File "/home/chase/.local/lib/python3.8/site-packages/urllib3/connection.py", line 358, in connect
    conn = self._new_conn()
           │    └ <function HTTPConnection._new_conn at 0x7f31f819e310>
           └ <urllib3.connection.HTTPSConnection object at 0x7f30782e6a60>
  File "/home/chase/.local/lib/python3.8/site-packages/urllib3/connection.py", line 186, in _new_conn
    raise NewConnectionError(
          └ <class 'urllib3.exceptions.NewConnectionError'>

urllib3.exceptions.NewConnectionError: <urllib3.connection.HTTPSConnection object at 0x7f30782e6a60>: Failed to establish a new connection: [Errno 22] Invalid argument


During handling of the above exception, another exception occurred:


Traceback (most recent call last):

  File "/home/chase/.local/lib/python3.8/site-packages/requests/adapters.py", line 439, in send
  File "/home/chase/.local/lib/python3.8/site-packages/urllib3/connectionpool.py", line 755, in urlopen
  File "/home/chase/.local/lib/python3.8/site-packages/urllib3/util/retry.py", line 574, in increment
    raise MaxRetryError(_pool, url, error or ResponseError(cause))
          │             │      │    │        │             └ 'unknown'
          │             │      │    │        └ <class 'urllib3.exceptions.ResponseError'>
          │             │      │    └ NewConnectionError('<urllib3.connection.HTTPSConnection object at 0x7f30782e6a60>: Failed to establish a new connection: [Err...
          │             │      └ '/ajax/side/hotSearch'
          │             └ <urllib3.connectionpool.HTTPSConnectionPool object at 0x7f2de99a3d90>
          └ <class 'urllib3.exceptions.MaxRetryError'>

urllib3.exceptions.MaxRetryError: HTTPSConnectionPool(host='weibo.com', port=443): Max retries exceeded with url: /ajax/side/hotSearch (Caused by NewConnectionError('<urllib3.connection.HTTPSConnection object at 0x7f30782e6a60>: Failed to establish a new connection: [Errno 22] Invalid argument'))


During handling of the above exception, another exception occurred:


Traceback (most recent call last):

  File "/usr/lib/python3.8/threading.py", line 890, in _bootstrap
    self._bootstrap_inner()
    │    └ <function Thread._bootstrap_inner at 0x7f321bf29a60>
    └ <Thread(Thread-11911, started daemon 139834033260288)>
  File "/usr/lib/python3.8/threading.py", line 932, in _bootstrap_inner
    self.run()
    │    └ <function Thread.run at 0x7f321bf29790>
    └ <Thread(Thread-11911, started daemon 139834033260288)>
  File "/usr/lib/python3.8/threading.py", line 870, in run
    self._target(*self._args, **self._kwargs)
    │    │        │    │        │    └ {}
    │    │        │    │        └ <Thread(Thread-11911, started daemon 139834033260288)>
    │    │        │    └ ([],)
    │    │        └ <Thread(Thread-11911, started daemon 139834033260288)>
    │    └ <bound method ProjectManager.crawl_hot_title of <monitor.projectManager.ProjectManager object at 0x7f31042e52e0>>
    └ <Thread(Thread-11911, started daemon 139834033260288)>

  File "/home/users/Scy/yuqing/spider/monitor/projectManager.py", line 725, in crawl_hot_title
    self.hot_spider_manager.crawl_hot()
    │    │                  └ <function HotSpiderManager.crawl_hot at 0x7f31042e7ca0>
    │    └ <monitor.spiderManager.HotSpiderManager object at 0x7f3103ffd9d0>
    └ <monitor.projectManager.ProjectManager object at 0x7f31042e52e0>

  File "/home/users/Scy/yuqing/spider/monitor/spiderManager.py", line 50, in crawl_hot
    status, title = spider.get_title(headers, hot_url)
    │               │      │         │        └ 'https://weibo.com/ajax/side/hotSearch'
    │               │      │         └ {'accept': 'application/json, text/plain, */*', 'accept-encoding': 'gzip, deflate, br', 'accept-language': 'zh-CN,zh;q=0.9', ...
    │               │      └ <function Weibo.get_title at 0x7f3103f531f0>
    │               └ <monitor.hotSpiders.weibo.Weibo object at 0x7f3103fb2670>
    └ False

> File "/home/users/Scy/yuqing/spider/monitor/hotSpiders/weibo.py", line 24, in get_title
    response = requests.get(url, headers=headers,timeout=10)
               │        │   │            └ {'accept': 'application/json, text/plain, */*', 'accept-encoding': 'gzip, deflate, br', 'accept-language': 'zh-CN,zh;q=0.9', ...
               │        │   └ 'https://weibo.com/ajax/side/hotSearch'
               │        └ <function get at 0x7f31f8028430>
               └ <module 'requests' from '/home/chase/.local/lib/python3.8/site-packages/requests/__init__.py'>

  File "/home/chase/.local/lib/python3.8/site-packages/requests/api.py", line 75, in get
    return request('get', url, params=params, **kwargs)
           │              │           │         └ {'headers': {'accept': 'application/json, text/plain, */*', 'accept-encoding': 'gzip, deflate, br', 'accept-language': 'zh-CN...
           │              │           └ None
           │              └ 'https://weibo.com/ajax/side/hotSearch'
           └ <function request at 0x7f31f8018280>
  File "/home/chase/.local/lib/python3.8/site-packages/requests/api.py", line 61, in request
    return session.request(method=method, url=url, **kwargs)
           │       │              │           │      └ {'params': None, 'headers': {'accept': 'application/json, text/plain, */*', 'accept-encoding': 'gzip, deflate, br', 'accept-l...
           │       │              │           └ 'https://weibo.com/ajax/side/hotSearch'
           │       │              └ 'get'
           │       └ <function Session.request at 0x7f31f8031b80>
           └ <requests.sessions.Session object at 0x7f2f981cdfa0>
  File "/home/chase/.local/lib/python3.8/site-packages/requests/sessions.py", line 542, in request
    resp = self.send(prep, **send_kwargs)
           │    │    │       └ {'timeout': 10, 'allow_redirects': True, 'verify': True, 'proxies': OrderedDict(), 'stream': False, 'cert': None}
           │    │    └ <PreparedRequest [GET]>
           │    └ <function Session.send at 0x7f31f8028040>
           └ <requests.sessions.Session object at 0x7f2f981cdfa0>
  File "/home/chase/.local/lib/python3.8/site-packages/requests/sessions.py", line 655, in send
    r = adapter.send(request, **kwargs)
        │       │    │          └ {'timeout': 10, 'verify': True, 'proxies': OrderedDict(), 'stream': False, 'cert': None}
        │       │    └ <PreparedRequest [GET]>
        │       └ <function HTTPAdapter.send at 0x7f31f80314c0>
        └ <requests.adapters.HTTPAdapter object at 0x7f3018622310>
  File "/home/chase/.local/lib/python3.8/site-packages/requests/adapters.py", line 516, in send
    raise ConnectionError(e, request=request)
          │                          └ <PreparedRequest [GET]>
          └ <class 'requests.exceptions.ConnectionError'>

requests.exceptions.ConnectionError: HTTPSConnectionPool(host='weibo.com', port=443): Max retries exceeded with url: /ajax/side/hotSearch (Caused by NewConnectionError('<urllib3.connection.HTTPSConnection object at 0x7f30782e6a60>: Failed to establish a new connection: [Errno 22] Invalid argument'))
2022-05-14 05:59:35.102 | ERROR    | base.db.mysql:update:390 - 【mysql更新数据出错】
Traceback (most recent call last):

  File "/home/chase/.local/lib/python3.8/site-packages/sqlalchemy/engine/base.py", line 1771, in _execute_context
    self.dialect.do_execute(
    │    │       └ <function DefaultDialect.do_execute at 0x7f31f38f75e0>
    │    └ <sqlalchemy.dialects.mysql.pymysql.MySQLDialect_pymysql object at 0x7f3103ffde20>
    └ <sqlalchemy.engine.base.Connection object at 0x7f2de9bb1e50>
  File "/home/chase/.local/lib/python3.8/site-packages/sqlalchemy/engine/default.py", line 717, in do_execute
    cursor.execute(statement, parameters)
    │      │       │          └ {'server_id': '180.201.163.246:6800', 'ip': '180.201.163.246', 'username': 'chase', 'password': '1004532947463916923527391366...
    │      │       └ 'UPDATE device SET server_id=%(server_id)s, ip=%(ip)s, username=%(username)s, password=%(password)s, address=%(address)s, por...
    │      └ <function Cursor.execute at 0x7f31f354cdc0>
    └ <pymysql.cursors.Cursor object at 0x7f30980a6af0>
  File "/home/chase/.local/lib/python3.8/site-packages/pymysql/cursors.py", line 148, in execute
    result = self._query(query)
             │    │      └ "UPDATE device SET server_id='180.201.163.246:6800', ip='180.201.163.246', username='chase', password='1004532947463916923527...
             │    └ <function Cursor._query at 0x7f31f34d7280>
             └ <pymysql.cursors.Cursor object at 0x7f30980a6af0>
  File "/home/chase/.local/lib/python3.8/site-packages/pymysql/cursors.py", line 310, in _query
    conn.query(q)
    │    │     └ "UPDATE device SET server_id='180.201.163.246:6800', ip='180.201.163.246', username='chase', password='1004532947463916923527...
    │    └ <function Connection.query at 0x7f31f34e5670>
    └ <pymysql.connections.Connection object at 0x7f2f98522400>
  File "/home/chase/.local/lib/python3.8/site-packages/pymysql/connections.py", line 548, in query
    self._affected_rows = self._read_query_result(unbuffered=unbuffered)
    │    │                │    │                             └ False
    │    │                │    └ <function Connection._read_query_result at 0x7f31f34e5ca0>
    │    │                └ <pymysql.connections.Connection object at 0x7f2f98522400>
    │    └ 1
    └ <pymysql.connections.Connection object at 0x7f2f98522400>
  File "/home/chase/.local/lib/python3.8/site-packages/pymysql/connections.py", line 775, in _read_query_result
    result.read()
    │      └ <function MySQLResult.read at 0x7f31f34e64c0>
    └ <pymysql.connections.MySQLResult object at 0x7f2de990ee80>
  File "/home/chase/.local/lib/python3.8/site-packages/pymysql/connections.py", line 1156, in read
    first_packet = self.connection._read_packet()
                   │    └ None
                   └ <pymysql.connections.MySQLResult object at 0x7f2de990ee80>
  File "/home/chase/.local/lib/python3.8/site-packages/pymysql/connections.py", line 725, in _read_packet
    packet.raise_for_error()
    │      └ <function MysqlPacket.raise_for_error at 0x7f31f34ddee0>
    └ <pymysql.protocol.MysqlPacket object at 0x7f309878bb80>
  File "/home/chase/.local/lib/python3.8/site-packages/pymysql/protocol.py", line 221, in raise_for_error
    err.raise_mysql_exception(self._data)
    │   │                     │    └ <member '_data' of 'MysqlPacket' objects>
    │   │                     └ <pymysql.protocol.MysqlPacket object at 0x7f309878bb80>
    │   └ <function raise_mysql_exception at 0x7f31f358c670>
    └ <module 'pymysql.err' from '/home/chase/.local/lib/python3.8/site-packages/pymysql/err.py'>
  File "/home/chase/.local/lib/python3.8/site-packages/pymysql/err.py", line 143, in raise_mysql_exception
    raise errorclass(errno, errval)
          │          │      └ "Duplicate entry '180.201.163.246:6800' for key 'device.PRIMARY'"
          │          └ 1062
          └ <class 'pymysql.err.IntegrityError'>

pymysql.err.IntegrityError: (1062, "Duplicate entry '180.201.163.246:6800' for key 'device.PRIMARY'")


The above exception was the direct cause of the following exception:


Traceback (most recent call last):

  File "/usr/lib/python3.8/threading.py", line 890, in _bootstrap
    self._bootstrap_inner()
    │    └ <function Thread._bootstrap_inner at 0x7f321bf29a60>
    └ <Thread(Thread-11914, started daemon 139839705151232)>
  File "/usr/lib/python3.8/threading.py", line 932, in _bootstrap_inner
    self.run()
    │    └ <function Thread.run at 0x7f321bf29790>
    └ <Thread(Thread-11914, started daemon 139839705151232)>
  File "/usr/lib/python3.8/threading.py", line 870, in run
    self._target(*self._args, **self._kwargs)
    │    │        │    │        │    └ {}
    │    │        │    │        └ <Thread(Thread-11914, started daemon 139839705151232)>
    │    │        │    └ ('ProjectManager.run_func_by_thread',)
    │    │        └ <Thread(Thread-11914, started daemon 139839705151232)>
    │    └ <bound method ProjectManager.get_request_from_keywords_hot of <monitor.projectManager.ProjectManager object at 0x7f31042e52e0>>
    └ <Thread(Thread-11914, started daemon 139839705151232)>

  File "/home/users/Scy/yuqing/spider/monitor/projectManager.py", line 799, in get_request_from_keywords_hot
    self.start_finished_spider_every_interval(project_names)
    │    │                                    └ ['default', 'test']
    │    └ <function ProjectManager.start_finished_spider_every_interval at 0x7f3104005280>
    └ <monitor.projectManager.ProjectManager object at 0x7f31042e52e0>

  File "/home/users/Scy/yuqing/spider/monitor/projectManager.py", line 784, in start_finished_spider_every_interval
    self[name].start_spider()
    │    └ 'default'
    └ <monitor.projectManager.ProjectManager object at 0x7f31042e52e0>

  File "/home/users/Scy/yuqing/spider/monitor/projectManager.py", line 366, in start_spider
    self.update_device_valid(device)
    │    │                   └ <monitor.deviceManager.DeviceC object at 0x7f3104029220>
    │    └ <function Project.update_device_valid at 0x7f3104003280>
    └ <monitor.projectManager.Project object at 0x7f3104029460>

  File "/home/users/Scy/yuqing/spider/monitor/projectManager.py", line 421, in update_device_valid
    self.database_manager.mysql.update(Device(**device.to_item()))
    │    │                │     │      │        │      └ <function DeviceC.to_item at 0x7f31f34ed310>
    │    │                │     │      │        └ <monitor.deviceManager.DeviceC object at 0x7f3104029220>
    │    │                │     │      └ <class 'base.db.mysql.Device'>
    │    │                │     └ <function Mysql.update at 0x7f31f35f4790>
    │    │                └ <base.db.mysql.Mysql object at 0x7f3103ffdfd0>
    │    └ <base.db.dbSlot.Slot object at 0x7f3103ffdf10>
    └ <monitor.projectManager.Project object at 0x7f3104029460>

> File "/home/users/Scy/yuqing/spider/base/db/mysql.py", line 375, in update
    row.update(new)
    │   │      └ {'server_id': '180.201.163.246:6800', 'ip': '180.201.163.246', 'username': 'chase', 'password': '1004532947463916923527391366...
    │   └ <function Query.update at 0x7f31f37333a0>
    └ <sqlalchemy.orm.query.Query object at 0x7f2de9bb1370>

  File "/home/chase/.local/lib/python3.8/site-packages/sqlalchemy/orm/query.py", line 3221, in update
    result = self.session.execute(
             │    │       └ <function Session.execute at 0x7f31f370faf0>
             │    └ <sqlalchemy.orm.session.Session object at 0x7f2de9bb1460>
             └ <sqlalchemy.orm.query.Query object at 0x7f2de9bb1370>
  File "/home/chase/.local/lib/python3.8/site-packages/sqlalchemy/orm/session.py", line 1689, in execute
    result = conn._execute_20(statement, params or {}, execution_options)
             │    │           │          │             └ immutabledict({'synchronize_session': 'evaluate', '_sa_orm_update_options': default_update_options(_matched_objects=[], _reso...
             │    │           │          └ immutabledict({})
             │    │           └ <sqlalchemy.sql.annotation.AnnotatedUpdate object at 0x7f30980a6910>
             │    └ <function Connection._execute_20 at 0x7f31f39bc790>
             └ <sqlalchemy.engine.base.Connection object at 0x7f2de9bb1e50>
  File "/home/chase/.local/lib/python3.8/site-packages/sqlalchemy/engine/base.py", line 1583, in _execute_20
    return meth(self, args_10style, kwargs_10style, execution_options)
           │    │     │             │               └ immutabledict({'synchronize_session': 'evaluate', '_sa_orm_update_options': default_update_options(_matched_objects=[], _reso...
           │    │     │             └ immutabledict({})
           │    │     └ ({},)
           │    └ <sqlalchemy.engine.base.Connection object at 0x7f2de9bb1e50>
           └ <bound method ClauseElement._execute_on_connection of <sqlalchemy.sql.annotation.AnnotatedUpdate object at 0x7f30980a6910>>
  File "/home/chase/.local/lib/python3.8/site-packages/sqlalchemy/sql/elements.py", line 323, in _execute_on_connection
    return connection._execute_clauseelement(
           │          └ <function Connection._execute_clauseelement at 0x7f31f39bc5e0>
           └ <sqlalchemy.engine.base.Connection object at 0x7f2de9bb1e50>
  File "/home/chase/.local/lib/python3.8/site-packages/sqlalchemy/engine/base.py", line 1452, in _execute_clauseelement
    ret = self._execute_context(
          │    └ <function Connection._execute_context at 0x7f31f39bc8b0>
          └ <sqlalchemy.engine.base.Connection object at 0x7f2de9bb1e50>
  File "/home/chase/.local/lib/python3.8/site-packages/sqlalchemy/engine/base.py", line 1814, in _execute_context
    self._handle_dbapi_exception(
    │    └ <function Connection._handle_dbapi_exception at 0x7f31f39bca60>
    └ <sqlalchemy.engine.base.Connection object at 0x7f2de9bb1e50>
  File "/home/chase/.local/lib/python3.8/site-packages/sqlalchemy/engine/base.py", line 1995, in _handle_dbapi_exception
    util.raise_(
    │    └ <function raise_ at 0x7f31f3d7ea60>
    └ <module 'sqlalchemy.util' from '/home/chase/.local/lib/python3.8/site-packages/sqlalchemy/util/__init__.py'>
  File "/home/chase/.local/lib/python3.8/site-packages/sqlalchemy/util/compat.py", line 207, in raise_
    raise exception
  File "/home/chase/.local/lib/python3.8/site-packages/sqlalchemy/engine/base.py", line 1771, in _execute_context
    self.dialect.do_execute(
    │    │       └ <function DefaultDialect.do_execute at 0x7f31f38f75e0>
    │    └ <sqlalchemy.dialects.mysql.pymysql.MySQLDialect_pymysql object at 0x7f3103ffde20>
    └ <sqlalchemy.engine.base.Connection object at 0x7f2de9bb1e50>
  File "/home/chase/.local/lib/python3.8/site-packages/sqlalchemy/engine/default.py", line 717, in do_execute
    cursor.execute(statement, parameters)
    │      │       │          └ {'server_id': '180.201.163.246:6800', 'ip': '180.201.163.246', 'username': 'chase', 'password': '1004532947463916923527391366...
    │      │       └ 'UPDATE device SET server_id=%(server_id)s, ip=%(ip)s, username=%(username)s, password=%(password)s, address=%(address)s, por...
    │      └ <function Cursor.execute at 0x7f31f354cdc0>
    └ <pymysql.cursors.Cursor object at 0x7f30980a6af0>
  File "/home/chase/.local/lib/python3.8/site-packages/pymysql/cursors.py", line 148, in execute
    result = self._query(query)
             │    │      └ "UPDATE device SET server_id='180.201.163.246:6800', ip='180.201.163.246', username='chase', password='1004532947463916923527...
             │    └ <function Cursor._query at 0x7f31f34d7280>
             └ <pymysql.cursors.Cursor object at 0x7f30980a6af0>
  File "/home/chase/.local/lib/python3.8/site-packages/pymysql/cursors.py", line 310, in _query
    conn.query(q)
    │    │     └ "UPDATE device SET server_id='180.201.163.246:6800', ip='180.201.163.246', username='chase', password='1004532947463916923527...
    │    └ <function Connection.query at 0x7f31f34e5670>
    └ <pymysql.connections.Connection object at 0x7f2f98522400>
  File "/home/chase/.local/lib/python3.8/site-packages/pymysql/connections.py", line 548, in query
    self._affected_rows = self._read_query_result(unbuffered=unbuffered)
    │    │                │    │                             └ False
    │    │                │    └ <function Connection._read_query_result at 0x7f31f34e5ca0>
    │    │                └ <pymysql.connections.Connection object at 0x7f2f98522400>
    │    └ 1
    └ <pymysql.connections.Connection object at 0x7f2f98522400>
  File "/home/chase/.local/lib/python3.8/site-packages/pymysql/connections.py", line 775, in _read_query_result
    result.read()
    │      └ <function MySQLResult.read at 0x7f31f34e64c0>
    └ <pymysql.connections.MySQLResult object at 0x7f2de990ee80>
  File "/home/chase/.local/lib/python3.8/site-packages/pymysql/connections.py", line 1156, in read
    first_packet = self.connection._read_packet()
                   │    └ None
                   └ <pymysql.connections.MySQLResult object at 0x7f2de990ee80>
  File "/home/chase/.local/lib/python3.8/site-packages/pymysql/connections.py", line 725, in _read_packet
    packet.raise_for_error()
    │      └ <function MysqlPacket.raise_for_error at 0x7f31f34ddee0>
    └ <pymysql.protocol.MysqlPacket object at 0x7f309878bb80>
  File "/home/chase/.local/lib/python3.8/site-packages/pymysql/protocol.py", line 221, in raise_for_error
    err.raise_mysql_exception(self._data)
    │   │                     │    └ <member '_data' of 'MysqlPacket' objects>
    │   │                     └ <pymysql.protocol.MysqlPacket object at 0x7f309878bb80>
    │   └ <function raise_mysql_exception at 0x7f31f358c670>
    └ <module 'pymysql.err' from '/home/chase/.local/lib/python3.8/site-packages/pymysql/err.py'>
  File "/home/chase/.local/lib/python3.8/site-packages/pymysql/err.py", line 143, in raise_mysql_exception
    raise errorclass(errno, errval)
          │          │      └ "Duplicate entry '180.201.163.246:6800' for key 'device.PRIMARY'"
          │          └ 1062
          └ <class 'pymysql.err.IntegrityError'>

sqlalchemy.exc.IntegrityError: (pymysql.err.IntegrityError) (1062, "Duplicate entry '180.201.163.246:6800' for key 'device.PRIMARY'")
[SQL: UPDATE device SET server_id=%(server_id)s, ip=%(ip)s, username=%(username)s, password=%(password)s, address=%(address)s, port=%(port)s, valid=%(valid)s WHERE device.ip = %(ip_1)s]
[parameters: {'server_id': '180.201.163.246:6800', 'ip': '180.201.163.246', 'username': 'chase', 'password': '10045329474639169235273913663345783128883960702389300636778863440109152202692291171172863626587744644950485277779911545464218535075406888418871745671 ... (9 characters truncated) ... 90239961393908509451325683244799850723326815417781167162618651505730429528054305775801811382449434896920449123163302651887484968972793247986711223643', 'address': '/home/users/CT/pycharmproject/spiders/', 'port': 6800, 'valid': 1, 'ip_1': '180.201.163.246'}]
(Background on this error at: https://sqlalche.me/e/14/gkpj)
2022-05-14 05:59:52.365 | ERROR    | base.db.mysql:update:390 - 【mysql更新数据出错】
Traceback (most recent call last):

  File "/home/chase/.local/lib/python3.8/site-packages/sqlalchemy/engine/base.py", line 1771, in _execute_context
    self.dialect.do_execute(
    │    │       └ <function DefaultDialect.do_execute at 0x7f31f38f75e0>
    │    └ <sqlalchemy.dialects.mysql.pymysql.MySQLDialect_pymysql object at 0x7f3103ffde20>
    └ <sqlalchemy.engine.base.Connection object at 0x7f30b8795eb0>
  File "/home/chase/.local/lib/python3.8/site-packages/sqlalchemy/engine/default.py", line 717, in do_execute
    cursor.execute(statement, parameters)
    │      │       │          └ {'server_id': '180.201.163.246:6800', 'ip': '180.201.163.246', 'username': 'chase', 'password': '2710126241622280273161777674...
    │      │       └ 'UPDATE device SET server_id=%(server_id)s, ip=%(ip)s, username=%(username)s, password=%(password)s, address=%(address)s, por...
    │      └ <function Cursor.execute at 0x7f31f354cdc0>
    └ <pymysql.cursors.Cursor object at 0x7f2fb8626490>
  File "/home/chase/.local/lib/python3.8/site-packages/pymysql/cursors.py", line 148, in execute
    result = self._query(query)
             │    │      └ "UPDATE device SET server_id='180.201.163.246:6800', ip='180.201.163.246', username='chase', password='2710126241622280273161...
             │    └ <function Cursor._query at 0x7f31f34d7280>
             └ <pymysql.cursors.Cursor object at 0x7f2fb8626490>
  File "/home/chase/.local/lib/python3.8/site-packages/pymysql/cursors.py", line 310, in _query
    conn.query(q)
    │    │     └ "UPDATE device SET server_id='180.201.163.246:6800', ip='180.201.163.246', username='chase', password='2710126241622280273161...
    │    └ <function Connection.query at 0x7f31f34e5670>
    └ <pymysql.connections.Connection object at 0x7f30d82da850>
  File "/home/chase/.local/lib/python3.8/site-packages/pymysql/connections.py", line 548, in query
    self._affected_rows = self._read_query_result(unbuffered=unbuffered)
    │    │                │    │                             └ False
    │    │                │    └ <function Connection._read_query_result at 0x7f31f34e5ca0>
    │    │                └ <pymysql.connections.Connection object at 0x7f30d82da850>
    │    └ 1
    └ <pymysql.connections.Connection object at 0x7f30d82da850>
  File "/home/chase/.local/lib/python3.8/site-packages/pymysql/connections.py", line 775, in _read_query_result
    result.read()
    │      └ <function MySQLResult.read at 0x7f31f34e64c0>
    └ <pymysql.connections.MySQLResult object at 0x7f30b86f9820>
  File "/home/chase/.local/lib/python3.8/site-packages/pymysql/connections.py", line 1156, in read
    first_packet = self.connection._read_packet()
                   │    └ None
                   └ <pymysql.connections.MySQLResult object at 0x7f30b86f9820>
  File "/home/chase/.local/lib/python3.8/site-packages/pymysql/connections.py", line 725, in _read_packet
    packet.raise_for_error()
    │      └ <function MysqlPacket.raise_for_error at 0x7f31f34ddee0>
    └ <pymysql.protocol.MysqlPacket object at 0x7f30d8572ca0>
  File "/home/chase/.local/lib/python3.8/site-packages/pymysql/protocol.py", line 221, in raise_for_error
    err.raise_mysql_exception(self._data)
    │   │                     │    └ <member '_data' of 'MysqlPacket' objects>
    │   │                     └ <pymysql.protocol.MysqlPacket object at 0x7f30d8572ca0>
    │   └ <function raise_mysql_exception at 0x7f31f358c670>
    └ <module 'pymysql.err' from '/home/chase/.local/lib/python3.8/site-packages/pymysql/err.py'>
  File "/home/chase/.local/lib/python3.8/site-packages/pymysql/err.py", line 143, in raise_mysql_exception
    raise errorclass(errno, errval)
          │          │      └ "Duplicate entry '180.201.163.246:6800' for key 'device.PRIMARY'"
          │          └ 1062
          └ <class 'pymysql.err.IntegrityError'>

pymysql.err.IntegrityError: (1062, "Duplicate entry '180.201.163.246:6800' for key 'device.PRIMARY'")


The above exception was the direct cause of the following exception:


Traceback (most recent call last):

  File "/usr/lib/python3.8/threading.py", line 890, in _bootstrap
    self._bootstrap_inner()
    │    └ <function Thread._bootstrap_inner at 0x7f321bf29a60>
    └ <Thread(Thread-11918, started daemon 139834159150848)>
  File "/usr/lib/python3.8/threading.py", line 932, in _bootstrap_inner
    self.run()
    │    └ <function Thread.run at 0x7f321bf29790>
    └ <Thread(Thread-11918, started daemon 139834159150848)>
  File "/usr/lib/python3.8/threading.py", line 870, in run
    self._target(*self._args, **self._kwargs)
    │    │        │    │        │    └ {}
    │    │        │    │        └ <Thread(Thread-11918, started daemon 139834159150848)>
    │    │        │    └ ('ProjectManager.run_func_by_thread',)
    │    │        └ <Thread(Thread-11918, started daemon 139834159150848)>
    │    └ <bound method ProjectManager.get_request_from_keywords_hot of <monitor.projectManager.ProjectManager object at 0x7f31042e52e0>>
    └ <Thread(Thread-11918, started daemon 139834159150848)>

  File "/home/users/Scy/yuqing/spider/monitor/projectManager.py", line 799, in get_request_from_keywords_hot
    self.start_finished_spider_every_interval(project_names)
    │    │                                    └ ['default', 'test']
    │    └ <function ProjectManager.start_finished_spider_every_interval at 0x7f3104005280>
    └ <monitor.projectManager.ProjectManager object at 0x7f31042e52e0>

  File "/home/users/Scy/yuqing/spider/monitor/projectManager.py", line 784, in start_finished_spider_every_interval
    self[name].start_spider()
    │    └ 'default'
    └ <monitor.projectManager.ProjectManager object at 0x7f31042e52e0>

  File "/home/users/Scy/yuqing/spider/monitor/projectManager.py", line 366, in start_spider
    self.update_device_valid(device)
    │    │                   └ <monitor.deviceManager.DeviceC object at 0x7f3104029220>
    │    └ <function Project.update_device_valid at 0x7f3104003280>
    └ <monitor.projectManager.Project object at 0x7f3104029460>

  File "/home/users/Scy/yuqing/spider/monitor/projectManager.py", line 421, in update_device_valid
    self.database_manager.mysql.update(Device(**device.to_item()))
    │    │                │     │      │        │      └ <function DeviceC.to_item at 0x7f31f34ed310>
    │    │                │     │      │        └ <monitor.deviceManager.DeviceC object at 0x7f3104029220>
    │    │                │     │      └ <class 'base.db.mysql.Device'>
    │    │                │     └ <function Mysql.update at 0x7f31f35f4790>
    │    │                └ <base.db.mysql.Mysql object at 0x7f3103ffdfd0>
    │    └ <base.db.dbSlot.Slot object at 0x7f3103ffdf10>
    └ <monitor.projectManager.Project object at 0x7f3104029460>

> File "/home/users/Scy/yuqing/spider/base/db/mysql.py", line 375, in update
    row.update(new)
    │   │      └ {'server_id': '180.201.163.246:6800', 'ip': '180.201.163.246', 'username': 'chase', 'password': '2710126241622280273161777674...
    │   └ <function Query.update at 0x7f31f37333a0>
    └ <sqlalchemy.orm.query.Query object at 0x7f3038064cd0>

  File "/home/chase/.local/lib/python3.8/site-packages/sqlalchemy/orm/query.py", line 3221, in update
    result = self.session.execute(
             │    │       └ <function Session.execute at 0x7f31f370faf0>
             │    └ <sqlalchemy.orm.session.Session object at 0x7f3078314a00>
             └ <sqlalchemy.orm.query.Query object at 0x7f3038064cd0>
  File "/home/chase/.local/lib/python3.8/site-packages/sqlalchemy/orm/session.py", line 1689, in execute
    result = conn._execute_20(statement, params or {}, execution_options)
             │    │           │          │             └ immutabledict({'synchronize_session': 'evaluate', '_sa_orm_update_options': default_update_options(_matched_objects=[], _reso...
             │    │           │          └ immutabledict({})
             │    │           └ <sqlalchemy.sql.annotation.AnnotatedUpdate object at 0x7f2de9c1a4c0>
             │    └ <function Connection._execute_20 at 0x7f31f39bc790>
             └ <sqlalchemy.engine.base.Connection object at 0x7f30b8795eb0>
  File "/home/chase/.local/lib/python3.8/site-packages/sqlalchemy/engine/base.py", line 1583, in _execute_20
    return meth(self, args_10style, kwargs_10style, execution_options)
           │    │     │             │               └ immutabledict({'synchronize_session': 'evaluate', '_sa_orm_update_options': default_update_options(_matched_objects=[], _reso...
           │    │     │             └ immutabledict({})
           │    │     └ ({},)
           │    └ <sqlalchemy.engine.base.Connection object at 0x7f30b8795eb0>
           └ <bound method ClauseElement._execute_on_connection of <sqlalchemy.sql.annotation.AnnotatedUpdate object at 0x7f2de9c1a4c0>>
  File "/home/chase/.local/lib/python3.8/site-packages/sqlalchemy/sql/elements.py", line 323, in _execute_on_connection
    return connection._execute_clauseelement(
           │          └ <function Connection._execute_clauseelement at 0x7f31f39bc5e0>
           └ <sqlalchemy.engine.base.Connection object at 0x7f30b8795eb0>
  File "/home/chase/.local/lib/python3.8/site-packages/sqlalchemy/engine/base.py", line 1452, in _execute_clauseelement
    ret = self._execute_context(
          │    └ <function Connection._execute_context at 0x7f31f39bc8b0>
          └ <sqlalchemy.engine.base.Connection object at 0x7f30b8795eb0>
  File "/home/chase/.local/lib/python3.8/site-packages/sqlalchemy/engine/base.py", line 1814, in _execute_context
    self._handle_dbapi_exception(
    │    └ <function Connection._handle_dbapi_exception at 0x7f31f39bca60>
    └ <sqlalchemy.engine.base.Connection object at 0x7f30b8795eb0>
  File "/home/chase/.local/lib/python3.8/site-packages/sqlalchemy/engine/base.py", line 1995, in _handle_dbapi_exception
    util.raise_(
    │    └ <function raise_ at 0x7f31f3d7ea60>
    └ <module 'sqlalchemy.util' from '/home/chase/.local/lib/python3.8/site-packages/sqlalchemy/util/__init__.py'>
  File "/home/chase/.local/lib/python3.8/site-packages/sqlalchemy/util/compat.py", line 207, in raise_
    raise exception
  File "/home/chase/.local/lib/python3.8/site-packages/sqlalchemy/engine/base.py", line 1771, in _execute_context
    self.dialect.do_execute(
    │    │       └ <function DefaultDialect.do_execute at 0x7f31f38f75e0>
    │    └ <sqlalchemy.dialects.mysql.pymysql.MySQLDialect_pymysql object at 0x7f3103ffde20>
    └ <sqlalchemy.engine.base.Connection object at 0x7f30b8795eb0>
  File "/home/chase/.local/lib/python3.8/site-packages/sqlalchemy/engine/default.py", line 717, in do_execute
    cursor.execute(statement, parameters)
    │      │       │          └ {'server_id': '180.201.163.246:6800', 'ip': '180.201.163.246', 'username': 'chase', 'password': '2710126241622280273161777674...
    │      │       └ 'UPDATE device SET server_id=%(server_id)s, ip=%(ip)s, username=%(username)s, password=%(password)s, address=%(address)s, por...
    │      └ <function Cursor.execute at 0x7f31f354cdc0>
    └ <pymysql.cursors.Cursor object at 0x7f2fb8626490>
  File "/home/chase/.local/lib/python3.8/site-packages/pymysql/cursors.py", line 148, in execute
    result = self._query(query)
             │    │      └ "UPDATE device SET server_id='180.201.163.246:6800', ip='180.201.163.246', username='chase', password='2710126241622280273161...
             │    └ <function Cursor._query at 0x7f31f34d7280>
             └ <pymysql.cursors.Cursor object at 0x7f2fb8626490>
  File "/home/chase/.local/lib/python3.8/site-packages/pymysql/cursors.py", line 310, in _query
    conn.query(q)
    │    │     └ "UPDATE device SET server_id='180.201.163.246:6800', ip='180.201.163.246', username='chase', password='2710126241622280273161...
    │    └ <function Connection.query at 0x7f31f34e5670>
    └ <pymysql.connections.Connection object at 0x7f30d82da850>
  File "/home/chase/.local/lib/python3.8/site-packages/pymysql/connections.py", line 548, in query
    self._affected_rows = self._read_query_result(unbuffered=unbuffered)
    │    │                │    │                             └ False
    │    │                │    └ <function Connection._read_query_result at 0x7f31f34e5ca0>
    │    │                └ <pymysql.connections.Connection object at 0x7f30d82da850>
    │    └ 1
    └ <pymysql.connections.Connection object at 0x7f30d82da850>
  File "/home/chase/.local/lib/python3.8/site-packages/pymysql/connections.py", line 775, in _read_query_result
    result.read()
    │      └ <function MySQLResult.read at 0x7f31f34e64c0>
    └ <pymysql.connections.MySQLResult object at 0x7f30b86f9820>
  File "/home/chase/.local/lib/python3.8/site-packages/pymysql/connections.py", line 1156, in read
    first_packet = self.connection._read_packet()
                   │    └ None
                   └ <pymysql.connections.MySQLResult object at 0x7f30b86f9820>
  File "/home/chase/.local/lib/python3.8/site-packages/pymysql/connections.py", line 725, in _read_packet
    packet.raise_for_error()
    │      └ <function MysqlPacket.raise_for_error at 0x7f31f34ddee0>
    └ <pymysql.protocol.MysqlPacket object at 0x7f30d8572ca0>
  File "/home/chase/.local/lib/python3.8/site-packages/pymysql/protocol.py", line 221, in raise_for_error
    err.raise_mysql_exception(self._data)
    │   │                     │    └ <member '_data' of 'MysqlPacket' objects>
    │   │                     └ <pymysql.protocol.MysqlPacket object at 0x7f30d8572ca0>
    │   └ <function raise_mysql_exception at 0x7f31f358c670>
    └ <module 'pymysql.err' from '/home/chase/.local/lib/python3.8/site-packages/pymysql/err.py'>
  File "/home/chase/.local/lib/python3.8/site-packages/pymysql/err.py", line 143, in raise_mysql_exception
    raise errorclass(errno, errval)
          │          │      └ "Duplicate entry '180.201.163.246:6800' for key 'device.PRIMARY'"
          │          └ 1062
          └ <class 'pymysql.err.IntegrityError'>

sqlalchemy.exc.IntegrityError: (pymysql.err.IntegrityError) (1062, "Duplicate entry '180.201.163.246:6800' for key 'device.PRIMARY'")
[SQL: UPDATE device SET server_id=%(server_id)s, ip=%(ip)s, username=%(username)s, password=%(password)s, address=%(address)s, port=%(port)s, valid=%(valid)s WHERE device.ip = %(ip_1)s]
[parameters: {'server_id': '180.201.163.246:6800', 'ip': '180.201.163.246', 'username': 'chase', 'password': '27101262416222802731617776746644146288182094661692123716027886813353981391767041934634039386527707368743544371368505711703663530292933196718642883597 ... (10 characters truncated) ... 09018669269285436535158712850056947863418688508222573168367517465488909984487752428978802812339094408987723475947261313976767395772530159572490723863', 'address': '/home/users/CT/pycharmproject/spiders/', 'port': 6800, 'valid': 1, 'ip_1': '180.201.163.246'}]
(Background on this error at: https://sqlalche.me/e/14/gkpj)
2022-05-14 06:00:10.347 | ERROR    | base.db.mysql:update:390 - 【mysql更新数据出错】
Traceback (most recent call last):

  File "/home/chase/.local/lib/python3.8/site-packages/sqlalchemy/engine/base.py", line 1771, in _execute_context
    self.dialect.do_execute(
    │    │       └ <function DefaultDialect.do_execute at 0x7f31f38f75e0>
    │    └ <sqlalchemy.dialects.mysql.pymysql.MySQLDialect_pymysql object at 0x7f3103ffde20>
    └ <sqlalchemy.engine.base.Connection object at 0x7f3018621d60>
  File "/home/chase/.local/lib/python3.8/site-packages/sqlalchemy/engine/default.py", line 717, in do_execute
    cursor.execute(statement, parameters)
    │      │       │          └ {'server_id': '180.201.163.246:6800', 'ip': '180.201.163.246', 'username': 'chase', 'password': '5810337789210403347146498079...
    │      │       └ 'UPDATE device SET server_id=%(server_id)s, ip=%(ip)s, username=%(username)s, password=%(password)s, address=%(address)s, por...
    │      └ <function Cursor.execute at 0x7f31f354cdc0>
    └ <pymysql.cursors.Cursor object at 0x7f30580eea90>
  File "/home/chase/.local/lib/python3.8/site-packages/pymysql/cursors.py", line 148, in execute
    result = self._query(query)
             │    │      └ "UPDATE device SET server_id='180.201.163.246:6800', ip='180.201.163.246', username='chase', password='5810337789210403347146...
             │    └ <function Cursor._query at 0x7f31f34d7280>
             └ <pymysql.cursors.Cursor object at 0x7f30580eea90>
  File "/home/chase/.local/lib/python3.8/site-packages/pymysql/cursors.py", line 310, in _query
    conn.query(q)
    │    │     └ "UPDATE device SET server_id='180.201.163.246:6800', ip='180.201.163.246', username='chase', password='5810337789210403347146...
    │    └ <function Connection.query at 0x7f31f34e5670>
    └ <pymysql.connections.Connection object at 0x7f2e12bf0280>
  File "/home/chase/.local/lib/python3.8/site-packages/pymysql/connections.py", line 548, in query
    self._affected_rows = self._read_query_result(unbuffered=unbuffered)
    │    │                │    │                             └ False
    │    │                │    └ <function Connection._read_query_result at 0x7f31f34e5ca0>
    │    │                └ <pymysql.connections.Connection object at 0x7f2e12bf0280>
    │    └ 1
    └ <pymysql.connections.Connection object at 0x7f2e12bf0280>
  File "/home/chase/.local/lib/python3.8/site-packages/pymysql/connections.py", line 775, in _read_query_result
    result.read()
    │      └ <function MySQLResult.read at 0x7f31f34e64c0>
    └ <pymysql.connections.MySQLResult object at 0x7f303845ae50>
  File "/home/chase/.local/lib/python3.8/site-packages/pymysql/connections.py", line 1156, in read
    first_packet = self.connection._read_packet()
                   │    └ None
                   └ <pymysql.connections.MySQLResult object at 0x7f303845ae50>
  File "/home/chase/.local/lib/python3.8/site-packages/pymysql/connections.py", line 725, in _read_packet
    packet.raise_for_error()
    │      └ <function MysqlPacket.raise_for_error at 0x7f31f34ddee0>
    └ <pymysql.protocol.MysqlPacket object at 0x7f2f78795a60>
  File "/home/chase/.local/lib/python3.8/site-packages/pymysql/protocol.py", line 221, in raise_for_error
    err.raise_mysql_exception(self._data)
    │   │                     │    └ <member '_data' of 'MysqlPacket' objects>
    │   │                     └ <pymysql.protocol.MysqlPacket object at 0x7f2f78795a60>
    │   └ <function raise_mysql_exception at 0x7f31f358c670>
    └ <module 'pymysql.err' from '/home/chase/.local/lib/python3.8/site-packages/pymysql/err.py'>
  File "/home/chase/.local/lib/python3.8/site-packages/pymysql/err.py", line 143, in raise_mysql_exception
    raise errorclass(errno, errval)
          │          │      └ "Duplicate entry '180.201.163.246:6800' for key 'device.PRIMARY'"
          │          └ 1062
          └ <class 'pymysql.err.IntegrityError'>

pymysql.err.IntegrityError: (1062, "Duplicate entry '180.201.163.246:6800' for key 'device.PRIMARY'")


The above exception was the direct cause of the following exception:


Traceback (most recent call last):

  File "/usr/lib/python3.8/threading.py", line 890, in _bootstrap
    self._bootstrap_inner()
    │    └ <function Thread._bootstrap_inner at 0x7f321bf29a60>
    └ <Thread(Thread-11923, started daemon 139848442009344)>
  File "/usr/lib/python3.8/threading.py", line 932, in _bootstrap_inner
    self.run()
    │    └ <function Thread.run at 0x7f321bf29790>
    └ <Thread(Thread-11923, started daemon 139848442009344)>
  File "/usr/lib/python3.8/threading.py", line 870, in run
    self._target(*self._args, **self._kwargs)
    │    │        │    │        │    └ {}
    │    │        │    │        └ <Thread(Thread-11923, started daemon 139848442009344)>
    │    │        │    └ ('ProjectManager.run_func_by_thread',)
    │    │        └ <Thread(Thread-11923, started daemon 139848442009344)>
    │    └ <bound method ProjectManager.get_request_from_keywords_hot of <monitor.projectManager.ProjectManager object at 0x7f31042e52e0>>
    └ <Thread(Thread-11923, started daemon 139848442009344)>

  File "/home/users/Scy/yuqing/spider/monitor/projectManager.py", line 799, in get_request_from_keywords_hot
    self.start_finished_spider_every_interval(project_names)
    │    │                                    └ ['default', 'test']
    │    └ <function ProjectManager.start_finished_spider_every_interval at 0x7f3104005280>
    └ <monitor.projectManager.ProjectManager object at 0x7f31042e52e0>

  File "/home/users/Scy/yuqing/spider/monitor/projectManager.py", line 784, in start_finished_spider_every_interval
    self[name].start_spider()
    │    └ 'default'
    └ <monitor.projectManager.ProjectManager object at 0x7f31042e52e0>

  File "/home/users/Scy/yuqing/spider/monitor/projectManager.py", line 366, in start_spider
    self.update_device_valid(device)
    │    │                   └ <monitor.deviceManager.DeviceC object at 0x7f3104029220>
    │    └ <function Project.update_device_valid at 0x7f3104003280>
    └ <monitor.projectManager.Project object at 0x7f3104029460>

  File "/home/users/Scy/yuqing/spider/monitor/projectManager.py", line 421, in update_device_valid
    self.database_manager.mysql.update(Device(**device.to_item()))
    │    │                │     │      │        │      └ <function DeviceC.to_item at 0x7f31f34ed310>
    │    │                │     │      │        └ <monitor.deviceManager.DeviceC object at 0x7f3104029220>
    │    │                │     │      └ <class 'base.db.mysql.Device'>
    │    │                │     └ <function Mysql.update at 0x7f31f35f4790>
    │    │                └ <base.db.mysql.Mysql object at 0x7f3103ffdfd0>
    │    └ <base.db.dbSlot.Slot object at 0x7f3103ffdf10>
    └ <monitor.projectManager.Project object at 0x7f3104029460>

> File "/home/users/Scy/yuqing/spider/base/db/mysql.py", line 375, in update
    row.update(new)
    │   │      └ {'server_id': '180.201.163.246:6800', 'ip': '180.201.163.246', 'username': 'chase', 'password': '5810337789210403347146498079...
    │   └ <function Query.update at 0x7f31f37333a0>
    └ <sqlalchemy.orm.query.Query object at 0x7f31f91b8610>

  File "/home/chase/.local/lib/python3.8/site-packages/sqlalchemy/orm/query.py", line 3221, in update
    result = self.session.execute(
             │    │       └ <function Session.execute at 0x7f31f370faf0>
             │    └ <sqlalchemy.orm.session.Session object at 0x7f31f91b8670>
             └ <sqlalchemy.orm.query.Query object at 0x7f31f91b8610>
  File "/home/chase/.local/lib/python3.8/site-packages/sqlalchemy/orm/session.py", line 1689, in execute
    result = conn._execute_20(statement, params or {}, execution_options)
             │    │           │          │             └ immutabledict({'synchronize_session': 'evaluate', '_sa_orm_update_options': default_update_options(_matched_objects=[], _reso...
             │    │           │          └ immutabledict({})
             │    │           └ <sqlalchemy.sql.annotation.AnnotatedUpdate object at 0x7f3098087370>
             │    └ <function Connection._execute_20 at 0x7f31f39bc790>
             └ <sqlalchemy.engine.base.Connection object at 0x7f3018621d60>
  File "/home/chase/.local/lib/python3.8/site-packages/sqlalchemy/engine/base.py", line 1583, in _execute_20
    return meth(self, args_10style, kwargs_10style, execution_options)
           │    │     │             │               └ immutabledict({'synchronize_session': 'evaluate', '_sa_orm_update_options': default_update_options(_matched_objects=[], _reso...
           │    │     │             └ immutabledict({})
           │    │     └ ({},)
           │    └ <sqlalchemy.engine.base.Connection object at 0x7f3018621d60>
           └ <bound method ClauseElement._execute_on_connection of <sqlalchemy.sql.annotation.AnnotatedUpdate object at 0x7f3098087370>>
  File "/home/chase/.local/lib/python3.8/site-packages/sqlalchemy/sql/elements.py", line 323, in _execute_on_connection
    return connection._execute_clauseelement(
           │          └ <function Connection._execute_clauseelement at 0x7f31f39bc5e0>
           └ <sqlalchemy.engine.base.Connection object at 0x7f3018621d60>
  File "/home/chase/.local/lib/python3.8/site-packages/sqlalchemy/engine/base.py", line 1452, in _execute_clauseelement
    ret = self._execute_context(
          │    └ <function Connection._execute_context at 0x7f31f39bc8b0>
          └ <sqlalchemy.engine.base.Connection object at 0x7f3018621d60>
  File "/home/chase/.local/lib/python3.8/site-packages/sqlalchemy/engine/base.py", line 1814, in _execute_context
    self._handle_dbapi_exception(
    │    └ <function Connection._handle_dbapi_exception at 0x7f31f39bca60>
    └ <sqlalchemy.engine.base.Connection object at 0x7f3018621d60>
  File "/home/chase/.local/lib/python3.8/site-packages/sqlalchemy/engine/base.py", line 1995, in _handle_dbapi_exception
    util.raise_(
    │    └ <function raise_ at 0x7f31f3d7ea60>
    └ <module 'sqlalchemy.util' from '/home/chase/.local/lib/python3.8/site-packages/sqlalchemy/util/__init__.py'>
  File "/home/chase/.local/lib/python3.8/site-packages/sqlalchemy/util/compat.py", line 207, in raise_
    raise exception
  File "/home/chase/.local/lib/python3.8/site-packages/sqlalchemy/engine/base.py", line 1771, in _execute_context
    self.dialect.do_execute(
    │    │       └ <function DefaultDialect.do_execute at 0x7f31f38f75e0>
    │    └ <sqlalchemy.dialects.mysql.pymysql.MySQLDialect_pymysql object at 0x7f3103ffde20>
    └ <sqlalchemy.engine.base.Connection object at 0x7f3018621d60>
  File "/home/chase/.local/lib/python3.8/site-packages/sqlalchemy/engine/default.py", line 717, in do_execute
    cursor.execute(statement, parameters)
    │      │       │          └ {'server_id': '180.201.163.246:6800', 'ip': '180.201.163.246', 'username': 'chase', 'password': '5810337789210403347146498079...
    │      │       └ 'UPDATE device SET server_id=%(server_id)s, ip=%(ip)s, username=%(username)s, password=%(password)s, address=%(address)s, por...
    │      └ <function Cursor.execute at 0x7f31f354cdc0>
    └ <pymysql.cursors.Cursor object at 0x7f30580eea90>
  File "/home/chase/.local/lib/python3.8/site-packages/pymysql/cursors.py", line 148, in execute
    result = self._query(query)
             │    │      └ "UPDATE device SET server_id='180.201.163.246:6800', ip='180.201.163.246', username='chase', password='5810337789210403347146...
             │    └ <function Cursor._query at 0x7f31f34d7280>
             └ <pymysql.cursors.Cursor object at 0x7f30580eea90>
  File "/home/chase/.local/lib/python3.8/site-packages/pymysql/cursors.py", line 310, in _query
    conn.query(q)
    │    │     └ "UPDATE device SET server_id='180.201.163.246:6800', ip='180.201.163.246', username='chase', password='5810337789210403347146...
    │    └ <function Connection.query at 0x7f31f34e5670>
    └ <pymysql.connections.Connection object at 0x7f2e12bf0280>
  File "/home/chase/.local/lib/python3.8/site-packages/pymysql/connections.py", line 548, in query
    self._affected_rows = self._read_query_result(unbuffered=unbuffered)
    │    │                │    │                             └ False
    │    │                │    └ <function Connection._read_query_result at 0x7f31f34e5ca0>
    │    │                └ <pymysql.connections.Connection object at 0x7f2e12bf0280>
    │    └ 1
    └ <pymysql.connections.Connection object at 0x7f2e12bf0280>
  File "/home/chase/.local/lib/python3.8/site-packages/pymysql/connections.py", line 775, in _read_query_result
    result.read()
    │      └ <function MySQLResult.read at 0x7f31f34e64c0>
    └ <pymysql.connections.MySQLResult object at 0x7f303845ae50>
  File "/home/chase/.local/lib/python3.8/site-packages/pymysql/connections.py", line 1156, in read
    first_packet = self.connection._read_packet()
                   │    └ None
                   └ <pymysql.connections.MySQLResult object at 0x7f303845ae50>
  File "/home/chase/.local/lib/python3.8/site-packages/pymysql/connections.py", line 725, in _read_packet
    packet.raise_for_error()
    │      └ <function MysqlPacket.raise_for_error at 0x7f31f34ddee0>
    └ <pymysql.protocol.MysqlPacket object at 0x7f2f78795a60>
  File "/home/chase/.local/lib/python3.8/site-packages/pymysql/protocol.py", line 221, in raise_for_error
    err.raise_mysql_exception(self._data)
    │   │                     │    └ <member '_data' of 'MysqlPacket' objects>
    │   │                     └ <pymysql.protocol.MysqlPacket object at 0x7f2f78795a60>
    │   └ <function raise_mysql_exception at 0x7f31f358c670>
    └ <module 'pymysql.err' from '/home/chase/.local/lib/python3.8/site-packages/pymysql/err.py'>
  File "/home/chase/.local/lib/python3.8/site-packages/pymysql/err.py", line 143, in raise_mysql_exception
    raise errorclass(errno, errval)
          │          │      └ "Duplicate entry '180.201.163.246:6800' for key 'device.PRIMARY'"
          │          └ 1062
          └ <class 'pymysql.err.IntegrityError'>

sqlalchemy.exc.IntegrityError: (pymysql.err.IntegrityError) (1062, "Duplicate entry '180.201.163.246:6800' for key 'device.PRIMARY'")
[SQL: UPDATE device SET server_id=%(server_id)s, ip=%(ip)s, username=%(username)s, password=%(password)s, address=%(address)s, port=%(port)s, valid=%(valid)s WHERE device.ip = %(ip_1)s]
[parameters: {'server_id': '180.201.163.246:6800', 'ip': '180.201.163.246', 'username': 'chase', 'password': '58103377892104033471464980797414942917724398001702349792010862069256787082057652244083365296552347311875236337838952445843116750844188379665151674798 ... (10 characters truncated) ... 71722004818847229624222660913389176555226410822813253717554953536184133616352498836712313242601073138034298342340395367843238006970242267142480626361', 'address': '/home/users/CT/pycharmproject/spiders/', 'port': 6800, 'valid': 1, 'ip_1': '180.201.163.246'}]
(Background on this error at: https://sqlalche.me/e/14/gkpj)
2022-05-14 06:00:29.075 | ERROR    | base.db.mysql:update:390 - 【mysql更新数据出错】
Traceback (most recent call last):

  File "/home/chase/.local/lib/python3.8/site-packages/sqlalchemy/engine/base.py", line 1771, in _execute_context
    self.dialect.do_execute(
    │    │       └ <function DefaultDialect.do_execute at 0x7f31f38f75e0>
    │    └ <sqlalchemy.dialects.mysql.pymysql.MySQLDialect_pymysql object at 0x7f3103ffde20>
    └ <sqlalchemy.engine.base.Connection object at 0x7f2e06001b50>
  File "/home/chase/.local/lib/python3.8/site-packages/sqlalchemy/engine/default.py", line 717, in do_execute
    cursor.execute(statement, parameters)
    │      │       │          └ {'server_id': '180.201.163.246:6800', 'ip': '180.201.163.246', 'username': 'chase', 'password': '1995107895713799779508675402...
    │      │       └ 'UPDATE device SET server_id=%(server_id)s, ip=%(ip)s, username=%(username)s, password=%(password)s, address=%(address)s, por...
    │      └ <function Cursor.execute at 0x7f31f354cdc0>
    └ <pymysql.cursors.Cursor object at 0x7f3100250610>
  File "/home/chase/.local/lib/python3.8/site-packages/pymysql/cursors.py", line 148, in execute
    result = self._query(query)
             │    │      └ "UPDATE device SET server_id='180.201.163.246:6800', ip='180.201.163.246', username='chase', password='1995107895713799779508...
             │    └ <function Cursor._query at 0x7f31f34d7280>
             └ <pymysql.cursors.Cursor object at 0x7f3100250610>
  File "/home/chase/.local/lib/python3.8/site-packages/pymysql/cursors.py", line 310, in _query
    conn.query(q)
    │    │     └ "UPDATE device SET server_id='180.201.163.246:6800', ip='180.201.163.246', username='chase', password='1995107895713799779508...
    │    └ <function Connection.query at 0x7f31f34e5670>
    └ <pymysql.connections.Connection object at 0x7f30580c7610>
  File "/home/chase/.local/lib/python3.8/site-packages/pymysql/connections.py", line 548, in query
    self._affected_rows = self._read_query_result(unbuffered=unbuffered)
    │    │                │    │                             └ False
    │    │                │    └ <function Connection._read_query_result at 0x7f31f34e5ca0>
    │    │                └ <pymysql.connections.Connection object at 0x7f30580c7610>
    │    └ 1
    └ <pymysql.connections.Connection object at 0x7f30580c7610>
  File "/home/chase/.local/lib/python3.8/site-packages/pymysql/connections.py", line 775, in _read_query_result
    result.read()
    │      └ <function MySQLResult.read at 0x7f31f34e64c0>
    └ <pymysql.connections.MySQLResult object at 0x7f2f982e4970>
  File "/home/chase/.local/lib/python3.8/site-packages/pymysql/connections.py", line 1156, in read
    first_packet = self.connection._read_packet()
                   │    └ None
                   └ <pymysql.connections.MySQLResult object at 0x7f2f982e4970>
  File "/home/chase/.local/lib/python3.8/site-packages/pymysql/connections.py", line 725, in _read_packet
    packet.raise_for_error()
    │      └ <function MysqlPacket.raise_for_error at 0x7f31f34ddee0>
    └ <pymysql.protocol.MysqlPacket object at 0x7f30d840b520>
  File "/home/chase/.local/lib/python3.8/site-packages/pymysql/protocol.py", line 221, in raise_for_error
    err.raise_mysql_exception(self._data)
    │   │                     │    └ <member '_data' of 'MysqlPacket' objects>
    │   │                     └ <pymysql.protocol.MysqlPacket object at 0x7f30d840b520>
    │   └ <function raise_mysql_exception at 0x7f31f358c670>
    └ <module 'pymysql.err' from '/home/chase/.local/lib/python3.8/site-packages/pymysql/err.py'>
  File "/home/chase/.local/lib/python3.8/site-packages/pymysql/err.py", line 143, in raise_mysql_exception
    raise errorclass(errno, errval)
          │          │      └ "Duplicate entry '180.201.163.246:6800' for key 'device.PRIMARY'"
          │          └ 1062
          └ <class 'pymysql.err.IntegrityError'>

pymysql.err.IntegrityError: (1062, "Duplicate entry '180.201.163.246:6800' for key 'device.PRIMARY'")


The above exception was the direct cause of the following exception:


Traceback (most recent call last):

  File "/usr/lib/python3.8/threading.py", line 890, in _bootstrap
    self._bootstrap_inner()
    │    └ <function Thread._bootstrap_inner at 0x7f321bf29a60>
    └ <Thread(Thread-11928, started daemon 139836096288512)>
  File "/usr/lib/python3.8/threading.py", line 932, in _bootstrap_inner
    self.run()
    │    └ <function Thread.run at 0x7f321bf29790>
    └ <Thread(Thread-11928, started daemon 139836096288512)>
  File "/usr/lib/python3.8/threading.py", line 870, in run
    self._target(*self._args, **self._kwargs)
    │    │        │    │        │    └ {}
    │    │        │    │        └ <Thread(Thread-11928, started daemon 139836096288512)>
    │    │        │    └ ('ProjectManager.run_func_by_thread',)
    │    │        └ <Thread(Thread-11928, started daemon 139836096288512)>
    │    └ <bound method ProjectManager.get_request_from_keywords_hot of <monitor.projectManager.ProjectManager object at 0x7f31042e52e0>>
    └ <Thread(Thread-11928, started daemon 139836096288512)>

  File "/home/users/Scy/yuqing/spider/monitor/projectManager.py", line 799, in get_request_from_keywords_hot
    self.start_finished_spider_every_interval(project_names)
    │    │                                    └ ['default', 'test']
    │    └ <function ProjectManager.start_finished_spider_every_interval at 0x7f3104005280>
    └ <monitor.projectManager.ProjectManager object at 0x7f31042e52e0>

  File "/home/users/Scy/yuqing/spider/monitor/projectManager.py", line 784, in start_finished_spider_every_interval
    self[name].start_spider()
    │    └ 'default'
    └ <monitor.projectManager.ProjectManager object at 0x7f31042e52e0>

  File "/home/users/Scy/yuqing/spider/monitor/projectManager.py", line 366, in start_spider
    self.update_device_valid(device)
    │    │                   └ <monitor.deviceManager.DeviceC object at 0x7f3104029220>
    │    └ <function Project.update_device_valid at 0x7f3104003280>
    └ <monitor.projectManager.Project object at 0x7f3104029460>

  File "/home/users/Scy/yuqing/spider/monitor/projectManager.py", line 421, in update_device_valid
    self.database_manager.mysql.update(Device(**device.to_item()))
    │    │                │     │      │        │      └ <function DeviceC.to_item at 0x7f31f34ed310>
    │    │                │     │      │        └ <monitor.deviceManager.DeviceC object at 0x7f3104029220>
    │    │                │     │      └ <class 'base.db.mysql.Device'>
    │    │                │     └ <function Mysql.update at 0x7f31f35f4790>
    │    │                └ <base.db.mysql.Mysql object at 0x7f3103ffdfd0>
    │    └ <base.db.dbSlot.Slot object at 0x7f3103ffdf10>
    └ <monitor.projectManager.Project object at 0x7f3104029460>

> File "/home/users/Scy/yuqing/spider/base/db/mysql.py", line 375, in update
    row.update(new)
    │   │      └ {'server_id': '180.201.163.246:6800', 'ip': '180.201.163.246', 'username': 'chase', 'password': '1995107895713799779508675402...
    │   └ <function Query.update at 0x7f31f37333a0>
    └ <sqlalchemy.orm.query.Query object at 0x7f30982224c0>

  File "/home/chase/.local/lib/python3.8/site-packages/sqlalchemy/orm/query.py", line 3221, in update
    result = self.session.execute(
             │    │       └ <function Session.execute at 0x7f31f370faf0>
             │    └ <sqlalchemy.orm.session.Session object at 0x7f31f937e7c0>
             └ <sqlalchemy.orm.query.Query object at 0x7f30982224c0>
  File "/home/chase/.local/lib/python3.8/site-packages/sqlalchemy/orm/session.py", line 1689, in execute
    result = conn._execute_20(statement, params or {}, execution_options)
             │    │           │          │             └ immutabledict({'synchronize_session': 'evaluate', '_sa_orm_update_options': default_update_options(_matched_objects=[], _reso...
             │    │           │          └ immutabledict({})
             │    │           └ <sqlalchemy.sql.annotation.AnnotatedUpdate object at 0x7f2de9beee50>
             │    └ <function Connection._execute_20 at 0x7f31f39bc790>
             └ <sqlalchemy.engine.base.Connection object at 0x7f2e06001b50>
  File "/home/chase/.local/lib/python3.8/site-packages/sqlalchemy/engine/base.py", line 1583, in _execute_20
    return meth(self, args_10style, kwargs_10style, execution_options)
           │    │     │             │               └ immutabledict({'synchronize_session': 'evaluate', '_sa_orm_update_options': default_update_options(_matched_objects=[], _reso...
           │    │     │             └ immutabledict({})
           │    │     └ ({},)
           │    └ <sqlalchemy.engine.base.Connection object at 0x7f2e06001b50>
           └ <bound method ClauseElement._execute_on_connection of <sqlalchemy.sql.annotation.AnnotatedUpdate object at 0x7f2de9beee50>>
  File "/home/chase/.local/lib/python3.8/site-packages/sqlalchemy/sql/elements.py", line 323, in _execute_on_connection
    return connection._execute_clauseelement(
           │          └ <function Connection._execute_clauseelement at 0x7f31f39bc5e0>
           └ <sqlalchemy.engine.base.Connection object at 0x7f2e06001b50>
  File "/home/chase/.local/lib/python3.8/site-packages/sqlalchemy/engine/base.py", line 1452, in _execute_clauseelement
    ret = self._execute_context(
          │    └ <function Connection._execute_context at 0x7f31f39bc8b0>
          └ <sqlalchemy.engine.base.Connection object at 0x7f2e06001b50>
  File "/home/chase/.local/lib/python3.8/site-packages/sqlalchemy/engine/base.py", line 1814, in _execute_context
    self._handle_dbapi_exception(
    │    └ <function Connection._handle_dbapi_exception at 0x7f31f39bca60>
    └ <sqlalchemy.engine.base.Connection object at 0x7f2e06001b50>
  File "/home/chase/.local/lib/python3.8/site-packages/sqlalchemy/engine/base.py", line 1995, in _handle_dbapi_exception
    util.raise_(
    │    └ <function raise_ at 0x7f31f3d7ea60>
    └ <module 'sqlalchemy.util' from '/home/chase/.local/lib/python3.8/site-packages/sqlalchemy/util/__init__.py'>
  File "/home/chase/.local/lib/python3.8/site-packages/sqlalchemy/util/compat.py", line 207, in raise_
    raise exception
  File "/home/chase/.local/lib/python3.8/site-packages/sqlalchemy/engine/base.py", line 1771, in _execute_context
    self.dialect.do_execute(
    │    │       └ <function DefaultDialect.do_execute at 0x7f31f38f75e0>
    │    └ <sqlalchemy.dialects.mysql.pymysql.MySQLDialect_pymysql object at 0x7f3103ffde20>
    └ <sqlalchemy.engine.base.Connection object at 0x7f2e06001b50>
  File "/home/chase/.local/lib/python3.8/site-packages/sqlalchemy/engine/default.py", line 717, in do_execute
    cursor.execute(statement, parameters)
    │      │       │          └ {'server_id': '180.201.163.246:6800', 'ip': '180.201.163.246', 'username': 'chase', 'password': '1995107895713799779508675402...
    │      │       └ 'UPDATE device SET server_id=%(server_id)s, ip=%(ip)s, username=%(username)s, password=%(password)s, address=%(address)s, por...
    │      └ <function Cursor.execute at 0x7f31f354cdc0>
    └ <pymysql.cursors.Cursor object at 0x7f3100250610>
  File "/home/chase/.local/lib/python3.8/site-packages/pymysql/cursors.py", line 148, in execute
    result = self._query(query)
             │    │      └ "UPDATE device SET server_id='180.201.163.246:6800', ip='180.201.163.246', username='chase', password='1995107895713799779508...
             │    └ <function Cursor._query at 0x7f31f34d7280>
             └ <pymysql.cursors.Cursor object at 0x7f3100250610>
  File "/home/chase/.local/lib/python3.8/site-packages/pymysql/cursors.py", line 310, in _query
    conn.query(q)
    │    │     └ "UPDATE device SET server_id='180.201.163.246:6800', ip='180.201.163.246', username='chase', password='1995107895713799779508...
    │    └ <function Connection.query at 0x7f31f34e5670>
    └ <pymysql.connections.Connection object at 0x7f30580c7610>
  File "/home/chase/.local/lib/python3.8/site-packages/pymysql/connections.py", line 548, in query
    self._affected_rows = self._read_query_result(unbuffered=unbuffered)
    │    │                │    │                             └ False
    │    │                │    └ <function Connection._read_query_result at 0x7f31f34e5ca0>
    │    │                └ <pymysql.connections.Connection object at 0x7f30580c7610>
    │    └ 1
    └ <pymysql.connections.Connection object at 0x7f30580c7610>
  File "/home/chase/.local/lib/python3.8/site-packages/pymysql/connections.py", line 775, in _read_query_result
    result.read()
    │      └ <function MySQLResult.read at 0x7f31f34e64c0>
    └ <pymysql.connections.MySQLResult object at 0x7f2f982e4970>
  File "/home/chase/.local/lib/python3.8/site-packages/pymysql/connections.py", line 1156, in read
    first_packet = self.connection._read_packet()
                   │    └ None
                   └ <pymysql.connections.MySQLResult object at 0x7f2f982e4970>
  File "/home/chase/.local/lib/python3.8/site-packages/pymysql/connections.py", line 725, in _read_packet
    packet.raise_for_error()
    │      └ <function MysqlPacket.raise_for_error at 0x7f31f34ddee0>
    └ <pymysql.protocol.MysqlPacket object at 0x7f30d840b520>
  File "/home/chase/.local/lib/python3.8/site-packages/pymysql/protocol.py", line 221, in raise_for_error
    err.raise_mysql_exception(self._data)
    │   │                     │    └ <member '_data' of 'MysqlPacket' objects>
    │   │                     └ <pymysql.protocol.MysqlPacket object at 0x7f30d840b520>
    │   └ <function raise_mysql_exception at 0x7f31f358c670>
    └ <module 'pymysql.err' from '/home/chase/.local/lib/python3.8/site-packages/pymysql/err.py'>
  File "/home/chase/.local/lib/python3.8/site-packages/pymysql/err.py", line 143, in raise_mysql_exception
    raise errorclass(errno, errval)
          │          │      └ "Duplicate entry '180.201.163.246:6800' for key 'device.PRIMARY'"
          │          └ 1062
          └ <class 'pymysql.err.IntegrityError'>

sqlalchemy.exc.IntegrityError: (pymysql.err.IntegrityError) (1062, "Duplicate entry '180.201.163.246:6800' for key 'device.PRIMARY'")
[SQL: UPDATE device SET server_id=%(server_id)s, ip=%(ip)s, username=%(username)s, password=%(password)s, address=%(address)s, port=%(port)s, valid=%(valid)s WHERE device.ip = %(ip_1)s]
[parameters: {'server_id': '180.201.163.246:6800', 'ip': '180.201.163.246', 'username': 'chase', 'password': '19951078957137997795086754025481805336181357582689453711520626485159014053769168633764818563921433879672969247812272136213668896986258715448532000010 ... (10 characters truncated) ... 75990664812706626215860765188315779174947662067349432830994009331306767411709380604131776600094132619665189740910589792408874409407125283624341898973', 'address': '/home/users/CT/pycharmproject/spiders/', 'port': 6800, 'valid': 1, 'ip_1': '180.201.163.246'}]
(Background on this error at: https://sqlalche.me/e/14/gkpj)
2022-05-14 06:00:48.467 | ERROR    | base.db.mysql:update:390 - 【mysql更新数据出错】
Traceback (most recent call last):

  File "/home/chase/.local/lib/python3.8/site-packages/sqlalchemy/engine/base.py", line 1771, in _execute_context
    self.dialect.do_execute(
    │    │       └ <function DefaultDialect.do_execute at 0x7f31f38f75e0>
    │    └ <sqlalchemy.dialects.mysql.pymysql.MySQLDialect_pymysql object at 0x7f3103ffde20>
    └ <sqlalchemy.engine.base.Connection object at 0x7f2e12be98e0>
  File "/home/chase/.local/lib/python3.8/site-packages/sqlalchemy/engine/default.py", line 717, in do_execute
    cursor.execute(statement, parameters)
    │      │       │          └ {'server_id': '180.201.163.246:6800', 'ip': '180.201.163.246', 'username': 'chase', 'password': '4883865905660102393480753348...
    │      │       └ 'UPDATE device SET server_id=%(server_id)s, ip=%(ip)s, username=%(username)s, password=%(password)s, address=%(address)s, por...
    │      └ <function Cursor.execute at 0x7f31f354cdc0>
    └ <pymysql.cursors.Cursor object at 0x7f3098539e50>
  File "/home/chase/.local/lib/python3.8/site-packages/pymysql/cursors.py", line 148, in execute
    result = self._query(query)
             │    │      └ "UPDATE device SET server_id='180.201.163.246:6800', ip='180.201.163.246', username='chase', password='4883865905660102393480...
             │    └ <function Cursor._query at 0x7f31f34d7280>
             └ <pymysql.cursors.Cursor object at 0x7f3098539e50>
  File "/home/chase/.local/lib/python3.8/site-packages/pymysql/cursors.py", line 310, in _query
    conn.query(q)
    │    │     └ "UPDATE device SET server_id='180.201.163.246:6800', ip='180.201.163.246', username='chase', password='4883865905660102393480...
    │    └ <function Connection.query at 0x7f31f34e5670>
    └ <pymysql.connections.Connection object at 0x7f30d860b8b0>
  File "/home/chase/.local/lib/python3.8/site-packages/pymysql/connections.py", line 548, in query
    self._affected_rows = self._read_query_result(unbuffered=unbuffered)
    │    │                │    │                             └ False
    │    │                │    └ <function Connection._read_query_result at 0x7f31f34e5ca0>
    │    │                └ <pymysql.connections.Connection object at 0x7f30d860b8b0>
    │    └ 1
    └ <pymysql.connections.Connection object at 0x7f30d860b8b0>
  File "/home/chase/.local/lib/python3.8/site-packages/pymysql/connections.py", line 775, in _read_query_result
    result.read()
    │      └ <function MySQLResult.read at 0x7f31f34e64c0>
    └ <pymysql.connections.MySQLResult object at 0x7f2de9aee0d0>
  File "/home/chase/.local/lib/python3.8/site-packages/pymysql/connections.py", line 1156, in read
    first_packet = self.connection._read_packet()
                   │    └ None
                   └ <pymysql.connections.MySQLResult object at 0x7f2de9aee0d0>
  File "/home/chase/.local/lib/python3.8/site-packages/pymysql/connections.py", line 725, in _read_packet
    packet.raise_for_error()
    │      └ <function MysqlPacket.raise_for_error at 0x7f31f34ddee0>
    └ <pymysql.protocol.MysqlPacket object at 0x7f2f78789310>
  File "/home/chase/.local/lib/python3.8/site-packages/pymysql/protocol.py", line 221, in raise_for_error
    err.raise_mysql_exception(self._data)
    │   │                     │    └ <member '_data' of 'MysqlPacket' objects>
    │   │                     └ <pymysql.protocol.MysqlPacket object at 0x7f2f78789310>
    │   └ <function raise_mysql_exception at 0x7f31f358c670>
    └ <module 'pymysql.err' from '/home/chase/.local/lib/python3.8/site-packages/pymysql/err.py'>
  File "/home/chase/.local/lib/python3.8/site-packages/pymysql/err.py", line 143, in raise_mysql_exception
    raise errorclass(errno, errval)
          │          │      └ "Duplicate entry '180.201.163.246:6800' for key 'device.PRIMARY'"
          │          └ 1062
          └ <class 'pymysql.err.IntegrityError'>

pymysql.err.IntegrityError: (1062, "Duplicate entry '180.201.163.246:6800' for key 'device.PRIMARY'")


The above exception was the direct cause of the following exception:


Traceback (most recent call last):

  File "/usr/lib/python3.8/threading.py", line 890, in _bootstrap
    self._bootstrap_inner()
    │    └ <function Thread._bootstrap_inner at 0x7f321bf29a60>
    └ <Thread(Thread-11933, started daemon 139847784179456)>
  File "/usr/lib/python3.8/threading.py", line 932, in _bootstrap_inner
    self.run()
    │    └ <function Thread.run at 0x7f321bf29790>
    └ <Thread(Thread-11933, started daemon 139847784179456)>
  File "/usr/lib/python3.8/threading.py", line 870, in run
    self._target(*self._args, **self._kwargs)
    │    │        │    │        │    └ {}
    │    │        │    │        └ <Thread(Thread-11933, started daemon 139847784179456)>
    │    │        │    └ ('ProjectManager.run_func_by_thread',)
    │    │        └ <Thread(Thread-11933, started daemon 139847784179456)>
    │    └ <bound method ProjectManager.get_request_from_keywords_hot of <monitor.projectManager.ProjectManager object at 0x7f31042e52e0>>
    └ <Thread(Thread-11933, started daemon 139847784179456)>

  File "/home/users/Scy/yuqing/spider/monitor/projectManager.py", line 799, in get_request_from_keywords_hot
    self.start_finished_spider_every_interval(project_names)
    │    │                                    └ ['default', 'test']
    │    └ <function ProjectManager.start_finished_spider_every_interval at 0x7f3104005280>
    └ <monitor.projectManager.ProjectManager object at 0x7f31042e52e0>

  File "/home/users/Scy/yuqing/spider/monitor/projectManager.py", line 784, in start_finished_spider_every_interval
    self[name].start_spider()
    │    └ 'default'
    └ <monitor.projectManager.ProjectManager object at 0x7f31042e52e0>

  File "/home/users/Scy/yuqing/spider/monitor/projectManager.py", line 366, in start_spider
    self.update_device_valid(device)
    │    │                   └ <monitor.deviceManager.DeviceC object at 0x7f3104029220>
    │    └ <function Project.update_device_valid at 0x7f3104003280>
    └ <monitor.projectManager.Project object at 0x7f3104029460>

  File "/home/users/Scy/yuqing/spider/monitor/projectManager.py", line 421, in update_device_valid
    self.database_manager.mysql.update(Device(**device.to_item()))
    │    │                │     │      │        │      └ <function DeviceC.to_item at 0x7f31f34ed310>
    │    │                │     │      │        └ <monitor.deviceManager.DeviceC object at 0x7f3104029220>
    │    │                │     │      └ <class 'base.db.mysql.Device'>
    │    │                │     └ <function Mysql.update at 0x7f31f35f4790>
    │    │                └ <base.db.mysql.Mysql object at 0x7f3103ffdfd0>
    │    └ <base.db.dbSlot.Slot object at 0x7f3103ffdf10>
    └ <monitor.projectManager.Project object at 0x7f3104029460>

> File "/home/users/Scy/yuqing/spider/base/db/mysql.py", line 375, in update
    row.update(new)
    │   │      └ {'server_id': '180.201.163.246:6800', 'ip': '180.201.163.246', 'username': 'chase', 'password': '4883865905660102393480753348...
    │   └ <function Query.update at 0x7f31f37333a0>
    └ <sqlalchemy.orm.query.Query object at 0x7f2de9cb8250>

  File "/home/chase/.local/lib/python3.8/site-packages/sqlalchemy/orm/query.py", line 3221, in update
    result = self.session.execute(
             │    │       └ <function Session.execute at 0x7f31f370faf0>
             │    └ <sqlalchemy.orm.session.Session object at 0x7f31021b62b0>
             └ <sqlalchemy.orm.query.Query object at 0x7f2de9cb8250>
  File "/home/chase/.local/lib/python3.8/site-packages/sqlalchemy/orm/session.py", line 1689, in execute
    result = conn._execute_20(statement, params or {}, execution_options)
             │    │           │          │             └ immutabledict({'synchronize_session': 'evaluate', '_sa_orm_update_options': default_update_options(_matched_objects=[], _reso...
             │    │           │          └ immutabledict({})
             │    │           └ <sqlalchemy.sql.annotation.AnnotatedUpdate object at 0x7f2e05fe8c10>
             │    └ <function Connection._execute_20 at 0x7f31f39bc790>
             └ <sqlalchemy.engine.base.Connection object at 0x7f2e12be98e0>
  File "/home/chase/.local/lib/python3.8/site-packages/sqlalchemy/engine/base.py", line 1583, in _execute_20
    return meth(self, args_10style, kwargs_10style, execution_options)
           │    │     │             │               └ immutabledict({'synchronize_session': 'evaluate', '_sa_orm_update_options': default_update_options(_matched_objects=[], _reso...
           │    │     │             └ immutabledict({})
           │    │     └ ({},)
           │    └ <sqlalchemy.engine.base.Connection object at 0x7f2e12be98e0>
           └ <bound method ClauseElement._execute_on_connection of <sqlalchemy.sql.annotation.AnnotatedUpdate object at 0x7f2e05fe8c10>>
  File "/home/chase/.local/lib/python3.8/site-packages/sqlalchemy/sql/elements.py", line 323, in _execute_on_connection
    return connection._execute_clauseelement(
           │          └ <function Connection._execute_clauseelement at 0x7f31f39bc5e0>
           └ <sqlalchemy.engine.base.Connection object at 0x7f2e12be98e0>
  File "/home/chase/.local/lib/python3.8/site-packages/sqlalchemy/engine/base.py", line 1452, in _execute_clauseelement
    ret = self._execute_context(
          │    └ <function Connection._execute_context at 0x7f31f39bc8b0>
          └ <sqlalchemy.engine.base.Connection object at 0x7f2e12be98e0>
  File "/home/chase/.local/lib/python3.8/site-packages/sqlalchemy/engine/base.py", line 1814, in _execute_context
    self._handle_dbapi_exception(
    │    └ <function Connection._handle_dbapi_exception at 0x7f31f39bca60>
    └ <sqlalchemy.engine.base.Connection object at 0x7f2e12be98e0>
  File "/home/chase/.local/lib/python3.8/site-packages/sqlalchemy/engine/base.py", line 1995, in _handle_dbapi_exception
    util.raise_(
    │    └ <function raise_ at 0x7f31f3d7ea60>
    └ <module 'sqlalchemy.util' from '/home/chase/.local/lib/python3.8/site-packages/sqlalchemy/util/__init__.py'>
  File "/home/chase/.local/lib/python3.8/site-packages/sqlalchemy/util/compat.py", line 207, in raise_
    raise exception
  File "/home/chase/.local/lib/python3.8/site-packages/sqlalchemy/engine/base.py", line 1771, in _execute_context
    self.dialect.do_execute(
    │    │       └ <function DefaultDialect.do_execute at 0x7f31f38f75e0>
    │    └ <sqlalchemy.dialects.mysql.pymysql.MySQLDialect_pymysql object at 0x7f3103ffde20>
    └ <sqlalchemy.engine.base.Connection object at 0x7f2e12be98e0>
  File "/home/chase/.local/lib/python3.8/site-packages/sqlalchemy/engine/default.py", line 717, in do_execute
    cursor.execute(statement, parameters)
    │      │       │          └ {'server_id': '180.201.163.246:6800', 'ip': '180.201.163.246', 'username': 'chase', 'password': '4883865905660102393480753348...
    │      │       └ 'UPDATE device SET server_id=%(server_id)s, ip=%(ip)s, username=%(username)s, password=%(password)s, address=%(address)s, por...
    │      └ <function Cursor.execute at 0x7f31f354cdc0>
    └ <pymysql.cursors.Cursor object at 0x7f3098539e50>
  File "/home/chase/.local/lib/python3.8/site-packages/pymysql/cursors.py", line 148, in execute
    result = self._query(query)
             │    │      └ "UPDATE device SET server_id='180.201.163.246:6800', ip='180.201.163.246', username='chase', password='4883865905660102393480...
             │    └ <function Cursor._query at 0x7f31f34d7280>
             └ <pymysql.cursors.Cursor object at 0x7f3098539e50>
  File "/home/chase/.local/lib/python3.8/site-packages/pymysql/cursors.py", line 310, in _query
    conn.query(q)
    │    │     └ "UPDATE device SET server_id='180.201.163.246:6800', ip='180.201.163.246', username='chase', password='4883865905660102393480...
    │    └ <function Connection.query at 0x7f31f34e5670>
    └ <pymysql.connections.Connection object at 0x7f30d860b8b0>
  File "/home/chase/.local/lib/python3.8/site-packages/pymysql/connections.py", line 548, in query
    self._affected_rows = self._read_query_result(unbuffered=unbuffered)
    │    │                │    │                             └ False
    │    │                │    └ <function Connection._read_query_result at 0x7f31f34e5ca0>
    │    │                └ <pymysql.connections.Connection object at 0x7f30d860b8b0>
    │    └ 1
    └ <pymysql.connections.Connection object at 0x7f30d860b8b0>
  File "/home/chase/.local/lib/python3.8/site-packages/pymysql/connections.py", line 775, in _read_query_result
    result.read()
    │      └ <function MySQLResult.read at 0x7f31f34e64c0>
    └ <pymysql.connections.MySQLResult object at 0x7f2de9aee0d0>
  File "/home/chase/.local/lib/python3.8/site-packages/pymysql/connections.py", line 1156, in read
    first_packet = self.connection._read_packet()
                   │    └ None
                   └ <pymysql.connections.MySQLResult object at 0x7f2de9aee0d0>
  File "/home/chase/.local/lib/python3.8/site-packages/pymysql/connections.py", line 725, in _read_packet
    packet.raise_for_error()
    │      └ <function MysqlPacket.raise_for_error at 0x7f31f34ddee0>
    └ <pymysql.protocol.MysqlPacket object at 0x7f2f78789310>
  File "/home/chase/.local/lib/python3.8/site-packages/pymysql/protocol.py", line 221, in raise_for_error
    err.raise_mysql_exception(self._data)
    │   │                     │    └ <member '_data' of 'MysqlPacket' objects>
    │   │                     └ <pymysql.protocol.MysqlPacket object at 0x7f2f78789310>
    │   └ <function raise_mysql_exception at 0x7f31f358c670>
    └ <module 'pymysql.err' from '/home/chase/.local/lib/python3.8/site-packages/pymysql/err.py'>
  File "/home/chase/.local/lib/python3.8/site-packages/pymysql/err.py", line 143, in raise_mysql_exception
    raise errorclass(errno, errval)
          │          │      └ "Duplicate entry '180.201.163.246:6800' for key 'device.PRIMARY'"
          │          └ 1062
          └ <class 'pymysql.err.IntegrityError'>

sqlalchemy.exc.IntegrityError: (pymysql.err.IntegrityError) (1062, "Duplicate entry '180.201.163.246:6800' for key 'device.PRIMARY'")
[SQL: UPDATE device SET server_id=%(server_id)s, ip=%(ip)s, username=%(username)s, password=%(password)s, address=%(address)s, port=%(port)s, valid=%(valid)s WHERE device.ip = %(ip_1)s]
[parameters: {'server_id': '180.201.163.246:6800', 'ip': '180.201.163.246', 'username': 'chase', 'password': '48838659056601023934807533484959310065772167437755579520743688901184853499081735096339226210135089807657347629012806478324172065200446829631338488103 ... (9 characters truncated) ... 61611620034931706068006596030578541082238028613134430275461222443957270791121072442360370660234673227443985396168241162204738562076753303861514449723', 'address': '/home/users/CT/pycharmproject/spiders/', 'port': 6800, 'valid': 1, 'ip_1': '180.201.163.246'}]
(Background on this error at: https://sqlalche.me/e/14/gkpj)
2022-05-14 06:01:05.631 | ERROR    | base.db.mysql:update:390 - 【mysql更新数据出错】
Traceback (most recent call last):

  File "/home/chase/.local/lib/python3.8/site-packages/sqlalchemy/engine/base.py", line 1771, in _execute_context
    self.dialect.do_execute(
    │    │       └ <function DefaultDialect.do_execute at 0x7f31f38f75e0>
    │    └ <sqlalchemy.dialects.mysql.pymysql.MySQLDialect_pymysql object at 0x7f3103ffde20>
    └ <sqlalchemy.engine.base.Connection object at 0x7f2e06037640>
  File "/home/chase/.local/lib/python3.8/site-packages/sqlalchemy/engine/default.py", line 717, in do_execute
    cursor.execute(statement, parameters)
    │      │       │          └ {'server_id': '180.201.163.246:6800', 'ip': '180.201.163.246', 'username': 'chase', 'password': '8174132255904869488037502016...
    │      │       └ 'UPDATE device SET server_id=%(server_id)s, ip=%(ip)s, username=%(username)s, password=%(password)s, address=%(address)s, por...
    │      └ <function Cursor.execute at 0x7f31f354cdc0>
    └ <pymysql.cursors.Cursor object at 0x7f2de9d15f10>
  File "/home/chase/.local/lib/python3.8/site-packages/pymysql/cursors.py", line 148, in execute
    result = self._query(query)
             │    │      └ "UPDATE device SET server_id='180.201.163.246:6800', ip='180.201.163.246', username='chase', password='8174132255904869488037...
             │    └ <function Cursor._query at 0x7f31f34d7280>
             └ <pymysql.cursors.Cursor object at 0x7f2de9d15f10>
  File "/home/chase/.local/lib/python3.8/site-packages/pymysql/cursors.py", line 310, in _query
    conn.query(q)
    │    │     └ "UPDATE device SET server_id='180.201.163.246:6800', ip='180.201.163.246', username='chase', password='8174132255904869488037...
    │    └ <function Connection.query at 0x7f31f34e5670>
    └ <pymysql.connections.Connection object at 0x7f2ff86a4190>
  File "/home/chase/.local/lib/python3.8/site-packages/pymysql/connections.py", line 548, in query
    self._affected_rows = self._read_query_result(unbuffered=unbuffered)
    │    │                │    │                             └ False
    │    │                │    └ <function Connection._read_query_result at 0x7f31f34e5ca0>
    │    │                └ <pymysql.connections.Connection object at 0x7f2ff86a4190>
    │    └ 1
    └ <pymysql.connections.Connection object at 0x7f2ff86a4190>
  File "/home/chase/.local/lib/python3.8/site-packages/pymysql/connections.py", line 775, in _read_query_result
    result.read()
    │      └ <function MySQLResult.read at 0x7f31f34e64c0>
    └ <pymysql.connections.MySQLResult object at 0x7f3018398250>
  File "/home/chase/.local/lib/python3.8/site-packages/pymysql/connections.py", line 1156, in read
    first_packet = self.connection._read_packet()
                   │    └ None
                   └ <pymysql.connections.MySQLResult object at 0x7f3018398250>
  File "/home/chase/.local/lib/python3.8/site-packages/pymysql/connections.py", line 725, in _read_packet
    packet.raise_for_error()
    │      └ <function MysqlPacket.raise_for_error at 0x7f31f34ddee0>
    └ <pymysql.protocol.MysqlPacket object at 0x7f3018092c70>
  File "/home/chase/.local/lib/python3.8/site-packages/pymysql/protocol.py", line 221, in raise_for_error
    err.raise_mysql_exception(self._data)
    │   │                     │    └ <member '_data' of 'MysqlPacket' objects>
    │   │                     └ <pymysql.protocol.MysqlPacket object at 0x7f3018092c70>
    │   └ <function raise_mysql_exception at 0x7f31f358c670>
    └ <module 'pymysql.err' from '/home/chase/.local/lib/python3.8/site-packages/pymysql/err.py'>
  File "/home/chase/.local/lib/python3.8/site-packages/pymysql/err.py", line 143, in raise_mysql_exception
    raise errorclass(errno, errval)
          │          │      └ "Duplicate entry '180.201.163.246:6800' for key 'device.PRIMARY'"
          │          └ 1062
          └ <class 'pymysql.err.IntegrityError'>

pymysql.err.IntegrityError: (1062, "Duplicate entry '180.201.163.246:6800' for key 'device.PRIMARY'")


The above exception was the direct cause of the following exception:


Traceback (most recent call last):

  File "/usr/lib/python3.8/threading.py", line 890, in _bootstrap
    self._bootstrap_inner()
    │    └ <function Thread._bootstrap_inner at 0x7f321bf29a60>
    └ <Thread(Thread-11937, started daemon 139839604438784)>
  File "/usr/lib/python3.8/threading.py", line 932, in _bootstrap_inner
    self.run()
    │    └ <function Thread.run at 0x7f321bf29790>
    └ <Thread(Thread-11937, started daemon 139839604438784)>
  File "/usr/lib/python3.8/threading.py", line 870, in run
    self._target(*self._args, **self._kwargs)
    │    │        │    │        │    └ {}
    │    │        │    │        └ <Thread(Thread-11937, started daemon 139839604438784)>
    │    │        │    └ ('ProjectManager.run_func_by_thread',)
    │    │        └ <Thread(Thread-11937, started daemon 139839604438784)>
    │    └ <bound method ProjectManager.get_request_from_keywords_hot of <monitor.projectManager.ProjectManager object at 0x7f31042e52e0>>
    └ <Thread(Thread-11937, started daemon 139839604438784)>

  File "/home/users/Scy/yuqing/spider/monitor/projectManager.py", line 799, in get_request_from_keywords_hot
    self.start_finished_spider_every_interval(project_names)
    │    │                                    └ ['default', 'test']
    │    └ <function ProjectManager.start_finished_spider_every_interval at 0x7f3104005280>
    └ <monitor.projectManager.ProjectManager object at 0x7f31042e52e0>

  File "/home/users/Scy/yuqing/spider/monitor/projectManager.py", line 784, in start_finished_spider_every_interval
    self[name].start_spider()
    │    └ 'default'
    └ <monitor.projectManager.ProjectManager object at 0x7f31042e52e0>

  File "/home/users/Scy/yuqing/spider/monitor/projectManager.py", line 366, in start_spider
    self.update_device_valid(device)
    │    │                   └ <monitor.deviceManager.DeviceC object at 0x7f3104029220>
    │    └ <function Project.update_device_valid at 0x7f3104003280>
    └ <monitor.projectManager.Project object at 0x7f3104029460>

  File "/home/users/Scy/yuqing/spider/monitor/projectManager.py", line 421, in update_device_valid
    self.database_manager.mysql.update(Device(**device.to_item()))
    │    │                │     │      │        │      └ <function DeviceC.to_item at 0x7f31f34ed310>
    │    │                │     │      │        └ <monitor.deviceManager.DeviceC object at 0x7f3104029220>
    │    │                │     │      └ <class 'base.db.mysql.Device'>
    │    │                │     └ <function Mysql.update at 0x7f31f35f4790>
    │    │                └ <base.db.mysql.Mysql object at 0x7f3103ffdfd0>
    │    └ <base.db.dbSlot.Slot object at 0x7f3103ffdf10>
    └ <monitor.projectManager.Project object at 0x7f3104029460>

> File "/home/users/Scy/yuqing/spider/base/db/mysql.py", line 375, in update
    row.update(new)
    │   │      └ {'server_id': '180.201.163.246:6800', 'ip': '180.201.163.246', 'username': 'chase', 'password': '8174132255904869488037502016...
    │   └ <function Query.update at 0x7f31f37333a0>
    └ <sqlalchemy.orm.query.Query object at 0x7f2f982ce310>

  File "/home/chase/.local/lib/python3.8/site-packages/sqlalchemy/orm/query.py", line 3221, in update
    result = self.session.execute(
             │    │       └ <function Session.execute at 0x7f31f370faf0>
             │    └ <sqlalchemy.orm.session.Session object at 0x7f2de9bd1fd0>
             └ <sqlalchemy.orm.query.Query object at 0x7f2f982ce310>
  File "/home/chase/.local/lib/python3.8/site-packages/sqlalchemy/orm/session.py", line 1689, in execute
    result = conn._execute_20(statement, params or {}, execution_options)
             │    │           │          │             └ immutabledict({'synchronize_session': 'evaluate', '_sa_orm_update_options': default_update_options(_matched_objects=[], _reso...
             │    │           │          └ immutabledict({})
             │    │           └ <sqlalchemy.sql.annotation.AnnotatedUpdate object at 0x7f301823b910>
             │    └ <function Connection._execute_20 at 0x7f31f39bc790>
             └ <sqlalchemy.engine.base.Connection object at 0x7f2e06037640>
  File "/home/chase/.local/lib/python3.8/site-packages/sqlalchemy/engine/base.py", line 1583, in _execute_20
    return meth(self, args_10style, kwargs_10style, execution_options)
           │    │     │             │               └ immutabledict({'synchronize_session': 'evaluate', '_sa_orm_update_options': default_update_options(_matched_objects=[], _reso...
           │    │     │             └ immutabledict({})
           │    │     └ ({},)
           │    └ <sqlalchemy.engine.base.Connection object at 0x7f2e06037640>
           └ <bound method ClauseElement._execute_on_connection of <sqlalchemy.sql.annotation.AnnotatedUpdate object at 0x7f301823b910>>
  File "/home/chase/.local/lib/python3.8/site-packages/sqlalchemy/sql/elements.py", line 323, in _execute_on_connection
    return connection._execute_clauseelement(
           │          └ <function Connection._execute_clauseelement at 0x7f31f39bc5e0>
           └ <sqlalchemy.engine.base.Connection object at 0x7f2e06037640>
  File "/home/chase/.local/lib/python3.8/site-packages/sqlalchemy/engine/base.py", line 1452, in _execute_clauseelement
    ret = self._execute_context(
          │    └ <function Connection._execute_context at 0x7f31f39bc8b0>
          └ <sqlalchemy.engine.base.Connection object at 0x7f2e06037640>
  File "/home/chase/.local/lib/python3.8/site-packages/sqlalchemy/engine/base.py", line 1814, in _execute_context
    self._handle_dbapi_exception(
    │    └ <function Connection._handle_dbapi_exception at 0x7f31f39bca60>
    └ <sqlalchemy.engine.base.Connection object at 0x7f2e06037640>
  File "/home/chase/.local/lib/python3.8/site-packages/sqlalchemy/engine/base.py", line 1995, in _handle_dbapi_exception
    util.raise_(
    │    └ <function raise_ at 0x7f31f3d7ea60>
    └ <module 'sqlalchemy.util' from '/home/chase/.local/lib/python3.8/site-packages/sqlalchemy/util/__init__.py'>
  File "/home/chase/.local/lib/python3.8/site-packages/sqlalchemy/util/compat.py", line 207, in raise_
    raise exception
  File "/home/chase/.local/lib/python3.8/site-packages/sqlalchemy/engine/base.py", line 1771, in _execute_context
    self.dialect.do_execute(
    │    │       └ <function DefaultDialect.do_execute at 0x7f31f38f75e0>
    │    └ <sqlalchemy.dialects.mysql.pymysql.MySQLDialect_pymysql object at 0x7f3103ffde20>
    └ <sqlalchemy.engine.base.Connection object at 0x7f2e06037640>
  File "/home/chase/.local/lib/python3.8/site-packages/sqlalchemy/engine/default.py", line 717, in do_execute
    cursor.execute(statement, parameters)
    │      │       │          └ {'server_id': '180.201.163.246:6800', 'ip': '180.201.163.246', 'username': 'chase', 'password': '8174132255904869488037502016...
    │      │       └ 'UPDATE device SET server_id=%(server_id)s, ip=%(ip)s, username=%(username)s, password=%(password)s, address=%(address)s, por...
    │      └ <function Cursor.execute at 0x7f31f354cdc0>
    └ <pymysql.cursors.Cursor object at 0x7f2de9d15f10>
  File "/home/chase/.local/lib/python3.8/site-packages/pymysql/cursors.py", line 148, in execute
    result = self._query(query)
             │    │      └ "UPDATE device SET server_id='180.201.163.246:6800', ip='180.201.163.246', username='chase', password='8174132255904869488037...
             │    └ <function Cursor._query at 0x7f31f34d7280>
             └ <pymysql.cursors.Cursor object at 0x7f2de9d15f10>
  File "/home/chase/.local/lib/python3.8/site-packages/pymysql/cursors.py", line 310, in _query
    conn.query(q)
    │    │     └ "UPDATE device SET server_id='180.201.163.246:6800', ip='180.201.163.246', username='chase', password='8174132255904869488037...
    │    └ <function Connection.query at 0x7f31f34e5670>
    └ <pymysql.connections.Connection object at 0x7f2ff86a4190>
  File "/home/chase/.local/lib/python3.8/site-packages/pymysql/connections.py", line 548, in query
    self._affected_rows = self._read_query_result(unbuffered=unbuffered)
    │    │                │    │                             └ False
    │    │                │    └ <function Connection._read_query_result at 0x7f31f34e5ca0>
    │    │                └ <pymysql.connections.Connection object at 0x7f2ff86a4190>
    │    └ 1
    └ <pymysql.connections.Connection object at 0x7f2ff86a4190>
  File "/home/chase/.local/lib/python3.8/site-packages/pymysql/connections.py", line 775, in _read_query_result
    result.read()
    │      └ <function MySQLResult.read at 0x7f31f34e64c0>
    └ <pymysql.connections.MySQLResult object at 0x7f3018398250>
  File "/home/chase/.local/lib/python3.8/site-packages/pymysql/connections.py", line 1156, in read
    first_packet = self.connection._read_packet()
                   │    └ None
                   └ <pymysql.connections.MySQLResult object at 0x7f3018398250>
  File "/home/chase/.local/lib/python3.8/site-packages/pymysql/connections.py", line 725, in _read_packet
    packet.raise_for_error()
    │      └ <function MysqlPacket.raise_for_error at 0x7f31f34ddee0>
    └ <pymysql.protocol.MysqlPacket object at 0x7f3018092c70>
  File "/home/chase/.local/lib/python3.8/site-packages/pymysql/protocol.py", line 221, in raise_for_error
    err.raise_mysql_exception(self._data)
    │   │                     │    └ <member '_data' of 'MysqlPacket' objects>
    │   │                     └ <pymysql.protocol.MysqlPacket object at 0x7f3018092c70>
    │   └ <function raise_mysql_exception at 0x7f31f358c670>
    └ <module 'pymysql.err' from '/home/chase/.local/lib/python3.8/site-packages/pymysql/err.py'>
  File "/home/chase/.local/lib/python3.8/site-packages/pymysql/err.py", line 143, in raise_mysql_exception
    raise errorclass(errno, errval)
          │          │      └ "Duplicate entry '180.201.163.246:6800' for key 'device.PRIMARY'"
          │          └ 1062
          └ <class 'pymysql.err.IntegrityError'>

sqlalchemy.exc.IntegrityError: (pymysql.err.IntegrityError) (1062, "Duplicate entry '180.201.163.246:6800' for key 'device.PRIMARY'")
[SQL: UPDATE device SET server_id=%(server_id)s, ip=%(ip)s, username=%(username)s, password=%(password)s, address=%(address)s, port=%(port)s, valid=%(valid)s WHERE device.ip = %(ip_1)s]
[parameters: {'server_id': '180.201.163.246:6800', 'ip': '180.201.163.246', 'username': 'chase', 'password': '81741322559048694880375020166144898337322583952254019738832999976422560056172035377819781888090025048148983430301749419714098693692653953203230512777 ... (10 characters truncated) ... 10171842809883285582306636382634451966434700198709127952215237396268919267907109617395882595918501095546542725313878864351201889502806171451849265129', 'address': '/home/users/CT/pycharmproject/spiders/', 'port': 6800, 'valid': 1, 'ip_1': '180.201.163.246'}]
(Background on this error at: https://sqlalche.me/e/14/gkpj)
2022-05-14 06:01:23.111 | ERROR    | base.db.mysql:update:390 - 【mysql更新数据出错】
Traceback (most recent call last):

  File "/home/chase/.local/lib/python3.8/site-packages/sqlalchemy/engine/base.py", line 1771, in _execute_context
    self.dialect.do_execute(
    │    │       └ <function DefaultDialect.do_execute at 0x7f31f38f75e0>
    │    └ <sqlalchemy.dialects.mysql.pymysql.MySQLDialect_pymysql object at 0x7f3103ffde20>
    └ <sqlalchemy.engine.base.Connection object at 0x7f2f78634c10>
  File "/home/chase/.local/lib/python3.8/site-packages/sqlalchemy/engine/default.py", line 717, in do_execute
    cursor.execute(statement, parameters)
    │      │       │          └ {'server_id': '180.201.163.246:6800', 'ip': '180.201.163.246', 'username': 'chase', 'password': '2673089041257655133154878844...
    │      │       └ 'UPDATE device SET server_id=%(server_id)s, ip=%(ip)s, username=%(username)s, password=%(password)s, address=%(address)s, por...
    │      └ <function Cursor.execute at 0x7f31f354cdc0>
    └ <pymysql.cursors.Cursor object at 0x7f2f982e4820>
  File "/home/chase/.local/lib/python3.8/site-packages/pymysql/cursors.py", line 148, in execute
    result = self._query(query)
             │    │      └ "UPDATE device SET server_id='180.201.163.246:6800', ip='180.201.163.246', username='chase', password='2673089041257655133154...
             │    └ <function Cursor._query at 0x7f31f34d7280>
             └ <pymysql.cursors.Cursor object at 0x7f2f982e4820>
  File "/home/chase/.local/lib/python3.8/site-packages/pymysql/cursors.py", line 310, in _query
    conn.query(q)
    │    │     └ "UPDATE device SET server_id='180.201.163.246:6800', ip='180.201.163.246', username='chase', password='2673089041257655133154...
    │    └ <function Connection.query at 0x7f31f34e5670>
    └ <pymysql.connections.Connection object at 0x7f2fb81e1cd0>
  File "/home/chase/.local/lib/python3.8/site-packages/pymysql/connections.py", line 548, in query
    self._affected_rows = self._read_query_result(unbuffered=unbuffered)
    │    │                │    │                             └ False
    │    │                │    └ <function Connection._read_query_result at 0x7f31f34e5ca0>
    │    │                └ <pymysql.connections.Connection object at 0x7f2fb81e1cd0>
    │    └ 1
    └ <pymysql.connections.Connection object at 0x7f2fb81e1cd0>
  File "/home/chase/.local/lib/python3.8/site-packages/pymysql/connections.py", line 775, in _read_query_result
    result.read()
    │      └ <function MySQLResult.read at 0x7f31f34e64c0>
    └ <pymysql.connections.MySQLResult object at 0x7f2e11b93d00>
  File "/home/chase/.local/lib/python3.8/site-packages/pymysql/connections.py", line 1156, in read
    first_packet = self.connection._read_packet()
                   │    └ None
                   └ <pymysql.connections.MySQLResult object at 0x7f2e11b93d00>
  File "/home/chase/.local/lib/python3.8/site-packages/pymysql/connections.py", line 725, in _read_packet
    packet.raise_for_error()
    │      └ <function MysqlPacket.raise_for_error at 0x7f31f34ddee0>
    └ <pymysql.protocol.MysqlPacket object at 0x7f2de994c280>
  File "/home/chase/.local/lib/python3.8/site-packages/pymysql/protocol.py", line 221, in raise_for_error
    err.raise_mysql_exception(self._data)
    │   │                     │    └ <member '_data' of 'MysqlPacket' objects>
    │   │                     └ <pymysql.protocol.MysqlPacket object at 0x7f2de994c280>
    │   └ <function raise_mysql_exception at 0x7f31f358c670>
    └ <module 'pymysql.err' from '/home/chase/.local/lib/python3.8/site-packages/pymysql/err.py'>
  File "/home/chase/.local/lib/python3.8/site-packages/pymysql/err.py", line 143, in raise_mysql_exception
    raise errorclass(errno, errval)
          │          │      └ "Duplicate entry '180.201.163.246:6800' for key 'device.PRIMARY'"
          │          └ 1062
          └ <class 'pymysql.err.IntegrityError'>

pymysql.err.IntegrityError: (1062, "Duplicate entry '180.201.163.246:6800' for key 'device.PRIMARY'")


The above exception was the direct cause of the following exception:


Traceback (most recent call last):

  File "/usr/lib/python3.8/threading.py", line 890, in _bootstrap
    self._bootstrap_inner()
    │    └ <function Thread._bootstrap_inner at 0x7f321bf29a60>
    └ <Thread(Thread-11941, started daemon 139847775786752)>
  File "/usr/lib/python3.8/threading.py", line 932, in _bootstrap_inner
    self.run()
    │    └ <function Thread.run at 0x7f321bf29790>
    └ <Thread(Thread-11941, started daemon 139847775786752)>
  File "/usr/lib/python3.8/threading.py", line 870, in run
    self._target(*self._args, **self._kwargs)
    │    │        │    │        │    └ {}
    │    │        │    │        └ <Thread(Thread-11941, started daemon 139847775786752)>
    │    │        │    └ ('ProjectManager.run_func_by_thread',)
    │    │        └ <Thread(Thread-11941, started daemon 139847775786752)>
    │    └ <bound method ProjectManager.get_request_from_keywords_hot of <monitor.projectManager.ProjectManager object at 0x7f31042e52e0>>
    └ <Thread(Thread-11941, started daemon 139847775786752)>

  File "/home/users/Scy/yuqing/spider/monitor/projectManager.py", line 799, in get_request_from_keywords_hot
    self.start_finished_spider_every_interval(project_names)
    │    │                                    └ ['default', 'test']
    │    └ <function ProjectManager.start_finished_spider_every_interval at 0x7f3104005280>
    └ <monitor.projectManager.ProjectManager object at 0x7f31042e52e0>

  File "/home/users/Scy/yuqing/spider/monitor/projectManager.py", line 784, in start_finished_spider_every_interval
    self[name].start_spider()
    │    └ 'default'
    └ <monitor.projectManager.ProjectManager object at 0x7f31042e52e0>

  File "/home/users/Scy/yuqing/spider/monitor/projectManager.py", line 366, in start_spider
    self.update_device_valid(device)
    │    │                   └ <monitor.deviceManager.DeviceC object at 0x7f3104029220>
    │    └ <function Project.update_device_valid at 0x7f3104003280>
    └ <monitor.projectManager.Project object at 0x7f3104029460>

  File "/home/users/Scy/yuqing/spider/monitor/projectManager.py", line 421, in update_device_valid
    self.database_manager.mysql.update(Device(**device.to_item()))
    │    │                │     │      │        │      └ <function DeviceC.to_item at 0x7f31f34ed310>
    │    │                │     │      │        └ <monitor.deviceManager.DeviceC object at 0x7f3104029220>
    │    │                │     │      └ <class 'base.db.mysql.Device'>
    │    │                │     └ <function Mysql.update at 0x7f31f35f4790>
    │    │                └ <base.db.mysql.Mysql object at 0x7f3103ffdfd0>
    │    └ <base.db.dbSlot.Slot object at 0x7f3103ffdf10>
    └ <monitor.projectManager.Project object at 0x7f3104029460>

> File "/home/users/Scy/yuqing/spider/base/db/mysql.py", line 375, in update
    row.update(new)
    │   │      └ {'server_id': '180.201.163.246:6800', 'ip': '180.201.163.246', 'username': 'chase', 'password': '2673089041257655133154878844...
    │   └ <function Query.update at 0x7f31f37333a0>
    └ <sqlalchemy.orm.query.Query object at 0x7f2ff86bc6d0>

  File "/home/chase/.local/lib/python3.8/site-packages/sqlalchemy/orm/query.py", line 3221, in update
    result = self.session.execute(
             │    │       └ <function Session.execute at 0x7f31f370faf0>
             │    └ <sqlalchemy.orm.session.Session object at 0x7f30d812f460>
             └ <sqlalchemy.orm.query.Query object at 0x7f2ff86bc6d0>
  File "/home/chase/.local/lib/python3.8/site-packages/sqlalchemy/orm/session.py", line 1689, in execute
    result = conn._execute_20(statement, params or {}, execution_options)
             │    │           │          │             └ immutabledict({'synchronize_session': 'evaluate', '_sa_orm_update_options': default_update_options(_matched_objects=[], _reso...
             │    │           │          └ immutabledict({})
             │    │           └ <sqlalchemy.sql.annotation.AnnotatedUpdate object at 0x7f31020304c0>
             │    └ <function Connection._execute_20 at 0x7f31f39bc790>
             └ <sqlalchemy.engine.base.Connection object at 0x7f2f78634c10>
  File "/home/chase/.local/lib/python3.8/site-packages/sqlalchemy/engine/base.py", line 1583, in _execute_20
    return meth(self, args_10style, kwargs_10style, execution_options)
           │    │     │             │               └ immutabledict({'synchronize_session': 'evaluate', '_sa_orm_update_options': default_update_options(_matched_objects=[], _reso...
           │    │     │             └ immutabledict({})
           │    │     └ ({},)
           │    └ <sqlalchemy.engine.base.Connection object at 0x7f2f78634c10>
           └ <bound method ClauseElement._execute_on_connection of <sqlalchemy.sql.annotation.AnnotatedUpdate object at 0x7f31020304c0>>
  File "/home/chase/.local/lib/python3.8/site-packages/sqlalchemy/sql/elements.py", line 323, in _execute_on_connection
    return connection._execute_clauseelement(
           │          └ <function Connection._execute_clauseelement at 0x7f31f39bc5e0>
           └ <sqlalchemy.engine.base.Connection object at 0x7f2f78634c10>
  File "/home/chase/.local/lib/python3.8/site-packages/sqlalchemy/engine/base.py", line 1452, in _execute_clauseelement
    ret = self._execute_context(
          │    └ <function Connection._execute_context at 0x7f31f39bc8b0>
          └ <sqlalchemy.engine.base.Connection object at 0x7f2f78634c10>
  File "/home/chase/.local/lib/python3.8/site-packages/sqlalchemy/engine/base.py", line 1814, in _execute_context
    self._handle_dbapi_exception(
    │    └ <function Connection._handle_dbapi_exception at 0x7f31f39bca60>
    └ <sqlalchemy.engine.base.Connection object at 0x7f2f78634c10>
  File "/home/chase/.local/lib/python3.8/site-packages/sqlalchemy/engine/base.py", line 1995, in _handle_dbapi_exception
    util.raise_(
    │    └ <function raise_ at 0x7f31f3d7ea60>
    └ <module 'sqlalchemy.util' from '/home/chase/.local/lib/python3.8/site-packages/sqlalchemy/util/__init__.py'>
  File "/home/chase/.local/lib/python3.8/site-packages/sqlalchemy/util/compat.py", line 207, in raise_
    raise exception
  File "/home/chase/.local/lib/python3.8/site-packages/sqlalchemy/engine/base.py", line 1771, in _execute_context
    self.dialect.do_execute(
    │    │       └ <function DefaultDialect.do_execute at 0x7f31f38f75e0>
    │    └ <sqlalchemy.dialects.mysql.pymysql.MySQLDialect_pymysql object at 0x7f3103ffde20>
    └ <sqlalchemy.engine.base.Connection object at 0x7f2f78634c10>
  File "/home/chase/.local/lib/python3.8/site-packages/sqlalchemy/engine/default.py", line 717, in do_execute
    cursor.execute(statement, parameters)
    │      │       │          └ {'server_id': '180.201.163.246:6800', 'ip': '180.201.163.246', 'username': 'chase', 'password': '2673089041257655133154878844...
    │      │       └ 'UPDATE device SET server_id=%(server_id)s, ip=%(ip)s, username=%(username)s, password=%(password)s, address=%(address)s, por...
    │      └ <function Cursor.execute at 0x7f31f354cdc0>
    └ <pymysql.cursors.Cursor object at 0x7f2f982e4820>
  File "/home/chase/.local/lib/python3.8/site-packages/pymysql/cursors.py", line 148, in execute
    result = self._query(query)
             │    │      └ "UPDATE device SET server_id='180.201.163.246:6800', ip='180.201.163.246', username='chase', password='2673089041257655133154...
             │    └ <function Cursor._query at 0x7f31f34d7280>
             └ <pymysql.cursors.Cursor object at 0x7f2f982e4820>
  File "/home/chase/.local/lib/python3.8/site-packages/pymysql/cursors.py", line 310, in _query
    conn.query(q)
    │    │     └ "UPDATE device SET server_id='180.201.163.246:6800', ip='180.201.163.246', username='chase', password='2673089041257655133154...
    │    └ <function Connection.query at 0x7f31f34e5670>
    └ <pymysql.connections.Connection object at 0x7f2fb81e1cd0>
  File "/home/chase/.local/lib/python3.8/site-packages/pymysql/connections.py", line 548, in query
    self._affected_rows = self._read_query_result(unbuffered=unbuffered)
    │    │                │    │                             └ False
    │    │                │    └ <function Connection._read_query_result at 0x7f31f34e5ca0>
    │    │                └ <pymysql.connections.Connection object at 0x7f2fb81e1cd0>
    │    └ 1
    └ <pymysql.connections.Connection object at 0x7f2fb81e1cd0>
  File "/home/chase/.local/lib/python3.8/site-packages/pymysql/connections.py", line 775, in _read_query_result
    result.read()
    │      └ <function MySQLResult.read at 0x7f31f34e64c0>
    └ <pymysql.connections.MySQLResult object at 0x7f2e11b93d00>
  File "/home/chase/.local/lib/python3.8/site-packages/pymysql/connections.py", line 1156, in read
    first_packet = self.connection._read_packet()
                   │    └ None
                   └ <pymysql.connections.MySQLResult object at 0x7f2e11b93d00>
  File "/home/chase/.local/lib/python3.8/site-packages/pymysql/connections.py", line 725, in _read_packet
    packet.raise_for_error()
    │      └ <function MysqlPacket.raise_for_error at 0x7f31f34ddee0>
    └ <pymysql.protocol.MysqlPacket object at 0x7f2de994c280>
  File "/home/chase/.local/lib/python3.8/site-packages/pymysql/protocol.py", line 221, in raise_for_error
    err.raise_mysql_exception(self._data)
    │   │                     │    └ <member '_data' of 'MysqlPacket' objects>
    │   │                     └ <pymysql.protocol.MysqlPacket object at 0x7f2de994c280>
    │   └ <function raise_mysql_exception at 0x7f31f358c670>
    └ <module 'pymysql.err' from '/home/chase/.local/lib/python3.8/site-packages/pymysql/err.py'>
  File "/home/chase/.local/lib/python3.8/site-packages/pymysql/err.py", line 143, in raise_mysql_exception
    raise errorclass(errno, errval)
          │          │      └ "Duplicate entry '180.201.163.246:6800' for key 'device.PRIMARY'"
          │          └ 1062
          └ <class 'pymysql.err.IntegrityError'>

sqlalchemy.exc.IntegrityError: (pymysql.err.IntegrityError) (1062, "Duplicate entry '180.201.163.246:6800' for key 'device.PRIMARY'")
[SQL: UPDATE device SET server_id=%(server_id)s, ip=%(ip)s, username=%(username)s, password=%(password)s, address=%(address)s, port=%(port)s, valid=%(valid)s WHERE device.ip = %(ip_1)s]
[parameters: {'server_id': '180.201.163.246:6800', 'ip': '180.201.163.246', 'username': 'chase', 'password': '26730890412576551331548788443745756216712652184196966177720232647775640609158707485273288654779650142400996866230705287135485178522310227907607713530 ... (10 characters truncated) ... 82791484795901942731727425568387518889408870475288417995603308401765201306752900285556506517417103115621124180804443781833937604308409553648558852650', 'address': '/home/users/CT/pycharmproject/spiders/', 'port': 6800, 'valid': 1, 'ip_1': '180.201.163.246'}]
(Background on this error at: https://sqlalche.me/e/14/gkpj)
2022-05-14 06:01:41.040 | ERROR    | base.db.mysql:update:390 - 【mysql更新数据出错】
Traceback (most recent call last):

  File "/home/chase/.local/lib/python3.8/site-packages/sqlalchemy/engine/base.py", line 1771, in _execute_context
    self.dialect.do_execute(
    │    │       └ <function DefaultDialect.do_execute at 0x7f31f38f75e0>
    │    └ <sqlalchemy.dialects.mysql.pymysql.MySQLDialect_pymysql object at 0x7f3103ffde20>
    └ <sqlalchemy.engine.base.Connection object at 0x7f30984b1be0>
  File "/home/chase/.local/lib/python3.8/site-packages/sqlalchemy/engine/default.py", line 717, in do_execute
    cursor.execute(statement, parameters)
    │      │       │          └ {'server_id': '180.201.163.246:6800', 'ip': '180.201.163.246', 'username': 'chase', 'password': '1136192444799705437558487195...
    │      │       └ 'UPDATE device SET server_id=%(server_id)s, ip=%(ip)s, username=%(username)s, password=%(password)s, address=%(address)s, por...
    │      └ <function Cursor.execute at 0x7f31f354cdc0>
    └ <pymysql.cursors.Cursor object at 0x7f305842a100>
  File "/home/chase/.local/lib/python3.8/site-packages/pymysql/cursors.py", line 148, in execute
    result = self._query(query)
             │    │      └ "UPDATE device SET server_id='180.201.163.246:6800', ip='180.201.163.246', username='chase', password='1136192444799705437558...
             │    └ <function Cursor._query at 0x7f31f34d7280>
             └ <pymysql.cursors.Cursor object at 0x7f305842a100>
  File "/home/chase/.local/lib/python3.8/site-packages/pymysql/cursors.py", line 310, in _query
    conn.query(q)
    │    │     └ "UPDATE device SET server_id='180.201.163.246:6800', ip='180.201.163.246', username='chase', password='1136192444799705437558...
    │    └ <function Connection.query at 0x7f31f34e5670>
    └ <pymysql.connections.Connection object at 0x7f2f78729dc0>
  File "/home/chase/.local/lib/python3.8/site-packages/pymysql/connections.py", line 548, in query
    self._affected_rows = self._read_query_result(unbuffered=unbuffered)
    │    │                │    │                             └ False
    │    │                │    └ <function Connection._read_query_result at 0x7f31f34e5ca0>
    │    │                └ <pymysql.connections.Connection object at 0x7f2f78729dc0>
    │    └ 1
    └ <pymysql.connections.Connection object at 0x7f2f78729dc0>
  File "/home/chase/.local/lib/python3.8/site-packages/pymysql/connections.py", line 775, in _read_query_result
    result.read()
    │      └ <function MySQLResult.read at 0x7f31f34e64c0>
    └ <pymysql.connections.MySQLResult object at 0x7f3058081250>
  File "/home/chase/.local/lib/python3.8/site-packages/pymysql/connections.py", line 1156, in read
    first_packet = self.connection._read_packet()
                   │    └ None
                   └ <pymysql.connections.MySQLResult object at 0x7f3058081250>
  File "/home/chase/.local/lib/python3.8/site-packages/pymysql/connections.py", line 725, in _read_packet
    packet.raise_for_error()
    │      └ <function MysqlPacket.raise_for_error at 0x7f31f34ddee0>
    └ <pymysql.protocol.MysqlPacket object at 0x7f2fb86d23a0>
  File "/home/chase/.local/lib/python3.8/site-packages/pymysql/protocol.py", line 221, in raise_for_error
    err.raise_mysql_exception(self._data)
    │   │                     │    └ <member '_data' of 'MysqlPacket' objects>
    │   │                     └ <pymysql.protocol.MysqlPacket object at 0x7f2fb86d23a0>
    │   └ <function raise_mysql_exception at 0x7f31f358c670>
    └ <module 'pymysql.err' from '/home/chase/.local/lib/python3.8/site-packages/pymysql/err.py'>
  File "/home/chase/.local/lib/python3.8/site-packages/pymysql/err.py", line 143, in raise_mysql_exception
    raise errorclass(errno, errval)
          │          │      └ "Duplicate entry '180.201.163.246:6800' for key 'device.PRIMARY'"
          │          └ 1062
          └ <class 'pymysql.err.IntegrityError'>

pymysql.err.IntegrityError: (1062, "Duplicate entry '180.201.163.246:6800' for key 'device.PRIMARY'")


The above exception was the direct cause of the following exception:


Traceback (most recent call last):

  File "/usr/lib/python3.8/threading.py", line 890, in _bootstrap
    self._bootstrap_inner()
    │    └ <function Thread._bootstrap_inner at 0x7f321bf29a60>
    └ <Thread(Thread-11946, started daemon 139847817750272)>
  File "/usr/lib/python3.8/threading.py", line 932, in _bootstrap_inner
    self.run()
    │    └ <function Thread.run at 0x7f321bf29790>
    └ <Thread(Thread-11946, started daemon 139847817750272)>
  File "/usr/lib/python3.8/threading.py", line 870, in run
    self._target(*self._args, **self._kwargs)
    │    │        │    │        │    └ {}
    │    │        │    │        └ <Thread(Thread-11946, started daemon 139847817750272)>
    │    │        │    └ ('ProjectManager.run_func_by_thread',)
    │    │        └ <Thread(Thread-11946, started daemon 139847817750272)>
    │    └ <bound method ProjectManager.get_request_from_keywords_hot of <monitor.projectManager.ProjectManager object at 0x7f31042e52e0>>
    └ <Thread(Thread-11946, started daemon 139847817750272)>

  File "/home/users/Scy/yuqing/spider/monitor/projectManager.py", line 799, in get_request_from_keywords_hot
    self.start_finished_spider_every_interval(project_names)
    │    │                                    └ ['default', 'test']
    │    └ <function ProjectManager.start_finished_spider_every_interval at 0x7f3104005280>
    └ <monitor.projectManager.ProjectManager object at 0x7f31042e52e0>

  File "/home/users/Scy/yuqing/spider/monitor/projectManager.py", line 784, in start_finished_spider_every_interval
    self[name].start_spider()
    │    └ 'default'
    └ <monitor.projectManager.ProjectManager object at 0x7f31042e52e0>

  File "/home/users/Scy/yuqing/spider/monitor/projectManager.py", line 366, in start_spider
    self.update_device_valid(device)
    │    │                   └ <monitor.deviceManager.DeviceC object at 0x7f3104029220>
    │    └ <function Project.update_device_valid at 0x7f3104003280>
    └ <monitor.projectManager.Project object at 0x7f3104029460>

  File "/home/users/Scy/yuqing/spider/monitor/projectManager.py", line 421, in update_device_valid
    self.database_manager.mysql.update(Device(**device.to_item()))
    │    │                │     │      │        │      └ <function DeviceC.to_item at 0x7f31f34ed310>
    │    │                │     │      │        └ <monitor.deviceManager.DeviceC object at 0x7f3104029220>
    │    │                │     │      └ <class 'base.db.mysql.Device'>
    │    │                │     └ <function Mysql.update at 0x7f31f35f4790>
    │    │                └ <base.db.mysql.Mysql object at 0x7f3103ffdfd0>
    │    └ <base.db.dbSlot.Slot object at 0x7f3103ffdf10>
    └ <monitor.projectManager.Project object at 0x7f3104029460>

> File "/home/users/Scy/yuqing/spider/base/db/mysql.py", line 375, in update
    row.update(new)
    │   │      └ {'server_id': '180.201.163.246:6800', 'ip': '180.201.163.246', 'username': 'chase', 'password': '1136192444799705437558487195...
    │   └ <function Query.update at 0x7f31f37333a0>
    └ <sqlalchemy.orm.query.Query object at 0x7f30982e98e0>

  File "/home/chase/.local/lib/python3.8/site-packages/sqlalchemy/orm/query.py", line 3221, in update
    result = self.session.execute(
             │    │       └ <function Session.execute at 0x7f31f370faf0>
             │    └ <sqlalchemy.orm.session.Session object at 0x7f31f9243430>
             └ <sqlalchemy.orm.query.Query object at 0x7f30982e98e0>
  File "/home/chase/.local/lib/python3.8/site-packages/sqlalchemy/orm/session.py", line 1689, in execute
    result = conn._execute_20(statement, params or {}, execution_options)
             │    │           │          │             └ immutabledict({'synchronize_session': 'evaluate', '_sa_orm_update_options': default_update_options(_matched_objects=[], _reso...
             │    │           │          └ immutabledict({})
             │    │           └ <sqlalchemy.sql.annotation.AnnotatedUpdate object at 0x7f3078424190>
             │    └ <function Connection._execute_20 at 0x7f31f39bc790>
             └ <sqlalchemy.engine.base.Connection object at 0x7f30984b1be0>
  File "/home/chase/.local/lib/python3.8/site-packages/sqlalchemy/engine/base.py", line 1583, in _execute_20
    return meth(self, args_10style, kwargs_10style, execution_options)
           │    │     │             │               └ immutabledict({'synchronize_session': 'evaluate', '_sa_orm_update_options': default_update_options(_matched_objects=[], _reso...
           │    │     │             └ immutabledict({})
           │    │     └ ({},)
           │    └ <sqlalchemy.engine.base.Connection object at 0x7f30984b1be0>
           └ <bound method ClauseElement._execute_on_connection of <sqlalchemy.sql.annotation.AnnotatedUpdate object at 0x7f3078424190>>
  File "/home/chase/.local/lib/python3.8/site-packages/sqlalchemy/sql/elements.py", line 323, in _execute_on_connection
    return connection._execute_clauseelement(
           │          └ <function Connection._execute_clauseelement at 0x7f31f39bc5e0>
           └ <sqlalchemy.engine.base.Connection object at 0x7f30984b1be0>
  File "/home/chase/.local/lib/python3.8/site-packages/sqlalchemy/engine/base.py", line 1452, in _execute_clauseelement
    ret = self._execute_context(
          │    └ <function Connection._execute_context at 0x7f31f39bc8b0>
          └ <sqlalchemy.engine.base.Connection object at 0x7f30984b1be0>
  File "/home/chase/.local/lib/python3.8/site-packages/sqlalchemy/engine/base.py", line 1814, in _execute_context
    self._handle_dbapi_exception(
    │    └ <function Connection._handle_dbapi_exception at 0x7f31f39bca60>
    └ <sqlalchemy.engine.base.Connection object at 0x7f30984b1be0>
  File "/home/chase/.local/lib/python3.8/site-packages/sqlalchemy/engine/base.py", line 1995, in _handle_dbapi_exception
    util.raise_(
    │    └ <function raise_ at 0x7f31f3d7ea60>
    └ <module 'sqlalchemy.util' from '/home/chase/.local/lib/python3.8/site-packages/sqlalchemy/util/__init__.py'>
  File "/home/chase/.local/lib/python3.8/site-packages/sqlalchemy/util/compat.py", line 207, in raise_
    raise exception
  File "/home/chase/.local/lib/python3.8/site-packages/sqlalchemy/engine/base.py", line 1771, in _execute_context
    self.dialect.do_execute(
    │    │       └ <function DefaultDialect.do_execute at 0x7f31f38f75e0>
    │    └ <sqlalchemy.dialects.mysql.pymysql.MySQLDialect_pymysql object at 0x7f3103ffde20>
    └ <sqlalchemy.engine.base.Connection object at 0x7f30984b1be0>
  File "/home/chase/.local/lib/python3.8/site-packages/sqlalchemy/engine/default.py", line 717, in do_execute
    cursor.execute(statement, parameters)
    │      │       │          └ {'server_id': '180.201.163.246:6800', 'ip': '180.201.163.246', 'username': 'chase', 'password': '1136192444799705437558487195...
    │      │       └ 'UPDATE device SET server_id=%(server_id)s, ip=%(ip)s, username=%(username)s, password=%(password)s, address=%(address)s, por...
    │      └ <function Cursor.execute at 0x7f31f354cdc0>
    └ <pymysql.cursors.Cursor object at 0x7f305842a100>
  File "/home/chase/.local/lib/python3.8/site-packages/pymysql/cursors.py", line 148, in execute
    result = self._query(query)
             │    │      └ "UPDATE device SET server_id='180.201.163.246:6800', ip='180.201.163.246', username='chase', password='1136192444799705437558...
             │    └ <function Cursor._query at 0x7f31f34d7280>
             └ <pymysql.cursors.Cursor object at 0x7f305842a100>
  File "/home/chase/.local/lib/python3.8/site-packages/pymysql/cursors.py", line 310, in _query
    conn.query(q)
    │    │     └ "UPDATE device SET server_id='180.201.163.246:6800', ip='180.201.163.246', username='chase', password='1136192444799705437558...
    │    └ <function Connection.query at 0x7f31f34e5670>
    └ <pymysql.connections.Connection object at 0x7f2f78729dc0>
  File "/home/chase/.local/lib/python3.8/site-packages/pymysql/connections.py", line 548, in query
    self._affected_rows = self._read_query_result(unbuffered=unbuffered)
    │    │                │    │                             └ False
    │    │                │    └ <function Connection._read_query_result at 0x7f31f34e5ca0>
    │    │                └ <pymysql.connections.Connection object at 0x7f2f78729dc0>
    │    └ 1
    └ <pymysql.connections.Connection object at 0x7f2f78729dc0>
  File "/home/chase/.local/lib/python3.8/site-packages/pymysql/connections.py", line 775, in _read_query_result
    result.read()
    │      └ <function MySQLResult.read at 0x7f31f34e64c0>
    └ <pymysql.connections.MySQLResult object at 0x7f3058081250>
  File "/home/chase/.local/lib/python3.8/site-packages/pymysql/connections.py", line 1156, in read
    first_packet = self.connection._read_packet()
                   │    └ None
                   └ <pymysql.connections.MySQLResult object at 0x7f3058081250>
  File "/home/chase/.local/lib/python3.8/site-packages/pymysql/connections.py", line 725, in _read_packet
    packet.raise_for_error()
    │      └ <function MysqlPacket.raise_for_error at 0x7f31f34ddee0>
    └ <pymysql.protocol.MysqlPacket object at 0x7f2fb86d23a0>
  File "/home/chase/.local/lib/python3.8/site-packages/pymysql/protocol.py", line 221, in raise_for_error
    err.raise_mysql_exception(self._data)
    │   │                     │    └ <member '_data' of 'MysqlPacket' objects>
    │   │                     └ <pymysql.protocol.MysqlPacket object at 0x7f2fb86d23a0>
    │   └ <function raise_mysql_exception at 0x7f31f358c670>
    └ <module 'pymysql.err' from '/home/chase/.local/lib/python3.8/site-packages/pymysql/err.py'>
  File "/home/chase/.local/lib/python3.8/site-packages/pymysql/err.py", line 143, in raise_mysql_exception
    raise errorclass(errno, errval)
          │          │      └ "Duplicate entry '180.201.163.246:6800' for key 'device.PRIMARY'"
          │          └ 1062
          └ <class 'pymysql.err.IntegrityError'>

sqlalchemy.exc.IntegrityError: (pymysql.err.IntegrityError) (1062, "Duplicate entry '180.201.163.246:6800' for key 'device.PRIMARY'")
[SQL: UPDATE device SET server_id=%(server_id)s, ip=%(ip)s, username=%(username)s, password=%(password)s, address=%(address)s, port=%(port)s, valid=%(valid)s WHERE device.ip = %(ip_1)s]
[parameters: {'server_id': '180.201.163.246:6800', 'ip': '180.201.163.246', 'username': 'chase', 'password': '11361924447997054375584871954724261644343936489007727035160150920320976345819724520164689557737734429027698739860701717724311285023831861767409216784 ... (10 characters truncated) ... 00487820741705808532350684807434368537121353438689955132990289384156938626372991923888848623408945333339939613423376910511316106725349141552307256200', 'address': '/home/users/CT/pycharmproject/spiders/', 'port': 6800, 'valid': 1, 'ip_1': '180.201.163.246'}]
(Background on this error at: https://sqlalche.me/e/14/gkpj)
2022-05-14 06:01:58.355 | ERROR    | base.db.mysql:update:390 - 【mysql更新数据出错】
Traceback (most recent call last):

  File "/home/chase/.local/lib/python3.8/site-packages/sqlalchemy/engine/base.py", line 1771, in _execute_context
    self.dialect.do_execute(
    │    │       └ <function DefaultDialect.do_execute at 0x7f31f38f75e0>
    │    └ <sqlalchemy.dialects.mysql.pymysql.MySQLDialect_pymysql object at 0x7f3103ffde20>
    └ <sqlalchemy.engine.base.Connection object at 0x7f2fb80a6b80>
  File "/home/chase/.local/lib/python3.8/site-packages/sqlalchemy/engine/default.py", line 717, in do_execute
    cursor.execute(statement, parameters)
    │      │       │          └ {'server_id': '180.201.163.246:6800', 'ip': '180.201.163.246', 'username': 'chase', 'password': '2159994668283637019111319032...
    │      │       └ 'UPDATE device SET server_id=%(server_id)s, ip=%(ip)s, username=%(username)s, password=%(password)s, address=%(address)s, por...
    │      └ <function Cursor.execute at 0x7f31f354cdc0>
    └ <pymysql.cursors.Cursor object at 0x7f2f786d1d30>
  File "/home/chase/.local/lib/python3.8/site-packages/pymysql/cursors.py", line 148, in execute
    result = self._query(query)
             │    │      └ "UPDATE device SET server_id='180.201.163.246:6800', ip='180.201.163.246', username='chase', password='2159994668283637019111...
             │    └ <function Cursor._query at 0x7f31f34d7280>
             └ <pymysql.cursors.Cursor object at 0x7f2f786d1d30>
  File "/home/chase/.local/lib/python3.8/site-packages/pymysql/cursors.py", line 310, in _query
    conn.query(q)
    │    │     └ "UPDATE device SET server_id='180.201.163.246:6800', ip='180.201.163.246', username='chase', password='2159994668283637019111...
    │    └ <function Connection.query at 0x7f31f34e5670>
    └ <pymysql.connections.Connection object at 0x7f3018718700>
  File "/home/chase/.local/lib/python3.8/site-packages/pymysql/connections.py", line 548, in query
    self._affected_rows = self._read_query_result(unbuffered=unbuffered)
    │    │                │    │                             └ False
    │    │                │    └ <function Connection._read_query_result at 0x7f31f34e5ca0>
    │    │                └ <pymysql.connections.Connection object at 0x7f3018718700>
    │    └ 1
    └ <pymysql.connections.Connection object at 0x7f3018718700>
  File "/home/chase/.local/lib/python3.8/site-packages/pymysql/connections.py", line 775, in _read_query_result
    result.read()
    │      └ <function MySQLResult.read at 0x7f31f34e64c0>
    └ <pymysql.connections.MySQLResult object at 0x7f30381398b0>
  File "/home/chase/.local/lib/python3.8/site-packages/pymysql/connections.py", line 1156, in read
    first_packet = self.connection._read_packet()
                   │    └ None
                   └ <pymysql.connections.MySQLResult object at 0x7f30381398b0>
  File "/home/chase/.local/lib/python3.8/site-packages/pymysql/connections.py", line 725, in _read_packet
    packet.raise_for_error()
    │      └ <function MysqlPacket.raise_for_error at 0x7f31f34ddee0>
    └ <pymysql.protocol.MysqlPacket object at 0x7f2de99c6ee0>
  File "/home/chase/.local/lib/python3.8/site-packages/pymysql/protocol.py", line 221, in raise_for_error
    err.raise_mysql_exception(self._data)
    │   │                     │    └ <member '_data' of 'MysqlPacket' objects>
    │   │                     └ <pymysql.protocol.MysqlPacket object at 0x7f2de99c6ee0>
    │   └ <function raise_mysql_exception at 0x7f31f358c670>
    └ <module 'pymysql.err' from '/home/chase/.local/lib/python3.8/site-packages/pymysql/err.py'>
  File "/home/chase/.local/lib/python3.8/site-packages/pymysql/err.py", line 143, in raise_mysql_exception
    raise errorclass(errno, errval)
          │          │      └ "Duplicate entry '180.201.163.246:6800' for key 'device.PRIMARY'"
          │          └ 1062
          └ <class 'pymysql.err.IntegrityError'>

pymysql.err.IntegrityError: (1062, "Duplicate entry '180.201.163.246:6800' for key 'device.PRIMARY'")


The above exception was the direct cause of the following exception:


Traceback (most recent call last):

  File "/usr/lib/python3.8/threading.py", line 890, in _bootstrap
    self._bootstrap_inner()
    │    └ <function Thread._bootstrap_inner at 0x7f321bf29a60>
    └ <Thread(Thread-11951, started daemon 139846744008448)>
  File "/usr/lib/python3.8/threading.py", line 932, in _bootstrap_inner
    self.run()
    │    └ <function Thread.run at 0x7f321bf29790>
    └ <Thread(Thread-11951, started daemon 139846744008448)>
  File "/usr/lib/python3.8/threading.py", line 870, in run
    self._target(*self._args, **self._kwargs)
    │    │        │    │        │    └ {}
    │    │        │    │        └ <Thread(Thread-11951, started daemon 139846744008448)>
    │    │        │    └ ('ProjectManager.run_func_by_thread',)
    │    │        └ <Thread(Thread-11951, started daemon 139846744008448)>
    │    └ <bound method ProjectManager.get_request_from_keywords_hot of <monitor.projectManager.ProjectManager object at 0x7f31042e52e0>>
    └ <Thread(Thread-11951, started daemon 139846744008448)>

  File "/home/users/Scy/yuqing/spider/monitor/projectManager.py", line 799, in get_request_from_keywords_hot
    self.start_finished_spider_every_interval(project_names)
    │    │                                    └ ['default', 'test']
    │    └ <function ProjectManager.start_finished_spider_every_interval at 0x7f3104005280>
    └ <monitor.projectManager.ProjectManager object at 0x7f31042e52e0>

  File "/home/users/Scy/yuqing/spider/monitor/projectManager.py", line 784, in start_finished_spider_every_interval
    self[name].start_spider()
    │    └ 'default'
    └ <monitor.projectManager.ProjectManager object at 0x7f31042e52e0>

  File "/home/users/Scy/yuqing/spider/monitor/projectManager.py", line 366, in start_spider
    self.update_device_valid(device)
    │    │                   └ <monitor.deviceManager.DeviceC object at 0x7f3104029220>
    │    └ <function Project.update_device_valid at 0x7f3104003280>
    └ <monitor.projectManager.Project object at 0x7f3104029460>

  File "/home/users/Scy/yuqing/spider/monitor/projectManager.py", line 421, in update_device_valid
    self.database_manager.mysql.update(Device(**device.to_item()))
    │    │                │     │      │        │      └ <function DeviceC.to_item at 0x7f31f34ed310>
    │    │                │     │      │        └ <monitor.deviceManager.DeviceC object at 0x7f3104029220>
    │    │                │     │      └ <class 'base.db.mysql.Device'>
    │    │                │     └ <function Mysql.update at 0x7f31f35f4790>
    │    │                └ <base.db.mysql.Mysql object at 0x7f3103ffdfd0>
    │    └ <base.db.dbSlot.Slot object at 0x7f3103ffdf10>
    └ <monitor.projectManager.Project object at 0x7f3104029460>

> File "/home/users/Scy/yuqing/spider/base/db/mysql.py", line 375, in update
    row.update(new)
    │   │      └ {'server_id': '180.201.163.246:6800', 'ip': '180.201.163.246', 'username': 'chase', 'password': '2159994668283637019111319032...
    │   └ <function Query.update at 0x7f31f37333a0>
    └ <sqlalchemy.orm.query.Query object at 0x7f305847cbb0>

  File "/home/chase/.local/lib/python3.8/site-packages/sqlalchemy/orm/query.py", line 3221, in update
    result = self.session.execute(
             │    │       └ <function Session.execute at 0x7f31f370faf0>
             │    └ <sqlalchemy.orm.session.Session object at 0x7f3038726460>
             └ <sqlalchemy.orm.query.Query object at 0x7f305847cbb0>
  File "/home/chase/.local/lib/python3.8/site-packages/sqlalchemy/orm/session.py", line 1689, in execute
    result = conn._execute_20(statement, params or {}, execution_options)
             │    │           │          │             └ immutabledict({'synchronize_session': 'evaluate', '_sa_orm_update_options': default_update_options(_matched_objects=[], _reso...
             │    │           │          └ immutabledict({})
             │    │           └ <sqlalchemy.sql.annotation.AnnotatedUpdate object at 0x7f309810a970>
             │    └ <function Connection._execute_20 at 0x7f31f39bc790>
             └ <sqlalchemy.engine.base.Connection object at 0x7f2fb80a6b80>
  File "/home/chase/.local/lib/python3.8/site-packages/sqlalchemy/engine/base.py", line 1583, in _execute_20
    return meth(self, args_10style, kwargs_10style, execution_options)
           │    │     │             │               └ immutabledict({'synchronize_session': 'evaluate', '_sa_orm_update_options': default_update_options(_matched_objects=[], _reso...
           │    │     │             └ immutabledict({})
           │    │     └ ({},)
           │    └ <sqlalchemy.engine.base.Connection object at 0x7f2fb80a6b80>
           └ <bound method ClauseElement._execute_on_connection of <sqlalchemy.sql.annotation.AnnotatedUpdate object at 0x7f309810a970>>
  File "/home/chase/.local/lib/python3.8/site-packages/sqlalchemy/sql/elements.py", line 323, in _execute_on_connection
    return connection._execute_clauseelement(
           │          └ <function Connection._execute_clauseelement at 0x7f31f39bc5e0>
           └ <sqlalchemy.engine.base.Connection object at 0x7f2fb80a6b80>
  File "/home/chase/.local/lib/python3.8/site-packages/sqlalchemy/engine/base.py", line 1452, in _execute_clauseelement
    ret = self._execute_context(
          │    └ <function Connection._execute_context at 0x7f31f39bc8b0>
          └ <sqlalchemy.engine.base.Connection object at 0x7f2fb80a6b80>
  File "/home/chase/.local/lib/python3.8/site-packages/sqlalchemy/engine/base.py", line 1814, in _execute_context
    self._handle_dbapi_exception(
    │    └ <function Connection._handle_dbapi_exception at 0x7f31f39bca60>
    └ <sqlalchemy.engine.base.Connection object at 0x7f2fb80a6b80>
  File "/home/chase/.local/lib/python3.8/site-packages/sqlalchemy/engine/base.py", line 1995, in _handle_dbapi_exception
    util.raise_(
    │    └ <function raise_ at 0x7f31f3d7ea60>
    └ <module 'sqlalchemy.util' from '/home/chase/.local/lib/python3.8/site-packages/sqlalchemy/util/__init__.py'>
  File "/home/chase/.local/lib/python3.8/site-packages/sqlalchemy/util/compat.py", line 207, in raise_
    raise exception
  File "/home/chase/.local/lib/python3.8/site-packages/sqlalchemy/engine/base.py", line 1771, in _execute_context
    self.dialect.do_execute(
    │    │       └ <function DefaultDialect.do_execute at 0x7f31f38f75e0>
    │    └ <sqlalchemy.dialects.mysql.pymysql.MySQLDialect_pymysql object at 0x7f3103ffde20>
    └ <sqlalchemy.engine.base.Connection object at 0x7f2fb80a6b80>
  File "/home/chase/.local/lib/python3.8/site-packages/sqlalchemy/engine/default.py", line 717, in do_execute
    cursor.execute(statement, parameters)
    │      │       │          └ {'server_id': '180.201.163.246:6800', 'ip': '180.201.163.246', 'username': 'chase', 'password': '2159994668283637019111319032...
    │      │       └ 'UPDATE device SET server_id=%(server_id)s, ip=%(ip)s, username=%(username)s, password=%(password)s, address=%(address)s, por...
    │      └ <function Cursor.execute at 0x7f31f354cdc0>
    └ <pymysql.cursors.Cursor object at 0x7f2f786d1d30>
  File "/home/chase/.local/lib/python3.8/site-packages/pymysql/cursors.py", line 148, in execute
    result = self._query(query)
             │    │      └ "UPDATE device SET server_id='180.201.163.246:6800', ip='180.201.163.246', username='chase', password='2159994668283637019111...
             │    └ <function Cursor._query at 0x7f31f34d7280>
             └ <pymysql.cursors.Cursor object at 0x7f2f786d1d30>
  File "/home/chase/.local/lib/python3.8/site-packages/pymysql/cursors.py", line 310, in _query
    conn.query(q)
    │    │     └ "UPDATE device SET server_id='180.201.163.246:6800', ip='180.201.163.246', username='chase', password='2159994668283637019111...
    │    └ <function Connection.query at 0x7f31f34e5670>
    └ <pymysql.connections.Connection object at 0x7f3018718700>
  File "/home/chase/.local/lib/python3.8/site-packages/pymysql/connections.py", line 548, in query
    self._affected_rows = self._read_query_result(unbuffered=unbuffered)
    │    │                │    │                             └ False
    │    │                │    └ <function Connection._read_query_result at 0x7f31f34e5ca0>
    │    │                └ <pymysql.connections.Connection object at 0x7f3018718700>
    │    └ 1
    └ <pymysql.connections.Connection object at 0x7f3018718700>
  File "/home/chase/.local/lib/python3.8/site-packages/pymysql/connections.py", line 775, in _read_query_result
    result.read()
    │      └ <function MySQLResult.read at 0x7f31f34e64c0>
    └ <pymysql.connections.MySQLResult object at 0x7f30381398b0>
  File "/home/chase/.local/lib/python3.8/site-packages/pymysql/connections.py", line 1156, in read
    first_packet = self.connection._read_packet()
                   │    └ None
                   └ <pymysql.connections.MySQLResult object at 0x7f30381398b0>
  File "/home/chase/.local/lib/python3.8/site-packages/pymysql/connections.py", line 725, in _read_packet
    packet.raise_for_error()
    │      └ <function MysqlPacket.raise_for_error at 0x7f31f34ddee0>
    └ <pymysql.protocol.MysqlPacket object at 0x7f2de99c6ee0>
  File "/home/chase/.local/lib/python3.8/site-packages/pymysql/protocol.py", line 221, in raise_for_error
    err.raise_mysql_exception(self._data)
    │   │                     │    └ <member '_data' of 'MysqlPacket' objects>
    │   │                     └ <pymysql.protocol.MysqlPacket object at 0x7f2de99c6ee0>
    │   └ <function raise_mysql_exception at 0x7f31f358c670>
    └ <module 'pymysql.err' from '/home/chase/.local/lib/python3.8/site-packages/pymysql/err.py'>
  File "/home/chase/.local/lib/python3.8/site-packages/pymysql/err.py", line 143, in raise_mysql_exception
    raise errorclass(errno, errval)
          │          │      └ "Duplicate entry '180.201.163.246:6800' for key 'device.PRIMARY'"
          │          └ 1062
          └ <class 'pymysql.err.IntegrityError'>

sqlalchemy.exc.IntegrityError: (pymysql.err.IntegrityError) (1062, "Duplicate entry '180.201.163.246:6800' for key 'device.PRIMARY'")
[SQL: UPDATE device SET server_id=%(server_id)s, ip=%(ip)s, username=%(username)s, password=%(password)s, address=%(address)s, port=%(port)s, valid=%(valid)s WHERE device.ip = %(ip_1)s]
[parameters: {'server_id': '180.201.163.246:6800', 'ip': '180.201.163.246', 'username': 'chase', 'password': '21599946682836370191113190321182027413080762873828159566569275205928898564928149780414192455662847166519401392732964951359551580257516452632815335102 ... (10 characters truncated) ... 59998962926208490013878533638696384656741756885099545813579127672160116201222100233223341043895037620435107526316753808713135710820680832393020935759', 'address': '/home/users/CT/pycharmproject/spiders/', 'port': 6800, 'valid': 1, 'ip_1': '180.201.163.246'}]
(Background on this error at: https://sqlalche.me/e/14/gkpj)
2022-05-14 06:02:16.720 | ERROR    | base.db.mysql:update:390 - 【mysql更新数据出错】
Traceback (most recent call last):

  File "/home/chase/.local/lib/python3.8/site-packages/sqlalchemy/engine/base.py", line 1771, in _execute_context
    self.dialect.do_execute(
    │    │       └ <function DefaultDialect.do_execute at 0x7f31f38f75e0>
    │    └ <sqlalchemy.dialects.mysql.pymysql.MySQLDialect_pymysql object at 0x7f3103ffde20>
    └ <sqlalchemy.engine.base.Connection object at 0x7f2de9a399a0>
  File "/home/chase/.local/lib/python3.8/site-packages/sqlalchemy/engine/default.py", line 717, in do_execute
    cursor.execute(statement, parameters)
    │      │       │          └ {'server_id': '180.201.163.246:6800', 'ip': '180.201.163.246', 'username': 'chase', 'password': '9872715928751043839610636921...
    │      │       └ 'UPDATE device SET server_id=%(server_id)s, ip=%(ip)s, username=%(username)s, password=%(password)s, address=%(address)s, por...
    │      └ <function Cursor.execute at 0x7f31f354cdc0>
    └ <pymysql.cursors.Cursor object at 0x7f3100245bb0>
  File "/home/chase/.local/lib/python3.8/site-packages/pymysql/cursors.py", line 148, in execute
    result = self._query(query)
             │    │      └ "UPDATE device SET server_id='180.201.163.246:6800', ip='180.201.163.246', username='chase', password='9872715928751043839610...
             │    └ <function Cursor._query at 0x7f31f34d7280>
             └ <pymysql.cursors.Cursor object at 0x7f3100245bb0>
  File "/home/chase/.local/lib/python3.8/site-packages/pymysql/cursors.py", line 310, in _query
    conn.query(q)
    │    │     └ "UPDATE device SET server_id='180.201.163.246:6800', ip='180.201.163.246', username='chase', password='9872715928751043839610...
    │    └ <function Connection.query at 0x7f31f34e5670>
    └ <pymysql.connections.Connection object at 0x7f30b87dfa90>
  File "/home/chase/.local/lib/python3.8/site-packages/pymysql/connections.py", line 548, in query
    self._affected_rows = self._read_query_result(unbuffered=unbuffered)
    │    │                │    │                             └ False
    │    │                │    └ <function Connection._read_query_result at 0x7f31f34e5ca0>
    │    │                └ <pymysql.connections.Connection object at 0x7f30b87dfa90>
    │    └ 1
    └ <pymysql.connections.Connection object at 0x7f30b87dfa90>
  File "/home/chase/.local/lib/python3.8/site-packages/pymysql/connections.py", line 775, in _read_query_result
    result.read()
    │      └ <function MySQLResult.read at 0x7f31f34e64c0>
    └ <pymysql.connections.MySQLResult object at 0x7f2f780a2610>
  File "/home/chase/.local/lib/python3.8/site-packages/pymysql/connections.py", line 1156, in read
    first_packet = self.connection._read_packet()
                   │    └ None
                   └ <pymysql.connections.MySQLResult object at 0x7f2f780a2610>
  File "/home/chase/.local/lib/python3.8/site-packages/pymysql/connections.py", line 725, in _read_packet
    packet.raise_for_error()
    │      └ <function MysqlPacket.raise_for_error at 0x7f31f34ddee0>
    └ <pymysql.protocol.MysqlPacket object at 0x7f2f78641790>
  File "/home/chase/.local/lib/python3.8/site-packages/pymysql/protocol.py", line 221, in raise_for_error
    err.raise_mysql_exception(self._data)
    │   │                     │    └ <member '_data' of 'MysqlPacket' objects>
    │   │                     └ <pymysql.protocol.MysqlPacket object at 0x7f2f78641790>
    │   └ <function raise_mysql_exception at 0x7f31f358c670>
    └ <module 'pymysql.err' from '/home/chase/.local/lib/python3.8/site-packages/pymysql/err.py'>
  File "/home/chase/.local/lib/python3.8/site-packages/pymysql/err.py", line 143, in raise_mysql_exception
    raise errorclass(errno, errval)
          │          │      └ "Duplicate entry '180.201.163.246:6800' for key 'device.PRIMARY'"
          │          └ 1062
          └ <class 'pymysql.err.IntegrityError'>

pymysql.err.IntegrityError: (1062, "Duplicate entry '180.201.163.246:6800' for key 'device.PRIMARY'")


The above exception was the direct cause of the following exception:


Traceback (most recent call last):

  File "/usr/lib/python3.8/threading.py", line 890, in _bootstrap
    self._bootstrap_inner()
    │    └ <function Thread._bootstrap_inner at 0x7f321bf29a60>
    └ <Thread(Thread-11956, started daemon 139840208713472)>
  File "/usr/lib/python3.8/threading.py", line 932, in _bootstrap_inner
    self.run()
    │    └ <function Thread.run at 0x7f321bf29790>
    └ <Thread(Thread-11956, started daemon 139840208713472)>
  File "/usr/lib/python3.8/threading.py", line 870, in run
    self._target(*self._args, **self._kwargs)
    │    │        │    │        │    └ {}
    │    │        │    │        └ <Thread(Thread-11956, started daemon 139840208713472)>
    │    │        │    └ ('ProjectManager.run_func_by_thread',)
    │    │        └ <Thread(Thread-11956, started daemon 139840208713472)>
    │    └ <bound method ProjectManager.get_request_from_keywords_hot of <monitor.projectManager.ProjectManager object at 0x7f31042e52e0>>
    └ <Thread(Thread-11956, started daemon 139840208713472)>

  File "/home/users/Scy/yuqing/spider/monitor/projectManager.py", line 799, in get_request_from_keywords_hot
    self.start_finished_spider_every_interval(project_names)
    │    │                                    └ ['default', 'test']
    │    └ <function ProjectManager.start_finished_spider_every_interval at 0x7f3104005280>
    └ <monitor.projectManager.ProjectManager object at 0x7f31042e52e0>

  File "/home/users/Scy/yuqing/spider/monitor/projectManager.py", line 784, in start_finished_spider_every_interval
    self[name].start_spider()
    │    └ 'default'
    └ <monitor.projectManager.ProjectManager object at 0x7f31042e52e0>

  File "/home/users/Scy/yuqing/spider/monitor/projectManager.py", line 366, in start_spider
    self.update_device_valid(device)
    │    │                   └ <monitor.deviceManager.DeviceC object at 0x7f3104029220>
    │    └ <function Project.update_device_valid at 0x7f3104003280>
    └ <monitor.projectManager.Project object at 0x7f3104029460>

  File "/home/users/Scy/yuqing/spider/monitor/projectManager.py", line 421, in update_device_valid
    self.database_manager.mysql.update(Device(**device.to_item()))
    │    │                │     │      │        │      └ <function DeviceC.to_item at 0x7f31f34ed310>
    │    │                │     │      │        └ <monitor.deviceManager.DeviceC object at 0x7f3104029220>
    │    │                │     │      └ <class 'base.db.mysql.Device'>
    │    │                │     └ <function Mysql.update at 0x7f31f35f4790>
    │    │                └ <base.db.mysql.Mysql object at 0x7f3103ffdfd0>
    │    └ <base.db.dbSlot.Slot object at 0x7f3103ffdf10>
    └ <monitor.projectManager.Project object at 0x7f3104029460>

> File "/home/users/Scy/yuqing/spider/base/db/mysql.py", line 375, in update
    row.update(new)
    │   │      └ {'server_id': '180.201.163.246:6800', 'ip': '180.201.163.246', 'username': 'chase', 'password': '9872715928751043839610636921...
    │   └ <function Query.update at 0x7f31f37333a0>
    └ <sqlalchemy.orm.query.Query object at 0x7f3038280610>

  File "/home/chase/.local/lib/python3.8/site-packages/sqlalchemy/orm/query.py", line 3221, in update
    result = self.session.execute(
             │    │       └ <function Session.execute at 0x7f31f370faf0>
             │    └ <sqlalchemy.orm.session.Session object at 0x7f30382800a0>
             └ <sqlalchemy.orm.query.Query object at 0x7f3038280610>
  File "/home/chase/.local/lib/python3.8/site-packages/sqlalchemy/orm/session.py", line 1689, in execute
    result = conn._execute_20(statement, params or {}, execution_options)
             │    │           │          │             └ immutabledict({'synchronize_session': 'evaluate', '_sa_orm_update_options': default_update_options(_matched_objects=[], _reso...
             │    │           │          └ immutabledict({})
             │    │           └ <sqlalchemy.sql.annotation.AnnotatedUpdate object at 0x7f305842a4f0>
             │    └ <function Connection._execute_20 at 0x7f31f39bc790>
             └ <sqlalchemy.engine.base.Connection object at 0x7f2de9a399a0>
  File "/home/chase/.local/lib/python3.8/site-packages/sqlalchemy/engine/base.py", line 1583, in _execute_20
    return meth(self, args_10style, kwargs_10style, execution_options)
           │    │     │             │               └ immutabledict({'synchronize_session': 'evaluate', '_sa_orm_update_options': default_update_options(_matched_objects=[], _reso...
           │    │     │             └ immutabledict({})
           │    │     └ ({},)
           │    └ <sqlalchemy.engine.base.Connection object at 0x7f2de9a399a0>
           └ <bound method ClauseElement._execute_on_connection of <sqlalchemy.sql.annotation.AnnotatedUpdate object at 0x7f305842a4f0>>
  File "/home/chase/.local/lib/python3.8/site-packages/sqlalchemy/sql/elements.py", line 323, in _execute_on_connection
    return connection._execute_clauseelement(
           │          └ <function Connection._execute_clauseelement at 0x7f31f39bc5e0>
           └ <sqlalchemy.engine.base.Connection object at 0x7f2de9a399a0>
  File "/home/chase/.local/lib/python3.8/site-packages/sqlalchemy/engine/base.py", line 1452, in _execute_clauseelement
    ret = self._execute_context(
          │    └ <function Connection._execute_context at 0x7f31f39bc8b0>
          └ <sqlalchemy.engine.base.Connection object at 0x7f2de9a399a0>
  File "/home/chase/.local/lib/python3.8/site-packages/sqlalchemy/engine/base.py", line 1814, in _execute_context
    self._handle_dbapi_exception(
    │    └ <function Connection._handle_dbapi_exception at 0x7f31f39bca60>
    └ <sqlalchemy.engine.base.Connection object at 0x7f2de9a399a0>
  File "/home/chase/.local/lib/python3.8/site-packages/sqlalchemy/engine/base.py", line 1995, in _handle_dbapi_exception
    util.raise_(
    │    └ <function raise_ at 0x7f31f3d7ea60>
    └ <module 'sqlalchemy.util' from '/home/chase/.local/lib/python3.8/site-packages/sqlalchemy/util/__init__.py'>
  File "/home/chase/.local/lib/python3.8/site-packages/sqlalchemy/util/compat.py", line 207, in raise_
    raise exception
  File "/home/chase/.local/lib/python3.8/site-packages/sqlalchemy/engine/base.py", line 1771, in _execute_context
    self.dialect.do_execute(
    │    │       └ <function DefaultDialect.do_execute at 0x7f31f38f75e0>
    │    └ <sqlalchemy.dialects.mysql.pymysql.MySQLDialect_pymysql object at 0x7f3103ffde20>
    └ <sqlalchemy.engine.base.Connection object at 0x7f2de9a399a0>
  File "/home/chase/.local/lib/python3.8/site-packages/sqlalchemy/engine/default.py", line 717, in do_execute
    cursor.execute(statement, parameters)
    │      │       │          └ {'server_id': '180.201.163.246:6800', 'ip': '180.201.163.246', 'username': 'chase', 'password': '9872715928751043839610636921...
    │      │       └ 'UPDATE device SET server_id=%(server_id)s, ip=%(ip)s, username=%(username)s, password=%(password)s, address=%(address)s, por...
    │      └ <function Cursor.execute at 0x7f31f354cdc0>
    └ <pymysql.cursors.Cursor object at 0x7f3100245bb0>
  File "/home/chase/.local/lib/python3.8/site-packages/pymysql/cursors.py", line 148, in execute
    result = self._query(query)
             │    │      └ "UPDATE device SET server_id='180.201.163.246:6800', ip='180.201.163.246', username='chase', password='9872715928751043839610...
             │    └ <function Cursor._query at 0x7f31f34d7280>
             └ <pymysql.cursors.Cursor object at 0x7f3100245bb0>
  File "/home/chase/.local/lib/python3.8/site-packages/pymysql/cursors.py", line 310, in _query
    conn.query(q)
    │    │     └ "UPDATE device SET server_id='180.201.163.246:6800', ip='180.201.163.246', username='chase', password='9872715928751043839610...
    │    └ <function Connection.query at 0x7f31f34e5670>
    └ <pymysql.connections.Connection object at 0x7f30b87dfa90>
  File "/home/chase/.local/lib/python3.8/site-packages/pymysql/connections.py", line 548, in query
    self._affected_rows = self._read_query_result(unbuffered=unbuffered)
    │    │                │    │                             └ False
    │    │                │    └ <function Connection._read_query_result at 0x7f31f34e5ca0>
    │    │                └ <pymysql.connections.Connection object at 0x7f30b87dfa90>
    │    └ 1
    └ <pymysql.connections.Connection object at 0x7f30b87dfa90>
  File "/home/chase/.local/lib/python3.8/site-packages/pymysql/connections.py", line 775, in _read_query_result
    result.read()
    │      └ <function MySQLResult.read at 0x7f31f34e64c0>
    └ <pymysql.connections.MySQLResult object at 0x7f2f780a2610>
  File "/home/chase/.local/lib/python3.8/site-packages/pymysql/connections.py", line 1156, in read
    first_packet = self.connection._read_packet()
                   │    └ None
                   └ <pymysql.connections.MySQLResult object at 0x7f2f780a2610>
  File "/home/chase/.local/lib/python3.8/site-packages/pymysql/connections.py", line 725, in _read_packet
    packet.raise_for_error()
    │      └ <function MysqlPacket.raise_for_error at 0x7f31f34ddee0>
    └ <pymysql.protocol.MysqlPacket object at 0x7f2f78641790>
  File "/home/chase/.local/lib/python3.8/site-packages/pymysql/protocol.py", line 221, in raise_for_error
    err.raise_mysql_exception(self._data)
    │   │                     │    └ <member '_data' of 'MysqlPacket' objects>
    │   │                     └ <pymysql.protocol.MysqlPacket object at 0x7f2f78641790>
    │   └ <function raise_mysql_exception at 0x7f31f358c670>
    └ <module 'pymysql.err' from '/home/chase/.local/lib/python3.8/site-packages/pymysql/err.py'>
  File "/home/chase/.local/lib/python3.8/site-packages/pymysql/err.py", line 143, in raise_mysql_exception
    raise errorclass(errno, errval)
          │          │      └ "Duplicate entry '180.201.163.246:6800' for key 'device.PRIMARY'"
          │          └ 1062
          └ <class 'pymysql.err.IntegrityError'>

sqlalchemy.exc.IntegrityError: (pymysql.err.IntegrityError) (1062, "Duplicate entry '180.201.163.246:6800' for key 'device.PRIMARY'")
[SQL: UPDATE device SET server_id=%(server_id)s, ip=%(ip)s, username=%(username)s, password=%(password)s, address=%(address)s, port=%(port)s, valid=%(valid)s WHERE device.ip = %(ip_1)s]
[parameters: {'server_id': '180.201.163.246:6800', 'ip': '180.201.163.246', 'username': 'chase', 'password': '98727159287510438396106369212751339140023478666820533211800775612409395085350372034307834559120432059376264180499222264201080625605726331151316524425 ... (10 characters truncated) ... 43096507915290276030096693060531299598542474747380827069208618878331738109073390604852917658494201355569838301935313659074193822192701793050270618760', 'address': '/home/users/CT/pycharmproject/spiders/', 'port': 6800, 'valid': 1, 'ip_1': '180.201.163.246'}]
(Background on this error at: https://sqlalche.me/e/14/gkpj)
