2022-05-12 15:33:02.843 | ERROR    | monitor.searchSpiders.qinagguoLT:get_request_from_keyword:27 - E 强国论坛错误HTTPConnectionPool(host='bbs1.people.com.cn', port=80): Max retries exceeded with url: /board/1.html (Caused by NewConnectionError('<urllib3.connection.HTTPConnection object at 0x7f916011c940>: Failed to establish a new connection: [Errno 111] Connection refused'))
Traceback (most recent call last):

  File "/home/chase/.local/lib/python3.8/site-packages/urllib3/connection.py", line 174, in _new_conn
    conn = connection.create_connection(
           │          └ <function create_connection at 0x7f92585fd1f0>
           └ <module 'urllib3.util.connection' from '/home/chase/.local/lib/python3.8/site-packages/urllib3/util/connection.py'>
  File "/home/chase/.local/lib/python3.8/site-packages/urllib3/util/connection.py", line 96, in create_connection
    raise err
          └ ConnectionRefusedError(111, 'Connection refused')
  File "/home/chase/.local/lib/python3.8/site-packages/urllib3/util/connection.py", line 86, in create_connection
    sock.connect(sa)
    │            └ ('1.31.128.212', 80)
    └ None

ConnectionRefusedError: [Errno 111] Connection refused


During handling of the above exception, another exception occurred:


Traceback (most recent call last):

  File "/home/chase/.local/lib/python3.8/site-packages/urllib3/connectionpool.py", line 699, in urlopen
    httplib_response = self._make_request(
                       │    └ <function HTTPConnectionPool._make_request at 0x7f92585c05e0>
                       └ <urllib3.connectionpool.HTTPConnectionPool object at 0x7f9148797310>
  File "/home/chase/.local/lib/python3.8/site-packages/urllib3/connectionpool.py", line 394, in _make_request
    conn.request(method, url, **httplib_request_kw)
    │    │       │       │      └ {'body': None, 'headers': {'User-Agent': 'Mozilla/5.0 (X11; Linux x86_64) AppleWebKit/537.36 (KHTML, like Gecko) Chrome/93.0....
    │    │       │       └ '/board/1.html'
    │    │       └ 'GET'
    │    └ <function HTTPConnection.request at 0x7f92585b0f70>
    └ <urllib3.connection.HTTPConnection object at 0x7f916011c940>
  File "/home/chase/.local/lib/python3.8/site-packages/urllib3/connection.py", line 239, in request
    super(HTTPConnection, self).request(method, url, body=body, headers=headers)
          │               │             │       │         │             └ {'User-Agent': 'Mozilla/5.0 (X11; Linux x86_64) AppleWebKit/537.36 (KHTML, like Gecko) Chrome/93.0.4577.63 Safari/537.36', 'A...
          │               │             │       │         └ None
          │               │             │       └ '/board/1.html'
          │               │             └ 'GET'
          │               └ <urllib3.connection.HTTPConnection object at 0x7f916011c940>
          └ <class 'urllib3.connection.HTTPConnection'>
  File "/usr/lib/python3.8/http/client.py", line 1256, in request
    self._send_request(method, url, body, headers, encode_chunked)
    │    │             │       │    │     │        └ False
    │    │             │       │    │     └ {'User-Agent': 'Mozilla/5.0 (X11; Linux x86_64) AppleWebKit/537.36 (KHTML, like Gecko) Chrome/93.0.4577.63 Safari/537.36', 'A...
    │    │             │       │    └ None
    │    │             │       └ '/board/1.html'
    │    │             └ 'GET'
    │    └ <function HTTPConnection._send_request at 0x7f926be50280>
    └ <urllib3.connection.HTTPConnection object at 0x7f916011c940>
  File "/usr/lib/python3.8/http/client.py", line 1302, in _send_request
    self.endheaders(body, encode_chunked=encode_chunked)
    │    │          │                    └ False
    │    │          └ None
    │    └ <function HTTPConnection.endheaders at 0x7f926be50160>
    └ <urllib3.connection.HTTPConnection object at 0x7f916011c940>
  File "/usr/lib/python3.8/http/client.py", line 1251, in endheaders
    self._send_output(message_body, encode_chunked=encode_chunked)
    │    │            │                            └ False
    │    │            └ None
    │    └ <function HTTPConnection._send_output at 0x7f926beb7d30>
    └ <urllib3.connection.HTTPConnection object at 0x7f916011c940>
  File "/usr/lib/python3.8/http/client.py", line 1011, in _send_output
    self.send(msg)
    │    │    └ b'GET /board/1.html HTTP/1.1\r\nHost: bbs1.people.com.cn\r\nUser-Agent: Mozilla/5.0 (X11; Linux x86_64) AppleWebKit/537.36 (K...
    │    └ <function HTTPConnection.send at 0x7f926beb7b80>
    └ <urllib3.connection.HTTPConnection object at 0x7f916011c940>
  File "/usr/lib/python3.8/http/client.py", line 951, in send
    self.connect()
    │    └ <function HTTPConnection.connect at 0x7f92585b0dc0>
    └ <urllib3.connection.HTTPConnection object at 0x7f916011c940>
  File "/home/chase/.local/lib/python3.8/site-packages/urllib3/connection.py", line 205, in connect
    conn = self._new_conn()
           │    └ <function HTTPConnection._new_conn at 0x7f92585b0c10>
           └ <urllib3.connection.HTTPConnection object at 0x7f916011c940>
  File "/home/chase/.local/lib/python3.8/site-packages/urllib3/connection.py", line 186, in _new_conn
    raise NewConnectionError(
          └ <class 'urllib3.exceptions.NewConnectionError'>

urllib3.exceptions.NewConnectionError: <urllib3.connection.HTTPConnection object at 0x7f916011c940>: Failed to establish a new connection: [Errno 111] Connection refused


During handling of the above exception, another exception occurred:


Traceback (most recent call last):

  File "/home/chase/.local/lib/python3.8/site-packages/requests/adapters.py", line 439, in send
    resp = conn.urlopen(
           │    └ <function HTTPConnectionPool.urlopen at 0x7f92585c0820>
           └ <urllib3.connectionpool.HTTPConnectionPool object at 0x7f9148797310>
  File "/home/chase/.local/lib/python3.8/site-packages/urllib3/connectionpool.py", line 755, in urlopen
    retries = retries.increment(
              │       └ <function Retry.increment at 0x7f9258608b80>
              └ Retry(total=0, connect=None, read=False, redirect=None, status=None)
  File "/home/chase/.local/lib/python3.8/site-packages/urllib3/util/retry.py", line 574, in increment
    raise MaxRetryError(_pool, url, error or ResponseError(cause))
          │             │      │    │        │             └ 'unknown'
          │             │      │    │        └ <class 'urllib3.exceptions.ResponseError'>
          │             │      │    └ NewConnectionError('<urllib3.connection.HTTPConnection object at 0x7f916011c940>: Failed to establish a new connection: [Errn...
          │             │      └ '/board/1.html'
          │             └ <urllib3.connectionpool.HTTPConnectionPool object at 0x7f9148797310>
          └ <class 'urllib3.exceptions.MaxRetryError'>

urllib3.exceptions.MaxRetryError: HTTPConnectionPool(host='bbs1.people.com.cn', port=80): Max retries exceeded with url: /board/1.html (Caused by NewConnectionError('<urllib3.connection.HTTPConnection object at 0x7f916011c940>: Failed to establish a new connection: [Errno 111] Connection refused'))


During handling of the above exception, another exception occurred:


Traceback (most recent call last):

  File "/usr/lib/python3.8/threading.py", line 890, in _bootstrap
    self._bootstrap_inner()
    │    └ <function Thread._bootstrap_inner at 0x7f927a614a60>
    └ <Thread(Thread-42, started daemon 140261980088064)>
  File "/usr/lib/python3.8/threading.py", line 932, in _bootstrap_inner
    self.run()
    │    └ <function Thread.run at 0x7f927a614790>
    └ <Thread(Thread-42, started daemon 140261980088064)>
  File "/usr/lib/python3.8/threading.py", line 870, in run
    self._target(*self._args, **self._kwargs)
    │    │        │    │        │    └ {}
    │    │        │    │        └ <Thread(Thread-42, started daemon 140261980088064)>
    │    │        │    └ ('ProjectManager.run_func_by_thread',)
    │    │        └ <Thread(Thread-42, started daemon 140261980088064)>
    │    └ <bound method ProjectManager.get_request_from_keywords_hot of <monitor.projectManager.ProjectManager object at 0x7f9162af4700>>
    └ <Thread(Thread-42, started daemon 140261980088064)>

  File "/home/users/Scy/yuqing/spider/monitor/projectManager.py", line 795, in get_request_from_keywords_hot
    self.search_spider_manager.crawl_by_keyword(
    │    │                     └ <function SearchSpidersManager.crawl_by_keyword at 0x7f9162b00040>
    │    └ <monitor.spiderManager.SearchSpidersManager object at 0x7f916270f0d0>
    └ <monitor.projectManager.ProjectManager object at 0x7f9162af4700>

  File "/home/users/Scy/yuqing/spider/monitor/spiderManager.py", line 118, in crawl_by_keyword
    self.crawl_by_keyword_signal_platform(project_names, platform, keyword, crawl_time, project_times)
    │    │                                │              │         │        │           └ {'default': <monitor.TimeSection object at 0x7f91628317f0>}
    │    │                                │              │         │        └ <monitor.TimeSection object at 0x7f91603ec070>
    │    │                                │              │         └ '第78集团军某旅：“伴随保障”强化战场意识'
    │    │                                │              └ '强国论坛'
    │    │                                └ ['default']
    │    └ <function SearchSpidersManager.crawl_by_keyword_signal_platform at 0x7f9162b000d0>
    └ <monitor.spiderManager.SearchSpidersManager object at 0x7f916270f0d0>

  File "/home/users/Scy/yuqing/spider/monitor/spiderManager.py", line 134, in crawl_by_keyword_signal_platform
    requests = self.get_request_from_keyword(platform, keyword, **crawl_time.to_dict())
               │    │                        │         │          │          └ <function TimeSection.to_dict at 0x7f925aaa8550>
               │    │                        │         │          └ <monitor.TimeSection object at 0x7f91603ec070>
               │    │                        │         └ '第78集团军某旅：“伴随保障”强化战场意识'
               │    │                        └ '强国论坛'
               │    └ <function SearchSpidersManager.get_request_from_keyword at 0x7f9162b001f0>
               └ <monitor.spiderManager.SearchSpidersManager object at 0x7f916270f0d0>

  File "/home/users/Scy/yuqing/spider/monitor/spiderManager.py", line 191, in get_request_from_keyword
    for request in self.spiders[platform].get_request_from_keyword(headers, search_url, keyword, content_url,
                   │    │       │                                  │        │           │        └ <string.Template object at 0x7f91601b4fa0>
                   │    │       │                                  │        │           └ '第78集团军某旅：“伴随保障”强化战场意识'
                   │    │       │                                  │        └ <string.Template object at 0x7f91601b4910>
                   │    │       │                                  └ {'Connection': 'keep-alive', 'Cache-Control': 'max-age=0', 'Upgrade-Insecure-Requests': '1', 'User-Agent': 'Mozilla/5.0 (X11;...
                   │    │       └ '强国论坛'
                   │    └ {'凤凰网': <monitor.searchSpiders.ifeng.Ifeng object at 0x7f916270f220>, '头条': <monitor.searchSpiders.toutiao.Toutiao object at ...
                   └ <monitor.spiderManager.SearchSpidersManager object at 0x7f916270f0d0>

> File "/home/users/Scy/yuqing/spider/monitor/searchSpiders/qinagguoLT.py", line 18, in get_request_from_keyword
    response = requests.get(search_url.substitute(), headers=headers)
               │        │   │          │                     └ {'Connection': 'keep-alive', 'Cache-Control': 'max-age=0', 'Upgrade-Insecure-Requests': '1', 'User-Agent': 'Mozilla/5.0 (X11;...
               │        │   │          └ <function Template.substitute at 0x7f927a5fd0d0>
               │        │   └ <string.Template object at 0x7f91601b4910>
               │        └ <function get at 0x7f92583e71f0>
               └ <module 'requests' from '/home/chase/.local/lib/python3.8/site-packages/requests/__init__.py'>

  File "/home/chase/.local/lib/python3.8/site-packages/requests/api.py", line 75, in get
    return request('get', url, params=params, **kwargs)
           │              │           │         └ {'headers': {'Connection': 'keep-alive', 'Cache-Control': 'max-age=0', 'Upgrade-Insecure-Requests': '1', 'User-Agent': 'Mozil...
           │              │           └ None
           │              └ 'http://bbs1.people.com.cn/board/1.html'
           └ <function request at 0x7f9258455040>
  File "/home/chase/.local/lib/python3.8/site-packages/requests/api.py", line 61, in request
    return session.request(method=method, url=url, **kwargs)
           │       │              │           │      └ {'params': None, 'headers': {'Connection': 'keep-alive', 'Cache-Control': 'max-age=0', 'Upgrade-Insecure-Requests': '1', 'Use...
           │       │              │           └ 'http://bbs1.people.com.cn/board/1.html'
           │       │              └ 'get'
           │       └ <function Session.request at 0x7f92583e6940>
           └ <requests.sessions.Session object at 0x7f91626f8f40>
  File "/home/chase/.local/lib/python3.8/site-packages/requests/sessions.py", line 542, in request
    resp = self.send(prep, **send_kwargs)
           │    │    │       └ {'timeout': None, 'allow_redirects': True, 'verify': True, 'proxies': OrderedDict(), 'stream': False, 'cert': None}
           │    │    └ <PreparedRequest [GET]>
           │    └ <function Session.send at 0x7f92583e6dc0>
           └ <requests.sessions.Session object at 0x7f91626f8f40>
  File "/home/chase/.local/lib/python3.8/site-packages/requests/sessions.py", line 655, in send
    r = adapter.send(request, **kwargs)
        │       │    │          └ {'timeout': None, 'verify': True, 'proxies': OrderedDict(), 'stream': False, 'cert': None}
        │       │    └ <PreparedRequest [GET]>
        │       └ <function HTTPAdapter.send at 0x7f92583e6280>
        └ <requests.adapters.HTTPAdapter object at 0x7f91601b4dc0>
  File "/home/chase/.local/lib/python3.8/site-packages/requests/adapters.py", line 516, in send
    raise ConnectionError(e, request=request)
          │                          └ <PreparedRequest [GET]>
          └ <class 'requests.exceptions.ConnectionError'>

requests.exceptions.ConnectionError: HTTPConnectionPool(host='bbs1.people.com.cn', port=80): Max retries exceeded with url: /board/1.html (Caused by NewConnectionError('<urllib3.connection.HTTPConnection object at 0x7f916011c940>: Failed to establish a new connection: [Errno 111] Connection refused'))
2022-05-12 15:33:02.857 | ERROR    | monitor.searchSpiders.qinagguoLT:get_request_from_keyword:27 - E 强国论坛错误HTTPConnectionPool(host='bbs1.people.com.cn', port=80): Max retries exceeded with url: /board/1.html (Caused by NewConnectionError('<urllib3.connection.HTTPConnection object at 0x7f91486b7760>: Failed to establish a new connection: [Errno 111] Connection refused'))
Traceback (most recent call last):

  File "/home/chase/.local/lib/python3.8/site-packages/urllib3/connection.py", line 174, in _new_conn
    conn = connection.create_connection(
           │          └ <function create_connection at 0x7f92585fd1f0>
           └ <module 'urllib3.util.connection' from '/home/chase/.local/lib/python3.8/site-packages/urllib3/util/connection.py'>
  File "/home/chase/.local/lib/python3.8/site-packages/urllib3/util/connection.py", line 96, in create_connection
    raise err
          └ ConnectionRefusedError(111, 'Connection refused')
  File "/home/chase/.local/lib/python3.8/site-packages/urllib3/util/connection.py", line 86, in create_connection
    sock.connect(sa)
    │            └ ('1.31.128.212', 80)
    └ None

ConnectionRefusedError: [Errno 111] Connection refused


During handling of the above exception, another exception occurred:


Traceback (most recent call last):

  File "/home/chase/.local/lib/python3.8/site-packages/urllib3/connectionpool.py", line 699, in urlopen
    httplib_response = self._make_request(
                       │    └ <function HTTPConnectionPool._make_request at 0x7f92585c05e0>
                       └ <urllib3.connectionpool.HTTPConnectionPool object at 0x7f914863c130>
  File "/home/chase/.local/lib/python3.8/site-packages/urllib3/connectionpool.py", line 394, in _make_request
    conn.request(method, url, **httplib_request_kw)
    │    │       │       │      └ {'body': None, 'headers': {'User-Agent': 'Mozilla/5.0 (X11; Linux x86_64) AppleWebKit/537.36 (KHTML, like Gecko) Chrome/93.0....
    │    │       │       └ '/board/1.html'
    │    │       └ 'GET'
    │    └ <function HTTPConnection.request at 0x7f92585b0f70>
    └ <urllib3.connection.HTTPConnection object at 0x7f91486b7760>
  File "/home/chase/.local/lib/python3.8/site-packages/urllib3/connection.py", line 239, in request
    super(HTTPConnection, self).request(method, url, body=body, headers=headers)
          │               │             │       │         │             └ {'User-Agent': 'Mozilla/5.0 (X11; Linux x86_64) AppleWebKit/537.36 (KHTML, like Gecko) Chrome/93.0.4577.63 Safari/537.36', 'A...
          │               │             │       │         └ None
          │               │             │       └ '/board/1.html'
          │               │             └ 'GET'
          │               └ <urllib3.connection.HTTPConnection object at 0x7f91486b7760>
          └ <class 'urllib3.connection.HTTPConnection'>
  File "/usr/lib/python3.8/http/client.py", line 1256, in request
    self._send_request(method, url, body, headers, encode_chunked)
    │    │             │       │    │     │        └ False
    │    │             │       │    │     └ {'User-Agent': 'Mozilla/5.0 (X11; Linux x86_64) AppleWebKit/537.36 (KHTML, like Gecko) Chrome/93.0.4577.63 Safari/537.36', 'A...
    │    │             │       │    └ None
    │    │             │       └ '/board/1.html'
    │    │             └ 'GET'
    │    └ <function HTTPConnection._send_request at 0x7f926be50280>
    └ <urllib3.connection.HTTPConnection object at 0x7f91486b7760>
  File "/usr/lib/python3.8/http/client.py", line 1302, in _send_request
    self.endheaders(body, encode_chunked=encode_chunked)
    │    │          │                    └ False
    │    │          └ None
    │    └ <function HTTPConnection.endheaders at 0x7f926be50160>
    └ <urllib3.connection.HTTPConnection object at 0x7f91486b7760>
  File "/usr/lib/python3.8/http/client.py", line 1251, in endheaders
    self._send_output(message_body, encode_chunked=encode_chunked)
    │    │            │                            └ False
    │    │            └ None
    │    └ <function HTTPConnection._send_output at 0x7f926beb7d30>
    └ <urllib3.connection.HTTPConnection object at 0x7f91486b7760>
  File "/usr/lib/python3.8/http/client.py", line 1011, in _send_output
    self.send(msg)
    │    │    └ b'GET /board/1.html HTTP/1.1\r\nHost: bbs1.people.com.cn\r\nUser-Agent: Mozilla/5.0 (X11; Linux x86_64) AppleWebKit/537.36 (K...
    │    └ <function HTTPConnection.send at 0x7f926beb7b80>
    └ <urllib3.connection.HTTPConnection object at 0x7f91486b7760>
  File "/usr/lib/python3.8/http/client.py", line 951, in send
    self.connect()
    │    └ <function HTTPConnection.connect at 0x7f92585b0dc0>
    └ <urllib3.connection.HTTPConnection object at 0x7f91486b7760>
  File "/home/chase/.local/lib/python3.8/site-packages/urllib3/connection.py", line 205, in connect
    conn = self._new_conn()
           │    └ <function HTTPConnection._new_conn at 0x7f92585b0c10>
           └ <urllib3.connection.HTTPConnection object at 0x7f91486b7760>
  File "/home/chase/.local/lib/python3.8/site-packages/urllib3/connection.py", line 186, in _new_conn
    raise NewConnectionError(
          └ <class 'urllib3.exceptions.NewConnectionError'>

urllib3.exceptions.NewConnectionError: <urllib3.connection.HTTPConnection object at 0x7f91486b7760>: Failed to establish a new connection: [Errno 111] Connection refused


During handling of the above exception, another exception occurred:


Traceback (most recent call last):

  File "/home/chase/.local/lib/python3.8/site-packages/requests/adapters.py", line 439, in send
    resp = conn.urlopen(
           │    └ <function HTTPConnectionPool.urlopen at 0x7f92585c0820>
           └ <urllib3.connectionpool.HTTPConnectionPool object at 0x7f914863c130>
  File "/home/chase/.local/lib/python3.8/site-packages/urllib3/connectionpool.py", line 755, in urlopen
    retries = retries.increment(
              │       └ <function Retry.increment at 0x7f9258608b80>
              └ Retry(total=0, connect=None, read=False, redirect=None, status=None)
  File "/home/chase/.local/lib/python3.8/site-packages/urllib3/util/retry.py", line 574, in increment
    raise MaxRetryError(_pool, url, error or ResponseError(cause))
          │             │      │    │        │             └ 'unknown'
          │             │      │    │        └ <class 'urllib3.exceptions.ResponseError'>
          │             │      │    └ NewConnectionError('<urllib3.connection.HTTPConnection object at 0x7f91486b7760>: Failed to establish a new connection: [Errn...
          │             │      └ '/board/1.html'
          │             └ <urllib3.connectionpool.HTTPConnectionPool object at 0x7f914863c130>
          └ <class 'urllib3.exceptions.MaxRetryError'>

urllib3.exceptions.MaxRetryError: HTTPConnectionPool(host='bbs1.people.com.cn', port=80): Max retries exceeded with url: /board/1.html (Caused by NewConnectionError('<urllib3.connection.HTTPConnection object at 0x7f91486b7760>: Failed to establish a new connection: [Errno 111] Connection refused'))


During handling of the above exception, another exception occurred:


Traceback (most recent call last):

  File "/usr/lib/python3.8/threading.py", line 890, in _bootstrap
    self._bootstrap_inner()
    │    └ <function Thread._bootstrap_inner at 0x7f927a614a60>
    └ <Thread(Thread-26, started daemon 140262005266176)>
  File "/usr/lib/python3.8/threading.py", line 932, in _bootstrap_inner
    self.run()
    │    └ <function Thread.run at 0x7f927a614790>
    └ <Thread(Thread-26, started daemon 140262005266176)>
  File "/usr/lib/python3.8/threading.py", line 870, in run
    self._target(*self._args, **self._kwargs)
    │    │        │    │        │    └ {}
    │    │        │    │        └ <Thread(Thread-26, started daemon 140262005266176)>
    │    │        │    └ ('ProjectManager.run_func_by_thread',)
    │    │        └ <Thread(Thread-26, started daemon 140262005266176)>
    │    └ <bound method ProjectManager.get_request_from_keywords_hot of <monitor.projectManager.ProjectManager object at 0x7f9162af4700>>
    └ <Thread(Thread-26, started daemon 140262005266176)>

  File "/home/users/Scy/yuqing/spider/monitor/projectManager.py", line 795, in get_request_from_keywords_hot
    self.search_spider_manager.crawl_by_keyword(
    │    │                     └ <function SearchSpidersManager.crawl_by_keyword at 0x7f9162b00040>
    │    └ <monitor.spiderManager.SearchSpidersManager object at 0x7f916270f0d0>
    └ <monitor.projectManager.ProjectManager object at 0x7f9162af4700>

  File "/home/users/Scy/yuqing/spider/monitor/spiderManager.py", line 118, in crawl_by_keyword
    self.crawl_by_keyword_signal_platform(project_names, platform, keyword, crawl_time, project_times)
    │    │                                │              │         │        │           └ {'default': <monitor.TimeSection object at 0x7f91628317f0>}
    │    │                                │              │         │        └ <monitor.TimeSection object at 0x7f916047e6a0>
    │    │                                │              │         └ '第78集团军某旅：“伴随保障”强化战场意识'
    │    │                                │              └ '强国论坛'
    │    │                                └ ['default']
    │    └ <function SearchSpidersManager.crawl_by_keyword_signal_platform at 0x7f9162b000d0>
    └ <monitor.spiderManager.SearchSpidersManager object at 0x7f916270f0d0>

  File "/home/users/Scy/yuqing/spider/monitor/spiderManager.py", line 134, in crawl_by_keyword_signal_platform
    requests = self.get_request_from_keyword(platform, keyword, **crawl_time.to_dict())
               │    │                        │         │          │          └ <function TimeSection.to_dict at 0x7f925aaa8550>
               │    │                        │         │          └ <monitor.TimeSection object at 0x7f916047e6a0>
               │    │                        │         └ '第78集团军某旅：“伴随保障”强化战场意识'
               │    │                        └ '强国论坛'
               │    └ <function SearchSpidersManager.get_request_from_keyword at 0x7f9162b001f0>
               └ <monitor.spiderManager.SearchSpidersManager object at 0x7f916270f0d0>

  File "/home/users/Scy/yuqing/spider/monitor/spiderManager.py", line 191, in get_request_from_keyword
    for request in self.spiders[platform].get_request_from_keyword(headers, search_url, keyword, content_url,
                   │    │       │                                  │        │           │        └ <string.Template object at 0x7f9160453df0>
                   │    │       │                                  │        │           └ '第78集团军某旅：“伴随保障”强化战场意识'
                   │    │       │                                  │        └ <string.Template object at 0x7f9160453ca0>
                   │    │       │                                  └ {'Connection': 'keep-alive', 'Cache-Control': 'max-age=0', 'Upgrade-Insecure-Requests': '1', 'User-Agent': 'Mozilla/5.0 (X11;...
                   │    │       └ '强国论坛'
                   │    └ {'凤凰网': <monitor.searchSpiders.ifeng.Ifeng object at 0x7f916270f220>, '头条': <monitor.searchSpiders.toutiao.Toutiao object at ...
                   └ <monitor.spiderManager.SearchSpidersManager object at 0x7f916270f0d0>

> File "/home/users/Scy/yuqing/spider/monitor/searchSpiders/qinagguoLT.py", line 18, in get_request_from_keyword
    response = requests.get(search_url.substitute(), headers=headers)
               │        │   │          │                     └ {'Connection': 'keep-alive', 'Cache-Control': 'max-age=0', 'Upgrade-Insecure-Requests': '1', 'User-Agent': 'Mozilla/5.0 (X11;...
               │        │   │          └ <function Template.substitute at 0x7f927a5fd0d0>
               │        │   └ <string.Template object at 0x7f9160453ca0>
               │        └ <function get at 0x7f92583e71f0>
               └ <module 'requests' from '/home/chase/.local/lib/python3.8/site-packages/requests/__init__.py'>

  File "/home/chase/.local/lib/python3.8/site-packages/requests/api.py", line 75, in get
    return request('get', url, params=params, **kwargs)
           │              │           │         └ {'headers': {'Connection': 'keep-alive', 'Cache-Control': 'max-age=0', 'Upgrade-Insecure-Requests': '1', 'User-Agent': 'Mozil...
           │              │           └ None
           │              └ 'http://bbs1.people.com.cn/board/1.html'
           └ <function request at 0x7f9258455040>
  File "/home/chase/.local/lib/python3.8/site-packages/requests/api.py", line 61, in request
    return session.request(method=method, url=url, **kwargs)
           │       │              │           │      └ {'params': None, 'headers': {'Connection': 'keep-alive', 'Cache-Control': 'max-age=0', 'Upgrade-Insecure-Requests': '1', 'Use...
           │       │              │           └ 'http://bbs1.people.com.cn/board/1.html'
           │       │              └ 'get'
           │       └ <function Session.request at 0x7f92583e6940>
           └ <requests.sessions.Session object at 0x7f91600dcaf0>
  File "/home/chase/.local/lib/python3.8/site-packages/requests/sessions.py", line 542, in request
    resp = self.send(prep, **send_kwargs)
           │    │    │       └ {'timeout': None, 'allow_redirects': True, 'verify': True, 'proxies': OrderedDict(), 'stream': False, 'cert': None}
           │    │    └ <PreparedRequest [GET]>
           │    └ <function Session.send at 0x7f92583e6dc0>
           └ <requests.sessions.Session object at 0x7f91600dcaf0>
  File "/home/chase/.local/lib/python3.8/site-packages/requests/sessions.py", line 655, in send
    r = adapter.send(request, **kwargs)
        │       │    │          └ {'timeout': None, 'verify': True, 'proxies': OrderedDict(), 'stream': False, 'cert': None}
        │       │    └ <PreparedRequest [GET]>
        │       └ <function HTTPAdapter.send at 0x7f92583e6280>
        └ <requests.adapters.HTTPAdapter object at 0x7f916062e730>
  File "/home/chase/.local/lib/python3.8/site-packages/requests/adapters.py", line 516, in send
    raise ConnectionError(e, request=request)
          │                          └ <PreparedRequest [GET]>
          └ <class 'requests.exceptions.ConnectionError'>

requests.exceptions.ConnectionError: HTTPConnectionPool(host='bbs1.people.com.cn', port=80): Max retries exceeded with url: /board/1.html (Caused by NewConnectionError('<urllib3.connection.HTTPConnection object at 0x7f91486b7760>: Failed to establish a new connection: [Errno 111] Connection refused'))
2022-05-12 15:33:02.927 | ERROR    | monitor.searchSpiders.qinagguoLT:get_request_from_keyword:27 - E 强国论坛错误HTTPConnectionPool(host='bbs1.people.com.cn', port=80): Max retries exceeded with url: /board/1.html (Caused by NewConnectionError('<urllib3.connection.HTTPConnection object at 0x7f9148736cd0>: Failed to establish a new connection: [Errno 111] Connection refused'))
Traceback (most recent call last):

  File "/home/chase/.local/lib/python3.8/site-packages/urllib3/connection.py", line 174, in _new_conn
    conn = connection.create_connection(
           │          └ <function create_connection at 0x7f92585fd1f0>
           └ <module 'urllib3.util.connection' from '/home/chase/.local/lib/python3.8/site-packages/urllib3/util/connection.py'>
  File "/home/chase/.local/lib/python3.8/site-packages/urllib3/util/connection.py", line 96, in create_connection
    raise err
          └ ConnectionRefusedError(111, 'Connection refused')
  File "/home/chase/.local/lib/python3.8/site-packages/urllib3/util/connection.py", line 86, in create_connection
    sock.connect(sa)
    │            └ ('1.31.128.212', 80)
    └ None

ConnectionRefusedError: [Errno 111] Connection refused


During handling of the above exception, another exception occurred:


Traceback (most recent call last):

  File "/home/chase/.local/lib/python3.8/site-packages/urllib3/connectionpool.py", line 699, in urlopen
    httplib_response = self._make_request(
                       │    └ <function HTTPConnectionPool._make_request at 0x7f92585c05e0>
                       └ <urllib3.connectionpool.HTTPConnectionPool object at 0x7f91606251c0>
  File "/home/chase/.local/lib/python3.8/site-packages/urllib3/connectionpool.py", line 394, in _make_request
    conn.request(method, url, **httplib_request_kw)
    │    │       │       │      └ {'body': None, 'headers': {'User-Agent': 'Mozilla/5.0 (X11; Linux x86_64) AppleWebKit/537.36 (KHTML, like Gecko) Chrome/93.0....
    │    │       │       └ '/board/1.html'
    │    │       └ 'GET'
    │    └ <function HTTPConnection.request at 0x7f92585b0f70>
    └ <urllib3.connection.HTTPConnection object at 0x7f9148736cd0>
  File "/home/chase/.local/lib/python3.8/site-packages/urllib3/connection.py", line 239, in request
    super(HTTPConnection, self).request(method, url, body=body, headers=headers)
          │               │             │       │         │             └ {'User-Agent': 'Mozilla/5.0 (X11; Linux x86_64) AppleWebKit/537.36 (KHTML, like Gecko) Chrome/93.0.4577.63 Safari/537.36', 'A...
          │               │             │       │         └ None
          │               │             │       └ '/board/1.html'
          │               │             └ 'GET'
          │               └ <urllib3.connection.HTTPConnection object at 0x7f9148736cd0>
          └ <class 'urllib3.connection.HTTPConnection'>
  File "/usr/lib/python3.8/http/client.py", line 1256, in request
    self._send_request(method, url, body, headers, encode_chunked)
    │    │             │       │    │     │        └ False
    │    │             │       │    │     └ {'User-Agent': 'Mozilla/5.0 (X11; Linux x86_64) AppleWebKit/537.36 (KHTML, like Gecko) Chrome/93.0.4577.63 Safari/537.36', 'A...
    │    │             │       │    └ None
    │    │             │       └ '/board/1.html'
    │    │             └ 'GET'
    │    └ <function HTTPConnection._send_request at 0x7f926be50280>
    └ <urllib3.connection.HTTPConnection object at 0x7f9148736cd0>
  File "/usr/lib/python3.8/http/client.py", line 1302, in _send_request
    self.endheaders(body, encode_chunked=encode_chunked)
    │    │          │                    └ False
    │    │          └ None
    │    └ <function HTTPConnection.endheaders at 0x7f926be50160>
    └ <urllib3.connection.HTTPConnection object at 0x7f9148736cd0>
  File "/usr/lib/python3.8/http/client.py", line 1251, in endheaders
    self._send_output(message_body, encode_chunked=encode_chunked)
    │    │            │                            └ False
    │    │            └ None
    │    └ <function HTTPConnection._send_output at 0x7f926beb7d30>
    └ <urllib3.connection.HTTPConnection object at 0x7f9148736cd0>
  File "/usr/lib/python3.8/http/client.py", line 1011, in _send_output
    self.send(msg)
    │    │    └ b'GET /board/1.html HTTP/1.1\r\nHost: bbs1.people.com.cn\r\nUser-Agent: Mozilla/5.0 (X11; Linux x86_64) AppleWebKit/537.36 (K...
    │    └ <function HTTPConnection.send at 0x7f926beb7b80>
    └ <urllib3.connection.HTTPConnection object at 0x7f9148736cd0>
  File "/usr/lib/python3.8/http/client.py", line 951, in send
    self.connect()
    │    └ <function HTTPConnection.connect at 0x7f92585b0dc0>
    └ <urllib3.connection.HTTPConnection object at 0x7f9148736cd0>
  File "/home/chase/.local/lib/python3.8/site-packages/urllib3/connection.py", line 205, in connect
    conn = self._new_conn()
           │    └ <function HTTPConnection._new_conn at 0x7f92585b0c10>
           └ <urllib3.connection.HTTPConnection object at 0x7f9148736cd0>
  File "/home/chase/.local/lib/python3.8/site-packages/urllib3/connection.py", line 186, in _new_conn
    raise NewConnectionError(
          └ <class 'urllib3.exceptions.NewConnectionError'>

urllib3.exceptions.NewConnectionError: <urllib3.connection.HTTPConnection object at 0x7f9148736cd0>: Failed to establish a new connection: [Errno 111] Connection refused


During handling of the above exception, another exception occurred:


Traceback (most recent call last):

  File "/home/chase/.local/lib/python3.8/site-packages/requests/adapters.py", line 439, in send
    resp = conn.urlopen(
           │    └ <function HTTPConnectionPool.urlopen at 0x7f92585c0820>
           └ <urllib3.connectionpool.HTTPConnectionPool object at 0x7f91606251c0>
  File "/home/chase/.local/lib/python3.8/site-packages/urllib3/connectionpool.py", line 755, in urlopen
    retries = retries.increment(
              │       └ <function Retry.increment at 0x7f9258608b80>
              └ Retry(total=0, connect=None, read=False, redirect=None, status=None)
  File "/home/chase/.local/lib/python3.8/site-packages/urllib3/util/retry.py", line 574, in increment
    raise MaxRetryError(_pool, url, error or ResponseError(cause))
          │             │      │    │        │             └ 'unknown'
          │             │      │    │        └ <class 'urllib3.exceptions.ResponseError'>
          │             │      │    └ NewConnectionError('<urllib3.connection.HTTPConnection object at 0x7f9148736cd0>: Failed to establish a new connection: [Errn...
          │             │      └ '/board/1.html'
          │             └ <urllib3.connectionpool.HTTPConnectionPool object at 0x7f91606251c0>
          └ <class 'urllib3.exceptions.MaxRetryError'>

urllib3.exceptions.MaxRetryError: HTTPConnectionPool(host='bbs1.people.com.cn', port=80): Max retries exceeded with url: /board/1.html (Caused by NewConnectionError('<urllib3.connection.HTTPConnection object at 0x7f9148736cd0>: Failed to establish a new connection: [Errno 111] Connection refused'))


During handling of the above exception, another exception occurred:


Traceback (most recent call last):

  File "/usr/lib/python3.8/threading.py", line 890, in _bootstrap
    self._bootstrap_inner()
    │    └ <function Thread._bootstrap_inner at 0x7f927a614a60>
    └ <Thread(Thread-65, started daemon 140261392893696)>
  File "/usr/lib/python3.8/threading.py", line 932, in _bootstrap_inner
    self.run()
    │    └ <function Thread.run at 0x7f927a614790>
    └ <Thread(Thread-65, started daemon 140261392893696)>
  File "/usr/lib/python3.8/threading.py", line 870, in run
    self._target(*self._args, **self._kwargs)
    │    │        │    │        │    └ {}
    │    │        │    │        └ <Thread(Thread-65, started daemon 140261392893696)>
    │    │        │    └ ('ProjectManager.run_func_by_thread',)
    │    │        └ <Thread(Thread-65, started daemon 140261392893696)>
    │    └ <bound method ProjectManager.get_request_from_keywords_hot of <monitor.projectManager.ProjectManager object at 0x7f9162af4700>>
    └ <Thread(Thread-65, started daemon 140261392893696)>

  File "/home/users/Scy/yuqing/spider/monitor/projectManager.py", line 795, in get_request_from_keywords_hot
    self.search_spider_manager.crawl_by_keyword(
    │    │                     └ <function SearchSpidersManager.crawl_by_keyword at 0x7f9162b00040>
    │    └ <monitor.spiderManager.SearchSpidersManager object at 0x7f916270f0d0>
    └ <monitor.projectManager.ProjectManager object at 0x7f9162af4700>

  File "/home/users/Scy/yuqing/spider/monitor/spiderManager.py", line 118, in crawl_by_keyword
    self.crawl_by_keyword_signal_platform(project_names, platform, keyword, crawl_time, project_times)
    │    │                                │              │         │        │           └ {'default': <monitor.TimeSection object at 0x7f91628317f0>}
    │    │                                │              │         │        └ <monitor.TimeSection object at 0x7f91601075e0>
    │    │                                │              │         └ '俄罗斯将举行纪念卫国战争胜利77周年的阅兵活动'
    │    │                                │              └ '强国论坛'
    │    │                                └ ['default']
    │    └ <function SearchSpidersManager.crawl_by_keyword_signal_platform at 0x7f9162b000d0>
    └ <monitor.spiderManager.SearchSpidersManager object at 0x7f916270f0d0>

  File "/home/users/Scy/yuqing/spider/monitor/spiderManager.py", line 134, in crawl_by_keyword_signal_platform
    requests = self.get_request_from_keyword(platform, keyword, **crawl_time.to_dict())
               │    │                        │         │          │          └ <function TimeSection.to_dict at 0x7f925aaa8550>
               │    │                        │         │          └ <monitor.TimeSection object at 0x7f91601075e0>
               │    │                        │         └ '俄罗斯将举行纪念卫国战争胜利77周年的阅兵活动'
               │    │                        └ '强国论坛'
               │    └ <function SearchSpidersManager.get_request_from_keyword at 0x7f9162b001f0>
               └ <monitor.spiderManager.SearchSpidersManager object at 0x7f916270f0d0>

  File "/home/users/Scy/yuqing/spider/monitor/spiderManager.py", line 191, in get_request_from_keyword
    for request in self.spiders[platform].get_request_from_keyword(headers, search_url, keyword, content_url,
                   │    │       │                                  │        │           │        └ <string.Template object at 0x7f9160453a60>
                   │    │       │                                  │        │           └ '俄罗斯将举行纪念卫国战争胜利77周年的阅兵活动'
                   │    │       │                                  │        └ <string.Template object at 0x7f916169aa60>
                   │    │       │                                  └ {'Connection': 'keep-alive', 'Cache-Control': 'max-age=0', 'Upgrade-Insecure-Requests': '1', 'User-Agent': 'Mozilla/5.0 (X11;...
                   │    │       └ '强国论坛'
                   │    └ {'凤凰网': <monitor.searchSpiders.ifeng.Ifeng object at 0x7f916270f220>, '头条': <monitor.searchSpiders.toutiao.Toutiao object at ...
                   └ <monitor.spiderManager.SearchSpidersManager object at 0x7f916270f0d0>

> File "/home/users/Scy/yuqing/spider/monitor/searchSpiders/qinagguoLT.py", line 18, in get_request_from_keyword
    response = requests.get(search_url.substitute(), headers=headers)
               │        │   │          │                     └ {'Connection': 'keep-alive', 'Cache-Control': 'max-age=0', 'Upgrade-Insecure-Requests': '1', 'User-Agent': 'Mozilla/5.0 (X11;...
               │        │   │          └ <function Template.substitute at 0x7f927a5fd0d0>
               │        │   └ <string.Template object at 0x7f916169aa60>
               │        └ <function get at 0x7f92583e71f0>
               └ <module 'requests' from '/home/chase/.local/lib/python3.8/site-packages/requests/__init__.py'>

  File "/home/chase/.local/lib/python3.8/site-packages/requests/api.py", line 75, in get
    return request('get', url, params=params, **kwargs)
           │              │           │         └ {'headers': {'Connection': 'keep-alive', 'Cache-Control': 'max-age=0', 'Upgrade-Insecure-Requests': '1', 'User-Agent': 'Mozil...
           │              │           └ None
           │              └ 'http://bbs1.people.com.cn/board/1.html'
           └ <function request at 0x7f9258455040>
  File "/home/chase/.local/lib/python3.8/site-packages/requests/api.py", line 61, in request
    return session.request(method=method, url=url, **kwargs)
           │       │              │           │      └ {'params': None, 'headers': {'Connection': 'keep-alive', 'Cache-Control': 'max-age=0', 'Upgrade-Insecure-Requests': '1', 'Use...
           │       │              │           └ 'http://bbs1.people.com.cn/board/1.html'
           │       │              └ 'get'
           │       └ <function Session.request at 0x7f92583e6940>
           └ <requests.sessions.Session object at 0x7f916169aaf0>
  File "/home/chase/.local/lib/python3.8/site-packages/requests/sessions.py", line 542, in request
    resp = self.send(prep, **send_kwargs)
           │    │    │       └ {'timeout': None, 'allow_redirects': True, 'verify': True, 'proxies': OrderedDict(), 'stream': False, 'cert': None}
           │    │    └ <PreparedRequest [GET]>
           │    └ <function Session.send at 0x7f92583e6dc0>
           └ <requests.sessions.Session object at 0x7f916169aaf0>
  File "/home/chase/.local/lib/python3.8/site-packages/requests/sessions.py", line 655, in send
    r = adapter.send(request, **kwargs)
        │       │    │          └ {'timeout': None, 'verify': True, 'proxies': OrderedDict(), 'stream': False, 'cert': None}
        │       │    └ <PreparedRequest [GET]>
        │       └ <function HTTPAdapter.send at 0x7f92583e6280>
        └ <requests.adapters.HTTPAdapter object at 0x7f91601dc190>
  File "/home/chase/.local/lib/python3.8/site-packages/requests/adapters.py", line 516, in send
    raise ConnectionError(e, request=request)
          │                          └ <PreparedRequest [GET]>
          └ <class 'requests.exceptions.ConnectionError'>

requests.exceptions.ConnectionError: HTTPConnectionPool(host='bbs1.people.com.cn', port=80): Max retries exceeded with url: /board/1.html (Caused by NewConnectionError('<urllib3.connection.HTTPConnection object at 0x7f9148736cd0>: Failed to establish a new connection: [Errno 111] Connection refused'))
2022-05-12 15:33:02.942 | ERROR    | monitor.searchSpiders.qinagguoLT:get_request_from_keyword:27 - E 强国论坛错误HTTPConnectionPool(host='bbs1.people.com.cn', port=80): Max retries exceeded with url: /board/1.html (Caused by NewConnectionError('<urllib3.connection.HTTPConnection object at 0x7f91604880d0>: Failed to establish a new connection: [Errno 111] Connection refused'))
Traceback (most recent call last):

  File "/home/chase/.local/lib/python3.8/site-packages/urllib3/connection.py", line 174, in _new_conn
    conn = connection.create_connection(
           │          └ <function create_connection at 0x7f92585fd1f0>
           └ <module 'urllib3.util.connection' from '/home/chase/.local/lib/python3.8/site-packages/urllib3/util/connection.py'>
  File "/home/chase/.local/lib/python3.8/site-packages/urllib3/util/connection.py", line 96, in create_connection
    raise err
          └ ConnectionRefusedError(111, 'Connection refused')
  File "/home/chase/.local/lib/python3.8/site-packages/urllib3/util/connection.py", line 86, in create_connection
    sock.connect(sa)
    │            └ ('1.31.128.212', 80)
    └ None

ConnectionRefusedError: [Errno 111] Connection refused


During handling of the above exception, another exception occurred:


Traceback (most recent call last):

  File "/home/chase/.local/lib/python3.8/site-packages/urllib3/connectionpool.py", line 699, in urlopen
    httplib_response = self._make_request(
                       │    └ <function HTTPConnectionPool._make_request at 0x7f92585c05e0>
                       └ <urllib3.connectionpool.HTTPConnectionPool object at 0x7f9160488730>
  File "/home/chase/.local/lib/python3.8/site-packages/urllib3/connectionpool.py", line 394, in _make_request
    conn.request(method, url, **httplib_request_kw)
    │    │       │       │      └ {'body': None, 'headers': {'User-Agent': 'Mozilla/5.0 (X11; Linux x86_64) AppleWebKit/537.36 (KHTML, like Gecko) Chrome/93.0....
    │    │       │       └ '/board/1.html'
    │    │       └ 'GET'
    │    └ <function HTTPConnection.request at 0x7f92585b0f70>
    └ <urllib3.connection.HTTPConnection object at 0x7f91604880d0>
  File "/home/chase/.local/lib/python3.8/site-packages/urllib3/connection.py", line 239, in request
    super(HTTPConnection, self).request(method, url, body=body, headers=headers)
          │               │             │       │         │             └ {'User-Agent': 'Mozilla/5.0 (X11; Linux x86_64) AppleWebKit/537.36 (KHTML, like Gecko) Chrome/93.0.4577.63 Safari/537.36', 'A...
          │               │             │       │         └ None
          │               │             │       └ '/board/1.html'
          │               │             └ 'GET'
          │               └ <urllib3.connection.HTTPConnection object at 0x7f91604880d0>
          └ <class 'urllib3.connection.HTTPConnection'>
  File "/usr/lib/python3.8/http/client.py", line 1256, in request
    self._send_request(method, url, body, headers, encode_chunked)
    │    │             │       │    │     │        └ False
    │    │             │       │    │     └ {'User-Agent': 'Mozilla/5.0 (X11; Linux x86_64) AppleWebKit/537.36 (KHTML, like Gecko) Chrome/93.0.4577.63 Safari/537.36', 'A...
    │    │             │       │    └ None
    │    │             │       └ '/board/1.html'
    │    │             └ 'GET'
    │    └ <function HTTPConnection._send_request at 0x7f926be50280>
    └ <urllib3.connection.HTTPConnection object at 0x7f91604880d0>
  File "/usr/lib/python3.8/http/client.py", line 1302, in _send_request
    self.endheaders(body, encode_chunked=encode_chunked)
    │    │          │                    └ False
    │    │          └ None
    │    └ <function HTTPConnection.endheaders at 0x7f926be50160>
    └ <urllib3.connection.HTTPConnection object at 0x7f91604880d0>
  File "/usr/lib/python3.8/http/client.py", line 1251, in endheaders
    self._send_output(message_body, encode_chunked=encode_chunked)
    │    │            │                            └ False
    │    │            └ None
    │    └ <function HTTPConnection._send_output at 0x7f926beb7d30>
    └ <urllib3.connection.HTTPConnection object at 0x7f91604880d0>
  File "/usr/lib/python3.8/http/client.py", line 1011, in _send_output
    self.send(msg)
    │    │    └ b'GET /board/1.html HTTP/1.1\r\nHost: bbs1.people.com.cn\r\nUser-Agent: Mozilla/5.0 (X11; Linux x86_64) AppleWebKit/537.36 (K...
    │    └ <function HTTPConnection.send at 0x7f926beb7b80>
    └ <urllib3.connection.HTTPConnection object at 0x7f91604880d0>
  File "/usr/lib/python3.8/http/client.py", line 951, in send
    self.connect()
    │    └ <function HTTPConnection.connect at 0x7f92585b0dc0>
    └ <urllib3.connection.HTTPConnection object at 0x7f91604880d0>
  File "/home/chase/.local/lib/python3.8/site-packages/urllib3/connection.py", line 205, in connect
    conn = self._new_conn()
           │    └ <function HTTPConnection._new_conn at 0x7f92585b0c10>
           └ <urllib3.connection.HTTPConnection object at 0x7f91604880d0>
  File "/home/chase/.local/lib/python3.8/site-packages/urllib3/connection.py", line 186, in _new_conn
    raise NewConnectionError(
          └ <class 'urllib3.exceptions.NewConnectionError'>

urllib3.exceptions.NewConnectionError: <urllib3.connection.HTTPConnection object at 0x7f91604880d0>: Failed to establish a new connection: [Errno 111] Connection refused


During handling of the above exception, another exception occurred:


Traceback (most recent call last):

  File "/home/chase/.local/lib/python3.8/site-packages/requests/adapters.py", line 439, in send
    resp = conn.urlopen(
           │    └ <function HTTPConnectionPool.urlopen at 0x7f92585c0820>
           └ <urllib3.connectionpool.HTTPConnectionPool object at 0x7f9160488730>
  File "/home/chase/.local/lib/python3.8/site-packages/urllib3/connectionpool.py", line 755, in urlopen
    retries = retries.increment(
              │       └ <function Retry.increment at 0x7f9258608b80>
              └ Retry(total=0, connect=None, read=False, redirect=None, status=None)
  File "/home/chase/.local/lib/python3.8/site-packages/urllib3/util/retry.py", line 574, in increment
    raise MaxRetryError(_pool, url, error or ResponseError(cause))
          │             │      │    │        │             └ 'unknown'
          │             │      │    │        └ <class 'urllib3.exceptions.ResponseError'>
          │             │      │    └ NewConnectionError('<urllib3.connection.HTTPConnection object at 0x7f91604880d0>: Failed to establish a new connection: [Errn...
          │             │      └ '/board/1.html'
          │             └ <urllib3.connectionpool.HTTPConnectionPool object at 0x7f9160488730>
          └ <class 'urllib3.exceptions.MaxRetryError'>

urllib3.exceptions.MaxRetryError: HTTPConnectionPool(host='bbs1.people.com.cn', port=80): Max retries exceeded with url: /board/1.html (Caused by NewConnectionError('<urllib3.connection.HTTPConnection object at 0x7f91604880d0>: Failed to establish a new connection: [Errno 111] Connection refused'))


During handling of the above exception, another exception occurred:


Traceback (most recent call last):

  File "/usr/lib/python3.8/threading.py", line 890, in _bootstrap
    self._bootstrap_inner()
    │    └ <function Thread._bootstrap_inner at 0x7f927a614a60>
    └ <Thread(Thread-70, started daemon 140261384500992)>
  File "/usr/lib/python3.8/threading.py", line 932, in _bootstrap_inner
    self.run()
    │    └ <function Thread.run at 0x7f927a614790>
    └ <Thread(Thread-70, started daemon 140261384500992)>
  File "/usr/lib/python3.8/threading.py", line 870, in run
    self._target(*self._args, **self._kwargs)
    │    │        │    │        │    └ {}
    │    │        │    │        └ <Thread(Thread-70, started daemon 140261384500992)>
    │    │        │    └ ('ProjectManager.run_func_by_thread',)
    │    │        └ <Thread(Thread-70, started daemon 140261384500992)>
    │    └ <bound method ProjectManager.get_request_from_keywords_hot of <monitor.projectManager.ProjectManager object at 0x7f9162af4700>>
    └ <Thread(Thread-70, started daemon 140261384500992)>

  File "/home/users/Scy/yuqing/spider/monitor/projectManager.py", line 795, in get_request_from_keywords_hot
    self.search_spider_manager.crawl_by_keyword(
    │    │                     └ <function SearchSpidersManager.crawl_by_keyword at 0x7f9162b00040>
    │    └ <monitor.spiderManager.SearchSpidersManager object at 0x7f916270f0d0>
    └ <monitor.projectManager.ProjectManager object at 0x7f9162af4700>

  File "/home/users/Scy/yuqing/spider/monitor/spiderManager.py", line 118, in crawl_by_keyword
    self.crawl_by_keyword_signal_platform(project_names, platform, keyword, crawl_time, project_times)
    │    │                                │              │         │        │           └ {'default': <monitor.TimeSection object at 0x7f91628317f0>}
    │    │                                │              │         │        └ <monitor.TimeSection object at 0x7f9160420040>
    │    │                                │              │         └ '匈牙利总理与欧盟委员会主席讨论对俄制裁问题'
    │    │                                │              └ '强国论坛'
    │    │                                └ ['default']
    │    └ <function SearchSpidersManager.crawl_by_keyword_signal_platform at 0x7f9162b000d0>
    └ <monitor.spiderManager.SearchSpidersManager object at 0x7f916270f0d0>

  File "/home/users/Scy/yuqing/spider/monitor/spiderManager.py", line 134, in crawl_by_keyword_signal_platform
    requests = self.get_request_from_keyword(platform, keyword, **crawl_time.to_dict())
               │    │                        │         │          │          └ <function TimeSection.to_dict at 0x7f925aaa8550>
               │    │                        │         │          └ <monitor.TimeSection object at 0x7f9160420040>
               │    │                        │         └ '匈牙利总理与欧盟委员会主席讨论对俄制裁问题'
               │    │                        └ '强国论坛'
               │    └ <function SearchSpidersManager.get_request_from_keyword at 0x7f9162b001f0>
               └ <monitor.spiderManager.SearchSpidersManager object at 0x7f916270f0d0>

  File "/home/users/Scy/yuqing/spider/monitor/spiderManager.py", line 191, in get_request_from_keyword
    for request in self.spiders[platform].get_request_from_keyword(headers, search_url, keyword, content_url,
                   │    │       │                                  │        │           │        └ <string.Template object at 0x7f9148783970>
                   │    │       │                                  │        │           └ '匈牙利总理与欧盟委员会主席讨论对俄制裁问题'
                   │    │       │                                  │        └ <string.Template object at 0x7f9148683b80>
                   │    │       │                                  └ {'Connection': 'keep-alive', 'Cache-Control': 'max-age=0', 'Upgrade-Insecure-Requests': '1', 'User-Agent': 'Mozilla/5.0 (X11;...
                   │    │       └ '强国论坛'
                   │    └ {'凤凰网': <monitor.searchSpiders.ifeng.Ifeng object at 0x7f916270f220>, '头条': <monitor.searchSpiders.toutiao.Toutiao object at ...
                   └ <monitor.spiderManager.SearchSpidersManager object at 0x7f916270f0d0>

> File "/home/users/Scy/yuqing/spider/monitor/searchSpiders/qinagguoLT.py", line 18, in get_request_from_keyword
    response = requests.get(search_url.substitute(), headers=headers)
               │        │   │          │                     └ {'Connection': 'keep-alive', 'Cache-Control': 'max-age=0', 'Upgrade-Insecure-Requests': '1', 'User-Agent': 'Mozilla/5.0 (X11;...
               │        │   │          └ <function Template.substitute at 0x7f927a5fd0d0>
               │        │   └ <string.Template object at 0x7f9148683b80>
               │        └ <function get at 0x7f92583e71f0>
               └ <module 'requests' from '/home/chase/.local/lib/python3.8/site-packages/requests/__init__.py'>

  File "/home/chase/.local/lib/python3.8/site-packages/requests/api.py", line 75, in get
    return request('get', url, params=params, **kwargs)
           │              │           │         └ {'headers': {'Connection': 'keep-alive', 'Cache-Control': 'max-age=0', 'Upgrade-Insecure-Requests': '1', 'User-Agent': 'Mozil...
           │              │           └ None
           │              └ 'http://bbs1.people.com.cn/board/1.html'
           └ <function request at 0x7f9258455040>
  File "/home/chase/.local/lib/python3.8/site-packages/requests/api.py", line 61, in request
    return session.request(method=method, url=url, **kwargs)
           │       │              │           │      └ {'params': None, 'headers': {'Connection': 'keep-alive', 'Cache-Control': 'max-age=0', 'Upgrade-Insecure-Requests': '1', 'Use...
           │       │              │           └ 'http://bbs1.people.com.cn/board/1.html'
           │       │              └ 'get'
           │       └ <function Session.request at 0x7f92583e6940>
           └ <requests.sessions.Session object at 0x7f9160285a30>
  File "/home/chase/.local/lib/python3.8/site-packages/requests/sessions.py", line 542, in request
    resp = self.send(prep, **send_kwargs)
           │    │    │       └ {'timeout': None, 'allow_redirects': True, 'verify': True, 'proxies': OrderedDict(), 'stream': False, 'cert': None}
           │    │    └ <PreparedRequest [GET]>
           │    └ <function Session.send at 0x7f92583e6dc0>
           └ <requests.sessions.Session object at 0x7f9160285a30>
  File "/home/chase/.local/lib/python3.8/site-packages/requests/sessions.py", line 655, in send
    r = adapter.send(request, **kwargs)
        │       │    │          └ {'timeout': None, 'verify': True, 'proxies': OrderedDict(), 'stream': False, 'cert': None}
        │       │    └ <PreparedRequest [GET]>
        │       └ <function HTTPAdapter.send at 0x7f92583e6280>
        └ <requests.adapters.HTTPAdapter object at 0x7f9148736040>
  File "/home/chase/.local/lib/python3.8/site-packages/requests/adapters.py", line 516, in send
    raise ConnectionError(e, request=request)
          │                          └ <PreparedRequest [GET]>
          └ <class 'requests.exceptions.ConnectionError'>

requests.exceptions.ConnectionError: HTTPConnectionPool(host='bbs1.people.com.cn', port=80): Max retries exceeded with url: /board/1.html (Caused by NewConnectionError('<urllib3.connection.HTTPConnection object at 0x7f91604880d0>: Failed to establish a new connection: [Errno 111] Connection refused'))
2022-05-12 15:33:03.108 | ERROR    | monitor.searchSpiders.qinagguoLT:get_request_from_keyword:27 - E 强国论坛错误HTTPConnectionPool(host='bbs1.people.com.cn', port=80): Max retries exceeded with url: /board/1.html (Caused by NewConnectionError('<urllib3.connection.HTTPConnection object at 0x7f9148768130>: Failed to establish a new connection: [Errno 111] Connection refused'))
Traceback (most recent call last):

  File "/home/chase/.local/lib/python3.8/site-packages/urllib3/connection.py", line 174, in _new_conn
    conn = connection.create_connection(
           │          └ <function create_connection at 0x7f92585fd1f0>
           └ <module 'urllib3.util.connection' from '/home/chase/.local/lib/python3.8/site-packages/urllib3/util/connection.py'>
  File "/home/chase/.local/lib/python3.8/site-packages/urllib3/util/connection.py", line 96, in create_connection
    raise err
          └ ConnectionRefusedError(111, 'Connection refused')
  File "/home/chase/.local/lib/python3.8/site-packages/urllib3/util/connection.py", line 86, in create_connection
    sock.connect(sa)
    │            └ ('1.31.128.212', 80)
    └ None

ConnectionRefusedError: [Errno 111] Connection refused


During handling of the above exception, another exception occurred:


Traceback (most recent call last):

  File "/home/chase/.local/lib/python3.8/site-packages/urllib3/connectionpool.py", line 699, in urlopen
    httplib_response = self._make_request(
                       │    └ <function HTTPConnectionPool._make_request at 0x7f92585c05e0>
                       └ <urllib3.connectionpool.HTTPConnectionPool object at 0x7f91600a5f10>
  File "/home/chase/.local/lib/python3.8/site-packages/urllib3/connectionpool.py", line 394, in _make_request
    conn.request(method, url, **httplib_request_kw)
    │    │       │       │      └ {'body': None, 'headers': {'User-Agent': 'Mozilla/5.0 (X11; Linux x86_64) AppleWebKit/537.36 (KHTML, like Gecko) Chrome/93.0....
    │    │       │       └ '/board/1.html'
    │    │       └ 'GET'
    │    └ <function HTTPConnection.request at 0x7f92585b0f70>
    └ <urllib3.connection.HTTPConnection object at 0x7f9148768130>
  File "/home/chase/.local/lib/python3.8/site-packages/urllib3/connection.py", line 239, in request
    super(HTTPConnection, self).request(method, url, body=body, headers=headers)
          │               │             │       │         │             └ {'User-Agent': 'Mozilla/5.0 (X11; Linux x86_64) AppleWebKit/537.36 (KHTML, like Gecko) Chrome/93.0.4577.63 Safari/537.36', 'A...
          │               │             │       │         └ None
          │               │             │       └ '/board/1.html'
          │               │             └ 'GET'
          │               └ <urllib3.connection.HTTPConnection object at 0x7f9148768130>
          └ <class 'urllib3.connection.HTTPConnection'>
  File "/usr/lib/python3.8/http/client.py", line 1256, in request
    self._send_request(method, url, body, headers, encode_chunked)
    │    │             │       │    │     │        └ False
    │    │             │       │    │     └ {'User-Agent': 'Mozilla/5.0 (X11; Linux x86_64) AppleWebKit/537.36 (KHTML, like Gecko) Chrome/93.0.4577.63 Safari/537.36', 'A...
    │    │             │       │    └ None
    │    │             │       └ '/board/1.html'
    │    │             └ 'GET'
    │    └ <function HTTPConnection._send_request at 0x7f926be50280>
    └ <urllib3.connection.HTTPConnection object at 0x7f9148768130>
  File "/usr/lib/python3.8/http/client.py", line 1302, in _send_request
    self.endheaders(body, encode_chunked=encode_chunked)
    │    │          │                    └ False
    │    │          └ None
    │    └ <function HTTPConnection.endheaders at 0x7f926be50160>
    └ <urllib3.connection.HTTPConnection object at 0x7f9148768130>
  File "/usr/lib/python3.8/http/client.py", line 1251, in endheaders
    self._send_output(message_body, encode_chunked=encode_chunked)
    │    │            │                            └ False
    │    │            └ None
    │    └ <function HTTPConnection._send_output at 0x7f926beb7d30>
    └ <urllib3.connection.HTTPConnection object at 0x7f9148768130>
  File "/usr/lib/python3.8/http/client.py", line 1011, in _send_output
    self.send(msg)
    │    │    └ b'GET /board/1.html HTTP/1.1\r\nHost: bbs1.people.com.cn\r\nUser-Agent: Mozilla/5.0 (X11; Linux x86_64) AppleWebKit/537.36 (K...
    │    └ <function HTTPConnection.send at 0x7f926beb7b80>
    └ <urllib3.connection.HTTPConnection object at 0x7f9148768130>
  File "/usr/lib/python3.8/http/client.py", line 951, in send
    self.connect()
    │    └ <function HTTPConnection.connect at 0x7f92585b0dc0>
    └ <urllib3.connection.HTTPConnection object at 0x7f9148768130>
  File "/home/chase/.local/lib/python3.8/site-packages/urllib3/connection.py", line 205, in connect
    conn = self._new_conn()
           │    └ <function HTTPConnection._new_conn at 0x7f92585b0c10>
           └ <urllib3.connection.HTTPConnection object at 0x7f9148768130>
  File "/home/chase/.local/lib/python3.8/site-packages/urllib3/connection.py", line 186, in _new_conn
    raise NewConnectionError(
          └ <class 'urllib3.exceptions.NewConnectionError'>

urllib3.exceptions.NewConnectionError: <urllib3.connection.HTTPConnection object at 0x7f9148768130>: Failed to establish a new connection: [Errno 111] Connection refused


During handling of the above exception, another exception occurred:


Traceback (most recent call last):

  File "/home/chase/.local/lib/python3.8/site-packages/requests/adapters.py", line 439, in send
    resp = conn.urlopen(
           │    └ <function HTTPConnectionPool.urlopen at 0x7f92585c0820>
           └ <urllib3.connectionpool.HTTPConnectionPool object at 0x7f91600a5f10>
  File "/home/chase/.local/lib/python3.8/site-packages/urllib3/connectionpool.py", line 755, in urlopen
    retries = retries.increment(
              │       └ <function Retry.increment at 0x7f9258608b80>
              └ Retry(total=0, connect=None, read=False, redirect=None, status=None)
  File "/home/chase/.local/lib/python3.8/site-packages/urllib3/util/retry.py", line 574, in increment
    raise MaxRetryError(_pool, url, error or ResponseError(cause))
          │             │      │    │        │             └ 'unknown'
          │             │      │    │        └ <class 'urllib3.exceptions.ResponseError'>
          │             │      │    └ NewConnectionError('<urllib3.connection.HTTPConnection object at 0x7f9148768130>: Failed to establish a new connection: [Errn...
          │             │      └ '/board/1.html'
          │             └ <urllib3.connectionpool.HTTPConnectionPool object at 0x7f91600a5f10>
          └ <class 'urllib3.exceptions.MaxRetryError'>

urllib3.exceptions.MaxRetryError: HTTPConnectionPool(host='bbs1.people.com.cn', port=80): Max retries exceeded with url: /board/1.html (Caused by NewConnectionError('<urllib3.connection.HTTPConnection object at 0x7f9148768130>: Failed to establish a new connection: [Errno 111] Connection refused'))


During handling of the above exception, another exception occurred:


Traceback (most recent call last):

  File "/usr/lib/python3.8/threading.py", line 890, in _bootstrap
    self._bootstrap_inner()
    │    └ <function Thread._bootstrap_inner at 0x7f927a614a60>
    └ <Thread(Thread-74, started daemon 140261367715584)>
  File "/usr/lib/python3.8/threading.py", line 932, in _bootstrap_inner
    self.run()
    │    └ <function Thread.run at 0x7f927a614790>
    └ <Thread(Thread-74, started daemon 140261367715584)>
  File "/usr/lib/python3.8/threading.py", line 870, in run
    self._target(*self._args, **self._kwargs)
    │    │        │    │        │    └ {}
    │    │        │    │        └ <Thread(Thread-74, started daemon 140261367715584)>
    │    │        │    └ ('ProjectManager.run_func_by_thread',)
    │    │        └ <Thread(Thread-74, started daemon 140261367715584)>
    │    └ <bound method ProjectManager.get_request_from_keywords_hot of <monitor.projectManager.ProjectManager object at 0x7f9162af4700>>
    └ <Thread(Thread-74, started daemon 140261367715584)>

  File "/home/users/Scy/yuqing/spider/monitor/projectManager.py", line 795, in get_request_from_keywords_hot
    self.search_spider_manager.crawl_by_keyword(
    │    │                     └ <function SearchSpidersManager.crawl_by_keyword at 0x7f9162b00040>
    │    └ <monitor.spiderManager.SearchSpidersManager object at 0x7f916270f0d0>
    └ <monitor.projectManager.ProjectManager object at 0x7f9162af4700>

  File "/home/users/Scy/yuqing/spider/monitor/spiderManager.py", line 118, in crawl_by_keyword
    self.crawl_by_keyword_signal_platform(project_names, platform, keyword, crawl_time, project_times)
    │    │                                │              │         │        │           └ {'default': <monitor.TimeSection object at 0x7f91628317f0>}
    │    │                                │              │         │        └ <monitor.TimeSection object at 0x7f916015fc10>
    │    │                                │              │         └ '第78集团军某旅：“伴随保障”强化战场意识'
    │    │                                │              └ '强国论坛'
    │    │                                └ ['default']
    │    └ <function SearchSpidersManager.crawl_by_keyword_signal_platform at 0x7f9162b000d0>
    └ <monitor.spiderManager.SearchSpidersManager object at 0x7f916270f0d0>

  File "/home/users/Scy/yuqing/spider/monitor/spiderManager.py", line 134, in crawl_by_keyword_signal_platform
    requests = self.get_request_from_keyword(platform, keyword, **crawl_time.to_dict())
               │    │                        │         │          │          └ <function TimeSection.to_dict at 0x7f925aaa8550>
               │    │                        │         │          └ <monitor.TimeSection object at 0x7f916015fc10>
               │    │                        │         └ '第78集团军某旅：“伴随保障”强化战场意识'
               │    │                        └ '强国论坛'
               │    └ <function SearchSpidersManager.get_request_from_keyword at 0x7f9162b001f0>
               └ <monitor.spiderManager.SearchSpidersManager object at 0x7f916270f0d0>

  File "/home/users/Scy/yuqing/spider/monitor/spiderManager.py", line 191, in get_request_from_keyword
    for request in self.spiders[platform].get_request_from_keyword(headers, search_url, keyword, content_url,
                   │    │       │                                  │        │           │        └ <string.Template object at 0x7f9160242cd0>
                   │    │       │                                  │        │           └ '第78集团军某旅：“伴随保障”强化战场意识'
                   │    │       │                                  │        └ <string.Template object at 0x7f916040a2e0>
                   │    │       │                                  └ {'Connection': 'keep-alive', 'Cache-Control': 'max-age=0', 'Upgrade-Insecure-Requests': '1', 'User-Agent': 'Mozilla/5.0 (X11;...
                   │    │       └ '强国论坛'
                   │    └ {'凤凰网': <monitor.searchSpiders.ifeng.Ifeng object at 0x7f916270f220>, '头条': <monitor.searchSpiders.toutiao.Toutiao object at ...
                   └ <monitor.spiderManager.SearchSpidersManager object at 0x7f916270f0d0>

> File "/home/users/Scy/yuqing/spider/monitor/searchSpiders/qinagguoLT.py", line 18, in get_request_from_keyword
    response = requests.get(search_url.substitute(), headers=headers)
               │        │   │          │                     └ {'Connection': 'keep-alive', 'Cache-Control': 'max-age=0', 'Upgrade-Insecure-Requests': '1', 'User-Agent': 'Mozilla/5.0 (X11;...
               │        │   │          └ <function Template.substitute at 0x7f927a5fd0d0>
               │        │   └ <string.Template object at 0x7f916040a2e0>
               │        └ <function get at 0x7f92583e71f0>
               └ <module 'requests' from '/home/chase/.local/lib/python3.8/site-packages/requests/__init__.py'>

  File "/home/chase/.local/lib/python3.8/site-packages/requests/api.py", line 75, in get
    return request('get', url, params=params, **kwargs)
           │              │           │         └ {'headers': {'Connection': 'keep-alive', 'Cache-Control': 'max-age=0', 'Upgrade-Insecure-Requests': '1', 'User-Agent': 'Mozil...
           │              │           └ None
           │              └ 'http://bbs1.people.com.cn/board/1.html'
           └ <function request at 0x7f9258455040>
  File "/home/chase/.local/lib/python3.8/site-packages/requests/api.py", line 61, in request
    return session.request(method=method, url=url, **kwargs)
           │       │              │           │      └ {'params': None, 'headers': {'Connection': 'keep-alive', 'Cache-Control': 'max-age=0', 'Upgrade-Insecure-Requests': '1', 'Use...
           │       │              │           └ 'http://bbs1.people.com.cn/board/1.html'
           │       │              └ 'get'
           │       └ <function Session.request at 0x7f92583e6940>
           └ <requests.sessions.Session object at 0x7f91600dc880>
  File "/home/chase/.local/lib/python3.8/site-packages/requests/sessions.py", line 542, in request
    resp = self.send(prep, **send_kwargs)
           │    │    │       └ {'timeout': None, 'allow_redirects': True, 'verify': True, 'proxies': OrderedDict(), 'stream': False, 'cert': None}
           │    │    └ <PreparedRequest [GET]>
           │    └ <function Session.send at 0x7f92583e6dc0>
           └ <requests.sessions.Session object at 0x7f91600dc880>
  File "/home/chase/.local/lib/python3.8/site-packages/requests/sessions.py", line 655, in send
    r = adapter.send(request, **kwargs)
        │       │    │          └ {'timeout': None, 'verify': True, 'proxies': OrderedDict(), 'stream': False, 'cert': None}
        │       │    └ <PreparedRequest [GET]>
        │       └ <function HTTPAdapter.send at 0x7f92583e6280>
        └ <requests.adapters.HTTPAdapter object at 0x7f91600a5df0>
  File "/home/chase/.local/lib/python3.8/site-packages/requests/adapters.py", line 516, in send
    raise ConnectionError(e, request=request)
          │                          └ <PreparedRequest [GET]>
          └ <class 'requests.exceptions.ConnectionError'>

requests.exceptions.ConnectionError: HTTPConnectionPool(host='bbs1.people.com.cn', port=80): Max retries exceeded with url: /board/1.html (Caused by NewConnectionError('<urllib3.connection.HTTPConnection object at 0x7f9148768130>: Failed to establish a new connection: [Errno 111] Connection refused'))
2022-05-12 15:33:03.213 | ERROR    | monitor.searchSpiders.qinagguoLT:get_request_from_keyword:27 - E 强国论坛错误HTTPConnectionPool(host='bbs1.people.com.cn', port=80): Max retries exceeded with url: /board/1.html (Caused by NewConnectionError('<urllib3.connection.HTTPConnection object at 0x7f916011c1f0>: Failed to establish a new connection: [Errno 111] Connection refused'))
Traceback (most recent call last):

  File "/home/chase/.local/lib/python3.8/site-packages/urllib3/connection.py", line 174, in _new_conn
    conn = connection.create_connection(
           │          └ <function create_connection at 0x7f92585fd1f0>
           └ <module 'urllib3.util.connection' from '/home/chase/.local/lib/python3.8/site-packages/urllib3/util/connection.py'>
  File "/home/chase/.local/lib/python3.8/site-packages/urllib3/util/connection.py", line 96, in create_connection
    raise err
          └ ConnectionRefusedError(111, 'Connection refused')
  File "/home/chase/.local/lib/python3.8/site-packages/urllib3/util/connection.py", line 86, in create_connection
    sock.connect(sa)
    │            └ ('1.31.128.212', 80)
    └ None

ConnectionRefusedError: [Errno 111] Connection refused


During handling of the above exception, another exception occurred:


Traceback (most recent call last):

  File "/home/chase/.local/lib/python3.8/site-packages/urllib3/connectionpool.py", line 699, in urlopen
    httplib_response = self._make_request(
                       │    └ <function HTTPConnectionPool._make_request at 0x7f92585c05e0>
                       └ <urllib3.connectionpool.HTTPConnectionPool object at 0x7f91601b4c10>
  File "/home/chase/.local/lib/python3.8/site-packages/urllib3/connectionpool.py", line 394, in _make_request
    conn.request(method, url, **httplib_request_kw)
    │    │       │       │      └ {'body': None, 'headers': {'User-Agent': 'Mozilla/5.0 (X11; Linux x86_64) AppleWebKit/537.36 (KHTML, like Gecko) Chrome/93.0....
    │    │       │       └ '/board/1.html'
    │    │       └ 'GET'
    │    └ <function HTTPConnection.request at 0x7f92585b0f70>
    └ <urllib3.connection.HTTPConnection object at 0x7f916011c1f0>
  File "/home/chase/.local/lib/python3.8/site-packages/urllib3/connection.py", line 239, in request
    super(HTTPConnection, self).request(method, url, body=body, headers=headers)
          │               │             │       │         │             └ {'User-Agent': 'Mozilla/5.0 (X11; Linux x86_64) AppleWebKit/537.36 (KHTML, like Gecko) Chrome/93.0.4577.63 Safari/537.36', 'A...
          │               │             │       │         └ None
          │               │             │       └ '/board/1.html'
          │               │             └ 'GET'
          │               └ <urllib3.connection.HTTPConnection object at 0x7f916011c1f0>
          └ <class 'urllib3.connection.HTTPConnection'>
  File "/usr/lib/python3.8/http/client.py", line 1256, in request
    self._send_request(method, url, body, headers, encode_chunked)
    │    │             │       │    │     │        └ False
    │    │             │       │    │     └ {'User-Agent': 'Mozilla/5.0 (X11; Linux x86_64) AppleWebKit/537.36 (KHTML, like Gecko) Chrome/93.0.4577.63 Safari/537.36', 'A...
    │    │             │       │    └ None
    │    │             │       └ '/board/1.html'
    │    │             └ 'GET'
    │    └ <function HTTPConnection._send_request at 0x7f926be50280>
    └ <urllib3.connection.HTTPConnection object at 0x7f916011c1f0>
  File "/usr/lib/python3.8/http/client.py", line 1302, in _send_request
    self.endheaders(body, encode_chunked=encode_chunked)
    │    │          │                    └ False
    │    │          └ None
    │    └ <function HTTPConnection.endheaders at 0x7f926be50160>
    └ <urllib3.connection.HTTPConnection object at 0x7f916011c1f0>
  File "/usr/lib/python3.8/http/client.py", line 1251, in endheaders
    self._send_output(message_body, encode_chunked=encode_chunked)
    │    │            │                            └ False
    │    │            └ None
    │    └ <function HTTPConnection._send_output at 0x7f926beb7d30>
    └ <urllib3.connection.HTTPConnection object at 0x7f916011c1f0>
  File "/usr/lib/python3.8/http/client.py", line 1011, in _send_output
    self.send(msg)
    │    │    └ b'GET /board/1.html HTTP/1.1\r\nHost: bbs1.people.com.cn\r\nUser-Agent: Mozilla/5.0 (X11; Linux x86_64) AppleWebKit/537.36 (K...
    │    └ <function HTTPConnection.send at 0x7f926beb7b80>
    └ <urllib3.connection.HTTPConnection object at 0x7f916011c1f0>
  File "/usr/lib/python3.8/http/client.py", line 951, in send
    self.connect()
    │    └ <function HTTPConnection.connect at 0x7f92585b0dc0>
    └ <urllib3.connection.HTTPConnection object at 0x7f916011c1f0>
  File "/home/chase/.local/lib/python3.8/site-packages/urllib3/connection.py", line 205, in connect
    conn = self._new_conn()
           │    └ <function HTTPConnection._new_conn at 0x7f92585b0c10>
           └ <urllib3.connection.HTTPConnection object at 0x7f916011c1f0>
  File "/home/chase/.local/lib/python3.8/site-packages/urllib3/connection.py", line 186, in _new_conn
    raise NewConnectionError(
          └ <class 'urllib3.exceptions.NewConnectionError'>

urllib3.exceptions.NewConnectionError: <urllib3.connection.HTTPConnection object at 0x7f916011c1f0>: Failed to establish a new connection: [Errno 111] Connection refused


During handling of the above exception, another exception occurred:


Traceback (most recent call last):

  File "/home/chase/.local/lib/python3.8/site-packages/requests/adapters.py", line 439, in send
    resp = conn.urlopen(
           │    └ <function HTTPConnectionPool.urlopen at 0x7f92585c0820>
           └ <urllib3.connectionpool.HTTPConnectionPool object at 0x7f91601b4c10>
  File "/home/chase/.local/lib/python3.8/site-packages/urllib3/connectionpool.py", line 755, in urlopen
    retries = retries.increment(
              │       └ <function Retry.increment at 0x7f9258608b80>
              └ Retry(total=0, connect=None, read=False, redirect=None, status=None)
  File "/home/chase/.local/lib/python3.8/site-packages/urllib3/util/retry.py", line 574, in increment
    raise MaxRetryError(_pool, url, error or ResponseError(cause))
          │             │      │    │        │             └ 'unknown'
          │             │      │    │        └ <class 'urllib3.exceptions.ResponseError'>
          │             │      │    └ NewConnectionError('<urllib3.connection.HTTPConnection object at 0x7f916011c1f0>: Failed to establish a new connection: [Errn...
          │             │      └ '/board/1.html'
          │             └ <urllib3.connectionpool.HTTPConnectionPool object at 0x7f91601b4c10>
          └ <class 'urllib3.exceptions.MaxRetryError'>

urllib3.exceptions.MaxRetryError: HTTPConnectionPool(host='bbs1.people.com.cn', port=80): Max retries exceeded with url: /board/1.html (Caused by NewConnectionError('<urllib3.connection.HTTPConnection object at 0x7f916011c1f0>: Failed to establish a new connection: [Errno 111] Connection refused'))


During handling of the above exception, another exception occurred:


Traceback (most recent call last):

  File "/usr/lib/python3.8/threading.py", line 890, in _bootstrap
    self._bootstrap_inner()
    │    └ <function Thread._bootstrap_inner at 0x7f927a614a60>
    └ <Thread(Thread-78, started daemon 140261376108288)>
  File "/usr/lib/python3.8/threading.py", line 932, in _bootstrap_inner
    self.run()
    │    └ <function Thread.run at 0x7f927a614790>
    └ <Thread(Thread-78, started daemon 140261376108288)>
  File "/usr/lib/python3.8/threading.py", line 870, in run
    self._target(*self._args, **self._kwargs)
    │    │        │    │        │    └ {}
    │    │        │    │        └ <Thread(Thread-78, started daemon 140261376108288)>
    │    │        │    └ ('ProjectManager.run_func_by_thread',)
    │    │        └ <Thread(Thread-78, started daemon 140261376108288)>
    │    └ <bound method ProjectManager.get_request_from_keywords_hot of <monitor.projectManager.ProjectManager object at 0x7f9162af4700>>
    └ <Thread(Thread-78, started daemon 140261376108288)>

  File "/home/users/Scy/yuqing/spider/monitor/projectManager.py", line 795, in get_request_from_keywords_hot
    self.search_spider_manager.crawl_by_keyword(
    │    │                     └ <function SearchSpidersManager.crawl_by_keyword at 0x7f9162b00040>
    │    └ <monitor.spiderManager.SearchSpidersManager object at 0x7f916270f0d0>
    └ <monitor.projectManager.ProjectManager object at 0x7f9162af4700>

  File "/home/users/Scy/yuqing/spider/monitor/spiderManager.py", line 118, in crawl_by_keyword
    self.crawl_by_keyword_signal_platform(project_names, platform, keyword, crawl_time, project_times)
    │    │                                │              │         │        │           └ {'default': <monitor.TimeSection object at 0x7f91628317f0>}
    │    │                                │              │         │        └ <monitor.TimeSection object at 0x7f91601652e0>
    │    │                                │              │         └ '第78集团军某旅：“伴随保障”强化战场意识'
    │    │                                │              └ '强国论坛'
    │    │                                └ ['default']
    │    └ <function SearchSpidersManager.crawl_by_keyword_signal_platform at 0x7f9162b000d0>
    └ <monitor.spiderManager.SearchSpidersManager object at 0x7f916270f0d0>

  File "/home/users/Scy/yuqing/spider/monitor/spiderManager.py", line 134, in crawl_by_keyword_signal_platform
    requests = self.get_request_from_keyword(platform, keyword, **crawl_time.to_dict())
               │    │                        │         │          │          └ <function TimeSection.to_dict at 0x7f925aaa8550>
               │    │                        │         │          └ <monitor.TimeSection object at 0x7f91601652e0>
               │    │                        │         └ '第78集团军某旅：“伴随保障”强化战场意识'
               │    │                        └ '强国论坛'
               │    └ <function SearchSpidersManager.get_request_from_keyword at 0x7f9162b001f0>
               └ <monitor.spiderManager.SearchSpidersManager object at 0x7f916270f0d0>

  File "/home/users/Scy/yuqing/spider/monitor/spiderManager.py", line 191, in get_request_from_keyword
    for request in self.spiders[platform].get_request_from_keyword(headers, search_url, keyword, content_url,
                   │    │       │                                  │        │           │        └ <string.Template object at 0x7f9160322ca0>
                   │    │       │                                  │        │           └ '第78集团军某旅：“伴随保障”强化战场意识'
                   │    │       │                                  │        └ <string.Template object at 0x7f9160322070>
                   │    │       │                                  └ {'Connection': 'keep-alive', 'Cache-Control': 'max-age=0', 'Upgrade-Insecure-Requests': '1', 'User-Agent': 'Mozilla/5.0 (X11;...
                   │    │       └ '强国论坛'
                   │    └ {'凤凰网': <monitor.searchSpiders.ifeng.Ifeng object at 0x7f916270f220>, '头条': <monitor.searchSpiders.toutiao.Toutiao object at ...
                   └ <monitor.spiderManager.SearchSpidersManager object at 0x7f916270f0d0>

> File "/home/users/Scy/yuqing/spider/monitor/searchSpiders/qinagguoLT.py", line 18, in get_request_from_keyword
    response = requests.get(search_url.substitute(), headers=headers)
               │        │   │          │                     └ {'Connection': 'keep-alive', 'Cache-Control': 'max-age=0', 'Upgrade-Insecure-Requests': '1', 'User-Agent': 'Mozilla/5.0 (X11;...
               │        │   │          └ <function Template.substitute at 0x7f927a5fd0d0>
               │        │   └ <string.Template object at 0x7f9160322070>
               │        └ <function get at 0x7f92583e71f0>
               └ <module 'requests' from '/home/chase/.local/lib/python3.8/site-packages/requests/__init__.py'>

  File "/home/chase/.local/lib/python3.8/site-packages/requests/api.py", line 75, in get
    return request('get', url, params=params, **kwargs)
           │              │           │         └ {'headers': {'Connection': 'keep-alive', 'Cache-Control': 'max-age=0', 'Upgrade-Insecure-Requests': '1', 'User-Agent': 'Mozil...
           │              │           └ None
           │              └ 'http://bbs1.people.com.cn/board/1.html'
           └ <function request at 0x7f9258455040>
  File "/home/chase/.local/lib/python3.8/site-packages/requests/api.py", line 61, in request
    return session.request(method=method, url=url, **kwargs)
           │       │              │           │      └ {'params': None, 'headers': {'Connection': 'keep-alive', 'Cache-Control': 'max-age=0', 'Upgrade-Insecure-Requests': '1', 'Use...
           │       │              │           └ 'http://bbs1.people.com.cn/board/1.html'
           │       │              └ 'get'
           │       └ <function Session.request at 0x7f92583e6940>
           └ <requests.sessions.Session object at 0x7f916012f100>
  File "/home/chase/.local/lib/python3.8/site-packages/requests/sessions.py", line 542, in request
    resp = self.send(prep, **send_kwargs)
           │    │    │       └ {'timeout': None, 'allow_redirects': True, 'verify': True, 'proxies': OrderedDict(), 'stream': False, 'cert': None}
           │    │    └ <PreparedRequest [GET]>
           │    └ <function Session.send at 0x7f92583e6dc0>
           └ <requests.sessions.Session object at 0x7f916012f100>
  File "/home/chase/.local/lib/python3.8/site-packages/requests/sessions.py", line 655, in send
    r = adapter.send(request, **kwargs)
        │       │    │          └ {'timeout': None, 'verify': True, 'proxies': OrderedDict(), 'stream': False, 'cert': None}
        │       │    └ <PreparedRequest [GET]>
        │       └ <function HTTPAdapter.send at 0x7f92583e6280>
        └ <requests.adapters.HTTPAdapter object at 0x7f91601b41f0>
  File "/home/chase/.local/lib/python3.8/site-packages/requests/adapters.py", line 516, in send
    raise ConnectionError(e, request=request)
          │                          └ <PreparedRequest [GET]>
          └ <class 'requests.exceptions.ConnectionError'>

requests.exceptions.ConnectionError: HTTPConnectionPool(host='bbs1.people.com.cn', port=80): Max retries exceeded with url: /board/1.html (Caused by NewConnectionError('<urllib3.connection.HTTPConnection object at 0x7f916011c1f0>: Failed to establish a new connection: [Errno 111] Connection refused'))
2022-05-12 15:33:04.210 | ERROR    | monitor.searchSpiders.qinagguoLT:get_request_from_keyword:27 - E 强国论坛错误HTTPConnectionPool(host='bbs1.people.com.cn', port=80): Max retries exceeded with url: /board/1.html (Caused by NewConnectionError('<urllib3.connection.HTTPConnection object at 0x7f9148734d00>: Failed to establish a new connection: [Errno 111] Connection refused'))
Traceback (most recent call last):

  File "/home/chase/.local/lib/python3.8/site-packages/urllib3/connection.py", line 174, in _new_conn
    conn = connection.create_connection(
           │          └ <function create_connection at 0x7f92585fd1f0>
           └ <module 'urllib3.util.connection' from '/home/chase/.local/lib/python3.8/site-packages/urllib3/util/connection.py'>
  File "/home/chase/.local/lib/python3.8/site-packages/urllib3/util/connection.py", line 96, in create_connection
    raise err
          └ ConnectionRefusedError(111, 'Connection refused')
  File "/home/chase/.local/lib/python3.8/site-packages/urllib3/util/connection.py", line 86, in create_connection
    sock.connect(sa)
    │            └ ('1.31.128.212', 80)
    └ None

ConnectionRefusedError: [Errno 111] Connection refused


During handling of the above exception, another exception occurred:


Traceback (most recent call last):

  File "/home/chase/.local/lib/python3.8/site-packages/urllib3/connectionpool.py", line 699, in urlopen
    httplib_response = self._make_request(
                       │    └ <function HTTPConnectionPool._make_request at 0x7f92585c05e0>
                       └ <urllib3.connectionpool.HTTPConnectionPool object at 0x7f91486cd9d0>
  File "/home/chase/.local/lib/python3.8/site-packages/urllib3/connectionpool.py", line 394, in _make_request
    conn.request(method, url, **httplib_request_kw)
    │    │       │       │      └ {'body': None, 'headers': {'User-Agent': 'Mozilla/5.0 (X11; Linux x86_64) AppleWebKit/537.36 (KHTML, like Gecko) Chrome/93.0....
    │    │       │       └ '/board/1.html'
    │    │       └ 'GET'
    │    └ <function HTTPConnection.request at 0x7f92585b0f70>
    └ <urllib3.connection.HTTPConnection object at 0x7f9148734d00>
  File "/home/chase/.local/lib/python3.8/site-packages/urllib3/connection.py", line 239, in request
    super(HTTPConnection, self).request(method, url, body=body, headers=headers)
          │               │             │       │         │             └ {'User-Agent': 'Mozilla/5.0 (X11; Linux x86_64) AppleWebKit/537.36 (KHTML, like Gecko) Chrome/93.0.4577.63 Safari/537.36', 'A...
          │               │             │       │         └ None
          │               │             │       └ '/board/1.html'
          │               │             └ 'GET'
          │               └ <urllib3.connection.HTTPConnection object at 0x7f9148734d00>
          └ <class 'urllib3.connection.HTTPConnection'>
  File "/usr/lib/python3.8/http/client.py", line 1256, in request
    self._send_request(method, url, body, headers, encode_chunked)
    │    │             │       │    │     │        └ False
    │    │             │       │    │     └ {'User-Agent': 'Mozilla/5.0 (X11; Linux x86_64) AppleWebKit/537.36 (KHTML, like Gecko) Chrome/93.0.4577.63 Safari/537.36', 'A...
    │    │             │       │    └ None
    │    │             │       └ '/board/1.html'
    │    │             └ 'GET'
    │    └ <function HTTPConnection._send_request at 0x7f926be50280>
    └ <urllib3.connection.HTTPConnection object at 0x7f9148734d00>
  File "/usr/lib/python3.8/http/client.py", line 1302, in _send_request
    self.endheaders(body, encode_chunked=encode_chunked)
    │    │          │                    └ False
    │    │          └ None
    │    └ <function HTTPConnection.endheaders at 0x7f926be50160>
    └ <urllib3.connection.HTTPConnection object at 0x7f9148734d00>
  File "/usr/lib/python3.8/http/client.py", line 1251, in endheaders
    self._send_output(message_body, encode_chunked=encode_chunked)
    │    │            │                            └ False
    │    │            └ None
    │    └ <function HTTPConnection._send_output at 0x7f926beb7d30>
    └ <urllib3.connection.HTTPConnection object at 0x7f9148734d00>
  File "/usr/lib/python3.8/http/client.py", line 1011, in _send_output
    self.send(msg)
    │    │    └ b'GET /board/1.html HTTP/1.1\r\nHost: bbs1.people.com.cn\r\nUser-Agent: Mozilla/5.0 (X11; Linux x86_64) AppleWebKit/537.36 (K...
    │    └ <function HTTPConnection.send at 0x7f926beb7b80>
    └ <urllib3.connection.HTTPConnection object at 0x7f9148734d00>
  File "/usr/lib/python3.8/http/client.py", line 951, in send
    self.connect()
    │    └ <function HTTPConnection.connect at 0x7f92585b0dc0>
    └ <urllib3.connection.HTTPConnection object at 0x7f9148734d00>
  File "/home/chase/.local/lib/python3.8/site-packages/urllib3/connection.py", line 205, in connect
    conn = self._new_conn()
           │    └ <function HTTPConnection._new_conn at 0x7f92585b0c10>
           └ <urllib3.connection.HTTPConnection object at 0x7f9148734d00>
  File "/home/chase/.local/lib/python3.8/site-packages/urllib3/connection.py", line 186, in _new_conn
    raise NewConnectionError(
          └ <class 'urllib3.exceptions.NewConnectionError'>

urllib3.exceptions.NewConnectionError: <urllib3.connection.HTTPConnection object at 0x7f9148734d00>: Failed to establish a new connection: [Errno 111] Connection refused


During handling of the above exception, another exception occurred:


Traceback (most recent call last):

  File "/home/chase/.local/lib/python3.8/site-packages/requests/adapters.py", line 439, in send
    resp = conn.urlopen(
           │    └ <function HTTPConnectionPool.urlopen at 0x7f92585c0820>
           └ <urllib3.connectionpool.HTTPConnectionPool object at 0x7f91486cd9d0>
  File "/home/chase/.local/lib/python3.8/site-packages/urllib3/connectionpool.py", line 755, in urlopen
    retries = retries.increment(
              │       └ <function Retry.increment at 0x7f9258608b80>
              └ Retry(total=0, connect=None, read=False, redirect=None, status=None)
  File "/home/chase/.local/lib/python3.8/site-packages/urllib3/util/retry.py", line 574, in increment
    raise MaxRetryError(_pool, url, error or ResponseError(cause))
          │             │      │    │        │             └ 'unknown'
          │             │      │    │        └ <class 'urllib3.exceptions.ResponseError'>
          │             │      │    └ NewConnectionError('<urllib3.connection.HTTPConnection object at 0x7f9148734d00>: Failed to establish a new connection: [Errn...
          │             │      └ '/board/1.html'
          │             └ <urllib3.connectionpool.HTTPConnectionPool object at 0x7f91486cd9d0>
          └ <class 'urllib3.exceptions.MaxRetryError'>

urllib3.exceptions.MaxRetryError: HTTPConnectionPool(host='bbs1.people.com.cn', port=80): Max retries exceeded with url: /board/1.html (Caused by NewConnectionError('<urllib3.connection.HTTPConnection object at 0x7f9148734d00>: Failed to establish a new connection: [Errno 111] Connection refused'))


During handling of the above exception, another exception occurred:


Traceback (most recent call last):

  File "/usr/lib/python3.8/threading.py", line 890, in _bootstrap
    self._bootstrap_inner()
    │    └ <function Thread._bootstrap_inner at 0x7f927a614a60>
    └ <Thread(Thread-3, started daemon 140262398256896)>
  File "/usr/lib/python3.8/threading.py", line 932, in _bootstrap_inner
    self.run()
    │    └ <function Thread.run at 0x7f927a614790>
    └ <Thread(Thread-3, started daemon 140262398256896)>
  File "/usr/lib/python3.8/threading.py", line 870, in run
    self._target(*self._args, **self._kwargs)
    │    │        │    │        │    └ {}
    │    │        │    │        └ <Thread(Thread-3, started daemon 140262398256896)>
    │    │        │    └ ('ProjectManager.run_func_by_thread',)
    │    │        └ <Thread(Thread-3, started daemon 140262398256896)>
    │    └ <bound method ProjectManager.get_request_from_keywords_hot of <monitor.projectManager.ProjectManager object at 0x7f9162af4700>>
    └ <Thread(Thread-3, started daemon 140262398256896)>

  File "/home/users/Scy/yuqing/spider/monitor/projectManager.py", line 795, in get_request_from_keywords_hot
    self.search_spider_manager.crawl_by_keyword(
    │    │                     └ <function SearchSpidersManager.crawl_by_keyword at 0x7f9162b00040>
    │    └ <monitor.spiderManager.SearchSpidersManager object at 0x7f916270f0d0>
    └ <monitor.projectManager.ProjectManager object at 0x7f9162af4700>

  File "/home/users/Scy/yuqing/spider/monitor/spiderManager.py", line 118, in crawl_by_keyword
    self.crawl_by_keyword_signal_platform(project_names, platform, keyword, crawl_time, project_times)
    │    │                                │              │         │        │           └ {'default': <monitor.TimeSection object at 0x7f91628317f0>}
    │    │                                │              │         │        └ <monitor.TimeSection object at 0x7f916168af70>
    │    │                                │              │         └ '俄罗斯将举行纪念卫国战争胜利77周年的阅兵活动'
    │    │                                │              └ '强国论坛'
    │    │                                └ ['default']
    │    └ <function SearchSpidersManager.crawl_by_keyword_signal_platform at 0x7f9162b000d0>
    └ <monitor.spiderManager.SearchSpidersManager object at 0x7f916270f0d0>

  File "/home/users/Scy/yuqing/spider/monitor/spiderManager.py", line 134, in crawl_by_keyword_signal_platform
    requests = self.get_request_from_keyword(platform, keyword, **crawl_time.to_dict())
               │    │                        │         │          │          └ <function TimeSection.to_dict at 0x7f925aaa8550>
               │    │                        │         │          └ <monitor.TimeSection object at 0x7f916168af70>
               │    │                        │         └ '俄罗斯将举行纪念卫国战争胜利77周年的阅兵活动'
               │    │                        └ '强国论坛'
               │    └ <function SearchSpidersManager.get_request_from_keyword at 0x7f9162b001f0>
               └ <monitor.spiderManager.SearchSpidersManager object at 0x7f916270f0d0>

  File "/home/users/Scy/yuqing/spider/monitor/spiderManager.py", line 191, in get_request_from_keyword
    for request in self.spiders[platform].get_request_from_keyword(headers, search_url, keyword, content_url,
                   │    │       │                                  │        │           │        └ <string.Template object at 0x7f9148784e50>
                   │    │       │                                  │        │           └ '俄罗斯将举行纪念卫国战争胜利77周年的阅兵活动'
                   │    │       │                                  │        └ <string.Template object at 0x7f9148784b80>
                   │    │       │                                  └ {'Connection': 'keep-alive', 'Cache-Control': 'max-age=0', 'Upgrade-Insecure-Requests': '1', 'User-Agent': 'Mozilla/5.0 (X11;...
                   │    │       └ '强国论坛'
                   │    └ {'凤凰网': <monitor.searchSpiders.ifeng.Ifeng object at 0x7f916270f220>, '头条': <monitor.searchSpiders.toutiao.Toutiao object at ...
                   └ <monitor.spiderManager.SearchSpidersManager object at 0x7f916270f0d0>

> File "/home/users/Scy/yuqing/spider/monitor/searchSpiders/qinagguoLT.py", line 18, in get_request_from_keyword
    response = requests.get(search_url.substitute(), headers=headers)
               │        │   │          │                     └ {'Connection': 'keep-alive', 'Cache-Control': 'max-age=0', 'Upgrade-Insecure-Requests': '1', 'User-Agent': 'Mozilla/5.0 (X11;...
               │        │   │          └ <function Template.substitute at 0x7f927a5fd0d0>
               │        │   └ <string.Template object at 0x7f9148784b80>
               │        └ <function get at 0x7f92583e71f0>
               └ <module 'requests' from '/home/chase/.local/lib/python3.8/site-packages/requests/__init__.py'>

  File "/home/chase/.local/lib/python3.8/site-packages/requests/api.py", line 75, in get
    return request('get', url, params=params, **kwargs)
           │              │           │         └ {'headers': {'Connection': 'keep-alive', 'Cache-Control': 'max-age=0', 'Upgrade-Insecure-Requests': '1', 'User-Agent': 'Mozil...
           │              │           └ None
           │              └ 'http://bbs1.people.com.cn/board/1.html'
           └ <function request at 0x7f9258455040>
  File "/home/chase/.local/lib/python3.8/site-packages/requests/api.py", line 61, in request
    return session.request(method=method, url=url, **kwargs)
           │       │              │           │      └ {'params': None, 'headers': {'Connection': 'keep-alive', 'Cache-Control': 'max-age=0', 'Upgrade-Insecure-Requests': '1', 'Use...
           │       │              │           └ 'http://bbs1.people.com.cn/board/1.html'
           │       │              └ 'get'
           │       └ <function Session.request at 0x7f92583e6940>
           └ <requests.sessions.Session object at 0x7f91616ab850>
  File "/home/chase/.local/lib/python3.8/site-packages/requests/sessions.py", line 542, in request
    resp = self.send(prep, **send_kwargs)
           │    │    │       └ {'timeout': None, 'allow_redirects': True, 'verify': True, 'proxies': OrderedDict(), 'stream': False, 'cert': None}
           │    │    └ <PreparedRequest [GET]>
           │    └ <function Session.send at 0x7f92583e6dc0>
           └ <requests.sessions.Session object at 0x7f91616ab850>
  File "/home/chase/.local/lib/python3.8/site-packages/requests/sessions.py", line 655, in send
    r = adapter.send(request, **kwargs)
        │       │    │          └ {'timeout': None, 'verify': True, 'proxies': OrderedDict(), 'stream': False, 'cert': None}
        │       │    └ <PreparedRequest [GET]>
        │       └ <function HTTPAdapter.send at 0x7f92583e6280>
        └ <requests.adapters.HTTPAdapter object at 0x7f91604253a0>
  File "/home/chase/.local/lib/python3.8/site-packages/requests/adapters.py", line 516, in send
    raise ConnectionError(e, request=request)
          │                          └ <PreparedRequest [GET]>
          └ <class 'requests.exceptions.ConnectionError'>

requests.exceptions.ConnectionError: HTTPConnectionPool(host='bbs1.people.com.cn', port=80): Max retries exceeded with url: /board/1.html (Caused by NewConnectionError('<urllib3.connection.HTTPConnection object at 0x7f9148734d00>: Failed to establish a new connection: [Errno 111] Connection refused'))
2022-05-12 15:33:04.882 | ERROR    | monitor.searchSpiders.qinagguoLT:get_request_from_keyword:27 - E 强国论坛错误HTTPConnectionPool(host='bbs1.people.com.cn', port=80): Max retries exceeded with url: /board/1.html (Caused by NewConnectionError('<urllib3.connection.HTTPConnection object at 0x7f9160453070>: Failed to establish a new connection: [Errno 111] Connection refused'))
Traceback (most recent call last):

  File "/home/chase/.local/lib/python3.8/site-packages/urllib3/connection.py", line 174, in _new_conn
    conn = connection.create_connection(
           │          └ <function create_connection at 0x7f92585fd1f0>
           └ <module 'urllib3.util.connection' from '/home/chase/.local/lib/python3.8/site-packages/urllib3/util/connection.py'>
  File "/home/chase/.local/lib/python3.8/site-packages/urllib3/util/connection.py", line 96, in create_connection
    raise err
          └ ConnectionRefusedError(111, 'Connection refused')
  File "/home/chase/.local/lib/python3.8/site-packages/urllib3/util/connection.py", line 86, in create_connection
    sock.connect(sa)
    │            └ ('1.31.128.212', 80)
    └ None

ConnectionRefusedError: [Errno 111] Connection refused


During handling of the above exception, another exception occurred:


Traceback (most recent call last):

  File "/home/chase/.local/lib/python3.8/site-packages/urllib3/connectionpool.py", line 699, in urlopen
    httplib_response = self._make_request(
                       │    └ <function HTTPConnectionPool._make_request at 0x7f92585c05e0>
                       └ <urllib3.connectionpool.HTTPConnectionPool object at 0x7f916025a280>
  File "/home/chase/.local/lib/python3.8/site-packages/urllib3/connectionpool.py", line 394, in _make_request
    conn.request(method, url, **httplib_request_kw)
    │    │       │       │      └ {'body': None, 'headers': {'User-Agent': 'Mozilla/5.0 (X11; Linux x86_64) AppleWebKit/537.36 (KHTML, like Gecko) Chrome/93.0....
    │    │       │       └ '/board/1.html'
    │    │       └ 'GET'
    │    └ <function HTTPConnection.request at 0x7f92585b0f70>
    └ <urllib3.connection.HTTPConnection object at 0x7f9160453070>
  File "/home/chase/.local/lib/python3.8/site-packages/urllib3/connection.py", line 239, in request
    super(HTTPConnection, self).request(method, url, body=body, headers=headers)
          │               │             │       │         │             └ {'User-Agent': 'Mozilla/5.0 (X11; Linux x86_64) AppleWebKit/537.36 (KHTML, like Gecko) Chrome/93.0.4577.63 Safari/537.36', 'A...
          │               │             │       │         └ None
          │               │             │       └ '/board/1.html'
          │               │             └ 'GET'
          │               └ <urllib3.connection.HTTPConnection object at 0x7f9160453070>
          └ <class 'urllib3.connection.HTTPConnection'>
  File "/usr/lib/python3.8/http/client.py", line 1256, in request
    self._send_request(method, url, body, headers, encode_chunked)
    │    │             │       │    │     │        └ False
    │    │             │       │    │     └ {'User-Agent': 'Mozilla/5.0 (X11; Linux x86_64) AppleWebKit/537.36 (KHTML, like Gecko) Chrome/93.0.4577.63 Safari/537.36', 'A...
    │    │             │       │    └ None
    │    │             │       └ '/board/1.html'
    │    │             └ 'GET'
    │    └ <function HTTPConnection._send_request at 0x7f926be50280>
    └ <urllib3.connection.HTTPConnection object at 0x7f9160453070>
  File "/usr/lib/python3.8/http/client.py", line 1302, in _send_request
    self.endheaders(body, encode_chunked=encode_chunked)
    │    │          │                    └ False
    │    │          └ None
    │    └ <function HTTPConnection.endheaders at 0x7f926be50160>
    └ <urllib3.connection.HTTPConnection object at 0x7f9160453070>
  File "/usr/lib/python3.8/http/client.py", line 1251, in endheaders
    self._send_output(message_body, encode_chunked=encode_chunked)
    │    │            │                            └ False
    │    │            └ None
    │    └ <function HTTPConnection._send_output at 0x7f926beb7d30>
    └ <urllib3.connection.HTTPConnection object at 0x7f9160453070>
  File "/usr/lib/python3.8/http/client.py", line 1011, in _send_output
    self.send(msg)
    │    │    └ b'GET /board/1.html HTTP/1.1\r\nHost: bbs1.people.com.cn\r\nUser-Agent: Mozilla/5.0 (X11; Linux x86_64) AppleWebKit/537.36 (K...
    │    └ <function HTTPConnection.send at 0x7f926beb7b80>
    └ <urllib3.connection.HTTPConnection object at 0x7f9160453070>
  File "/usr/lib/python3.8/http/client.py", line 951, in send
    self.connect()
    │    └ <function HTTPConnection.connect at 0x7f92585b0dc0>
    └ <urllib3.connection.HTTPConnection object at 0x7f9160453070>
  File "/home/chase/.local/lib/python3.8/site-packages/urllib3/connection.py", line 205, in connect
    conn = self._new_conn()
           │    └ <function HTTPConnection._new_conn at 0x7f92585b0c10>
           └ <urllib3.connection.HTTPConnection object at 0x7f9160453070>
  File "/home/chase/.local/lib/python3.8/site-packages/urllib3/connection.py", line 186, in _new_conn
    raise NewConnectionError(
          └ <class 'urllib3.exceptions.NewConnectionError'>

urllib3.exceptions.NewConnectionError: <urllib3.connection.HTTPConnection object at 0x7f9160453070>: Failed to establish a new connection: [Errno 111] Connection refused


During handling of the above exception, another exception occurred:


Traceback (most recent call last):

  File "/home/chase/.local/lib/python3.8/site-packages/requests/adapters.py", line 439, in send
    resp = conn.urlopen(
           │    └ <function HTTPConnectionPool.urlopen at 0x7f92585c0820>
           └ <urllib3.connectionpool.HTTPConnectionPool object at 0x7f916025a280>
  File "/home/chase/.local/lib/python3.8/site-packages/urllib3/connectionpool.py", line 755, in urlopen
    retries = retries.increment(
              │       └ <function Retry.increment at 0x7f9258608b80>
              └ Retry(total=0, connect=None, read=False, redirect=None, status=None)
  File "/home/chase/.local/lib/python3.8/site-packages/urllib3/util/retry.py", line 574, in increment
    raise MaxRetryError(_pool, url, error or ResponseError(cause))
          │             │      │    │        │             └ 'unknown'
          │             │      │    │        └ <class 'urllib3.exceptions.ResponseError'>
          │             │      │    └ NewConnectionError('<urllib3.connection.HTTPConnection object at 0x7f9160453070>: Failed to establish a new connection: [Errn...
          │             │      └ '/board/1.html'
          │             └ <urllib3.connectionpool.HTTPConnectionPool object at 0x7f916025a280>
          └ <class 'urllib3.exceptions.MaxRetryError'>

urllib3.exceptions.MaxRetryError: HTTPConnectionPool(host='bbs1.people.com.cn', port=80): Max retries exceeded with url: /board/1.html (Caused by NewConnectionError('<urllib3.connection.HTTPConnection object at 0x7f9160453070>: Failed to establish a new connection: [Errno 111] Connection refused'))


During handling of the above exception, another exception occurred:


Traceback (most recent call last):

  File "/usr/lib/python3.8/threading.py", line 890, in _bootstrap
    self._bootstrap_inner()
    │    └ <function Thread._bootstrap_inner at 0x7f927a614a60>
    └ <Thread(Thread-8, started daemon 140262381209344)>
  File "/usr/lib/python3.8/threading.py", line 932, in _bootstrap_inner
    self.run()
    │    └ <function Thread.run at 0x7f927a614790>
    └ <Thread(Thread-8, started daemon 140262381209344)>
  File "/usr/lib/python3.8/threading.py", line 870, in run
    self._target(*self._args, **self._kwargs)
    │    │        │    │        │    └ {}
    │    │        │    │        └ <Thread(Thread-8, started daemon 140262381209344)>
    │    │        │    └ ('ProjectManager.run_func_by_thread',)
    │    │        └ <Thread(Thread-8, started daemon 140262381209344)>
    │    └ <bound method ProjectManager.get_request_from_keywords_hot of <monitor.projectManager.ProjectManager object at 0x7f9162af4700>>
    └ <Thread(Thread-8, started daemon 140262381209344)>

  File "/home/users/Scy/yuqing/spider/monitor/projectManager.py", line 795, in get_request_from_keywords_hot
    self.search_spider_manager.crawl_by_keyword(
    │    │                     └ <function SearchSpidersManager.crawl_by_keyword at 0x7f9162b00040>
    │    └ <monitor.spiderManager.SearchSpidersManager object at 0x7f916270f0d0>
    └ <monitor.projectManager.ProjectManager object at 0x7f9162af4700>

  File "/home/users/Scy/yuqing/spider/monitor/spiderManager.py", line 118, in crawl_by_keyword
    self.crawl_by_keyword_signal_platform(project_names, platform, keyword, crawl_time, project_times)
    │    │                                │              │         │        │           └ {'default': <monitor.TimeSection object at 0x7f91628317f0>}
    │    │                                │              │         │        └ <monitor.TimeSection object at 0x7f916060c7c0>
    │    │                                │              │         └ '俄罗斯将举行纪念卫国战争胜利77周年的阅兵活动'
    │    │                                │              └ '强国论坛'
    │    │                                └ ['default']
    │    └ <function SearchSpidersManager.crawl_by_keyword_signal_platform at 0x7f9162b000d0>
    └ <monitor.spiderManager.SearchSpidersManager object at 0x7f916270f0d0>

  File "/home/users/Scy/yuqing/spider/monitor/spiderManager.py", line 134, in crawl_by_keyword_signal_platform
    requests = self.get_request_from_keyword(platform, keyword, **crawl_time.to_dict())
               │    │                        │         │          │          └ <function TimeSection.to_dict at 0x7f925aaa8550>
               │    │                        │         │          └ <monitor.TimeSection object at 0x7f916060c7c0>
               │    │                        │         └ '俄罗斯将举行纪念卫国战争胜利77周年的阅兵活动'
               │    │                        └ '强国论坛'
               │    └ <function SearchSpidersManager.get_request_from_keyword at 0x7f9162b001f0>
               └ <monitor.spiderManager.SearchSpidersManager object at 0x7f916270f0d0>

  File "/home/users/Scy/yuqing/spider/monitor/spiderManager.py", line 191, in get_request_from_keyword
    for request in self.spiders[platform].get_request_from_keyword(headers, search_url, keyword, content_url,
                   │    │       │                                  │        │           │        └ <string.Template object at 0x7f9160204700>
                   │    │       │                                  │        │           └ '俄罗斯将举行纪念卫国战争胜利77周年的阅兵活动'
                   │    │       │                                  │        └ <string.Template object at 0x7f914870dc70>
                   │    │       │                                  └ {'Connection': 'keep-alive', 'Cache-Control': 'max-age=0', 'Upgrade-Insecure-Requests': '1', 'User-Agent': 'Mozilla/5.0 (X11;...
                   │    │       └ '强国论坛'
                   │    └ {'凤凰网': <monitor.searchSpiders.ifeng.Ifeng object at 0x7f916270f220>, '头条': <monitor.searchSpiders.toutiao.Toutiao object at ...
                   └ <monitor.spiderManager.SearchSpidersManager object at 0x7f916270f0d0>

> File "/home/users/Scy/yuqing/spider/monitor/searchSpiders/qinagguoLT.py", line 18, in get_request_from_keyword
    response = requests.get(search_url.substitute(), headers=headers)
               │        │   │          │                     └ {'Connection': 'keep-alive', 'Cache-Control': 'max-age=0', 'Upgrade-Insecure-Requests': '1', 'User-Agent': 'Mozilla/5.0 (X11;...
               │        │   │          └ <function Template.substitute at 0x7f927a5fd0d0>
               │        │   └ <string.Template object at 0x7f914870dc70>
               │        └ <function get at 0x7f92583e71f0>
               └ <module 'requests' from '/home/chase/.local/lib/python3.8/site-packages/requests/__init__.py'>

  File "/home/chase/.local/lib/python3.8/site-packages/requests/api.py", line 75, in get
    return request('get', url, params=params, **kwargs)
           │              │           │         └ {'headers': {'Connection': 'keep-alive', 'Cache-Control': 'max-age=0', 'Upgrade-Insecure-Requests': '1', 'User-Agent': 'Mozil...
           │              │           └ None
           │              └ 'http://bbs1.people.com.cn/board/1.html'
           └ <function request at 0x7f9258455040>
  File "/home/chase/.local/lib/python3.8/site-packages/requests/api.py", line 61, in request
    return session.request(method=method, url=url, **kwargs)
           │       │              │           │      └ {'params': None, 'headers': {'Connection': 'keep-alive', 'Cache-Control': 'max-age=0', 'Upgrade-Insecure-Requests': '1', 'Use...
           │       │              │           └ 'http://bbs1.people.com.cn/board/1.html'
           │       │              └ 'get'
           │       └ <function Session.request at 0x7f92583e6940>
           └ <requests.sessions.Session object at 0x7f91601e81c0>
  File "/home/chase/.local/lib/python3.8/site-packages/requests/sessions.py", line 542, in request
    resp = self.send(prep, **send_kwargs)
           │    │    │       └ {'timeout': None, 'allow_redirects': True, 'verify': True, 'proxies': OrderedDict(), 'stream': False, 'cert': None}
           │    │    └ <PreparedRequest [GET]>
           │    └ <function Session.send at 0x7f92583e6dc0>
           └ <requests.sessions.Session object at 0x7f91601e81c0>
  File "/home/chase/.local/lib/python3.8/site-packages/requests/sessions.py", line 655, in send
    r = adapter.send(request, **kwargs)
        │       │    │          └ {'timeout': None, 'verify': True, 'proxies': OrderedDict(), 'stream': False, 'cert': None}
        │       │    └ <PreparedRequest [GET]>
        │       └ <function HTTPAdapter.send at 0x7f92583e6280>
        └ <requests.adapters.HTTPAdapter object at 0x7f9148727940>
  File "/home/chase/.local/lib/python3.8/site-packages/requests/adapters.py", line 516, in send
    raise ConnectionError(e, request=request)
          │                          └ <PreparedRequest [GET]>
          └ <class 'requests.exceptions.ConnectionError'>

requests.exceptions.ConnectionError: HTTPConnectionPool(host='bbs1.people.com.cn', port=80): Max retries exceeded with url: /board/1.html (Caused by NewConnectionError('<urllib3.connection.HTTPConnection object at 0x7f9160453070>: Failed to establish a new connection: [Errno 111] Connection refused'))
2022-05-12 15:33:05.836 | ERROR    | monitor.searchSpiders.qinagguoLT:get_request_from_keyword:27 - E 强国论坛错误HTTPConnectionPool(host='bbs1.people.com.cn', port=80): Max retries exceeded with url: /board/1.html (Caused by NewConnectionError('<urllib3.connection.HTTPConnection object at 0x7f9148584640>: Failed to establish a new connection: [Errno 111] Connection refused'))
Traceback (most recent call last):

  File "/home/chase/.local/lib/python3.8/site-packages/urllib3/connection.py", line 174, in _new_conn
    conn = connection.create_connection(
           │          └ <function create_connection at 0x7f92585fd1f0>
           └ <module 'urllib3.util.connection' from '/home/chase/.local/lib/python3.8/site-packages/urllib3/util/connection.py'>
  File "/home/chase/.local/lib/python3.8/site-packages/urllib3/util/connection.py", line 96, in create_connection
    raise err
          └ ConnectionRefusedError(111, 'Connection refused')
  File "/home/chase/.local/lib/python3.8/site-packages/urllib3/util/connection.py", line 86, in create_connection
    sock.connect(sa)
    │            └ ('1.31.128.212', 80)
    └ None

ConnectionRefusedError: [Errno 111] Connection refused


During handling of the above exception, another exception occurred:


Traceback (most recent call last):

  File "/home/chase/.local/lib/python3.8/site-packages/urllib3/connectionpool.py", line 699, in urlopen
    httplib_response = self._make_request(
                       │    └ <function HTTPConnectionPool._make_request at 0x7f92585c05e0>
                       └ <urllib3.connectionpool.HTTPConnectionPool object at 0x7f9148665250>
  File "/home/chase/.local/lib/python3.8/site-packages/urllib3/connectionpool.py", line 394, in _make_request
    conn.request(method, url, **httplib_request_kw)
    │    │       │       │      └ {'body': None, 'headers': {'User-Agent': 'Mozilla/5.0 (X11; Linux x86_64) AppleWebKit/537.36 (KHTML, like Gecko) Chrome/93.0....
    │    │       │       └ '/board/1.html'
    │    │       └ 'GET'
    │    └ <function HTTPConnection.request at 0x7f92585b0f70>
    └ <urllib3.connection.HTTPConnection object at 0x7f9148584640>
  File "/home/chase/.local/lib/python3.8/site-packages/urllib3/connection.py", line 239, in request
    super(HTTPConnection, self).request(method, url, body=body, headers=headers)
          │               │             │       │         │             └ {'User-Agent': 'Mozilla/5.0 (X11; Linux x86_64) AppleWebKit/537.36 (KHTML, like Gecko) Chrome/93.0.4577.63 Safari/537.36', 'A...
          │               │             │       │         └ None
          │               │             │       └ '/board/1.html'
          │               │             └ 'GET'
          │               └ <urllib3.connection.HTTPConnection object at 0x7f9148584640>
          └ <class 'urllib3.connection.HTTPConnection'>
  File "/usr/lib/python3.8/http/client.py", line 1256, in request
    self._send_request(method, url, body, headers, encode_chunked)
    │    │             │       │    │     │        └ False
    │    │             │       │    │     └ {'User-Agent': 'Mozilla/5.0 (X11; Linux x86_64) AppleWebKit/537.36 (KHTML, like Gecko) Chrome/93.0.4577.63 Safari/537.36', 'A...
    │    │             │       │    └ None
    │    │             │       └ '/board/1.html'
    │    │             └ 'GET'
    │    └ <function HTTPConnection._send_request at 0x7f926be50280>
    └ <urllib3.connection.HTTPConnection object at 0x7f9148584640>
  File "/usr/lib/python3.8/http/client.py", line 1302, in _send_request
    self.endheaders(body, encode_chunked=encode_chunked)
    │    │          │                    └ False
    │    │          └ None
    │    └ <function HTTPConnection.endheaders at 0x7f926be50160>
    └ <urllib3.connection.HTTPConnection object at 0x7f9148584640>
  File "/usr/lib/python3.8/http/client.py", line 1251, in endheaders
    self._send_output(message_body, encode_chunked=encode_chunked)
    │    │            │                            └ False
    │    │            └ None
    │    └ <function HTTPConnection._send_output at 0x7f926beb7d30>
    └ <urllib3.connection.HTTPConnection object at 0x7f9148584640>
  File "/usr/lib/python3.8/http/client.py", line 1011, in _send_output
    self.send(msg)
    │    │    └ b'GET /board/1.html HTTP/1.1\r\nHost: bbs1.people.com.cn\r\nUser-Agent: Mozilla/5.0 (X11; Linux x86_64) AppleWebKit/537.36 (K...
    │    └ <function HTTPConnection.send at 0x7f926beb7b80>
    └ <urllib3.connection.HTTPConnection object at 0x7f9148584640>
  File "/usr/lib/python3.8/http/client.py", line 951, in send
    self.connect()
    │    └ <function HTTPConnection.connect at 0x7f92585b0dc0>
    └ <urllib3.connection.HTTPConnection object at 0x7f9148584640>
  File "/home/chase/.local/lib/python3.8/site-packages/urllib3/connection.py", line 205, in connect
    conn = self._new_conn()
           │    └ <function HTTPConnection._new_conn at 0x7f92585b0c10>
           └ <urllib3.connection.HTTPConnection object at 0x7f9148584640>
  File "/home/chase/.local/lib/python3.8/site-packages/urllib3/connection.py", line 186, in _new_conn
    raise NewConnectionError(
          └ <class 'urllib3.exceptions.NewConnectionError'>

urllib3.exceptions.NewConnectionError: <urllib3.connection.HTTPConnection object at 0x7f9148584640>: Failed to establish a new connection: [Errno 111] Connection refused


During handling of the above exception, another exception occurred:


Traceback (most recent call last):

  File "/home/chase/.local/lib/python3.8/site-packages/requests/adapters.py", line 439, in send
    resp = conn.urlopen(
           │    └ <function HTTPConnectionPool.urlopen at 0x7f92585c0820>
           └ <urllib3.connectionpool.HTTPConnectionPool object at 0x7f9148665250>
  File "/home/chase/.local/lib/python3.8/site-packages/urllib3/connectionpool.py", line 755, in urlopen
    retries = retries.increment(
              │       └ <function Retry.increment at 0x7f9258608b80>
              └ Retry(total=0, connect=None, read=False, redirect=None, status=None)
  File "/home/chase/.local/lib/python3.8/site-packages/urllib3/util/retry.py", line 574, in increment
    raise MaxRetryError(_pool, url, error or ResponseError(cause))
          │             │      │    │        │             └ 'unknown'
          │             │      │    │        └ <class 'urllib3.exceptions.ResponseError'>
          │             │      │    └ NewConnectionError('<urllib3.connection.HTTPConnection object at 0x7f9148584640>: Failed to establish a new connection: [Errn...
          │             │      └ '/board/1.html'
          │             └ <urllib3.connectionpool.HTTPConnectionPool object at 0x7f9148665250>
          └ <class 'urllib3.exceptions.MaxRetryError'>

urllib3.exceptions.MaxRetryError: HTTPConnectionPool(host='bbs1.people.com.cn', port=80): Max retries exceeded with url: /board/1.html (Caused by NewConnectionError('<urllib3.connection.HTTPConnection object at 0x7f9148584640>: Failed to establish a new connection: [Errno 111] Connection refused'))


During handling of the above exception, another exception occurred:


Traceback (most recent call last):

  File "/usr/lib/python3.8/threading.py", line 890, in _bootstrap
    self._bootstrap_inner()
    │    └ <function Thread._bootstrap_inner at 0x7f927a614a60>
    └ <Thread(Thread-88, started daemon 140260872808192)>
  File "/usr/lib/python3.8/threading.py", line 932, in _bootstrap_inner
    self.run()
    │    └ <function Thread.run at 0x7f927a614790>
    └ <Thread(Thread-88, started daemon 140260872808192)>
  File "/usr/lib/python3.8/threading.py", line 870, in run
    self._target(*self._args, **self._kwargs)
    │    │        │    │        │    └ {}
    │    │        │    │        └ <Thread(Thread-88, started daemon 140260872808192)>
    │    │        │    └ ('ProjectManager.run_func_by_thread',)
    │    │        └ <Thread(Thread-88, started daemon 140260872808192)>
    │    └ <bound method ProjectManager.get_request_from_keywords_hot of <monitor.projectManager.ProjectManager object at 0x7f9162af4700>>
    └ <Thread(Thread-88, started daemon 140260872808192)>

  File "/home/users/Scy/yuqing/spider/monitor/projectManager.py", line 795, in get_request_from_keywords_hot
    self.search_spider_manager.crawl_by_keyword(
    │    │                     └ <function SearchSpidersManager.crawl_by_keyword at 0x7f9162b00040>
    │    └ <monitor.spiderManager.SearchSpidersManager object at 0x7f916270f0d0>
    └ <monitor.projectManager.ProjectManager object at 0x7f9162af4700>

  File "/home/users/Scy/yuqing/spider/monitor/spiderManager.py", line 118, in crawl_by_keyword
    self.crawl_by_keyword_signal_platform(project_names, platform, keyword, crawl_time, project_times)
    │    │                                │              │         │        │           └ {'default': <monitor.TimeSection object at 0x7f91628317f0>}
    │    │                                │              │         │        └ <monitor.TimeSection object at 0x7f91600c09d0>
    │    │                                │              │         └ '俄罗斯举行胜利日阅兵'
    │    │                                │              └ '强国论坛'
    │    │                                └ ['default']
    │    └ <function SearchSpidersManager.crawl_by_keyword_signal_platform at 0x7f9162b000d0>
    └ <monitor.spiderManager.SearchSpidersManager object at 0x7f916270f0d0>

  File "/home/users/Scy/yuqing/spider/monitor/spiderManager.py", line 134, in crawl_by_keyword_signal_platform
    requests = self.get_request_from_keyword(platform, keyword, **crawl_time.to_dict())
               │    │                        │         │          │          └ <function TimeSection.to_dict at 0x7f925aaa8550>
               │    │                        │         │          └ <monitor.TimeSection object at 0x7f91600c09d0>
               │    │                        │         └ '俄罗斯举行胜利日阅兵'
               │    │                        └ '强国论坛'
               │    └ <function SearchSpidersManager.get_request_from_keyword at 0x7f9162b001f0>
               └ <monitor.spiderManager.SearchSpidersManager object at 0x7f916270f0d0>

  File "/home/users/Scy/yuqing/spider/monitor/spiderManager.py", line 191, in get_request_from_keyword
    for request in self.spiders[platform].get_request_from_keyword(headers, search_url, keyword, content_url,
                   │    │       │                                  │        │           │        └ <string.Template object at 0x7f9148584fa0>
                   │    │       │                                  │        │           └ '俄罗斯举行胜利日阅兵'
                   │    │       │                                  │        └ <string.Template object at 0x7f9160451b50>
                   │    │       │                                  └ {'Connection': 'keep-alive', 'Cache-Control': 'max-age=0', 'Upgrade-Insecure-Requests': '1', 'User-Agent': 'Mozilla/5.0 (X11;...
                   │    │       └ '强国论坛'
                   │    └ {'凤凰网': <monitor.searchSpiders.ifeng.Ifeng object at 0x7f916270f220>, '头条': <monitor.searchSpiders.toutiao.Toutiao object at ...
                   └ <monitor.spiderManager.SearchSpidersManager object at 0x7f916270f0d0>

> File "/home/users/Scy/yuqing/spider/monitor/searchSpiders/qinagguoLT.py", line 18, in get_request_from_keyword
    response = requests.get(search_url.substitute(), headers=headers)
               │        │   │          │                     └ {'Connection': 'keep-alive', 'Cache-Control': 'max-age=0', 'Upgrade-Insecure-Requests': '1', 'User-Agent': 'Mozilla/5.0 (X11;...
               │        │   │          └ <function Template.substitute at 0x7f927a5fd0d0>
               │        │   └ <string.Template object at 0x7f9160451b50>
               │        └ <function get at 0x7f92583e71f0>
               └ <module 'requests' from '/home/chase/.local/lib/python3.8/site-packages/requests/__init__.py'>

  File "/home/chase/.local/lib/python3.8/site-packages/requests/api.py", line 75, in get
    return request('get', url, params=params, **kwargs)
           │              │           │         └ {'headers': {'Connection': 'keep-alive', 'Cache-Control': 'max-age=0', 'Upgrade-Insecure-Requests': '1', 'User-Agent': 'Mozil...
           │              │           └ None
           │              └ 'http://bbs1.people.com.cn/board/1.html'
           └ <function request at 0x7f9258455040>
  File "/home/chase/.local/lib/python3.8/site-packages/requests/api.py", line 61, in request
    return session.request(method=method, url=url, **kwargs)
           │       │              │           │      └ {'params': None, 'headers': {'Connection': 'keep-alive', 'Cache-Control': 'max-age=0', 'Upgrade-Insecure-Requests': '1', 'Use...
           │       │              │           └ 'http://bbs1.people.com.cn/board/1.html'
           │       │              └ 'get'
           │       └ <function Session.request at 0x7f92583e6940>
           └ <requests.sessions.Session object at 0x7f91604d71f0>
  File "/home/chase/.local/lib/python3.8/site-packages/requests/sessions.py", line 542, in request
    resp = self.send(prep, **send_kwargs)
           │    │    │       └ {'timeout': None, 'allow_redirects': True, 'verify': True, 'proxies': OrderedDict(), 'stream': False, 'cert': None}
           │    │    └ <PreparedRequest [GET]>
           │    └ <function Session.send at 0x7f92583e6dc0>
           └ <requests.sessions.Session object at 0x7f91604d71f0>
  File "/home/chase/.local/lib/python3.8/site-packages/requests/sessions.py", line 655, in send
    r = adapter.send(request, **kwargs)
        │       │    │          └ {'timeout': None, 'verify': True, 'proxies': OrderedDict(), 'stream': False, 'cert': None}
        │       │    └ <PreparedRequest [GET]>
        │       └ <function HTTPAdapter.send at 0x7f92583e6280>
        └ <requests.adapters.HTTPAdapter object at 0x7f9160250ca0>
  File "/home/chase/.local/lib/python3.8/site-packages/requests/adapters.py", line 516, in send
    raise ConnectionError(e, request=request)
          │                          └ <PreparedRequest [GET]>
          └ <class 'requests.exceptions.ConnectionError'>

requests.exceptions.ConnectionError: HTTPConnectionPool(host='bbs1.people.com.cn', port=80): Max retries exceeded with url: /board/1.html (Caused by NewConnectionError('<urllib3.connection.HTTPConnection object at 0x7f9148584640>: Failed to establish a new connection: [Errno 111] Connection refused'))
2022-05-12 15:33:07.919 | ERROR    | monitor.searchSpiders.people:get_request_from_keyword:45 - E 人民网错误HTTPConnectionPool(host='search.people.cn', port=80): Max retries exceeded with url: /search-platform/front/search (Caused by NewConnectionError('<urllib3.connection.HTTPConnection object at 0x7f91604a12b0>: Failed to establish a new connection: [Errno 111] Connection refused'))
Traceback (most recent call last):

  File "/home/chase/.local/lib/python3.8/site-packages/urllib3/connection.py", line 174, in _new_conn
    conn = connection.create_connection(
           │          └ <function create_connection at 0x7f92585fd1f0>
           └ <module 'urllib3.util.connection' from '/home/chase/.local/lib/python3.8/site-packages/urllib3/util/connection.py'>
  File "/home/chase/.local/lib/python3.8/site-packages/urllib3/util/connection.py", line 96, in create_connection
    raise err
          └ ConnectionRefusedError(111, 'Connection refused')
  File "/home/chase/.local/lib/python3.8/site-packages/urllib3/util/connection.py", line 86, in create_connection
    sock.connect(sa)
    │            └ ('1.31.128.250', 80)
    └ None

ConnectionRefusedError: [Errno 111] Connection refused


During handling of the above exception, another exception occurred:


Traceback (most recent call last):

  File "/home/chase/.local/lib/python3.8/site-packages/urllib3/connectionpool.py", line 699, in urlopen
    httplib_response = self._make_request(
                       │    └ <function HTTPConnectionPool._make_request at 0x7f92585c05e0>
                       └ <urllib3.connectionpool.HTTPConnectionPool object at 0x7f91601e8a30>
  File "/home/chase/.local/lib/python3.8/site-packages/urllib3/connectionpool.py", line 394, in _make_request
    conn.request(method, url, **httplib_request_kw)
    │    │       │       │      └ {'body': b'{"key": "\\u7b2c78\\u96c6\\u56e2\\u519b\\u67d0\\u65c5\\uff1a\\u201c\\u4f34\\u968f\\u4fdd\\u969c\\u201d\\u5f3a\\u53...
    │    │       │       └ '/search-platform/front/search'
    │    │       └ 'POST'
    │    └ <function HTTPConnection.request at 0x7f92585b0f70>
    └ <urllib3.connection.HTTPConnection object at 0x7f91604a12b0>
  File "/home/chase/.local/lib/python3.8/site-packages/urllib3/connection.py", line 239, in request
    super(HTTPConnection, self).request(method, url, body=body, headers=headers)
          │               │             │       │         │             └ {'User-Agent': 'Mozilla/5.0 (Windows NT 10.0; Win64; x64) AppleWebKit/537.36 (KHTML, like Gecko) Chrome/101.0.4951.54 Safari/...
          │               │             │       │         └ b'{"key": "\\u7b2c78\\u96c6\\u56e2\\u519b\\u67d0\\u65c5\\uff1a\\u201c\\u4f34\\u968f\\u4fdd\\u969c\\u201d\\u5f3a\\u5316\\u6218...
          │               │             │       └ '/search-platform/front/search'
          │               │             └ 'POST'
          │               └ <urllib3.connection.HTTPConnection object at 0x7f91604a12b0>
          └ <class 'urllib3.connection.HTTPConnection'>
  File "/usr/lib/python3.8/http/client.py", line 1256, in request
    self._send_request(method, url, body, headers, encode_chunked)
    │    │             │       │    │     │        └ False
    │    │             │       │    │     └ {'User-Agent': 'Mozilla/5.0 (Windows NT 10.0; Win64; x64) AppleWebKit/537.36 (KHTML, like Gecko) Chrome/101.0.4951.54 Safari/...
    │    │             │       │    └ b'{"key": "\\u7b2c78\\u96c6\\u56e2\\u519b\\u67d0\\u65c5\\uff1a\\u201c\\u4f34\\u968f\\u4fdd\\u969c\\u201d\\u5f3a\\u5316\\u6218...
    │    │             │       └ '/search-platform/front/search'
    │    │             └ 'POST'
    │    └ <function HTTPConnection._send_request at 0x7f926be50280>
    └ <urllib3.connection.HTTPConnection object at 0x7f91604a12b0>
  File "/usr/lib/python3.8/http/client.py", line 1302, in _send_request
    self.endheaders(body, encode_chunked=encode_chunked)
    │    │          │                    └ False
    │    │          └ b'{"key": "\\u7b2c78\\u96c6\\u56e2\\u519b\\u67d0\\u65c5\\uff1a\\u201c\\u4f34\\u968f\\u4fdd\\u969c\\u201d\\u5f3a\\u5316\\u6218...
    │    └ <function HTTPConnection.endheaders at 0x7f926be50160>
    └ <urllib3.connection.HTTPConnection object at 0x7f91604a12b0>
  File "/usr/lib/python3.8/http/client.py", line 1251, in endheaders
    self._send_output(message_body, encode_chunked=encode_chunked)
    │    │            │                            └ False
    │    │            └ b'{"key": "\\u7b2c78\\u96c6\\u56e2\\u519b\\u67d0\\u65c5\\uff1a\\u201c\\u4f34\\u968f\\u4fdd\\u969c\\u201d\\u5f3a\\u5316\\u6218...
    │    └ <function HTTPConnection._send_output at 0x7f926beb7d30>
    └ <urllib3.connection.HTTPConnection object at 0x7f91604a12b0>
  File "/usr/lib/python3.8/http/client.py", line 1011, in _send_output
    self.send(msg)
    │    │    └ b'POST /search-platform/front/search HTTP/1.1\r\nHost: search.people.cn\r\nUser-Agent: Mozilla/5.0 (Windows NT 10.0; Win64; x...
    │    └ <function HTTPConnection.send at 0x7f926beb7b80>
    └ <urllib3.connection.HTTPConnection object at 0x7f91604a12b0>
  File "/usr/lib/python3.8/http/client.py", line 951, in send
    self.connect()
    │    └ <function HTTPConnection.connect at 0x7f92585b0dc0>
    └ <urllib3.connection.HTTPConnection object at 0x7f91604a12b0>
  File "/home/chase/.local/lib/python3.8/site-packages/urllib3/connection.py", line 205, in connect
    conn = self._new_conn()
           │    └ <function HTTPConnection._new_conn at 0x7f92585b0c10>
           └ <urllib3.connection.HTTPConnection object at 0x7f91604a12b0>
  File "/home/chase/.local/lib/python3.8/site-packages/urllib3/connection.py", line 186, in _new_conn
    raise NewConnectionError(
          └ <class 'urllib3.exceptions.NewConnectionError'>

urllib3.exceptions.NewConnectionError: <urllib3.connection.HTTPConnection object at 0x7f91604a12b0>: Failed to establish a new connection: [Errno 111] Connection refused


During handling of the above exception, another exception occurred:


Traceback (most recent call last):

  File "/home/chase/.local/lib/python3.8/site-packages/requests/adapters.py", line 439, in send
    resp = conn.urlopen(
           │    └ <function HTTPConnectionPool.urlopen at 0x7f92585c0820>
           └ <urllib3.connectionpool.HTTPConnectionPool object at 0x7f91601e8a30>
  File "/home/chase/.local/lib/python3.8/site-packages/urllib3/connectionpool.py", line 755, in urlopen
    retries = retries.increment(
              │       └ <function Retry.increment at 0x7f9258608b80>
              └ Retry(total=0, connect=None, read=False, redirect=None, status=None)
  File "/home/chase/.local/lib/python3.8/site-packages/urllib3/util/retry.py", line 574, in increment
    raise MaxRetryError(_pool, url, error or ResponseError(cause))
          │             │      │    │        │             └ 'unknown'
          │             │      │    │        └ <class 'urllib3.exceptions.ResponseError'>
          │             │      │    └ NewConnectionError('<urllib3.connection.HTTPConnection object at 0x7f91604a12b0>: Failed to establish a new connection: [Errn...
          │             │      └ '/search-platform/front/search'
          │             └ <urllib3.connectionpool.HTTPConnectionPool object at 0x7f91601e8a30>
          └ <class 'urllib3.exceptions.MaxRetryError'>

urllib3.exceptions.MaxRetryError: HTTPConnectionPool(host='search.people.cn', port=80): Max retries exceeded with url: /search-platform/front/search (Caused by NewConnectionError('<urllib3.connection.HTTPConnection object at 0x7f91604a12b0>: Failed to establish a new connection: [Errno 111] Connection refused'))


During handling of the above exception, another exception occurred:


Traceback (most recent call last):

  File "/usr/lib/python3.8/threading.py", line 890, in _bootstrap
    self._bootstrap_inner()
    │    └ <function Thread._bootstrap_inner at 0x7f927a614a60>
    └ <Thread(Thread-22, started daemon 140261996873472)>
  File "/usr/lib/python3.8/threading.py", line 932, in _bootstrap_inner
    self.run()
    │    └ <function Thread.run at 0x7f927a614790>
    └ <Thread(Thread-22, started daemon 140261996873472)>
  File "/usr/lib/python3.8/threading.py", line 870, in run
    self._target(*self._args, **self._kwargs)
    │    │        │    │        │    └ {}
    │    │        │    │        └ <Thread(Thread-22, started daemon 140261996873472)>
    │    │        │    └ ('ProjectManager.run_func_by_thread',)
    │    │        └ <Thread(Thread-22, started daemon 140261996873472)>
    │    └ <bound method ProjectManager.get_request_from_keywords_hot of <monitor.projectManager.ProjectManager object at 0x7f9162af4700>>
    └ <Thread(Thread-22, started daemon 140261996873472)>

  File "/home/users/Scy/yuqing/spider/monitor/projectManager.py", line 795, in get_request_from_keywords_hot
    self.search_spider_manager.crawl_by_keyword(
    │    │                     └ <function SearchSpidersManager.crawl_by_keyword at 0x7f9162b00040>
    │    └ <monitor.spiderManager.SearchSpidersManager object at 0x7f916270f0d0>
    └ <monitor.projectManager.ProjectManager object at 0x7f9162af4700>

  File "/home/users/Scy/yuqing/spider/monitor/spiderManager.py", line 118, in crawl_by_keyword
    self.crawl_by_keyword_signal_platform(project_names, platform, keyword, crawl_time, project_times)
    │    │                                │              │         │        │           └ {'default': <monitor.TimeSection object at 0x7f91628317f0>}
    │    │                                │              │         │        └ <monitor.TimeSection object at 0x7f91603edbe0>
    │    │                                │              │         └ '第78集团军某旅：“伴随保障”强化战场意识'
    │    │                                │              └ '人民网'
    │    │                                └ ['default']
    │    └ <function SearchSpidersManager.crawl_by_keyword_signal_platform at 0x7f9162b000d0>
    └ <monitor.spiderManager.SearchSpidersManager object at 0x7f916270f0d0>

  File "/home/users/Scy/yuqing/spider/monitor/spiderManager.py", line 134, in crawl_by_keyword_signal_platform
    requests = self.get_request_from_keyword(platform, keyword, **crawl_time.to_dict())
               │    │                        │         │          │          └ <function TimeSection.to_dict at 0x7f925aaa8550>
               │    │                        │         │          └ <monitor.TimeSection object at 0x7f91603edbe0>
               │    │                        │         └ '第78集团军某旅：“伴随保障”强化战场意识'
               │    │                        └ '人民网'
               │    └ <function SearchSpidersManager.get_request_from_keyword at 0x7f9162b001f0>
               └ <monitor.spiderManager.SearchSpidersManager object at 0x7f916270f0d0>

  File "/home/users/Scy/yuqing/spider/monitor/spiderManager.py", line 191, in get_request_from_keyword
    for request in self.spiders[platform].get_request_from_keyword(headers, search_url, keyword, content_url,
                   │    │       │                                  │        │           │        └ <string.Template object at 0x7f916016cf40>
                   │    │       │                                  │        │           └ '第78集团军某旅：“伴随保障”强化战场意识'
                   │    │       │                                  │        └ <string.Template object at 0x7f91485d6520>
                   │    │       │                                  └ {'Accept': 'application/json, text/plain, */*', 'Accept-Language': 'zh-CN,zh;q=0.9', 'Connection': 'keep-alive', 'Origin': 'h...
                   │    │       └ '人民网'
                   │    └ {'凤凰网': <monitor.searchSpiders.ifeng.Ifeng object at 0x7f916270f220>, '头条': <monitor.searchSpiders.toutiao.Toutiao object at ...
                   └ <monitor.spiderManager.SearchSpidersManager object at 0x7f916270f0d0>

> File "/home/users/Scy/yuqing/spider/monitor/searchSpiders/people.py", line 28, in get_request_from_keyword
    response = requests.post(search_url.substitute(), json=data, headers=headers)
               │        │    │          │                  │             └ {'Accept': 'application/json, text/plain, */*', 'Accept-Language': 'zh-CN,zh;q=0.9', 'Connection': 'keep-alive', 'Origin': 'h...
               │        │    │          │                  └ {'key': '第78集团军某旅：“伴随保障”强化战场意识', 'page': 1, 'limit': 10, 'hasTitle': True, 'hasContent': True, 'isFuzzy': True, 'type': 0, 's...
               │        │    │          └ <function Template.substitute at 0x7f927a5fd0d0>
               │        │    └ <string.Template object at 0x7f91485d6520>
               │        └ <function post at 0x7f92583e73a0>
               └ <module 'requests' from '/home/chase/.local/lib/python3.8/site-packages/requests/__init__.py'>

  File "/home/chase/.local/lib/python3.8/site-packages/requests/api.py", line 117, in post
    return request('post', url, data=data, json=json, **kwargs)
           │               │         │          │       └ {'headers': {'Accept': 'application/json, text/plain, */*', 'Accept-Language': 'zh-CN,zh;q=0.9', 'Connection': 'keep-alive', ...
           │               │         │          └ {'key': '第78集团军某旅：“伴随保障”强化战场意识', 'page': 1, 'limit': 10, 'hasTitle': True, 'hasContent': True, 'isFuzzy': True, 'type': 0, 's...
           │               │         └ None
           │               └ 'http://search.people.cn/search-platform/front/search'
           └ <function request at 0x7f9258455040>
  File "/home/chase/.local/lib/python3.8/site-packages/requests/api.py", line 61, in request
    return session.request(method=method, url=url, **kwargs)
           │       │              │           │      └ {'data': None, 'json': {'key': '第78集团军某旅：“伴随保障”强化战场意识', 'page': 1, 'limit': 10, 'hasTitle': True, 'hasContent': True, 'isFuzz...
           │       │              │           └ 'http://search.people.cn/search-platform/front/search'
           │       │              └ 'post'
           │       └ <function Session.request at 0x7f92583e6940>
           └ <requests.sessions.Session object at 0x7f91487aa0d0>
  File "/home/chase/.local/lib/python3.8/site-packages/requests/sessions.py", line 542, in request
    resp = self.send(prep, **send_kwargs)
           │    │    │       └ {'timeout': None, 'allow_redirects': True, 'verify': True, 'proxies': OrderedDict(), 'stream': False, 'cert': None}
           │    │    └ <PreparedRequest [POST]>
           │    └ <function Session.send at 0x7f92583e6dc0>
           └ <requests.sessions.Session object at 0x7f91487aa0d0>
  File "/home/chase/.local/lib/python3.8/site-packages/requests/sessions.py", line 655, in send
    r = adapter.send(request, **kwargs)
        │       │    │          └ {'timeout': None, 'verify': True, 'proxies': OrderedDict(), 'stream': False, 'cert': None}
        │       │    └ <PreparedRequest [POST]>
        │       └ <function HTTPAdapter.send at 0x7f92583e6280>
        └ <requests.adapters.HTTPAdapter object at 0x7f9160087af0>
  File "/home/chase/.local/lib/python3.8/site-packages/requests/adapters.py", line 516, in send
    raise ConnectionError(e, request=request)
          │                          └ <PreparedRequest [POST]>
          └ <class 'requests.exceptions.ConnectionError'>

requests.exceptions.ConnectionError: HTTPConnectionPool(host='search.people.cn', port=80): Max retries exceeded with url: /search-platform/front/search (Caused by NewConnectionError('<urllib3.connection.HTTPConnection object at 0x7f91604a12b0>: Failed to establish a new connection: [Errno 111] Connection refused'))
2022-05-12 15:33:08.037 | ERROR    | monitor.searchSpiders.people:get_request_from_keyword:45 - E 人民网错误HTTPConnectionPool(host='search.people.cn', port=80): Max retries exceeded with url: /search-platform/front/search (Caused by NewConnectionError('<urllib3.connection.HTTPConnection object at 0x7f9160165ee0>: Failed to establish a new connection: [Errno 111] Connection refused'))
Traceback (most recent call last):

  File "/home/chase/.local/lib/python3.8/site-packages/urllib3/connection.py", line 174, in _new_conn
    conn = connection.create_connection(
           │          └ <function create_connection at 0x7f92585fd1f0>
           └ <module 'urllib3.util.connection' from '/home/chase/.local/lib/python3.8/site-packages/urllib3/util/connection.py'>
  File "/home/chase/.local/lib/python3.8/site-packages/urllib3/util/connection.py", line 96, in create_connection
    raise err
          └ ConnectionRefusedError(111, 'Connection refused')
  File "/home/chase/.local/lib/python3.8/site-packages/urllib3/util/connection.py", line 86, in create_connection
    sock.connect(sa)
    │            └ ('1.31.128.250', 80)
    └ None

ConnectionRefusedError: [Errno 111] Connection refused


During handling of the above exception, another exception occurred:


Traceback (most recent call last):

  File "/home/chase/.local/lib/python3.8/site-packages/urllib3/connectionpool.py", line 699, in urlopen
    httplib_response = self._make_request(
                       │    └ <function HTTPConnectionPool._make_request at 0x7f92585c05e0>
                       └ <urllib3.connectionpool.HTTPConnectionPool object at 0x7f9148784160>
  File "/home/chase/.local/lib/python3.8/site-packages/urllib3/connectionpool.py", line 394, in _make_request
    conn.request(method, url, **httplib_request_kw)
    │    │       │       │      └ {'body': b'{"key": "\\u7b2c78\\u96c6\\u56e2\\u519b\\u67d0\\u65c5\\uff1a\\u201c\\u4f34\\u968f\\u4fdd\\u969c\\u201d\\u5f3a\\u53...
    │    │       │       └ '/search-platform/front/search'
    │    │       └ 'POST'
    │    └ <function HTTPConnection.request at 0x7f92585b0f70>
    └ <urllib3.connection.HTTPConnection object at 0x7f9160165ee0>
  File "/home/chase/.local/lib/python3.8/site-packages/urllib3/connection.py", line 239, in request
    super(HTTPConnection, self).request(method, url, body=body, headers=headers)
          │               │             │       │         │             └ {'User-Agent': 'Mozilla/5.0 (Windows NT 10.0; Win64; x64) AppleWebKit/537.36 (KHTML, like Gecko) Chrome/101.0.4951.54 Safari/...
          │               │             │       │         └ b'{"key": "\\u7b2c78\\u96c6\\u56e2\\u519b\\u67d0\\u65c5\\uff1a\\u201c\\u4f34\\u968f\\u4fdd\\u969c\\u201d\\u5f3a\\u5316\\u6218...
          │               │             │       └ '/search-platform/front/search'
          │               │             └ 'POST'
          │               └ <urllib3.connection.HTTPConnection object at 0x7f9160165ee0>
          └ <class 'urllib3.connection.HTTPConnection'>
  File "/usr/lib/python3.8/http/client.py", line 1256, in request
    self._send_request(method, url, body, headers, encode_chunked)
    │    │             │       │    │     │        └ False
    │    │             │       │    │     └ {'User-Agent': 'Mozilla/5.0 (Windows NT 10.0; Win64; x64) AppleWebKit/537.36 (KHTML, like Gecko) Chrome/101.0.4951.54 Safari/...
    │    │             │       │    └ b'{"key": "\\u7b2c78\\u96c6\\u56e2\\u519b\\u67d0\\u65c5\\uff1a\\u201c\\u4f34\\u968f\\u4fdd\\u969c\\u201d\\u5f3a\\u5316\\u6218...
    │    │             │       └ '/search-platform/front/search'
    │    │             └ 'POST'
    │    └ <function HTTPConnection._send_request at 0x7f926be50280>
    └ <urllib3.connection.HTTPConnection object at 0x7f9160165ee0>
  File "/usr/lib/python3.8/http/client.py", line 1302, in _send_request
    self.endheaders(body, encode_chunked=encode_chunked)
    │    │          │                    └ False
    │    │          └ b'{"key": "\\u7b2c78\\u96c6\\u56e2\\u519b\\u67d0\\u65c5\\uff1a\\u201c\\u4f34\\u968f\\u4fdd\\u969c\\u201d\\u5f3a\\u5316\\u6218...
    │    └ <function HTTPConnection.endheaders at 0x7f926be50160>
    └ <urllib3.connection.HTTPConnection object at 0x7f9160165ee0>
  File "/usr/lib/python3.8/http/client.py", line 1251, in endheaders
    self._send_output(message_body, encode_chunked=encode_chunked)
    │    │            │                            └ False
    │    │            └ b'{"key": "\\u7b2c78\\u96c6\\u56e2\\u519b\\u67d0\\u65c5\\uff1a\\u201c\\u4f34\\u968f\\u4fdd\\u969c\\u201d\\u5f3a\\u5316\\u6218...
    │    └ <function HTTPConnection._send_output at 0x7f926beb7d30>
    └ <urllib3.connection.HTTPConnection object at 0x7f9160165ee0>
  File "/usr/lib/python3.8/http/client.py", line 1011, in _send_output
    self.send(msg)
    │    │    └ b'POST /search-platform/front/search HTTP/1.1\r\nHost: search.people.cn\r\nUser-Agent: Mozilla/5.0 (Windows NT 10.0; Win64; x...
    │    └ <function HTTPConnection.send at 0x7f926beb7b80>
    └ <urllib3.connection.HTTPConnection object at 0x7f9160165ee0>
  File "/usr/lib/python3.8/http/client.py", line 951, in send
    self.connect()
    │    └ <function HTTPConnection.connect at 0x7f92585b0dc0>
    └ <urllib3.connection.HTTPConnection object at 0x7f9160165ee0>
  File "/home/chase/.local/lib/python3.8/site-packages/urllib3/connection.py", line 205, in connect
    conn = self._new_conn()
           │    └ <function HTTPConnection._new_conn at 0x7f92585b0c10>
           └ <urllib3.connection.HTTPConnection object at 0x7f9160165ee0>
  File "/home/chase/.local/lib/python3.8/site-packages/urllib3/connection.py", line 186, in _new_conn
    raise NewConnectionError(
          └ <class 'urllib3.exceptions.NewConnectionError'>

urllib3.exceptions.NewConnectionError: <urllib3.connection.HTTPConnection object at 0x7f9160165ee0>: Failed to establish a new connection: [Errno 111] Connection refused


During handling of the above exception, another exception occurred:


Traceback (most recent call last):

  File "/home/chase/.local/lib/python3.8/site-packages/requests/adapters.py", line 439, in send
    resp = conn.urlopen(
           │    └ <function HTTPConnectionPool.urlopen at 0x7f92585c0820>
           └ <urllib3.connectionpool.HTTPConnectionPool object at 0x7f9148784160>
  File "/home/chase/.local/lib/python3.8/site-packages/urllib3/connectionpool.py", line 755, in urlopen
    retries = retries.increment(
              │       └ <function Retry.increment at 0x7f9258608b80>
              └ Retry(total=0, connect=None, read=False, redirect=None, status=None)
  File "/home/chase/.local/lib/python3.8/site-packages/urllib3/util/retry.py", line 574, in increment
    raise MaxRetryError(_pool, url, error or ResponseError(cause))
          │             │      │    │        │             └ 'unknown'
          │             │      │    │        └ <class 'urllib3.exceptions.ResponseError'>
          │             │      │    └ NewConnectionError('<urllib3.connection.HTTPConnection object at 0x7f9160165ee0>: Failed to establish a new connection: [Errn...
          │             │      └ '/search-platform/front/search'
          │             └ <urllib3.connectionpool.HTTPConnectionPool object at 0x7f9148784160>
          └ <class 'urllib3.exceptions.MaxRetryError'>

urllib3.exceptions.MaxRetryError: HTTPConnectionPool(host='search.people.cn', port=80): Max retries exceeded with url: /search-platform/front/search (Caused by NewConnectionError('<urllib3.connection.HTTPConnection object at 0x7f9160165ee0>: Failed to establish a new connection: [Errno 111] Connection refused'))


During handling of the above exception, another exception occurred:


Traceback (most recent call last):

  File "/usr/lib/python3.8/threading.py", line 890, in _bootstrap
    self._bootstrap_inner()
    │    └ <function Thread._bootstrap_inner at 0x7f927a614a60>
    └ <Thread(Thread-47, started daemon 140261971695360)>
  File "/usr/lib/python3.8/threading.py", line 932, in _bootstrap_inner
    self.run()
    │    └ <function Thread.run at 0x7f927a614790>
    └ <Thread(Thread-47, started daemon 140261971695360)>
  File "/usr/lib/python3.8/threading.py", line 870, in run
    self._target(*self._args, **self._kwargs)
    │    │        │    │        │    └ {}
    │    │        │    │        └ <Thread(Thread-47, started daemon 140261971695360)>
    │    │        │    └ ('ProjectManager.run_func_by_thread',)
    │    │        └ <Thread(Thread-47, started daemon 140261971695360)>
    │    └ <bound method ProjectManager.get_request_from_keywords_hot of <monitor.projectManager.ProjectManager object at 0x7f9162af4700>>
    └ <Thread(Thread-47, started daemon 140261971695360)>

  File "/home/users/Scy/yuqing/spider/monitor/projectManager.py", line 795, in get_request_from_keywords_hot
    self.search_spider_manager.crawl_by_keyword(
    │    │                     └ <function SearchSpidersManager.crawl_by_keyword at 0x7f9162b00040>
    │    └ <monitor.spiderManager.SearchSpidersManager object at 0x7f916270f0d0>
    └ <monitor.projectManager.ProjectManager object at 0x7f9162af4700>

  File "/home/users/Scy/yuqing/spider/monitor/spiderManager.py", line 118, in crawl_by_keyword
    self.crawl_by_keyword_signal_platform(project_names, platform, keyword, crawl_time, project_times)
    │    │                                │              │         │        │           └ {'default': <monitor.TimeSection object at 0x7f91628317f0>}
    │    │                                │              │         │        └ <monitor.TimeSection object at 0x7f91603f2520>
    │    │                                │              │         └ '第78集团军某旅：“伴随保障”强化战场意识'
    │    │                                │              └ '人民网'
    │    │                                └ ['default']
    │    └ <function SearchSpidersManager.crawl_by_keyword_signal_platform at 0x7f9162b000d0>
    └ <monitor.spiderManager.SearchSpidersManager object at 0x7f916270f0d0>

  File "/home/users/Scy/yuqing/spider/monitor/spiderManager.py", line 134, in crawl_by_keyword_signal_platform
    requests = self.get_request_from_keyword(platform, keyword, **crawl_time.to_dict())
               │    │                        │         │          │          └ <function TimeSection.to_dict at 0x7f925aaa8550>
               │    │                        │         │          └ <monitor.TimeSection object at 0x7f91603f2520>
               │    │                        │         └ '第78集团军某旅：“伴随保障”强化战场意识'
               │    │                        └ '人民网'
               │    └ <function SearchSpidersManager.get_request_from_keyword at 0x7f9162b001f0>
               └ <monitor.spiderManager.SearchSpidersManager object at 0x7f916270f0d0>

  File "/home/users/Scy/yuqing/spider/monitor/spiderManager.py", line 191, in get_request_from_keyword
    for request in self.spiders[platform].get_request_from_keyword(headers, search_url, keyword, content_url,
                   │    │       │                                  │        │           │        └ <string.Template object at 0x7f9148584580>
                   │    │       │                                  │        │           └ '第78集团军某旅：“伴随保障”强化战场意识'
                   │    │       │                                  │        └ <string.Template object at 0x7f9160087910>
                   │    │       │                                  └ {'Accept': 'application/json, text/plain, */*', 'Accept-Language': 'zh-CN,zh;q=0.9', 'Connection': 'keep-alive', 'Origin': 'h...
                   │    │       └ '人民网'
                   │    └ {'凤凰网': <monitor.searchSpiders.ifeng.Ifeng object at 0x7f916270f220>, '头条': <monitor.searchSpiders.toutiao.Toutiao object at ...
                   └ <monitor.spiderManager.SearchSpidersManager object at 0x7f916270f0d0>

> File "/home/users/Scy/yuqing/spider/monitor/searchSpiders/people.py", line 28, in get_request_from_keyword
    response = requests.post(search_url.substitute(), json=data, headers=headers)
               │        │    │          │                  │             └ {'Accept': 'application/json, text/plain, */*', 'Accept-Language': 'zh-CN,zh;q=0.9', 'Connection': 'keep-alive', 'Origin': 'h...
               │        │    │          │                  └ {'key': '第78集团军某旅：“伴随保障”强化战场意识', 'page': 1, 'limit': 10, 'hasTitle': True, 'hasContent': True, 'isFuzzy': True, 'type': 0, 's...
               │        │    │          └ <function Template.substitute at 0x7f927a5fd0d0>
               │        │    └ <string.Template object at 0x7f9160087910>
               │        └ <function post at 0x7f92583e73a0>
               └ <module 'requests' from '/home/chase/.local/lib/python3.8/site-packages/requests/__init__.py'>

  File "/home/chase/.local/lib/python3.8/site-packages/requests/api.py", line 117, in post
    return request('post', url, data=data, json=json, **kwargs)
           │               │         │          │       └ {'headers': {'Accept': 'application/json, text/plain, */*', 'Accept-Language': 'zh-CN,zh;q=0.9', 'Connection': 'keep-alive', ...
           │               │         │          └ {'key': '第78集团军某旅：“伴随保障”强化战场意识', 'page': 1, 'limit': 10, 'hasTitle': True, 'hasContent': True, 'isFuzzy': True, 'type': 0, 's...
           │               │         └ None
           │               └ 'http://search.people.cn/search-platform/front/search'
           └ <function request at 0x7f9258455040>
  File "/home/chase/.local/lib/python3.8/site-packages/requests/api.py", line 61, in request
    return session.request(method=method, url=url, **kwargs)
           │       │              │           │      └ {'data': None, 'json': {'key': '第78集团军某旅：“伴随保障”强化战场意识', 'page': 1, 'limit': 10, 'hasTitle': True, 'hasContent': True, 'isFuzz...
           │       │              │           └ 'http://search.people.cn/search-platform/front/search'
           │       │              └ 'post'
           │       └ <function Session.request at 0x7f92583e6940>
           └ <requests.sessions.Session object at 0x7f91485f13a0>
  File "/home/chase/.local/lib/python3.8/site-packages/requests/sessions.py", line 542, in request
    resp = self.send(prep, **send_kwargs)
           │    │    │       └ {'timeout': None, 'allow_redirects': True, 'verify': True, 'proxies': OrderedDict(), 'stream': False, 'cert': None}
           │    │    └ <PreparedRequest [POST]>
           │    └ <function Session.send at 0x7f92583e6dc0>
           └ <requests.sessions.Session object at 0x7f91485f13a0>
  File "/home/chase/.local/lib/python3.8/site-packages/requests/sessions.py", line 655, in send
    r = adapter.send(request, **kwargs)
        │       │    │          └ {'timeout': None, 'verify': True, 'proxies': OrderedDict(), 'stream': False, 'cert': None}
        │       │    └ <PreparedRequest [POST]>
        │       └ <function HTTPAdapter.send at 0x7f92583e6280>
        └ <requests.adapters.HTTPAdapter object at 0x7f9160087df0>
  File "/home/chase/.local/lib/python3.8/site-packages/requests/adapters.py", line 516, in send
    raise ConnectionError(e, request=request)
          │                          └ <PreparedRequest [POST]>
          └ <class 'requests.exceptions.ConnectionError'>

requests.exceptions.ConnectionError: HTTPConnectionPool(host='search.people.cn', port=80): Max retries exceeded with url: /search-platform/front/search (Caused by NewConnectionError('<urllib3.connection.HTTPConnection object at 0x7f9160165ee0>: Failed to establish a new connection: [Errno 111] Connection refused'))
2022-05-12 15:33:09.684 | ERROR    | monitor.searchSpiders.people:get_request_from_keyword:45 - E 人民网错误HTTPConnectionPool(host='search.people.cn', port=80): Max retries exceeded with url: /search-platform/front/search (Caused by NewConnectionError('<urllib3.connection.HTTPConnection object at 0x7f9148783610>: Failed to establish a new connection: [Errno 111] Connection refused'))
Traceback (most recent call last):

  File "/home/chase/.local/lib/python3.8/site-packages/urllib3/connection.py", line 174, in _new_conn
    conn = connection.create_connection(
           │          └ <function create_connection at 0x7f92585fd1f0>
           └ <module 'urllib3.util.connection' from '/home/chase/.local/lib/python3.8/site-packages/urllib3/util/connection.py'>
  File "/home/chase/.local/lib/python3.8/site-packages/urllib3/util/connection.py", line 96, in create_connection
    raise err
          └ ConnectionRefusedError(111, 'Connection refused')
  File "/home/chase/.local/lib/python3.8/site-packages/urllib3/util/connection.py", line 86, in create_connection
    sock.connect(sa)
    │            └ ('1.31.128.250', 80)
    └ None

ConnectionRefusedError: [Errno 111] Connection refused


During handling of the above exception, another exception occurred:


Traceback (most recent call last):

  File "/home/chase/.local/lib/python3.8/site-packages/urllib3/connectionpool.py", line 699, in urlopen
    httplib_response = self._make_request(
                       │    └ <function HTTPConnectionPool._make_request at 0x7f92585c05e0>
                       └ <urllib3.connectionpool.HTTPConnectionPool object at 0x7f91601dc760>
  File "/home/chase/.local/lib/python3.8/site-packages/urllib3/connectionpool.py", line 394, in _make_request
    conn.request(method, url, **httplib_request_kw)
    │    │       │       │      └ {'body': b'{"key": "\\u201c\\u4e91\\u7aef\\u201d\\u5c0f\\u6751", "page": 1, "limit": 10, "hasTitle": true, "hasContent": true...
    │    │       │       └ '/search-platform/front/search'
    │    │       └ 'POST'
    │    └ <function HTTPConnection.request at 0x7f92585b0f70>
    └ <urllib3.connection.HTTPConnection object at 0x7f9148783610>
  File "/home/chase/.local/lib/python3.8/site-packages/urllib3/connection.py", line 239, in request
    super(HTTPConnection, self).request(method, url, body=body, headers=headers)
          │               │             │       │         │             └ {'User-Agent': 'Mozilla/5.0 (Windows NT 10.0; Win64; x64) AppleWebKit/537.36 (KHTML, like Gecko) Chrome/101.0.4951.54 Safari/...
          │               │             │       │         └ b'{"key": "\\u201c\\u4e91\\u7aef\\u201d\\u5c0f\\u6751", "page": 1, "limit": 10, "hasTitle": true, "hasContent": true, "isFuzz...
          │               │             │       └ '/search-platform/front/search'
          │               │             └ 'POST'
          │               └ <urllib3.connection.HTTPConnection object at 0x7f9148783610>
          └ <class 'urllib3.connection.HTTPConnection'>
  File "/usr/lib/python3.8/http/client.py", line 1256, in request
    self._send_request(method, url, body, headers, encode_chunked)
    │    │             │       │    │     │        └ False
    │    │             │       │    │     └ {'User-Agent': 'Mozilla/5.0 (Windows NT 10.0; Win64; x64) AppleWebKit/537.36 (KHTML, like Gecko) Chrome/101.0.4951.54 Safari/...
    │    │             │       │    └ b'{"key": "\\u201c\\u4e91\\u7aef\\u201d\\u5c0f\\u6751", "page": 1, "limit": 10, "hasTitle": true, "hasContent": true, "isFuzz...
    │    │             │       └ '/search-platform/front/search'
    │    │             └ 'POST'
    │    └ <function HTTPConnection._send_request at 0x7f926be50280>
    └ <urllib3.connection.HTTPConnection object at 0x7f9148783610>
  File "/usr/lib/python3.8/http/client.py", line 1302, in _send_request
    self.endheaders(body, encode_chunked=encode_chunked)
    │    │          │                    └ False
    │    │          └ b'{"key": "\\u201c\\u4e91\\u7aef\\u201d\\u5c0f\\u6751", "page": 1, "limit": 10, "hasTitle": true, "hasContent": true, "isFuzz...
    │    └ <function HTTPConnection.endheaders at 0x7f926be50160>
    └ <urllib3.connection.HTTPConnection object at 0x7f9148783610>
  File "/usr/lib/python3.8/http/client.py", line 1251, in endheaders
    self._send_output(message_body, encode_chunked=encode_chunked)
    │    │            │                            └ False
    │    │            └ b'{"key": "\\u201c\\u4e91\\u7aef\\u201d\\u5c0f\\u6751", "page": 1, "limit": 10, "hasTitle": true, "hasContent": true, "isFuzz...
    │    └ <function HTTPConnection._send_output at 0x7f926beb7d30>
    └ <urllib3.connection.HTTPConnection object at 0x7f9148783610>
  File "/usr/lib/python3.8/http/client.py", line 1011, in _send_output
    self.send(msg)
    │    │    └ b'POST /search-platform/front/search HTTP/1.1\r\nHost: search.people.cn\r\nUser-Agent: Mozilla/5.0 (Windows NT 10.0; Win64; x...
    │    └ <function HTTPConnection.send at 0x7f926beb7b80>
    └ <urllib3.connection.HTTPConnection object at 0x7f9148783610>
  File "/usr/lib/python3.8/http/client.py", line 951, in send
    self.connect()
    │    └ <function HTTPConnection.connect at 0x7f92585b0dc0>
    └ <urllib3.connection.HTTPConnection object at 0x7f9148783610>
  File "/home/chase/.local/lib/python3.8/site-packages/urllib3/connection.py", line 205, in connect
    conn = self._new_conn()
           │    └ <function HTTPConnection._new_conn at 0x7f92585b0c10>
           └ <urllib3.connection.HTTPConnection object at 0x7f9148783610>
  File "/home/chase/.local/lib/python3.8/site-packages/urllib3/connection.py", line 186, in _new_conn
    raise NewConnectionError(
          └ <class 'urllib3.exceptions.NewConnectionError'>

urllib3.exceptions.NewConnectionError: <urllib3.connection.HTTPConnection object at 0x7f9148783610>: Failed to establish a new connection: [Errno 111] Connection refused


During handling of the above exception, another exception occurred:


Traceback (most recent call last):

  File "/home/chase/.local/lib/python3.8/site-packages/requests/adapters.py", line 439, in send
    resp = conn.urlopen(
           │    └ <function HTTPConnectionPool.urlopen at 0x7f92585c0820>
           └ <urllib3.connectionpool.HTTPConnectionPool object at 0x7f91601dc760>
  File "/home/chase/.local/lib/python3.8/site-packages/urllib3/connectionpool.py", line 755, in urlopen
    retries = retries.increment(
              │       └ <function Retry.increment at 0x7f9258608b80>
              └ Retry(total=0, connect=None, read=False, redirect=None, status=None)
  File "/home/chase/.local/lib/python3.8/site-packages/urllib3/util/retry.py", line 574, in increment
    raise MaxRetryError(_pool, url, error or ResponseError(cause))
          │             │      │    │        │             └ 'unknown'
          │             │      │    │        └ <class 'urllib3.exceptions.ResponseError'>
          │             │      │    └ NewConnectionError('<urllib3.connection.HTTPConnection object at 0x7f9148783610>: Failed to establish a new connection: [Errn...
          │             │      └ '/search-platform/front/search'
          │             └ <urllib3.connectionpool.HTTPConnectionPool object at 0x7f91601dc760>
          └ <class 'urllib3.exceptions.MaxRetryError'>

urllib3.exceptions.MaxRetryError: HTTPConnectionPool(host='search.people.cn', port=80): Max retries exceeded with url: /search-platform/front/search (Caused by NewConnectionError('<urllib3.connection.HTTPConnection object at 0x7f9148783610>: Failed to establish a new connection: [Errno 111] Connection refused'))


During handling of the above exception, another exception occurred:


Traceback (most recent call last):

  File "/usr/lib/python3.8/threading.py", line 890, in _bootstrap
    self._bootstrap_inner()
    │    └ <function Thread._bootstrap_inner at 0x7f927a614a60>
    └ <Thread(Thread-60, started daemon 140261401286400)>
  File "/usr/lib/python3.8/threading.py", line 932, in _bootstrap_inner
    self.run()
    │    └ <function Thread.run at 0x7f927a614790>
    └ <Thread(Thread-60, started daemon 140261401286400)>
  File "/usr/lib/python3.8/threading.py", line 870, in run
    self._target(*self._args, **self._kwargs)
    │    │        │    │        │    └ {}
    │    │        │    │        └ <Thread(Thread-60, started daemon 140261401286400)>
    │    │        │    └ ('ProjectManager.run_func_by_thread',)
    │    │        └ <Thread(Thread-60, started daemon 140261401286400)>
    │    └ <bound method ProjectManager.get_request_from_keywords_hot of <monitor.projectManager.ProjectManager object at 0x7f9162af4700>>
    └ <Thread(Thread-60, started daemon 140261401286400)>

  File "/home/users/Scy/yuqing/spider/monitor/projectManager.py", line 795, in get_request_from_keywords_hot
    self.search_spider_manager.crawl_by_keyword(
    │    │                     └ <function SearchSpidersManager.crawl_by_keyword at 0x7f9162b00040>
    │    └ <monitor.spiderManager.SearchSpidersManager object at 0x7f916270f0d0>
    └ <monitor.projectManager.ProjectManager object at 0x7f9162af4700>

  File "/home/users/Scy/yuqing/spider/monitor/spiderManager.py", line 118, in crawl_by_keyword
    self.crawl_by_keyword_signal_platform(project_names, platform, keyword, crawl_time, project_times)
    │    │                                │              │         │        │           └ {'default': <monitor.TimeSection object at 0x7f91628317f0>}
    │    │                                │              │         │        └ <monitor.TimeSection object at 0x7f9160459ee0>
    │    │                                │              │         └ '“云端”小村'
    │    │                                │              └ '人民网'
    │    │                                └ ['default']
    │    └ <function SearchSpidersManager.crawl_by_keyword_signal_platform at 0x7f9162b000d0>
    └ <monitor.spiderManager.SearchSpidersManager object at 0x7f916270f0d0>

  File "/home/users/Scy/yuqing/spider/monitor/spiderManager.py", line 134, in crawl_by_keyword_signal_platform
    requests = self.get_request_from_keyword(platform, keyword, **crawl_time.to_dict())
               │    │                        │         │          │          └ <function TimeSection.to_dict at 0x7f925aaa8550>
               │    │                        │         │          └ <monitor.TimeSection object at 0x7f9160459ee0>
               │    │                        │         └ '“云端”小村'
               │    │                        └ '人民网'
               │    └ <function SearchSpidersManager.get_request_from_keyword at 0x7f9162b001f0>
               └ <monitor.spiderManager.SearchSpidersManager object at 0x7f916270f0d0>

  File "/home/users/Scy/yuqing/spider/monitor/spiderManager.py", line 191, in get_request_from_keyword
    for request in self.spiders[platform].get_request_from_keyword(headers, search_url, keyword, content_url,
                   │    │       │                                  │        │           │        └ <string.Template object at 0x7f91485c2100>
                   │    │       │                                  │        │           └ '“云端”小村'
                   │    │       │                                  │        └ <string.Template object at 0x7f916011c730>
                   │    │       │                                  └ {'Accept': 'application/json, text/plain, */*', 'Accept-Language': 'zh-CN,zh;q=0.9', 'Connection': 'keep-alive', 'Origin': 'h...
                   │    │       └ '人民网'
                   │    └ {'凤凰网': <monitor.searchSpiders.ifeng.Ifeng object at 0x7f916270f220>, '头条': <monitor.searchSpiders.toutiao.Toutiao object at ...
                   └ <monitor.spiderManager.SearchSpidersManager object at 0x7f916270f0d0>

> File "/home/users/Scy/yuqing/spider/monitor/searchSpiders/people.py", line 28, in get_request_from_keyword
    response = requests.post(search_url.substitute(), json=data, headers=headers)
               │        │    │          │                  │             └ {'Accept': 'application/json, text/plain, */*', 'Accept-Language': 'zh-CN,zh;q=0.9', 'Connection': 'keep-alive', 'Origin': 'h...
               │        │    │          │                  └ {'key': '“云端”小村', 'page': 1, 'limit': 10, 'hasTitle': True, 'hasContent': True, 'isFuzzy': True, 'type': 0, 'sortType': 2, 's...
               │        │    │          └ <function Template.substitute at 0x7f927a5fd0d0>
               │        │    └ <string.Template object at 0x7f916011c730>
               │        └ <function post at 0x7f92583e73a0>
               └ <module 'requests' from '/home/chase/.local/lib/python3.8/site-packages/requests/__init__.py'>

  File "/home/chase/.local/lib/python3.8/site-packages/requests/api.py", line 117, in post
    return request('post', url, data=data, json=json, **kwargs)
           │               │         │          │       └ {'headers': {'Accept': 'application/json, text/plain, */*', 'Accept-Language': 'zh-CN,zh;q=0.9', 'Connection': 'keep-alive', ...
           │               │         │          └ {'key': '“云端”小村', 'page': 1, 'limit': 10, 'hasTitle': True, 'hasContent': True, 'isFuzzy': True, 'type': 0, 'sortType': 2, 's...
           │               │         └ None
           │               └ 'http://search.people.cn/search-platform/front/search'
           └ <function request at 0x7f9258455040>
  File "/home/chase/.local/lib/python3.8/site-packages/requests/api.py", line 61, in request
    return session.request(method=method, url=url, **kwargs)
           │       │              │           │      └ {'data': None, 'json': {'key': '“云端”小村', 'page': 1, 'limit': 10, 'hasTitle': True, 'hasContent': True, 'isFuzzy': True, 'type...
           │       │              │           └ 'http://search.people.cn/search-platform/front/search'
           │       │              └ 'post'
           │       └ <function Session.request at 0x7f92583e6940>
           └ <requests.sessions.Session object at 0x7f91604d75b0>
  File "/home/chase/.local/lib/python3.8/site-packages/requests/sessions.py", line 542, in request
    resp = self.send(prep, **send_kwargs)
           │    │    │       └ {'timeout': None, 'allow_redirects': True, 'verify': True, 'proxies': OrderedDict(), 'stream': False, 'cert': None}
           │    │    └ <PreparedRequest [POST]>
           │    └ <function Session.send at 0x7f92583e6dc0>
           └ <requests.sessions.Session object at 0x7f91604d75b0>
  File "/home/chase/.local/lib/python3.8/site-packages/requests/sessions.py", line 655, in send
    r = adapter.send(request, **kwargs)
        │       │    │          └ {'timeout': None, 'verify': True, 'proxies': OrderedDict(), 'stream': False, 'cert': None}
        │       │    └ <PreparedRequest [POST]>
        │       └ <function HTTPAdapter.send at 0x7f92583e6280>
        └ <requests.adapters.HTTPAdapter object at 0x7f91485f75b0>
  File "/home/chase/.local/lib/python3.8/site-packages/requests/adapters.py", line 516, in send
    raise ConnectionError(e, request=request)
          │                          └ <PreparedRequest [POST]>
          └ <class 'requests.exceptions.ConnectionError'>

requests.exceptions.ConnectionError: HTTPConnectionPool(host='search.people.cn', port=80): Max retries exceeded with url: /search-platform/front/search (Caused by NewConnectionError('<urllib3.connection.HTTPConnection object at 0x7f9148783610>: Failed to establish a new connection: [Errno 111] Connection refused'))
