2022-04-20 15:29:33.866 | ERROR    | __main__:get_request_from_keyword:36 - E 联合早报错误can only concatenate str (not "NoneType") to str
Traceback (most recent call last):

  File "/home/users/Scy/yuqing/spider/monitor/searchSpiders/lianhezb.py", line 53, in <module>
    for i in a.get_request_from_keyword(header, search_url, '石油'):
        │    │ │                        │       └ 'https://www.zaobao.com/search?pageNo={}&pageSize=10&keywords={}'
        │    │ │                        └ {'Proxy-Connection': 'keep-alive', 'Cache-Control': 'max-age=0', 'Upgrade-Insecure-Requests': '1', 'User-Agent': 'Mozilla/5.0...
        │    │ └ <function Lianhezb.get_request_from_keyword at 0x7fb690f1d280>
        │    └ <__main__.Lianhezb object at 0x7fb6b25abca0>
        └ <GET https://www.zaobao.com//realtime/world/story20220404-1259347>

> File "/home/users/Scy/yuqing/spider/monitor/searchSpiders/lianhezb.py", line 31, in get_request_from_keyword
    url = 'https://www.zaobao.com/' + d['url']
                                      └ {'id': '1259288', 'title': '消息：中国进口商拟购买廉价俄罗斯液化天然气', 'digest': None, 'contentPreview': '因应西方制裁措施，俄罗斯液化天然受到国际市场冷遇，中国进口商据悉正谨慎地寻求...

TypeError: can only concatenate str (not "NoneType") to str
2022-04-20 15:33:10.874 | ERROR    | __main__:get_request_from_keyword:36 - E 联合早报错误can only concatenate str (not "NoneType") to str
Traceback (most recent call last):

  File "/home/users/Scy/yuqing/spider/monitor/searchSpiders/lianhezb.py", line 53, in <module>
    for i in a.get_request_from_keyword(header, search_url, '石油'):
        │    │ │                        │       └ 'https://www.zaobao.com/search?pageNo={}&pageSize=10&keywords={}'
        │    │ │                        └ {'Proxy-Connection': 'keep-alive', 'Cache-Control': 'max-age=0', 'Upgrade-Insecure-Requests': '1', 'User-Agent': 'Mozilla/5.0...
        │    │ └ <function Lianhezb.get_request_from_keyword at 0x7f9943e85280>
        │    └ <__main__.Lianhezb object at 0x7f99654d3ca0>
        └ <GET https://www.zaobao.com//realtime/world/story20220404-1259347>

> File "/home/users/Scy/yuqing/spider/monitor/searchSpiders/lianhezb.py", line 31, in get_request_from_keyword
    url = 'https://www.zaobao.com/' + d['url']
                                      └ {'id': '1259288', 'title': '消息：中国进口商拟购买廉价俄罗斯液化天然气', 'digest': None, 'contentPreview': '因应西方制裁措施，俄罗斯液化天然受到国际市场冷遇，中国进口商据悉正谨慎地寻求...

TypeError: can only concatenate str (not "NoneType") to str
2022-04-20 17:04:19.476 | ERROR    | __main__:get_request_from_keyword:29 - E 复兴网错误Invalid URL 'fuxingwang': No schema supplied. Perhaps you meant http://fuxingwang?
Traceback (most recent call last):

  File "/home/users/Scy/yuqing/spider/monitor/searchSpiders/fuxingwang.py", line 45, in <module>
    for i in a.get_request_from_keyword(header, search_url, '石油'):
             │ │                        │       └ 'fuxingwang'
             │ │                        └ {'Connection': 'keep-alive', 'Cache-Control': 'max-age=0', 'Upgrade-Insecure-Requests': '1', 'User-Agent': 'Mozilla/5.0 (X11;...
             │ └ <function Douban.get_request_from_keyword at 0x7fa1ede89550>
             └ <__main__.Douban object at 0x7fa216120ca0>

> File "/home/users/Scy/yuqing/spider/monitor/searchSpiders/fuxingwang.py", line 20, in get_request_from_keyword
    request = requests.get(search_url, headers=headers)
              │        │   │                   └ {'Connection': 'keep-alive', 'Cache-Control': 'max-age=0', 'Upgrade-Insecure-Requests': '1', 'User-Agent': 'Mozilla/5.0 (X11;...
              │        │   └ 'fuxingwang'
              │        └ <function get at 0x7fa1f709f8b0>
              └ <module 'requests' from '/home/chase/.local/lib/python3.8/site-packages/requests/__init__.py'>

  File "/home/chase/.local/lib/python3.8/site-packages/requests/api.py", line 75, in get
    return request('get', url, params=params, **kwargs)
           │              │           │         └ {'headers': {'Connection': 'keep-alive', 'Cache-Control': 'max-age=0', 'Upgrade-Insecure-Requests': '1', 'User-Agent': 'Mozil...
           │              │           └ None
           │              └ 'fuxingwang'
           └ <function request at 0x7fa1f7094790>
  File "/home/chase/.local/lib/python3.8/site-packages/requests/api.py", line 61, in request
    return session.request(method=method, url=url, **kwargs)
           │       │              │           │      └ {'params': None, 'headers': {'Connection': 'keep-alive', 'Cache-Control': 'max-age=0', 'Upgrade-Insecure-Requests': '1', 'Use...
           │       │              │           └ 'fuxingwang'
           │       │              └ 'get'
           │       └ <function Session.request at 0x7fa1f709f040>
           └ <requests.sessions.Session object at 0x7fa216120340>
  File "/home/chase/.local/lib/python3.8/site-packages/requests/sessions.py", line 528, in request
    prep = self.prepare_request(req)
           │    │               └ <Request [GET]>
           │    └ <function Session.prepare_request at 0x7fa1f70a6f70>
           └ <requests.sessions.Session object at 0x7fa216120340>
  File "/home/chase/.local/lib/python3.8/site-packages/requests/sessions.py", line 456, in prepare_request
    p.prepare(
    │ └ <function PreparedRequest.prepare at 0x7fa1f7112430>
    └ <PreparedRequest [GET]>
  File "/home/chase/.local/lib/python3.8/site-packages/requests/models.py", line 316, in prepare
    self.prepare_url(url, params)
    │    │           │    └ OrderedDict()
    │    │           └ 'fuxingwang'
    │    └ <function PreparedRequest.prepare_url at 0x7fa1f7112700>
    └ <PreparedRequest [GET]>
  File "/home/chase/.local/lib/python3.8/site-packages/requests/models.py", line 390, in prepare_url
    raise MissingSchema(error)
          │             └ "Invalid URL 'fuxingwang': No schema supplied. Perhaps you meant http://fuxingwang?"
          └ <class 'requests.exceptions.MissingSchema'>

requests.exceptions.MissingSchema: Invalid URL 'fuxingwang': No schema supplied. Perhaps you meant http://fuxingwang?
2022-04-20 17:04:37.421 | ERROR    | __main__:get_request_from_keyword:29 - E 复兴网错误HTTPConnectionPool(host='fuxingwang', port=80): Max retries exceeded with url: / (Caused by NewConnectionError('<urllib3.connection.HTTPConnection object at 0x7f9ab20105b0>: Failed to establish a new connection: [Errno -3] Temporary failure in name resolution'))
Traceback (most recent call last):

  File "/home/chase/.local/lib/python3.8/site-packages/urllib3/connection.py", line 174, in _new_conn
    conn = connection.create_connection(
           │          └ <function create_connection at 0x7f9ac995d820>
           └ <module 'urllib3.util.connection' from '/home/chase/.local/lib/python3.8/site-packages/urllib3/util/connection.py'>
  File "/home/chase/.local/lib/python3.8/site-packages/urllib3/util/connection.py", line 73, in create_connection
    for res in socket.getaddrinfo(host, port, family, socket.SOCK_STREAM):
               │      │           │     │     │       │      └ <SocketKind.SOCK_STREAM: 1>
               │      │           │     │     │       └ <module 'socket' from '/usr/lib/python3.8/socket.py'>
               │      │           │     │     └ <AddressFamily.AF_UNSPEC: 0>
               │      │           │     └ 80
               │      │           └ 'fuxingwang'
               │      └ <function getaddrinfo at 0x7f9ac9a35790>
               └ <module 'socket' from '/usr/lib/python3.8/socket.py'>
  File "/usr/lib/python3.8/socket.py", line 918, in getaddrinfo
    for res in _socket.getaddrinfo(host, port, family, type, proto, flags):
               │       │           │     │     │       │     │      └ 0
               │       │           │     │     │       │     └ 0
               │       │           │     │     │       └ <SocketKind.SOCK_STREAM: 1>
               │       │           │     │     └ <AddressFamily.AF_UNSPEC: 0>
               │       │           │     └ 80
               │       │           └ 'fuxingwang'
               │       └ <built-in function getaddrinfo>
               └ <module '_socket' (built-in)>

socket.gaierror: [Errno -3] Temporary failure in name resolution


During handling of the above exception, another exception occurred:


Traceback (most recent call last):

  File "/home/chase/.local/lib/python3.8/site-packages/urllib3/connectionpool.py", line 699, in urlopen
    httplib_response = self._make_request(
                       │    └ <function HTTPConnectionPool._make_request at 0x7f9abb555940>
                       └ <urllib3.connectionpool.HTTPConnectionPool object at 0x7f9ab202e160>
  File "/home/chase/.local/lib/python3.8/site-packages/urllib3/connectionpool.py", line 394, in _make_request
    conn.request(method, url, **httplib_request_kw)
    │    │       │       │      └ {'body': None, 'headers': {'User-Agent': 'Mozilla/5.0 (X11; Linux x86_64) AppleWebKit/537.36 (KHTML, like Gecko) Chrome/93.0....
    │    │       │       └ '/'
    │    │       └ 'GET'
    │    └ <function HTTPConnection.request at 0x7f9ac99965e0>
    └ <urllib3.connection.HTTPConnection object at 0x7f9ab20105b0>
  File "/home/chase/.local/lib/python3.8/site-packages/urllib3/connection.py", line 239, in request
    super(HTTPConnection, self).request(method, url, body=body, headers=headers)
          │               │             │       │         │             └ {'User-Agent': 'Mozilla/5.0 (X11; Linux x86_64) AppleWebKit/537.36 (KHTML, like Gecko) Chrome/93.0.4577.63 Safari/537.36', 'A...
          │               │             │       │         └ None
          │               │             │       └ '/'
          │               │             └ 'GET'
          │               └ <urllib3.connection.HTTPConnection object at 0x7f9ab20105b0>
          └ <class 'urllib3.connection.HTTPConnection'>
  File "/usr/lib/python3.8/http/client.py", line 1256, in request
    self._send_request(method, url, body, headers, encode_chunked)
    │    │             │       │    │     │        └ False
    │    │             │       │    │     └ {'User-Agent': 'Mozilla/5.0 (X11; Linux x86_64) AppleWebKit/537.36 (KHTML, like Gecko) Chrome/93.0.4577.63 Safari/537.36', 'A...
    │    │             │       │    └ None
    │    │             │       └ '/'
    │    │             └ 'GET'
    │    └ <function HTTPConnection._send_request at 0x7f9ac99c2430>
    └ <urllib3.connection.HTTPConnection object at 0x7f9ab20105b0>
  File "/usr/lib/python3.8/http/client.py", line 1302, in _send_request
    self.endheaders(body, encode_chunked=encode_chunked)
    │    │          │                    └ False
    │    │          └ None
    │    └ <function HTTPConnection.endheaders at 0x7f9ac99c2310>
    └ <urllib3.connection.HTTPConnection object at 0x7f9ab20105b0>
  File "/usr/lib/python3.8/http/client.py", line 1251, in endheaders
    self._send_output(message_body, encode_chunked=encode_chunked)
    │    │            │                            └ False
    │    │            └ None
    │    └ <function HTTPConnection._send_output at 0x7f9ac99c1ee0>
    └ <urllib3.connection.HTTPConnection object at 0x7f9ab20105b0>
  File "/usr/lib/python3.8/http/client.py", line 1011, in _send_output
    self.send(msg)
    │    │    └ b"GET / HTTP/1.1\r\nHost: fuxingwang\r\nUser-Agent: Mozilla/5.0 (X11; Linux x86_64) AppleWebKit/537.36 (KHTML, like Gecko) Ch...
    │    └ <function HTTPConnection.send at 0x7f9ac99c1d30>
    └ <urllib3.connection.HTTPConnection object at 0x7f9ab20105b0>
  File "/usr/lib/python3.8/http/client.py", line 951, in send
    self.connect()
    │    └ <function HTTPConnection.connect at 0x7f9ac9996430>
    └ <urllib3.connection.HTTPConnection object at 0x7f9ab20105b0>
  File "/home/chase/.local/lib/python3.8/site-packages/urllib3/connection.py", line 205, in connect
    conn = self._new_conn()
           │    └ <function HTTPConnection._new_conn at 0x7f9ac9996280>
           └ <urllib3.connection.HTTPConnection object at 0x7f9ab20105b0>
  File "/home/chase/.local/lib/python3.8/site-packages/urllib3/connection.py", line 186, in _new_conn
    raise NewConnectionError(
          └ <class 'urllib3.exceptions.NewConnectionError'>

urllib3.exceptions.NewConnectionError: <urllib3.connection.HTTPConnection object at 0x7f9ab20105b0>: Failed to establish a new connection: [Errno -3] Temporary failure in name resolution


During handling of the above exception, another exception occurred:


Traceback (most recent call last):

  File "/home/chase/.local/lib/python3.8/site-packages/requests/adapters.py", line 439, in send
    resp = conn.urlopen(
           │    └ <function HTTPConnectionPool.urlopen at 0x7f9abb555b80>
           └ <urllib3.connectionpool.HTTPConnectionPool object at 0x7f9ab202e160>
  File "/home/chase/.local/lib/python3.8/site-packages/urllib3/connectionpool.py", line 755, in urlopen
    retries = retries.increment(
              │       └ <function Retry.increment at 0x7f9ac99691f0>
              └ Retry(total=0, connect=None, read=False, redirect=None, status=None)
  File "/home/chase/.local/lib/python3.8/site-packages/urllib3/util/retry.py", line 574, in increment
    raise MaxRetryError(_pool, url, error or ResponseError(cause))
          │             │      │    │        │             └ 'unknown'
          │             │      │    │        └ <class 'urllib3.exceptions.ResponseError'>
          │             │      │    └ NewConnectionError('<urllib3.connection.HTTPConnection object at 0x7f9ab20105b0>: Failed to establish a new connection: [Errn...
          │             │      └ '/'
          │             └ <urllib3.connectionpool.HTTPConnectionPool object at 0x7f9ab202e160>
          └ <class 'urllib3.exceptions.MaxRetryError'>

urllib3.exceptions.MaxRetryError: HTTPConnectionPool(host='fuxingwang', port=80): Max retries exceeded with url: / (Caused by NewConnectionError('<urllib3.connection.HTTPConnection object at 0x7f9ab20105b0>: Failed to establish a new connection: [Errno -3] Temporary failure in name resolution'))


During handling of the above exception, another exception occurred:


Traceback (most recent call last):

  File "/home/users/Scy/yuqing/spider/monitor/searchSpiders/fuxingwang.py", line 45, in <module>
    for i in a.get_request_from_keyword(header, search_url, '石油'):
             │ │                        │       └ ' http://fuxingwang'
             │ │                        └ {'Connection': 'keep-alive', 'Cache-Control': 'max-age=0', 'Upgrade-Insecure-Requests': '1', 'User-Agent': 'Mozilla/5.0 (X11;...
             │ └ <function Douban.get_request_from_keyword at 0x7f9ab2027550>
             └ <__main__.Douban object at 0x7f9ada2c7ca0>

> File "/home/users/Scy/yuqing/spider/monitor/searchSpiders/fuxingwang.py", line 20, in get_request_from_keyword
    request = requests.get(search_url, headers=headers)
              │        │   │                   └ {'Connection': 'keep-alive', 'Cache-Control': 'max-age=0', 'Upgrade-Insecure-Requests': '1', 'User-Agent': 'Mozilla/5.0 (X11;...
              │        │   └ ' http://fuxingwang'
              │        └ <function get at 0x7f9abb2068b0>
              └ <module 'requests' from '/home/chase/.local/lib/python3.8/site-packages/requests/__init__.py'>

  File "/home/chase/.local/lib/python3.8/site-packages/requests/api.py", line 75, in get
    return request('get', url, params=params, **kwargs)
           │              │           │         └ {'headers': {'Connection': 'keep-alive', 'Cache-Control': 'max-age=0', 'Upgrade-Insecure-Requests': '1', 'User-Agent': 'Mozil...
           │              │           └ None
           │              └ ' http://fuxingwang'
           └ <function request at 0x7f9abb1fc790>
  File "/home/chase/.local/lib/python3.8/site-packages/requests/api.py", line 61, in request
    return session.request(method=method, url=url, **kwargs)
           │       │              │           │      └ {'params': None, 'headers': {'Connection': 'keep-alive', 'Cache-Control': 'max-age=0', 'Upgrade-Insecure-Requests': '1', 'Use...
           │       │              │           └ ' http://fuxingwang'
           │       │              └ 'get'
           │       └ <function Session.request at 0x7f9abb206040>
           └ <requests.sessions.Session object at 0x7f9ada2c7340>
  File "/home/chase/.local/lib/python3.8/site-packages/requests/sessions.py", line 542, in request
    resp = self.send(prep, **send_kwargs)
           │    │    │       └ {'timeout': None, 'allow_redirects': True, 'verify': True, 'proxies': OrderedDict(), 'stream': False, 'cert': None}
           │    │    └ <PreparedRequest [GET]>
           │    └ <function Session.send at 0x7f9abb2064c0>
           └ <requests.sessions.Session object at 0x7f9ada2c7340>
  File "/home/chase/.local/lib/python3.8/site-packages/requests/sessions.py", line 655, in send
    r = adapter.send(request, **kwargs)
        │       │    │          └ {'timeout': None, 'verify': True, 'proxies': OrderedDict(), 'stream': False, 'cert': None}
        │       │    └ <PreparedRequest [GET]>
        │       └ <function HTTPAdapter.send at 0x7f9abb20d940>
        └ <requests.adapters.HTTPAdapter object at 0x7f9ab2010e50>
  File "/home/chase/.local/lib/python3.8/site-packages/requests/adapters.py", line 516, in send
    raise ConnectionError(e, request=request)
          │                          └ <PreparedRequest [GET]>
          └ <class 'requests.exceptions.ConnectionError'>

requests.exceptions.ConnectionError: HTTPConnectionPool(host='fuxingwang', port=80): Max retries exceeded with url: / (Caused by NewConnectionError('<urllib3.connection.HTTPConnection object at 0x7f9ab20105b0>: Failed to establish a new connection: [Errno -3] Temporary failure in name resolution'))
2022-04-20 17:06:40.546 | ERROR    | __main__:get_request_from_keyword:29 - E 复兴网错误XPath error: Invalid expression in ./text*()
Traceback (most recent call last):

  File "/home/chase/.local/lib/python3.8/site-packages/parsel/selector.py", line 254, in xpath
    result = xpathev(query, namespaces=nsp,
             │       │                 └ {'re': 'http://exslt.org/regular-expressions', 'set': 'http://exslt.org/sets'}
             │       └ './text*()'
             └ <bound method _Element.xpath of <Element a at 0x7f6e6811f4f0>>
  File "src/lxml/etree.pyx", line 1582, in lxml.etree._Element.xpath
  File "src/lxml/xpath.pxi", line 305, in lxml.etree.XPathElementEvaluator.__call__
  File "src/lxml/xpath.pxi", line 225, in lxml.etree._XPathEvaluatorBase._handle_result

lxml.etree.XPathEvalError: Invalid expression


During handling of the above exception, another exception occurred:


Traceback (most recent call last):

  File "/home/users/Scy/yuqing/spider/monitor/searchSpiders/fuxingwang.py", line 45, in <module>
    for i in a.get_request_from_keyword(header, search_url, '石油'):
             │ │                        │       └ 'https://www.mzfxw.com/'
             │ │                        └ {'Connection': 'keep-alive', 'Cache-Control': 'max-age=0', 'Upgrade-Insecure-Requests': '1', 'User-Agent': 'Mozilla/5.0 (X11;...
             │ └ <function Douban.get_request_from_keyword at 0x7f6e68187550>
             └ <__main__.Douban object at 0x7f6e8c41aca0>

> File "/home/users/Scy/yuqing/spider/monitor/searchSpiders/fuxingwang.py", line 25, in get_request_from_keyword
    title = item.xpath("./text*()").get()
            │    └ <function Selector.xpath at 0x7f6e6c44fca0>
            └ <Selector xpath='//ul[@class="commonlist"]/li/a' data='<a class="elite_5" href="https://www....'>

  File "/home/chase/.local/lib/python3.8/site-packages/parsel/selector.py", line 260, in xpath
    six.reraise(ValueError, ValueError(msg), sys.exc_info()[2])
    │   │                              │     │   └ <built-in function exc_info>
    │   │                              │     └ <module 'sys' (built-in)>
    │   │                              └ 'XPath error: Invalid expression in ./text*()'
    │   └ <function reraise at 0x7f6e8439e040>
    └ <module 'six' from '/home/chase/.local/lib/python3.8/site-packages/six.py'>
  File "/home/chase/.local/lib/python3.8/site-packages/six.py", line 702, in reraise
    raise value.with_traceback(tb)
          │                    └ None
          └ None
  File "/home/chase/.local/lib/python3.8/site-packages/parsel/selector.py", line 254, in xpath
    result = xpathev(query, namespaces=nsp,
             │       │                 └ {'re': 'http://exslt.org/regular-expressions', 'set': 'http://exslt.org/sets'}
             │       └ './text*()'
             └ <bound method _Element.xpath of <Element a at 0x7f6e6811f4f0>>
  File "src/lxml/etree.pyx", line 1582, in lxml.etree._Element.xpath
  File "src/lxml/xpath.pxi", line 305, in lxml.etree.XPathElementEvaluator.__call__
  File "src/lxml/xpath.pxi", line 225, in lxml.etree._XPathEvaluatorBase._handle_result

ValueError: XPath error: Invalid expression in ./text*()
2022-04-20 17:10:57.751 | ERROR    | __main__:get_request_from_keyword:30 - E 复兴网错误XPath error: Invalid expression in ./text*()
Traceback (most recent call last):

  File "/home/chase/.local/lib/python3.8/site-packages/parsel/selector.py", line 254, in xpath
    result = xpathev(query, namespaces=nsp,
             │       │                 └ {'re': 'http://exslt.org/regular-expressions', 'set': 'http://exslt.org/sets'}
             │       └ './text*()'
             └ <bound method _Element.xpath of <Element a at 0x7fbf2703b4f0>>
  File "src/lxml/etree.pyx", line 1582, in lxml.etree._Element.xpath
  File "src/lxml/xpath.pxi", line 305, in lxml.etree.XPathElementEvaluator.__call__
  File "src/lxml/xpath.pxi", line 225, in lxml.etree._XPathEvaluatorBase._handle_result

lxml.etree.XPathEvalError: Invalid expression


During handling of the above exception, another exception occurred:


Traceback (most recent call last):

  File "/home/users/Scy/yuqing/spider/monitor/searchSpiders/fuxingwang.py", line 46, in <module>
    for i in a.get_request_from_keyword(header, search_url):
             │ │                        │       └ 'https://www.mzfxw.com/'
             │ │                        └ {'Connection': 'keep-alive', 'Cache-Control': 'max-age=0', 'Upgrade-Insecure-Requests': '1', 'User-Agent': 'Mozilla/5.0 (X11;...
             │ └ <function Douban.get_request_from_keyword at 0x7fbf270a3550>
             └ <__main__.Douban object at 0x7fbf4f336ca0>

> File "/home/users/Scy/yuqing/spider/monitor/searchSpiders/fuxingwang.py", line 26, in get_request_from_keyword
    title = item.xpath("./text*()").get()
            │    └ <function Selector.xpath at 0x7fbf2f303ca0>
            └ <Selector xpath='//ul[@class="commonlist"]/li/a' data='<a class="elite_5" href="https://www....'>

  File "/home/chase/.local/lib/python3.8/site-packages/parsel/selector.py", line 260, in xpath
    six.reraise(ValueError, ValueError(msg), sys.exc_info()[2])
    │   │                              │     │   └ <built-in function exc_info>
    │   │                              │     └ <module 'sys' (built-in)>
    │   │                              └ 'XPath error: Invalid expression in ./text*()'
    │   └ <function reraise at 0x7fbf412bb040>
    └ <module 'six' from '/home/chase/.local/lib/python3.8/site-packages/six.py'>
  File "/home/chase/.local/lib/python3.8/site-packages/six.py", line 702, in reraise
    raise value.with_traceback(tb)
          │                    └ None
          └ None
  File "/home/chase/.local/lib/python3.8/site-packages/parsel/selector.py", line 254, in xpath
    result = xpathev(query, namespaces=nsp,
             │       │                 └ {'re': 'http://exslt.org/regular-expressions', 'set': 'http://exslt.org/sets'}
             │       └ './text*()'
             └ <bound method _Element.xpath of <Element a at 0x7fbf2703b4f0>>
  File "src/lxml/etree.pyx", line 1582, in lxml.etree._Element.xpath
  File "src/lxml/xpath.pxi", line 305, in lxml.etree.XPathElementEvaluator.__call__
  File "src/lxml/xpath.pxi", line 225, in lxml.etree._XPathEvaluatorBase._handle_result

ValueError: XPath error: Invalid expression in ./text*()
2022-04-20 17:11:53.261 | ERROR    | __main__:get_request_from_keyword:30 - E 复兴网错误'Douban' object has no attribute 'headers'
Traceback (most recent call last):

  File "/home/users/Scy/yuqing/spider/monitor/searchSpiders/fuxingwang.py", line 46, in <module>
    for i in a.get_request_from_keyword(header, search_url):
             │ │                        │       └ 'https://www.mzfxw.com/'
             │ │                        └ {'Connection': 'keep-alive', 'Cache-Control': 'max-age=0', 'Upgrade-Insecure-Requests': '1', 'User-Agent': 'Mozilla/5.0 (X11;...
             │ └ <function Douban.get_request_from_keyword at 0x7f6ca149a550>
             └ <__main__.Douban object at 0x7f6cc9730ca0>

> File "/home/users/Scy/yuqing/spider/monitor/searchSpiders/fuxingwang.py", line 28, in get_request_from_keyword
    yield scrapy.Request(url, headers=self.headers, meta=meta)
          │      │       │            │                  └ {'name': '复兴网', 'callback': 'parse_passage', 'keyword': '毛泽东：在延安文艺座谈会上的讲话'}
          │      │       │            └ <__main__.Douban object at 0x7f6cc9730ca0>
          │      │       └ 'https://www.mzfxw.com/e/action/ShowInfo.php?classid=23&id=136802'
          │      └ <class 'scrapy.http.request.Request'>
          └ <module 'scrapy' from '/home/chase/.local/lib/python3.8/site-packages/scrapy/__init__.py'>

AttributeError: 'Douban' object has no attribute 'headers'
2022-04-20 19:43:02.963 | ERROR    | __main__:get_request_from_keyword:36 - E 联合早报错误Expecting value: line 1 column 1 (char 0)
Traceback (most recent call last):

  File "/home/users/Scy/yuqing/spider/monitor/searchSpiders/lianhezb.py", line 52, in <module>
    for i in a.get_request_from_keyword(header, search_url, '石油'):
             │ │                        │       └ 'http://search.people.cn/api-search/front/search'
             │ │                        └ {'Proxy-Connection': 'keep-alive', 'Cache-Control': 'max-age=0', 'Upgrade-Insecure-Requests': '1', 'User-Agent': 'Mozilla/5.0...
             │ └ <function Lianhezb.get_request_from_keyword at 0x7f825cfb1430>
             └ <__main__.Lianhezb object at 0x7f828124bca0>

> File "/home/users/Scy/yuqing/spider/monitor/searchSpiders/lianhezb.py", line 21, in get_request_from_keyword
    json_response = json.loads(response.text)
                    │    │     │        └ <property object at 0x7f82621fb9a0>
                    │    │     └ <Response [200]>
                    │    └ <function loads at 0x7f8280ed7040>
                    └ <module 'json' from '/usr/lib/python3.8/json/__init__.py'>

  File "/usr/lib/python3.8/json/__init__.py", line 357, in loads
    return _default_decoder.decode(s)
           │                │      └ '<!doctype html>\n<html>\n  <head>\n    <title>äººæ°\x91ç½\x91-æ\x90\x9cç´¢</title><meta data-n-head="1" charset="utf-8"><met...
           │                └ <function JSONDecoder.decode at 0x7f8280f46940>
           └ <json.decoder.JSONDecoder object at 0x7f8280f3e760>
  File "/usr/lib/python3.8/json/decoder.py", line 337, in decode
    obj, end = self.raw_decode(s, idx=_w(s, 0).end())
               │    │          │      │  └ '<!doctype html>\n<html>\n  <head>\n    <title>äººæ°\x91ç½\x91-æ\x90\x9cç´¢</title><meta data-n-head="1" charset="utf-8"><met...
               │    │          │      └ <built-in method match of re.Pattern object at 0x7f8280f71e70>
               │    │          └ '<!doctype html>\n<html>\n  <head>\n    <title>äººæ°\x91ç½\x91-æ\x90\x9cç´¢</title><meta data-n-head="1" charset="utf-8"><met...
               │    └ <function JSONDecoder.raw_decode at 0x7f8280f469d0>
               └ <json.decoder.JSONDecoder object at 0x7f8280f3e760>
  File "/usr/lib/python3.8/json/decoder.py", line 355, in raw_decode
    raise JSONDecodeError("Expecting value", s, err.value) from None
          │                                  └ '<!doctype html>\n<html>\n  <head>\n    <title>äººæ°\x91ç½\x91-æ\x90\x9cç´¢</title><meta data-n-head="1" charset="utf-8"><met...
          └ <class 'json.decoder.JSONDecodeError'>

json.decoder.JSONDecodeError: Expecting value: line 1 column 1 (char 0)
2022-04-20 20:09:54.878 | ERROR    | spiders.spiders.people:page_parse:120 - E 人民网错误'Response' object has no attribute 'meta'
Traceback (most recent call last):

  File "/home/users/Scy/yuqing/spider/monitor/searchSpiders/people.py", line 58, in <module>
    for j in a.page_parse(response):
             │ │          └ <Response [200]>
             │ └ <function People.page_parse at 0x7f78f1389e50>
             └ <spiders.spiders.people.People object at 0x7f78f137ce50>

> File "/home/users/Scy/yuqing/spider/spiders/spiders/people.py", line 80, in page_parse
    keyword = response.meta.get("keyword")
              └ <Response [200]>

AttributeError: 'Response' object has no attribute 'meta'
2022-04-20 20:13:00.918 | ERROR    | spiders.spiders.people:page_parse:119 - E 人民网错误time data '2022Äê04ÔÂ01ÈÕ15:28' does not match format '%Y年%m月%d日%H:%M'
Traceback (most recent call last):

  File "/home/users/Scy/yuqing/spider/monitor/searchSpiders/people.py", line 58, in <module>
    for j in a.page_parse(response):
             │ │          └ <Response [200]>
             │ └ <function People.page_parse at 0x7f97dd917ee0>
             └ <spiders.spiders.people.People object at 0x7f9801b30b20>

> File "/home/users/Scy/yuqing/spider/spiders/spiders/people.py", line 92, in page_parse
    date = people_time_change(date)
           │                  └ '\n\t\t\t\t\t2022Äê04ÔÂ01ÈÕ15:28 | À´Ô´£º'
           └ <function people_time_change at 0x7f97e0a08550>

  File "/home/users/Scy/yuqing/spider/base/utils/time.py", line 108, in people_time_change
    return datetime.datetime.strptime(time, "%Y年%m月%d日%H:%M").strftime("%Y-%m-%d %H:%M:%S")
           │        │        │        └ '2022Äê04ÔÂ01ÈÕ15:28'
           │        │        └ <method 'strptime' of 'datetime.datetime' objects>
           │        └ <class 'datetime.datetime'>
           └ <module 'datetime' from '/usr/lib/python3.8/datetime.py'>

  File "/usr/lib/python3.8/_strptime.py", line 568, in _strptime_datetime
    tt, fraction, gmtoff_fraction = _strptime(data_string, format)
                                    │         │            └ '%Y年%m月%d日%H:%M'
                                    │         └ '2022Äê04ÔÂ01ÈÕ15:28'
                                    └ <function _strptime at 0x7f97dd8da430>
  File "/usr/lib/python3.8/_strptime.py", line 349, in _strptime
    raise ValueError("time data %r does not match format %r" %

ValueError: time data '2022Äê04ÔÂ01ÈÕ15:28' does not match format '%Y年%m月%d日%H:%M'
2022-04-20 20:14:00.990 | ERROR    | spiders.spiders.people:page_parse:119 - E 人民网错误time data '2022��04��01��15:28' does not match format '%Y年%m月%d日%H:%M'
Traceback (most recent call last):

  File "/home/users/Scy/yuqing/spider/monitor/searchSpiders/people.py", line 59, in <module>
    for j in a.page_parse(response):
             │ │          └ <Response [200]>
             │ └ <function People.page_parse at 0x7fbcfe668e50>
             └ <spiders.spiders.people.People object at 0x7fbd22887d30>

> File "/home/users/Scy/yuqing/spider/spiders/spiders/people.py", line 92, in page_parse
    date = people_time_change(date)
           │                  └ '\n\t\t\t\t\t2022��04��01��15:28 | ��Դ��'
           └ <function people_time_change at 0x7fbd0175f550>

  File "/home/users/Scy/yuqing/spider/base/utils/time.py", line 108, in people_time_change
    return datetime.datetime.strptime(time, "%Y年%m月%d日%H:%M").strftime("%Y-%m-%d %H:%M:%S")
           │        │        │        └ '2022��04��01��15:28'
           │        │        └ <method 'strptime' of 'datetime.datetime' objects>
           │        └ <class 'datetime.datetime'>
           └ <module 'datetime' from '/usr/lib/python3.8/datetime.py'>

  File "/usr/lib/python3.8/_strptime.py", line 568, in _strptime_datetime
    tt, fraction, gmtoff_fraction = _strptime(data_string, format)
                                    │         │            └ '%Y年%m月%d日%H:%M'
                                    │         └ '2022��04��01��15:28'
                                    └ <function _strptime at 0x7fbcfe6314c0>
  File "/usr/lib/python3.8/_strptime.py", line 349, in _strptime
    raise ValueError("time data %r does not match format %r" %

ValueError: time data '2022��04��01��15:28' does not match format '%Y年%m月%d日%H:%M'
2022-04-20 20:14:14.757 | ERROR    | spiders.spiders.people:page_parse:119 - E 人民网错误'Response' object has no attribute 'xpath'
Traceback (most recent call last):

  File "/home/users/Scy/yuqing/spider/monitor/searchSpiders/people.py", line 59, in <module>
    for j in a.page_parse(response):
             │ │          └ <Response [200]>
             │ └ <function People.page_parse at 0x7f1d66189e50>
             └ <spiders.spiders.people.People object at 0x7f1d8a3a8d30>

> File "/home/users/Scy/yuqing/spider/spiders/spiders/people.py", line 93, in page_parse
    account = response.xpath("//div[@class='edit cf']/text()").get()
              └ <Response [200]>

AttributeError: 'Response' object has no attribute 'xpath'
2022-04-20 20:28:13.486 | ERROR    | __main__:get_request_from_keyword:33 - E 强国论坛错误'QiangguoLT' object has no attribute 'search_url'
Traceback (most recent call last):

  File "/home/users/Scy/yuqing/spider/monitor/searchSpiders/qinagguoLT.py", line 48, in <module>
    for i in a.get_request_from_keyword(header, search_url, '石油'):
             │ │                        │       └ 'https://www.zaobao.com/search?pageNo={}&pageSize=10&keywords={}'
             │ │                        └ {'Proxy-Connection': 'keep-alive', 'Cache-Control': 'max-age=0', 'Upgrade-Insecure-Requests': '1', 'User-Agent': 'Mozilla/5.0...
             │ └ <function QiangguoLT.get_request_from_keyword at 0x7f720385dee0>
             └ <__main__.QiangguoLT object at 0x7f722bb01ca0>

> File "/home/users/Scy/yuqing/spider/monitor/searchSpiders/qinagguoLT.py", line 20, in get_request_from_keyword
    if self.search_url:
       └ <__main__.QiangguoLT object at 0x7f722bb01ca0>

AttributeError: 'QiangguoLT' object has no attribute 'search_url'
2022-04-20 20:30:21.263 | ERROR    | __main__:get_request_from_keyword:33 - E 强国论坛错误'QiangguoLT' object has no attribute 'search_url'
Traceback (most recent call last):

  File "/home/users/Scy/yuqing/spider/monitor/searchSpiders/qinagguoLT.py", line 47, in <module>
    for i in a.get_request_from_keyword(header, search_url):
             │ │                        │       └ 'http://bbs1.people.com.cn/board/1.html'
             │ │                        └ {'Connection': 'keep-alive', 'Cache-Control': 'max-age=0', 'Upgrade-Insecure-Requests': '1', 'User-Agent': 'Mozilla/5.0 (X11;...
             │ └ <function QiangguoLT.get_request_from_keyword at 0x7f0132791ca0>
             └ <__main__.QiangguoLT object at 0x7f015aa28ca0>

> File "/home/users/Scy/yuqing/spider/monitor/searchSpiders/qinagguoLT.py", line 20, in get_request_from_keyword
    if self.search_url:
       └ <__main__.QiangguoLT object at 0x7f015aa28ca0>

AttributeError: 'QiangguoLT' object has no attribute 'search_url'
2022-04-20 20:32:23.046 | ERROR    | __main__:get_request_from_keyword:31 - E 强国论坛错误request() got an unexpected keyword argument 'meta'
Traceback (most recent call last):

  File "/home/users/Scy/yuqing/spider/monitor/searchSpiders/qinagguoLT.py", line 45, in <module>
    for i in a.get_request_from_keyword(header, search_url):
             │ │                        │       └ 'http://bbs1.people.com.cn/board/1.html'
             │ │                        └ {'Connection': 'keep-alive', 'Cache-Control': 'max-age=0', 'Upgrade-Insecure-Requests': '1', 'User-Agent': 'Mozilla/5.0 (X11;...
             │ └ <function QiangguoLT.get_request_from_keyword at 0x7f507f29bca0>
             └ <__main__.QiangguoLT object at 0x7f50a7532ca0>

> File "/home/users/Scy/yuqing/spider/monitor/searchSpiders/qinagguoLT.py", line 21, in get_request_from_keyword
    response = requests.get(search_url, headers=header, meta=meta)
               │        │   │                   │            └ {'name': 'qiangguoLT', 'callback': 'parse_page'}
               │        │   │                   └ {'Connection': 'keep-alive', 'Cache-Control': 'max-age=0', 'Upgrade-Insecure-Requests': '1', 'User-Agent': 'Mozilla/5.0 (X11;...
               │        │   └ 'http://bbs1.people.com.cn/board/1.html'
               │        └ <function get at 0x7f50884b1940>
               └ <module 'requests' from '/home/chase/.local/lib/python3.8/site-packages/requests/__init__.py'>

  File "/home/chase/.local/lib/python3.8/site-packages/requests/api.py", line 75, in get
    return request('get', url, params=params, **kwargs)
           │              │           │         └ {'headers': {'Connection': 'keep-alive', 'Cache-Control': 'max-age=0', 'Upgrade-Insecure-Requests': '1', 'User-Agent': 'Mozil...
           │              │           └ None
           │              └ 'http://bbs1.people.com.cn/board/1.html'
           └ <function request at 0x7f50884a7820>
  File "/home/chase/.local/lib/python3.8/site-packages/requests/api.py", line 61, in request
    return session.request(method=method, url=url, **kwargs)
           │       │              │           │      └ {'params': None, 'headers': {'Connection': 'keep-alive', 'Cache-Control': 'max-age=0', 'Upgrade-Insecure-Requests': '1', 'Use...
           │       │              │           └ 'http://bbs1.people.com.cn/board/1.html'
           │       │              └ 'get'
           │       └ <function Session.request at 0x7f50884b10d0>
           └ <requests.sessions.Session object at 0x7f50a7532df0>

TypeError: request() got an unexpected keyword argument 'meta'
2022-04-20 20:32:45.526 | ERROR    | __main__:get_request_from_keyword:31 - E 强国论坛错误request() got an unexpected keyword argument 'meta'
Traceback (most recent call last):

  File "/home/users/Scy/yuqing/spider/monitor/searchSpiders/qinagguoLT.py", line 45, in <module>
    for i in a.get_request_from_keyword(header, search_url):
             │ │                        │       └ 'http://bbs1.people.com.cn/board/1.html'
             │ │                        └ {'Connection': 'keep-alive', 'Cache-Control': 'max-age=0', 'Upgrade-Insecure-Requests': '1', 'User-Agent': 'Mozilla/5.0 (X11;...
             │ └ <function QiangguoLT.get_request_from_keyword at 0x7f2834b13ca0>
             └ <__main__.QiangguoLT object at 0x7f2858da9ca0>

> File "/home/users/Scy/yuqing/spider/monitor/searchSpiders/qinagguoLT.py", line 21, in get_request_from_keyword
    response = requests.get(search_url, headers=header, meta=meta)
               │        │   │                   │            └ {'name': 'qiangguoLT', 'callback': 'parse_page'}
               │        │   │                   └ {'Connection': 'keep-alive', 'Cache-Control': 'max-age=0', 'Upgrade-Insecure-Requests': '1', 'User-Agent': 'Mozilla/5.0 (X11;...
               │        │   └ 'http://bbs1.people.com.cn/board/1.html'
               │        └ <function get at 0x7f2839d28940>
               └ <module 'requests' from '/home/chase/.local/lib/python3.8/site-packages/requests/__init__.py'>

  File "/home/chase/.local/lib/python3.8/site-packages/requests/api.py", line 75, in get
    return request('get', url, params=params, **kwargs)
           │              │           │         └ {'headers': {'Connection': 'keep-alive', 'Cache-Control': 'max-age=0', 'Upgrade-Insecure-Requests': '1', 'User-Agent': 'Mozil...
           │              │           └ None
           │              └ 'http://bbs1.people.com.cn/board/1.html'
           └ <function request at 0x7f2839d1e820>
  File "/home/chase/.local/lib/python3.8/site-packages/requests/api.py", line 61, in request
    return session.request(method=method, url=url, **kwargs)
           │       │              │           │      └ {'params': None, 'headers': {'Connection': 'keep-alive', 'Cache-Control': 'max-age=0', 'Upgrade-Insecure-Requests': '1', 'Use...
           │       │              │           └ 'http://bbs1.people.com.cn/board/1.html'
           │       │              └ 'get'
           │       └ <function Session.request at 0x7f2839d280d0>
           └ <requests.sessions.Session object at 0x7f2858da9df0>

TypeError: request() got an unexpected keyword argument 'meta'
2022-04-20 20:32:51.274 | ERROR    | __main__:get_request_from_keyword:30 - E 强国论坛错误invalid literal for int() with base 10: '\t\t\t\t\t\t\t\t\t\t\t\t今日关注\r\n\t\t\t\t\t\t\t\t\t\t\t\t\t04'
Traceback (most recent call last):

  File "/home/users/Scy/yuqing/spider/monitor/searchSpiders/qinagguoLT.py", line 44, in <module>
    for i in a.get_request_from_keyword(header, search_url):
             │ │                        │       └ 'http://bbs1.people.com.cn/board/1.html'
             │ │                        └ {'Connection': 'keep-alive', 'Cache-Control': 'max-age=0', 'Upgrade-Insecure-Requests': '1', 'User-Agent': 'Mozilla/5.0 (X11;...
             │ └ <function QiangguoLT.get_request_from_keyword at 0x7f18ca1e3ca0>
             └ <__main__.QiangguoLT object at 0x7f18f2481ca0>

> File "/home/users/Scy/yuqing/spider/monitor/searchSpiders/qinagguoLT.py", line 27, in get_request_from_keyword
    if get_delta_time(zh_time_change(time)) == 0:
       │              │              └ '\t\t\t\t\t\t\t\t\t\t\t\t今日关注\r\n\t\t\t\t\t\t\t\t\t\t\t\t\t04月20日 08:05\t\t\t\t\t\t'
       │              └ <function zh_time_change at 0x7f18d13eb160>
       └ <function get_delta_time at 0x7f18d13eb670>

  File "/home/users/Scy/yuqing/spider/base/utils/time.py", line 70, in zh_time_change
    month = int(time.split("月")[0])
                │    └ <method 'split' of 'str' objects>
                └ '\t\t\t\t\t\t\t\t\t\t\t\t今日关注\r\n\t\t\t\t\t\t\t\t\t\t\t\t\t04月20日 08:05\t\t\t\t\t\t'

ValueError: invalid literal for int() with base 10: '\t\t\t\t\t\t\t\t\t\t\t\t今日关注\r\n\t\t\t\t\t\t\t\t\t\t\t\t\t04'
2022-04-20 20:33:14.492 | ERROR    | __main__:get_request_from_keyword:30 - E 强国论坛错误invalid literal for int() with base 10: '\t\t\t\t\t\t\t\t\t\t\t\t今日关注\r\n\t\t\t\t\t\t\t\t\t\t\t\t\t04'
Traceback (most recent call last):

  File "/home/users/Scy/yuqing/spider/monitor/searchSpiders/qinagguoLT.py", line 44, in <module>
    for i in a.get_request_from_keyword(header, search_url):
             │ │                        │       └ 'http://bbs1.people.com.cn/board/1.html'
             │ │                        └ {'Connection': 'keep-alive', 'Cache-Control': 'max-age=0', 'Upgrade-Insecure-Requests': '1', 'User-Agent': 'Mozilla/5.0 (X11;...
             │ └ <function QiangguoLT.get_request_from_keyword at 0x7f8a5209cc10>
             └ <__main__.QiangguoLT object at 0x7f8a7a332ca0>

> File "/home/users/Scy/yuqing/spider/monitor/searchSpiders/qinagguoLT.py", line 27, in get_request_from_keyword
    if get_delta_time(zh_time_change(time)) == 0:
       │              │              └ '\t\t\t\t\t\t\t\t\t\t\t\t今日关注\r\n\t\t\t\t\t\t\t\t\t\t\t\t\t04月20日 08:05\t\t\t\t\t\t'
       │              └ <function zh_time_change at 0x7f8a592dd0d0>
       └ <function get_delta_time at 0x7f8a592dd5e0>

  File "/home/users/Scy/yuqing/spider/base/utils/time.py", line 70, in zh_time_change
    month = int(time.split("月")[0])
                │    └ <method 'split' of 'str' objects>
                └ '\t\t\t\t\t\t\t\t\t\t\t\t今日关注\r\n\t\t\t\t\t\t\t\t\t\t\t\t\t04月20日 08:05\t\t\t\t\t\t'

ValueError: invalid literal for int() with base 10: '\t\t\t\t\t\t\t\t\t\t\t\t今日关注\r\n\t\t\t\t\t\t\t\t\t\t\t\t\t04'
2022-04-20 20:35:36.952 | ERROR    | __main__:get_request_from_keyword:30 - E 强国论坛错误name 'logger' is not defined
Traceback (most recent call last):

  File "/home/users/Scy/yuqing/spider/base/utils/time.py", line 69, in zh_time_change
    month = int(time.split("月")[0])
                │    └ <method 'split' of 'str' objects>
                └ '\t\t\t\t\t\t\t\t\t\t\t\t今日关注\r\n\t\t\t\t\t\t\t\t\t\t\t\t\t04月20日 08:05\t\t\t\t\t\t'

ValueError: invalid literal for int() with base 10: '\t\t\t\t\t\t\t\t\t\t\t\t今日关注\r\n\t\t\t\t\t\t\t\t\t\t\t\t\t04'


During handling of the above exception, another exception occurred:


Traceback (most recent call last):

  File "/home/users/Scy/yuqing/spider/monitor/searchSpiders/qinagguoLT.py", line 44, in <module>
    for i in a.get_request_from_keyword(header, search_url):
             │ │                        │       └ 'http://bbs1.people.com.cn/board/1.html'
             │ │                        └ {'Connection': 'keep-alive', 'Cache-Control': 'max-age=0', 'Upgrade-Insecure-Requests': '1', 'User-Agent': 'Mozilla/5.0 (X11;...
             │ └ <function QiangguoLT.get_request_from_keyword at 0x7f23dfc05af0>
             └ <__main__.QiangguoLT object at 0x7f2407ff3ca0>

> File "/home/users/Scy/yuqing/spider/monitor/searchSpiders/qinagguoLT.py", line 27, in get_request_from_keyword
    if get_delta_time(zh_time_change(time)) == 0:
       │              │              └ '\t\t\t\t\t\t\t\t\t\t\t\t今日关注\r\n\t\t\t\t\t\t\t\t\t\t\t\t\t04月20日 08:05\t\t\t\t\t\t'
       │              └ <function zh_time_change at 0x7f23e6fd9dc0>
       └ <function get_delta_time at 0x7f23e6fe3310>

  File "/home/users/Scy/yuqing/spider/base/utils/time.py", line 75, in zh_time_change
    logger.exception(f"E 强国论坛时间解析错误{e}")

NameError: name 'logger' is not defined
2022-04-20 20:35:53.311 | ERROR    | __main__:get_request_from_keyword:30 - E 强国论坛错误unsupported operand type(s) for -: 'datetime.datetime' and 'NoneType'
Traceback (most recent call last):

  File "/home/users/Scy/yuqing/spider/monitor/searchSpiders/qinagguoLT.py", line 44, in <module>
    for i in a.get_request_from_keyword(header, search_url):
             │ │                        │       └ 'http://bbs1.people.com.cn/board/1.html'
             │ │                        └ {'Connection': 'keep-alive', 'Cache-Control': 'max-age=0', 'Upgrade-Insecure-Requests': '1', 'User-Agent': 'Mozilla/5.0 (X11;...
             │ └ <function QiangguoLT.get_request_from_keyword at 0x7ffb74a0eb80>
             └ <__main__.QiangguoLT object at 0x7ffb98ca2ca0>

> File "/home/users/Scy/yuqing/spider/monitor/searchSpiders/qinagguoLT.py", line 27, in get_request_from_keyword
    if get_delta_time(zh_time_change(time)) == 0:
       │              │              └ '\t\t\t\t\t\t\t\t\t\t\t\t今日关注\r\n\t\t\t\t\t\t\t\t\t\t\t\t\t04月20日 08:05\t\t\t\t\t\t'
       │              └ <function zh_time_change at 0x7ffb77c0f1f0>
       └ <function get_delta_time at 0x7ffb77c0f700>

  File "/home/users/Scy/yuqing/spider/base/utils/time.py", line 188, in get_delta_time
    return (now - time1).days
            │     └ None
            └ datetime.datetime(2022, 4, 20, 20, 35, 53, 311033)

TypeError: unsupported operand type(s) for -: 'datetime.datetime' and 'NoneType'
2022-04-20 20:36:44.530 | ERROR    | __main__:get_request_from_keyword:30 - E 强国论坛错误unsupported operand type(s) for -: 'datetime.datetime' and 'NoneType'
Traceback (most recent call last):

  File "/home/users/Scy/yuqing/spider/monitor/searchSpiders/qinagguoLT.py", line 44, in <module>
    for i in a.get_request_from_keyword(header, search_url):
             │ │                        │       └ 'http://bbs1.people.com.cn/board/1.html'
             │ │                        └ {'Connection': 'keep-alive', 'Cache-Control': 'max-age=0', 'Upgrade-Insecure-Requests': '1', 'User-Agent': 'Mozilla/5.0 (X11;...
             │ └ <function QiangguoLT.get_request_from_keyword at 0x7f5522a3fb80>
             └ <__main__.QiangguoLT object at 0x7f554acd3ca0>

> File "/home/users/Scy/yuqing/spider/monitor/searchSpiders/qinagguoLT.py", line 27, in get_request_from_keyword
    if get_delta_time(zh_time_change(time)) == 0:
       │              │              └ '\t\t\t\t\t\t\t\t\t\t\t\t今日关注\r\n\t\t\t\t\t\t\t\t\t\t\t\t\t04月20日 08:05\t\t\t\t\t\t'
       │              └ <function zh_time_change at 0x7f5529c7f1f0>
       └ <function get_delta_time at 0x7f5529c7f700>

  File "/home/users/Scy/yuqing/spider/base/utils/time.py", line 188, in get_delta_time
    return (now - time1).days
            │     └ None
            └ datetime.datetime(2022, 4, 20, 20, 36, 44, 530929)

TypeError: unsupported operand type(s) for -: 'datetime.datetime' and 'NoneType'
