2022-05-14 01:18:09.109 | ERROR    | base.db.mysql:update:390 - 【mysql更新数据出错】
Traceback (most recent call last):

  File "/home/chase/.local/lib/python3.8/site-packages/sqlalchemy/engine/base.py", line 1771, in _execute_context
    self.dialect.do_execute(
    │    │       └ <function DefaultDialect.do_execute at 0x7f31f38f75e0>
    │    └ <sqlalchemy.dialects.mysql.pymysql.MySQLDialect_pymysql object at 0x7f3103ffde20>
    └ <sqlalchemy.engine.base.Connection object at 0x7f3102431400>
  File "/home/chase/.local/lib/python3.8/site-packages/sqlalchemy/engine/default.py", line 717, in do_execute
    cursor.execute(statement, parameters)
    │      │       │          └ {'server_id': '180.201.163.246:6800', 'ip': '180.201.163.246', 'username': 'chase', 'password': '8374678731713047049292519458...
    │      │       └ 'UPDATE device SET server_id=%(server_id)s, ip=%(ip)s, username=%(username)s, password=%(password)s, address=%(address)s, por...
    │      └ <function Cursor.execute at 0x7f31f354cdc0>
    └ <pymysql.cursors.Cursor object at 0x7f301823a520>
  File "/home/chase/.local/lib/python3.8/site-packages/pymysql/cursors.py", line 148, in execute
    result = self._query(query)
             │    │      └ "UPDATE device SET server_id='180.201.163.246:6800', ip='180.201.163.246', username='chase', password='8374678731713047049292...
             │    └ <function Cursor._query at 0x7f31f34d7280>
             └ <pymysql.cursors.Cursor object at 0x7f301823a520>
  File "/home/chase/.local/lib/python3.8/site-packages/pymysql/cursors.py", line 310, in _query
    conn.query(q)
    │    │     └ "UPDATE device SET server_id='180.201.163.246:6800', ip='180.201.163.246', username='chase', password='8374678731713047049292...
    │    └ <function Connection.query at 0x7f31f34e5670>
    └ <pymysql.connections.Connection object at 0x7f30b8127cd0>
  File "/home/chase/.local/lib/python3.8/site-packages/pymysql/connections.py", line 548, in query
    self._affected_rows = self._read_query_result(unbuffered=unbuffered)
    │    │                │    │                             └ False
    │    │                │    └ <function Connection._read_query_result at 0x7f31f34e5ca0>
    │    │                └ <pymysql.connections.Connection object at 0x7f30b8127cd0>
    │    └ 1
    └ <pymysql.connections.Connection object at 0x7f30b8127cd0>
  File "/home/chase/.local/lib/python3.8/site-packages/pymysql/connections.py", line 775, in _read_query_result
    result.read()
    │      └ <function MySQLResult.read at 0x7f31f34e64c0>
    └ <pymysql.connections.MySQLResult object at 0x7f2ff85fa6a0>
  File "/home/chase/.local/lib/python3.8/site-packages/pymysql/connections.py", line 1156, in read
    first_packet = self.connection._read_packet()
                   │    └ None
                   └ <pymysql.connections.MySQLResult object at 0x7f2ff85fa6a0>
  File "/home/chase/.local/lib/python3.8/site-packages/pymysql/connections.py", line 725, in _read_packet
    packet.raise_for_error()
    │      └ <function MysqlPacket.raise_for_error at 0x7f31f34ddee0>
    └ <pymysql.protocol.MysqlPacket object at 0x7f3038514550>
  File "/home/chase/.local/lib/python3.8/site-packages/pymysql/protocol.py", line 221, in raise_for_error
    err.raise_mysql_exception(self._data)
    │   │                     │    └ <member '_data' of 'MysqlPacket' objects>
    │   │                     └ <pymysql.protocol.MysqlPacket object at 0x7f3038514550>
    │   └ <function raise_mysql_exception at 0x7f31f358c670>
    └ <module 'pymysql.err' from '/home/chase/.local/lib/python3.8/site-packages/pymysql/err.py'>
  File "/home/chase/.local/lib/python3.8/site-packages/pymysql/err.py", line 143, in raise_mysql_exception
    raise errorclass(errno, errval)
          │          │      └ "Duplicate entry '180.201.163.246:6800' for key 'device.PRIMARY'"
          │          └ 1062
          └ <class 'pymysql.err.IntegrityError'>

pymysql.err.IntegrityError: (1062, "Duplicate entry '180.201.163.246:6800' for key 'device.PRIMARY'")


The above exception was the direct cause of the following exception:


Traceback (most recent call last):

  File "/usr/lib/python3.8/threading.py", line 890, in _bootstrap
    self._bootstrap_inner()
    │    └ <function Thread._bootstrap_inner at 0x7f321bf29a60>
    └ <Thread(Thread-7589, started daemon 139837313230592)>
  File "/usr/lib/python3.8/threading.py", line 932, in _bootstrap_inner
    self.run()
    │    └ <function Thread.run at 0x7f321bf29790>
    └ <Thread(Thread-7589, started daemon 139837313230592)>
  File "/usr/lib/python3.8/threading.py", line 870, in run
    self._target(*self._args, **self._kwargs)
    │    │        │    │        │    └ {}
    │    │        │    │        └ <Thread(Thread-7589, started daemon 139837313230592)>
    │    │        │    └ ('ProjectManager.run_func_by_thread',)
    │    │        └ <Thread(Thread-7589, started daemon 139837313230592)>
    │    └ <bound method ProjectManager.get_request_from_keywords_hot of <monitor.projectManager.ProjectManager object at 0x7f31042e52e0>>
    └ <Thread(Thread-7589, started daemon 139837313230592)>

  File "/home/users/Scy/yuqing/spider/monitor/projectManager.py", line 799, in get_request_from_keywords_hot
    self.start_finished_spider_every_interval(project_names)
    │    │                                    └ ['default', 'test']
    │    └ <function ProjectManager.start_finished_spider_every_interval at 0x7f3104005280>
    └ <monitor.projectManager.ProjectManager object at 0x7f31042e52e0>

  File "/home/users/Scy/yuqing/spider/monitor/projectManager.py", line 784, in start_finished_spider_every_interval
    self[name].start_spider()
    │    └ 'default'
    └ <monitor.projectManager.ProjectManager object at 0x7f31042e52e0>

  File "/home/users/Scy/yuqing/spider/monitor/projectManager.py", line 366, in start_spider
    self.update_device_valid(device)
    │    │                   └ <monitor.deviceManager.DeviceC object at 0x7f3104029220>
    │    └ <function Project.update_device_valid at 0x7f3104003280>
    └ <monitor.projectManager.Project object at 0x7f3104029460>

  File "/home/users/Scy/yuqing/spider/monitor/projectManager.py", line 421, in update_device_valid
    self.database_manager.mysql.update(Device(**device.to_item()))
    │    │                │     │      │        │      └ <function DeviceC.to_item at 0x7f31f34ed310>
    │    │                │     │      │        └ <monitor.deviceManager.DeviceC object at 0x7f3104029220>
    │    │                │     │      └ <class 'base.db.mysql.Device'>
    │    │                │     └ <function Mysql.update at 0x7f31f35f4790>
    │    │                └ <base.db.mysql.Mysql object at 0x7f3103ffdfd0>
    │    └ <base.db.dbSlot.Slot object at 0x7f3103ffdf10>
    └ <monitor.projectManager.Project object at 0x7f3104029460>

> File "/home/users/Scy/yuqing/spider/base/db/mysql.py", line 375, in update
    row.update(new)
    │   │      └ {'server_id': '180.201.163.246:6800', 'ip': '180.201.163.246', 'username': 'chase', 'password': '8374678731713047049292519458...
    │   └ <function Query.update at 0x7f31f37333a0>
    └ <sqlalchemy.orm.query.Query object at 0x7f30d859ef40>

  File "/home/chase/.local/lib/python3.8/site-packages/sqlalchemy/orm/query.py", line 3221, in update
    result = self.session.execute(
             │    │       └ <function Session.execute at 0x7f31f370faf0>
             │    └ <sqlalchemy.orm.session.Session object at 0x7f30d859e9a0>
             └ <sqlalchemy.orm.query.Query object at 0x7f30d859ef40>
  File "/home/chase/.local/lib/python3.8/site-packages/sqlalchemy/orm/session.py", line 1689, in execute
    result = conn._execute_20(statement, params or {}, execution_options)
             │    │           │          │             └ immutabledict({'synchronize_session': 'evaluate', '_sa_orm_update_options': default_update_options(_matched_objects=[], _reso...
             │    │           │          └ immutabledict({})
             │    │           └ <sqlalchemy.sql.annotation.AnnotatedUpdate object at 0x7f30585d1e50>
             │    └ <function Connection._execute_20 at 0x7f31f39bc790>
             └ <sqlalchemy.engine.base.Connection object at 0x7f3102431400>
  File "/home/chase/.local/lib/python3.8/site-packages/sqlalchemy/engine/base.py", line 1583, in _execute_20
    return meth(self, args_10style, kwargs_10style, execution_options)
           │    │     │             │               └ immutabledict({'synchronize_session': 'evaluate', '_sa_orm_update_options': default_update_options(_matched_objects=[], _reso...
           │    │     │             └ immutabledict({})
           │    │     └ ({},)
           │    └ <sqlalchemy.engine.base.Connection object at 0x7f3102431400>
           └ <bound method ClauseElement._execute_on_connection of <sqlalchemy.sql.annotation.AnnotatedUpdate object at 0x7f30585d1e50>>
  File "/home/chase/.local/lib/python3.8/site-packages/sqlalchemy/sql/elements.py", line 323, in _execute_on_connection
    return connection._execute_clauseelement(
           │          └ <function Connection._execute_clauseelement at 0x7f31f39bc5e0>
           └ <sqlalchemy.engine.base.Connection object at 0x7f3102431400>
  File "/home/chase/.local/lib/python3.8/site-packages/sqlalchemy/engine/base.py", line 1452, in _execute_clauseelement
    ret = self._execute_context(
          │    └ <function Connection._execute_context at 0x7f31f39bc8b0>
          └ <sqlalchemy.engine.base.Connection object at 0x7f3102431400>
  File "/home/chase/.local/lib/python3.8/site-packages/sqlalchemy/engine/base.py", line 1814, in _execute_context
    self._handle_dbapi_exception(
    │    └ <function Connection._handle_dbapi_exception at 0x7f31f39bca60>
    └ <sqlalchemy.engine.base.Connection object at 0x7f3102431400>
  File "/home/chase/.local/lib/python3.8/site-packages/sqlalchemy/engine/base.py", line 1995, in _handle_dbapi_exception
    util.raise_(
    │    └ <function raise_ at 0x7f31f3d7ea60>
    └ <module 'sqlalchemy.util' from '/home/chase/.local/lib/python3.8/site-packages/sqlalchemy/util/__init__.py'>
  File "/home/chase/.local/lib/python3.8/site-packages/sqlalchemy/util/compat.py", line 207, in raise_
    raise exception
  File "/home/chase/.local/lib/python3.8/site-packages/sqlalchemy/engine/base.py", line 1771, in _execute_context
    self.dialect.do_execute(
    │    │       └ <function DefaultDialect.do_execute at 0x7f31f38f75e0>
    │    └ <sqlalchemy.dialects.mysql.pymysql.MySQLDialect_pymysql object at 0x7f3103ffde20>
    └ <sqlalchemy.engine.base.Connection object at 0x7f3102431400>
  File "/home/chase/.local/lib/python3.8/site-packages/sqlalchemy/engine/default.py", line 717, in do_execute
    cursor.execute(statement, parameters)
    │      │       │          └ {'server_id': '180.201.163.246:6800', 'ip': '180.201.163.246', 'username': 'chase', 'password': '8374678731713047049292519458...
    │      │       └ 'UPDATE device SET server_id=%(server_id)s, ip=%(ip)s, username=%(username)s, password=%(password)s, address=%(address)s, por...
    │      └ <function Cursor.execute at 0x7f31f354cdc0>
    └ <pymysql.cursors.Cursor object at 0x7f301823a520>
  File "/home/chase/.local/lib/python3.8/site-packages/pymysql/cursors.py", line 148, in execute
    result = self._query(query)
             │    │      └ "UPDATE device SET server_id='180.201.163.246:6800', ip='180.201.163.246', username='chase', password='8374678731713047049292...
             │    └ <function Cursor._query at 0x7f31f34d7280>
             └ <pymysql.cursors.Cursor object at 0x7f301823a520>
  File "/home/chase/.local/lib/python3.8/site-packages/pymysql/cursors.py", line 310, in _query
    conn.query(q)
    │    │     └ "UPDATE device SET server_id='180.201.163.246:6800', ip='180.201.163.246', username='chase', password='8374678731713047049292...
    │    └ <function Connection.query at 0x7f31f34e5670>
    └ <pymysql.connections.Connection object at 0x7f30b8127cd0>
  File "/home/chase/.local/lib/python3.8/site-packages/pymysql/connections.py", line 548, in query
    self._affected_rows = self._read_query_result(unbuffered=unbuffered)
    │    │                │    │                             └ False
    │    │                │    └ <function Connection._read_query_result at 0x7f31f34e5ca0>
    │    │                └ <pymysql.connections.Connection object at 0x7f30b8127cd0>
    │    └ 1
    └ <pymysql.connections.Connection object at 0x7f30b8127cd0>
  File "/home/chase/.local/lib/python3.8/site-packages/pymysql/connections.py", line 775, in _read_query_result
    result.read()
    │      └ <function MySQLResult.read at 0x7f31f34e64c0>
    └ <pymysql.connections.MySQLResult object at 0x7f2ff85fa6a0>
  File "/home/chase/.local/lib/python3.8/site-packages/pymysql/connections.py", line 1156, in read
    first_packet = self.connection._read_packet()
                   │    └ None
                   └ <pymysql.connections.MySQLResult object at 0x7f2ff85fa6a0>
  File "/home/chase/.local/lib/python3.8/site-packages/pymysql/connections.py", line 725, in _read_packet
    packet.raise_for_error()
    │      └ <function MysqlPacket.raise_for_error at 0x7f31f34ddee0>
    └ <pymysql.protocol.MysqlPacket object at 0x7f3038514550>
  File "/home/chase/.local/lib/python3.8/site-packages/pymysql/protocol.py", line 221, in raise_for_error
    err.raise_mysql_exception(self._data)
    │   │                     │    └ <member '_data' of 'MysqlPacket' objects>
    │   │                     └ <pymysql.protocol.MysqlPacket object at 0x7f3038514550>
    │   └ <function raise_mysql_exception at 0x7f31f358c670>
    └ <module 'pymysql.err' from '/home/chase/.local/lib/python3.8/site-packages/pymysql/err.py'>
  File "/home/chase/.local/lib/python3.8/site-packages/pymysql/err.py", line 143, in raise_mysql_exception
    raise errorclass(errno, errval)
          │          │      └ "Duplicate entry '180.201.163.246:6800' for key 'device.PRIMARY'"
          │          └ 1062
          └ <class 'pymysql.err.IntegrityError'>

sqlalchemy.exc.IntegrityError: (pymysql.err.IntegrityError) (1062, "Duplicate entry '180.201.163.246:6800' for key 'device.PRIMARY'")
[SQL: UPDATE device SET server_id=%(server_id)s, ip=%(ip)s, username=%(username)s, password=%(password)s, address=%(address)s, port=%(port)s, valid=%(valid)s WHERE device.ip = %(ip_1)s]
[parameters: {'server_id': '180.201.163.246:6800', 'ip': '180.201.163.246', 'username': 'chase', 'password': '83746787317130470492925194587438482082116884060486502350323464859555725936402787436212448834067480275863794473384611569921447519541718500489264107742 ... (10 characters truncated) ... 20029771531968012982936563391342195428975564951169556311707805390756234702210768125744295514480082584846901836727692986457255102591467344723276785826', 'address': '/home/users/CT/pycharmproject/spiders/', 'port': 6800, 'valid': 1, 'ip_1': '180.201.163.246'}]
(Background on this error at: https://sqlalche.me/e/14/gkpj)
2022-05-14 01:18:13.219 | ERROR    | base.db.mysql:update:390 - 【mysql更新数据出错】
Traceback (most recent call last):

  File "/home/chase/.local/lib/python3.8/site-packages/sqlalchemy/engine/base.py", line 1771, in _execute_context
    self.dialect.do_execute(
    │    │       └ <function DefaultDialect.do_execute at 0x7f31f38f75e0>
    │    └ <sqlalchemy.dialects.mysql.pymysql.MySQLDialect_pymysql object at 0x7f3103ffde20>
    └ <sqlalchemy.engine.base.Connection object at 0x7f305847c610>
  File "/home/chase/.local/lib/python3.8/site-packages/sqlalchemy/engine/default.py", line 717, in do_execute
    cursor.execute(statement, parameters)
    │      │       │          └ {'server_id': '180.201.163.246:6800', 'ip': '180.201.163.246', 'username': 'chase', 'password': '6609993186077371893822709735...
    │      │       └ 'UPDATE device SET server_id=%(server_id)s, ip=%(ip)s, username=%(username)s, password=%(password)s, address=%(address)s, por...
    │      └ <function Cursor.execute at 0x7f31f354cdc0>
    └ <pymysql.cursors.Cursor object at 0x7f3038166880>
  File "/home/chase/.local/lib/python3.8/site-packages/pymysql/cursors.py", line 148, in execute
    result = self._query(query)
             │    │      └ "UPDATE device SET server_id='180.201.163.246:6800', ip='180.201.163.246', username='chase', password='6609993186077371893822...
             │    └ <function Cursor._query at 0x7f31f34d7280>
             └ <pymysql.cursors.Cursor object at 0x7f3038166880>
  File "/home/chase/.local/lib/python3.8/site-packages/pymysql/cursors.py", line 310, in _query
    conn.query(q)
    │    │     └ "UPDATE device SET server_id='180.201.163.246:6800', ip='180.201.163.246', username='chase', password='6609993186077371893822...
    │    └ <function Connection.query at 0x7f31f34e5670>
    └ <pymysql.connections.Connection object at 0x7f30384e0ac0>
  File "/home/chase/.local/lib/python3.8/site-packages/pymysql/connections.py", line 548, in query
    self._affected_rows = self._read_query_result(unbuffered=unbuffered)
    │    │                │    │                             └ False
    │    │                │    └ <function Connection._read_query_result at 0x7f31f34e5ca0>
    │    │                └ <pymysql.connections.Connection object at 0x7f30384e0ac0>
    │    └ 1
    └ <pymysql.connections.Connection object at 0x7f30384e0ac0>
  File "/home/chase/.local/lib/python3.8/site-packages/pymysql/connections.py", line 775, in _read_query_result
    result.read()
    │      └ <function MySQLResult.read at 0x7f31f34e64c0>
    └ <pymysql.connections.MySQLResult object at 0x7f30b85753a0>
  File "/home/chase/.local/lib/python3.8/site-packages/pymysql/connections.py", line 1156, in read
    first_packet = self.connection._read_packet()
                   │    └ None
                   └ <pymysql.connections.MySQLResult object at 0x7f30b85753a0>
  File "/home/chase/.local/lib/python3.8/site-packages/pymysql/connections.py", line 725, in _read_packet
    packet.raise_for_error()
    │      └ <function MysqlPacket.raise_for_error at 0x7f31f34ddee0>
    └ <pymysql.protocol.MysqlPacket object at 0x7f30d81e9820>
  File "/home/chase/.local/lib/python3.8/site-packages/pymysql/protocol.py", line 221, in raise_for_error
    err.raise_mysql_exception(self._data)
    │   │                     │    └ <member '_data' of 'MysqlPacket' objects>
    │   │                     └ <pymysql.protocol.MysqlPacket object at 0x7f30d81e9820>
    │   └ <function raise_mysql_exception at 0x7f31f358c670>
    └ <module 'pymysql.err' from '/home/chase/.local/lib/python3.8/site-packages/pymysql/err.py'>
  File "/home/chase/.local/lib/python3.8/site-packages/pymysql/err.py", line 143, in raise_mysql_exception
    raise errorclass(errno, errval)
          │          │      └ "Duplicate entry '180.201.163.246:6800' for key 'device.PRIMARY'"
          │          └ 1062
          └ <class 'pymysql.err.IntegrityError'>

pymysql.err.IntegrityError: (1062, "Duplicate entry '180.201.163.246:6800' for key 'device.PRIMARY'")


The above exception was the direct cause of the following exception:


Traceback (most recent call last):

  File "/usr/lib/python3.8/threading.py", line 890, in _bootstrap
    self._bootstrap_inner()
    │    └ <function Thread._bootstrap_inner at 0x7f321bf29a60>
    └ <Thread(Thread-7598, started daemon 139840712275712)>
  File "/usr/lib/python3.8/threading.py", line 932, in _bootstrap_inner
    self.run()
    │    └ <function Thread.run at 0x7f321bf29790>
    └ <Thread(Thread-7598, started daemon 139840712275712)>
  File "/usr/lib/python3.8/threading.py", line 870, in run
    self._target(*self._args, **self._kwargs)
    │    │        │    │        │    └ {}
    │    │        │    │        └ <Thread(Thread-7598, started daemon 139840712275712)>
    │    │        │    └ ('ProjectManager.run_func_by_thread',)
    │    │        └ <Thread(Thread-7598, started daemon 139840712275712)>
    │    └ <bound method ProjectManager.get_request_from_keywords_hot of <monitor.projectManager.ProjectManager object at 0x7f31042e52e0>>
    └ <Thread(Thread-7598, started daemon 139840712275712)>

  File "/home/users/Scy/yuqing/spider/monitor/projectManager.py", line 799, in get_request_from_keywords_hot
    self.start_finished_spider_every_interval(project_names)
    │    │                                    └ ['default', 'test']
    │    └ <function ProjectManager.start_finished_spider_every_interval at 0x7f3104005280>
    └ <monitor.projectManager.ProjectManager object at 0x7f31042e52e0>

  File "/home/users/Scy/yuqing/spider/monitor/projectManager.py", line 784, in start_finished_spider_every_interval
    self[name].start_spider()
    │    └ 'default'
    └ <monitor.projectManager.ProjectManager object at 0x7f31042e52e0>

  File "/home/users/Scy/yuqing/spider/monitor/projectManager.py", line 366, in start_spider
    self.update_device_valid(device)
    │    │                   └ <monitor.deviceManager.DeviceC object at 0x7f3104029220>
    │    └ <function Project.update_device_valid at 0x7f3104003280>
    └ <monitor.projectManager.Project object at 0x7f3104029460>

  File "/home/users/Scy/yuqing/spider/monitor/projectManager.py", line 421, in update_device_valid
    self.database_manager.mysql.update(Device(**device.to_item()))
    │    │                │     │      │        │      └ <function DeviceC.to_item at 0x7f31f34ed310>
    │    │                │     │      │        └ <monitor.deviceManager.DeviceC object at 0x7f3104029220>
    │    │                │     │      └ <class 'base.db.mysql.Device'>
    │    │                │     └ <function Mysql.update at 0x7f31f35f4790>
    │    │                └ <base.db.mysql.Mysql object at 0x7f3103ffdfd0>
    │    └ <base.db.dbSlot.Slot object at 0x7f3103ffdf10>
    └ <monitor.projectManager.Project object at 0x7f3104029460>

> File "/home/users/Scy/yuqing/spider/base/db/mysql.py", line 375, in update
    row.update(new)
    │   │      └ {'server_id': '180.201.163.246:6800', 'ip': '180.201.163.246', 'username': 'chase', 'password': '6609993186077371893822709735...
    │   └ <function Query.update at 0x7f31f37333a0>
    └ <sqlalchemy.orm.query.Query object at 0x7f30d83f35e0>

  File "/home/chase/.local/lib/python3.8/site-packages/sqlalchemy/orm/query.py", line 3221, in update
    result = self.session.execute(
             │    │       └ <function Session.execute at 0x7f31f370faf0>
             │    └ <sqlalchemy.orm.session.Session object at 0x7f30b855a460>
             └ <sqlalchemy.orm.query.Query object at 0x7f30d83f35e0>
  File "/home/chase/.local/lib/python3.8/site-packages/sqlalchemy/orm/session.py", line 1689, in execute
    result = conn._execute_20(statement, params or {}, execution_options)
             │    │           │          │             └ immutabledict({'synchronize_session': 'evaluate', '_sa_orm_update_options': default_update_options(_matched_objects=[], _reso...
             │    │           │          └ immutabledict({})
             │    │           └ <sqlalchemy.sql.annotation.AnnotatedUpdate object at 0x7f30381666d0>
             │    └ <function Connection._execute_20 at 0x7f31f39bc790>
             └ <sqlalchemy.engine.base.Connection object at 0x7f305847c610>
  File "/home/chase/.local/lib/python3.8/site-packages/sqlalchemy/engine/base.py", line 1583, in _execute_20
    return meth(self, args_10style, kwargs_10style, execution_options)
           │    │     │             │               └ immutabledict({'synchronize_session': 'evaluate', '_sa_orm_update_options': default_update_options(_matched_objects=[], _reso...
           │    │     │             └ immutabledict({})
           │    │     └ ({},)
           │    └ <sqlalchemy.engine.base.Connection object at 0x7f305847c610>
           └ <bound method ClauseElement._execute_on_connection of <sqlalchemy.sql.annotation.AnnotatedUpdate object at 0x7f30381666d0>>
  File "/home/chase/.local/lib/python3.8/site-packages/sqlalchemy/sql/elements.py", line 323, in _execute_on_connection
    return connection._execute_clauseelement(
           │          └ <function Connection._execute_clauseelement at 0x7f31f39bc5e0>
           └ <sqlalchemy.engine.base.Connection object at 0x7f305847c610>
  File "/home/chase/.local/lib/python3.8/site-packages/sqlalchemy/engine/base.py", line 1452, in _execute_clauseelement
    ret = self._execute_context(
          │    └ <function Connection._execute_context at 0x7f31f39bc8b0>
          └ <sqlalchemy.engine.base.Connection object at 0x7f305847c610>
  File "/home/chase/.local/lib/python3.8/site-packages/sqlalchemy/engine/base.py", line 1814, in _execute_context
    self._handle_dbapi_exception(
    │    └ <function Connection._handle_dbapi_exception at 0x7f31f39bca60>
    └ <sqlalchemy.engine.base.Connection object at 0x7f305847c610>
  File "/home/chase/.local/lib/python3.8/site-packages/sqlalchemy/engine/base.py", line 1995, in _handle_dbapi_exception
    util.raise_(
    │    └ <function raise_ at 0x7f31f3d7ea60>
    └ <module 'sqlalchemy.util' from '/home/chase/.local/lib/python3.8/site-packages/sqlalchemy/util/__init__.py'>
  File "/home/chase/.local/lib/python3.8/site-packages/sqlalchemy/util/compat.py", line 207, in raise_
    raise exception
  File "/home/chase/.local/lib/python3.8/site-packages/sqlalchemy/engine/base.py", line 1771, in _execute_context
    self.dialect.do_execute(
    │    │       └ <function DefaultDialect.do_execute at 0x7f31f38f75e0>
    │    └ <sqlalchemy.dialects.mysql.pymysql.MySQLDialect_pymysql object at 0x7f3103ffde20>
    └ <sqlalchemy.engine.base.Connection object at 0x7f305847c610>
  File "/home/chase/.local/lib/python3.8/site-packages/sqlalchemy/engine/default.py", line 717, in do_execute
    cursor.execute(statement, parameters)
    │      │       │          └ {'server_id': '180.201.163.246:6800', 'ip': '180.201.163.246', 'username': 'chase', 'password': '6609993186077371893822709735...
    │      │       └ 'UPDATE device SET server_id=%(server_id)s, ip=%(ip)s, username=%(username)s, password=%(password)s, address=%(address)s, por...
    │      └ <function Cursor.execute at 0x7f31f354cdc0>
    └ <pymysql.cursors.Cursor object at 0x7f3038166880>
  File "/home/chase/.local/lib/python3.8/site-packages/pymysql/cursors.py", line 148, in execute
    result = self._query(query)
             │    │      └ "UPDATE device SET server_id='180.201.163.246:6800', ip='180.201.163.246', username='chase', password='6609993186077371893822...
             │    └ <function Cursor._query at 0x7f31f34d7280>
             └ <pymysql.cursors.Cursor object at 0x7f3038166880>
  File "/home/chase/.local/lib/python3.8/site-packages/pymysql/cursors.py", line 310, in _query
    conn.query(q)
    │    │     └ "UPDATE device SET server_id='180.201.163.246:6800', ip='180.201.163.246', username='chase', password='6609993186077371893822...
    │    └ <function Connection.query at 0x7f31f34e5670>
    └ <pymysql.connections.Connection object at 0x7f30384e0ac0>
  File "/home/chase/.local/lib/python3.8/site-packages/pymysql/connections.py", line 548, in query
    self._affected_rows = self._read_query_result(unbuffered=unbuffered)
    │    │                │    │                             └ False
    │    │                │    └ <function Connection._read_query_result at 0x7f31f34e5ca0>
    │    │                └ <pymysql.connections.Connection object at 0x7f30384e0ac0>
    │    └ 1
    └ <pymysql.connections.Connection object at 0x7f30384e0ac0>
  File "/home/chase/.local/lib/python3.8/site-packages/pymysql/connections.py", line 775, in _read_query_result
    result.read()
    │      └ <function MySQLResult.read at 0x7f31f34e64c0>
    └ <pymysql.connections.MySQLResult object at 0x7f30b85753a0>
  File "/home/chase/.local/lib/python3.8/site-packages/pymysql/connections.py", line 1156, in read
    first_packet = self.connection._read_packet()
                   │    └ None
                   └ <pymysql.connections.MySQLResult object at 0x7f30b85753a0>
  File "/home/chase/.local/lib/python3.8/site-packages/pymysql/connections.py", line 725, in _read_packet
    packet.raise_for_error()
    │      └ <function MysqlPacket.raise_for_error at 0x7f31f34ddee0>
    └ <pymysql.protocol.MysqlPacket object at 0x7f30d81e9820>
  File "/home/chase/.local/lib/python3.8/site-packages/pymysql/protocol.py", line 221, in raise_for_error
    err.raise_mysql_exception(self._data)
    │   │                     │    └ <member '_data' of 'MysqlPacket' objects>
    │   │                     └ <pymysql.protocol.MysqlPacket object at 0x7f30d81e9820>
    │   └ <function raise_mysql_exception at 0x7f31f358c670>
    └ <module 'pymysql.err' from '/home/chase/.local/lib/python3.8/site-packages/pymysql/err.py'>
  File "/home/chase/.local/lib/python3.8/site-packages/pymysql/err.py", line 143, in raise_mysql_exception
    raise errorclass(errno, errval)
          │          │      └ "Duplicate entry '180.201.163.246:6800' for key 'device.PRIMARY'"
          │          └ 1062
          └ <class 'pymysql.err.IntegrityError'>

sqlalchemy.exc.IntegrityError: (pymysql.err.IntegrityError) (1062, "Duplicate entry '180.201.163.246:6800' for key 'device.PRIMARY'")
[SQL: UPDATE device SET server_id=%(server_id)s, ip=%(ip)s, username=%(username)s, password=%(password)s, address=%(address)s, port=%(port)s, valid=%(valid)s WHERE device.ip = %(ip_1)s]
[parameters: {'server_id': '180.201.163.246:6800', 'ip': '180.201.163.246', 'username': 'chase', 'password': '66099931860773718938227097350505055688311167454372020048793288418908218840052478055077700897900649443849702947651456628678226448442598033099538877218 ... (10 characters truncated) ... 66071304729436359462308547720934923033595976683052109416357882008867299977468883049978917919732398701546389388437510048417097461136014047894566905982', 'address': '/home/users/CT/pycharmproject/spiders/', 'port': 6800, 'valid': 1, 'ip_1': '180.201.163.246'}]
(Background on this error at: https://sqlalche.me/e/14/gkpj)
2022-05-14 01:18:25.441 | ERROR    | base.db.mysql:update:390 - 【mysql更新数据出错】
Traceback (most recent call last):

  File "/usr/lib/python3.8/threading.py", line 890, in _bootstrap
    self._bootstrap_inner()
    │    └ <function Thread._bootstrap_inner at 0x7f321bf29a60>
    └ <Thread(Thread-7593, started daemon 139837556619008)>
  File "/usr/lib/python3.8/threading.py", line 932, in _bootstrap_inner
    self.run()
    │    └ <function Thread.run at 0x7f321bf29790>
    └ <Thread(Thread-7593, started daemon 139837556619008)>
  File "/usr/lib/python3.8/threading.py", line 870, in run
    self._target(*self._args, **self._kwargs)
    │    │        │    │        │    └ {}
    │    │        │    │        └ <Thread(Thread-7593, started daemon 139837556619008)>
    │    │        │    └ ('ProjectManager.run_func_by_thread',)
    │    │        └ <Thread(Thread-7593, started daemon 139837556619008)>
    │    └ <bound method ProjectManager.get_request_from_keywords_hot of <monitor.projectManager.ProjectManager object at 0x7f31042e52e0>>
    └ <Thread(Thread-7593, started daemon 139837556619008)>

  File "/home/users/Scy/yuqing/spider/monitor/projectManager.py", line 799, in get_request_from_keywords_hot
    self.start_finished_spider_every_interval(project_names)
    │    │                                    └ ['default', 'test']
    │    └ <function ProjectManager.start_finished_spider_every_interval at 0x7f3104005280>
    └ <monitor.projectManager.ProjectManager object at 0x7f31042e52e0>

  File "/home/users/Scy/yuqing/spider/monitor/projectManager.py", line 784, in start_finished_spider_every_interval
    self[name].start_spider()
    │    └ 'default'
    └ <monitor.projectManager.ProjectManager object at 0x7f31042e52e0>

  File "/home/users/Scy/yuqing/spider/monitor/projectManager.py", line 366, in start_spider
    self.update_device_valid(device)
    │    │                   └ <monitor.deviceManager.DeviceC object at 0x7f3104029220>
    │    └ <function Project.update_device_valid at 0x7f3104003280>
    └ <monitor.projectManager.Project object at 0x7f3104029460>

  File "/home/users/Scy/yuqing/spider/monitor/projectManager.py", line 421, in update_device_valid
    self.database_manager.mysql.update(Device(**device.to_item()))
    │    │                │     │      │        │      └ <function DeviceC.to_item at 0x7f31f34ed310>
    │    │                │     │      │        └ <monitor.deviceManager.DeviceC object at 0x7f3104029220>
    │    │                │     │      └ <class 'base.db.mysql.Device'>
    │    │                │     └ <function Mysql.update at 0x7f31f35f4790>
    │    │                └ <base.db.mysql.Mysql object at 0x7f3103ffdfd0>
    │    └ <base.db.dbSlot.Slot object at 0x7f3103ffdf10>
    └ <monitor.projectManager.Project object at 0x7f3104029460>

> File "/home/users/Scy/yuqing/spider/base/db/mysql.py", line 373, in update
    if row.all():
       │   └ <function Query.all at 0x7f31f3730700>
       └ <sqlalchemy.orm.query.Query object at 0x7f30b8315460>

  File "/home/chase/.local/lib/python3.8/site-packages/sqlalchemy/orm/query.py", line 2711, in all
    return self._iter().all()
           │    └ <function Query._iter at 0x7f31f3730e50>
           └ <sqlalchemy.orm.query.Query object at 0x7f30b8315460>
  File "/home/chase/.local/lib/python3.8/site-packages/sqlalchemy/orm/query.py", line 2846, in _iter
    result = self.session.execute(
             │    │       └ <function Session.execute at 0x7f31f370faf0>
             │    └ <sqlalchemy.orm.session.Session object at 0x7f30d87b8430>
             └ <sqlalchemy.orm.query.Query object at 0x7f30b8315460>
  File "/home/chase/.local/lib/python3.8/site-packages/sqlalchemy/orm/session.py", line 1688, in execute
    conn = self._connection_for_bind(bind)
           │    │                    └ Engine(mysql+pymysql://root:***@180.201.163.246:33061/spider?autocommit=true&charset=utf8)
           │    └ <function Session._connection_for_bind at 0x7f31f370fa60>
           └ <sqlalchemy.orm.session.Session object at 0x7f30d87b8430>
  File "/home/chase/.local/lib/python3.8/site-packages/sqlalchemy/orm/session.py", line 1529, in _connection_for_bind
    return self._transaction._connection_for_bind(
           │    │            └ <function SessionTransaction._connection_for_bind at 0x7f31f370c670>
           │    └ <sqlalchemy.orm.session.SessionTransaction object at 0x7f30186f3b50>
           └ <sqlalchemy.orm.session.Session object at 0x7f30d87b8430>
  File "/home/chase/.local/lib/python3.8/site-packages/sqlalchemy/orm/session.py", line 747, in _connection_for_bind
    conn = bind.connect()
           │    └ <function Engine.connect at 0x7f31f39c6040>
           └ Engine(mysql+pymysql://root:***@180.201.163.246:33061/spider?autocommit=true&charset=utf8)
  File "/home/chase/.local/lib/python3.8/site-packages/sqlalchemy/engine/base.py", line 3166, in connect
    return self._connection_cls(self, close_with_result=close_with_result)
           │    │               │                       └ False
           │    │               └ Engine(mysql+pymysql://root:***@180.201.163.246:33061/spider?autocommit=true&charset=utf8)
           │    └ <class 'sqlalchemy.engine.base.Connection'>
           └ Engine(mysql+pymysql://root:***@180.201.163.246:33061/spider?autocommit=true&charset=utf8)
  File "/home/chase/.local/lib/python3.8/site-packages/sqlalchemy/engine/base.py", line 96, in __init__
    else engine.raw_connection()
         │      └ <function Engine.raw_connection at 0x7f31f39c64c0>
         └ Engine(mysql+pymysql://root:***@180.201.163.246:33061/spider?autocommit=true&charset=utf8)
  File "/home/chase/.local/lib/python3.8/site-packages/sqlalchemy/engine/base.py", line 3245, in raw_connection
    return self._wrap_pool_connect(self.pool.connect, _connection)
           │    │                  │    │    │        └ None
           │    │                  │    │    └ <function Pool.connect at 0x7f31f396f550>
           │    │                  │    └ <sqlalchemy.pool.impl.QueuePool object at 0x7f3103ffdb20>
           │    │                  └ Engine(mysql+pymysql://root:***@180.201.163.246:33061/spider?autocommit=true&charset=utf8)
           │    └ <function Engine._wrap_pool_connect at 0x7f31f39c60d0>
           └ Engine(mysql+pymysql://root:***@180.201.163.246:33061/spider?autocommit=true&charset=utf8)
  File "/home/chase/.local/lib/python3.8/site-packages/sqlalchemy/engine/base.py", line 3212, in _wrap_pool_connect
    return fn()
           └ <bound method Pool.connect of <sqlalchemy.pool.impl.QueuePool object at 0x7f3103ffdb20>>
  File "/home/chase/.local/lib/python3.8/site-packages/sqlalchemy/pool/base.py", line 307, in connect
    return _ConnectionFairy._checkout(self)
           │                │         └ <sqlalchemy.pool.impl.QueuePool object at 0x7f3103ffdb20>
           │                └ <classmethod object at 0x7f31f3969a00>
           └ <class 'sqlalchemy.pool.base._ConnectionFairy'>
  File "/home/chase/.local/lib/python3.8/site-packages/sqlalchemy/pool/base.py", line 767, in _checkout
    fairy = _ConnectionRecord.checkout(pool)
            │                 │        └ <sqlalchemy.pool.impl.QueuePool object at 0x7f3103ffdb20>
            │                 └ <classmethod object at 0x7f31f39699a0>
            └ <class 'sqlalchemy.pool.base._ConnectionRecord'>
  File "/home/chase/.local/lib/python3.8/site-packages/sqlalchemy/pool/base.py", line 425, in checkout
    rec = pool._do_get()
          │    └ <function QueuePool._do_get at 0x7f31f39819d0>
          └ <sqlalchemy.pool.impl.QueuePool object at 0x7f3103ffdb20>
  File "/home/chase/.local/lib/python3.8/site-packages/sqlalchemy/pool/impl.py", line 134, in _do_get
    raise exc.TimeoutError(
          │   └ <class 'sqlalchemy.exc.TimeoutError'>
          └ <module 'sqlalchemy.exc' from '/home/chase/.local/lib/python3.8/site-packages/sqlalchemy/exc.py'>

sqlalchemy.exc.TimeoutError: QueuePool limit of size 5 overflow 10 reached, connection timed out, timeout 30.00 (Background on this error at: https://sqlalche.me/e/14/3o7r)
2022-05-14 01:18:29.535 | ERROR    | base.db.mysql:update:390 - 【mysql更新数据出错】
Traceback (most recent call last):

  File "/home/chase/.local/lib/python3.8/site-packages/sqlalchemy/engine/base.py", line 1771, in _execute_context
    self.dialect.do_execute(
    │    │       └ <function DefaultDialect.do_execute at 0x7f31f38f75e0>
    │    └ <sqlalchemy.dialects.mysql.pymysql.MySQLDialect_pymysql object at 0x7f3103ffde20>
    └ <sqlalchemy.engine.base.Connection object at 0x7f30b814ae20>
  File "/home/chase/.local/lib/python3.8/site-packages/sqlalchemy/engine/default.py", line 717, in do_execute
    cursor.execute(statement, parameters)
    │      │       │          └ {'server_id': '180.201.163.246:6800', 'ip': '180.201.163.246', 'username': 'chase', 'password': '8439247564013406313063729801...
    │      │       └ 'UPDATE device SET server_id=%(server_id)s, ip=%(ip)s, username=%(username)s, password=%(password)s, address=%(address)s, por...
    │      └ <function Cursor.execute at 0x7f31f354cdc0>
    └ <pymysql.cursors.Cursor object at 0x7f30b877a430>
  File "/home/chase/.local/lib/python3.8/site-packages/pymysql/cursors.py", line 148, in execute
    result = self._query(query)
             │    │      └ "UPDATE device SET server_id='180.201.163.246:6800', ip='180.201.163.246', username='chase', password='8439247564013406313063...
             │    └ <function Cursor._query at 0x7f31f34d7280>
             └ <pymysql.cursors.Cursor object at 0x7f30b877a430>
  File "/home/chase/.local/lib/python3.8/site-packages/pymysql/cursors.py", line 310, in _query
    conn.query(q)
    │    │     └ "UPDATE device SET server_id='180.201.163.246:6800', ip='180.201.163.246', username='chase', password='8439247564013406313063...
    │    └ <function Connection.query at 0x7f31f34e5670>
    └ <pymysql.connections.Connection object at 0x7f3038366250>
  File "/home/chase/.local/lib/python3.8/site-packages/pymysql/connections.py", line 548, in query
    self._affected_rows = self._read_query_result(unbuffered=unbuffered)
    │    │                │    │                             └ False
    │    │                │    └ <function Connection._read_query_result at 0x7f31f34e5ca0>
    │    │                └ <pymysql.connections.Connection object at 0x7f3038366250>
    │    └ 1
    └ <pymysql.connections.Connection object at 0x7f3038366250>
  File "/home/chase/.local/lib/python3.8/site-packages/pymysql/connections.py", line 775, in _read_query_result
    result.read()
    │      └ <function MySQLResult.read at 0x7f31f34e64c0>
    └ <pymysql.connections.MySQLResult object at 0x7f30b8144cd0>
  File "/home/chase/.local/lib/python3.8/site-packages/pymysql/connections.py", line 1156, in read
    first_packet = self.connection._read_packet()
                   │    └ None
                   └ <pymysql.connections.MySQLResult object at 0x7f30b8144cd0>
  File "/home/chase/.local/lib/python3.8/site-packages/pymysql/connections.py", line 725, in _read_packet
    packet.raise_for_error()
    │      └ <function MysqlPacket.raise_for_error at 0x7f31f34ddee0>
    └ <pymysql.protocol.MysqlPacket object at 0x7f2f98556bb0>
  File "/home/chase/.local/lib/python3.8/site-packages/pymysql/protocol.py", line 221, in raise_for_error
    err.raise_mysql_exception(self._data)
    │   │                     │    └ <member '_data' of 'MysqlPacket' objects>
    │   │                     └ <pymysql.protocol.MysqlPacket object at 0x7f2f98556bb0>
    │   └ <function raise_mysql_exception at 0x7f31f358c670>
    └ <module 'pymysql.err' from '/home/chase/.local/lib/python3.8/site-packages/pymysql/err.py'>
  File "/home/chase/.local/lib/python3.8/site-packages/pymysql/err.py", line 143, in raise_mysql_exception
    raise errorclass(errno, errval)
          │          │      └ "Duplicate entry '180.201.163.246:6800' for key 'device.PRIMARY'"
          │          └ 1062
          └ <class 'pymysql.err.IntegrityError'>

pymysql.err.IntegrityError: (1062, "Duplicate entry '180.201.163.246:6800' for key 'device.PRIMARY'")


The above exception was the direct cause of the following exception:


Traceback (most recent call last):

  File "/usr/lib/python3.8/threading.py", line 890, in _bootstrap
    self._bootstrap_inner()
    │    └ <function Thread._bootstrap_inner at 0x7f321bf29a60>
    └ <Thread(Thread-7603, started daemon 139836625028864)>
  File "/usr/lib/python3.8/threading.py", line 932, in _bootstrap_inner
    self.run()
    │    └ <function Thread.run at 0x7f321bf29790>
    └ <Thread(Thread-7603, started daemon 139836625028864)>
  File "/usr/lib/python3.8/threading.py", line 870, in run
    self._target(*self._args, **self._kwargs)
    │    │        │    │        │    └ {}
    │    │        │    │        └ <Thread(Thread-7603, started daemon 139836625028864)>
    │    │        │    └ ('ProjectManager.run_func_by_thread',)
    │    │        └ <Thread(Thread-7603, started daemon 139836625028864)>
    │    └ <bound method ProjectManager.get_request_from_keywords_hot of <monitor.projectManager.ProjectManager object at 0x7f31042e52e0>>
    └ <Thread(Thread-7603, started daemon 139836625028864)>

  File "/home/users/Scy/yuqing/spider/monitor/projectManager.py", line 799, in get_request_from_keywords_hot
    self.start_finished_spider_every_interval(project_names)
    │    │                                    └ ['default', 'test']
    │    └ <function ProjectManager.start_finished_spider_every_interval at 0x7f3104005280>
    └ <monitor.projectManager.ProjectManager object at 0x7f31042e52e0>

  File "/home/users/Scy/yuqing/spider/monitor/projectManager.py", line 784, in start_finished_spider_every_interval
    self[name].start_spider()
    │    └ 'default'
    └ <monitor.projectManager.ProjectManager object at 0x7f31042e52e0>

  File "/home/users/Scy/yuqing/spider/monitor/projectManager.py", line 366, in start_spider
    self.update_device_valid(device)
    │    │                   └ <monitor.deviceManager.DeviceC object at 0x7f3104029220>
    │    └ <function Project.update_device_valid at 0x7f3104003280>
    └ <monitor.projectManager.Project object at 0x7f3104029460>

  File "/home/users/Scy/yuqing/spider/monitor/projectManager.py", line 421, in update_device_valid
    self.database_manager.mysql.update(Device(**device.to_item()))
    │    │                │     │      │        │      └ <function DeviceC.to_item at 0x7f31f34ed310>
    │    │                │     │      │        └ <monitor.deviceManager.DeviceC object at 0x7f3104029220>
    │    │                │     │      └ <class 'base.db.mysql.Device'>
    │    │                │     └ <function Mysql.update at 0x7f31f35f4790>
    │    │                └ <base.db.mysql.Mysql object at 0x7f3103ffdfd0>
    │    └ <base.db.dbSlot.Slot object at 0x7f3103ffdf10>
    └ <monitor.projectManager.Project object at 0x7f3104029460>

> File "/home/users/Scy/yuqing/spider/base/db/mysql.py", line 375, in update
    row.update(new)
    │   │      └ {'server_id': '180.201.163.246:6800', 'ip': '180.201.163.246', 'username': 'chase', 'password': '8439247564013406313063729801...
    │   └ <function Query.update at 0x7f31f37333a0>
    └ <sqlalchemy.orm.query.Query object at 0x7f30b8370820>

  File "/home/chase/.local/lib/python3.8/site-packages/sqlalchemy/orm/query.py", line 3221, in update
    result = self.session.execute(
             │    │       └ <function Session.execute at 0x7f31f370faf0>
             │    └ <sqlalchemy.orm.session.Session object at 0x7f2fb84a1c40>
             └ <sqlalchemy.orm.query.Query object at 0x7f30b8370820>
  File "/home/chase/.local/lib/python3.8/site-packages/sqlalchemy/orm/session.py", line 1689, in execute
    result = conn._execute_20(statement, params or {}, execution_options)
             │    │           │          │             └ immutabledict({'synchronize_session': 'evaluate', '_sa_orm_update_options': default_update_options(_matched_objects=[], _reso...
             │    │           │          └ immutabledict({})
             │    │           └ <sqlalchemy.sql.annotation.AnnotatedUpdate object at 0x7f3078279af0>
             │    └ <function Connection._execute_20 at 0x7f31f39bc790>
             └ <sqlalchemy.engine.base.Connection object at 0x7f30b814ae20>
  File "/home/chase/.local/lib/python3.8/site-packages/sqlalchemy/engine/base.py", line 1583, in _execute_20
    return meth(self, args_10style, kwargs_10style, execution_options)
           │    │     │             │               └ immutabledict({'synchronize_session': 'evaluate', '_sa_orm_update_options': default_update_options(_matched_objects=[], _reso...
           │    │     │             └ immutabledict({})
           │    │     └ ({},)
           │    └ <sqlalchemy.engine.base.Connection object at 0x7f30b814ae20>
           └ <bound method ClauseElement._execute_on_connection of <sqlalchemy.sql.annotation.AnnotatedUpdate object at 0x7f3078279af0>>
  File "/home/chase/.local/lib/python3.8/site-packages/sqlalchemy/sql/elements.py", line 323, in _execute_on_connection
    return connection._execute_clauseelement(
           │          └ <function Connection._execute_clauseelement at 0x7f31f39bc5e0>
           └ <sqlalchemy.engine.base.Connection object at 0x7f30b814ae20>
  File "/home/chase/.local/lib/python3.8/site-packages/sqlalchemy/engine/base.py", line 1452, in _execute_clauseelement
    ret = self._execute_context(
          │    └ <function Connection._execute_context at 0x7f31f39bc8b0>
          └ <sqlalchemy.engine.base.Connection object at 0x7f30b814ae20>
  File "/home/chase/.local/lib/python3.8/site-packages/sqlalchemy/engine/base.py", line 1814, in _execute_context
    self._handle_dbapi_exception(
    │    └ <function Connection._handle_dbapi_exception at 0x7f31f39bca60>
    └ <sqlalchemy.engine.base.Connection object at 0x7f30b814ae20>
  File "/home/chase/.local/lib/python3.8/site-packages/sqlalchemy/engine/base.py", line 1995, in _handle_dbapi_exception
    util.raise_(
    │    └ <function raise_ at 0x7f31f3d7ea60>
    └ <module 'sqlalchemy.util' from '/home/chase/.local/lib/python3.8/site-packages/sqlalchemy/util/__init__.py'>
  File "/home/chase/.local/lib/python3.8/site-packages/sqlalchemy/util/compat.py", line 207, in raise_
    raise exception
  File "/home/chase/.local/lib/python3.8/site-packages/sqlalchemy/engine/base.py", line 1771, in _execute_context
    self.dialect.do_execute(
    │    │       └ <function DefaultDialect.do_execute at 0x7f31f38f75e0>
    │    └ <sqlalchemy.dialects.mysql.pymysql.MySQLDialect_pymysql object at 0x7f3103ffde20>
    └ <sqlalchemy.engine.base.Connection object at 0x7f30b814ae20>
  File "/home/chase/.local/lib/python3.8/site-packages/sqlalchemy/engine/default.py", line 717, in do_execute
    cursor.execute(statement, parameters)
    │      │       │          └ {'server_id': '180.201.163.246:6800', 'ip': '180.201.163.246', 'username': 'chase', 'password': '8439247564013406313063729801...
    │      │       └ 'UPDATE device SET server_id=%(server_id)s, ip=%(ip)s, username=%(username)s, password=%(password)s, address=%(address)s, por...
    │      └ <function Cursor.execute at 0x7f31f354cdc0>
    └ <pymysql.cursors.Cursor object at 0x7f30b877a430>
  File "/home/chase/.local/lib/python3.8/site-packages/pymysql/cursors.py", line 148, in execute
    result = self._query(query)
             │    │      └ "UPDATE device SET server_id='180.201.163.246:6800', ip='180.201.163.246', username='chase', password='8439247564013406313063...
             │    └ <function Cursor._query at 0x7f31f34d7280>
             └ <pymysql.cursors.Cursor object at 0x7f30b877a430>
  File "/home/chase/.local/lib/python3.8/site-packages/pymysql/cursors.py", line 310, in _query
    conn.query(q)
    │    │     └ "UPDATE device SET server_id='180.201.163.246:6800', ip='180.201.163.246', username='chase', password='8439247564013406313063...
    │    └ <function Connection.query at 0x7f31f34e5670>
    └ <pymysql.connections.Connection object at 0x7f3038366250>
  File "/home/chase/.local/lib/python3.8/site-packages/pymysql/connections.py", line 548, in query
    self._affected_rows = self._read_query_result(unbuffered=unbuffered)
    │    │                │    │                             └ False
    │    │                │    └ <function Connection._read_query_result at 0x7f31f34e5ca0>
    │    │                └ <pymysql.connections.Connection object at 0x7f3038366250>
    │    └ 1
    └ <pymysql.connections.Connection object at 0x7f3038366250>
  File "/home/chase/.local/lib/python3.8/site-packages/pymysql/connections.py", line 775, in _read_query_result
    result.read()
    │      └ <function MySQLResult.read at 0x7f31f34e64c0>
    └ <pymysql.connections.MySQLResult object at 0x7f30b8144cd0>
  File "/home/chase/.local/lib/python3.8/site-packages/pymysql/connections.py", line 1156, in read
    first_packet = self.connection._read_packet()
                   │    └ None
                   └ <pymysql.connections.MySQLResult object at 0x7f30b8144cd0>
  File "/home/chase/.local/lib/python3.8/site-packages/pymysql/connections.py", line 725, in _read_packet
    packet.raise_for_error()
    │      └ <function MysqlPacket.raise_for_error at 0x7f31f34ddee0>
    └ <pymysql.protocol.MysqlPacket object at 0x7f2f98556bb0>
  File "/home/chase/.local/lib/python3.8/site-packages/pymysql/protocol.py", line 221, in raise_for_error
    err.raise_mysql_exception(self._data)
    │   │                     │    └ <member '_data' of 'MysqlPacket' objects>
    │   │                     └ <pymysql.protocol.MysqlPacket object at 0x7f2f98556bb0>
    │   └ <function raise_mysql_exception at 0x7f31f358c670>
    └ <module 'pymysql.err' from '/home/chase/.local/lib/python3.8/site-packages/pymysql/err.py'>
  File "/home/chase/.local/lib/python3.8/site-packages/pymysql/err.py", line 143, in raise_mysql_exception
    raise errorclass(errno, errval)
          │          │      └ "Duplicate entry '180.201.163.246:6800' for key 'device.PRIMARY'"
          │          └ 1062
          └ <class 'pymysql.err.IntegrityError'>

sqlalchemy.exc.IntegrityError: (pymysql.err.IntegrityError) (1062, "Duplicate entry '180.201.163.246:6800' for key 'device.PRIMARY'")
[SQL: UPDATE device SET server_id=%(server_id)s, ip=%(ip)s, username=%(username)s, password=%(password)s, address=%(address)s, port=%(port)s, valid=%(valid)s WHERE device.ip = %(ip_1)s]
[parameters: {'server_id': '180.201.163.246:6800', 'ip': '180.201.163.246', 'username': 'chase', 'password': '84392475640134063130637298018585846426102851693731936169843244144356064527818741109655560069321873446794054636391543382283525828314843049964062750168 ... (9 characters truncated) ... 52395915599240239105016110501430169707839934715674105262450668202542932205561160219633342026910131399933760295873558338337642520622495120812520705141', 'address': '/home/users/CT/pycharmproject/spiders/', 'port': 6800, 'valid': 1, 'ip_1': '180.201.163.246'}]
(Background on this error at: https://sqlalche.me/e/14/gkpj)
2022-05-14 01:19:01.130 | ERROR    | base.db.mysql:update:390 - 【mysql更新数据出错】
Traceback (most recent call last):

  File "/home/chase/.local/lib/python3.8/site-packages/sqlalchemy/engine/base.py", line 1771, in _execute_context
    self.dialect.do_execute(
    │    │       └ <function DefaultDialect.do_execute at 0x7f31f38f75e0>
    │    └ <sqlalchemy.dialects.mysql.pymysql.MySQLDialect_pymysql object at 0x7f3103ffde20>
    └ <sqlalchemy.engine.base.Connection object at 0x7f30b821da00>
  File "/home/chase/.local/lib/python3.8/site-packages/sqlalchemy/engine/default.py", line 717, in do_execute
    cursor.execute(statement, parameters)
    │      │       │          └ {'server_id': '180.201.163.246:6800', 'ip': '180.201.163.246', 'username': 'chase', 'password': '9639645390881749582677706196...
    │      │       └ 'UPDATE device SET server_id=%(server_id)s, ip=%(ip)s, username=%(username)s, password=%(password)s, address=%(address)s, por...
    │      └ <function Cursor.execute at 0x7f31f354cdc0>
    └ <pymysql.cursors.Cursor object at 0x7f30183a9040>
  File "/home/chase/.local/lib/python3.8/site-packages/pymysql/cursors.py", line 148, in execute
    result = self._query(query)
             │    │      └ "UPDATE device SET server_id='180.201.163.246:6800', ip='180.201.163.246', username='chase', password='9639645390881749582677...
             │    └ <function Cursor._query at 0x7f31f34d7280>
             └ <pymysql.cursors.Cursor object at 0x7f30183a9040>
  File "/home/chase/.local/lib/python3.8/site-packages/pymysql/cursors.py", line 310, in _query
    conn.query(q)
    │    │     └ "UPDATE device SET server_id='180.201.163.246:6800', ip='180.201.163.246', username='chase', password='9639645390881749582677...
    │    └ <function Connection.query at 0x7f31f34e5670>
    └ <pymysql.connections.Connection object at 0x7f30d8577e50>
  File "/home/chase/.local/lib/python3.8/site-packages/pymysql/connections.py", line 548, in query
    self._affected_rows = self._read_query_result(unbuffered=unbuffered)
    │    │                │    │                             └ False
    │    │                │    └ <function Connection._read_query_result at 0x7f31f34e5ca0>
    │    │                └ <pymysql.connections.Connection object at 0x7f30d8577e50>
    │    └ 1
    └ <pymysql.connections.Connection object at 0x7f30d8577e50>
  File "/home/chase/.local/lib/python3.8/site-packages/pymysql/connections.py", line 775, in _read_query_result
    result.read()
    │      └ <function MySQLResult.read at 0x7f31f34e64c0>
    └ <pymysql.connections.MySQLResult object at 0x7f30783a3100>
  File "/home/chase/.local/lib/python3.8/site-packages/pymysql/connections.py", line 1156, in read
    first_packet = self.connection._read_packet()
                   │    └ None
                   └ <pymysql.connections.MySQLResult object at 0x7f30783a3100>
  File "/home/chase/.local/lib/python3.8/site-packages/pymysql/connections.py", line 725, in _read_packet
    packet.raise_for_error()
    │      └ <function MysqlPacket.raise_for_error at 0x7f31f34ddee0>
    └ <pymysql.protocol.MysqlPacket object at 0x7f305861eca0>
  File "/home/chase/.local/lib/python3.8/site-packages/pymysql/protocol.py", line 221, in raise_for_error
    err.raise_mysql_exception(self._data)
    │   │                     │    └ <member '_data' of 'MysqlPacket' objects>
    │   │                     └ <pymysql.protocol.MysqlPacket object at 0x7f305861eca0>
    │   └ <function raise_mysql_exception at 0x7f31f358c670>
    └ <module 'pymysql.err' from '/home/chase/.local/lib/python3.8/site-packages/pymysql/err.py'>
  File "/home/chase/.local/lib/python3.8/site-packages/pymysql/err.py", line 143, in raise_mysql_exception
    raise errorclass(errno, errval)
          │          │      └ "Duplicate entry '180.201.163.246:6800' for key 'device.PRIMARY'"
          │          └ 1062
          └ <class 'pymysql.err.IntegrityError'>

pymysql.err.IntegrityError: (1062, "Duplicate entry '180.201.163.246:6800' for key 'device.PRIMARY'")


The above exception was the direct cause of the following exception:


Traceback (most recent call last):

  File "/usr/lib/python3.8/threading.py", line 890, in _bootstrap
    self._bootstrap_inner()
    │    └ <function Thread._bootstrap_inner at 0x7f321bf29a60>
    └ <Thread(Thread-7608, started daemon 139837741258496)>
  File "/usr/lib/python3.8/threading.py", line 932, in _bootstrap_inner
    self.run()
    │    └ <function Thread.run at 0x7f321bf29790>
    └ <Thread(Thread-7608, started daemon 139837741258496)>
  File "/usr/lib/python3.8/threading.py", line 870, in run
    self._target(*self._args, **self._kwargs)
    │    │        │    │        │    └ {}
    │    │        │    │        └ <Thread(Thread-7608, started daemon 139837741258496)>
    │    │        │    └ ('ProjectManager.run_func_by_thread',)
    │    │        └ <Thread(Thread-7608, started daemon 139837741258496)>
    │    └ <bound method ProjectManager.get_request_from_keywords_hot of <monitor.projectManager.ProjectManager object at 0x7f31042e52e0>>
    └ <Thread(Thread-7608, started daemon 139837741258496)>

  File "/home/users/Scy/yuqing/spider/monitor/projectManager.py", line 799, in get_request_from_keywords_hot
    self.start_finished_spider_every_interval(project_names)
    │    │                                    └ ['default', 'test']
    │    └ <function ProjectManager.start_finished_spider_every_interval at 0x7f3104005280>
    └ <monitor.projectManager.ProjectManager object at 0x7f31042e52e0>

  File "/home/users/Scy/yuqing/spider/monitor/projectManager.py", line 784, in start_finished_spider_every_interval
    self[name].start_spider()
    │    └ 'default'
    └ <monitor.projectManager.ProjectManager object at 0x7f31042e52e0>

  File "/home/users/Scy/yuqing/spider/monitor/projectManager.py", line 366, in start_spider
    self.update_device_valid(device)
    │    │                   └ <monitor.deviceManager.DeviceC object at 0x7f3104029220>
    │    └ <function Project.update_device_valid at 0x7f3104003280>
    └ <monitor.projectManager.Project object at 0x7f3104029460>

  File "/home/users/Scy/yuqing/spider/monitor/projectManager.py", line 421, in update_device_valid
    self.database_manager.mysql.update(Device(**device.to_item()))
    │    │                │     │      │        │      └ <function DeviceC.to_item at 0x7f31f34ed310>
    │    │                │     │      │        └ <monitor.deviceManager.DeviceC object at 0x7f3104029220>
    │    │                │     │      └ <class 'base.db.mysql.Device'>
    │    │                │     └ <function Mysql.update at 0x7f31f35f4790>
    │    │                └ <base.db.mysql.Mysql object at 0x7f3103ffdfd0>
    │    └ <base.db.dbSlot.Slot object at 0x7f3103ffdf10>
    └ <monitor.projectManager.Project object at 0x7f3104029460>

> File "/home/users/Scy/yuqing/spider/base/db/mysql.py", line 375, in update
    row.update(new)
    │   │      └ {'server_id': '180.201.163.246:6800', 'ip': '180.201.163.246', 'username': 'chase', 'password': '9639645390881749582677706196...
    │   └ <function Query.update at 0x7f31f37333a0>
    └ <sqlalchemy.orm.query.Query object at 0x7f30b815e400>

  File "/home/chase/.local/lib/python3.8/site-packages/sqlalchemy/orm/query.py", line 3221, in update
    result = self.session.execute(
             │    │       └ <function Session.execute at 0x7f31f370faf0>
             │    └ <sqlalchemy.orm.session.Session object at 0x7f3078279790>
             └ <sqlalchemy.orm.query.Query object at 0x7f30b815e400>
  File "/home/chase/.local/lib/python3.8/site-packages/sqlalchemy/orm/session.py", line 1689, in execute
    result = conn._execute_20(statement, params or {}, execution_options)
             │    │           │          │             └ immutabledict({'synchronize_session': 'evaluate', '_sa_orm_update_options': default_update_options(_matched_objects=[], _reso...
             │    │           │          └ immutabledict({})
             │    │           └ <sqlalchemy.sql.annotation.AnnotatedUpdate object at 0x7f30781521c0>
             │    └ <function Connection._execute_20 at 0x7f31f39bc790>
             └ <sqlalchemy.engine.base.Connection object at 0x7f30b821da00>
  File "/home/chase/.local/lib/python3.8/site-packages/sqlalchemy/engine/base.py", line 1583, in _execute_20
    return meth(self, args_10style, kwargs_10style, execution_options)
           │    │     │             │               └ immutabledict({'synchronize_session': 'evaluate', '_sa_orm_update_options': default_update_options(_matched_objects=[], _reso...
           │    │     │             └ immutabledict({})
           │    │     └ ({},)
           │    └ <sqlalchemy.engine.base.Connection object at 0x7f30b821da00>
           └ <bound method ClauseElement._execute_on_connection of <sqlalchemy.sql.annotation.AnnotatedUpdate object at 0x7f30781521c0>>
  File "/home/chase/.local/lib/python3.8/site-packages/sqlalchemy/sql/elements.py", line 323, in _execute_on_connection
    return connection._execute_clauseelement(
           │          └ <function Connection._execute_clauseelement at 0x7f31f39bc5e0>
           └ <sqlalchemy.engine.base.Connection object at 0x7f30b821da00>
  File "/home/chase/.local/lib/python3.8/site-packages/sqlalchemy/engine/base.py", line 1452, in _execute_clauseelement
    ret = self._execute_context(
          │    └ <function Connection._execute_context at 0x7f31f39bc8b0>
          └ <sqlalchemy.engine.base.Connection object at 0x7f30b821da00>
  File "/home/chase/.local/lib/python3.8/site-packages/sqlalchemy/engine/base.py", line 1814, in _execute_context
    self._handle_dbapi_exception(
    │    └ <function Connection._handle_dbapi_exception at 0x7f31f39bca60>
    └ <sqlalchemy.engine.base.Connection object at 0x7f30b821da00>
  File "/home/chase/.local/lib/python3.8/site-packages/sqlalchemy/engine/base.py", line 1995, in _handle_dbapi_exception
    util.raise_(
    │    └ <function raise_ at 0x7f31f3d7ea60>
    └ <module 'sqlalchemy.util' from '/home/chase/.local/lib/python3.8/site-packages/sqlalchemy/util/__init__.py'>
  File "/home/chase/.local/lib/python3.8/site-packages/sqlalchemy/util/compat.py", line 207, in raise_
    raise exception
  File "/home/chase/.local/lib/python3.8/site-packages/sqlalchemy/engine/base.py", line 1771, in _execute_context
    self.dialect.do_execute(
    │    │       └ <function DefaultDialect.do_execute at 0x7f31f38f75e0>
    │    └ <sqlalchemy.dialects.mysql.pymysql.MySQLDialect_pymysql object at 0x7f3103ffde20>
    └ <sqlalchemy.engine.base.Connection object at 0x7f30b821da00>
  File "/home/chase/.local/lib/python3.8/site-packages/sqlalchemy/engine/default.py", line 717, in do_execute
    cursor.execute(statement, parameters)
    │      │       │          └ {'server_id': '180.201.163.246:6800', 'ip': '180.201.163.246', 'username': 'chase', 'password': '9639645390881749582677706196...
    │      │       └ 'UPDATE device SET server_id=%(server_id)s, ip=%(ip)s, username=%(username)s, password=%(password)s, address=%(address)s, por...
    │      └ <function Cursor.execute at 0x7f31f354cdc0>
    └ <pymysql.cursors.Cursor object at 0x7f30183a9040>
  File "/home/chase/.local/lib/python3.8/site-packages/pymysql/cursors.py", line 148, in execute
    result = self._query(query)
             │    │      └ "UPDATE device SET server_id='180.201.163.246:6800', ip='180.201.163.246', username='chase', password='9639645390881749582677...
             │    └ <function Cursor._query at 0x7f31f34d7280>
             └ <pymysql.cursors.Cursor object at 0x7f30183a9040>
  File "/home/chase/.local/lib/python3.8/site-packages/pymysql/cursors.py", line 310, in _query
    conn.query(q)
    │    │     └ "UPDATE device SET server_id='180.201.163.246:6800', ip='180.201.163.246', username='chase', password='9639645390881749582677...
    │    └ <function Connection.query at 0x7f31f34e5670>
    └ <pymysql.connections.Connection object at 0x7f30d8577e50>
  File "/home/chase/.local/lib/python3.8/site-packages/pymysql/connections.py", line 548, in query
    self._affected_rows = self._read_query_result(unbuffered=unbuffered)
    │    │                │    │                             └ False
    │    │                │    └ <function Connection._read_query_result at 0x7f31f34e5ca0>
    │    │                └ <pymysql.connections.Connection object at 0x7f30d8577e50>
    │    └ 1
    └ <pymysql.connections.Connection object at 0x7f30d8577e50>
  File "/home/chase/.local/lib/python3.8/site-packages/pymysql/connections.py", line 775, in _read_query_result
    result.read()
    │      └ <function MySQLResult.read at 0x7f31f34e64c0>
    └ <pymysql.connections.MySQLResult object at 0x7f30783a3100>
  File "/home/chase/.local/lib/python3.8/site-packages/pymysql/connections.py", line 1156, in read
    first_packet = self.connection._read_packet()
                   │    └ None
                   └ <pymysql.connections.MySQLResult object at 0x7f30783a3100>
  File "/home/chase/.local/lib/python3.8/site-packages/pymysql/connections.py", line 725, in _read_packet
    packet.raise_for_error()
    │      └ <function MysqlPacket.raise_for_error at 0x7f31f34ddee0>
    └ <pymysql.protocol.MysqlPacket object at 0x7f305861eca0>
  File "/home/chase/.local/lib/python3.8/site-packages/pymysql/protocol.py", line 221, in raise_for_error
    err.raise_mysql_exception(self._data)
    │   │                     │    └ <member '_data' of 'MysqlPacket' objects>
    │   │                     └ <pymysql.protocol.MysqlPacket object at 0x7f305861eca0>
    │   └ <function raise_mysql_exception at 0x7f31f358c670>
    └ <module 'pymysql.err' from '/home/chase/.local/lib/python3.8/site-packages/pymysql/err.py'>
  File "/home/chase/.local/lib/python3.8/site-packages/pymysql/err.py", line 143, in raise_mysql_exception
    raise errorclass(errno, errval)
          │          │      └ "Duplicate entry '180.201.163.246:6800' for key 'device.PRIMARY'"
          │          └ 1062
          └ <class 'pymysql.err.IntegrityError'>

sqlalchemy.exc.IntegrityError: (pymysql.err.IntegrityError) (1062, "Duplicate entry '180.201.163.246:6800' for key 'device.PRIMARY'")
[SQL: UPDATE device SET server_id=%(server_id)s, ip=%(ip)s, username=%(username)s, password=%(password)s, address=%(address)s, port=%(port)s, valid=%(valid)s WHERE device.ip = %(ip_1)s]
[parameters: {'server_id': '180.201.163.246:6800', 'ip': '180.201.163.246', 'username': 'chase', 'password': '96396453908817495826777061966420785559669599426876620384709613085637533093809236336369977134667263447749465980438786019165218032815687033014515859361 ... (10 characters truncated) ... 52838312292480297281737097704438248854895800661682698885536841880730931671104913169285588387295625591676383556280082214905533526130952407681325860308', 'address': '/home/users/CT/pycharmproject/spiders/', 'port': 6800, 'valid': 1, 'ip_1': '180.201.163.246'}]
(Background on this error at: https://sqlalche.me/e/14/gkpj)
2022-05-14 01:19:04.883 | ERROR    | base.db.mysql:update:390 - 【mysql更新数据出错】
Traceback (most recent call last):

  File "/home/chase/.local/lib/python3.8/site-packages/sqlalchemy/engine/base.py", line 1771, in _execute_context
    self.dialect.do_execute(
    │    │       └ <function DefaultDialect.do_execute at 0x7f31f38f75e0>
    │    └ <sqlalchemy.dialects.mysql.pymysql.MySQLDialect_pymysql object at 0x7f3103ffde20>
    └ <sqlalchemy.engine.base.Connection object at 0x7f30783237c0>
  File "/home/chase/.local/lib/python3.8/site-packages/sqlalchemy/engine/default.py", line 717, in do_execute
    cursor.execute(statement, parameters)
    │      │       │          └ {'server_id': '180.201.163.246:6800', 'ip': '180.201.163.246', 'username': 'chase', 'password': '7312841100745623483596312093...
    │      │       └ 'UPDATE device SET server_id=%(server_id)s, ip=%(ip)s, username=%(username)s, password=%(password)s, address=%(address)s, por...
    │      └ <function Cursor.execute at 0x7f31f354cdc0>
    └ <pymysql.cursors.Cursor object at 0x7f30b821d340>
  File "/home/chase/.local/lib/python3.8/site-packages/pymysql/cursors.py", line 148, in execute
    result = self._query(query)
             │    │      └ "UPDATE device SET server_id='180.201.163.246:6800', ip='180.201.163.246', username='chase', password='7312841100745623483596...
             │    └ <function Cursor._query at 0x7f31f34d7280>
             └ <pymysql.cursors.Cursor object at 0x7f30b821d340>
  File "/home/chase/.local/lib/python3.8/site-packages/pymysql/cursors.py", line 310, in _query
    conn.query(q)
    │    │     └ "UPDATE device SET server_id='180.201.163.246:6800', ip='180.201.163.246', username='chase', password='7312841100745623483596...
    │    └ <function Connection.query at 0x7f31f34e5670>
    └ <pymysql.connections.Connection object at 0x7f30986ac580>
  File "/home/chase/.local/lib/python3.8/site-packages/pymysql/connections.py", line 548, in query
    self._affected_rows = self._read_query_result(unbuffered=unbuffered)
    │    │                │    │                             └ False
    │    │                │    └ <function Connection._read_query_result at 0x7f31f34e5ca0>
    │    │                └ <pymysql.connections.Connection object at 0x7f30986ac580>
    │    └ 1
    └ <pymysql.connections.Connection object at 0x7f30986ac580>
  File "/home/chase/.local/lib/python3.8/site-packages/pymysql/connections.py", line 775, in _read_query_result
    result.read()
    │      └ <function MySQLResult.read at 0x7f31f34e64c0>
    └ <pymysql.connections.MySQLResult object at 0x7f3100324280>
  File "/home/chase/.local/lib/python3.8/site-packages/pymysql/connections.py", line 1156, in read
    first_packet = self.connection._read_packet()
                   │    └ None
                   └ <pymysql.connections.MySQLResult object at 0x7f3100324280>
  File "/home/chase/.local/lib/python3.8/site-packages/pymysql/connections.py", line 725, in _read_packet
    packet.raise_for_error()
    │      └ <function MysqlPacket.raise_for_error at 0x7f31f34ddee0>
    └ <pymysql.protocol.MysqlPacket object at 0x7f30782c9100>
  File "/home/chase/.local/lib/python3.8/site-packages/pymysql/protocol.py", line 221, in raise_for_error
    err.raise_mysql_exception(self._data)
    │   │                     │    └ <member '_data' of 'MysqlPacket' objects>
    │   │                     └ <pymysql.protocol.MysqlPacket object at 0x7f30782c9100>
    │   └ <function raise_mysql_exception at 0x7f31f358c670>
    └ <module 'pymysql.err' from '/home/chase/.local/lib/python3.8/site-packages/pymysql/err.py'>
  File "/home/chase/.local/lib/python3.8/site-packages/pymysql/err.py", line 143, in raise_mysql_exception
    raise errorclass(errno, errval)
          │          │      └ "Duplicate entry '180.201.163.246:6800' for key 'device.PRIMARY'"
          │          └ 1062
          └ <class 'pymysql.err.IntegrityError'>

pymysql.err.IntegrityError: (1062, "Duplicate entry '180.201.163.246:6800' for key 'device.PRIMARY'")


The above exception was the direct cause of the following exception:


Traceback (most recent call last):

  File "/usr/lib/python3.8/threading.py", line 890, in _bootstrap
    self._bootstrap_inner()
    │    └ <function Thread._bootstrap_inner at 0x7f321bf29a60>
    └ <Thread(Thread-7612, started daemon 139838009825024)>
  File "/usr/lib/python3.8/threading.py", line 932, in _bootstrap_inner
    self.run()
    │    └ <function Thread.run at 0x7f321bf29790>
    └ <Thread(Thread-7612, started daemon 139838009825024)>
  File "/usr/lib/python3.8/threading.py", line 870, in run
    self._target(*self._args, **self._kwargs)
    │    │        │    │        │    └ {}
    │    │        │    │        └ <Thread(Thread-7612, started daemon 139838009825024)>
    │    │        │    └ ('ProjectManager.run_func_by_thread',)
    │    │        └ <Thread(Thread-7612, started daemon 139838009825024)>
    │    └ <bound method ProjectManager.get_request_from_keywords_hot of <monitor.projectManager.ProjectManager object at 0x7f31042e52e0>>
    └ <Thread(Thread-7612, started daemon 139838009825024)>

  File "/home/users/Scy/yuqing/spider/monitor/projectManager.py", line 799, in get_request_from_keywords_hot
    self.start_finished_spider_every_interval(project_names)
    │    │                                    └ ['default', 'test']
    │    └ <function ProjectManager.start_finished_spider_every_interval at 0x7f3104005280>
    └ <monitor.projectManager.ProjectManager object at 0x7f31042e52e0>

  File "/home/users/Scy/yuqing/spider/monitor/projectManager.py", line 784, in start_finished_spider_every_interval
    self[name].start_spider()
    │    └ 'default'
    └ <monitor.projectManager.ProjectManager object at 0x7f31042e52e0>

  File "/home/users/Scy/yuqing/spider/monitor/projectManager.py", line 366, in start_spider
    self.update_device_valid(device)
    │    │                   └ <monitor.deviceManager.DeviceC object at 0x7f3104029220>
    │    └ <function Project.update_device_valid at 0x7f3104003280>
    └ <monitor.projectManager.Project object at 0x7f3104029460>

  File "/home/users/Scy/yuqing/spider/monitor/projectManager.py", line 421, in update_device_valid
    self.database_manager.mysql.update(Device(**device.to_item()))
    │    │                │     │      │        │      └ <function DeviceC.to_item at 0x7f31f34ed310>
    │    │                │     │      │        └ <monitor.deviceManager.DeviceC object at 0x7f3104029220>
    │    │                │     │      └ <class 'base.db.mysql.Device'>
    │    │                │     └ <function Mysql.update at 0x7f31f35f4790>
    │    │                └ <base.db.mysql.Mysql object at 0x7f3103ffdfd0>
    │    └ <base.db.dbSlot.Slot object at 0x7f3103ffdf10>
    └ <monitor.projectManager.Project object at 0x7f3104029460>

> File "/home/users/Scy/yuqing/spider/base/db/mysql.py", line 375, in update
    row.update(new)
    │   │      └ {'server_id': '180.201.163.246:6800', 'ip': '180.201.163.246', 'username': 'chase', 'password': '7312841100745623483596312093...
    │   └ <function Query.update at 0x7f31f37333a0>
    └ <sqlalchemy.orm.query.Query object at 0x7f30d8725820>

  File "/home/chase/.local/lib/python3.8/site-packages/sqlalchemy/orm/query.py", line 3221, in update
    result = self.session.execute(
             │    │       └ <function Session.execute at 0x7f31f370faf0>
             │    └ <sqlalchemy.orm.session.Session object at 0x7f2f9844d8b0>
             └ <sqlalchemy.orm.query.Query object at 0x7f30d8725820>
  File "/home/chase/.local/lib/python3.8/site-packages/sqlalchemy/orm/session.py", line 1689, in execute
    result = conn._execute_20(statement, params or {}, execution_options)
             │    │           │          │             └ immutabledict({'synchronize_session': 'evaluate', '_sa_orm_update_options': default_update_options(_matched_objects=[], _reso...
             │    │           │          └ immutabledict({})
             │    │           └ <sqlalchemy.sql.annotation.AnnotatedUpdate object at 0x7f30383f0df0>
             │    └ <function Connection._execute_20 at 0x7f31f39bc790>
             └ <sqlalchemy.engine.base.Connection object at 0x7f30783237c0>
  File "/home/chase/.local/lib/python3.8/site-packages/sqlalchemy/engine/base.py", line 1583, in _execute_20
    return meth(self, args_10style, kwargs_10style, execution_options)
           │    │     │             │               └ immutabledict({'synchronize_session': 'evaluate', '_sa_orm_update_options': default_update_options(_matched_objects=[], _reso...
           │    │     │             └ immutabledict({})
           │    │     └ ({},)
           │    └ <sqlalchemy.engine.base.Connection object at 0x7f30783237c0>
           └ <bound method ClauseElement._execute_on_connection of <sqlalchemy.sql.annotation.AnnotatedUpdate object at 0x7f30383f0df0>>
  File "/home/chase/.local/lib/python3.8/site-packages/sqlalchemy/sql/elements.py", line 323, in _execute_on_connection
    return connection._execute_clauseelement(
           │          └ <function Connection._execute_clauseelement at 0x7f31f39bc5e0>
           └ <sqlalchemy.engine.base.Connection object at 0x7f30783237c0>
  File "/home/chase/.local/lib/python3.8/site-packages/sqlalchemy/engine/base.py", line 1452, in _execute_clauseelement
    ret = self._execute_context(
          │    └ <function Connection._execute_context at 0x7f31f39bc8b0>
          └ <sqlalchemy.engine.base.Connection object at 0x7f30783237c0>
  File "/home/chase/.local/lib/python3.8/site-packages/sqlalchemy/engine/base.py", line 1814, in _execute_context
    self._handle_dbapi_exception(
    │    └ <function Connection._handle_dbapi_exception at 0x7f31f39bca60>
    └ <sqlalchemy.engine.base.Connection object at 0x7f30783237c0>
  File "/home/chase/.local/lib/python3.8/site-packages/sqlalchemy/engine/base.py", line 1995, in _handle_dbapi_exception
    util.raise_(
    │    └ <function raise_ at 0x7f31f3d7ea60>
    └ <module 'sqlalchemy.util' from '/home/chase/.local/lib/python3.8/site-packages/sqlalchemy/util/__init__.py'>
  File "/home/chase/.local/lib/python3.8/site-packages/sqlalchemy/util/compat.py", line 207, in raise_
    raise exception
  File "/home/chase/.local/lib/python3.8/site-packages/sqlalchemy/engine/base.py", line 1771, in _execute_context
    self.dialect.do_execute(
    │    │       └ <function DefaultDialect.do_execute at 0x7f31f38f75e0>
    │    └ <sqlalchemy.dialects.mysql.pymysql.MySQLDialect_pymysql object at 0x7f3103ffde20>
    └ <sqlalchemy.engine.base.Connection object at 0x7f30783237c0>
  File "/home/chase/.local/lib/python3.8/site-packages/sqlalchemy/engine/default.py", line 717, in do_execute
    cursor.execute(statement, parameters)
    │      │       │          └ {'server_id': '180.201.163.246:6800', 'ip': '180.201.163.246', 'username': 'chase', 'password': '7312841100745623483596312093...
    │      │       └ 'UPDATE device SET server_id=%(server_id)s, ip=%(ip)s, username=%(username)s, password=%(password)s, address=%(address)s, por...
    │      └ <function Cursor.execute at 0x7f31f354cdc0>
    └ <pymysql.cursors.Cursor object at 0x7f30b821d340>
  File "/home/chase/.local/lib/python3.8/site-packages/pymysql/cursors.py", line 148, in execute
    result = self._query(query)
             │    │      └ "UPDATE device SET server_id='180.201.163.246:6800', ip='180.201.163.246', username='chase', password='7312841100745623483596...
             │    └ <function Cursor._query at 0x7f31f34d7280>
             └ <pymysql.cursors.Cursor object at 0x7f30b821d340>
  File "/home/chase/.local/lib/python3.8/site-packages/pymysql/cursors.py", line 310, in _query
    conn.query(q)
    │    │     └ "UPDATE device SET server_id='180.201.163.246:6800', ip='180.201.163.246', username='chase', password='7312841100745623483596...
    │    └ <function Connection.query at 0x7f31f34e5670>
    └ <pymysql.connections.Connection object at 0x7f30986ac580>
  File "/home/chase/.local/lib/python3.8/site-packages/pymysql/connections.py", line 548, in query
    self._affected_rows = self._read_query_result(unbuffered=unbuffered)
    │    │                │    │                             └ False
    │    │                │    └ <function Connection._read_query_result at 0x7f31f34e5ca0>
    │    │                └ <pymysql.connections.Connection object at 0x7f30986ac580>
    │    └ 1
    └ <pymysql.connections.Connection object at 0x7f30986ac580>
  File "/home/chase/.local/lib/python3.8/site-packages/pymysql/connections.py", line 775, in _read_query_result
    result.read()
    │      └ <function MySQLResult.read at 0x7f31f34e64c0>
    └ <pymysql.connections.MySQLResult object at 0x7f3100324280>
  File "/home/chase/.local/lib/python3.8/site-packages/pymysql/connections.py", line 1156, in read
    first_packet = self.connection._read_packet()
                   │    └ None
                   └ <pymysql.connections.MySQLResult object at 0x7f3100324280>
  File "/home/chase/.local/lib/python3.8/site-packages/pymysql/connections.py", line 725, in _read_packet
    packet.raise_for_error()
    │      └ <function MysqlPacket.raise_for_error at 0x7f31f34ddee0>
    └ <pymysql.protocol.MysqlPacket object at 0x7f30782c9100>
  File "/home/chase/.local/lib/python3.8/site-packages/pymysql/protocol.py", line 221, in raise_for_error
    err.raise_mysql_exception(self._data)
    │   │                     │    └ <member '_data' of 'MysqlPacket' objects>
    │   │                     └ <pymysql.protocol.MysqlPacket object at 0x7f30782c9100>
    │   └ <function raise_mysql_exception at 0x7f31f358c670>
    └ <module 'pymysql.err' from '/home/chase/.local/lib/python3.8/site-packages/pymysql/err.py'>
  File "/home/chase/.local/lib/python3.8/site-packages/pymysql/err.py", line 143, in raise_mysql_exception
    raise errorclass(errno, errval)
          │          │      └ "Duplicate entry '180.201.163.246:6800' for key 'device.PRIMARY'"
          │          └ 1062
          └ <class 'pymysql.err.IntegrityError'>

sqlalchemy.exc.IntegrityError: (pymysql.err.IntegrityError) (1062, "Duplicate entry '180.201.163.246:6800' for key 'device.PRIMARY'")
[SQL: UPDATE device SET server_id=%(server_id)s, ip=%(ip)s, username=%(username)s, password=%(password)s, address=%(address)s, port=%(port)s, valid=%(valid)s WHERE device.ip = %(ip_1)s]
[parameters: {'server_id': '180.201.163.246:6800', 'ip': '180.201.163.246', 'username': 'chase', 'password': '73128411007456234835963120939740272240377407714202810648984788215226043604041227237486037368699201030998043238358597911380749962613510413910452701698 ... (10 characters truncated) ... 69386261780441850545345466756700118976553595783512143440412086390666452327941361803955873131350263528877897193847020725023922481333045184847004215783', 'address': '/home/users/CT/pycharmproject/spiders/', 'port': 6800, 'valid': 1, 'ip_1': '180.201.163.246'}]
(Background on this error at: https://sqlalche.me/e/14/gkpj)
2022-05-14 01:19:23.881 | ERROR    | base.db.mysql:update:390 - 【mysql更新数据出错】
Traceback (most recent call last):

  File "/home/chase/.local/lib/python3.8/site-packages/sqlalchemy/engine/base.py", line 1771, in _execute_context
    self.dialect.do_execute(
    │    │       └ <function DefaultDialect.do_execute at 0x7f31f38f75e0>
    │    └ <sqlalchemy.dialects.mysql.pymysql.MySQLDialect_pymysql object at 0x7f3103ffde20>
    └ <sqlalchemy.engine.base.Connection object at 0x7f301857a070>
  File "/home/chase/.local/lib/python3.8/site-packages/sqlalchemy/engine/default.py", line 717, in do_execute
    cursor.execute(statement, parameters)
    │      │       │          └ {'server_id': '180.201.163.246:6800', 'ip': '180.201.163.246', 'username': 'chase', 'password': '7445211004415574658491631480...
    │      │       └ 'UPDATE device SET server_id=%(server_id)s, ip=%(ip)s, username=%(username)s, password=%(password)s, address=%(address)s, por...
    │      └ <function Cursor.execute at 0x7f31f354cdc0>
    └ <pymysql.cursors.Cursor object at 0x7f2f987bb0d0>
  File "/home/chase/.local/lib/python3.8/site-packages/pymysql/cursors.py", line 148, in execute
    result = self._query(query)
             │    │      └ "UPDATE device SET server_id='180.201.163.246:6800', ip='180.201.163.246', username='chase', password='7445211004415574658491...
             │    └ <function Cursor._query at 0x7f31f34d7280>
             └ <pymysql.cursors.Cursor object at 0x7f2f987bb0d0>
  File "/home/chase/.local/lib/python3.8/site-packages/pymysql/cursors.py", line 310, in _query
    conn.query(q)
    │    │     └ "UPDATE device SET server_id='180.201.163.246:6800', ip='180.201.163.246', username='chase', password='7445211004415574658491...
    │    └ <function Connection.query at 0x7f31f34e5670>
    └ <pymysql.connections.Connection object at 0x7f3100190700>
  File "/home/chase/.local/lib/python3.8/site-packages/pymysql/connections.py", line 548, in query
    self._affected_rows = self._read_query_result(unbuffered=unbuffered)
    │    │                │    │                             └ False
    │    │                │    └ <function Connection._read_query_result at 0x7f31f34e5ca0>
    │    │                └ <pymysql.connections.Connection object at 0x7f3100190700>
    │    └ 1
    └ <pymysql.connections.Connection object at 0x7f3100190700>
  File "/home/chase/.local/lib/python3.8/site-packages/pymysql/connections.py", line 775, in _read_query_result
    result.read()
    │      └ <function MySQLResult.read at 0x7f31f34e64c0>
    └ <pymysql.connections.MySQLResult object at 0x7f3078530e80>
  File "/home/chase/.local/lib/python3.8/site-packages/pymysql/connections.py", line 1156, in read
    first_packet = self.connection._read_packet()
                   │    └ None
                   └ <pymysql.connections.MySQLResult object at 0x7f3078530e80>
  File "/home/chase/.local/lib/python3.8/site-packages/pymysql/connections.py", line 725, in _read_packet
    packet.raise_for_error()
    │      └ <function MysqlPacket.raise_for_error at 0x7f31f34ddee0>
    └ <pymysql.protocol.MysqlPacket object at 0x7f2f983ba760>
  File "/home/chase/.local/lib/python3.8/site-packages/pymysql/protocol.py", line 221, in raise_for_error
    err.raise_mysql_exception(self._data)
    │   │                     │    └ <member '_data' of 'MysqlPacket' objects>
    │   │                     └ <pymysql.protocol.MysqlPacket object at 0x7f2f983ba760>
    │   └ <function raise_mysql_exception at 0x7f31f358c670>
    └ <module 'pymysql.err' from '/home/chase/.local/lib/python3.8/site-packages/pymysql/err.py'>
  File "/home/chase/.local/lib/python3.8/site-packages/pymysql/err.py", line 143, in raise_mysql_exception
    raise errorclass(errno, errval)
          │          │      └ "Duplicate entry '180.201.163.246:6800' for key 'device.PRIMARY'"
          │          └ 1062
          └ <class 'pymysql.err.IntegrityError'>

pymysql.err.IntegrityError: (1062, "Duplicate entry '180.201.163.246:6800' for key 'device.PRIMARY'")


The above exception was the direct cause of the following exception:


Traceback (most recent call last):

  File "/usr/lib/python3.8/threading.py", line 890, in _bootstrap
    self._bootstrap_inner()
    │    └ <function Thread._bootstrap_inner at 0x7f321bf29a60>
    └ <Thread(Thread-7616, started daemon 139839596046080)>
  File "/usr/lib/python3.8/threading.py", line 932, in _bootstrap_inner
    self.run()
    │    └ <function Thread.run at 0x7f321bf29790>
    └ <Thread(Thread-7616, started daemon 139839596046080)>
  File "/usr/lib/python3.8/threading.py", line 870, in run
    self._target(*self._args, **self._kwargs)
    │    │        │    │        │    └ {}
    │    │        │    │        └ <Thread(Thread-7616, started daemon 139839596046080)>
    │    │        │    └ ('ProjectManager.run_func_by_thread',)
    │    │        └ <Thread(Thread-7616, started daemon 139839596046080)>
    │    └ <bound method ProjectManager.get_request_from_keywords_hot of <monitor.projectManager.ProjectManager object at 0x7f31042e52e0>>
    └ <Thread(Thread-7616, started daemon 139839596046080)>

  File "/home/users/Scy/yuqing/spider/monitor/projectManager.py", line 799, in get_request_from_keywords_hot
    self.start_finished_spider_every_interval(project_names)
    │    │                                    └ ['default', 'test']
    │    └ <function ProjectManager.start_finished_spider_every_interval at 0x7f3104005280>
    └ <monitor.projectManager.ProjectManager object at 0x7f31042e52e0>

  File "/home/users/Scy/yuqing/spider/monitor/projectManager.py", line 784, in start_finished_spider_every_interval
    self[name].start_spider()
    │    └ 'default'
    └ <monitor.projectManager.ProjectManager object at 0x7f31042e52e0>

  File "/home/users/Scy/yuqing/spider/monitor/projectManager.py", line 366, in start_spider
    self.update_device_valid(device)
    │    │                   └ <monitor.deviceManager.DeviceC object at 0x7f3104029220>
    │    └ <function Project.update_device_valid at 0x7f3104003280>
    └ <monitor.projectManager.Project object at 0x7f3104029460>

  File "/home/users/Scy/yuqing/spider/monitor/projectManager.py", line 421, in update_device_valid
    self.database_manager.mysql.update(Device(**device.to_item()))
    │    │                │     │      │        │      └ <function DeviceC.to_item at 0x7f31f34ed310>
    │    │                │     │      │        └ <monitor.deviceManager.DeviceC object at 0x7f3104029220>
    │    │                │     │      └ <class 'base.db.mysql.Device'>
    │    │                │     └ <function Mysql.update at 0x7f31f35f4790>
    │    │                └ <base.db.mysql.Mysql object at 0x7f3103ffdfd0>
    │    └ <base.db.dbSlot.Slot object at 0x7f3103ffdf10>
    └ <monitor.projectManager.Project object at 0x7f3104029460>

> File "/home/users/Scy/yuqing/spider/base/db/mysql.py", line 375, in update
    row.update(new)
    │   │      └ {'server_id': '180.201.163.246:6800', 'ip': '180.201.163.246', 'username': 'chase', 'password': '7445211004415574658491631480...
    │   └ <function Query.update at 0x7f31f37333a0>
    └ <sqlalchemy.orm.query.Query object at 0x7f2ff8617b80>

  File "/home/chase/.local/lib/python3.8/site-packages/sqlalchemy/orm/query.py", line 3221, in update
    result = self.session.execute(
             │    │       └ <function Session.execute at 0x7f31f370faf0>
             │    └ <sqlalchemy.orm.session.Session object at 0x7f305852ceb0>
             └ <sqlalchemy.orm.query.Query object at 0x7f2ff8617b80>
  File "/home/chase/.local/lib/python3.8/site-packages/sqlalchemy/orm/session.py", line 1689, in execute
    result = conn._execute_20(statement, params or {}, execution_options)
             │    │           │          │             └ immutabledict({'synchronize_session': 'evaluate', '_sa_orm_update_options': default_update_options(_matched_objects=[], _reso...
             │    │           │          └ immutabledict({})
             │    │           └ <sqlalchemy.sql.annotation.AnnotatedUpdate object at 0x7f2f987bb880>
             │    └ <function Connection._execute_20 at 0x7f31f39bc790>
             └ <sqlalchemy.engine.base.Connection object at 0x7f301857a070>
  File "/home/chase/.local/lib/python3.8/site-packages/sqlalchemy/engine/base.py", line 1583, in _execute_20
    return meth(self, args_10style, kwargs_10style, execution_options)
           │    │     │             │               └ immutabledict({'synchronize_session': 'evaluate', '_sa_orm_update_options': default_update_options(_matched_objects=[], _reso...
           │    │     │             └ immutabledict({})
           │    │     └ ({},)
           │    └ <sqlalchemy.engine.base.Connection object at 0x7f301857a070>
           └ <bound method ClauseElement._execute_on_connection of <sqlalchemy.sql.annotation.AnnotatedUpdate object at 0x7f2f987bb880>>
  File "/home/chase/.local/lib/python3.8/site-packages/sqlalchemy/sql/elements.py", line 323, in _execute_on_connection
    return connection._execute_clauseelement(
           │          └ <function Connection._execute_clauseelement at 0x7f31f39bc5e0>
           └ <sqlalchemy.engine.base.Connection object at 0x7f301857a070>
  File "/home/chase/.local/lib/python3.8/site-packages/sqlalchemy/engine/base.py", line 1452, in _execute_clauseelement
    ret = self._execute_context(
          │    └ <function Connection._execute_context at 0x7f31f39bc8b0>
          └ <sqlalchemy.engine.base.Connection object at 0x7f301857a070>
  File "/home/chase/.local/lib/python3.8/site-packages/sqlalchemy/engine/base.py", line 1814, in _execute_context
    self._handle_dbapi_exception(
    │    └ <function Connection._handle_dbapi_exception at 0x7f31f39bca60>
    └ <sqlalchemy.engine.base.Connection object at 0x7f301857a070>
  File "/home/chase/.local/lib/python3.8/site-packages/sqlalchemy/engine/base.py", line 1995, in _handle_dbapi_exception
    util.raise_(
    │    └ <function raise_ at 0x7f31f3d7ea60>
    └ <module 'sqlalchemy.util' from '/home/chase/.local/lib/python3.8/site-packages/sqlalchemy/util/__init__.py'>
  File "/home/chase/.local/lib/python3.8/site-packages/sqlalchemy/util/compat.py", line 207, in raise_
    raise exception
  File "/home/chase/.local/lib/python3.8/site-packages/sqlalchemy/engine/base.py", line 1771, in _execute_context
    self.dialect.do_execute(
    │    │       └ <function DefaultDialect.do_execute at 0x7f31f38f75e0>
    │    └ <sqlalchemy.dialects.mysql.pymysql.MySQLDialect_pymysql object at 0x7f3103ffde20>
    └ <sqlalchemy.engine.base.Connection object at 0x7f301857a070>
  File "/home/chase/.local/lib/python3.8/site-packages/sqlalchemy/engine/default.py", line 717, in do_execute
    cursor.execute(statement, parameters)
    │      │       │          └ {'server_id': '180.201.163.246:6800', 'ip': '180.201.163.246', 'username': 'chase', 'password': '7445211004415574658491631480...
    │      │       └ 'UPDATE device SET server_id=%(server_id)s, ip=%(ip)s, username=%(username)s, password=%(password)s, address=%(address)s, por...
    │      └ <function Cursor.execute at 0x7f31f354cdc0>
    └ <pymysql.cursors.Cursor object at 0x7f2f987bb0d0>
  File "/home/chase/.local/lib/python3.8/site-packages/pymysql/cursors.py", line 148, in execute
    result = self._query(query)
             │    │      └ "UPDATE device SET server_id='180.201.163.246:6800', ip='180.201.163.246', username='chase', password='7445211004415574658491...
             │    └ <function Cursor._query at 0x7f31f34d7280>
             └ <pymysql.cursors.Cursor object at 0x7f2f987bb0d0>
  File "/home/chase/.local/lib/python3.8/site-packages/pymysql/cursors.py", line 310, in _query
    conn.query(q)
    │    │     └ "UPDATE device SET server_id='180.201.163.246:6800', ip='180.201.163.246', username='chase', password='7445211004415574658491...
    │    └ <function Connection.query at 0x7f31f34e5670>
    └ <pymysql.connections.Connection object at 0x7f3100190700>
  File "/home/chase/.local/lib/python3.8/site-packages/pymysql/connections.py", line 548, in query
    self._affected_rows = self._read_query_result(unbuffered=unbuffered)
    │    │                │    │                             └ False
    │    │                │    └ <function Connection._read_query_result at 0x7f31f34e5ca0>
    │    │                └ <pymysql.connections.Connection object at 0x7f3100190700>
    │    └ 1
    └ <pymysql.connections.Connection object at 0x7f3100190700>
  File "/home/chase/.local/lib/python3.8/site-packages/pymysql/connections.py", line 775, in _read_query_result
    result.read()
    │      └ <function MySQLResult.read at 0x7f31f34e64c0>
    └ <pymysql.connections.MySQLResult object at 0x7f3078530e80>
  File "/home/chase/.local/lib/python3.8/site-packages/pymysql/connections.py", line 1156, in read
    first_packet = self.connection._read_packet()
                   │    └ None
                   └ <pymysql.connections.MySQLResult object at 0x7f3078530e80>
  File "/home/chase/.local/lib/python3.8/site-packages/pymysql/connections.py", line 725, in _read_packet
    packet.raise_for_error()
    │      └ <function MysqlPacket.raise_for_error at 0x7f31f34ddee0>
    └ <pymysql.protocol.MysqlPacket object at 0x7f2f983ba760>
  File "/home/chase/.local/lib/python3.8/site-packages/pymysql/protocol.py", line 221, in raise_for_error
    err.raise_mysql_exception(self._data)
    │   │                     │    └ <member '_data' of 'MysqlPacket' objects>
    │   │                     └ <pymysql.protocol.MysqlPacket object at 0x7f2f983ba760>
    │   └ <function raise_mysql_exception at 0x7f31f358c670>
    └ <module 'pymysql.err' from '/home/chase/.local/lib/python3.8/site-packages/pymysql/err.py'>
  File "/home/chase/.local/lib/python3.8/site-packages/pymysql/err.py", line 143, in raise_mysql_exception
    raise errorclass(errno, errval)
          │          │      └ "Duplicate entry '180.201.163.246:6800' for key 'device.PRIMARY'"
          │          └ 1062
          └ <class 'pymysql.err.IntegrityError'>

sqlalchemy.exc.IntegrityError: (pymysql.err.IntegrityError) (1062, "Duplicate entry '180.201.163.246:6800' for key 'device.PRIMARY'")
[SQL: UPDATE device SET server_id=%(server_id)s, ip=%(ip)s, username=%(username)s, password=%(password)s, address=%(address)s, port=%(port)s, valid=%(valid)s WHERE device.ip = %(ip_1)s]
[parameters: {'server_id': '180.201.163.246:6800', 'ip': '180.201.163.246', 'username': 'chase', 'password': '74452110044155746584916314804324055537255571548166974497627433618213551690552128500896890976312427905865588838808645676346025614746781228725324582862 ... (10 characters truncated) ... 47005911462952609079606342250396467210707467666788029501054341922226933318466103266598558279495506372885039016713953072571669132397914062344067739582', 'address': '/home/users/CT/pycharmproject/spiders/', 'port': 6800, 'valid': 1, 'ip_1': '180.201.163.246'}]
(Background on this error at: https://sqlalche.me/e/14/gkpj)
2022-05-14 01:19:41.221 | ERROR    | base.db.mysql:update:390 - 【mysql更新数据出错】
Traceback (most recent call last):

  File "/home/chase/.local/lib/python3.8/site-packages/sqlalchemy/engine/base.py", line 1771, in _execute_context
    self.dialect.do_execute(
    │    │       └ <function DefaultDialect.do_execute at 0x7f31f38f75e0>
    │    └ <sqlalchemy.dialects.mysql.pymysql.MySQLDialect_pymysql object at 0x7f3103ffde20>
    └ <sqlalchemy.engine.base.Connection object at 0x7f30783232b0>
  File "/home/chase/.local/lib/python3.8/site-packages/sqlalchemy/engine/default.py", line 717, in do_execute
    cursor.execute(statement, parameters)
    │      │       │          └ {'server_id': '180.201.163.246:6800', 'ip': '180.201.163.246', 'username': 'chase', 'password': '6167157415807122159058328263...
    │      │       └ 'UPDATE device SET server_id=%(server_id)s, ip=%(ip)s, username=%(username)s, password=%(password)s, address=%(address)s, por...
    │      └ <function Cursor.execute at 0x7f31f354cdc0>
    └ <pymysql.cursors.Cursor object at 0x7f30d8089550>
  File "/home/chase/.local/lib/python3.8/site-packages/pymysql/cursors.py", line 148, in execute
    result = self._query(query)
             │    │      └ "UPDATE device SET server_id='180.201.163.246:6800', ip='180.201.163.246', username='chase', password='6167157415807122159058...
             │    └ <function Cursor._query at 0x7f31f34d7280>
             └ <pymysql.cursors.Cursor object at 0x7f30d8089550>
  File "/home/chase/.local/lib/python3.8/site-packages/pymysql/cursors.py", line 310, in _query
    conn.query(q)
    │    │     └ "UPDATE device SET server_id='180.201.163.246:6800', ip='180.201.163.246', username='chase', password='6167157415807122159058...
    │    └ <function Connection.query at 0x7f31f34e5670>
    └ <pymysql.connections.Connection object at 0x7f301821ae50>
  File "/home/chase/.local/lib/python3.8/site-packages/pymysql/connections.py", line 548, in query
    self._affected_rows = self._read_query_result(unbuffered=unbuffered)
    │    │                │    │                             └ False
    │    │                │    └ <function Connection._read_query_result at 0x7f31f34e5ca0>
    │    │                └ <pymysql.connections.Connection object at 0x7f301821ae50>
    │    └ 1
    └ <pymysql.connections.Connection object at 0x7f301821ae50>
  File "/home/chase/.local/lib/python3.8/site-packages/pymysql/connections.py", line 775, in _read_query_result
    result.read()
    │      └ <function MySQLResult.read at 0x7f31f34e64c0>
    └ <pymysql.connections.MySQLResult object at 0x7f30783230d0>
  File "/home/chase/.local/lib/python3.8/site-packages/pymysql/connections.py", line 1156, in read
    first_packet = self.connection._read_packet()
                   │    └ None
                   └ <pymysql.connections.MySQLResult object at 0x7f30783230d0>
  File "/home/chase/.local/lib/python3.8/site-packages/pymysql/connections.py", line 725, in _read_packet
    packet.raise_for_error()
    │      └ <function MysqlPacket.raise_for_error at 0x7f31f34ddee0>
    └ <pymysql.protocol.MysqlPacket object at 0x7f2ff87a4d60>
  File "/home/chase/.local/lib/python3.8/site-packages/pymysql/protocol.py", line 221, in raise_for_error
    err.raise_mysql_exception(self._data)
    │   │                     │    └ <member '_data' of 'MysqlPacket' objects>
    │   │                     └ <pymysql.protocol.MysqlPacket object at 0x7f2ff87a4d60>
    │   └ <function raise_mysql_exception at 0x7f31f358c670>
    └ <module 'pymysql.err' from '/home/chase/.local/lib/python3.8/site-packages/pymysql/err.py'>
  File "/home/chase/.local/lib/python3.8/site-packages/pymysql/err.py", line 143, in raise_mysql_exception
    raise errorclass(errno, errval)
          │          │      └ "Duplicate entry '180.201.163.246:6800' for key 'device.PRIMARY'"
          │          └ 1062
          └ <class 'pymysql.err.IntegrityError'>

pymysql.err.IntegrityError: (1062, "Duplicate entry '180.201.163.246:6800' for key 'device.PRIMARY'")


The above exception was the direct cause of the following exception:


Traceback (most recent call last):

  File "/usr/lib/python3.8/threading.py", line 890, in _bootstrap
    self._bootstrap_inner()
    │    └ <function Thread._bootstrap_inner at 0x7f321bf29a60>
    └ <Thread(Thread-7621, started daemon 139840502458112)>
  File "/usr/lib/python3.8/threading.py", line 932, in _bootstrap_inner
    self.run()
    │    └ <function Thread.run at 0x7f321bf29790>
    └ <Thread(Thread-7621, started daemon 139840502458112)>
  File "/usr/lib/python3.8/threading.py", line 870, in run
    self._target(*self._args, **self._kwargs)
    │    │        │    │        │    └ {}
    │    │        │    │        └ <Thread(Thread-7621, started daemon 139840502458112)>
    │    │        │    └ ('ProjectManager.run_func_by_thread',)
    │    │        └ <Thread(Thread-7621, started daemon 139840502458112)>
    │    └ <bound method ProjectManager.get_request_from_keywords_hot of <monitor.projectManager.ProjectManager object at 0x7f31042e52e0>>
    └ <Thread(Thread-7621, started daemon 139840502458112)>

  File "/home/users/Scy/yuqing/spider/monitor/projectManager.py", line 799, in get_request_from_keywords_hot
    self.start_finished_spider_every_interval(project_names)
    │    │                                    └ ['default', 'test']
    │    └ <function ProjectManager.start_finished_spider_every_interval at 0x7f3104005280>
    └ <monitor.projectManager.ProjectManager object at 0x7f31042e52e0>

  File "/home/users/Scy/yuqing/spider/monitor/projectManager.py", line 784, in start_finished_spider_every_interval
    self[name].start_spider()
    │    └ 'default'
    └ <monitor.projectManager.ProjectManager object at 0x7f31042e52e0>

  File "/home/users/Scy/yuqing/spider/monitor/projectManager.py", line 366, in start_spider
    self.update_device_valid(device)
    │    │                   └ <monitor.deviceManager.DeviceC object at 0x7f3104029220>
    │    └ <function Project.update_device_valid at 0x7f3104003280>
    └ <monitor.projectManager.Project object at 0x7f3104029460>

  File "/home/users/Scy/yuqing/spider/monitor/projectManager.py", line 421, in update_device_valid
    self.database_manager.mysql.update(Device(**device.to_item()))
    │    │                │     │      │        │      └ <function DeviceC.to_item at 0x7f31f34ed310>
    │    │                │     │      │        └ <monitor.deviceManager.DeviceC object at 0x7f3104029220>
    │    │                │     │      └ <class 'base.db.mysql.Device'>
    │    │                │     └ <function Mysql.update at 0x7f31f35f4790>
    │    │                └ <base.db.mysql.Mysql object at 0x7f3103ffdfd0>
    │    └ <base.db.dbSlot.Slot object at 0x7f3103ffdf10>
    └ <monitor.projectManager.Project object at 0x7f3104029460>

> File "/home/users/Scy/yuqing/spider/base/db/mysql.py", line 375, in update
    row.update(new)
    │   │      └ {'server_id': '180.201.163.246:6800', 'ip': '180.201.163.246', 'username': 'chase', 'password': '6167157415807122159058328263...
    │   └ <function Query.update at 0x7f31f37333a0>
    └ <sqlalchemy.orm.query.Query object at 0x7f31f9243160>

  File "/home/chase/.local/lib/python3.8/site-packages/sqlalchemy/orm/query.py", line 3221, in update
    result = self.session.execute(
             │    │       └ <function Session.execute at 0x7f31f370faf0>
             │    └ <sqlalchemy.orm.session.Session object at 0x7f31f92438b0>
             └ <sqlalchemy.orm.query.Query object at 0x7f31f9243160>
  File "/home/chase/.local/lib/python3.8/site-packages/sqlalchemy/orm/session.py", line 1689, in execute
    result = conn._execute_20(statement, params or {}, execution_options)
             │    │           │          │             └ immutabledict({'synchronize_session': 'evaluate', '_sa_orm_update_options': default_update_options(_matched_objects=[], _reso...
             │    │           │          └ immutabledict({})
             │    │           └ <sqlalchemy.sql.annotation.AnnotatedUpdate object at 0x7f30d8089b80>
             │    └ <function Connection._execute_20 at 0x7f31f39bc790>
             └ <sqlalchemy.engine.base.Connection object at 0x7f30783232b0>
  File "/home/chase/.local/lib/python3.8/site-packages/sqlalchemy/engine/base.py", line 1583, in _execute_20
    return meth(self, args_10style, kwargs_10style, execution_options)
           │    │     │             │               └ immutabledict({'synchronize_session': 'evaluate', '_sa_orm_update_options': default_update_options(_matched_objects=[], _reso...
           │    │     │             └ immutabledict({})
           │    │     └ ({},)
           │    └ <sqlalchemy.engine.base.Connection object at 0x7f30783232b0>
           └ <bound method ClauseElement._execute_on_connection of <sqlalchemy.sql.annotation.AnnotatedUpdate object at 0x7f30d8089b80>>
  File "/home/chase/.local/lib/python3.8/site-packages/sqlalchemy/sql/elements.py", line 323, in _execute_on_connection
    return connection._execute_clauseelement(
           │          └ <function Connection._execute_clauseelement at 0x7f31f39bc5e0>
           └ <sqlalchemy.engine.base.Connection object at 0x7f30783232b0>
  File "/home/chase/.local/lib/python3.8/site-packages/sqlalchemy/engine/base.py", line 1452, in _execute_clauseelement
    ret = self._execute_context(
          │    └ <function Connection._execute_context at 0x7f31f39bc8b0>
          └ <sqlalchemy.engine.base.Connection object at 0x7f30783232b0>
  File "/home/chase/.local/lib/python3.8/site-packages/sqlalchemy/engine/base.py", line 1814, in _execute_context
    self._handle_dbapi_exception(
    │    └ <function Connection._handle_dbapi_exception at 0x7f31f39bca60>
    └ <sqlalchemy.engine.base.Connection object at 0x7f30783232b0>
  File "/home/chase/.local/lib/python3.8/site-packages/sqlalchemy/engine/base.py", line 1995, in _handle_dbapi_exception
    util.raise_(
    │    └ <function raise_ at 0x7f31f3d7ea60>
    └ <module 'sqlalchemy.util' from '/home/chase/.local/lib/python3.8/site-packages/sqlalchemy/util/__init__.py'>
  File "/home/chase/.local/lib/python3.8/site-packages/sqlalchemy/util/compat.py", line 207, in raise_
    raise exception
  File "/home/chase/.local/lib/python3.8/site-packages/sqlalchemy/engine/base.py", line 1771, in _execute_context
    self.dialect.do_execute(
    │    │       └ <function DefaultDialect.do_execute at 0x7f31f38f75e0>
    │    └ <sqlalchemy.dialects.mysql.pymysql.MySQLDialect_pymysql object at 0x7f3103ffde20>
    └ <sqlalchemy.engine.base.Connection object at 0x7f30783232b0>
  File "/home/chase/.local/lib/python3.8/site-packages/sqlalchemy/engine/default.py", line 717, in do_execute
    cursor.execute(statement, parameters)
    │      │       │          └ {'server_id': '180.201.163.246:6800', 'ip': '180.201.163.246', 'username': 'chase', 'password': '6167157415807122159058328263...
    │      │       └ 'UPDATE device SET server_id=%(server_id)s, ip=%(ip)s, username=%(username)s, password=%(password)s, address=%(address)s, por...
    │      └ <function Cursor.execute at 0x7f31f354cdc0>
    └ <pymysql.cursors.Cursor object at 0x7f30d8089550>
  File "/home/chase/.local/lib/python3.8/site-packages/pymysql/cursors.py", line 148, in execute
    result = self._query(query)
             │    │      └ "UPDATE device SET server_id='180.201.163.246:6800', ip='180.201.163.246', username='chase', password='6167157415807122159058...
             │    └ <function Cursor._query at 0x7f31f34d7280>
             └ <pymysql.cursors.Cursor object at 0x7f30d8089550>
  File "/home/chase/.local/lib/python3.8/site-packages/pymysql/cursors.py", line 310, in _query
    conn.query(q)
    │    │     └ "UPDATE device SET server_id='180.201.163.246:6800', ip='180.201.163.246', username='chase', password='6167157415807122159058...
    │    └ <function Connection.query at 0x7f31f34e5670>
    └ <pymysql.connections.Connection object at 0x7f301821ae50>
  File "/home/chase/.local/lib/python3.8/site-packages/pymysql/connections.py", line 548, in query
    self._affected_rows = self._read_query_result(unbuffered=unbuffered)
    │    │                │    │                             └ False
    │    │                │    └ <function Connection._read_query_result at 0x7f31f34e5ca0>
    │    │                └ <pymysql.connections.Connection object at 0x7f301821ae50>
    │    └ 1
    └ <pymysql.connections.Connection object at 0x7f301821ae50>
  File "/home/chase/.local/lib/python3.8/site-packages/pymysql/connections.py", line 775, in _read_query_result
    result.read()
    │      └ <function MySQLResult.read at 0x7f31f34e64c0>
    └ <pymysql.connections.MySQLResult object at 0x7f30783230d0>
  File "/home/chase/.local/lib/python3.8/site-packages/pymysql/connections.py", line 1156, in read
    first_packet = self.connection._read_packet()
                   │    └ None
                   └ <pymysql.connections.MySQLResult object at 0x7f30783230d0>
  File "/home/chase/.local/lib/python3.8/site-packages/pymysql/connections.py", line 725, in _read_packet
    packet.raise_for_error()
    │      └ <function MysqlPacket.raise_for_error at 0x7f31f34ddee0>
    └ <pymysql.protocol.MysqlPacket object at 0x7f2ff87a4d60>
  File "/home/chase/.local/lib/python3.8/site-packages/pymysql/protocol.py", line 221, in raise_for_error
    err.raise_mysql_exception(self._data)
    │   │                     │    └ <member '_data' of 'MysqlPacket' objects>
    │   │                     └ <pymysql.protocol.MysqlPacket object at 0x7f2ff87a4d60>
    │   └ <function raise_mysql_exception at 0x7f31f358c670>
    └ <module 'pymysql.err' from '/home/chase/.local/lib/python3.8/site-packages/pymysql/err.py'>
  File "/home/chase/.local/lib/python3.8/site-packages/pymysql/err.py", line 143, in raise_mysql_exception
    raise errorclass(errno, errval)
          │          │      └ "Duplicate entry '180.201.163.246:6800' for key 'device.PRIMARY'"
          │          └ 1062
          └ <class 'pymysql.err.IntegrityError'>

sqlalchemy.exc.IntegrityError: (pymysql.err.IntegrityError) (1062, "Duplicate entry '180.201.163.246:6800' for key 'device.PRIMARY'")
[SQL: UPDATE device SET server_id=%(server_id)s, ip=%(ip)s, username=%(username)s, password=%(password)s, address=%(address)s, port=%(port)s, valid=%(valid)s WHERE device.ip = %(ip_1)s]
[parameters: {'server_id': '180.201.163.246:6800', 'ip': '180.201.163.246', 'username': 'chase', 'password': '61671574158071221590583282630760934824407731869514278330461780574977534984525473099845344023425891787892146094518905878901035125876653777832591892299 ... (10 characters truncated) ... 52631679485165714083573921891377134588353829549988902604197923092806710492656645623177708293853264719170588687363237428871880242211171145876844276132', 'address': '/home/users/CT/pycharmproject/spiders/', 'port': 6800, 'valid': 1, 'ip_1': '180.201.163.246'}]
(Background on this error at: https://sqlalche.me/e/14/gkpj)
2022-05-14 01:19:59.082 | ERROR    | base.db.mysql:update:390 - 【mysql更新数据出错】
Traceback (most recent call last):

  File "/home/chase/.local/lib/python3.8/site-packages/sqlalchemy/engine/base.py", line 1771, in _execute_context
    self.dialect.do_execute(
    │    │       └ <function DefaultDialect.do_execute at 0x7f31f38f75e0>
    │    └ <sqlalchemy.dialects.mysql.pymysql.MySQLDialect_pymysql object at 0x7f3103ffde20>
    └ <sqlalchemy.engine.base.Connection object at 0x7f31f9320730>
  File "/home/chase/.local/lib/python3.8/site-packages/sqlalchemy/engine/default.py", line 717, in do_execute
    cursor.execute(statement, parameters)
    │      │       │          └ {'server_id': '180.201.163.246:6800', 'ip': '180.201.163.246', 'username': 'chase', 'password': '6993716782146261259730862438...
    │      │       └ 'UPDATE device SET server_id=%(server_id)s, ip=%(ip)s, username=%(username)s, password=%(password)s, address=%(address)s, por...
    │      └ <function Cursor.execute at 0x7f31f354cdc0>
    └ <pymysql.cursors.Cursor object at 0x7f2f9827a7c0>
  File "/home/chase/.local/lib/python3.8/site-packages/pymysql/cursors.py", line 148, in execute
    result = self._query(query)
             │    │      └ "UPDATE device SET server_id='180.201.163.246:6800', ip='180.201.163.246', username='chase', password='6993716782146261259730...
             │    └ <function Cursor._query at 0x7f31f34d7280>
             └ <pymysql.cursors.Cursor object at 0x7f2f9827a7c0>
  File "/home/chase/.local/lib/python3.8/site-packages/pymysql/cursors.py", line 310, in _query
    conn.query(q)
    │    │     └ "UPDATE device SET server_id='180.201.163.246:6800', ip='180.201.163.246', username='chase', password='6993716782146261259730...
    │    └ <function Connection.query at 0x7f31f34e5670>
    └ <pymysql.connections.Connection object at 0x7f30d856a3a0>
  File "/home/chase/.local/lib/python3.8/site-packages/pymysql/connections.py", line 548, in query
    self._affected_rows = self._read_query_result(unbuffered=unbuffered)
    │    │                │    │                             └ False
    │    │                │    └ <function Connection._read_query_result at 0x7f31f34e5ca0>
    │    │                └ <pymysql.connections.Connection object at 0x7f30d856a3a0>
    │    └ 1
    └ <pymysql.connections.Connection object at 0x7f30d856a3a0>
  File "/home/chase/.local/lib/python3.8/site-packages/pymysql/connections.py", line 775, in _read_query_result
    result.read()
    │      └ <function MySQLResult.read at 0x7f31f34e64c0>
    └ <pymysql.connections.MySQLResult object at 0x7f2ff828e5e0>
  File "/home/chase/.local/lib/python3.8/site-packages/pymysql/connections.py", line 1156, in read
    first_packet = self.connection._read_packet()
                   │    └ None
                   └ <pymysql.connections.MySQLResult object at 0x7f2ff828e5e0>
  File "/home/chase/.local/lib/python3.8/site-packages/pymysql/connections.py", line 725, in _read_packet
    packet.raise_for_error()
    │      └ <function MysqlPacket.raise_for_error at 0x7f31f34ddee0>
    └ <pymysql.protocol.MysqlPacket object at 0x7f3078152340>
  File "/home/chase/.local/lib/python3.8/site-packages/pymysql/protocol.py", line 221, in raise_for_error
    err.raise_mysql_exception(self._data)
    │   │                     │    └ <member '_data' of 'MysqlPacket' objects>
    │   │                     └ <pymysql.protocol.MysqlPacket object at 0x7f3078152340>
    │   └ <function raise_mysql_exception at 0x7f31f358c670>
    └ <module 'pymysql.err' from '/home/chase/.local/lib/python3.8/site-packages/pymysql/err.py'>
  File "/home/chase/.local/lib/python3.8/site-packages/pymysql/err.py", line 143, in raise_mysql_exception
    raise errorclass(errno, errval)
          │          │      └ "Duplicate entry '180.201.163.246:6800' for key 'device.PRIMARY'"
          │          └ 1062
          └ <class 'pymysql.err.IntegrityError'>

pymysql.err.IntegrityError: (1062, "Duplicate entry '180.201.163.246:6800' for key 'device.PRIMARY'")


The above exception was the direct cause of the following exception:


Traceback (most recent call last):

  File "/usr/lib/python3.8/threading.py", line 890, in _bootstrap
    self._bootstrap_inner()
    │    └ <function Thread._bootstrap_inner at 0x7f321bf29a60>
    └ <Thread(Thread-7626, started daemon 139848495625984)>
  File "/usr/lib/python3.8/threading.py", line 932, in _bootstrap_inner
    self.run()
    │    └ <function Thread.run at 0x7f321bf29790>
    └ <Thread(Thread-7626, started daemon 139848495625984)>
  File "/usr/lib/python3.8/threading.py", line 870, in run
    self._target(*self._args, **self._kwargs)
    │    │        │    │        │    └ {}
    │    │        │    │        └ <Thread(Thread-7626, started daemon 139848495625984)>
    │    │        │    └ ('ProjectManager.run_func_by_thread',)
    │    │        └ <Thread(Thread-7626, started daemon 139848495625984)>
    │    └ <bound method ProjectManager.get_request_from_keywords_hot of <monitor.projectManager.ProjectManager object at 0x7f31042e52e0>>
    └ <Thread(Thread-7626, started daemon 139848495625984)>

  File "/home/users/Scy/yuqing/spider/monitor/projectManager.py", line 799, in get_request_from_keywords_hot
    self.start_finished_spider_every_interval(project_names)
    │    │                                    └ ['default', 'test']
    │    └ <function ProjectManager.start_finished_spider_every_interval at 0x7f3104005280>
    └ <monitor.projectManager.ProjectManager object at 0x7f31042e52e0>

  File "/home/users/Scy/yuqing/spider/monitor/projectManager.py", line 784, in start_finished_spider_every_interval
    self[name].start_spider()
    │    └ 'default'
    └ <monitor.projectManager.ProjectManager object at 0x7f31042e52e0>

  File "/home/users/Scy/yuqing/spider/monitor/projectManager.py", line 366, in start_spider
    self.update_device_valid(device)
    │    │                   └ <monitor.deviceManager.DeviceC object at 0x7f3104029220>
    │    └ <function Project.update_device_valid at 0x7f3104003280>
    └ <monitor.projectManager.Project object at 0x7f3104029460>

  File "/home/users/Scy/yuqing/spider/monitor/projectManager.py", line 421, in update_device_valid
    self.database_manager.mysql.update(Device(**device.to_item()))
    │    │                │     │      │        │      └ <function DeviceC.to_item at 0x7f31f34ed310>
    │    │                │     │      │        └ <monitor.deviceManager.DeviceC object at 0x7f3104029220>
    │    │                │     │      └ <class 'base.db.mysql.Device'>
    │    │                │     └ <function Mysql.update at 0x7f31f35f4790>
    │    │                └ <base.db.mysql.Mysql object at 0x7f3103ffdfd0>
    │    └ <base.db.dbSlot.Slot object at 0x7f3103ffdf10>
    └ <monitor.projectManager.Project object at 0x7f3104029460>

> File "/home/users/Scy/yuqing/spider/base/db/mysql.py", line 375, in update
    row.update(new)
    │   │      └ {'server_id': '180.201.163.246:6800', 'ip': '180.201.163.246', 'username': 'chase', 'password': '6993716782146261259730862438...
    │   └ <function Query.update at 0x7f31f37333a0>
    └ <sqlalchemy.orm.query.Query object at 0x7f31f9320d60>

  File "/home/chase/.local/lib/python3.8/site-packages/sqlalchemy/orm/query.py", line 3221, in update
    result = self.session.execute(
             │    │       └ <function Session.execute at 0x7f31f370faf0>
             │    └ <sqlalchemy.orm.session.Session object at 0x7f31f9320910>
             └ <sqlalchemy.orm.query.Query object at 0x7f31f9320d60>
  File "/home/chase/.local/lib/python3.8/site-packages/sqlalchemy/orm/session.py", line 1689, in execute
    result = conn._execute_20(statement, params or {}, execution_options)
             │    │           │          │             └ immutabledict({'synchronize_session': 'evaluate', '_sa_orm_update_options': default_update_options(_matched_objects=[], _reso...
             │    │           │          └ immutabledict({})
             │    │           └ <sqlalchemy.sql.annotation.AnnotatedUpdate object at 0x7f3018654250>
             │    └ <function Connection._execute_20 at 0x7f31f39bc790>
             └ <sqlalchemy.engine.base.Connection object at 0x7f31f9320730>
  File "/home/chase/.local/lib/python3.8/site-packages/sqlalchemy/engine/base.py", line 1583, in _execute_20
    return meth(self, args_10style, kwargs_10style, execution_options)
           │    │     │             │               └ immutabledict({'synchronize_session': 'evaluate', '_sa_orm_update_options': default_update_options(_matched_objects=[], _reso...
           │    │     │             └ immutabledict({})
           │    │     └ ({},)
           │    └ <sqlalchemy.engine.base.Connection object at 0x7f31f9320730>
           └ <bound method ClauseElement._execute_on_connection of <sqlalchemy.sql.annotation.AnnotatedUpdate object at 0x7f3018654250>>
  File "/home/chase/.local/lib/python3.8/site-packages/sqlalchemy/sql/elements.py", line 323, in _execute_on_connection
    return connection._execute_clauseelement(
           │          └ <function Connection._execute_clauseelement at 0x7f31f39bc5e0>
           └ <sqlalchemy.engine.base.Connection object at 0x7f31f9320730>
  File "/home/chase/.local/lib/python3.8/site-packages/sqlalchemy/engine/base.py", line 1452, in _execute_clauseelement
    ret = self._execute_context(
          │    └ <function Connection._execute_context at 0x7f31f39bc8b0>
          └ <sqlalchemy.engine.base.Connection object at 0x7f31f9320730>
  File "/home/chase/.local/lib/python3.8/site-packages/sqlalchemy/engine/base.py", line 1814, in _execute_context
    self._handle_dbapi_exception(
    │    └ <function Connection._handle_dbapi_exception at 0x7f31f39bca60>
    └ <sqlalchemy.engine.base.Connection object at 0x7f31f9320730>
  File "/home/chase/.local/lib/python3.8/site-packages/sqlalchemy/engine/base.py", line 1995, in _handle_dbapi_exception
    util.raise_(
    │    └ <function raise_ at 0x7f31f3d7ea60>
    └ <module 'sqlalchemy.util' from '/home/chase/.local/lib/python3.8/site-packages/sqlalchemy/util/__init__.py'>
  File "/home/chase/.local/lib/python3.8/site-packages/sqlalchemy/util/compat.py", line 207, in raise_
    raise exception
  File "/home/chase/.local/lib/python3.8/site-packages/sqlalchemy/engine/base.py", line 1771, in _execute_context
    self.dialect.do_execute(
    │    │       └ <function DefaultDialect.do_execute at 0x7f31f38f75e0>
    │    └ <sqlalchemy.dialects.mysql.pymysql.MySQLDialect_pymysql object at 0x7f3103ffde20>
    └ <sqlalchemy.engine.base.Connection object at 0x7f31f9320730>
  File "/home/chase/.local/lib/python3.8/site-packages/sqlalchemy/engine/default.py", line 717, in do_execute
    cursor.execute(statement, parameters)
    │      │       │          └ {'server_id': '180.201.163.246:6800', 'ip': '180.201.163.246', 'username': 'chase', 'password': '6993716782146261259730862438...
    │      │       └ 'UPDATE device SET server_id=%(server_id)s, ip=%(ip)s, username=%(username)s, password=%(password)s, address=%(address)s, por...
    │      └ <function Cursor.execute at 0x7f31f354cdc0>
    └ <pymysql.cursors.Cursor object at 0x7f2f9827a7c0>
  File "/home/chase/.local/lib/python3.8/site-packages/pymysql/cursors.py", line 148, in execute
    result = self._query(query)
             │    │      └ "UPDATE device SET server_id='180.201.163.246:6800', ip='180.201.163.246', username='chase', password='6993716782146261259730...
             │    └ <function Cursor._query at 0x7f31f34d7280>
             └ <pymysql.cursors.Cursor object at 0x7f2f9827a7c0>
  File "/home/chase/.local/lib/python3.8/site-packages/pymysql/cursors.py", line 310, in _query
    conn.query(q)
    │    │     └ "UPDATE device SET server_id='180.201.163.246:6800', ip='180.201.163.246', username='chase', password='6993716782146261259730...
    │    └ <function Connection.query at 0x7f31f34e5670>
    └ <pymysql.connections.Connection object at 0x7f30d856a3a0>
  File "/home/chase/.local/lib/python3.8/site-packages/pymysql/connections.py", line 548, in query
    self._affected_rows = self._read_query_result(unbuffered=unbuffered)
    │    │                │    │                             └ False
    │    │                │    └ <function Connection._read_query_result at 0x7f31f34e5ca0>
    │    │                └ <pymysql.connections.Connection object at 0x7f30d856a3a0>
    │    └ 1
    └ <pymysql.connections.Connection object at 0x7f30d856a3a0>
  File "/home/chase/.local/lib/python3.8/site-packages/pymysql/connections.py", line 775, in _read_query_result
    result.read()
    │      └ <function MySQLResult.read at 0x7f31f34e64c0>
    └ <pymysql.connections.MySQLResult object at 0x7f2ff828e5e0>
  File "/home/chase/.local/lib/python3.8/site-packages/pymysql/connections.py", line 1156, in read
    first_packet = self.connection._read_packet()
                   │    └ None
                   └ <pymysql.connections.MySQLResult object at 0x7f2ff828e5e0>
  File "/home/chase/.local/lib/python3.8/site-packages/pymysql/connections.py", line 725, in _read_packet
    packet.raise_for_error()
    │      └ <function MysqlPacket.raise_for_error at 0x7f31f34ddee0>
    └ <pymysql.protocol.MysqlPacket object at 0x7f3078152340>
  File "/home/chase/.local/lib/python3.8/site-packages/pymysql/protocol.py", line 221, in raise_for_error
    err.raise_mysql_exception(self._data)
    │   │                     │    └ <member '_data' of 'MysqlPacket' objects>
    │   │                     └ <pymysql.protocol.MysqlPacket object at 0x7f3078152340>
    │   └ <function raise_mysql_exception at 0x7f31f358c670>
    └ <module 'pymysql.err' from '/home/chase/.local/lib/python3.8/site-packages/pymysql/err.py'>
  File "/home/chase/.local/lib/python3.8/site-packages/pymysql/err.py", line 143, in raise_mysql_exception
    raise errorclass(errno, errval)
          │          │      └ "Duplicate entry '180.201.163.246:6800' for key 'device.PRIMARY'"
          │          └ 1062
          └ <class 'pymysql.err.IntegrityError'>

sqlalchemy.exc.IntegrityError: (pymysql.err.IntegrityError) (1062, "Duplicate entry '180.201.163.246:6800' for key 'device.PRIMARY'")
[SQL: UPDATE device SET server_id=%(server_id)s, ip=%(ip)s, username=%(username)s, password=%(password)s, address=%(address)s, port=%(port)s, valid=%(valid)s WHERE device.ip = %(ip_1)s]
[parameters: {'server_id': '180.201.163.246:6800', 'ip': '180.201.163.246', 'username': 'chase', 'password': '69937167821462612597308624386834634313495918062126882091740035792691626982822721154390237076095690086021548282227950104689342920035577136419367905193 ... (10 characters truncated) ... 34467075560080358893155952166684695753179051786363037344369335663788262771008985062391937416961177759544407034656497314055097760196025779101593757119', 'address': '/home/users/CT/pycharmproject/spiders/', 'port': 6800, 'valid': 1, 'ip_1': '180.201.163.246'}]
(Background on this error at: https://sqlalche.me/e/14/gkpj)
2022-05-14 01:20:17.284 | ERROR    | base.db.mysql:update:390 - 【mysql更新数据出错】
Traceback (most recent call last):

  File "/home/chase/.local/lib/python3.8/site-packages/sqlalchemy/engine/base.py", line 1771, in _execute_context
    self.dialect.do_execute(
    │    │       └ <function DefaultDialect.do_execute at 0x7f31f38f75e0>
    │    └ <sqlalchemy.dialects.mysql.pymysql.MySQLDialect_pymysql object at 0x7f3103ffde20>
    └ <sqlalchemy.engine.base.Connection object at 0x7f30584ccd00>
  File "/home/chase/.local/lib/python3.8/site-packages/sqlalchemy/engine/default.py", line 717, in do_execute
    cursor.execute(statement, parameters)
    │      │       │          └ {'server_id': '180.201.163.246:6800', 'ip': '180.201.163.246', 'username': 'chase', 'password': '8107046204334271188664597070...
    │      │       └ 'UPDATE device SET server_id=%(server_id)s, ip=%(ip)s, username=%(username)s, password=%(password)s, address=%(address)s, por...
    │      └ <function Cursor.execute at 0x7f31f354cdc0>
    └ <pymysql.cursors.Cursor object at 0x7f2fb86a25e0>
  File "/home/chase/.local/lib/python3.8/site-packages/pymysql/cursors.py", line 148, in execute
    result = self._query(query)
             │    │      └ "UPDATE device SET server_id='180.201.163.246:6800', ip='180.201.163.246', username='chase', password='8107046204334271188664...
             │    └ <function Cursor._query at 0x7f31f34d7280>
             └ <pymysql.cursors.Cursor object at 0x7f2fb86a25e0>
  File "/home/chase/.local/lib/python3.8/site-packages/pymysql/cursors.py", line 310, in _query
    conn.query(q)
    │    │     └ "UPDATE device SET server_id='180.201.163.246:6800', ip='180.201.163.246', username='chase', password='8107046204334271188664...
    │    └ <function Connection.query at 0x7f31f34e5670>
    └ <pymysql.connections.Connection object at 0x7f30985a5070>
  File "/home/chase/.local/lib/python3.8/site-packages/pymysql/connections.py", line 548, in query
    self._affected_rows = self._read_query_result(unbuffered=unbuffered)
    │    │                │    │                             └ False
    │    │                │    └ <function Connection._read_query_result at 0x7f31f34e5ca0>
    │    │                └ <pymysql.connections.Connection object at 0x7f30985a5070>
    │    └ 1
    └ <pymysql.connections.Connection object at 0x7f30985a5070>
  File "/home/chase/.local/lib/python3.8/site-packages/pymysql/connections.py", line 775, in _read_query_result
    result.read()
    │      └ <function MySQLResult.read at 0x7f31f34e64c0>
    └ <pymysql.connections.MySQLResult object at 0x7f30b854afd0>
  File "/home/chase/.local/lib/python3.8/site-packages/pymysql/connections.py", line 1156, in read
    first_packet = self.connection._read_packet()
                   │    └ None
                   └ <pymysql.connections.MySQLResult object at 0x7f30b854afd0>
  File "/home/chase/.local/lib/python3.8/site-packages/pymysql/connections.py", line 725, in _read_packet
    packet.raise_for_error()
    │      └ <function MysqlPacket.raise_for_error at 0x7f31f34ddee0>
    └ <pymysql.protocol.MysqlPacket object at 0x7f2f98568cd0>
  File "/home/chase/.local/lib/python3.8/site-packages/pymysql/protocol.py", line 221, in raise_for_error
    err.raise_mysql_exception(self._data)
    │   │                     │    └ <member '_data' of 'MysqlPacket' objects>
    │   │                     └ <pymysql.protocol.MysqlPacket object at 0x7f2f98568cd0>
    │   └ <function raise_mysql_exception at 0x7f31f358c670>
    └ <module 'pymysql.err' from '/home/chase/.local/lib/python3.8/site-packages/pymysql/err.py'>
  File "/home/chase/.local/lib/python3.8/site-packages/pymysql/err.py", line 143, in raise_mysql_exception
    raise errorclass(errno, errval)
          │          │      └ "Duplicate entry '180.201.163.246:6800' for key 'device.PRIMARY'"
          │          └ 1062
          └ <class 'pymysql.err.IntegrityError'>

pymysql.err.IntegrityError: (1062, "Duplicate entry '180.201.163.246:6800' for key 'device.PRIMARY'")


The above exception was the direct cause of the following exception:


Traceback (most recent call last):

  File "/usr/lib/python3.8/threading.py", line 890, in _bootstrap
    self._bootstrap_inner()
    │    └ <function Thread._bootstrap_inner at 0x7f321bf29a60>
    └ <Thread(Thread-7631, started daemon 139839495333632)>
  File "/usr/lib/python3.8/threading.py", line 932, in _bootstrap_inner
    self.run()
    │    └ <function Thread.run at 0x7f321bf29790>
    └ <Thread(Thread-7631, started daemon 139839495333632)>
  File "/usr/lib/python3.8/threading.py", line 870, in run
    self._target(*self._args, **self._kwargs)
    │    │        │    │        │    └ {}
    │    │        │    │        └ <Thread(Thread-7631, started daemon 139839495333632)>
    │    │        │    └ ('ProjectManager.run_func_by_thread',)
    │    │        └ <Thread(Thread-7631, started daemon 139839495333632)>
    │    └ <bound method ProjectManager.get_request_from_keywords_hot of <monitor.projectManager.ProjectManager object at 0x7f31042e52e0>>
    └ <Thread(Thread-7631, started daemon 139839495333632)>

  File "/home/users/Scy/yuqing/spider/monitor/projectManager.py", line 799, in get_request_from_keywords_hot
    self.start_finished_spider_every_interval(project_names)
    │    │                                    └ ['default', 'test']
    │    └ <function ProjectManager.start_finished_spider_every_interval at 0x7f3104005280>
    └ <monitor.projectManager.ProjectManager object at 0x7f31042e52e0>

  File "/home/users/Scy/yuqing/spider/monitor/projectManager.py", line 784, in start_finished_spider_every_interval
    self[name].start_spider()
    │    └ 'default'
    └ <monitor.projectManager.ProjectManager object at 0x7f31042e52e0>

  File "/home/users/Scy/yuqing/spider/monitor/projectManager.py", line 366, in start_spider
    self.update_device_valid(device)
    │    │                   └ <monitor.deviceManager.DeviceC object at 0x7f3104029220>
    │    └ <function Project.update_device_valid at 0x7f3104003280>
    └ <monitor.projectManager.Project object at 0x7f3104029460>

  File "/home/users/Scy/yuqing/spider/monitor/projectManager.py", line 421, in update_device_valid
    self.database_manager.mysql.update(Device(**device.to_item()))
    │    │                │     │      │        │      └ <function DeviceC.to_item at 0x7f31f34ed310>
    │    │                │     │      │        └ <monitor.deviceManager.DeviceC object at 0x7f3104029220>
    │    │                │     │      └ <class 'base.db.mysql.Device'>
    │    │                │     └ <function Mysql.update at 0x7f31f35f4790>
    │    │                └ <base.db.mysql.Mysql object at 0x7f3103ffdfd0>
    │    └ <base.db.dbSlot.Slot object at 0x7f3103ffdf10>
    └ <monitor.projectManager.Project object at 0x7f3104029460>

> File "/home/users/Scy/yuqing/spider/base/db/mysql.py", line 375, in update
    row.update(new)
    │   │      └ {'server_id': '180.201.163.246:6800', 'ip': '180.201.163.246', 'username': 'chase', 'password': '8107046204334271188664597070...
    │   └ <function Query.update at 0x7f31f37333a0>
    └ <sqlalchemy.orm.query.Query object at 0x7f30b8370c10>

  File "/home/chase/.local/lib/python3.8/site-packages/sqlalchemy/orm/query.py", line 3221, in update
    result = self.session.execute(
             │    │       └ <function Session.execute at 0x7f31f370faf0>
             │    └ <sqlalchemy.orm.session.Session object at 0x7f3018461d60>
             └ <sqlalchemy.orm.query.Query object at 0x7f30b8370c10>
  File "/home/chase/.local/lib/python3.8/site-packages/sqlalchemy/orm/session.py", line 1689, in execute
    result = conn._execute_20(statement, params or {}, execution_options)
             │    │           │          │             └ immutabledict({'synchronize_session': 'evaluate', '_sa_orm_update_options': default_update_options(_matched_objects=[], _reso...
             │    │           │          └ immutabledict({})
             │    │           └ <sqlalchemy.sql.annotation.AnnotatedUpdate object at 0x7f30782e6a00>
             │    └ <function Connection._execute_20 at 0x7f31f39bc790>
             └ <sqlalchemy.engine.base.Connection object at 0x7f30584ccd00>
  File "/home/chase/.local/lib/python3.8/site-packages/sqlalchemy/engine/base.py", line 1583, in _execute_20
    return meth(self, args_10style, kwargs_10style, execution_options)
           │    │     │             │               └ immutabledict({'synchronize_session': 'evaluate', '_sa_orm_update_options': default_update_options(_matched_objects=[], _reso...
           │    │     │             └ immutabledict({})
           │    │     └ ({},)
           │    └ <sqlalchemy.engine.base.Connection object at 0x7f30584ccd00>
           └ <bound method ClauseElement._execute_on_connection of <sqlalchemy.sql.annotation.AnnotatedUpdate object at 0x7f30782e6a00>>
  File "/home/chase/.local/lib/python3.8/site-packages/sqlalchemy/sql/elements.py", line 323, in _execute_on_connection
    return connection._execute_clauseelement(
           │          └ <function Connection._execute_clauseelement at 0x7f31f39bc5e0>
           └ <sqlalchemy.engine.base.Connection object at 0x7f30584ccd00>
  File "/home/chase/.local/lib/python3.8/site-packages/sqlalchemy/engine/base.py", line 1452, in _execute_clauseelement
    ret = self._execute_context(
          │    └ <function Connection._execute_context at 0x7f31f39bc8b0>
          └ <sqlalchemy.engine.base.Connection object at 0x7f30584ccd00>
  File "/home/chase/.local/lib/python3.8/site-packages/sqlalchemy/engine/base.py", line 1814, in _execute_context
    self._handle_dbapi_exception(
    │    └ <function Connection._handle_dbapi_exception at 0x7f31f39bca60>
    └ <sqlalchemy.engine.base.Connection object at 0x7f30584ccd00>
  File "/home/chase/.local/lib/python3.8/site-packages/sqlalchemy/engine/base.py", line 1995, in _handle_dbapi_exception
    util.raise_(
    │    └ <function raise_ at 0x7f31f3d7ea60>
    └ <module 'sqlalchemy.util' from '/home/chase/.local/lib/python3.8/site-packages/sqlalchemy/util/__init__.py'>
  File "/home/chase/.local/lib/python3.8/site-packages/sqlalchemy/util/compat.py", line 207, in raise_
    raise exception
  File "/home/chase/.local/lib/python3.8/site-packages/sqlalchemy/engine/base.py", line 1771, in _execute_context
    self.dialect.do_execute(
    │    │       └ <function DefaultDialect.do_execute at 0x7f31f38f75e0>
    │    └ <sqlalchemy.dialects.mysql.pymysql.MySQLDialect_pymysql object at 0x7f3103ffde20>
    └ <sqlalchemy.engine.base.Connection object at 0x7f30584ccd00>
  File "/home/chase/.local/lib/python3.8/site-packages/sqlalchemy/engine/default.py", line 717, in do_execute
    cursor.execute(statement, parameters)
    │      │       │          └ {'server_id': '180.201.163.246:6800', 'ip': '180.201.163.246', 'username': 'chase', 'password': '8107046204334271188664597070...
    │      │       └ 'UPDATE device SET server_id=%(server_id)s, ip=%(ip)s, username=%(username)s, password=%(password)s, address=%(address)s, por...
    │      └ <function Cursor.execute at 0x7f31f354cdc0>
    └ <pymysql.cursors.Cursor object at 0x7f2fb86a25e0>
  File "/home/chase/.local/lib/python3.8/site-packages/pymysql/cursors.py", line 148, in execute
    result = self._query(query)
             │    │      └ "UPDATE device SET server_id='180.201.163.246:6800', ip='180.201.163.246', username='chase', password='8107046204334271188664...
             │    └ <function Cursor._query at 0x7f31f34d7280>
             └ <pymysql.cursors.Cursor object at 0x7f2fb86a25e0>
  File "/home/chase/.local/lib/python3.8/site-packages/pymysql/cursors.py", line 310, in _query
    conn.query(q)
    │    │     └ "UPDATE device SET server_id='180.201.163.246:6800', ip='180.201.163.246', username='chase', password='8107046204334271188664...
    │    └ <function Connection.query at 0x7f31f34e5670>
    └ <pymysql.connections.Connection object at 0x7f30985a5070>
  File "/home/chase/.local/lib/python3.8/site-packages/pymysql/connections.py", line 548, in query
    self._affected_rows = self._read_query_result(unbuffered=unbuffered)
    │    │                │    │                             └ False
    │    │                │    └ <function Connection._read_query_result at 0x7f31f34e5ca0>
    │    │                └ <pymysql.connections.Connection object at 0x7f30985a5070>
    │    └ 1
    └ <pymysql.connections.Connection object at 0x7f30985a5070>
  File "/home/chase/.local/lib/python3.8/site-packages/pymysql/connections.py", line 775, in _read_query_result
    result.read()
    │      └ <function MySQLResult.read at 0x7f31f34e64c0>
    └ <pymysql.connections.MySQLResult object at 0x7f30b854afd0>
  File "/home/chase/.local/lib/python3.8/site-packages/pymysql/connections.py", line 1156, in read
    first_packet = self.connection._read_packet()
                   │    └ None
                   └ <pymysql.connections.MySQLResult object at 0x7f30b854afd0>
  File "/home/chase/.local/lib/python3.8/site-packages/pymysql/connections.py", line 725, in _read_packet
    packet.raise_for_error()
    │      └ <function MysqlPacket.raise_for_error at 0x7f31f34ddee0>
    └ <pymysql.protocol.MysqlPacket object at 0x7f2f98568cd0>
  File "/home/chase/.local/lib/python3.8/site-packages/pymysql/protocol.py", line 221, in raise_for_error
    err.raise_mysql_exception(self._data)
    │   │                     │    └ <member '_data' of 'MysqlPacket' objects>
    │   │                     └ <pymysql.protocol.MysqlPacket object at 0x7f2f98568cd0>
    │   └ <function raise_mysql_exception at 0x7f31f358c670>
    └ <module 'pymysql.err' from '/home/chase/.local/lib/python3.8/site-packages/pymysql/err.py'>
  File "/home/chase/.local/lib/python3.8/site-packages/pymysql/err.py", line 143, in raise_mysql_exception
    raise errorclass(errno, errval)
          │          │      └ "Duplicate entry '180.201.163.246:6800' for key 'device.PRIMARY'"
          │          └ 1062
          └ <class 'pymysql.err.IntegrityError'>

sqlalchemy.exc.IntegrityError: (pymysql.err.IntegrityError) (1062, "Duplicate entry '180.201.163.246:6800' for key 'device.PRIMARY'")
[SQL: UPDATE device SET server_id=%(server_id)s, ip=%(ip)s, username=%(username)s, password=%(password)s, address=%(address)s, port=%(port)s, valid=%(valid)s WHERE device.ip = %(ip_1)s]
[parameters: {'server_id': '180.201.163.246:6800', 'ip': '180.201.163.246', 'username': 'chase', 'password': '81070462043342711886645970703804173375789563396016759045353677052687722041875810894783858849746487034375051225800650783490163088132842192510275121401 ... (10 characters truncated) ... 01087232684960289658590762124681171523225178306844005813724363957276369118040428058982818475120259291322647063574244069729991558169954358324673984581', 'address': '/home/users/CT/pycharmproject/spiders/', 'port': 6800, 'valid': 1, 'ip_1': '180.201.163.246'}]
(Background on this error at: https://sqlalche.me/e/14/gkpj)
2022-05-14 01:20:34.812 | ERROR    | base.db.mysql:update:390 - 【mysql更新数据出错】
Traceback (most recent call last):

  File "/home/chase/.local/lib/python3.8/site-packages/sqlalchemy/engine/base.py", line 1771, in _execute_context
    self.dialect.do_execute(
    │    │       └ <function DefaultDialect.do_execute at 0x7f31f38f75e0>
    │    └ <sqlalchemy.dialects.mysql.pymysql.MySQLDialect_pymysql object at 0x7f3103ffde20>
    └ <sqlalchemy.engine.base.Connection object at 0x7f30784e50d0>
  File "/home/chase/.local/lib/python3.8/site-packages/sqlalchemy/engine/default.py", line 717, in do_execute
    cursor.execute(statement, parameters)
    │      │       │          └ {'server_id': '180.201.163.246:6800', 'ip': '180.201.163.246', 'username': 'chase', 'password': '4873273314850449171795796706...
    │      │       └ 'UPDATE device SET server_id=%(server_id)s, ip=%(ip)s, username=%(username)s, password=%(password)s, address=%(address)s, por...
    │      └ <function Cursor.execute at 0x7f31f354cdc0>
    └ <pymysql.cursors.Cursor object at 0x7f3078315ca0>
  File "/home/chase/.local/lib/python3.8/site-packages/pymysql/cursors.py", line 148, in execute
    result = self._query(query)
             │    │      └ "UPDATE device SET server_id='180.201.163.246:6800', ip='180.201.163.246', username='chase', password='4873273314850449171795...
             │    └ <function Cursor._query at 0x7f31f34d7280>
             └ <pymysql.cursors.Cursor object at 0x7f3078315ca0>
  File "/home/chase/.local/lib/python3.8/site-packages/pymysql/cursors.py", line 310, in _query
    conn.query(q)
    │    │     └ "UPDATE device SET server_id='180.201.163.246:6800', ip='180.201.163.246', username='chase', password='4873273314850449171795...
    │    └ <function Connection.query at 0x7f31f34e5670>
    └ <pymysql.connections.Connection object at 0x7f3102014cd0>
  File "/home/chase/.local/lib/python3.8/site-packages/pymysql/connections.py", line 548, in query
    self._affected_rows = self._read_query_result(unbuffered=unbuffered)
    │    │                │    │                             └ False
    │    │                │    └ <function Connection._read_query_result at 0x7f31f34e5ca0>
    │    │                └ <pymysql.connections.Connection object at 0x7f3102014cd0>
    │    └ 1
    └ <pymysql.connections.Connection object at 0x7f3102014cd0>
  File "/home/chase/.local/lib/python3.8/site-packages/pymysql/connections.py", line 775, in _read_query_result
    result.read()
    │      └ <function MySQLResult.read at 0x7f31f34e64c0>
    └ <pymysql.connections.MySQLResult object at 0x7f3102299ee0>
  File "/home/chase/.local/lib/python3.8/site-packages/pymysql/connections.py", line 1156, in read
    first_packet = self.connection._read_packet()
                   │    └ None
                   └ <pymysql.connections.MySQLResult object at 0x7f3102299ee0>
  File "/home/chase/.local/lib/python3.8/site-packages/pymysql/connections.py", line 725, in _read_packet
    packet.raise_for_error()
    │      └ <function MysqlPacket.raise_for_error at 0x7f31f34ddee0>
    └ <pymysql.protocol.MysqlPacket object at 0x7f310230d640>
  File "/home/chase/.local/lib/python3.8/site-packages/pymysql/protocol.py", line 221, in raise_for_error
    err.raise_mysql_exception(self._data)
    │   │                     │    └ <member '_data' of 'MysqlPacket' objects>
    │   │                     └ <pymysql.protocol.MysqlPacket object at 0x7f310230d640>
    │   └ <function raise_mysql_exception at 0x7f31f358c670>
    └ <module 'pymysql.err' from '/home/chase/.local/lib/python3.8/site-packages/pymysql/err.py'>
  File "/home/chase/.local/lib/python3.8/site-packages/pymysql/err.py", line 143, in raise_mysql_exception
    raise errorclass(errno, errval)
          │          │      └ "Duplicate entry '180.201.163.246:6800' for key 'device.PRIMARY'"
          │          └ 1062
          └ <class 'pymysql.err.IntegrityError'>

pymysql.err.IntegrityError: (1062, "Duplicate entry '180.201.163.246:6800' for key 'device.PRIMARY'")


The above exception was the direct cause of the following exception:


Traceback (most recent call last):

  File "/usr/lib/python3.8/threading.py", line 890, in _bootstrap
    self._bootstrap_inner()
    │    └ <function Thread._bootstrap_inner at 0x7f321bf29a60>
    └ <Thread(Thread-7635, started daemon 139847289272064)>
  File "/usr/lib/python3.8/threading.py", line 932, in _bootstrap_inner
    self.run()
    │    └ <function Thread.run at 0x7f321bf29790>
    └ <Thread(Thread-7635, started daemon 139847289272064)>
  File "/usr/lib/python3.8/threading.py", line 870, in run
    self._target(*self._args, **self._kwargs)
    │    │        │    │        │    └ {}
    │    │        │    │        └ <Thread(Thread-7635, started daemon 139847289272064)>
    │    │        │    └ ('ProjectManager.run_func_by_thread',)
    │    │        └ <Thread(Thread-7635, started daemon 139847289272064)>
    │    └ <bound method ProjectManager.get_request_from_keywords_hot of <monitor.projectManager.ProjectManager object at 0x7f31042e52e0>>
    └ <Thread(Thread-7635, started daemon 139847289272064)>

  File "/home/users/Scy/yuqing/spider/monitor/projectManager.py", line 799, in get_request_from_keywords_hot
    self.start_finished_spider_every_interval(project_names)
    │    │                                    └ ['default', 'test']
    │    └ <function ProjectManager.start_finished_spider_every_interval at 0x7f3104005280>
    └ <monitor.projectManager.ProjectManager object at 0x7f31042e52e0>

  File "/home/users/Scy/yuqing/spider/monitor/projectManager.py", line 784, in start_finished_spider_every_interval
    self[name].start_spider()
    │    └ 'default'
    └ <monitor.projectManager.ProjectManager object at 0x7f31042e52e0>

  File "/home/users/Scy/yuqing/spider/monitor/projectManager.py", line 366, in start_spider
    self.update_device_valid(device)
    │    │                   └ <monitor.deviceManager.DeviceC object at 0x7f3104029220>
    │    └ <function Project.update_device_valid at 0x7f3104003280>
    └ <monitor.projectManager.Project object at 0x7f3104029460>

  File "/home/users/Scy/yuqing/spider/monitor/projectManager.py", line 421, in update_device_valid
    self.database_manager.mysql.update(Device(**device.to_item()))
    │    │                │     │      │        │      └ <function DeviceC.to_item at 0x7f31f34ed310>
    │    │                │     │      │        └ <monitor.deviceManager.DeviceC object at 0x7f3104029220>
    │    │                │     │      └ <class 'base.db.mysql.Device'>
    │    │                │     └ <function Mysql.update at 0x7f31f35f4790>
    │    │                └ <base.db.mysql.Mysql object at 0x7f3103ffdfd0>
    │    └ <base.db.dbSlot.Slot object at 0x7f3103ffdf10>
    └ <monitor.projectManager.Project object at 0x7f3104029460>

> File "/home/users/Scy/yuqing/spider/base/db/mysql.py", line 375, in update
    row.update(new)
    │   │      └ {'server_id': '180.201.163.246:6800', 'ip': '180.201.163.246', 'username': 'chase', 'password': '4873273314850449171795796706...
    │   └ <function Query.update at 0x7f31f37333a0>
    └ <sqlalchemy.orm.query.Query object at 0x7f31001de160>

  File "/home/chase/.local/lib/python3.8/site-packages/sqlalchemy/orm/query.py", line 3221, in update
    result = self.session.execute(
             │    │       └ <function Session.execute at 0x7f31f370faf0>
             │    └ <sqlalchemy.orm.session.Session object at 0x7f30384ac7c0>
             └ <sqlalchemy.orm.query.Query object at 0x7f31001de160>
  File "/home/chase/.local/lib/python3.8/site-packages/sqlalchemy/orm/session.py", line 1689, in execute
    result = conn._execute_20(statement, params or {}, execution_options)
             │    │           │          │             └ immutabledict({'synchronize_session': 'evaluate', '_sa_orm_update_options': default_update_options(_matched_objects=[], _reso...
             │    │           │          └ immutabledict({})
             │    │           └ <sqlalchemy.sql.annotation.AnnotatedUpdate object at 0x7f2fb81c1fd0>
             │    └ <function Connection._execute_20 at 0x7f31f39bc790>
             └ <sqlalchemy.engine.base.Connection object at 0x7f30784e50d0>
  File "/home/chase/.local/lib/python3.8/site-packages/sqlalchemy/engine/base.py", line 1583, in _execute_20
    return meth(self, args_10style, kwargs_10style, execution_options)
           │    │     │             │               └ immutabledict({'synchronize_session': 'evaluate', '_sa_orm_update_options': default_update_options(_matched_objects=[], _reso...
           │    │     │             └ immutabledict({})
           │    │     └ ({},)
           │    └ <sqlalchemy.engine.base.Connection object at 0x7f30784e50d0>
           └ <bound method ClauseElement._execute_on_connection of <sqlalchemy.sql.annotation.AnnotatedUpdate object at 0x7f2fb81c1fd0>>
  File "/home/chase/.local/lib/python3.8/site-packages/sqlalchemy/sql/elements.py", line 323, in _execute_on_connection
    return connection._execute_clauseelement(
           │          └ <function Connection._execute_clauseelement at 0x7f31f39bc5e0>
           └ <sqlalchemy.engine.base.Connection object at 0x7f30784e50d0>
  File "/home/chase/.local/lib/python3.8/site-packages/sqlalchemy/engine/base.py", line 1452, in _execute_clauseelement
    ret = self._execute_context(
          │    └ <function Connection._execute_context at 0x7f31f39bc8b0>
          └ <sqlalchemy.engine.base.Connection object at 0x7f30784e50d0>
  File "/home/chase/.local/lib/python3.8/site-packages/sqlalchemy/engine/base.py", line 1814, in _execute_context
    self._handle_dbapi_exception(
    │    └ <function Connection._handle_dbapi_exception at 0x7f31f39bca60>
    └ <sqlalchemy.engine.base.Connection object at 0x7f30784e50d0>
  File "/home/chase/.local/lib/python3.8/site-packages/sqlalchemy/engine/base.py", line 1995, in _handle_dbapi_exception
    util.raise_(
    │    └ <function raise_ at 0x7f31f3d7ea60>
    └ <module 'sqlalchemy.util' from '/home/chase/.local/lib/python3.8/site-packages/sqlalchemy/util/__init__.py'>
  File "/home/chase/.local/lib/python3.8/site-packages/sqlalchemy/util/compat.py", line 207, in raise_
    raise exception
  File "/home/chase/.local/lib/python3.8/site-packages/sqlalchemy/engine/base.py", line 1771, in _execute_context
    self.dialect.do_execute(
    │    │       └ <function DefaultDialect.do_execute at 0x7f31f38f75e0>
    │    └ <sqlalchemy.dialects.mysql.pymysql.MySQLDialect_pymysql object at 0x7f3103ffde20>
    └ <sqlalchemy.engine.base.Connection object at 0x7f30784e50d0>
  File "/home/chase/.local/lib/python3.8/site-packages/sqlalchemy/engine/default.py", line 717, in do_execute
    cursor.execute(statement, parameters)
    │      │       │          └ {'server_id': '180.201.163.246:6800', 'ip': '180.201.163.246', 'username': 'chase', 'password': '4873273314850449171795796706...
    │      │       └ 'UPDATE device SET server_id=%(server_id)s, ip=%(ip)s, username=%(username)s, password=%(password)s, address=%(address)s, por...
    │      └ <function Cursor.execute at 0x7f31f354cdc0>
    └ <pymysql.cursors.Cursor object at 0x7f3078315ca0>
  File "/home/chase/.local/lib/python3.8/site-packages/pymysql/cursors.py", line 148, in execute
    result = self._query(query)
             │    │      └ "UPDATE device SET server_id='180.201.163.246:6800', ip='180.201.163.246', username='chase', password='4873273314850449171795...
             │    └ <function Cursor._query at 0x7f31f34d7280>
             └ <pymysql.cursors.Cursor object at 0x7f3078315ca0>
  File "/home/chase/.local/lib/python3.8/site-packages/pymysql/cursors.py", line 310, in _query
    conn.query(q)
    │    │     └ "UPDATE device SET server_id='180.201.163.246:6800', ip='180.201.163.246', username='chase', password='4873273314850449171795...
    │    └ <function Connection.query at 0x7f31f34e5670>
    └ <pymysql.connections.Connection object at 0x7f3102014cd0>
  File "/home/chase/.local/lib/python3.8/site-packages/pymysql/connections.py", line 548, in query
    self._affected_rows = self._read_query_result(unbuffered=unbuffered)
    │    │                │    │                             └ False
    │    │                │    └ <function Connection._read_query_result at 0x7f31f34e5ca0>
    │    │                └ <pymysql.connections.Connection object at 0x7f3102014cd0>
    │    └ 1
    └ <pymysql.connections.Connection object at 0x7f3102014cd0>
  File "/home/chase/.local/lib/python3.8/site-packages/pymysql/connections.py", line 775, in _read_query_result
    result.read()
    │      └ <function MySQLResult.read at 0x7f31f34e64c0>
    └ <pymysql.connections.MySQLResult object at 0x7f3102299ee0>
  File "/home/chase/.local/lib/python3.8/site-packages/pymysql/connections.py", line 1156, in read
    first_packet = self.connection._read_packet()
                   │    └ None
                   └ <pymysql.connections.MySQLResult object at 0x7f3102299ee0>
  File "/home/chase/.local/lib/python3.8/site-packages/pymysql/connections.py", line 725, in _read_packet
    packet.raise_for_error()
    │      └ <function MysqlPacket.raise_for_error at 0x7f31f34ddee0>
    └ <pymysql.protocol.MysqlPacket object at 0x7f310230d640>
  File "/home/chase/.local/lib/python3.8/site-packages/pymysql/protocol.py", line 221, in raise_for_error
    err.raise_mysql_exception(self._data)
    │   │                     │    └ <member '_data' of 'MysqlPacket' objects>
    │   │                     └ <pymysql.protocol.MysqlPacket object at 0x7f310230d640>
    │   └ <function raise_mysql_exception at 0x7f31f358c670>
    └ <module 'pymysql.err' from '/home/chase/.local/lib/python3.8/site-packages/pymysql/err.py'>
  File "/home/chase/.local/lib/python3.8/site-packages/pymysql/err.py", line 143, in raise_mysql_exception
    raise errorclass(errno, errval)
          │          │      └ "Duplicate entry '180.201.163.246:6800' for key 'device.PRIMARY'"
          │          └ 1062
          └ <class 'pymysql.err.IntegrityError'>

sqlalchemy.exc.IntegrityError: (pymysql.err.IntegrityError) (1062, "Duplicate entry '180.201.163.246:6800' for key 'device.PRIMARY'")
[SQL: UPDATE device SET server_id=%(server_id)s, ip=%(ip)s, username=%(username)s, password=%(password)s, address=%(address)s, port=%(port)s, valid=%(valid)s WHERE device.ip = %(ip_1)s]
[parameters: {'server_id': '180.201.163.246:6800', 'ip': '180.201.163.246', 'username': 'chase', 'password': '48732733148504491717957967061059808326814630278978591750203822691589549626516711285193734359333848717533719779380823831909928616071087764886289547716 ... (10 characters truncated) ... 79884685919592469225803067594709911377348939235666346051422413888096306497871458828247573241176380207561422344665541793469854594162114623886451503454', 'address': '/home/users/CT/pycharmproject/spiders/', 'port': 6800, 'valid': 1, 'ip_1': '180.201.163.246'}]
(Background on this error at: https://sqlalche.me/e/14/gkpj)
2022-05-14 01:20:54.301 | ERROR    | base.db.mysql:update:390 - 【mysql更新数据出错】
Traceback (most recent call last):

  File "/home/chase/.local/lib/python3.8/site-packages/sqlalchemy/engine/base.py", line 1771, in _execute_context
    self.dialect.do_execute(
    │    │       └ <function DefaultDialect.do_execute at 0x7f31f38f75e0>
    │    └ <sqlalchemy.dialects.mysql.pymysql.MySQLDialect_pymysql object at 0x7f3103ffde20>
    └ <sqlalchemy.engine.base.Connection object at 0x7f30d8574fd0>
  File "/home/chase/.local/lib/python3.8/site-packages/sqlalchemy/engine/default.py", line 717, in do_execute
    cursor.execute(statement, parameters)
    │      │       │          └ {'server_id': '180.201.163.246:6800', 'ip': '180.201.163.246', 'username': 'chase', 'password': '4751938617972299926481810389...
    │      │       └ 'UPDATE device SET server_id=%(server_id)s, ip=%(ip)s, username=%(username)s, password=%(password)s, address=%(address)s, por...
    │      └ <function Cursor.execute at 0x7f31f354cdc0>
    └ <pymysql.cursors.Cursor object at 0x7f2fb86a1ee0>
  File "/home/chase/.local/lib/python3.8/site-packages/pymysql/cursors.py", line 148, in execute
    result = self._query(query)
             │    │      └ "UPDATE device SET server_id='180.201.163.246:6800', ip='180.201.163.246', username='chase', password='4751938617972299926481...
             │    └ <function Cursor._query at 0x7f31f34d7280>
             └ <pymysql.cursors.Cursor object at 0x7f2fb86a1ee0>
  File "/home/chase/.local/lib/python3.8/site-packages/pymysql/cursors.py", line 310, in _query
    conn.query(q)
    │    │     └ "UPDATE device SET server_id='180.201.163.246:6800', ip='180.201.163.246', username='chase', password='4751938617972299926481...
    │    └ <function Connection.query at 0x7f31f34e5670>
    └ <pymysql.connections.Connection object at 0x7f2f98556370>
  File "/home/chase/.local/lib/python3.8/site-packages/pymysql/connections.py", line 548, in query
    self._affected_rows = self._read_query_result(unbuffered=unbuffered)
    │    │                │    │                             └ False
    │    │                │    └ <function Connection._read_query_result at 0x7f31f34e5ca0>
    │    │                └ <pymysql.connections.Connection object at 0x7f2f98556370>
    │    └ 1
    └ <pymysql.connections.Connection object at 0x7f2f98556370>
  File "/home/chase/.local/lib/python3.8/site-packages/pymysql/connections.py", line 775, in _read_query_result
    result.read()
    │      └ <function MySQLResult.read at 0x7f31f34e64c0>
    └ <pymysql.connections.MySQLResult object at 0x7f2f9875cd00>
  File "/home/chase/.local/lib/python3.8/site-packages/pymysql/connections.py", line 1156, in read
    first_packet = self.connection._read_packet()
                   │    └ None
                   └ <pymysql.connections.MySQLResult object at 0x7f2f9875cd00>
  File "/home/chase/.local/lib/python3.8/site-packages/pymysql/connections.py", line 725, in _read_packet
    packet.raise_for_error()
    │      └ <function MysqlPacket.raise_for_error at 0x7f31f34ddee0>
    └ <pymysql.protocol.MysqlPacket object at 0x7f30783b5790>
  File "/home/chase/.local/lib/python3.8/site-packages/pymysql/protocol.py", line 221, in raise_for_error
    err.raise_mysql_exception(self._data)
    │   │                     │    └ <member '_data' of 'MysqlPacket' objects>
    │   │                     └ <pymysql.protocol.MysqlPacket object at 0x7f30783b5790>
    │   └ <function raise_mysql_exception at 0x7f31f358c670>
    └ <module 'pymysql.err' from '/home/chase/.local/lib/python3.8/site-packages/pymysql/err.py'>
  File "/home/chase/.local/lib/python3.8/site-packages/pymysql/err.py", line 143, in raise_mysql_exception
    raise errorclass(errno, errval)
          │          │      └ "Duplicate entry '180.201.163.246:6800' for key 'device.PRIMARY'"
          │          └ 1062
          └ <class 'pymysql.err.IntegrityError'>

pymysql.err.IntegrityError: (1062, "Duplicate entry '180.201.163.246:6800' for key 'device.PRIMARY'")


The above exception was the direct cause of the following exception:


Traceback (most recent call last):

  File "/usr/lib/python3.8/threading.py", line 890, in _bootstrap
    self._bootstrap_inner()
    │    └ <function Thread._bootstrap_inner at 0x7f321bf29a60>
    └ <Thread(Thread-7639, started daemon 139847784179456)>
  File "/usr/lib/python3.8/threading.py", line 932, in _bootstrap_inner
    self.run()
    │    └ <function Thread.run at 0x7f321bf29790>
    └ <Thread(Thread-7639, started daemon 139847784179456)>
  File "/usr/lib/python3.8/threading.py", line 870, in run
    self._target(*self._args, **self._kwargs)
    │    │        │    │        │    └ {}
    │    │        │    │        └ <Thread(Thread-7639, started daemon 139847784179456)>
    │    │        │    └ ('ProjectManager.run_func_by_thread',)
    │    │        └ <Thread(Thread-7639, started daemon 139847784179456)>
    │    └ <bound method ProjectManager.get_request_from_keywords_hot of <monitor.projectManager.ProjectManager object at 0x7f31042e52e0>>
    └ <Thread(Thread-7639, started daemon 139847784179456)>

  File "/home/users/Scy/yuqing/spider/monitor/projectManager.py", line 799, in get_request_from_keywords_hot
    self.start_finished_spider_every_interval(project_names)
    │    │                                    └ ['default', 'test']
    │    └ <function ProjectManager.start_finished_spider_every_interval at 0x7f3104005280>
    └ <monitor.projectManager.ProjectManager object at 0x7f31042e52e0>

  File "/home/users/Scy/yuqing/spider/monitor/projectManager.py", line 784, in start_finished_spider_every_interval
    self[name].start_spider()
    │    └ 'default'
    └ <monitor.projectManager.ProjectManager object at 0x7f31042e52e0>

  File "/home/users/Scy/yuqing/spider/monitor/projectManager.py", line 366, in start_spider
    self.update_device_valid(device)
    │    │                   └ <monitor.deviceManager.DeviceC object at 0x7f3104029220>
    │    └ <function Project.update_device_valid at 0x7f3104003280>
    └ <monitor.projectManager.Project object at 0x7f3104029460>

  File "/home/users/Scy/yuqing/spider/monitor/projectManager.py", line 421, in update_device_valid
    self.database_manager.mysql.update(Device(**device.to_item()))
    │    │                │     │      │        │      └ <function DeviceC.to_item at 0x7f31f34ed310>
    │    │                │     │      │        └ <monitor.deviceManager.DeviceC object at 0x7f3104029220>
    │    │                │     │      └ <class 'base.db.mysql.Device'>
    │    │                │     └ <function Mysql.update at 0x7f31f35f4790>
    │    │                └ <base.db.mysql.Mysql object at 0x7f3103ffdfd0>
    │    └ <base.db.dbSlot.Slot object at 0x7f3103ffdf10>
    └ <monitor.projectManager.Project object at 0x7f3104029460>

> File "/home/users/Scy/yuqing/spider/base/db/mysql.py", line 375, in update
    row.update(new)
    │   │      └ {'server_id': '180.201.163.246:6800', 'ip': '180.201.163.246', 'username': 'chase', 'password': '4751938617972299926481810389...
    │   └ <function Query.update at 0x7f31f37333a0>
    └ <sqlalchemy.orm.query.Query object at 0x7f31f92157f0>

  File "/home/chase/.local/lib/python3.8/site-packages/sqlalchemy/orm/query.py", line 3221, in update
    result = self.session.execute(
             │    │       └ <function Session.execute at 0x7f31f370faf0>
             │    └ <sqlalchemy.orm.session.Session object at 0x7f301817c820>
             └ <sqlalchemy.orm.query.Query object at 0x7f31f92157f0>
  File "/home/chase/.local/lib/python3.8/site-packages/sqlalchemy/orm/session.py", line 1689, in execute
    result = conn._execute_20(statement, params or {}, execution_options)
             │    │           │          │             └ immutabledict({'synchronize_session': 'evaluate', '_sa_orm_update_options': default_update_options(_matched_objects=[], _reso...
             │    │           │          └ immutabledict({})
             │    │           └ <sqlalchemy.sql.annotation.AnnotatedUpdate object at 0x7f305851e0d0>
             │    └ <function Connection._execute_20 at 0x7f31f39bc790>
             └ <sqlalchemy.engine.base.Connection object at 0x7f30d8574fd0>
  File "/home/chase/.local/lib/python3.8/site-packages/sqlalchemy/engine/base.py", line 1583, in _execute_20
    return meth(self, args_10style, kwargs_10style, execution_options)
           │    │     │             │               └ immutabledict({'synchronize_session': 'evaluate', '_sa_orm_update_options': default_update_options(_matched_objects=[], _reso...
           │    │     │             └ immutabledict({})
           │    │     └ ({},)
           │    └ <sqlalchemy.engine.base.Connection object at 0x7f30d8574fd0>
           └ <bound method ClauseElement._execute_on_connection of <sqlalchemy.sql.annotation.AnnotatedUpdate object at 0x7f305851e0d0>>
  File "/home/chase/.local/lib/python3.8/site-packages/sqlalchemy/sql/elements.py", line 323, in _execute_on_connection
    return connection._execute_clauseelement(
           │          └ <function Connection._execute_clauseelement at 0x7f31f39bc5e0>
           └ <sqlalchemy.engine.base.Connection object at 0x7f30d8574fd0>
  File "/home/chase/.local/lib/python3.8/site-packages/sqlalchemy/engine/base.py", line 1452, in _execute_clauseelement
    ret = self._execute_context(
          │    └ <function Connection._execute_context at 0x7f31f39bc8b0>
          └ <sqlalchemy.engine.base.Connection object at 0x7f30d8574fd0>
  File "/home/chase/.local/lib/python3.8/site-packages/sqlalchemy/engine/base.py", line 1814, in _execute_context
    self._handle_dbapi_exception(
    │    └ <function Connection._handle_dbapi_exception at 0x7f31f39bca60>
    └ <sqlalchemy.engine.base.Connection object at 0x7f30d8574fd0>
  File "/home/chase/.local/lib/python3.8/site-packages/sqlalchemy/engine/base.py", line 1995, in _handle_dbapi_exception
    util.raise_(
    │    └ <function raise_ at 0x7f31f3d7ea60>
    └ <module 'sqlalchemy.util' from '/home/chase/.local/lib/python3.8/site-packages/sqlalchemy/util/__init__.py'>
  File "/home/chase/.local/lib/python3.8/site-packages/sqlalchemy/util/compat.py", line 207, in raise_
    raise exception
  File "/home/chase/.local/lib/python3.8/site-packages/sqlalchemy/engine/base.py", line 1771, in _execute_context
    self.dialect.do_execute(
    │    │       └ <function DefaultDialect.do_execute at 0x7f31f38f75e0>
    │    └ <sqlalchemy.dialects.mysql.pymysql.MySQLDialect_pymysql object at 0x7f3103ffde20>
    └ <sqlalchemy.engine.base.Connection object at 0x7f30d8574fd0>
  File "/home/chase/.local/lib/python3.8/site-packages/sqlalchemy/engine/default.py", line 717, in do_execute
    cursor.execute(statement, parameters)
    │      │       │          └ {'server_id': '180.201.163.246:6800', 'ip': '180.201.163.246', 'username': 'chase', 'password': '4751938617972299926481810389...
    │      │       └ 'UPDATE device SET server_id=%(server_id)s, ip=%(ip)s, username=%(username)s, password=%(password)s, address=%(address)s, por...
    │      └ <function Cursor.execute at 0x7f31f354cdc0>
    └ <pymysql.cursors.Cursor object at 0x7f2fb86a1ee0>
  File "/home/chase/.local/lib/python3.8/site-packages/pymysql/cursors.py", line 148, in execute
    result = self._query(query)
             │    │      └ "UPDATE device SET server_id='180.201.163.246:6800', ip='180.201.163.246', username='chase', password='4751938617972299926481...
             │    └ <function Cursor._query at 0x7f31f34d7280>
             └ <pymysql.cursors.Cursor object at 0x7f2fb86a1ee0>
  File "/home/chase/.local/lib/python3.8/site-packages/pymysql/cursors.py", line 310, in _query
    conn.query(q)
    │    │     └ "UPDATE device SET server_id='180.201.163.246:6800', ip='180.201.163.246', username='chase', password='4751938617972299926481...
    │    └ <function Connection.query at 0x7f31f34e5670>
    └ <pymysql.connections.Connection object at 0x7f2f98556370>
  File "/home/chase/.local/lib/python3.8/site-packages/pymysql/connections.py", line 548, in query
    self._affected_rows = self._read_query_result(unbuffered=unbuffered)
    │    │                │    │                             └ False
    │    │                │    └ <function Connection._read_query_result at 0x7f31f34e5ca0>
    │    │                └ <pymysql.connections.Connection object at 0x7f2f98556370>
    │    └ 1
    └ <pymysql.connections.Connection object at 0x7f2f98556370>
  File "/home/chase/.local/lib/python3.8/site-packages/pymysql/connections.py", line 775, in _read_query_result
    result.read()
    │      └ <function MySQLResult.read at 0x7f31f34e64c0>
    └ <pymysql.connections.MySQLResult object at 0x7f2f9875cd00>
  File "/home/chase/.local/lib/python3.8/site-packages/pymysql/connections.py", line 1156, in read
    first_packet = self.connection._read_packet()
                   │    └ None
                   └ <pymysql.connections.MySQLResult object at 0x7f2f9875cd00>
  File "/home/chase/.local/lib/python3.8/site-packages/pymysql/connections.py", line 725, in _read_packet
    packet.raise_for_error()
    │      └ <function MysqlPacket.raise_for_error at 0x7f31f34ddee0>
    └ <pymysql.protocol.MysqlPacket object at 0x7f30783b5790>
  File "/home/chase/.local/lib/python3.8/site-packages/pymysql/protocol.py", line 221, in raise_for_error
    err.raise_mysql_exception(self._data)
    │   │                     │    └ <member '_data' of 'MysqlPacket' objects>
    │   │                     └ <pymysql.protocol.MysqlPacket object at 0x7f30783b5790>
    │   └ <function raise_mysql_exception at 0x7f31f358c670>
    └ <module 'pymysql.err' from '/home/chase/.local/lib/python3.8/site-packages/pymysql/err.py'>
  File "/home/chase/.local/lib/python3.8/site-packages/pymysql/err.py", line 143, in raise_mysql_exception
    raise errorclass(errno, errval)
          │          │      └ "Duplicate entry '180.201.163.246:6800' for key 'device.PRIMARY'"
          │          └ 1062
          └ <class 'pymysql.err.IntegrityError'>

sqlalchemy.exc.IntegrityError: (pymysql.err.IntegrityError) (1062, "Duplicate entry '180.201.163.246:6800' for key 'device.PRIMARY'")
[SQL: UPDATE device SET server_id=%(server_id)s, ip=%(ip)s, username=%(username)s, password=%(password)s, address=%(address)s, port=%(port)s, valid=%(valid)s WHERE device.ip = %(ip_1)s]
[parameters: {'server_id': '180.201.163.246:6800', 'ip': '180.201.163.246', 'username': 'chase', 'password': '47519386179722999264818103896193105721168861059371800871216851306461672593842301417120678786914073103463670995075488153702881882998163209765664117577 ... (9 characters truncated) ... 24119348290164826193080876661972070657671344481671107300188655696599196313700091951352159466503924048486635047112256172624272285502510608810766344892', 'address': '/home/users/CT/pycharmproject/spiders/', 'port': 6800, 'valid': 1, 'ip_1': '180.201.163.246'}]
(Background on this error at: https://sqlalche.me/e/14/gkpj)
2022-05-14 01:21:11.516 | ERROR    | base.db.mysql:update:390 - 【mysql更新数据出错】
Traceback (most recent call last):

  File "/home/chase/.local/lib/python3.8/site-packages/sqlalchemy/engine/base.py", line 1771, in _execute_context
    self.dialect.do_execute(
    │    │       └ <function DefaultDialect.do_execute at 0x7f31f38f75e0>
    │    └ <sqlalchemy.dialects.mysql.pymysql.MySQLDialect_pymysql object at 0x7f3103ffde20>
    └ <sqlalchemy.engine.base.Connection object at 0x7f2f981aa880>
  File "/home/chase/.local/lib/python3.8/site-packages/sqlalchemy/engine/default.py", line 717, in do_execute
    cursor.execute(statement, parameters)
    │      │       │          └ {'server_id': '180.201.163.246:6800', 'ip': '180.201.163.246', 'username': 'chase', 'password': '6734793990868219599350210657...
    │      │       └ 'UPDATE device SET server_id=%(server_id)s, ip=%(ip)s, username=%(username)s, password=%(password)s, address=%(address)s, por...
    │      └ <function Cursor.execute at 0x7f31f354cdc0>
    └ <pymysql.cursors.Cursor object at 0x7f31000927f0>
  File "/home/chase/.local/lib/python3.8/site-packages/pymysql/cursors.py", line 148, in execute
    result = self._query(query)
             │    │      └ "UPDATE device SET server_id='180.201.163.246:6800', ip='180.201.163.246', username='chase', password='6734793990868219599350...
             │    └ <function Cursor._query at 0x7f31f34d7280>
             └ <pymysql.cursors.Cursor object at 0x7f31000927f0>
  File "/home/chase/.local/lib/python3.8/site-packages/pymysql/cursors.py", line 310, in _query
    conn.query(q)
    │    │     └ "UPDATE device SET server_id='180.201.163.246:6800', ip='180.201.163.246', username='chase', password='6734793990868219599350...
    │    └ <function Connection.query at 0x7f31f34e5670>
    └ <pymysql.connections.Connection object at 0x7f2ff847bc10>
  File "/home/chase/.local/lib/python3.8/site-packages/pymysql/connections.py", line 548, in query
    self._affected_rows = self._read_query_result(unbuffered=unbuffered)
    │    │                │    │                             └ False
    │    │                │    └ <function Connection._read_query_result at 0x7f31f34e5ca0>
    │    │                └ <pymysql.connections.Connection object at 0x7f2ff847bc10>
    │    └ 1
    └ <pymysql.connections.Connection object at 0x7f2ff847bc10>
  File "/home/chase/.local/lib/python3.8/site-packages/pymysql/connections.py", line 775, in _read_query_result
    result.read()
    │      └ <function MySQLResult.read at 0x7f31f34e64c0>
    └ <pymysql.connections.MySQLResult object at 0x7f30b81a6df0>
  File "/home/chase/.local/lib/python3.8/site-packages/pymysql/connections.py", line 1156, in read
    first_packet = self.connection._read_packet()
                   │    └ None
                   └ <pymysql.connections.MySQLResult object at 0x7f30b81a6df0>
  File "/home/chase/.local/lib/python3.8/site-packages/pymysql/connections.py", line 725, in _read_packet
    packet.raise_for_error()
    │      └ <function MysqlPacket.raise_for_error at 0x7f31f34ddee0>
    └ <pymysql.protocol.MysqlPacket object at 0x7f30b814a880>
  File "/home/chase/.local/lib/python3.8/site-packages/pymysql/protocol.py", line 221, in raise_for_error
    err.raise_mysql_exception(self._data)
    │   │                     │    └ <member '_data' of 'MysqlPacket' objects>
    │   │                     └ <pymysql.protocol.MysqlPacket object at 0x7f30b814a880>
    │   └ <function raise_mysql_exception at 0x7f31f358c670>
    └ <module 'pymysql.err' from '/home/chase/.local/lib/python3.8/site-packages/pymysql/err.py'>
  File "/home/chase/.local/lib/python3.8/site-packages/pymysql/err.py", line 143, in raise_mysql_exception
    raise errorclass(errno, errval)
          │          │      └ "Duplicate entry '180.201.163.246:6800' for key 'device.PRIMARY'"
          │          └ 1062
          └ <class 'pymysql.err.IntegrityError'>

pymysql.err.IntegrityError: (1062, "Duplicate entry '180.201.163.246:6800' for key 'device.PRIMARY'")


The above exception was the direct cause of the following exception:


Traceback (most recent call last):

  File "/usr/lib/python3.8/threading.py", line 890, in _bootstrap
    self._bootstrap_inner()
    │    └ <function Thread._bootstrap_inner at 0x7f321bf29a60>
    └ <Thread(Thread-7644, started daemon 139847255701248)>
  File "/usr/lib/python3.8/threading.py", line 932, in _bootstrap_inner
    self.run()
    │    └ <function Thread.run at 0x7f321bf29790>
    └ <Thread(Thread-7644, started daemon 139847255701248)>
  File "/usr/lib/python3.8/threading.py", line 870, in run
    self._target(*self._args, **self._kwargs)
    │    │        │    │        │    └ {}
    │    │        │    │        └ <Thread(Thread-7644, started daemon 139847255701248)>
    │    │        │    └ ('ProjectManager.run_func_by_thread',)
    │    │        └ <Thread(Thread-7644, started daemon 139847255701248)>
    │    └ <bound method ProjectManager.get_request_from_keywords_hot of <monitor.projectManager.ProjectManager object at 0x7f31042e52e0>>
    └ <Thread(Thread-7644, started daemon 139847255701248)>

  File "/home/users/Scy/yuqing/spider/monitor/projectManager.py", line 799, in get_request_from_keywords_hot
    self.start_finished_spider_every_interval(project_names)
    │    │                                    └ ['default', 'test']
    │    └ <function ProjectManager.start_finished_spider_every_interval at 0x7f3104005280>
    └ <monitor.projectManager.ProjectManager object at 0x7f31042e52e0>

  File "/home/users/Scy/yuqing/spider/monitor/projectManager.py", line 784, in start_finished_spider_every_interval
    self[name].start_spider()
    │    └ 'default'
    └ <monitor.projectManager.ProjectManager object at 0x7f31042e52e0>

  File "/home/users/Scy/yuqing/spider/monitor/projectManager.py", line 366, in start_spider
    self.update_device_valid(device)
    │    │                   └ <monitor.deviceManager.DeviceC object at 0x7f3104029220>
    │    └ <function Project.update_device_valid at 0x7f3104003280>
    └ <monitor.projectManager.Project object at 0x7f3104029460>

  File "/home/users/Scy/yuqing/spider/monitor/projectManager.py", line 421, in update_device_valid
    self.database_manager.mysql.update(Device(**device.to_item()))
    │    │                │     │      │        │      └ <function DeviceC.to_item at 0x7f31f34ed310>
    │    │                │     │      │        └ <monitor.deviceManager.DeviceC object at 0x7f3104029220>
    │    │                │     │      └ <class 'base.db.mysql.Device'>
    │    │                │     └ <function Mysql.update at 0x7f31f35f4790>
    │    │                └ <base.db.mysql.Mysql object at 0x7f3103ffdfd0>
    │    └ <base.db.dbSlot.Slot object at 0x7f3103ffdf10>
    └ <monitor.projectManager.Project object at 0x7f3104029460>

> File "/home/users/Scy/yuqing/spider/base/db/mysql.py", line 375, in update
    row.update(new)
    │   │      └ {'server_id': '180.201.163.246:6800', 'ip': '180.201.163.246', 'username': 'chase', 'password': '6734793990868219599350210657...
    │   └ <function Query.update at 0x7f31f37333a0>
    └ <sqlalchemy.orm.query.Query object at 0x7f30d83bfb20>

  File "/home/chase/.local/lib/python3.8/site-packages/sqlalchemy/orm/query.py", line 3221, in update
    result = self.session.execute(
             │    │       └ <function Session.execute at 0x7f31f370faf0>
             │    └ <sqlalchemy.orm.session.Session object at 0x7f30d83bfa90>
             └ <sqlalchemy.orm.query.Query object at 0x7f30d83bfb20>
  File "/home/chase/.local/lib/python3.8/site-packages/sqlalchemy/orm/session.py", line 1689, in execute
    result = conn._execute_20(statement, params or {}, execution_options)
             │    │           │          │             └ immutabledict({'synchronize_session': 'evaluate', '_sa_orm_update_options': default_update_options(_matched_objects=[], _reso...
             │    │           │          └ immutabledict({})
             │    │           └ <sqlalchemy.sql.annotation.AnnotatedUpdate object at 0x7f31f937eeb0>
             │    └ <function Connection._execute_20 at 0x7f31f39bc790>
             └ <sqlalchemy.engine.base.Connection object at 0x7f2f981aa880>
  File "/home/chase/.local/lib/python3.8/site-packages/sqlalchemy/engine/base.py", line 1583, in _execute_20
    return meth(self, args_10style, kwargs_10style, execution_options)
           │    │     │             │               └ immutabledict({'synchronize_session': 'evaluate', '_sa_orm_update_options': default_update_options(_matched_objects=[], _reso...
           │    │     │             └ immutabledict({})
           │    │     └ ({},)
           │    └ <sqlalchemy.engine.base.Connection object at 0x7f2f981aa880>
           └ <bound method ClauseElement._execute_on_connection of <sqlalchemy.sql.annotation.AnnotatedUpdate object at 0x7f31f937eeb0>>
  File "/home/chase/.local/lib/python3.8/site-packages/sqlalchemy/sql/elements.py", line 323, in _execute_on_connection
    return connection._execute_clauseelement(
           │          └ <function Connection._execute_clauseelement at 0x7f31f39bc5e0>
           └ <sqlalchemy.engine.base.Connection object at 0x7f2f981aa880>
  File "/home/chase/.local/lib/python3.8/site-packages/sqlalchemy/engine/base.py", line 1452, in _execute_clauseelement
    ret = self._execute_context(
          │    └ <function Connection._execute_context at 0x7f31f39bc8b0>
          └ <sqlalchemy.engine.base.Connection object at 0x7f2f981aa880>
  File "/home/chase/.local/lib/python3.8/site-packages/sqlalchemy/engine/base.py", line 1814, in _execute_context
    self._handle_dbapi_exception(
    │    └ <function Connection._handle_dbapi_exception at 0x7f31f39bca60>
    └ <sqlalchemy.engine.base.Connection object at 0x7f2f981aa880>
  File "/home/chase/.local/lib/python3.8/site-packages/sqlalchemy/engine/base.py", line 1995, in _handle_dbapi_exception
    util.raise_(
    │    └ <function raise_ at 0x7f31f3d7ea60>
    └ <module 'sqlalchemy.util' from '/home/chase/.local/lib/python3.8/site-packages/sqlalchemy/util/__init__.py'>
  File "/home/chase/.local/lib/python3.8/site-packages/sqlalchemy/util/compat.py", line 207, in raise_
    raise exception
  File "/home/chase/.local/lib/python3.8/site-packages/sqlalchemy/engine/base.py", line 1771, in _execute_context
    self.dialect.do_execute(
    │    │       └ <function DefaultDialect.do_execute at 0x7f31f38f75e0>
    │    └ <sqlalchemy.dialects.mysql.pymysql.MySQLDialect_pymysql object at 0x7f3103ffde20>
    └ <sqlalchemy.engine.base.Connection object at 0x7f2f981aa880>
  File "/home/chase/.local/lib/python3.8/site-packages/sqlalchemy/engine/default.py", line 717, in do_execute
    cursor.execute(statement, parameters)
    │      │       │          └ {'server_id': '180.201.163.246:6800', 'ip': '180.201.163.246', 'username': 'chase', 'password': '6734793990868219599350210657...
    │      │       └ 'UPDATE device SET server_id=%(server_id)s, ip=%(ip)s, username=%(username)s, password=%(password)s, address=%(address)s, por...
    │      └ <function Cursor.execute at 0x7f31f354cdc0>
    └ <pymysql.cursors.Cursor object at 0x7f31000927f0>
  File "/home/chase/.local/lib/python3.8/site-packages/pymysql/cursors.py", line 148, in execute
    result = self._query(query)
             │    │      └ "UPDATE device SET server_id='180.201.163.246:6800', ip='180.201.163.246', username='chase', password='6734793990868219599350...
             │    └ <function Cursor._query at 0x7f31f34d7280>
             └ <pymysql.cursors.Cursor object at 0x7f31000927f0>
  File "/home/chase/.local/lib/python3.8/site-packages/pymysql/cursors.py", line 310, in _query
    conn.query(q)
    │    │     └ "UPDATE device SET server_id='180.201.163.246:6800', ip='180.201.163.246', username='chase', password='6734793990868219599350...
    │    └ <function Connection.query at 0x7f31f34e5670>
    └ <pymysql.connections.Connection object at 0x7f2ff847bc10>
  File "/home/chase/.local/lib/python3.8/site-packages/pymysql/connections.py", line 548, in query
    self._affected_rows = self._read_query_result(unbuffered=unbuffered)
    │    │                │    │                             └ False
    │    │                │    └ <function Connection._read_query_result at 0x7f31f34e5ca0>
    │    │                └ <pymysql.connections.Connection object at 0x7f2ff847bc10>
    │    └ 1
    └ <pymysql.connections.Connection object at 0x7f2ff847bc10>
  File "/home/chase/.local/lib/python3.8/site-packages/pymysql/connections.py", line 775, in _read_query_result
    result.read()
    │      └ <function MySQLResult.read at 0x7f31f34e64c0>
    └ <pymysql.connections.MySQLResult object at 0x7f30b81a6df0>
  File "/home/chase/.local/lib/python3.8/site-packages/pymysql/connections.py", line 1156, in read
    first_packet = self.connection._read_packet()
                   │    └ None
                   └ <pymysql.connections.MySQLResult object at 0x7f30b81a6df0>
  File "/home/chase/.local/lib/python3.8/site-packages/pymysql/connections.py", line 725, in _read_packet
    packet.raise_for_error()
    │      └ <function MysqlPacket.raise_for_error at 0x7f31f34ddee0>
    └ <pymysql.protocol.MysqlPacket object at 0x7f30b814a880>
  File "/home/chase/.local/lib/python3.8/site-packages/pymysql/protocol.py", line 221, in raise_for_error
    err.raise_mysql_exception(self._data)
    │   │                     │    └ <member '_data' of 'MysqlPacket' objects>
    │   │                     └ <pymysql.protocol.MysqlPacket object at 0x7f30b814a880>
    │   └ <function raise_mysql_exception at 0x7f31f358c670>
    └ <module 'pymysql.err' from '/home/chase/.local/lib/python3.8/site-packages/pymysql/err.py'>
  File "/home/chase/.local/lib/python3.8/site-packages/pymysql/err.py", line 143, in raise_mysql_exception
    raise errorclass(errno, errval)
          │          │      └ "Duplicate entry '180.201.163.246:6800' for key 'device.PRIMARY'"
          │          └ 1062
          └ <class 'pymysql.err.IntegrityError'>

sqlalchemy.exc.IntegrityError: (pymysql.err.IntegrityError) (1062, "Duplicate entry '180.201.163.246:6800' for key 'device.PRIMARY'")
[SQL: UPDATE device SET server_id=%(server_id)s, ip=%(ip)s, username=%(username)s, password=%(password)s, address=%(address)s, port=%(port)s, valid=%(valid)s WHERE device.ip = %(ip_1)s]
[parameters: {'server_id': '180.201.163.246:6800', 'ip': '180.201.163.246', 'username': 'chase', 'password': '67347939908682195993502106572146647596030732451764082147026629359664822800927664563072407611521345299071030246035694821870112312638347488094816094353 ... (10 characters truncated) ... 62405547597448948076034941282114593353650146879497733364641144645202052990923102576660993393949701483378263534042752347182135856622175980098192075772', 'address': '/home/users/CT/pycharmproject/spiders/', 'port': 6800, 'valid': 1, 'ip_1': '180.201.163.246'}]
(Background on this error at: https://sqlalche.me/e/14/gkpj)
